Workbook

Sheet 0 - Indice
A1: Barista FIRE — il divario, il lavoro leggero e le tre strade fiscali
A2: Strumento informativo / divulgativo. NON è consulenza finanziaria. I valori sono indicativi al 2026 e vanno verificati col tuo consulente.
A4: Indice
A5: 1 - INPUT | B5: Il caso, il lavoro leggero, i mercati e la sequenza
A6: 1b - COMPOSIZIONE | B6: Da dove viene il capitale: la latente si CALCOLA, non si sceglie
A7: 1c - NASPI | B7: I 24 assegni con la tutela degli over 55, dal lordo alla cassa
A8: 2 - SIMULAZIONE | B8: Il motore: 37 anni riga per riga e i DUE fattori di lordizzazione
A9: 3 - CRUSCOTTO | B9: Il cruscotto: divario, copertura, capitale, reddito necessario
A10: 4 - CAPITALE EQUIV | B10: Quanto vale un reddito a termine, netto e al lordo dell'imposta
A11: 5 - LE TRE STRADE | B11: Occasionale, dipendente, forfettario: i due pareggi e i costi reali
A12: 6 - PONTE E PENSIONE | B12: Le pensioni di coppia dal 2039 e la pensione che il part-time aggiunge
A13: 7 - SEQUENZA | B13: Quattro ordini di rendimento, stessa media, esiti molto diversi
A14: 8 - PARAMETRI 2026 | B14: Tutti i parametri 2026 con la fonte, e le due scadenze
A16: Come usare
A17: 1. Le celle GIALLE sono input — modificale coi tuoi numeri.
A18: 2. Le celle VERDI sono output — si aggiornano automaticamente.
A19: 3. Tutti i numeri di default sono al 2026 da fonti pubbliche.
A20: 4. Niente codice nascosto: l'Excel è solo formule modificabili.
A22: Fonti dati
A23: • D.Lgs. 4 marzo 2015 n. 22 (NASpI): artt. 3, 4 c. 1, 5, 10
A24: • L. 145/2018 art. 1 c. 510 (decalage dall'ottavo mese per gli over 55)
A25: • Messaggio INPS n. 1414 del 9 aprile 2024 (soglie 5.500 / 8.500)
A26: • Corte cost. n. 90/2024 e circolare INPS n. 36 del 4 febbraio 2025
A27: • L. 190/2014 art. 1 cc. 54-89 e Allegato 4 (regime forfettario)
A28: • L. 199/2025 art. 1 c. 27 (soglia 35.000 € per il 2025 e il 2026)
... A36: Aggiornamenti: github.com/marcofire-it/marco-fire-simulatori

Sheet 1 - INPUT
A1: 1 — INPUT: il caso, il lavoro leggero, i mercati
A2: Strumento informativo / divulgativo. NON è consulenza finanziaria. I valori sono indicativi al 2026 e vanno verificati col tuo consulente.
A4: IL CASO — Franco e Giulia, 55 anni, nati nel 1971
A5: Patrimonio iniziale | B5: 1100000 | D5: 1.100.000 € è la scelta d'ancoraggio dell'orchestratore, dichiarata come tale: le tre componenti del foglio 1b sono state calibrate per rispettarla, non viceversa.
A6: Spesa annua netta | B6: 70000 | D6: Variabile di scelta, non un dato: è 2,60 volte il tenore tenuto durante l'accumulo (foglio 1b) e circa due volte l'ISTAT di coppia.
A7: Spesa mensile | B7: =B6/12
A8: età oggi | B8: 55
A9: Anno dell'uscita dal lavoro pieno | B9: 2026
A10: Orizzonte del piano (anni) | B10: 37 | D10: 37 anni: fino ai 92 di Franco.
A11: Anni di ponte fino alle pensioni | B11: 13
A12: Anno di decorrenza delle pensioni | B12: =B9+B11 | D12: 68 anni e 2 mesi nel 2039 è una PROIEZIONE della Ragioneria Generale dello Stato, non una norma: va dichiarato ogni volta.
A13: Pensione netta di coppia (annua, 13 mensilità) | B13: 29094 | D13: 2.238 €/mese netti: Franco 1.372 + Giulia 866, dalla matrice stop-55 del foglio 6. È il 41,6% della spesa.
A15: IL LAVORO LEGGERO
A16: Reddito netto annuo dal part-time | B16: 18000
A17: Anni di lavoro | B17: 13
A18: Primo anno di lavoro (1 = subito) | B18: 1 | D18: Porta B (scenario canonico): il lavoro parte subito e l'indennità decade. Porta A: 1 e 2 di sola indennità, lavoro dal terzo anno (metti 3 qui e 11 sopra).
A19: Coefficiente di redditività (Allegato 4) | B19: 0.67 | D19: 67% = «altre attività economiche», assistenza e servizi tecnici leggeri. È una SCELTA, non un dato: il foglio 5 pubblica anche il 40% e il 78%.
A20: Costi reali, in % dei ricavi | B20: 0.1
A21: Fattore costo per chi paga | B21: 1.34 | D21: Contributi del datore ~30% nel terziario più il TFR 6,91%. Banda dichiarata 1,30-1,38.
A22: Ore annue lavorate | B22: 630 | D22: 2 giorni x 7 ore x 45 settimane (52 meno 5 di ferie e 2 di festivita' e chiusure).
A23: Compenso orario lordo | B23: 12 | D23: CCNL Pubblici esercizi, 5o livello: circa 9 €/ora di paga base, 11-12 comprensivi dei ratei. FONTE SECONDARIA (tabelle retributive): a video sempre «circa».
A24: Compenso lordo annuo | B24: =B22*B23
A26: MERCATI, IMPOSTE, SEQUENZA
A27: Rendimento reale annuo | B27: 0.03
A28: Imposta sulla plusvalenza | B28: 0.26
A29: Imposta di bollo sul dossier | B29: 0.002
A30: PLUSVALENZA LATENTE INIZIALE (calcolata) | B30: ='1b - COMPOSIZIONE'!B31 | D30: DERIVATA dal foglio 1b, non postulata: è il risultato della composizione patrimoniale.
A31: Ordine dei rendimenti (0 costante, 1 inizio, 2 metà, 3 fine) | B31: 0
A32: Primo crollo | B32: -0.35
A33: Secondo crollo | B33: -0.2
A34: Posizioni dei crolli — «all'inizio» | B34: 1 | C34: 2
A35: Posizioni dei crolli — «a metà» | B35: 19 | C35: 20
A36: Posizioni dei crolli — «alla fine» | B36: 36 | C36: 37
A37: Rendimento degli anni normali (calcolato) | B37: =((1+B27)^B10/((1+B32)*(1+B33)))^(1/(B10-2))-1 | D37: Calibrato perché la media geometrica dei 37 anni resti pari al rendimento scelto: i quattro ordini hanno lo STESSO rendimento medio e differiscono solo per la sequenza.
A39: L'INDENNITÀ NEL PIANO
A40: indennità inclusa nel piano (1 = sì, 0 = no) | B40: 0 | D40: Franco esce per risoluzione consensuale in sede protetta e ha diritto alla NASpI per 24 mesi — ma nella PORTA B lavora subito e l'indennità DECADE: per questo il default è zero. Metti 1 (con lavoro dal terzo anno per 11 anni) per la porta A. Se ti DIMETTI l'indennità non c'è in nessuna delle due.
A41: indennità netta anno 1 | B41: ='1c - NASPI'!B59
A42: indennità netta anno 2 | B42: ='1c - NASPI'!C59
A43: IL CORTOCIRCUITO: indennità e lavoro NON convivono. Entro le soglie di compatibilità (5.500 € per il lavoro autonomo, 8.500 per il subordinato, msg. INPS 1414/2024) l'indennità prosegue ridotta dell'80% del reddito previsto — venti centesimi per euro, e solo DENTRO la finestra dell'indennità; oltre le soglie, decadenza. I 18.000 € del part-time fanno decadere la NASpI: le due risorse vanno in ALTERNATIVA, mai in somma. Per questo il piano ha due porte, non una somma.

Sheet 1b - COMPOSIZIONE
A1: 1b — DA DOVE VIENE IL CAPITALE, e quanta plusvalenza c'è dentro
A2: Strumento informativo / divulgativo. NON è consulenza finanziaria. I valori sono indicativi al 2026 e vanno verificati col tuo consulente.
A4: COMPONENTI EVENTO — incassate e investite all'uscita
A5: Componente | B5: Valore | C5: Base di costo | D5: Incassate e investite all'uscita: base di costo = valore, latente zero.
A6: TFR netto (30 anni di anzianità, tassazione separata) | B6: 68000 | C6: =B6
A7: Incentivo all'esodo: mensilità | B7: 26
A8: Retribuzione mensile (35.000 / 13) | B8: =35000/13
A9: Incentivo lordo | B9: =B7*B8
A10: Aliquota della tassazione separata | B10: 0.2476 | D10: Aliquota della separata con reddito di riferimento 34.000 € (art. 19 TUIR).
A11: Incentivo all'esodo NETTO | B11: =B9*(1-B10) | C11: =B11
A12: Cessione dell'immobile locato, netta | B12: 225000 | C12: =B12 | D12: Acquistato nel 2003 CON MUTUO e messo a reddito: possesso oltre cinque anni, nessuna imposta sulla plusvalenza (art. 67 c. 1 lett. b TUIR). I canoni storici sono ESCLUSI dal conto del tasso di risparmio.
A13: TOTALE COMPONENTI EVENTO | B13: =B6+B11+B12 | C13: =C6+C11+C12
A15: ACCUMULO FINANZIARIO — e paga il bollo
A16: Anni di accumulo | B16: 30
A17: Rendimento reale lordo | B17: 0.03
A18: Imposta di bollo in accumulo | B18: 0.002
A19: Rendimento reale NETTO BOLLO | B19: =B17-B18 | D19: Anche l'accumulo paga il bollo: 3,0% - 0,2% = 2,8%. Senza questa correzione il versamento richiesto sarebbe sottostimato.
A20: Fattore di montante | B20: =((1+B19)^B16-1)/B19
A21: MONTANTE DELL'ACCUMULO (per differenza) | B21: ='1 - INPUT'!B5-B13 | D21: È il residuo dell'ancoraggio: il totale 1.100.000 è la scelta dichiarata, le componenti sono calibrate su di essa.
A22: Versamento annuo reale implicito | B22: =B21/B20
A23: Inflazione | B23: 0.02
A24: Fattore della base di costo nominale | B24: =(1-(1+B23)^-B16)/B23*(1+B23) | D24: Versamenti REALI costanti = versamenti NOMINALI crescenti al 2%: la base di costo è la somma dei nominali.
A25: BASE DI COSTO NOMINALE DELL'ACCUMULO | B25: =B22*B24
A27: IL TOTALE E LA LATENTE — derivata, non postulata
A28: Patrimonio totale | B28: =B13+B21
A29: Base di costo totale | B29: =C13+B25
A30: Plusvalenza latente, in euro | B30: =B28-B29
A31: PLUSVALENZA LATENTE INIZIALE | B31: =1-B29/B28 | D31: Non è un input libero: è quello che la composizione patrimoniale IMPLICA. Da qui discendono tutti i tassi di prelievo e i due fattori di lordizzazione.
A33: IL TASSO DI RISPARMIO E IL SALTO
B34: Franco | C34: Giulia
A35: Retribuzione lorda in carriera | B35: 35000 | C35: 20000
A36: Contributi a carico del lavoratore (9,19%) | B36: =B35*0.0919 | C36: =C35*0.0919
A37: Imponibile | B37: =B35-B36 | C37: =C35-C36
A38: IRPEF lorda | B38: =(MIN(B37,28000)*0.23+MAX(0,MIN(B37,50000)-28000)*0.33+MAX(0,B37-50000)*0.43) | C38: =(MIN(C37,28000)*0.23+MAX(0,MIN(C37,50000)-28000)*0.33+MAX(0,C37-50000)*0.43)
A39: Detrazioni (art. 13 c. 1 e ulteriore) | B39: =IF(B37<=15000,1955,IF(B37<=28000,1910+1190*(28000-B37)/13000,IF(B37<=50000,1910*(50000-B37)/22000,0)))+IF(B37<=20000,0,IF(B37<=32000,1000,IF(B37<=40000,1000*(40000-B37)/8000,0))) | C39: =IF(C37<=15000,1955,IF(C37<=28000,1910+1190*(28000-C37)/13000,IF(C37<=50000,1910*(50000-C37)/22000,0)))+IF(C37<=20000,0,IF(C37<=32000,1000,IF(C37<=40000,1000*(40000-C37)/8000,0)))
A40: IRPEF netta | B40: =MAX(0,B38-B39) | C40: =MAX(0,C38-C39)
A41: Somma integrativa sul cuneo | B41: =IF(B37<=8500,0.071*B37,IF(B37<=15000,0.053*B37,IF(B37<=20000,0.048*B37,0))) | C41: =IF(C37<=8500,0.071*C37,IF(C37<=15000,0.053*C37,IF(C37<=20000,0.048*C37,0)))
A42: Addizionali locali (2,0%) | B42: =IF(B40>0,B37*0.02,0) | C42: =IF(C40>0,C37*0.02,0)
A43: NETTO | B43: =B37-B40+B41-B42 | C43: =C37-C40+C41-C42
A44: Netto di coppia durante l'accumulo | B44: =B43+C43
...

Sheet 1c - NASPI
A1: 1c — LA NASpI DI FRANCO: 24 assegni, con la tutela degli over 55
A2: Strumento informativo / divulgativo. NON è consulenza finanziaria. I valori sono indicativi al 2026 e vanno verificati col tuo consulente.
A4: LA FATTISPECIE E L'ASSEGNO
A5: Retribuzione lorda annua | B5: 35000 | E5: Risoluzione consensuale in sede protetta (art. 3 D.Lgs. 22/2015 con art. 7 L. 604/1966): Franco HA diritto. Se ti DIMETTI, no.
A6: Anni di riferimento | B6: 4
A7: Settimane del quadriennio | B7: 208
A8: Coefficiente di mensilizzazione | B8: 4.33 | E8: Lo STESSO coefficiente in ogni formula del foglio, comprese le soglie: 4,33 e non 13/3.
A9: Retribuzione media mensile imponibile | B9: =B5*B6/B7*B8
A10: Soglia della formula 2026 | B10: 1456.72
A11: Tetto mensile 2026 | B11: 1584.7
A12: ASSEGNO INIZIALE | B12: =MIN(B11,0.75*B10+0.25*(B9-B10))
A13: Il tetto è saturato? | B13: =IF(0.75*B10+0.25*(B9-B10)>=B11,"SI","NO")
A14: Retribuzione annua che satura il tetto | B14: =((B11-0.75*B10)/0.25+B10)/B8*B7/B6 | E14: Franco è a 35.000: SOTTO la soglia di saturazione, quindi il suo assegno NON è quello di chi il tetto lo tocca.
A15: età alla data della domanda | B15: 55
A16: Decorrenza del decalage (mese) | B16: =IF(B15>=55,8,6) | E16: Chi ha compiuto 55 anni alla domanda vede la riduzione partire dal primo giorno dell'OTTAVO mese (211o giorno) e non dal sesto: art. 4 c. 1 D.Lgs. 22/2015 come modificato dalla L. 145/2018 art. 1 c. 510. È la tutela che cambia i numeri a valle di tutto il piano.
A17: Riduzione mensile | B17: 0.03
A19: I 24 ASSEGNI, MESE PER MESE
A20: Mese | B20: Coefficiente | C20: Assegno lordo | D20: Anno
A21: 1 | B21: =IF(A21<$B$16,1,(1-$B$17)^(A21-$B$16+1)) | C21: =$B$12*B21 | D21: =IF(A21<=12,1,2)
A22: 2 | B22: =IF(A22<$B$16,1,(1-$B$17)^(A22-$B$16+1)) | C22: =$B$12*B22 | D22: =IF(A22<=12,1,2)
A23: 3 | B23: =IF(A23<$B$16,1,(1-$B$17)^(A23-$B$16+1)) | C23: =$B$12*B23 | D23: =IF(A23<=12,1,2)
A24: 4 | B24: =IF(A24<$B$16,1,(1-$B$17)^(A24-$B$16+1)) | C24: =$B$12*B24 | D24: =IF(A24<=12,1,2)
A25: 5 | B25: =IF(A25<$B$16,1,(1-$B$17)^(A25-$B$16+1)) | C25: =$B$12*B25 | D25: =IF(A25<=12,1,2)
A26: 6 | B26: =IF(A26<$B$16,1,(1-$B$17)^(A26-$B$16+1)) | C26: =$B$12*B26 | D26: =IF(A26<=12,1,2)
A27: 7 | B27: =IF(A27<$B$16,1,(1-$B$17)^(A27-$B$16+1)) | C27: =$B$12*B27 | D27: =IF(A27<=12,1,2)
A28: 8 | B28: =IF(A28<$B$16,1,(1-$B$17)^(A28-$B$16+1)) | C28: =$B$12*B28 | D28: =IF(A28<=12,1,2)
A29: 9 | B29: =IF(A29<$B$16,1,(1-$B$17)^(A29-$B$16+1)) | C29: =$B$12*B29 | D29: =IF(A29<=12,1,2)
A30: 10 | B30: =IF(A30<$B$16,1,(1-$B$17)^(A30-$B$16+1)) | C30: =$B$12*B30 | D30: =IF(A30<=12,1,2)
A31: 11 | B31: =IF(A31<$B$16,1,(1-$B$17)^(A31-$B$16+1)) | C31: =$B$12*B31 | D31: =IF(A31<=12,1,2)
A32: 12 | B32: =IF(A32<$B$16,1,(1-$B$17)^(A32-$B$16+1)) | C32: =$B$12*B32 | D32: =IF(A32<=12,1,2)
... A44: 24 | B44: =IF(A44<$B$16,1,(1-$B$17)^(A44-$B$16+1)) | C44: =$B$12*B44 | D44: =IF(A44<=12,1,2)
A45: Fattore cumulato — anno 1 | B45: =SUMIF($D$21:$D$44,1,$B$21:$B$44)
A46: Fattore cumulato — anno 2 | B46: =SUMIF($D$21:$D$44,2,$B$21:$B$44)
A47: FATTORE CUMULATO 24 MESI | B47: =B45+B46
A48: Ultimo assegno (24o mese) | B48: =C44
A49: Ultimo assegno in % del primo | B49: =C44/B12
A51: DAL LORDO ALLA CASSA
B52: Anno 1 | C52: Anno 2 | D52: Totale
A53: Lordo | B53: =$B$12*$B$45 | C53: =$B$12*$B$46 | D53: =B53+C53
A54: IRPEF lorda (23%) | B54: =B53*0.23 | C54: =C53*0.23 | D54: =B54+C54
...

Sheet 2 - SIMULAZIONE
A1: 2 — IL MOTORE: trentasette anni, riga per riga
A2: Strumento informativo / divulgativo. NON è consulenza finanziaria. I valori sono indicativi al 2026 e vanno verificati col tuo consulente.
A4: SCENARIO DEL TEST — lascia 0 (o -1) per usare il foglio 1
A5: Patrimonio iniziale del test (0 = foglio 1) | C5: 0
A6: Spesa annua del test (0 = foglio 1) | C6: 64089.31 | E6: SCENARIO DI RIFERIMENTO DEL FOGLIO: la SPESA MASSIMA della porta B, cioe' quella che porta il patrimonio esattamente a zero al trentasettesimo anno. È su questo scenario che si misurano i due fattori di lordizzazione in fondo al foglio. Metti 0 per vedere il piano com'è oggi, con la spesa scelta di settantamila euro: il patrimonio finisce prima.
A7: Reddito da lavoro del test (-1 = foglio 1) | C7: -1
A8: Anni di lavoro del test (-1 = foglio 1) | C8: -1
A9: Primo anno di lavoro del test (0 = foglio 1) | C9: 0
A10: indennità nel test (-1 = foglio 1) | C10: -1
A11: Rendimento reale del test (-1 = foglio 1) | C11: -1
A12: Ordine dei rendimenti del test (-1 = foglio 1) | C12: -1
A14: Patrimonio iniziale usato | C14: =IF(C5>0,C5,'1 - INPUT'!B5)
A15: Spesa annua usata | C15: =IF(C6>0,C6,'1 - INPUT'!B6)
A16: Reddito da lavoro usato | C16: =IF(C7>=0,C7,'1 - INPUT'!B16)
A17: Anni di lavoro usati | C17: =IF(C8>=0,C8,'1 - INPUT'!B17)
A18: Primo anno di lavoro usato | C18: =IF(C9>0,C9,'1 - INPUT'!B18)
A19: indennità usata (1/0) | C19: =IF(C10>=0,C10,'1 - INPUT'!B40)
A20: Rendimento reale usato | C20: =IF(C11>=0,C11,'1 - INPUT'!B27)
A21: Ordine usato | C21: =IF(C12>=0,C12,'1 - INPUT'!B31)
A22: Base di costo iniziale | C22: =C14*(1-'1 - INPUT'!B30)
A23: Rendimento degli anni normali | C23: =((1+C20)^'1 - INPUT'!B10/((1+'1 - INPUT'!B32)*(1+'1 - INPUT'!B33)))^(1/('1 - INPUT'!B10-2))-1
A25: TRENTASETTE ANNI DI PIANO
A26: Anno | B26: Civile | C26: Patrimonio a inizio anno | D26: Base di costo | E26: Latente | F26: Lavoro | G26: indennità | H26: Pensioni | I26: Fabbisogno netto | J26: Vendita lorda | K26: Rendim. | L26: Bollo | M26: Patrimonio a fine anno | N26: Base a fine anno
A27: 1 | B27: ='1 - INPUT'!$B$9+A27-1 | C27: =$C$14 | D27: =$C$22 | E27: =MAX(0,1-D27/C27) | F27: =IF(AND(A27>=$C$18,A27<$C$18+$C$17),$C$16,0) | G27: =IF(A27=1,$C$19*'1c - NASPI'!$B$59,IF(A27=2,$C$19*'1c - NASPI'!$C$59,0)) | H27: =IF(A27>'1 - INPUT'!$B$11,'1 - INPUT'!$B$13,0) | I27: =MAX(0,$C$15-F27-G27-H27) | J27: =I27/(1-'1 - INPUT'!$B$28*E27) | K27: =IF($C$21=0,$C$20,IF(A27=CHOOSE($C$21,'1 - INPUT'!$B$34,'1 - INPUT'!$B$35,'1 - INPUT'!$B$36),'1 - INPUT'!$B$32,IF(A27=CHOOSE($C$21,'1 - INPUT'!$C$34,'1 - INPUT'!$C$35,'1 - INPUT'!$C$36),'1 - INPUT'!$B$33,$C$23))) | L27: =(C27-J27)*(1+K27)*'1 - INPUT'!$B$29 | M27: =(C27-J27)*(1+K27)-L27 | N27: =D27*(1-J27/C27)
A28: 2 | B28: ='1 - INPUT'!$B$9+A28-1 | C28: =M27 | D28: =N27 | E28: =MAX(0,1-D28/C28) | F28: =IF(AND(A28>=$C$18,A28<$C$18+$C$17),$C$16,0) | G28: =IF(A28=1,$C$19*'1c - NASPI'!$B$59,IF(A28=2,$C$19*'1c - NASPI'!$C$59,0)) | H28: =IF(A28>'1 - INPUT'!$B$11,'1 - INPUT'!$B$13,0) | I28: =MAX(0,$C$15-F28-G28-H28) | J28: =I28/(1-'1 - INPUT'!$B$28*E28) | K28: =IF($C$21=0,$C$20,IF(A28=CHOOSE($C$21,'1 - INPUT'!$B$34,'1 - INPUT'!$B$35,'1 - INPUT'!$B$36),'1 - INPUT'!$B$32,IF(A28=CHOOSE($C$21,'1 - INPUT'!$C$34,'1 - INPUT'!$C$35,'1 - INPUT'!$C$36),'1 - INPUT'!$B$33,$C$23))) | L28: =(C28-J28)*(1+K28)*'1 - INPUT'!$B$29 | M28: =(C28-J28)*(1+K28)-L28 | N28: =D28*(1-J28/C28)
A29: 3 | B29: ='1 - INPUT'!$B$9+A29-1 | C29: =M28 | D29: =N28 | E29: =MAX(0,1-D29/C29) | F29: =IF(AND(A29>=$C$18,A29<$C$18+$C$17),$C$16,0) | G29: =IF(A29=1,$C$19*'1c - NASPI'!$B$59,IF(A29=2,$C$19*'1c - NASPI'!$C$59,0)) | H29: =IF(A29>'1 - INPUT'!$B$11,'1 - INPUT'!$B$13,0) | I29: =MAX(0,$C$15-F29-G29-H29) | J29: =I29/(1-'1 - INPUT'!$B$28*E29) | K29: =IF($C$21=0,$C$20,IF(A29=CHOOSE($C$21,'1 - INPUT'!$B$34,'1 - INPUT'!$B$35,'1 - INPUT'!$B$36),'1 - INPUT'!$B$32,IF(A29=CHOOSE($C$21,'1 - INPUT'!$C$34,'1 - INPUT'!$C$35,'1 - INPUT'!$C$36),'1 - INPUT'!$B$33,$C$23))) | L29: =(C29-J29)*(1+K29)*'1 - INPUT'!$B$29 | M29: =(C29-J29)*(1+K29)-L29 | N29: =D29*(1-J29/C29)
A30: 4 | B30: ='1 - INPUT'!$B$9+A30-1 | C30: =M29 | D30: =N29 | E30: =MAX(0,1-D30/C30) | F30: =IF(AND(A30>=$C$18,A30<$C$18+$C$17),$C$16,0) | G30: =IF(A30=1,$C$19*'1c - NASPI'!$B$59,IF(A30=2,$C$19*'1c - NASPI'!$C$59,0)) | H30: =IF(A30>'1 - INPUT'!$B$11,'1 - INPUT'!$B$13,0) | I30: =MAX(0,$C$15-F30-G30-H30) | J30: =I30/(1-'1 - INPUT'!$B$28*E30) | K30: =IF($C$21=0,$C$20,IF(A30=CHOOSE($C$21,'1 - INPUT'!$B$34,'1 - INPUT'!$B$35,'1 - INPUT'!$B$36),'1 - INPUT'!$B$32,IF(A30=CHOOSE($C$21,'1 - INPUT'!$C$34,'1 - INPUT'!$C$35,'1 - INPUT'!$C$36),'1 - INPUT'!$B$33,$C$23))) | L30: =(C30-J30)*(1+K30)*'1 - INPUT'!$B$29 | M30: =(C30-J30)*(1+K30)-L30 | N30: =D30*(1-J30/C30)
A31: 5 | B31: ='1 - INPUT'!$B$9+A31-1 | C31: =M30 | D31: =N30 | E31: =MAX(0,1-D31/C31) | F31: =IF(AND(A31>=$C$18,A31<$C$18+$C$17),$C$16,0) | G31: =IF(A31=1,$C$19*'1c - NASPI'!$B$59,IF(A31=2,$C$19*'1c - NASPI'!$C$59,0)) | H31: =IF(A31>'1 - INPUT'!$B$11,'1 - INPUT'!$B$13,0) | I31: =MAX(0,$C$15-F31-G31-H31) | J31: =I31/(1-'1 - INPUT'!$B$28*E31) | K31: =IF($C$21=0,$C$20,IF(A31=CHOOSE($C$21,'1 - INPUT'!$B$34,'1 - INPUT'!$B$35,'1 - INPUT'!$B$36),'1 - INPUT'!$B$32,IF(A31=CHOOSE($C$21,'1 - INPUT'!$C$34,'1 - INPUT'!$C$35,'1 - INPUT'!$C$36),'1 - INPUT'!$B$33,$C$23))) | L31: =(C31-J31)*(1+K31)*'1 - INPUT'!$B$29 | M31: =(C31-J31)*(1+K31)-L31 | N31: =D31*(1-J31/C31)
A32: 6 | B32: ='1 - INPUT'!$B$9+A32-1 | C32: =M31 | D32: =N31 | E32: =MAX(0,1-D32/C32) | F32: =IF(AND(A32>=$C$18,A32<$C$18+$C$17),$C$16,0) | G32: =IF(A32=1,$C$19*'1c - NASPI'!$B$59,IF(A32=2,$C$19*'1c - NASPI'!$C$59,0)) | H32: =IF(A32>'1 - INPUT'!$B$11,'1 - INPUT'!$B$13,0) | I32: =MAX(0,$C$15-F32-G32-H32) | J32: =I32/(1-'1 - INPUT'!$B$28*E32) | K32: =IF($C$21=0,$C$20,IF(A32=CHOOSE($C$21,'1 - INPUT'!$B$34,'1 - INPUT'!$B$35,'1 - INPUT'!$B$36),'1 - INPUT'!$B$32,IF(A32=CHOOSE($C$21,'1 - INPUT'!$C$34,'1 - INPUT'!$C$35,'1 - INPUT'!$C$36),'1 - INPUT'!$B$33,$C$23))) | L32: =(C32-J32)*(1+K32)*'1 - INPUT'!$B$29 | M32: =(C32-J32)*(1+K32)-L32 | N32: =D32*(1-J32/C32)
A33: 7 | B33: ='1 - INPUT'!$B$9+A33-1 | C33: =M32 | D33: =N32 | E33: =MAX(0,1-D33/C33) | F33: =IF(AND(A33>=$C$18,A33<$C$18+$C$17),$C$16,0) | G33: =IF(A33=1,$C$19*'1c - NASPI'!$B$59,IF(A33=2,$C$19*'1c - NASPI'!$C$59,0)) | H33: =IF(A33>'1 - INPUT'!$B$11,'1 - INPUT'!$B$13,0) | I33: =MAX(0,$C$15-F33-G33-H33) | J33: =I33/(1-'1 - INPUT'!$B$28*E33) | K33: =IF($C$21=0,$C$20,IF(A33=CHOOSE($C$21,'1 - INPUT'!$B$34,'1 - INPUT'!$B$35,'1 - INPUT'!$B$36),'1 - INPUT'!$B$32,IF(A33=CHOOSE($C$21,'1 - INPUT'!$C$34,'1 - INPUT'!$C$35,'1 - INPUT'!$C$36),'1 - INPUT'!$B$33,$C$23))) | L33: =(C33-J33)*(1+K33)*'1 - INPUT'!$B$29 | M33: =(C33-J33)*(1+K33)-L33 | N33: =D33*(1-J33/C33)
A34: 8 | B34: ='1 - INPUT'!$B$9+A34-1 | C34: =M33 | D34: =N33 | E34: =MAX(0,1-D34/C34) | F34: =IF(AND(A34>=$C$18,A34<$C$18+$C$17),$C$16,0) | G34: =IF(A34=1,$C$19*'1c - NASPI'!$B$59,IF(A34=2,$C$19*'1c - NASPI'!$C$59,0)) | H34: =IF(A34>'1 - INPUT'!$B$11,'1 - INPUT'!$B$13,0) | I34: =MAX(0,$C$15-F34-G34-H34) | J34: =I34/(1-'1 - INPUT'!$B$28*E34) | K34: =IF($C$21=0,$C$20,IF(A34=CHOOSE($C$21,'1 - INPUT'!$B$34,'1 - INPUT'!$B$35,'1 - INPUT'!$B$36),'1 - INPUT'!$B$32,IF(A34=CHOOSE($C$21,'1 - INPUT'!$C$34,'1 - INPUT'!$C$35,'1 - INPUT'!$C$36),'1 - INPUT'!$B$33,$C$23))) | L34: =(C34-J34)*(1+K34)*'1 - INPUT'!$B$29 | M34: =(C34-J34)*(1+K34)-L34 | N34: =D34*(1-J34/C34)
A35: 9 | B35: ='1 - INPUT'!$B$9+A35-1 | C35: =M34 | D35: =N34 | E35: =MAX(0,1-D35/C35) | F35: =IF(AND(A35>=$C$18,A35<$C$18+$C$17),$C$16,0) | G35: =IF(A35=1,$C$19*'1c - NASPI'!$B$59,IF(A35=2,$C$19*'1c - NASPI'!$C$59,0)) | H35: =IF(A35>'1 - INPUT'!$B$11,'1 - INPUT'!$B$13,0) | I35: =MAX(0,$C$15-F35-G35-H35) | J35: =I35/(1-'1 - INPUT'!$B$28*E35) | K35: =IF($C$21=0,$C$20,IF(A35=CHOOSE($C$21,'1 - INPUT'!$B$34,'1 - INPUT'!$B$35,'1 - INPUT'!$B$36),'1 - INPUT'!$B$32,IF(A35=CHOOSE($C$21,'1 - INPUT'!$C$34,'1 - INPUT'!$C$35,'1 - INPUT'!$C$36),'1 - INPUT'!$B$33,$C$23))) | L35: =(C35-J35)*(1+K35)*'1 - INPUT'!$B$29 | M35: =(C35-J35)*(1+K35)-L35 | N35: =D35*(1-J35/C35)
A36: 10 | B36: ='1 - INPUT'!$B$9+A36-1 | C36: =M35 | D36: =N35 | E36: =MAX(0,1-D36/C36) | F36: =IF(AND(A36>=$C$18,A36<$C$18+$C$17),$C$16,0) | G36: =IF(A36=1,$C$19*'1c - NASPI'!$B$59,IF(A36=2,$C$19*'1c - NASPI'!$C$59,0)) | H36: =IF(A36>'1 - INPUT'!$B$11,'1 - INPUT'!$B$13,0) | I36: =MAX(0,$C$15-F36-G36-H36) | J36: =I36/(1-'1 - INPUT'!$B$28*E36) | K36: =IF($C$21=0,$C$20,IF(A36=CHOOSE($C$21,'1 - INPUT'!$B$34,'1 - INPUT'!$B$35,'1 - INPUT'!$B$36),'1 - INPUT'!$B$32,IF(A36=CHOOSE($C$21,'1 - INPUT'!$C$34,'1 - INPUT'!$C$35,'1 - INPUT'!$C$36),'1 - INPUT'!$B$33,$C$23))) | L36: =(C36-J36)*(1+K36)*'1 - INPUT'!$B$29 | M36: =(C36-J36)*(1+K36)-L36 | N36: =D36*(1-J36/C36)
A37: 11 | B37: ='1 - INPUT'!$B$9+A37-1 | C37: =M36 | D37: =N36 | E37: =MAX(0,1-D37/C37) | F37: =IF(AND(A37>=$C$18,A37<$C$18+$C$17),$C$16,0) | G37: =IF(A37=1,$C$19*'1c - NASPI'!$B$59,IF(A37=2,$C$19*'1c - NASPI'!$C$59,0)) | H37: =IF(A37>'1 - INPUT'!$B$11,'1 - INPUT'!$B$13,0) | I37: =MAX(0,$C$15-F37-G37-H37) | J37: =I37/(1-'1 - INPUT'!$B$28*E37) | K37: =IF($C$21=0,$C$20,IF(A37=CHOOSE($C$21,'1 - INPUT'!$B$34,'1 - INPUT'!$B$35,'1 - INPUT'!$B$36),'1 - INPUT'!$B$32,IF(A37=CHOOSE($C$21,'1 - INPUT'!$C$34,'1 - INPUT'!$C$35,'1 - INPUT'!$C$36),'1 - INPUT'!$B$33,$C$23))) | L37: =(C37-J37)*(1+K37)*'1 - INPUT'!$B$29 | M37: =(C37-J37)*(1+K37)-L37 | N37: =D37*(1-J37/C37)
A38: 12 | B38: ='1 - INPUT'!$B$9+A38-1 | C38: =M37 | D38: =N37 | E38: =MAX(0,1-D38/C38) | F38: =IF(AND(A38>=$C$18,A38<$C$18+$C$17),$C$16,0) | G38: =IF(A38=1,$C$19*'1c - NASPI'!$B$59,IF(A38=2,$C$19*'1c - NASPI'!$C$59,0)) | H38: =IF(A38>'1 - INPUT'!$B$11,'1 - INPUT'!$B$13,0) | I38: =MAX(0,$C$15-F38-G38-H38) | J38: =I38/(1-'1 - INPUT'!$B$28*E38) | K38: =IF($C$21=0,$C$20,IF(A38=CHOOSE($C$21,'1 - INPUT'!$B$34,'1 - INPUT'!$B$35,'1 - INPUT'!$B$36),'1 - INPUT'!$B$32,IF(A38=CHOOSE($C$21,'1 - INPUT'!$C$34,'1 - INPUT'!$C$35,'1 - INPUT'!$C$36),'1 - INPUT'!$B$33,$C$23))) | L38: =(C38-J38)*(1+K38)*'1 - INPUT'!$B$29 | M38: =(C38-J38)*(1+K38)-L38 | N38: =D38*(1-J38/C38)
A39: 13 | B39: ='1 - INPUT'!$B$9+A39-1 | C39: =M38 | D39: =N38 | E39: =MAX(0,1-D39/C39) | F39: =IF(AND(A39>=$C$18,A39<$C$18+$C$17),$C$16,0) | G39: =IF(A39=1,$C$19*'1c - NASPI'!$B$59,IF(A39=2,$C$19*'1c - NASPI'!$C$59,0)) | H39: =IF(A39>'1 - INPUT'!$B$11,'1 - INPUT'!$B$13,0) | I39: =MAX(0,$C$15-F39-G39-H39) | J39: =I39/(1-'1 - INPUT'!$B$28*E39) | K39: =IF($C$21=0,$C$20,IF(A39=CHOOSE($C$21,'1 - INPUT'!$B$34,'1 - INPUT'!$B$35,'1 - INPUT'!$B$36),'1 - INPUT'!$B$32,IF(A39=CHOOSE($C$21,'1 - INPUT'!$C$34,'1 - INPUT'!$C$35,'1 - INPUT'!$C$36),'1 - INPUT'!$B$33,$C$23))) | L39: =(C39-J39)*(1+K39)*'1 - INPUT'!$B$29 | M39: =(C39-J39)*(1+K39)-L39 | N39: =D39*(1-J39/C39)
... A63: 37 | B63: ='1 - INPUT'!$B$9+A63-1 | C63: =M62 | D63: =N62 | E63: =MAX(0,1-D63/C63) | F63: =IF(AND(A63>=$C$18,A63<$C$18+$C$17),$C$16,0) | G63: =IF(A63=1,$C$19*'1c - NASPI'!$B$59,IF(A63=2,$C$19*'1c - NASPI'!$C$59,0)) | H63: =IF(A63>'1 - INPUT'!$B$11,'1 - INPUT'!$B$13,0) | I63: =MAX(0,$C$15-F63-G63-H63) | J63: =I63/(1-'1 - INPUT'!$B$28*E63) | K63: =IF($C$21=0,$C$20,IF(A63=CHOOSE($C$21,'1 - INPUT'!$B$34,'1 - INPUT'!$B$35,'1 - INPUT'!$B$36),'1 - INPUT'!$B$32,IF(A63=CHOOSE($C$21,'1 - INPUT'!$C$34,'1 - INPUT'!$C$35,'1 - INPUT'!$C$36),'1 - INPUT'!$B$33,$C$23))) | L63: =(C63-J63)*(1+K63)*'1 - INPUT'!$B$29 | M63: =(C63-J63)*(1+K63)-L63 | N63: =D63*(1-J63/C63)
A65: I DUE FATTORI DI LORDIZZAZIONE — misurati, non scelti
B66: Prelievi netti | C66: Vendite lorde | D66: Fattore | E66: Latente media ponderata
A67: Orizzonte intero (37 anni) | B67: =SUM(I27:I63) | C67: =SUM(J27:J63) | D67: =C67/B67 | E67: =(1-B67/C67)/'1 - INPUT'!B28
...

Sheet 3 - CRUSCOTTO
A1: 3 — IL CRUSCOTTO: il divario, quanto ne copre il lavoro, quanto resta
A2: Strumento informativo / divulgativo. NON è consulenza finanziaria. I valori sono indicativi al 2026 e vanno verificati col tuo consulente.
A4: IL CONTO DI FRANCO E GIULIA — banda obbligatoria 1/2/3%
A5: Grandezza | B5: r = 1% | C5: r = 2% | D5: r = 3%
A6: Portafoglio da solo, con l'indennità, senza lavoro | B6: 49280.72 | C6: 52927.25 | D6: 57008.59 | E6: È la baseline: quello che Franco ottiene se non fa niente. L'indennità c'è perché esce per risoluzione consensuale.
A7: IL DIVARIO (spesa meno portafoglio) | B7: ='1 - INPUT'!$B$6-B6 | C7: ='1 - INPUT'!$B$6-C6 | D7: ='1 - INPUT'!$B$6-D6
A8: Spesa massima con il part-time (porta B) | B8: 55264.38 | C8: 59453.62 | D8: 64089.31
A9: Il lavoro copre, in euro | B9: =B8-B6 | C9: =C8-C6 | D9: =D8-D6
A10: IL LAVORO COPRE, in % del divario | B10: =B9/B7 | C10: =C9/C7 | D10: =D9/D7 | E10: LA COPERTURA DIPENDE DAL RENDIMENTO PIÙ DI QUALUNQUE ALTRA COSA: è il numero più fragile del verdetto e non va mai detto da solo.
A11: Resta scoperto, in euro | B11: ='1 - INPUT'!$B$6-B8 | C11: ='1 - INPUT'!$B$6-C8 | D11: ='1 - INPUT'!$B$6-D8
A12: Resta scoperto, in % della spesa | B12: =B11/'1 - INPUT'!$B$6 | C12: =C11/'1 - INPUT'!$B$6 | D12: =D11/'1 - INPUT'!$B$6
A13: Porta A: 24 mesi di indennità, poi 11 anni di lavoro | B13: 55023.14 | C13: 59177.38 | D13: 63774.84
A14: Distanza fra le due porte | B14: =B8-B13 | C14: =C8-C13 | D14: =D8-D13 | E14: Le due porte QUASI SI PAREGGIANO: l'indennità è certa e arriva prima, il lavoro rende di più ma va trovato.
A15: Spesa massima senza lavoro e senza indennità | B15: 48433.03 | C15: 51954.64 | D15: 55899.13
A16: La pendenza: valore di 1.000 € di reddito per 13 anni | B16: =(B8-B15)/('1 - INPUT'!$B$16/1000) | C16: =(C8-C15)/('1 - INPUT'!$B$16/1000) | D16: =(D8-D15)/('1 - INPUT'!$B$16/1000) | E16: Misura il lavoro DA SOLO. Nel conto di Franco il part-time prende il posto dell'indennità, non si somma: per questo la copertura del divario è più bassa del prodotto.
A17: CAPITALE PER SMETTERE DEL TUTTO | B17: 1850185 | C17: 1636856 | D17: 1456878.5
A18: Capitale necessario con il part-time | B18: 1633534.1 | C18: 1431633.1 | D18: 1262368.7
A19: REDDITO NETTO NECESSARIO PER LA SPESA PIENA | B19: 56827.01 | C19: 43314.76 | D19: 30990.24 | E19: A venti euro l'ora sono più di duemila ore: quattro giorni e mezzo a settimana. La soglia di plausibilita' del reddito non è lineare, anche se il modello lo è.
A21: IL SEMAFORO
A22: Spesa scelta | B22: ='1 - INPUT'!B6
A23: Spesa massima col lavoro, al rendimento scelto | B23: =IF('1 - INPUT'!B27<=0.015,B8,IF('1 - INPUT'!B27<=0.025,C8,D8))
A24: ESITO | B24: =IF(B22<=B23,"REGGE","NON REGGE")
A25: Quanto manca | B25: =MAX(0,B22-B23) | E25: Con i default il semaforo è ROSSO: la spesa scelta è sopra quello che il piano regge. Non è un errore del piano: è il verdetto del video.
A27: I TRE TASSI DI PRELIEVO DELL'ANNO 1
B28: Prelievo netto | C28: Vendita lorda | D28: cassa | E28: omogeneo / col bollo
A29: Senza lavoro | B29: ='1 - INPUT'!B6 | C29: =B29/(1-'1 - INPUT'!B28*'1 - INPUT'!B30) | D29: =B29/'1 - INPUT'!B5
A30: Con il lavoro | B30: ='1 - INPUT'!B6-'1 - INPUT'!B16 | C30: =B30/(1-'1 - INPUT'!B28*'1 - INPUT'!B30) | D30: =B30/'1 - INPUT'!B5
A31: Tasso omogeneo — senza lavoro / con il lavoro | B31: =C29/'1 - INPUT'!B5 | C31: =C30/'1 - INPUT'!B5
A32: Tasso col bollo — senza lavoro / con il lavoro | B32: =(C29+'1 - INPUT'!B29*'1 - INPUT'!B5)/'1 - INPUT'!B5 | C32: =(C30+'1 - INPUT'!B29*'1 - INPUT'!B5)/'1 - INPUT'!B5 | E32: IL NUMERO DA CONFRONTARE CON IL QUATTRO PER CENTO DELLA REGOLA FAMOSA È QUELLO OMOGENEO, la vendita lorda: è l'unico misurato sulla stessa scala.
A34: SE IL LAVORO FINISCE PRIMA (r = 3%)
A35: Anni di lavoro | B35: 0 | C35: 1 | D35: 2 | E35: 3 | F35: 4 | G35: 5 | H35: 6 | I35: 7 | J35: 8 | K35: 9 | L35: 10 | M35: 11 | N35: 12 | O35: 13
A36: Spesa massima sostenibile | B36: 55899.13 | C36: 56619.09 | D36: 57323.05 | E36: 58011.3 | F36: 58684.11 | G36: 59341.76 | H36: 59984.52 | I36: 60612.65 | J36: 61226.43 | K36: 61826.12 | L36: 62412 | M36: 62984.31 | N36: 63543.33 | O36: 64089.31
A37: La curva è piatta: perdere tre anni di lavoro costa poco, perderli tutti costa circa ottomila euro l'anno di spesa. Il valore a ZERO anni è SENZA indennità: serve al confronto fra le due porte, non è la linea di partenza del divario.
A39: LA SCALA ONESTA DEL PRELIEVO (r = 3%, 13 anni di lavoro)
A40: Reddito netto dal lavoro | B40: Spesa massima | C40: Guadagno rispetto a zero | D40: Per 1.000 € di reddito
A41: 0 | B41: 55899.13 | C41: =B41-$B$41 | D41: =IF(A41=0,"—",C41/(A41/1000))
A42: 5000 | B42: 58174.18 | C42: =B42-$B$41 | D42: =IF(A42=0,"—",C42/(A42/1000))
A43: 15000 | B43: 62724.28 | C43: =B43-$B$41 | D43: =IF(A43=0,"—",C43/(A43/1000))
A44: 25000 | B44: 67274.38 | C44: =B44-$B$41 | D44: =IF(A44=0,"—",C44/(A44/1000))
A45: 35000 | B45: 71824.48 | C45: =B45-$B$41 | D45: =IF(A45=0,"—",C45/(A45/1000))
...

Sheet 4 - CAPITALE EQUIV
A1: 4 — QUANTO VALE DAVVERO UN REDDITO A TERMINE
A2: Strumento informativo / divulgativo. NON è consulenza finanziaria. I valori sono indicativi al 2026 e vanno verificati col tuo consulente.
A4: VALORE ATTUALE DI UNA RENDITA ANTICIPATA
A5: Reddito annuo netto | B5: ='1 - INPUT'!B16
A6: Durata (anni) | B6: r = 1% | C6: r = 2% | D6: r = 3% | E6: r = 4%
A7: 5 | B7: =$B$5*(1-(1+0.01)^-$A7)/0.01*(1+0.01) | C7: =$B$5*(1-(1+0.02)^-$A7)/0.02*(1+0.02) | D7: =$B$5*(1-(1+0.03)^-$A7)/0.03*(1+0.03) | E7: =$B$5*(1-(1+0.04)^-$A7)/0.04*(1+0.04)
A8: 10 | B8: =$B$5*(1-(1+0.01)^-$A8)/0.01*(1+0.01) | C8: =$B$5*(1-(1+0.02)^-$A8)/0.02*(1+0.02) | D8: =$B$5*(1-(1+0.03)^-$A8)/0.03*(1+0.03) | E8: =$B$5*(1-(1+0.04)^-$A8)/0.04*(1+0.04)
A9: 13 | B9: =$B$5*(1-(1+0.01)^-$A9)/0.01*(1+0.01) | C9: =$B$5*(1-(1+0.02)^-$A9)/0.02*(1+0.02) | D9: =$B$5*(1-(1+0.03)^-$A9)/0.03*(1+0.03) | E9: =$B$5*(1-(1+0.04)^-$A9)/0.04*(1+0.04)
A10: 20 | B10: =$B$5*(1-(1+0.01)^-$A10)/0.01*(1+0.01) | C10: =$B$5*(1-(1+0.02)^-$A10)/0.02*(1+0.02) | D10: =$B$5*(1-(1+0.03)^-$A10)/0.03*(1+0.03) | E10: =$B$5*(1-(1+0.04)^-$A10)/0.04*(1+0.04)
A11: 30 | B11: =$B$5*(1-(1+0.01)^-$A11)/0.01*(1+0.01) | C11: =$B$5*(1-(1+0.02)^-$A11)/0.02*(1+0.02) | D11: =$B$5*(1-(1+0.03)^-$A11)/0.03*(1+0.03) | E11: =$B$5*(1-(1+0.04)^-$A11)/0.04*(1+0.04)
A12: 37 | B12: =$B$5*(1-(1+0.01)^-$A12)/0.01*(1+0.01) | C12: =$B$5*(1-(1+0.02)^-$A12)/0.02*(1+0.02) | D12: =$B$5*(1-(1+0.03)^-$A12)/0.03*(1+0.03) | E12: =$B$5*(1-(1+0.04)^-$A12)/0.04*(1+0.04)
A13: PERPETUO (reddito / tasso) | B13: =$B$5/0.01 | C13: =$B$5/0.02 | D13: =$B$5/0.03 | E13: =$B$5/0.04
A14: Perpetuo / valore a 13 anni | B14: =B13/B9 | C14: =C13/C9 | D14: =D13/D9 | E14: =E13/E9 | F14: Il numero canonico del video: al 3% reale il perpetuo vale TRE VOLTE il valore vero di un lavoro che dura tredici anni. «Diecimila euro l'anno valgono trecentomila» è vero solo se durano per sempre.
A16: LO STESSO NUMERO AL LORDO DELL'IMPOSTA (Y7)
A17: Valore attuale NETTO, 13 anni al 3% | B17: =D9
A18: Fattore di lordizzazione della FINESTRA (13 anni) | B18: ='2 - SIMULAZIONE'!D68
A19: Valore attuale LORDIZZATO | B19: =B17*B18
A20: Capitale risparmiato, misurato dalla simulazione | B20: 224986.98
A21: SCARTO della formula chiusa | B21: =B19/B20-1
A22: Fattore sull'orizzonte intero (solo confronto) | B22: ='2 - SIMULAZIONE'!D67
A23: Cosa darebbe il fattore sbagliato | B23: =B17*B22 | F23: LO SCARTO SI DICHIARA, NON SI NASCONDE: sotto l'uno per cento, e la formula chiusa SOTTOSTIMA — è conservativa. Il fattore dell'orizzonte darebbe quasi novemila euro in più: è la differenza fra misurare la finestra giusta e quella comoda.
A25: E SE IL LAVORO DURASSE TUTTA LA VITA (Y3)
A26: Perpetuo netto (reddito / 3%) | B26: =D13
A27: Rendita a termine di 37 anni — il TRONCAMENTO | B27: =D12
A28: Effetto del troncamento | B28: =B27/B26-1
A29: Capitale risparmiato misurato dalla simulazione | B29: 494466.1
A30: Effetto delle IMPOSTE | B30: =B29/B27-1
A31: Effetto netto sul perpetuo | B31: =B29/B26-1
A32: PERPETUO / VALORE VERO | B32: =B26/B29 | F32: LE IMPOSTE ALZANO IL VALORE DEL LAVORO, non lo abbassano: un euro di lavoro arriva netto, un euro prelevato dal portafoglio va lordizzato. La causa del divario è il TRONCAMENTO — anche «tutta la vita» sono trentasette anni, non l'infinito.

Sheet 5 - LE TRE STRADE
A1: 5 — LE TRE STRADE: occasionale, dipendente, forfettario
A2: Strumento informativo / divulgativo. NON è consulenza finanziaria. I valori sono indicativi al 2026 e vanno verificati col tuo consulente.
A4: PARAMETRI DELLE TRE STRADE
A5: Contributi a carico del dipendente | B5: 0.0919
A6: Aliquota IVS gestione commercianti | B6: 0.2448
A7: Maternita' (quota fissa) | B7: 7.44 | D7: Paghi il 24,48% ma te ne accreditano il 24: lo 0,48% finanzia l'indennizzo per la cessazione dell'attività commerciale e non la pensione.
A8: Reddito minimale INPS | B8: 18808
A9: Riduzione contributiva richiesta | B9: 0.35 | D9: La riduzione del 35% si applica alla sola quota IVS, non alla maternita': 4.604,20 x 0,65 + 7,44 = 3.000,17.
A10: Aliquota del forfettario | B10: 0.15
A11: Gestione Separata — professionisti | B11: 0.2607
A12: Gestione Separata — occasionali | B12: 0.3372
A13: Addizionali locali | B13: 0.02
A14: Aliquota di computo — commercianti | B14: 0.24
A15: Aliquota di computo — dipendenti | B15: 0.33
A18: A PARITÀ DI COMPENSO LORDO CONTRATTUALE
A19: Compenso lordo | B19: DIP contributi | C19: DIP imponibile | D19: DIP IRPEF lorda | E19: DIP detrazioni | F19: DIP IRPEF netta | G19: DIP bonus | H19: DIP addizionali | I19: DIPENDENTE netto | J19: FORF forfettizzato | K19: FORF contributi | L19: FORF imponibile | M19: FORF imposta | N19: FORF costi reali | O19: FORFETTARIO netto | P19: Differenza
A20: 5000 | B20: =A20*$B$5 | C20: =A20-B20 | D20: =(MIN(C20,28000)*0.23+MAX(0,MIN(C20,50000)-28000)*0.33+MAX(0,C20-50000)*0.43) | E20: =IF(C20<=15000,1955,IF(C20<=28000,1910+1190*(28000-C20)/13000,IF(C20<=50000,1910*(50000-C20)/22000,0)))+IF(C20<=20000,0,IF(C20<=32000,1000,IF(C20<=40000,1000*(40000-C20)/8000,0))) | F20: =MAX(0,D20-E20) | G20: =IF(AND(C20<=15000,(MIN(C20,28000)*0.23+MAX(0,MIN(C20,50000)-28000)*0.33+MAX(0,C20-50000)*0.43)>IF(C20<=15000,1955,IF(C20<=28000,1910+1190*(28000-C20)/13000,IF(C20<=50000,1910*(50000-C20)/22000,0)))),1200,0)+IF(C20<=8500,0.071*C20,IF(C20<=15000,0.053*C20,IF(C20<=20000,0.048*C20,0))) | H20: =IF(F20>0,C20*$B$13,0) | I20: =C20-F20+G20-H20 | J20: =A20*'1 - INPUT'!$B$19 | K20: =$B$8*$B$6*(1-$B$9)+$B$7+MAX(0,J20-$B$8)*$B$6*(1-$B$9) | L20: =MAX(0,J20-K20) | M20: =L20*$B$10 | N20: =A20*'1 - INPUT'!$B$20 | O20: =A20-N20-K20-M20 | P20: =I20-O20
A21: 10000 | B21: =A21*$B$5 | C21: =A21-B21 | D21: =(MIN(C21,28000)*0.23+MAX(0,MIN(C21,50000)-28000)*0.33+MAX(0,C21-50000)*0.43) | E21: =IF(C21<=15000,1955,IF(C21<=28000,1910+1190*(28000-C21)/13000,IF(C21<=50000,1910*(50000-C21)/22000,0)))+IF(C21<=20000,0,IF(C21<=32000,1000,IF(C21<=40000,1000*(40000-C21)/8000,0))) | F21: =MAX(0,D21-E21) | G21: =IF(AND(C21<=15000,(MIN(C21,28000)*0.23+MAX(0,MIN(C21,50000)-28000)*0.33+MAX(0,C21-50000)*0.43)>IF(C21<=15000,1955,IF(C21<=28000,1910+1190*(28000-C21)/13000,IF(C21<=50000,1910*(50000-C21)/22000,0)))),1200,0)+IF(C21<=8500,0.071*C21,IF(C21<=15000,0.053*C21,IF(C21<=20000,0.048*C21,0))) | H21: =IF(F21>0,C21*$B$13,0) | I21: =C21-F21+G21-H21 | J21: =A21*'1 - INPUT'!$B$19 | K21: =$B$8*$B$6*(1-$B$9)+$B$7+MAX(0,J21-$B$8)*$B$6*(1-$B$9) | L21: =MAX(0,J21-K21) | M21: =L21*$B$10 | N21: =A21*'1 - INPUT'!$B$20 | O21: =A21-N21-K21-M21 | P21: =I21-O21
A22: 12000 | B22: =A22*$B$5 | C22: =A22-B22 | D22: =(MIN(C22,28000)*0.23+MAX(0,MIN(C22,50000)-28000)*0.33+MAX(0,C22-50000)*0.43) | E22: =IF(C22<=15000,1955,IF(C22<=28000,1910+1190*(28000-C22)/13000,IF(C22<=50000,1910*(50000-C22)/22000,0)))+IF(C22<=20000,0,IF(C22<=32000,1000,IF(C22<=40000,1000*(40000-C22)/8000,0))) | F22: =MAX(0,D22-E22) | G22: =IF(AND(C22<=15000,(MIN(C22,28000)*0.23+MAX(0,MIN(C22,50000)-28000)*0.33+MAX(0,C22-50000)*0.43)>IF(C22<=15000,1955,IF(C22<=28000,1910+1190*(28000-C22)/13000,IF(C22<=50000,1910*(50000-C22)/22000,0)))),1200,0)+IF(C22<=8500,0.071*C22,IF(C22<=15000,0.053*C22,IF(C22<=20000,0.048*C22,0))) | H22: =IF(F22>0,C22*$B$13,0) | I22: =C22-F22+G22-H22 | J22: =A22*'1 - INPUT'!$B$19 | K22: =$B$8*$B$6*(1-$B$9)+$B$7+MAX(0,J22-$B$8)*$B$6*(1-$B$9) | L22: =MAX(0,J22-K22) | M22: =L22*$B$10 | N22: =A22*'1 - INPUT'!$B$20 | O22: =A22-N22-K22-M22 | P22: =I22-O22
A23: 15000 | B23: =A23*$B$5 | C23: =A23-B23 | D23: =(MIN(C23,28000)*0.23+MAX(0,MIN(C23,50000)-28000)*0.33+MAX(0,C23-50000)*0.43) | E23: =IF(C23<=15000,1955,IF(C23<=28000,1910+1190*(28000-C23)/13000,IF(C23<=50000,1910*(50000-C23)/22000,0)))+IF(C23<=20000,0,IF(C23<=32000,1000,IF(C23<=40000,1000*(40000-C23)/8000,0))) | F23: =MAX(0,D23-E23) | G23: =IF(AND(C23<=15000,(MIN(C23,28000)*0.23+MAX(0,MIN(C23,50000)-28000)*0.33+MAX(0,C23-50000)*0.43)>IF(C23<=15000,1955,IF(C23<=28000,1910+1190*(28000-C23)/13000,IF(C23<=50000,1910*(50000-C23)/22000,0)))),1200,0)+IF(C23<=8500,0.071*C23,IF(C23<=15000,0.053*C23,IF(C23<=20000,0.048*C23,0))) | H23: =IF(F23>0,C23*$B$13,0) | I23: =C23-F23+G23-H23 | J23: =A23*'1 - INPUT'!$B$19 | K23: =$B$8*$B$6*(1-$B$9)+$B$7+MAX(0,J23-$B$8)*$B$6*(1-$B$9) | L23: =MAX(0,J23-K23) | M23: =L23*$B$10 | N23: =A23*'1 - INPUT'!$B$20 | O23: =A23-N23-K23-M23 | P23: =I23-O23
A24: 20000 | B24: =A24*$B$5 | C24: =A24-B24 | D24: =(MIN(C24,28000)*0.23+MAX(0,MIN(C24,50000)-28000)*0.33+MAX(0,C24-50000)*0.43) | E24: =IF(C24<=15000,1955,IF(C24<=28000,1910+1190*(28000-C24)/13000,IF(C24<=50000,1910*(50000-C24)/22000,0)))+IF(C24<=20000,0,IF(C24<=32000,1000,IF(C24<=40000,1000*(40000-C24)/8000,0))) | F24: =MAX(0,D24-E24) | G24: =IF(AND(C24<=15000,(MIN(C24,28000)*0.23+MAX(0,MIN(C24,50000)-28000)*0.33+MAX(0,C24-50000)*0.43)>IF(C24<=15000,1955,IF(C24<=28000,1910+1190*(28000-C24)/13000,IF(C24<=50000,1910*(50000-C24)/22000,0)))),1200,0)+IF(C24<=8500,0.071*C24,IF(C24<=15000,0.053*C24,IF(C24<=20000,0.048*C24,0))) | H24: =IF(F24>0,C24*$B$13,0) | I24: =C24-F24+G24-H24 | J24: =A24*'1 - INPUT'!$B$19 | K24: =$B$8*$B$6*(1-$B$9)+$B$7+MAX(0,J24-$B$8)*$B$6*(1-$B$9) | L24: =MAX(0,J24-K24) | M24: =L24*$B$10 | N24: =A24*'1 - INPUT'!$B$20 | O24: =A24-N24-K24-M24 | P24: =I24-O24
A25: 25000 | B25: =A25*$B$5 | C25: =A25-B25 | D25: =(MIN(C25,28000)*0.23+MAX(0,MIN(C25,50000)-28000)*0.33+MAX(0,C25-50000)*0.43) | E25: =IF(C25<=15000,1955,IF(C25<=28000,1910+1190*(28000-C25)/13000,IF(C25<=50000,1910*(50000-C25)/22000,0)))+IF(C25<=20000,0,IF(C25<=32000,1000,IF(C25<=40000,1000*(40000-C25)/8000,0))) | F25: =MAX(0,D25-E25) | G25: =IF(AND(C25<=15000,(MIN(C25,28000)*0.23+MAX(0,MIN(C25,50000)-28000)*0.33+MAX(0,C25-50000)*0.43)>IF(C25<=15000,1955,IF(C25<=28000,1910+1190*(28000-C25)/13000,IF(C25<=50000,1910*(50000-C25)/22000,0)))),1200,0)+IF(C25<=8500,0.071*C25,IF(C25<=15000,0.053*C25,IF(C25<=20000,0.048*C25,0))) | H25: =IF(F25>0,C25*$B$13,0) | I25: =C25-F25+G25-H25 | J25: =A25*'1 - INPUT'!$B$19 | K25: =$B$8*$B$6*(1-$B$9)+$B$7+MAX(0,J25-$B$8)*$B$6*(1-$B$9) | L25: =MAX(0,J25-K25) | M25: =L25*$B$10 | N25: =A25*'1 - INPUT'!$B$20 | O25: =A25-N25-K25-M25 | P25: =I25-O25
A26: 30000 | B26: =A26*$B$5 | C26: =A26-B26 | D26: =(MIN(C26,28000)*0.23+MAX(0,MIN(C26,50000)-28000)*0.33+MAX(0,C26-50000)*0.43) | E26: =IF(C26<=15000,1955,IF(C26<=28000,1910+1190*(28000-C26)/13000,IF(C26<=50000,1910*(50000-C26)/22000,0)))+IF(C26<=20000,0,IF(C26<=32000,1000,IF(C26<=40000,1000*(40000-C26)/8000,0))) | F26: =MAX(0,D26-E26) | G26: =IF(AND(C26<=15000,(MIN(C26,28000)*0.23+MAX(0,MIN(C26,50000)-28000)*0.33+MAX(0,C26-50000)*0.43)>IF(C26<=15000,1955,IF(C26<=28000,1910+1190*(28000-C26)/13000,IF(C26<=50000,1910*(50000-C26)/22000,0)))),1200,0)+IF(C26<=8500,0.071*C26,IF(C26<=15000,0.053*C26,IF(C26<=20000,0.048*C26,0))) | H26: =IF(F26>0,C26*$B$13,0) | I26: =C26-F26+G26-H26 | J26: =A26*'1 - INPUT'!$B$19 | K26: =$B$8*$B$6*(1-$B$9)+$B$7+MAX(0,J26-$B$8)*$B$6*(1-$B$9) | L26: =MAX(0,J26-K26) | M26: =L26*$B$10 | N26: =A26*'1 - INPUT'!$B$20 | O26: =A26-N26-K26-M26 | P26: =I26-O26
A27: 39062.62 | B27: =A27*$B$5 | C27: =A27-B27 | D27: =(MIN(C27,28000)*0.23+MAX(0,MIN(C27,50000)-28000)*0.33+MAX(0,C27-50000)*0.43) | E27: =IF(C27<=15000,1955,IF(C27<=28000,1910+1190*(28000-C27)/13000,IF(C27<=50000,1910*(50000-C27)/22000,0)))+IF(C27<=20000,0,IF(C27<=32000,1000,IF(C27<=40000,1000*(40000-C27)/8000,0))) | F27: =MAX(0,D27-E27) | G27: =IF(AND(C27<=15000,(MIN(C27,28000)*0.23+MAX(0,MIN(C27,50000)-28000)*0.33+MAX(0,C27-50000)*0.43)>IF(C27<=15000,1955,IF(C27<=28000,1910+1190*(28000-C27)/13000,IF(C27<=50000,1910*(50000-C27)/22000,0)))),1200,0)+IF(C27<=8500,0.071*C27,IF(C27<=15000,0.053*C27,IF(C27<=20000,0.048*C27,0))) | H27: =IF(F27>0,C27*$B$13,0) | I27: =C27-F27+G27-H27 | J27: =A27*'1 - INPUT'!$B$19 | K27: =$B$8*$B$6*(1-$B$9)+$B$7+MAX(0,J27-$B$8)*$B$6*(1-$B$9) | L27: =MAX(0,J27-K27) | M27: =L27*$B$10 | N27: =A27*'1 - INPUT'!$B$20 | O27: =A27-N27-K27-M27 | P27: =I27-O27
A28: 45000 | B28: =A28*$B$5 | C28: =A28-B28 | D28: =(MIN(C28,28000)*0.23+MAX(0,MIN(C28,50000)-28000)*0.33+MAX(0,C28-50000)*0.43) | E28: =IF(C28<=15000,1955,IF(C28<=28000,1910+1190*(28000-C28)/13000,IF(C28<=50000,1910*(50000-C28)/22000,0)))+IF(C28<=20000,0,IF(C28<=32000,1000,IF(C28<=40000,1000*(40000-C28)/8000,0))) | F28: =MAX(0,D28-E28) | G28: =IF(AND(C28<=15000,(MIN(C28,28000)*0.23+MAX(0,MIN(C28,50000)-28000)*0.33+MAX(0,C28-50000)*0.43)>IF(C28<=15000,1955,IF(C28<=28000,1910+1190*(28000-C28)/13000,IF(C28<=50000,1910*(50000-C28)/22000,0)))),1200,0)+IF(C28<=8500,0.071*C28,IF(C28<=15000,0.053*C28,IF(C28<=20000,0.048*C28,0))) | H28: =IF(F28>0,C28*$B$13,0) | I28: =C28-F28+G28-H28 | J28: =A28*'1 - INPUT'!$B$19 | K28: =$B$8*$B$6*(1-$B$9)+$B$7+MAX(0,J28-$B$8)*$B$6*(1-$B$9) | L28: =MAX(0,J28-K28) | M28: =L28*$B$10 | N28: =A28*'1 - INPUT'!$B$20 | O28: =A28-N28-K28-M28 | P28: =I28-O28
A29: PAREGGIO a parità di lordo, costi reali 10% | B29: 39062.62
A30: PAREGGIO a parità di lordo, costi ZERO | B30: 26606.51 | D30: «Ecco quanto pesano i costi»: dodicimila euro di soglia in più fra la riga a costi zero e quella con i costi veri.
A32: A PARITÀ DI COSTO PER CHI PAGA
A33: Costo per chi paga | B33: RAL equivalente | C33: DIP contributi | D33: DIP imponibile | E33: DIP IRPEF netta | F33: DIP bonus | G33: DIP addizionali | H33: DIPENDENTE netto | I33: FORF contributi | J33: FORF imposta | K33: FORF costi reali | L33: FORFETTARIO netto | M33: Vince
A34: 8000 | B34: =A34/'1 - INPUT'!$B$21 | C34: =B34*$B$5 | D34: =B34-C34 | E34: =MAX(0,(MIN(D34,28000)*0.23+MAX(0,MIN(D34,50000)-28000)*0.33+MAX(0,D34-50000)*0.43)-IF(D34<=15000,1955,IF(D34<=28000,1910+1190*(28000-D34)/13000,IF(D34<=50000,1910*(50000-D34)/22000,0)))-IF(D34<=20000,0,IF(D34<=32000,1000,IF(D34<=40000,1000*(40000-D34)/8000,0)))) | F34: =IF(AND(D34<=15000,(MIN(D34,28000)*0.23+MAX(0,MIN(D34,50000)-28000)*0.33+MAX(0,D34-50000)*0.43)>IF(D34<=15000,1955,IF(D34<=28000,1910+1190*(28000-D34)/13000,IF(D34<=50000,1910*(50000-D34)/22000,0)))),1200,0)+IF(D34<=8500,0.071*D34,IF(D34<=15000,0.053*D34,IF(D34<=20000,0.048*D34,0))) | G34: =IF(E34>0,D34*$B$13,0) | H34: =D34-E34+F34-G34 | I34: =$B$8*$B$6*(1-$B$9)+$B$7+MAX(0,A34*'1 - INPUT'!$B$19-$B$8)*$B$6*(1-$B$9) | J34: =MAX(0,A34*'1 - INPUT'!$B$19-I34)*$B$10 | K34: =A34*'1 - INPUT'!$B$20 | L34: =A34-K34-I34-J34 | M34: =IF(H34>=L34,"dipendente","forfettario")
A35: 12000 | B35: =A35/'1 - INPUT'!$B$21 | C35: =B35*$B$5 | D35: =B35-C35 | E35: =MAX(0,(MIN(D35,28000)*0.23+MAX(0,MIN(D35,50000)-28000)*0.33+MAX(0,D35-50000)*0.43)-IF(D35<=15000,1955,IF(D35<=28000,1910+1190*(28000-D35)/13000,IF(D35<=50000,1910*(50000-D35)/22000,0)))-IF(D35<=20000,0,IF(D35<=32000,1000,IF(D35<=40000,1000*(40000-D35)/8000,0)))) | F35: =IF(AND(D35<=15000,(MIN(D35,28000)*0.23+MAX(0,MIN(D35,50000)-28000)*0.33+MAX(0,D35-50000)*0.43)>IF(D35<=15000,1955,IF(D35<=28000,1910+1190*(28000-D35)/13000,IF(D35<=50000,1910*(50000-D35)/22000,0)))),1200,0)+IF(D35<=8500,0.071*D35,IF(D35<=15000,0.053*D35,IF(D35<=20000,0.048*D35,0))) | G35: =IF(E35>0,D35*$B$13,0) | H35: =D35-E35+F35-G35 | I35: =$B$8*$B$6*(1-$B$9)+$B$7+MAX(0,A35*'1 - INPUT'!$B$19-$B$8)*$B$6*(1-$B$9) | J35: =MAX(0,A35*'1 - INPUT'!$B$19-I35)*$B$10 | K35: =A35*'1 - INPUT'!$B$20 | L35: =A35-K35-I35-J35 | M35: =IF(H35>=L35,"dipendente","forfettario")
A36: 15000 | B36: =A36/'1 - INPUT'!$B$21 | C36: =B36*$B$5 | D36: =B36-C36 | E36: =MAX(0,(MIN(D36,28000)*0.23+MAX(0,MIN(D36,50000)-28000)*0.33+MAX(0,D36-50000)*0.43)-IF(D36<=15000,1955,IF(D36<=28000,1910+1190*(28000-D36)/13000,IF(D36<=50000,1910*(50000-D36)/22000,0)))-IF(D36<=20000,0,IF(D36<=32000,1000,IF(D36<=40000,1000*(40000-D36)/8000,0)))) | F36: =IF(AND(D36<=15000,(MIN(D36,28000)*0.23+MAX(0,MIN(D36,50000)-28000)*0.33+MAX(0,D36-50000)*0.43)>IF(D36<=15000,1955,IF(D36<=28000,1910+1190*(28000-D36)/13000,IF(D36<=50000,1910*(50000-D36)/22000,0)))),1200,0)+IF(D36<=8500,0.071*D36,IF(D36<=15000,0.053*D36,IF(D36<=20000,0.048*D36,0))) | G36: =IF(E36>0,D36*$B$13,0) | H36: =D36-E36+F36-G36 | I36: =$B$8*$B$6*(1-$B$9)+$B$7+MAX(0,A36*'1 - INPUT'!$B$19-$B$8)*$B$6*(1-$B$9) | J36: =MAX(0,A36*'1 - INPUT'!$B$19-I36)*$B$10 | K36: =A36*'1 - INPUT'!$B$20 | L36: =A36-K36-I36-J36 | M36: =IF(H36>=L36,"dipendente","forfettario")
A37: 20000 | B37: =A37/'1 - INPUT'!$B$21 | C37: =B37*$B$5 | D37: =B37-C37 | E37: =MAX(0,(MIN(D37,28000)*0.23+MAX(0,MIN(D37,50000)-28000)*0.33+MAX(0,D37-50000)*0.43)-IF(D37<=15000,1955,IF(D37<=28000,1910+1190*(28000-D37)/13000,IF(D37<=50000,1910*(50000-D37)/22000,0)))-IF(D37<=20000,0,IF(D37<=32000,1000,IF(D37<=40000,1000*(40000-D37)/8000,0)))) | F37: =IF(AND(D37<=15000,(MIN(D37,28000)*0.23+MAX(0,MIN(D37,50000)-28000)*0.33+MAX(0,D37-50000)*0.43)>IF(D37<=15000,1955,IF(D37<=28000,1910+1190*(28000-D37)/13000,IF(D37<=50000,1910*(50000-D37)/22000,0)))),1200,0)+IF(D37<=8500,0.071*D37,IF(D37<=15000,0.053*D37,IF(D37<=20000,0.048*D37,0))) | G37: =IF(E37>0,D37*$B$13,0) | H37: =D37-E37+F37-G37 | I37: =$B$8*$B$6*(1-$B$9)+$B$7+MAX(0,A37*'1 - INPUT'!$B$19-$B$8)*$B$6*(1-$B$9) | J37: =MAX(0,A37*'1 - INPUT'!$B$19-I37)*$B$10 | K37: =A37*'1 - INPUT'!$B$20 | L37: =A37-K37-I37-J37 | M37: =IF(H37>=L37,"dipendente","forfettario")
A38: 22134.13 | B38: =A38/'1 - INPUT'!$B$21 | C38: =B38*$B$5 | D38: =B38-C38 | E38: =MAX(0,(MIN(D38,28000)*0.23+MAX(0,MIN(D38,50000)-28000)*0.33+MAX(0,D38-50000)*0.43)-IF(D38<=15000,1955,IF(D38<=28000,1910+1190*(28000-D38)/13000,IF(D38<=50000,1910*(50000-D38)/22000,0)))-IF(D38<=20000,0,IF(D38<=32000,1000,IF(D38<=40000,1000*(40000-D38)/8000,0)))) | F38: =IF(AND(D38<=15000,(MIN(D38,28000)*0.23+MAX(0,MIN(D38,50000)-28000)*0.33+MAX(0,D38-50000)*0.43)>IF(D38<=15000,1955,IF(D38<=28000,1910+1190*(28000-D38)/13000,IF(D38<=50000,1910*(50000-D38)/22000,0)))),1200,0)+IF(D38<=8500,0.071*D38,IF(D38<=15000,0.053*D38,IF(D38<=20000,0.048*D38,0))) | G38: =IF(E38>0,D38*$B$13,0) | H38: =D38-E38+F38-G38 | I38: =$B$8*$B$6*(1-$B$9)+$B$7+MAX(0,A38*'1 - INPUT'!$B$19-$B$8)*$B$6*(1-$B$9) | J38: =MAX(0,A38*'1 - INPUT'!$B$19-I38)*$B$10 | K38: =A38*'1 - INPUT'!$B$20 | L38: =A38-K38-I38-J38 | M38: =IF(H38>=L38,"dipendente","forfettario")
A39: 27000 | B39: =A39/'1 - INPUT'!$B$21 | C39: =B39*$B$5 | D39: =B39-C39 | E39: =MAX(0,(MIN(D39,28000)*0.23+MAX(0,MIN(D39,50000)-28000)*0.33+MAX(0,D39-50000)*0.43)-IF(D39<=15000,1955,IF(D39<=28000,1910+1190*(28000-D39)/13000,IF(D39<=50000,1910*(50000-D39)/22000,0)))-IF(D39<=20000,0,IF(D39<=32000,1000,IF(D39<=40000,1000*(40000-D39)/8000,0)))) | F39: =IF(AND(D39<=15000,(MIN(D39,28000)*0.23+MAX(0,MIN(D39,50000)-28000)*0.33+MAX(0,D39-50000)*0.43)>IF(D39<=15000,1955,IF(D39<=28000,1910+1190*(28000-D39)/13000,IF(D39<=50000,1910*(50000-D39)/22000,0)))),1200,0)+IF(D39<=8500,0.071*D39,IF(D39<=15000,0.053*D39,IF(D39<=20000,0.048*D39,0))) | G39: =IF(E39>0,D39*$B$13,0) | H39: =D39-E39+F39-G39 | I39: =$B$8*$B$6*(1-$B$9)+$B$7+MAX(0,A39*'1 - INPUT'!$B$19-$B$8)*$B$6*(1-$B$9) | J39: =MAX(0,A39*'1 - INPUT'!$B$19-I39)*$B$10 | K39: =A39*'1 - INPUT'!$B$20 | L39: =A39-K39-I39-J39 | M39: =IF(H39>=L39,"dipendente","forfettario")
A40: 35000 | B40: =A40/'1 - INPUT'!$B$21 | C40: =B40*$B$5 | D40: =B40-C40 | E40: =MAX(0,(MIN(D40,28000)*0.23+MAX(0,MIN(D40,50000)-28000)*0.33+MAX(0,D40-50000)*0.43)-IF(D40<=15000,1955,IF(D40<=28000,1910+1190*(28000-D40)/13000,IF(D40<=50000,1910*(50000-D40)/22000,0)))-IF(D40<=20000,0,IF(D40<=32000,1000,IF(D40<=40000,1000*(40000-D40)/8000,0)))) | F40: =IF(AND(D40<=15000,(MIN(D40,28000)*0.23+MAX(0,MIN(D40,50000)-28000)*0.33+MAX(0,D40-50000)*0.43)>IF(D40<=15000,1955,IF(D40<=28000,1910+1190*(28000-D40)/13000,IF(D40<=50000,1910*(50000-D40)/22000,0)))),1200,0)+IF(D40<=8500,0.071*D40,IF(D40<=15000,0.053*D40,IF(D40<=20000,0.048*D40,0))) | G40: =IF(E40>0,D40*$B$13,0) | H40: =D40-E40+F40-G40 | I40: =$B$8*$B$6*(1-$B$9)+$B$7+MAX(0,A40*'1 - INPUT'!$B$19-$B$8)*$B$6*(1-$B$9) | J40: =MAX(0,A40*'1 - INPUT'!$B$19-I40)*$B$10 | K40: =A40*'1 - INPUT'!$B$20 | L40: =A40-K40-I40-J40 | M40: =IF(H40>=L40,"dipendente","forfettario")
A41: PAREGGIO a parità di costo, costi reali 10% | B41: 22134.13
A42: PAREGGIO a parità di costo, costi ZERO | B42: 16056.46
A43: Banda del fattore: 1,30 / 1,38 | B43: 22950.99 | C43: 21045.12 | E43: A PARITÀ DI QUELLO CHE TI OFFRONO VINCE IL DIPENDENTE; A PARITÀ DI QUELLO CHE COSTI VINCE LA PARTITA IVA. La domanda vera è quale delle due cifre stai negoziando. Il pareggio a parità di costo cade dove il trattamento integrativo e la somma sul cuneo si spengono: è un gradino, non una curva liscia.
A45: IL COEFFICIENTE DECIDE TUTTO, E I COSTI REALI PURE
...

Sheet 6 - PONTE E PENSIONE
A1: 6 — IL PONTE E LA PENSIONE: 2026 → 2039 → 2062
A2: Strumento informativo / divulgativo. NON è consulenza finanziaria. I valori sono indicativi al 2026 e vanno verificati col tuo consulente.
A4: LE DUE PENSIONI — matrice stop-55, BLOCCATA
B5: Lorda mensile | C5: Netta mensile | D5: Fattore di nettizz.
A6: Franco — carriera 35.000, densita' 100%, inizio a 25 anni | B6: 1720 | C6: 1372 | D6: =C6/B6
A7: Giulia — carriera 20.000, densita' 100%, inizio a 25 anni | B7: 983 | C7: 866
A8: COPPIA, mensile | B8: =B6+B7 | C8: =C6+C7
A9: COPPIA, annua (13 mensilità) | C9: =C8*13
A10: Copertura della spesa | C10: =C9/'1 - INPUT'!B6
A11: Coefficiente di trasformazione (68 anni e 2 mesi, interpolato) | B11: 0.05844 | F11: Il 68 anni e 2 mesi e il 2039 sono una PROIEZIONE della Ragioneria Generale dello Stato (Nota di aggiornamento dicembre 2025), NON una norma: da dichiarare ogni volta che si nominano.
A12: Tasso di capitalizzazione del montante | B12: 0.006
A13: Fattore di montante su 13 anni | B13: =((1+B12)^'1 - INPUT'!B17-1)/B12
A15: LA PENSIONE CHE IL PART-TIME AGGIUNGE (convenzione NETTA)
A16: Inquadramento | B16: Di tasca tua, lordo | C16: Di tasca tua, NETTO | D16: Montante annuo | E16: Pensione lorda in più | F16: Pensione netta in più / per euro proprio
A17: Forfettario, riduzione 35% | B17: ='5 - LE TRE STRADE'!$B$8*'5 - LE TRE STRADE'!$B$6*(1-'5 - LE TRE STRADE'!$B$9) | C17: =B17*0.85 | D17: ='5 - LE TRE STRADE'!$B$8*'5 - LE TRE STRADE'!$B$14*(1-'5 - LE TRE STRADE'!$B$9) | E17: =D17*$B$13*$B$11 | F17: =E17*$D$6/C17
A18: Forfettario pieno (commercianti) | B18: ='5 - LE TRE STRADE'!$B$8*'5 - LE TRE STRADE'!$B$6 | C18: =B18*0.85 | D18: ='5 - LE TRE STRADE'!$B$8*'5 - LE TRE STRADE'!$B$14 | E18: =D18*$B$13*$B$11 | F18: =E18*$D$6/C18
A19: Dipendente, 15.000 € lordi | B19: =15000*'5 - LE TRE STRADE'!$B$5 | C19: =B19*0.75 | D19: =15000*'5 - LE TRE STRADE'!$B$15 | E19: =D19*$B$13*$B$11 | F19: =E19*$D$6/C19
A20: MOLTIPLICATORE: dipendente / forfettario ridotto | B20: =F19/F17 | F20: Circa QUATTRO VOLTE, per euro di tasca propria. La convenzione è unica e NETTA: costo netto (i contributi si deducono) contro beneficio netto (la pensione è tassata), col fattore di nettizzazione della cella D6.
A21: Pensione lorda in più, al mese (13 mensilità) | B21: =E17/13 | C21: =E18/13 | D21: =E19/13
A23: QUANTO COSTA LA RIDUZIONE DEL 35%
A24: Costo lordo annuo (contributi in meno) | B24: ='5 - LE TRE STRADE'!$B$8*'5 - LE TRE STRADE'!$B$6*'5 - LE TRE STRADE'!$B$9
A25: Costo NETTO annuo (deducibili al 15%) | B25: =B24*0.85
A26: Montante annuo in meno | B26: ='5 - LE TRE STRADE'!$B$8*'5 - LE TRE STRADE'!$B$14*'5 - LE TRE STRADE'!$B$9
A27: Beneficio LORDO annuo (pensione in meno) | B27: =B26*$B$13*$B$11
A28: Beneficio NETTO annuo | B28: =B27*$D$6
A29: Anni di erogazione della pensione | B29: ='1 - INPUT'!B10-'1 - INPUT'!B11
A30: Valori attuali | C30: r = 1% | D30: r = 2% | E30: r = 3%
A31: Valore attuale del COSTO (13 anni) | C31: =$B$25*(1-(1+0.01)^-'1 - INPUT'!$B$17)/0.01*(1+0.01) | D31: =$B$25*(1-(1+0.02)^-'1 - INPUT'!$B$17)/0.02*(1+0.02) | E31: =$B$25*(1-(1+0.03)^-'1 - INPUT'!$B$17)/0.03*(1+0.03)
A32: Valore attuale del BENEFICIO LORDO | C32: =$B$27*(1-(1+0.01)^-$B$29)/0.01*(1+0.01)/(1+0.01)^'1 - INPUT'!$B$11 | D32: =$B$27*(1-(1+0.02)^-$B$29)/0.02*(1+0.02)/(1+0.02)^'1 - INPUT'!$B$11 | E32: =$B$27*(1-(1+0.03)^-$B$29)/0.03*(1+0.03)/(1+0.03)^'1 - INPUT'!$B$11
A33: Rapporto costo / beneficio LORDO | C33: =C31/C32 | D33: =D31/D32 | E33: =E31/E32
A34: Valore attuale del BENEFICIO NETTO | C34: =C32*$D$6 | D34: =D32*$D$6 | E34: =E32*$D$6
A35: RAPPORTO COSTO / BENEFICIO NETTO | C35: =C31/C34 | D35: =D31/D34 | E35: =E31/E34 | F35: Il SEGNO DEL VERDETTO DIPENDE DALLA CONVENZIONE: al 3% conviene tenere lo sconto, all'1% conviene rinunciarci. Per questo si pubblicano tutte e due le righe, non solo quella comoda.
A37: IL PONTE, ANNO PER ANNO
A38: Fase | B38: Dal | C38: Al | D38: Anni | E38: Risorse
A39: indennità (solo nella porta A) | B39: ='1 - INPUT'!B9 | C39: ='1 - INPUT'!B9+1 | D39: =2 | E39: NASpI 24 mesi
A40: Ponte: portafoglio (più il lavoro leggero) | B40: ='1 - INPUT'!B9 | C40: ='1 - INPUT'!B12-1 | D40: ='1 - INPUT'!B11 | E40: portafoglio + part-time
A41: Dalle pensioni in poi | B41: ='1 - INPUT'!B12 | C41: ='1 - INPUT'!B9+'1 - INPUT'!B10-1 | D41: ='1 - INPUT'!B10-'1 - INPUT'!B11 | E41: portafoglio + pensioni di coppia
A42: Prelievo netto dal portafoglio, con il lavoro, fino al 2039 | B42: ='1 - INPUT'!B6-'1 - INPUT'!B16
A43: Prelievo netto dal portafoglio, dal 2039 | B43: ='1 - INPUT'!B6-'1 - INPUT'!B13
A44: È IL PIANO COM'È OGGI, non una previsione: le due fasi si leggono sulla riga del fabbisogno del foglio 2. Nel piano NON esistono rendite: cedole e dividendi non sono una terza fonte, sono già dentro il rendimento del portafoglio.

Sheet 7 - SEQUENZA
A1: 7 — L'ORDINE DEI RENDIMENTI: quattro sequenze, stessa media
A2: Strumento informativo / divulgativo. NON è consulenza finanziaria. I valori sono indicativi al 2026 e vanno verificati col tuo consulente.
A4: ILLUSTRATIVO, NON PROBABILISTICO. I quattro ordini hanno lo STESSO rendimento medio geometrico: due crolli (-35% e -20%) e trentacinque anni calibrati perché la media torni. Cambia le posizioni dei crolli nel foglio 1 e ricalcola col motore del foglio 2.
A6: RENDIMENTO REALE MEDIO 1%
B7: costante | C7: crolli all'INIZIO | D7: crolli a METÀ | E7: crolli alla FINE
A8: Capitale necessario SENZA lavoro | B8: 1880877.7 | C8: 2617888.8 | D8: 1845887.3 | E8: 1503248.7
A9: Capitale necessario CON il part-time | B9: 1633534.1 | C9: 2235105.3 | D9: 1620515.6 | E9: 1277877
A10: Capitale risparmiato dal lavoro | B10: =B8-B9 | C10: =C8-C9 | D10: =D8-D9 | E10: =E8-E9
A11: PER 1.000 € DI REDDITO ANNUO | B11: =B10/('1 - INPUT'!$B$16/1000) | C11: =C10/('1 - INPUT'!$B$16/1000) | D11: =D10/('1 - INPUT'!$B$16/1000) | E11: =E10/('1 - INPUT'!$B$16/1000)
A12: Sovrappeso rispetto all'ordine costante | B12: =B11/$B$11-1 | C12: =C11/$B$11-1 | D12: =D11/$B$11-1 | E12: =E11/$B$11-1
A14: RENDIMENTO REALE MEDIO 2%
B15: costante | C15: crolli all'INIZIO | D15: crolli a METÀ | E15: crolli alla FINE
A16: Capitale necessario SENZA lavoro | B16: 1667440.1 | C16: 2374584.2 | D16: 1625730.6 | E16: 1337476
A17: Capitale necessario CON il part-time | B17: 1431633.1 | C17: 2005906.1 | D17: 1411287.6 | E17: 1123033
A18: Capitale risparmiato dal lavoro | B18: =B16-B17 | C18: =C16-C17 | D18: =D16-D17 | E18: =E16-E17
A19: PER 1.000 € DI REDDITO ANNUO | B19: =B18/('1 - INPUT'!$B$16/1000) | C19: =C18/('1 - INPUT'!$B$16/1000) | D19: =D18/('1 - INPUT'!$B$16/1000) | E19: =E18/('1 - INPUT'!$B$16/1000)
A20: Sovrappeso rispetto all'ordine costante | B20: =B19/$B$19-1 | C20: =C19/$B$19-1 | D20: =D19/$B$19-1 | E20: =E19/$B$19-1
A22: RENDIMENTO REALE MEDIO 3%
B23: costante | C23: crolli all'INIZIO | D23: crolli a METÀ | E23: crolli alla FINE
A24: Capitale necessario SENZA lavoro | B24: 1487355.6 | C24: 2168540 | D24: 1439679.1 | E24: 1199735.8
A25: Capitale necessario CON il part-time | B25: 1262368.7 | C25: 1812390.8 | D25: 1235423.9 | E25: 995480.53
A26: Capitale risparmiato dal lavoro | B26: =B24-B25 | C26: =C24-C25 | D26: =D24-D25 | E26: =E24-E25
A27: PER 1.000 € DI REDDITO ANNUO | B27: =B26/('1 - INPUT'!$B$16/1000) | C27: =C26/('1 - INPUT'!$B$16/1000) | D27: =D26/('1 - INPUT'!$B$16/1000) | E27: =E26/('1 - INPUT'!$B$16/1000)
A28: Sovrappeso rispetto all'ordine costante | B28: =B27/$B$27-1 | C28: =C27/$B$27-1 | D28: =D27/$B$27-1 | E28: =E27/$B$27-1
A30: COSA DICE E COSA NON DICE
A31: METÀ E FINE DANNO LO STESSO VALORE in questa metrica: non è un errore di trascrizione, è una proprietà del modello. Al livello di capitale necessario il vincolo che morde è lo stesso nei due ordini, e i due numeri non vanno mai messi a schermo come se fossero misure indipendenti.
A32: Il lavoro leggero vale MOLTO DI PIÙ se i crolli arrivano nei primi anni: quando il portafoglio è basso, ogni euro che non devi prelevare vale quanto una vendita che non fai al momento peggiore. È l'unico ordine, fra i quattro che ho costruito, in cui il part-time cambia davvero la scala del problema.
A33: CON I CROLLI ALLA FINE il lavoro vale di più in euro di spesa e MENO in euro di capitale: è controintuitivo, ed è onesto dirlo. Le due metriche rispondono a due domande diverse.
A35: Rendimento degli anni normali (r = 3%) | B35: ='1 - INPUT'!B37
A36: Posizioni dei crolli — inizio / metà / fine | B36: ='1 - INPUT'!B34&" e "&'1 - INPUT'!C34 | C36: ='1 - INPUT'!B35&" e "&'1 - INPUT'!C35 | D36: ='1 - INPUT'!B36&" e "&'1 - INPUT'!C36

Sheet 8 - PARAMETRI 2026
A1: 8 — I PARAMETRI 2026, con la fonte di ciascuno
A2: Strumento informativo / divulgativo. NON è consulenza finanziaria. I valori sono indicativi al 2026 e vanno verificati col tuo consulente.
A4: NASPI E LAVORO DIPENDENTE
A5: Soglia della formula NASpI 2026 | B5: 1456.72 | C5: INPS, circolare 4/2026
A6: Tetto mensile NASpI 2026 | B6: 1584.7 | C6: INPS, circolare 4/2026
A7: Riduzione mensile (decalage) | B7: 0.03 | C7: Art. 4 c. 1 D.Lgs. 22/2015
A8: Decorrenza del decalage — regola generale | B8: 6 | C8: Art. 4 c. 1 D.Lgs. 22/2015: primo giorno del sesto mese (151o giorno)
A9: Decorrenza del decalage — chi ha compiuto 55 anni | B9: 8 | C9: Art. 4 c. 1 D.Lgs. 22/2015 come modificato dalla L. 145/2018 art. 1 c. 510: primo giorno dell'ottavo mese (211o giorno). È la regola di Franco. Da riconfermare su circolare INPS prima di ogni riuso.
A10: Durata massima della NASpI | B10: 24 | C10: Art. 5 D.Lgs. 22/2015 (mesi)
A11: Soglia di compatibilità — lavoro autonomo | B11: 5500 | C11: Messaggio INPS n. 1414 del 9 aprile 2024
