Workbook

Sheet 0 - Indice
A1: Scaletta contro titolo lungo: 200.000 € a 73 anni nel BTP 2053
A2: Strumento informativo / divulgativo. NON è consulenza finanziaria. I valori sono indicativi al 2026 e vanno verificati col tuo consulente.
A4: Indice
A5: 1 - Titoli e shock | B5: 15 titoli quotati: rateo, rendimento lordo e netto, duration, shock dei tassi, 12 mesi contro un conto deposito
A6: 2 - Scaletta e confronto | B6: Scaletta di 10 titoli contro il titolo unico 2053 a H anni: reddito, valore, rendimento, pareggio
A7: 3 - Inflazione e vendita | B7: Cedola in euro di oggi, vendita a 80 anni, vendita per cassa (ipotesi di scena)
A8: 4 - Vita e successione | B8: Probabilità di essere vivi (ISTAT 2025) e successione dei titoli di Stato
A9: 5 - Motore flussi | B9: Flussi datati e XIRR per scenario: motore del calcolo, non modificare
A11: Come usare
A12: 1. Le celle GIALLE sono input — modificale coi tuoi numeri.
A13: 2. Le celle VERDI sono output — si aggiornano automaticamente.
A14: 3. Tutti i numeri di default sono al 2026 da fonti pubbliche.
A15: 4. Niente codice nascosto: l'Excel è solo formule modificabili.
A17: Fonti dati
A18: • Borsa Italiana, schede dei titoli, prezzi di riferimento del 15/10/2026 (regolamento 19/10/2026)
A19: • ISTAT, tavole di mortalità 2025 per ripartizione (tavola di periodo; non conta i miglioramenti futuri)
A20: • D.Lgs. 346/1990 art. 12 c. 1 lett. h)-i); dal 1/1/2027 D.Lgs. 123/2025 art. 97 (decorrenza spostata dal D.L. 200/2025 art. 4 c. 5)
A21: • Imposta 12,5% su cedole e sconto; bollo 0,20% (DPR 642/1972, Tariffa art. 13 c. 2-ter); D.Lgs. 139/2024 (aliquote di successione)
A22: • Calcoli miei: dossier del video, motore in Python e questo foglio. Il caso di Ennio è inventato
A24: Aggiornamenti: github.com/marcofire-it/marco-fire-simulatori

Sheet 1 - Titoli e shock
A1: Titoli quotati, shock dei tassi e 12 mesi contro un conto deposito
A2: Strumento informativo / divulgativo. NON è consulenza finanziaria. I valori sono indicativi al 2026 e vanno verificati col tuo consulente.
A4: Parametri (celle gialle = input)
A5: Data dei prezzi (Borsa Italiana) | B5: 46310
A6: Data di regolamento | B6: 46314
A7: Capitale investito (€) | B7: 200000
A8: Aliquota su cedole e sconto | B8: 0.125
A9: Bollo annuo sul valore | B9: 0.002
A10: Shock dei tassi Δ (punti, da −1 a +3) | B10: 1
A11: Orizzonte H (anni: 7, 10, 14 o 16) | B11: 10
A12: Tasso di reinvestimento lordo effettivo: forzatura (vuoto = rendimento del 10 anni ott 2036)
A13: Tasso di reinvestimento usato | B13: =IF(B12="",K30,B12) -> 0.044879535
A14: Conto deposito, rendimento lordo annuo | B14: 0.025
A15: Imposta sugli interessi del conto | B15: 0.26
A16: Data fra 12 mesi | B16: =EDATE(B6,12) -> 46679
A17: Data di fine orizzonte | B17: =EDATE(B6,12*B11) -> 49967
A19: I 15 titoli: dati Borsa Italiana (gialli) e calcoli (verdi)
A20: Titolo | B20: Codice | C20: Cedola | D20: Scadenza | E20: Prezzo secco | F20: Lordo Borsa Italiana | G20: Netto Borsa Italiana | H20: Duration Borsa Italiana | I20: Rateo lordo per 100 | J20: Rendimento nominale | K20: Lordo effettivo | L20: Duration (calcolo) | M20: Netto nominale (imposta anche sullo sconto) | N20: Netto effettivo | O20: Netto dopo bollo | P20: Vita residua (anni) | Q20: Prezzo dopo lo shock Δ | R20: Nominale acquistato (€) | S20: Variazione in € (Δ) | T20: Variazione % (Δ) | U20: Prezzo con +1 punto | V20: Variazione in € (+1 punto) | W20: Lordo calcolo − Borsa Italiana (punti)
A21: BTP 2,70% ott 2027 | B21: IT0005622128 | C21: 0.027 | D21: 46675 | E21: 99.556 | F21: 0.0318 | G21: 0.0284 | H21: 0.95 | I21: =C21*100/2*COUPDAYBS($B$6,D21,2,1)/COUPDAYS($B$6,D21,2,1) -> 0.02967033 | J21: =YIELD($B$6,D21,C21,E21,100,2,1) -> 0.031592849 | K21: =(1+J21/2)^2-1 -> 0.031842376 | L21: =MDURATION($B$6,D21,C21,J21,2,1)/(1+J21/2) -> 0.95202139 | M21: =YIELD($B$6,D21,C21*(1-$B$8),E21,100-$B$8*MAX(0,100-E21),2,1) -> 0.027647754 | N21: =(1+M21/2)^2-1 -> 0.027838854 | O21: =N21-$B$9*E21/100 -> 0.025847734 | P21: =(D21-$B$6)/365.25 -> 0.98836413 | Q21: =PRICE($B$6,D21,C21,2*((1+K21+$B$10/100)^0.5-1),100,2,1) -> 98.616958 | R21: =$B$7/(E21+I21)*100 -> 200832.11 | S21: =R21*(Q21-E21)/100 -> -1885.897 | T21: =Q21/E21-1 -> -0.0094322954 | U21: =PRICE($B$6,D21,C21,2*((1+K21+1/100)^0.5-1),100,2,1) -> 98.616958 | V21: =R21*(U21-E21)/100 -> -1885.897 | W21: =(K21-F21)*100 -> 0.004237634
A22: BTP 2,80% dic 2028 | B22: IT0005340929 | C22: 0.028 | D22: 47088 | E22: 98.8 | F22: 0.0341 | G22: 0.0305 | H22: 1.98 | I22: =C22*100/2*COUPDAYBS($B$6,D22,2,1)/COUPDAYS($B$6,D22,2,1) -> 1.0710383 | J22: =YIELD($B$6,D22,C22,E22,100,2,1) -> 0.033910428 | K22: =(1+J22/2)^2-1 -> 0.034197908 | L22: =MDURATION($B$6,D22,C22,J22,2,1)/(1+J22/2) -> 1.9810779 | M22: =YIELD($B$6,D22,C22*(1-$B$8),E22,100-$B$8*MAX(0,100-E22),2,1) -> 0.029689477 | N22: =(1+M22/2)^2-1 -> 0.029909843 | O22: =N22-$B$9*E22/100 -> 0.027933843 | P22: =(D22-$B$6)/365.25 -> 2.1190965 | Q22: =PRICE($B$6,D22,C22,2*((1+K22+$B$10/100)^0.5-1),100,2,1) -> 96.850715 | R22: =$B$7/(E22+I22)*100 -> 200258.26 | S22: =R22*(Q22-E22)/100 -> -3903.6044 | T22: =Q22/E22-1 -> -0.019729606 | U22: =PRICE($B$6,D22,C22,2*((1+K22+1/100)^0.5-1),100,2,1) -> 96.850715 | V22: =R22*(U22-E22)/100 -> -3903.6044 | W22: =(K22-F22)*100 -> 0.0097907534
A23: BTP 3,00% ott 2029 | B23: IT0005611055 | C23: 0.03 | D23: 47392 | E23: 98.28 | F23: 0.0365 | G23: 0.0326 | H23: 2.74 | I23: =C23*100/2*COUPDAYBS($B$6,D23,2,1)/COUPDAYS($B$6,D23,2,1) -> 0.14835165 | J23: =YIELD($B$6,D23,C23,E23,100,2,1) -> 0.036194465 | K23: =(1+J23/2)^2-1 -> 0.036521975 | L23: =MDURATION($B$6,D23,C23,J23,2,1)/(1+J23/2) -> 2.7406227 | M23: =YIELD($B$6,D23,C23*(1-$B$8),E23,100-$B$8*MAX(0,100-E23),2,1) -> 0.031698145 | N23: =(1+M23/2)^2-1 -> 0.031949338 | O23: =N23-$B$9*E23/100 -> 0.029983738 | P23: =(D23-$B$6)/365.25 -> 2.9514031 | Q23: =PRICE($B$6,D23,C23,2*((1+K23+$B$10/100)^0.5-1),100,2,1) -> 95.632508 | R23: =$B$7/(E23+I23)*100 -> 203193.49 | S23: =R23*(Q23-E23)/100 -> -5379.5317 | T23: =Q23/E23-1 -> -0.02693826 | U23: =PRICE($B$6,D23,C23,2*((1+K23+1/100)^0.5-1),100,2,1) -> 95.632508 | V23: =R23*(U23-E23)/100 -> -5379.5317 | W23: =(K23-F23)*100 -> 0.0021975207
A24: BTP 2,70% ott 2030 | B24: IT0005654642 | C24: 0.027 | D24: 47757 | E24: 96.04 | F24: 0.0382 | G24: 0.0346 | H24: 3.63 | I24: =C24*100/2*COUPDAYBS($B$6,D24,2,1)/COUPDAYS($B$6,D24,2,1) -> 0.13351648 | J24: =YIELD($B$6,D24,C24,E24,100,2,1) -> 0.0378841 | K24: =(1+J24/2)^2-1 -> 0.038242902 | L24: =MDURATION($B$6,D24,C24,J24,2,1)/(1+J24/2) -> 3.6256875 | M24: =YIELD($B$6,D24,C24*(1-$B$8),E24,100-$B$8*MAX(0,100-E24),2,1) -> 0.033218642 | N24: =(1+M24/2)^2-1 -> 0.033494512 | O24: =N24-$B$9*E24/100 -> 0.031573712 | P24: =(D24-$B$6)/365.25 -> 3.9507187 | Q24: =PRICE($B$6,D24,C24,2*((1+K24+$B$10/100)^0.5-1),100,2,1) -> 92.633471 | R24: =$B$7/(E24+I24)*100 -> 207957.46 | S24: =R24*(Q24-E24)/100 -> -7084.132 | T24: =Q24/E24-1 -> -0.035469902 | U24: =PRICE($B$6,D24,C24,2*((1+K24+1/100)^0.5-1),100,2,1) -> 92.633471 | V24: =R24*(U24-E24)/100 -> -7084.132 | W24: =(K24-F24)*100 -> 0.004290153
A25: BTP 3,15% nov 2031 | B25: IT0005619546 | C25: 0.0315 | D25: 48167 | E25: 96.56 | F25: 0.0394 | G25: 0.0352 | H25: 4.49 | I25: =C25*100/2*COUPDAYBS($B$6,D25,2,1)/COUPDAYS($B$6,D25,2,1) -> 1.3438859 | J25: =YIELD($B$6,D25,C25,E25,100,2,1) -> 0.03903562 | K25: =(1+J25/2)^2-1 -> 0.039416565 | L25: =MDURATION($B$6,D25,C25,J25,2,1)/(1+J25/2) -> 4.4800286 | M25: =YIELD($B$6,D25,C25*(1-$B$8),E25,100-$B$8*MAX(0,100-E25),2,1) -> 0.034219801 | N25: =(1+M25/2)^2-1 -> 0.03451255 | O25: =N25-$B$9*E25/100 -> 0.03258135 | P25: =(D25-$B$6)/365.25 -> 5.0732375 | Q25: =PRICE($B$6,D25,C25,2*((1+K25+$B$10/100)^0.5-1),100,2,1) -> 92.2964 | R25: =$B$7/(E25+I25)*100 -> 204281.98 | S25: =R25*(Q25-E25)/100 -> -8709.7664 | T25: =Q25/E25-1 -> -0.044154928 | U25: =PRICE($B$6,D25,C25,2*((1+K25+1/100)^0.5-1),100,2,1) -> 92.2964 | V25: =R25*(U25-E25)/100 -> -8709.7664 | W25: =(K25-F25)*100 -> 0.0016565047
A26: BTP 3,25% nov 2032 | B26: IT0005668220 | C26: 0.0325 | D26: 48533 | E26: 95.9 | F26: 0.0405 | G26: 0.0362 | H26: 5.26 | I26: =C26*100/2*COUPDAYBS($B$6,D26,2,1)/COUPDAYS($B$6,D26,2,1) -> 1.3865489 | J26: =YIELD($B$6,D26,C26,E26,100,2,1) -> 0.04017119 | K26: =(1+J26/2)^2-1 -> 0.040574621 | L26: =MDURATION($B$6,D26,C26,J26,2,1)/(1+J26/2) -> 5.2552761 | M26: =YIELD($B$6,D26,C26*(1-$B$8),E26,100-$B$8*MAX(0,100-E26),2,1) -> 0.035228206 | N26: =(1+M26/2)^2-1 -> 0.035538463 | O26: =N26-$B$9*E26/100 -> 0.033620463 | P26: =(D26-$B$6)/365.25 -> 6.0752909 | Q26: =PRICE($B$6,D26,C26,2*((1+K26+$B$10/100)^0.5-1),100,2,1) -> 90.951926 | R26: =$B$7/(E26+I26)*100 -> 205578.27 | S26: =R26*(Q26-E26)/100 -> -10172.164 | T26: =Q26/E26-1 -> -0.051596181 | U26: =PRICE($B$6,D26,C26,2*((1+K26+1/100)^0.5-1),100,2,1) -> 90.951926 | V26: =R26*(U26-E26)/100 -> -10172.164 | W26: =(K26-F26)*100 -> 0.0074621472
A27: BTP 4,35% nov 2033 | B27: IT0005544082 | C27: 0.0435 | D27: 48884 | E27: 101.22 | F27: 0.0419 | G27: 0.0364 | H27: 5.79 | I27: =C27*100/2*COUPDAYBS($B$6,D27,2,1)/COUPDAYS($B$6,D27,2,1) -> 2.0213315 | J27: =YIELD($B$6,D27,C27,E27,100,2,1) -> 0.041480348 | K27: =(1+J27/2)^2-1 -> 0.041910503 | L27: =MDURATION($B$6,D27,C27,J27,2,1)/(1+J27/2) -> 5.7802228 | M27: =YIELD($B$6,D27,C27*(1-$B$8),E27,100-$B$8*MAX(0,100-E27),2,1) -> 0.036081664 | N27: =(1+M27/2)^2-1 -> 0.036407136 | O27: =N27-$B$9*E27/100 -> 0.034382736 | P27: =(D27-$B$6)/365.25 -> 7.0362765 | Q27: =PRICE($B$6,D27,C27,2*((1+K27+$B$10/100)^0.5-1),100,2,1) -> 95.466414 | R27: =$B$7/(E27+I27)*100 -> 193720.86 | S27: =R27*(Q27-E27)/100 -> -11145.897 | T27: =Q27/E27-1 -> -0.056842387 | U27: =PRICE($B$6,D27,C27,2*((1+K27+1/100)^0.5-1),100,2,1) -> 95.466414 | V27: =R27*(U27-E27)/100 -> -11145.897 | W27: =(K27-F27)*100 -> 0.001050269
A28: BTP 3,85% feb 2035 | B28: IT0005607970 | C28: 0.0385 | D28: 49341 | E28: 96.91 | F28: 0.0434 | G28: 0.0384 | H28: 6.8 | I28: =C28*100/2*COUPDAYBS($B$6,D28,2,1)/COUPDAYS($B$6,D28,2,1) -> 0.82649457 | J28: =YIELD($B$6,D28,C28,E28,100,2,1) -> 0.042964845 | K28: =(1+J28/2)^2-1 -> 0.043426339 | L28: =MDURATION($B$6,D28,C28,J28,2,1)/(1+J28/2) -> 6.7964438 | M28: =YIELD($B$6,D28,C28*(1-$B$8),E28,100-$B$8*MAX(0,100-E28),2,1) -> 0.03765668 | N28: =(1+M28/2)^2-1 -> 0.038011187 | O28: =N28-$B$9*E28/100 -> 0.036072987 | P28: =(D28-$B$6)/365.25 -> 8.2874743 | Q28: =PRICE($B$6,D28,C28,2*((1+K28+$B$10/100)^0.5-1),100,2,1) -> 90.540073 | R28: =$B$7/(E28+I28)*100 -> 204631.85 | S28: =R28*(Q28-E28)/100 -> -13034.899 | T28: =Q28/E28-1 -> -0.065730333 | U28: =PRICE($B$6,D28,C28,2*((1+K28+1/100)^0.5-1),100,2,1) -> 90.540073 | V28: =R28*(U28-E28)/100 -> -13034.899 | W28: =(K28-F28)*100 -> 0.0026339126
A29: BTP 3,60% ott 2035 | B29: IT0005648149 | C29: 0.036 | D29: 49583 | E29: 94.5 | F29: 0.0439 | G29: 0.0392 | H29: 7.36 | I29: =C29*100/2*COUPDAYBS($B$6,D29,2,1)/COUPDAYS($B$6,D29,2,1) -> 0.17802198 | J29: =YIELD($B$6,D29,C29,E29,100,2,1) -> 0.043481369 | K29: =(1+J29/2)^2-1 -> 0.043954026 | L29: =MDURATION($B$6,D29,C29,J29,2,1)/(1+J29/2) -> 7.3506712 | M29: =YIELD($B$6,D29,C29*(1-$B$8),E29,100-$B$8*MAX(0,100-E29),2,1) -> 0.038158335 | N29: =(1+M29/2)^2-1 -> 0.03852235 | O29: =N29-$B$9*E29/100 -> 0.03663235 | P29: =(D29-$B$6)/365.25 -> 8.9500342 | Q29: =PRICE($B$6,D29,C29,2*((1+K29+$B$10/100)^0.5-1),100,2,1) -> 87.845443 | R29: =$B$7/(E29+I29)*100 -> 211242.27 | S29: =R29*(Q29-E29)/100 -> -14057.238 | T29: =Q29/E29-1 -> -0.070418597 | U29: =PRICE($B$6,D29,C29,2*((1+K29+1/100)^0.5-1),100,2,1) -> 87.845443 | V29: =R29*(U29-E29)/100 -> -14057.238 | W29: =(K29-F29)*100 -> 0.0054026053
A30: BTP 4,00% ott 2036 | B30: IT0005729931 | C30: 0.04 | D30: 49949 | E30: 96.5 | F30: 0.0448 | G30: 0.0396 | H30: 7.91 | I30: =C30*100/2*COUPDAYBS($B$6,D30,2,1)/COUPDAYS($B$6,D30,2,1) -> 0.1978022 | J30: =YIELD($B$6,D30,C30,E30,100,2,1) -> 0.044386984 | K30: =(1+J30/2)^2-1 -> 0.044879535 | L30: =MDURATION($B$6,D30,C30,J30,2,1)/(1+J30/2) -> 7.898967 | M30: =YIELD($B$6,D30,C30*(1-$B$8),E30,100-$B$8*MAX(0,100-E30),2,1) -> 0.038909751 | N30: =(1+M30/2)^2-1 -> 0.039288243 | O30: =N30-$B$9*E30/100 -> 0.037358243 | P30: =(D30-$B$6)/365.25 -> 9.9520876 | Q30: =PRICE($B$6,D30,C30,2*((1+K30+$B$10/100)^0.5-1),100,2,1) -> 89.224389 | R30: =$B$7/(E30+I30)*100 -> 206829.93 | S30: =R30*(Q30-E30)/100 -> -15048.141 | T30: =Q30/E30-1 -> -0.075394932 | U30: =PRICE($B$6,D30,C30,2*((1+K30+1/100)^0.5-1),100,2,1) -> 89.224389 | V30: =R30*(U30-E30)/100 -> -15048.141 | W30: =(K30-F30)*100 -> 0.007953548
A31: BTP 3,95% ott 2041 | B31: IT0005694630 | C31: 0.0395 | D31: 51775 | E31: 91.55 | F31: 0.048 | G31: 0.0427 | H31: 10.71 | I31: =C31*100/2*COUPDAYBS($B$6,D31,2,1)/COUPDAYS($B$6,D31,2,1) -> 0.19532967 | J31: =YIELD($B$6,D31,C31,E31,100,2,1) -> 0.047454164 | K31: =(1+J31/2)^2-1 -> 0.048017138 | L31: =MDURATION($B$6,D31,C31,J31,2,1)/(1+J31/2) -> 10.705812 | M31: =YIELD($B$6,D31,C31*(1-$B$8),E31,100-$B$8*MAX(0,100-E31),2,1) -> 0.041697357 | N31: =(1+M31/2)^2-1 -> 0.042132024 | O31: =N31-$B$9*E31/100 -> 0.040301024 | P31: =(D31-$B$6)/365.25 -> 14.951403 | Q31: =PRICE($B$6,D31,C31,2*((1+K31+$B$10/100)^0.5-1),100,2,1) -> 82.37076 | R31: =$B$7/(E31+I31)*100 -> 217994.75 | S31: =R31*(Q31-E31)/100 -> -20010.261 | T31: =Q31/E31-1 -> -0.10026478 | U31: =PRICE($B$6,D31,C31,2*((1+K31+1/100)^0.5-1),100,2,1) -> 82.37076 | V31: =R31*(U31-E31)/100 -> -20010.261 | W31: =(K31-F31)*100 -> 0.0017138301
A32: BTP 2,70% mar 2047 | B32: IT0005162828 | C32: 0.027 | D32: 53752 | E32: 72.32 | F32: 0.0491 | G32: 0.0449 | H32: 14.07 | I32: =C32*100/2*COUPDAYBS($B$6,D32,2,1)/COUPDAYS($B$6,D32,2,1) -> 0.35801105 | J32: =YIELD($B$6,D32,C32,E32,100,2,1) -> 0.048548334 | K32: =(1+J32/2)^2-1 -> 0.049137569 | L32: =MDURATION($B$6,D32,C32,J32,2,1)/(1+J32/2) -> 14.059585 | M32: =YIELD($B$6,D32,C32*(1-$B$8),E32,100-$B$8*MAX(0,100-E32),2,1) -> 0.043099089 | N32: =(1+M32/2)^2-1 -> 0.043563472 | O32: =N32-$B$9*E32/100 -> 0.042117072 | P32: =(D32-$B$6)/365.25 -> 20.364134 | Q32: =PRICE($B$6,D32,C32,2*((1+K32+$B$10/100)^0.5-1),100,2,1) -> 62.974333 | R32: =$B$7/(E32+I32)*100 -> 275186.4 | S32: =R32*(Q32-E32)/100 -> -25718.005 | T32: =Q32/E32-1 -> -0.1292266 | U32: =PRICE($B$6,D32,C32,2*((1+K32+1/100)^0.5-1),100,2,1) -> 62.974333 | V32: =R32*(U32-E32)/100 -> -25718.005 | W32: =(K32-F32)*100 -> 0.0037568872
... A35: BTP 4,65% ott 2055 | B35: IT0005668238 | C35: 0.0465 | D35: 56888 | E35: 94.41 | F35: 0.0508 | G35: 0.0446 | H35: 15.02 | I35: =C35*100/2*COUPDAYBS($B$6,D35,2,1)/COUPDAYS($B$6,D35,2,1) -> 0.22994505 | J35: =YIELD($B$6,D35,C35,E35,100,2,1) -> 0.050180282 | K35: =(1+J35/2)^2-1 -> 0.050809797 | L35: =MDURATION($B$6,D35,C35,J35,2,1)/(1+J35/2) -> 15.010569 | M35: =YIELD($B$6,D35,C35*(1-$B$8),E35,100-$B$8*MAX(0,100-E35),2,1) -> 0.043997986 | N35: =(1+M35/2)^2-1 -> 0.044481941 | O35: =N35-$B$9*E35/100 -> 0.042593741 | P35: =(D35-$B$6)/365.25 -> 28.950034 | Q35: =PRICE($B$6,D35,C35,2*((1+K35+$B$10/100)^0.5-1),100,2,1) -> 81.663178 | R35: =$B$7/(E35+I35)*100 -> 211327.26 | S35: =R35*(Q35-E35)/100 -> -26937.508 | T35: =Q35/E35-1 -> -0.13501559 | U35: =PRICE($B$6,D35,C35,2*((1+K35+1/100)^0.5-1),100,2,1) -> 81.663178 | V35: =R35*(U35-E35)/100 -> -26937.508 | W35: =(K35-F35)*100 -> 0.00097974335
A36: Il netto usa la convenzione dello speciale: imposta 12,5% sulle cedole e anche sullo sconto sotto la pari; Borsa Italiana conta le sole cedole, per questo i suoi netti sono un poco più alti. La duration Borsa Italiana del 2053 è 14,69.
A37: Curva dei rendimenti: i 15 titoli ordinati per vita residua (colonne P e K), interpolazione lineare nel foglio 5.
A39: 12 mesi: titolo contro conto deposito (prezzo fra un anno = rendimento di oggi + Δ)
A40: Conto deposito netto a 12 mesi | B40: =B14*(1-B15) -> 0.0185
I41: Δ da provare (punti) →
A42: Titolo | B42: Prezzo oggi | C42: Rateo oggi | D42: Lordo effettivo | E42: Prima cedola | F42: Quota 1ª cedola tassata | G42: Cedola lorda semestrale | H42: Cedole nette a 12 mesi | I42: Rateo fra 12 mesi | J42: 0 | K42: 0.1 | L42: 0.2 | M42: 0.3 | N42: 0.4 | O42: 0.5 | P42: Pareggio contro il conto (punti) | Q42: Passaggio 1 | R42: Passaggio 2 | S42: Passaggio 3 | T42: Passaggio 4 | U42: Passaggio 5
A43: =A30 -> BTP 4,00% ott 2036 | B43: =E30 -> 96.5 | C43: =I30 -> 0.1978022 | D43: =K30 -> 0.044879535 | E43: =COUPNCD($B$6,D30,2,1) -> 46478 | F43: =(E43-$B$6)/(E43-COUPPCD($B$6,D30,2,1)) -> 0.9010989 | G43: =C30*100/2 -> 2 | H43: =G43-$B$8*G43*F43+IF(EDATE(E43,6)<=$B$16,G43*(1-$B$8),0)+IF(EDATE(E43,12)<=$B$16,G43*(1-$B$8),0) -> 3.5247253 | I43: =G43*COUPDAYBS($B$16,D30,2,1)/COUPDAYS($B$16,D30,2,1) -> 0.19672131 | J43: =(PRICE($B$16,$D$30,$C$30,2*((1+$D43+J$42/100)^0.5-1),100,2,1)+$I43+$H43-$B$8*(MAX(0,PRICE($B$16,$D$30,$C$30,2*((1+$D43+J$42/100)^0.5-1),100,2,1)-$B43)+$I43)-($B43+$C43))/($B43+$C43) -> 0.038777997 | K43: =(PRICE($B$16,$D$30,$C$30,2*((1+$D43+K$42/100)^0.5-1),100,2,1)+$I43+$H43-$B$8*(MAX(0,PRICE($B$16,$D$30,$C$30,2*((1+$D43+K$42/100)^0.5-1),100,2,1)-$B43)+$I43)-($B43+$C43))/($B43+$C43) -> 0.031915218 | L43: =(PRICE($B$16,$D$30,$C$30,2*((1+$D43+L$42/100)^0.5-1),100,2,1)+$I43+$H43-$B$8*(MAX(0,PRICE($B$16,$D$30,$C$30,2*((1+$D43+L$42/100)^0.5-1),100,2,1)-$B43)+$I43)-($B43+$C43))/($B43+$C43) -> 0.024746881 | M43: =(PRICE($B$16,$D$30,$C$30,2*((1+$D43+M$42/100)^0.5-1),100,2,1)+$I43+$H43-$B$8*(MAX(0,PRICE($B$16,$D$30,$C$30,2*((1+$D43+M$42/100)^0.5-1),100,2,1)-$B43)+$I43)-($B43+$C43))/($B43+$C43) -> 0.017642693 | N43: =(PRICE($B$16,$D$30,$C$30,2*((1+$D43+N$42/100)^0.5-1),100,2,1)+$I43+$H43-$B$8*(MAX(0,PRICE($B$16,$D$30,$C$30,2*((1+$D43+N$42/100)^0.5-1),100,2,1)-$B43)+$I43)-($B43+$C43))/($B43+$C43) -> 0.010602006 | O43: =(PRICE($B$16,$D$30,$C$30,2*((1+$D43+O$42/100)^0.5-1),100,2,1)+$I43+$H43-$B$8*(MAX(0,PRICE($B$16,$D$30,$C$30,2*((1+$D43+O$42/100)^0.5-1),100,2,1)-$B43)+$I43)-($B43+$C43))/($B43+$C43) -> 0.0036241773 | P43: =IF(COUNT(Q43:U43)=0,"n/d",MIN(Q43:U43)) -> 0.28793238 | Q43: =IF(AND(J43>=$B$40,K43<$B$40),J$42+(K$42-J$42)*(J43-$B$40)/(J43-K43),"") | R43: =IF(AND(K43>=$B$40,L43<$B$40),K$42+(L$42-K$42)*(K43-$B$40)/(K43-L43),"") | S43: =IF(AND(L43>=$B$40,M43<$B$40),L$42+(M$42-L$42)*(L43-$B$40)/(L43-M43),"") -> 0.28793238 | T43: =IF(AND(M43>=$B$40,N43<$B$40),M$42+(N$42-M$42)*(M43-$B$40)/(M43-N43),"") | U43: =IF(AND(N43>=$B$40,O43<$B$40),N$42+(O$42-N$42)*(N43-$B$40)/(N43-O43),"")
A44: =A31 -> BTP 3,95% ott 2041 | B44: =E31 -> 91.55 | C44: =I31 -> 0.19532967 | D44: =K31 -> 0.048017138 | E44: =COUPNCD($B$6,D31,2,1) -> 46478 | F44: =(E44-$B$6)/(E44-COUPPCD($B$6,D31,2,1)) -> 0.9010989 | G44: =C31*100/2 -> 1.975 | H44: =G44-$B$8*G44*F44+IF(EDATE(E44,6)<=$B$16,G44*(1-$B$8),0)+IF(EDATE(E44,12)<=$B$16,G44*(1-$B$8),0) -> 3.4806662 | I44: =G44*COUPDAYBS($B$16,D31,2,1)/COUPDAYS($B$16,D31,2,1) -> 0.1942623 | J44: =(PRICE($B$16,$D$31,$C$31,2*((1+$D44+J$42/100)^0.5-1),100,2,1)+$I44+$H44-$B$8*(MAX(0,PRICE($B$16,$D$31,$C$31,2*((1+$D44+J$42/100)^0.5-1),100,2,1)-$B44)+$I44)-($B44+$C44))/($B44+$C44) -> 0.041468423 | K44: =(PRICE($B$16,$D$31,$C$31,2*((1+$D44+K$42/100)^0.5-1),100,2,1)+$I44+$H44-$B$8*(MAX(0,PRICE($B$16,$D$31,$C$31,2*((1+$D44+K$42/100)^0.5-1),100,2,1)-$B44)+$I44)-($B44+$C44))/($B44+$C44) -> 0.0318458 | L44: =(PRICE($B$16,$D$31,$C$31,2*((1+$D44+L$42/100)^0.5-1),100,2,1)+$I44+$H44-$B$8*(MAX(0,PRICE($B$16,$D$31,$C$31,2*((1+$D44+L$42/100)^0.5-1),100,2,1)-$B44)+$I44)-($B44+$C44))/($B44+$C44) -> 0.021810553 | M44: =(PRICE($B$16,$D$31,$C$31,2*((1+$D44+M$42/100)^0.5-1),100,2,1)+$I44+$H44-$B$8*(MAX(0,PRICE($B$16,$D$31,$C$31,2*((1+$D44+M$42/100)^0.5-1),100,2,1)-$B44)+$I44)-($B44+$C44))/($B44+$C44) -> 0.011904565 | N44: =(PRICE($B$16,$D$31,$C$31,2*((1+$D44+N$42/100)^0.5-1),100,2,1)+$I44+$H44-$B$8*(MAX(0,PRICE($B$16,$D$31,$C$31,2*((1+$D44+N$42/100)^0.5-1),100,2,1)-$B44)+$I44)-($B44+$C44))/($B44+$C44) -> 0.002125978 | O44: =(PRICE($B$16,$D$31,$C$31,2*((1+$D44+O$42/100)^0.5-1),100,2,1)+$I44+$H44-$B$8*(MAX(0,PRICE($B$16,$D$31,$C$31,2*((1+$D44+O$42/100)^0.5-1),100,2,1)-$B44)+$I44)-($B44+$C44))/($B44+$C44) -> -0.0075270383 | P44: =IF(COUNT(Q44:U44)=0,"n/d",MIN(Q44:U44)) -> 0.23341972 | Q44: =IF(AND(J44>=$B$40,K44<$B$40),J$42+(K$42-J$42)*(J44-$B$40)/(J44-K44),"") | R44: =IF(AND(K44>=$B$40,L44<$B$40),K$42+(L$42-K$42)*(K44-$B$40)/(K44-L44),"") | S44: =IF(AND(L44>=$B$40,M44<$B$40),L$42+(M$42-L$42)*(L44-$B$40)/(L44-M44),"") -> 0.23341972 | T44: =IF(AND(M44>=$B$40,N44<$B$40),M$42+(N$42-M$42)*(M44-$B$40)/(M44-N44),"") | U44: =IF(AND(N44>=$B$40,O44<$B$40),N$42+(O$42-N$42)*(N44-$B$40)/(N44-O44),"")
A45: =A33 -> BTP 4,50% ott 2053 | B45: =E33 -> 93.04 | C45: =I33 -> 0.22252747 | D45: =K33 -> 0.050331617 | E45: =COUPNCD($B$6,D33,2,1) -> 46478 | F45: =(E45-$B$6)/(E45-COUPPCD($B$6,D33,2,1)) -> 0.9010989 | G45: =C33*100/2 -> 2.25 | H45: =G45-$B$8*G45*F45+IF(EDATE(E45,6)<=$B$16,G45*(1-$B$8),0)+IF(EDATE(E45,12)<=$B$16,G45*(1-$B$8),0) -> 3.9653159 | I45: =G45*COUPDAYBS($B$16,D33,2,1)/COUPDAYS($B$16,D33,2,1) -> 0.22131148 | J45: =(PRICE($B$16,$D$33,$C$33,2*((1+$D45+J$42/100)^0.5-1),100,2,1)+$I45+$H45-$B$8*(MAX(0,PRICE($B$16,$D$33,$C$33,2*((1+$D45+J$42/100)^0.5-1),100,2,1)-$B45)+$I45)-($B45+$C45))/($B45+$C45) -> 0.043399893 | K45: =(PRICE($B$16,$D$33,$C$33,2*((1+$D45+K$42/100)^0.5-1),100,2,1)+$I45+$H45-$B$8*(MAX(0,PRICE($B$16,$D$33,$C$33,2*((1+$D45+K$42/100)^0.5-1),100,2,1)-$B45)+$I45)-($B45+$C45))/($B45+$C45) -> 0.029292966 | L45: =(PRICE($B$16,$D$33,$C$33,2*((1+$D45+L$42/100)^0.5-1),100,2,1)+$I45+$H45-$B$8*(MAX(0,PRICE($B$16,$D$33,$C$33,2*((1+$D45+L$42/100)^0.5-1),100,2,1)-$B45)+$I45)-($B45+$C45))/($B45+$C45) -> 0.015308771 | M45: =(PRICE($B$16,$D$33,$C$33,2*((1+$D45+M$42/100)^0.5-1),100,2,1)+$I45+$H45-$B$8*(MAX(0,PRICE($B$16,$D$33,$C$33,2*((1+$D45+M$42/100)^0.5-1),100,2,1)-$B45)+$I45)-($B45+$C45))/($B45+$C45) -> 0.0016106724 | N45: =(PRICE($B$16,$D$33,$C$33,2*((1+$D45+N$42/100)^0.5-1),100,2,1)+$I45+$H45-$B$8*(MAX(0,PRICE($B$16,$D$33,$C$33,2*((1+$D45+N$42/100)^0.5-1),100,2,1)-$B45)+$I45)-($B45+$C45))/($B45+$C45) -> -0.011808044 | O45: =(PRICE($B$16,$D$33,$C$33,2*((1+$D45+O$42/100)^0.5-1),100,2,1)+$I45+$H45-$B$8*(MAX(0,PRICE($B$16,$D$33,$C$33,2*((1+$D45+O$42/100)^0.5-1),100,2,1)-$B45)+$I45)-($B45+$C45))/($B45+$C45) -> -0.024953923 | P45: =IF(COUNT(Q45:U45)=0,"n/d",MIN(Q45:U45)) -> 0.17717974 | Q45: =IF(AND(J45>=$B$40,K45<$B$40),J$42+(K$42-J$42)*(J45-$B$40)/(J45-K45),"") | R45: =IF(AND(K45>=$B$40,L45<$B$40),K$42+(L$42-K$42)*(K45-$B$40)/(K45-L45),"") -> 0.17717974 | S45: =IF(AND(L45>=$B$40,M45<$B$40),L$42+(M$42-L$42)*(L45-$B$40)/(L45-M45),"") | T45: =IF(AND(M45>=$B$40,N45<$B$40),M$42+(N$42-M$42)*(M45-$B$40)/(M45-N45),"") | U45: =IF(AND(N45>=$B$40,O45<$B$40),N$42+(O$42-N$42)*(N45-$B$40)/(N45-O45),"")
...

Sheet 2 - Scaletta e confronto
A1: Scaletta di dieci titoli contro il titolo unico 2053
A2: Strumento informativo / divulgativo. NON è consulenza finanziaria. I valori sono indicativi al 2026 e vanno verificati col tuo consulente.
A4: Parametri (dal foglio 1: si cambiano là)
A5: Orizzonte H (anni) | B5: ='1 - Titoli e shock'!$B$11 -> 10
A6: Tasso di reinvestimento lordo effettivo usato | B6: ='1 - Titoli e shock'!$B$13 -> 0.044879535
A7: Capitale (€) | B7: ='1 - Titoli e shock'!$B$7 -> 200000
A8: Importo per ogni titolo della scaletta (€) | B8: =B7/10 -> 20000
A10: Composizione della scaletta (prezzi Borsa Italiana, 15/10/2026)
A11: Titolo | B11: Scadenza | C11: Prezzo secco | D11: Nominale (€) | E11: Cedola netta annua a regime (€) | F11: Netto effettivo
A12: ='1 - Titoli e shock'!A21 -> BTP 2,70% ott 2027 | B12: ='1 - Titoli e shock'!D21 -> 46675 | C12: ='1 - Titoli e shock'!E21 -> 99.556 | D12: ='5 - Motore flussi'!C34*100 -> 20083.211 | E12: =D12*'1 - Titoli e shock'!C21*(1-'1 - Titoli e shock'!$B$8) -> 474.46585 | F12: ='1 - Titoli e shock'!N21 -> 0.027838854
A13: ='1 - Titoli e shock'!A22 -> BTP 2,80% dic 2028 | B13: ='1 - Titoli e shock'!D22 -> 47088 | C13: ='1 - Titoli e shock'!E22 -> 98.8 | D13: ='5 - Motore flussi'!C35*100 -> 20025.826 | E13: =D13*'1 - Titoli e shock'!C22*(1-'1 - Titoli e shock'!$B$8) -> 490.63273 | F13: ='1 - Titoli e shock'!N22 -> 0.029909843
A14: ='1 - Titoli e shock'!A23 -> BTP 3,00% ott 2029 | B14: ='1 - Titoli e shock'!D23 -> 47392 | C14: ='1 - Titoli e shock'!E23 -> 98.28 | D14: ='5 - Motore flussi'!C36*100 -> 20319.349 | E14: =D14*'1 - Titoli e shock'!C23*(1-'1 - Titoli e shock'!$B$8) -> 533.3829 | F14: ='1 - Titoli e shock'!N23 -> 0.031949338
A15: ='1 - Titoli e shock'!A24 -> BTP 2,70% ott 2030 | B15: ='1 - Titoli e shock'!D24 -> 47757 | C15: ='1 - Titoli e shock'!E24 -> 96.04 | D15: ='5 - Motore flussi'!C37*100 -> 20795.746 | E15: =D15*'1 - Titoli e shock'!C24*(1-'1 - Titoli e shock'!$B$8) -> 491.29949 | F15: ='1 - Titoli e shock'!N24 -> 0.033494512
A16: ='1 - Titoli e shock'!A25 -> BTP 3,15% nov 2031 | B16: ='1 - Titoli e shock'!D25 -> 48167 | C16: ='1 - Titoli e shock'!E25 -> 96.56 | D16: ='5 - Motore flussi'!C38*100 -> 20428.198 | E16: =D16*'1 - Titoli e shock'!C25*(1-'1 - Titoli e shock'!$B$8) -> 563.05222 | F16: ='1 - Titoli e shock'!N25 -> 0.03451255
A17: ='1 - Titoli e shock'!A26 -> BTP 3,25% nov 2032 | B17: ='1 - Titoli e shock'!D26 -> 48533 | C17: ='1 - Titoli e shock'!E26 -> 95.9 | D17: ='5 - Motore flussi'!C39*100 -> 20557.827 | E17: =D17*'1 - Titoli e shock'!C26*(1-'1 - Titoli e shock'!$B$8) -> 584.61319 | F17: ='1 - Titoli e shock'!N26 -> 0.035538463
A18: ='1 - Titoli e shock'!A27 -> BTP 4,35% nov 2033 | B18: ='1 - Titoli e shock'!D27 -> 48884 | C18: ='1 - Titoli e shock'!E27 -> 101.22 | D18: ='5 - Motore flussi'!C40*100 -> 19372.086 | E18: =D18*'1 - Titoli e shock'!C27*(1-'1 - Titoli e shock'!$B$8) -> 737.35004 | F18: ='1 - Titoli e shock'!N27 -> 0.036407136
A19: ='1 - Titoli e shock'!A28 -> BTP 3,85% feb 2035 | B19: ='1 - Titoli e shock'!D28 -> 49341 | C19: ='1 - Titoli e shock'!E28 -> 96.91 | D19: ='5 - Motore flussi'!C41*100 -> 20463.185 | E19: =D19*'1 - Titoli e shock'!C28*(1-'1 - Titoli e shock'!$B$8) -> 689.35356 | F19: ='1 - Titoli e shock'!N28 -> 0.038011187
A20: ='1 - Titoli e shock'!A29 -> BTP 3,60% ott 2035 | B20: ='1 - Titoli e shock'!D29 -> 49583 | C20: ='1 - Titoli e shock'!E29 -> 94.5 | D20: ='5 - Motore flussi'!C42*100 -> 21124.227 | E20: =D20*'1 - Titoli e shock'!C29*(1-'1 - Titoli e shock'!$B$8) -> 665.41314 | F20: ='1 - Titoli e shock'!N29 -> 0.03852235
A21: ='1 - Titoli e shock'!A30 -> BTP 4,00% ott 2036 | B21: ='1 - Titoli e shock'!D30 -> 49949 | C21: ='1 - Titoli e shock'!E30 -> 96.5 | D21: ='5 - Motore flussi'!C43*100 -> 20682.993 | E21: =D21*'1 - Titoli e shock'!C30*(1-'1 - Titoli e shock'!$B$8) -> 723.90477 | F21: ='1 - Titoli e shock'!N30 -> 0.039288243
A22: Totale scaletta: cedola netta a regime (€) e in % del capitale | E22: =SUM(E12:E21) -> 5953.4679 | F22: =E22/B7 -> 0.029767339
A23: Titolo unico 2053: nominale (€) e cedola netta annua a regime (€) | D23: ='1 - Titoli e shock'!R33 -> 214448.4 | E23: =D23*'1 - Titoli e shock'!C33*(1-'1 - Titoli e shock'!$B$8) -> 8443.9058
A25: Confronto a H anni: quattro ipotesi di tassi (curva ferma = Δ 0; Δ in punti)
A26: Misura | B26: ='5 - Motore flussi'!F5 -> -1 | C26: ='5 - Motore flussi'!G5 -> 0 | D26: ='5 - Motore flussi'!H5 -> 1 | E26: ='5 - Motore flussi'!I5 -> 2
A27: Scaletta
A28: reddito 1° anno | B28: ='5 - Motore flussi'!F9 -> 6138.1113 | C28: ='5 - Motore flussi'!G9 -> 6138.1113 | D28: ='5 - Motore flussi'!H9 -> 6138.1113 | E28: ='5 - Motore flussi'!I9 -> 6138.1113
A29: reddito medio annuo | B29: ='5 - Motore flussi'!F11 -> 6298.1168 | C29: ='5 - Motore flussi'!G11 -> 7035.8806 | D29: ='5 - Motore flussi'!H11 -> 7770.1223 | E29: ='5 - Motore flussi'!I11 -> 8500.892
A30: valore netto finale | B30: ='5 - Motore flussi'!F13 -> 204449.87 | C30: ='5 - Motore flussi'!G13 -> 204816.53 | D30: ='5 - Motore flussi'!H13 -> 205181.45 | E30: ='5 - Motore flussi'!I13 -> 205544.64
A31: rendimento annuo XIRR, prima del bollo | B31: ='5 - Motore flussi'!F14 -> 0.03382008 | C31: ='5 - Motore flussi'!G14 -> 0.037477511 | D31: ='5 - Motore flussi'!H14 -> 0.041074722 | E31: ='5 - Motore flussi'!I14 -> 0.044613503
A32: rendimento annuo XIRR, dopo il bollo | B32: ='5 - Motore flussi'!F15 -> 0.031754445 | C32: ='5 - Motore flussi'!G15 -> 0.035456521 | D32: ='5 - Motore flussi'!H15 -> 0.039096254 | E32: ='5 - Motore flussi'!I15 -> 0.042675562
A33: prelievo annuo che lascia 200.000 € di valore di mercato a H anni | B33: ='5 - Motore flussi'!F16 -> 6743.1034 | C33: ='5 - Motore flussi'!G16 -> 7517.5338 | D33: ='5 - Motore flussi'!H16 -> 8288.2671 | E33: ='5 - Motore flussi'!I16 -> 9055.3558
A34: Titolo 2053
A35: reddito 1° anno | B35: ='5 - Motore flussi'!F17 -> 8503.5567 | C35: ='5 - Motore flussi'!G17 -> 8503.5567 | D35: ='5 - Motore flussi'!H17 -> 8503.5567 | E35: ='5 - Motore flussi'!I17 -> 8503.5567
A36: reddito medio annuo | B36: ='5 - Motore flussi'!F19 -> 8449.8709 | C36: ='5 - Motore flussi'!G19 -> 8449.8709 | D36: ='5 - Motore flussi'!H19 -> 8449.8709 | E36: ='5 - Motore flussi'!I19 -> 8449.8709
A37: valore netto finale | B37: ='5 - Motore flussi'!F21 -> 229132.96 | C37: ='5 - Motore flussi'!G21 -> 206816.27 | D37: ='5 - Motore flussi'!H21 -> 185862.28 | E37: ='5 - Motore flussi'!I21 -> 166942
A38: rendimento annuo XIRR, prima del bollo | B38: ='5 - Motore flussi'!F22 -> 0.05424244 | C38: ='5 - Motore flussi'!G22 -> 0.045555551 | D38: ='5 - Motore flussi'!H22 -> 0.036708501 | E38: ='5 - Motore flussi'!I22 -> 0.02803581
A39: rendimento annuo XIRR, dopo il bollo | B39: ='5 - Motore flussi'!F23 -> 0.052045835 | C39: ='5 - Motore flussi'!G23 -> 0.043530076 | D39: ='5 - Motore flussi'!H23 -> 0.034823521 | E39: ='5 - Motore flussi'!I23 -> 0.026268684
A40: prelievo annuo che lascia 200.000 € di valore di mercato a H anni | B40: ='5 - Motore flussi'!F24 -> 11363.167 | C40: ='5 - Motore flussi'!G24 -> 9131.4974 | D40: ='5 - Motore flussi'!H24 -> 7036.0994 | E40: ='5 - Motore flussi'!I24 -> 5144.0707
A42: Pareggio: di quanto devono salire i tassi perché la scaletta renda come il 2053
A43: Pareggio (Δ in punti, interpolato sulla griglia del foglio 5) | B43: ='5 - Motore flussi'!F29 -> 0.65441041
A44: Cambiando H (7, 10, 14, 16) o il tasso di reinvestimento nel foglio 1 il pareggio si ricalcola: è un intervallo, non un numero. Il prelievo che lascia 200.000 € di valore di mercato a H anni non è un rendimento: oltre la cedola, per il titolo 2053 richiede vendite parziali al prezzo del giorno. Per la vendita a 7 anni del video impostare H = 7; per l'intervallo del pareggio cambiare il reinvestimento (foglio 1, B12) a 4,00% e 5,04%.
...

Sheet 3 - Inflazione e vendita
A1: La cedola nel tempo e la vendita a 80 anni (ipotesi di scena)
A2: Strumento informativo / divulgativo. NON è consulenza finanziaria. I valori sono indicativi al 2026 e vanno verificati col tuo consulente.
A4: Ipotesi
A5: Inflazione annua (canone del canale) | B5: 0.02
A6: Pensione netta al mese (€, 12 mensilità) | B6: 1350
A7: Fabbisogno in una volta (€): ipotesi di scena, non un costo di RSA | B7: 60000
A8: Età oggi | B8: 73
A9: Capitale (€) | B9: ='1 - Titoli e shock'!$B$7 -> 200000
A10: Nominale del titolo 2053 acquistato (€) | B10: ='1 - Titoli e shock'!R33 -> 214448.4
A11: Cedola netta annua a regime (€) | B11: =B10*'1 - Titoli e shock'!C33*(1-'1 - Titoli e shock'!$B$8) -> 8443.9058
A12: Cedola netta al mese (€), fissa fino al 01/10/2053 | B12: =B11/12 -> 703.65882
A14: Cedola e pensione negli anni, in euro di oggi
A15: Anni da oggi | B15: 7 | C15: 10 | D15: 14 | E15: 27
A16: Età | B16: =$B$8+B15 -> 80 | C16: =$B$8+C15 -> 83 | D16: =$B$8+D15 -> 87 | E16: =$B$8+E15 -> 100
A17: Fattore dei prezzi (1 + inflazione)^anni | B17: =(1+$B$5)^B15 -> 1.1486857 | C17: =(1+$B$5)^C15 -> 1.2189944 | D17: =(1+$B$5)^D15 -> 1.3194788 | E17: =(1+$B$5)^E15 -> 1.7068865
A18: Cedola netta al mese in euro di oggi (€) | B18: =$B$12/B17 -> 612.57735 | C18: =$B$12/C17 -> 577.24532 | D18: =$B$12/D17 -> 533.28545 | E18: =$B$12/E17 -> 412.24699
A19: Cedola netta all'anno in euro di oggi (€) | B19: =$B$11/B17 -> 7350.9282 | C19: =$B$11/C17 -> 6926.9438 | D19: =$B$11/D17 -> 6399.4253 | E19: =$B$11/E17 -> 4946.9639
A20: Potere d'acquisto perso dalla cedola | B20: =1-1/B17 -> 0.12943982 | C20: =1-1/C17 -> 0.1796517 | D20: =1-1/D17 -> 0.24212498 | E20: =1-1/E17 -> 0.41413796
A21: Pensione netta rivalutata come i prezzi, al mese (€ nominali) | B21: =$B$6*B17 -> 1550.7257 | C21: =$B$6*C17 -> 1645.6425 | D21: =$B$6*D17 -> 1781.2963 | E21: =$B$6*E17 -> 2304.2967
A23: Rendimento reale a scadenza del 2053 (inflazione costante)
A24: Netto effettivo, bollo escluso | B24: ='1 - Titoli e shock'!N33 -> 0.044093086
A25: Netto reale, bollo escluso | B25: =(1+B24)/(1+B5)-1 -> 0.023620672
A26: Netto effettivo dopo il bollo | B26: ='1 - Titoli e shock'!O33 -> 0.042232286
A27: Netto reale dopo il bollo | B27: =(1+B26)/(1+B5)-1 -> 0.021796359
A29: Vendita dopo N anni: prezzo netto di imposta (prezzo secco + rateo − imposta sul guadagno e sul rateo)
A30: Anni alla vendita | B30: 7
A31: Data della vendita | B31: =EDATE('1 - Titoli e shock'!$B$6,12*B30) -> 48871
A32: Δ dei tassi (punti) | B32: -1 | C32: 0 | D32: 1 | E32: 2
A34: BTP ott 2053
A35: vita residua alla vendita (anni) | B35: =('1 - Titoli e shock'!D33-$B$31)/365.25 -> 19.950719
A36: rendimento di curva alla vendita | B36: =IF(B35<='1 - Titoli e shock'!$P$21,'1 - Titoli e shock'!$K$21,IF(B35>='1 - Titoli e shock'!$P$35,'1 - Titoli e shock'!$K$35,INDEX('1 - Titoli e shock'!$K$21:$K$35,MATCH(B35,'1 - Titoli e shock'!$P$21:$P$35,1))+(INDEX('1 - Titoli e shock'!$K$21:$K$35,MATCH(B35,'1 - Titoli e shock'!$P$21:$P$35,1)+1)-INDEX('1 - Titoli e shock'!$K$21:$K$35,MATCH(B35,'1 - Titoli e shock'!$P$21:$P$35,1)))*(B35-INDEX('1 - Titoli e shock'!$P$21:$P$35,MATCH(B35,'1 - Titoli e shock'!$P$21:$P$35,1)))/(INDEX('1 - Titoli e shock'!$P$21:$P$35,MATCH(B35,'1 - Titoli e shock'!$P$21:$P$35,1)+1)-INDEX('1 - Titoli e shock'!$P$21:$P$35,MATCH(B35,'1 - Titoli e shock'!$P$21:$P$35,1))))) -> 0.049051992
A37: rateo lordo per 100 alla vendita | B37: ='1 - Titoli e shock'!C33*100/2*COUPDAYBS($B$31,'1 - Titoli e shock'!D33,2,1)/COUPDAYS($B$31,'1 - Titoli e shock'!D33,2,1) -> 0.22252747
A38: prezzo secco alla vendita | B38: =PRICE($B$31,'1 - Titoli e shock'!$D$33,'1 - Titoli e shock'!$C$33,2*((1+$B$36+B$32/100)^0.5-1),100,2,1) -> 108.73185 | C38: =PRICE($B$31,'1 - Titoli e shock'!$D$33,'1 - Titoli e shock'!$C$33,2*((1+$B$36+C$32/100)^0.5-1),100,2,1) -> 95.598566 | D38: =PRICE($B$31,'1 - Titoli e shock'!$D$33,'1 - Titoli e shock'!$C$33,2*((1+$B$36+D$32/100)^0.5-1),100,2,1) -> 84.532167 | E38: =PRICE($B$31,'1 - Titoli e shock'!$D$33,'1 - Titoli e shock'!$C$33,2*((1+$B$36+E$32/100)^0.5-1),100,2,1) -> 75.171704
A39: imposta per 100 (guadagno sul prezzo di acquisto + rateo) | B39: ='1 - Titoli e shock'!$B$8*(MAX(0,B38-'1 - Titoli e shock'!$E$33)+$B$37) -> 1.9892968 | C39: ='1 - Titoli e shock'!$B$8*(MAX(0,C38-'1 - Titoli e shock'!$E$33)+$B$37) -> 0.34763671 | D39: ='1 - Titoli e shock'!$B$8*(MAX(0,D38-'1 - Titoli e shock'!$E$33)+$B$37) -> 0.027815934 | E39: ='1 - Titoli e shock'!$B$8*(MAX(0,E38-'1 - Titoli e shock'!$E$33)+$B$37) -> 0.027815934
A40: P_netto per 100 = prezzo + rateo − imposta | B40: =B38+$B$37-B39 -> 106.96508 | C40: =C38+$B$37-C39 -> 95.473457 | D40: =D38+$B$37-D39 -> 84.726879 | E40: =E38+$B$37-E39 -> 75.366415
A41: valore netto del portafoglio (€) | B41: =B40*'1 - Titoli e shock'!$R$33/100 -> 229384.9 | C41: =C40*'1 - Titoli e shock'!$R$33/100 -> 204741.3 | D41: =D40*'1 - Titoli e shock'!$R$33/100 -> 181695.44 | E41: =E40*'1 - Titoli e shock'!$R$33/100 -> 161622.07
A42: cedole nette incassate fino alla vendita (€) | B42: ='1 - Titoli e shock'!R33/100*'1 - Titoli e shock'!C33*100/2*(2*$B$30-'1 - Titoli e shock'!$B$8*(2*$B$30-1+((COUPNCD('1 - Titoli e shock'!$B$6,'1 - Titoli e shock'!D33,2,1)-'1 - Titoli e shock'!$B$6)/(COUPNCD('1 - Titoli e shock'!$B$6,'1 - Titoli e shock'!D33,2,1)-COUPPCD('1 - Titoli e shock'!$B$6,'1 - Titoli e shock'!D33,2,1))))) -> 59166.992
A44: BTP ott 2041
A45: vita residua alla vendita (anni) | B45: =('1 - Titoli e shock'!D31-$B$31)/365.25 -> 7.9507187
A46: rendimento di curva alla vendita | B46: =IF(B45<='1 - Titoli e shock'!$P$21,'1 - Titoli e shock'!$K$21,IF(B45>='1 - Titoli e shock'!$P$35,'1 - Titoli e shock'!$K$35,INDEX('1 - Titoli e shock'!$K$21:$K$35,MATCH(B45,'1 - Titoli e shock'!$P$21:$P$35,1))+(INDEX('1 - Titoli e shock'!$K$21:$K$35,MATCH(B45,'1 - Titoli e shock'!$P$21:$P$35,1)+1)-INDEX('1 - Titoli e shock'!$K$21:$K$35,MATCH(B45,'1 - Titoli e shock'!$P$21:$P$35,1)))*(B45-INDEX('1 - Titoli e shock'!$P$21:$P$35,MATCH(B45,'1 - Titoli e shock'!$P$21:$P$35,1)))/(INDEX('1 - Titoli e shock'!$P$21:$P$35,MATCH(B45,'1 - Titoli e shock'!$P$21:$P$35,1)+1)-INDEX('1 - Titoli e shock'!$P$21:$P$35,MATCH(B45,'1 - Titoli e shock'!$P$21:$P$35,1))))) -> 0.043018357
...

Sheet 4 - Vita e successione
A1: Probabilità di essere vivi e successione dei titoli di Stato
A2: Strumento informativo / divulgativo. NON è consulenza finanziaria. I valori sono indicativi al 2026 e vanno verificati col tuo consulente.
A4: Sopravviventi per 100.000 nati, tavola di periodo ISTAT 2025, Italia (dati di fonte; csv ISTAT, sha256 ea4c097efc4f2004…)
A5: Età | B5: Sopravviventi uomini l(x) | C5: Sopravviventi donne l(x) | D5: P(vivo a x | 73) uomini | E5: P(vivo a x | 73) donne
A6: 73 | B6: 81093 | C6: 88718 | D6: =B6/B$6 -> 1 | E6: =C6/C$6 -> 1
A7: 74 | B7: 79402 | C7: 87651 | D7: =B7/B$6 -> 0.9791474 | E7: =C7/C$6 -> 0.98797313
A8: 75 | B8: 77532 | C8: 86446 | D8: =B8/B$6 -> 0.95608746 | E8: =C8/C$6 -> 0.97439077
A9: 76 | B9: 75512 | C9: 85107 | D9: =B9/B$6 -> 0.93117778 | E9: =C9/C$6 -> 0.959298
A10: 77 | B10: 73298 | C10: 83609 | D10: =B10/B$6 -> 0.9038758 | E10: =C10/C$6 -> 0.94241304
A11: 78 | B11: 70994 | C11: 81960 | D11: =B11/B$6 -> 0.87546397 | E11: =C11/C$6 -> 0.92382606
A12: 79 | B12: 68531 | C12: 80119 | D12: =B12/B$6 -> 0.84509144 | E12: =C12/C$6 -> 0.90307491
A13: 80 | B13: 65866 | C13: 78052 | D13: =B13/B$6 -> 0.81222794 | E13: =C13/C$6 -> 0.87977637
A14: 81 | B14: 62947 | C14: 75715 | D14: =B14/B$6 -> 0.77623223 | E14: =C14/C$6 -> 0.85343448
A15: 82 | B15: 59800 | C15: 73148 | D15: =B15/B$6 -> 0.73742493 | E15: =C15/C$6 -> 0.8245001
A16: 83 | B16: 56305 | C16: 70245 | D16: =B16/B$6 -> 0.69432627 | E16: =C16/C$6 -> 0.79177844
A17: 84 | B17: 52600 | C17: 67053 | D17: =B17/B$6 -> 0.64863798 | E17: =C17/C$6 -> 0.75579927
... A33: 100 | B33: 1768 | C33: 4057 | D33: =B33/B$6 -> 0.021802128 | E33: =C33/C$6 -> 0.045729164
A35: Speranza di vita a 73 anni (anni; dato di fonte): uomini e donne | B35: 13.791 | C35: 15.986
A36: Dati di fonte incollati (non formule). La tavola di periodo non conta i miglioramenti futuri della sopravvivenza: stima prudente.
A38: Probabilità di essere vivi a una certa età, dato di avere 73 anni (uomo)
A39: Età | B39: 80 | C39: 90 | D39: 99 | E39: 100
A40: P(vivo, dato 73) | B40: =INDEX($D$6:$D$33,MATCH(B39,$A$6:$A$33,0)) -> 0.81222794 | C40: =INDEX($D$6:$D$33,MATCH(C39,$A$6:$A$33,0)) -> 0.34280394 | D40: =INDEX($D$6:$D$33,MATCH(D39,$A$6:$A$33,0)) -> 0.032333247 | E40: =INDEX($D$6:$D$33,MATCH(E39,$A$6:$A$33,0)) -> 0.021802128
A42: Alla scadenza del titolo 2053
A43: Età alla scadenza (anni) | B43: ='3 - Inflazione e vendita'!B8+('1 - Titoli e shock'!D33-'1 - Titoli e shock'!$B$6)/365.25 -> 99.951403 | C43: =INT(B43)&" anni e "&ROUND(MOD(B43,1)*12,0)&" mesi" -> 99 anni e 11 mesi
A44: P(vivo alla scadenza), uomo, interpolazione fra due età | B44: =IF(B43>=100,$D$33,(INDEX($B$6:$B$33,MATCH(INT(B43),$A$6:$A$33,0))+(B43-INT(B43))*(INDEX($B$6:$B$33,MATCH(INT(B43),$A$6:$A$33,0)+1)-INDEX($B$6:$B$33,MATCH(INT(B43),$A$6:$A$33,0))))/$B$6) -> 0.022313908
A45: Probabilità che il titolo passi agli eredi prima della scadenza | B45: =1-B44 -> 0.97768609
A47: Successione: i titoli di Stato non entrano nell'attivo ereditario (art. 12 D.Lgs. 346/1990; dal 1/1/2027 art. 97 D.Lgs. 123/2025)
A48: Erede | B48: Franchigia per erede (€) | C48: Aliquota sopra la franchigia
A49: 1 - Coniuge o figli (linea retta) | B49: 1000000 | C49: 0.04
A50: 2 - Fratelli e sorelle | B50: 100000 | C50: 0.06
A51: 3 - Altri parenti fino al 4° grado | B51: 0 | C51: 0.06
A52: 4 - Altri soggetti | B52: 0 | C52: 0.08
A54: Tipo di erede (1-4) | B54: 1
A55: Altri beni ricevuti dall'erede, titoli di Stato esclusi (€) | B55: 0
A56: Titoli di Stato ricevuti (€) | B56: ='1 - Titoli e shock'!$B$7 -> 200000
A57: Imposta oggi (titoli fuori dall'attivo) | B57: =MAX(0,B55-INDEX($B$49:$B$52,B54))*INDEX($C$49:$C$52,B54) -> 0
A58: Imposta se i titoli fossero nell'attivo (confronto) | B58: =MAX(0,B55+B56-INDEX($B$49:$B$52,B54))*INDEX($C$49:$C$52,B54) -> 0
A59: Effetto dell'esclusione dei titoli (€) | B59: =B58-B57 -> 0
A60: Per figli e coniuge 200.000 € stanno sotto la franchigia anche senza l'esclusione: conta per fratelli, nipoti, altri. L'esclusione riguarda l'attivo ereditario: dichiarazione di successione e altre imposte restano. Fotografia di ottobre 2026, non regime stabile.

Sheet 5 - Motore flussi
A1: Motore dei flussi: scaletta contro titolo unico, per scenario di tassi
A2: Strumento informativo / divulgativo. NON è consulenza finanziaria. I valori sono indicativi al 2026 e vanno verificati col tuo consulente.
A3: Motore del calcolo, non modificare. Un flusso per riga, datato; XIRR su 365 giorni. Struttura calibrata sul regolamento del 19/10/2026 e su H fino a 16 anni.
A4: Scenari di tassi (Δ in punti, giallo) e tasso nominale di reinvestimento
A5: Δ (punti) | F5: -1 | G5: 0 | H5: 1 | I5: 2 | J5: 0.25 | K5: 0.5 | L5: 0.6 | M5: 0.7 | N5: 0.8 | O5: 0.9 | P5: 1.1 | Q5: 1.2 | R5: 1.3 | S5: 1.4 | T5: 1.5 | U5: 3
A6: Tasso nominale di reinvestimento | F6: =2*((1+'1 - Titoli e shock'!$B$13+F5/100)^0.5-1) -> 0.034580581 | G6: =2*((1+'1 - Titoli e shock'!$B$13+G5/100)^0.5-1) -> 0.044386984 | H6: =2*((1+'1 - Titoli e shock'!$B$13+H5/100)^0.5-1) -> 0.054146573 | I6: =2*((1+'1 - Titoli e shock'!$B$13+I5/100)^0.5-1) -> 0.06386001 | J6: =2*((1+'1 - Titoli e shock'!$B$13+J5/100)^0.5-1) -> 0.046831244 | K6: =2*((1+'1 - Titoli e shock'!$B$13+K5/100)^0.5-1) -> 0.049272588 | L6: =2*((1+'1 - Titoli e shock'!$B$13+L5/100)^0.5-1) -> 0.050248312 | M6: =2*((1+'1 - Titoli e shock'!$B$13+M5/100)^0.5-1) -> 0.051223572 | ... U6: =2*((1+'1 - Titoli e shock'!$B$13+U5/100)^0.5-1) -> 0.073527946
A8: Risultati per scenario: scaletta (9-16), titolo unico 2053 (17-24), differenza e pareggio (25-29)
A9: scaletta: reddito 1° anno | F9: =SUMIFS(F$170:F$512,$A$170:$A$512,"cedola*",$D$170:$D$512,1) -> 6138.1113 | G9: =SUMIFS(G$170:G$512,$A$170:$A$512,"cedola*",$D$170:$D$512,1) -> 6138.1113 | H9: =SUMIFS(H$170:H$512,$A$170:$A$512,"cedola*",$D$170:$D$512,1) -> 6138.1113 | I9: =SUMIFS(I$170:I$512,$A$170:$A$512,"cedola*",$D$170:$D$512,1) -> 6138.1113 | J9: =SUMIFS(J$170:J$512,$A$170:$A$512,"cedola*",$D$170:$D$512,1) -> 6138.1113 | K9: =SUMIFS(K$170:K$512,$A$170:$A$512,"cedola*",$D$170:$D$512,1) -> 6138.1113 | L9: =SUMIFS(L$170:L$512,$A$170:$A$512,"cedola*",$D$170:$D$512,1) -> 6138.1113 | M9: =SUMIFS(M$170:M$512,$A$170:$A$512,"cedola*",$D$170:$D$512,1) -> 6138.1113 | ... U9: =SUMIFS(U$170:U$512,$A$170:$A$512,"cedola*",$D$170:$D$512,1) -> 6138.1113
A10: scaletta: cedole totali | F10: =SUMIFS(F$170:F$512,$A$170:$A$512,"cedola*") -> 62981.168 | G10: =SUMIFS(G$170:G$512,$A$170:$A$512,"cedola*") -> 70358.806 | H10: =SUMIFS(H$170:H$512,$A$170:$A$512,"cedola*") -> 77701.223 | I10: =SUMIFS(I$170:I$512,$A$170:$A$512,"cedola*") -> 85008.92 | J10: =SUMIFS(J$170:J$512,$A$170:$A$512,"cedola*") -> 72197.692 | K10: =SUMIFS(K$170:K$512,$A$170:$A$512,"cedola*") -> 74034.386 | L10: =SUMIFS(L$170:L$512,$A$170:$A$512,"cedola*") -> 74768.451 | M10: =SUMIFS(M$170:M$512,$A$170:$A$512,"cedola*") -> 75502.166 | ... U10: =SUMIFS(U$170:U$512,$A$170:$A$512,"cedola*") -> 92282.385
A11: scaletta: reddito medio annuo | F11: =F10/'1 - Titoli e shock'!$B$11 -> 6298.1168 | G11: =G10/'1 - Titoli e shock'!$B$11 -> 7035.8806 | H11: =H10/'1 - Titoli e shock'!$B$11 -> 7770.1223 | I11: =I10/'1 - Titoli e shock'!$B$11 -> 8500.892 | J11: =J10/'1 - Titoli e shock'!$B$11 -> 7219.7692 | K11: =K10/'1 - Titoli e shock'!$B$11 -> 7403.4386 | L11: =L10/'1 - Titoli e shock'!$B$11 -> 7476.8451 | M11: =M10/'1 - Titoli e shock'!$B$11 -> 7550.2166 | ... U11: =U10/'1 - Titoli e shock'!$B$11 -> 9228.2385
A12: scaletta: rimborsi in cassa | F12: =SUMIFS(F$170:F$512,$A$170:$A$512,"rimborso reinv.") -> 0 | G12: =SUMIFS(G$170:G$512,$A$170:$A$512,"rimborso reinv.") -> 0 | H12: =SUMIFS(H$170:H$512,$A$170:$A$512,"rimborso reinv.") -> 0 | I12: =SUMIFS(I$170:I$512,$A$170:$A$512,"rimborso reinv.") -> 0 | J12: =SUMIFS(J$170:J$512,$A$170:$A$512,"rimborso reinv.") -> 0 | K12: =SUMIFS(K$170:K$512,$A$170:$A$512,"rimborso reinv.") -> 0 | L12: =SUMIFS(L$170:L$512,$A$170:$A$512,"rimborso reinv.") -> 0 | M12: =SUMIFS(M$170:M$512,$A$170:$A$512,"rimborso reinv.") -> 0 | ... U12: =SUMIFS(U$170:U$512,$A$170:$A$512,"rimborso reinv.") -> 0
A13: scaletta: valore netto finale | F13: =F69 -> 204449.87 | G13: =G69 -> 204816.53 | H13: =H69 -> 205181.45 | I13: =I69 -> 205544.64 | J13: =J69 -> 204907.92 | K13: =K69 -> 204999.21 | L13: =L69 -> 205035.69 | M13: =M69 -> 205072.16 | ... U13: =U69 -> 205906.13
A14: scaletta: XIRR prima del bollo | F14: =XIRR(F$170:F$496,$C$170:$C$496) -> 0.03382008 | G14: =XIRR(G$170:G$496,$C$170:$C$496) -> 0.037477511 | H14: =XIRR(H$170:H$496,$C$170:$C$496) -> 0.041074722 | I14: =XIRR(I$170:I$496,$C$170:$C$496) -> 0.044613503 | J14: =XIRR(J$170:J$496,$C$170:$C$496) -> 0.038382388 | K14: =XIRR(K$170:K$496,$C$170:$C$496) -> 0.03928353 | L14: =XIRR(L$170:L$496,$C$170:$C$496) -> 0.039642948 | M14: =XIRR(M$170:M$496,$C$170:$C$496) -> 0.040001774 | ... U14: =XIRR(U$170:U$496,$C$170:$C$496) -> 0.048095578
A15: scaletta: XIRR dopo il bollo | F15: =XIRR(F$170:F$512,$C$170:$C$512) -> 0.031754445 | G15: =XIRR(G$170:G$512,$C$170:$C$512) -> 0.035456521 | H15: =XIRR(H$170:H$512,$C$170:$C$512) -> 0.039096254 | I15: =XIRR(I$170:I$512,$C$170:$C$512) -> 0.042675562
A16: scaletta: prelievo annuo che lascia 200.000 € di valore di mercato a H anni | F16: =(F10+F12+F13-'1 - Titoli e shock'!$B$7)/'1 - Titoli e shock'!$B$11 -> 6743.1034 | G16: =(G10+G12+G13-'1 - Titoli e shock'!$B$7)/'1 - Titoli e shock'!$B$11 -> 7517.5338 | H16: =(H10+H12+H13-'1 - Titoli e shock'!$B$7)/'1 - Titoli e shock'!$B$11 -> 8288.2671 | I16: =(I10+I12+I13-'1 - Titoli e shock'!$B$7)/'1 - Titoli e shock'!$B$11 -> 9055.3558 | J16: =(J10+J12+J13-'1 - Titoli e shock'!$B$7)/'1 - Titoli e shock'!$B$11 -> 7710.5616 | K16: =(K10+K12+K13-'1 - Titoli e shock'!$B$7)/'1 - Titoli e shock'!$B$11 -> 7903.3593 | L16: =(L10+L12+L13-'1 - Titoli e shock'!$B$7)/'1 - Titoli e shock'!$B$11 -> 7980.414 | M16: =(M10+M12+M13-'1 - Titoli e shock'!$B$7)/'1 - Titoli e shock'!$B$11 -> 8057.4322 | ... U16: =(U10+U12+U13-'1 - Titoli e shock'!$B$7)/'1 - Titoli e shock'!$B$11 -> 9818.8512
A17: 2053: reddito 1° anno | F17: =SUMIFS(F$515:F$564,$A$515:$A$564,"cedola*",$D$515:$D$564,1) -> 8503.5567 | G17: =SUMIFS(G$515:G$564,$A$515:$A$564,"cedola*",$D$515:$D$564,1) -> 8503.5567 | H17: =SUMIFS(H$515:H$564,$A$515:$A$564,"cedola*",$D$515:$D$564,1) -> 8503.5567 | I17: =SUMIFS(I$515:I$564,$A$515:$A$564,"cedola*",$D$515:$D$564,1) -> 8503.5567 | J17: =SUMIFS(J$515:J$564,$A$515:$A$564,"cedola*",$D$515:$D$564,1) -> 8503.5567 | K17: =SUMIFS(K$515:K$564,$A$515:$A$564,"cedola*",$D$515:$D$564,1) -> 8503.5567 | L17: =SUMIFS(L$515:L$564,$A$515:$A$564,"cedola*",$D$515:$D$564,1) -> 8503.5567 | M17: =SUMIFS(M$515:M$564,$A$515:$A$564,"cedola*",$D$515:$D$564,1) -> 8503.5567 | ... U17: =SUMIFS(U$515:U$564,$A$515:$A$564,"cedola*",$D$515:$D$564,1) -> 8503.5567
A18: 2053: cedole totali | F18: =SUMIFS(F$515:F$564,$A$515:$A$564,"cedola*") -> 84498.709 | G18: =SUMIFS(G$515:G$564,$A$515:$A$564,"cedola*") -> 84498.709 | H18: =SUMIFS(H$515:H$564,$A$515:$A$564,"cedola*") -> 84498.709 | I18: =SUMIFS(I$515:I$564,$A$515:$A$564,"cedola*") -> 84498.709 | J18: =SUMIFS(J$515:J$564,$A$515:$A$564,"cedola*") -> 84498.709 | K18: =SUMIFS(K$515:K$564,$A$515:$A$564,"cedola*") -> 84498.709 | L18: =SUMIFS(L$515:L$564,$A$515:$A$564,"cedola*") -> 84498.709 | M18: =SUMIFS(M$515:M$564,$A$515:$A$564,"cedola*") -> 84498.709 | ... U18: =SUMIFS(U$515:U$564,$A$515:$A$564,"cedola*") -> 84498.709
A19: 2053: reddito medio annuo | F19: =F18/'1 - Titoli e shock'!$B$11 -> 8449.8709 | G19: =G18/'1 - Titoli e shock'!$B$11 -> 8449.8709 | H19: =H18/'1 - Titoli e shock'!$B$11 -> 8449.8709 | I19: =I18/'1 - Titoli e shock'!$B$11 -> 8449.8709 | J19: =J18/'1 - Titoli e shock'!$B$11 -> 8449.8709 | K19: =K18/'1 - Titoli e shock'!$B$11 -> 8449.8709 | L19: =L18/'1 - Titoli e shock'!$B$11 -> 8449.8709 | M19: =M18/'1 - Titoli e shock'!$B$11 -> 8449.8709 | ... U19: =U18/'1 - Titoli e shock'!$B$11 -> 8449.8709
A20: 2053: rimborsi in cassa | F20: =SUMIFS(F$515:F$564,$A$515:$A$564,"rimborso reinv.") -> 0 | G20: =SUMIFS(G$515:G$564,$A$515:$A$564,"rimborso reinv.") -> 0 | H20: =SUMIFS(H$515:H$564,$A$515:$A$564,"rimborso reinv.") -> 0 | I20: =SUMIFS(I$515:I$564,$A$515:$A$564,"rimborso reinv.") -> 0 | J20: =SUMIFS(J$515:J$564,$A$515:$A$564,"rimborso reinv.") -> 0 | K20: =SUMIFS(K$515:K$564,$A$515:$A$564,"rimborso reinv.") -> 0 | L20: =SUMIFS(L$515:L$564,$A$515:$A$564,"rimborso reinv.") -> 0 | M20: =SUMIFS(M$515:M$564,$A$515:$A$564,"rimborso reinv.") -> 0 | ... U20: =SUMIFS(U$515:U$564,$A$515:$A$564,"rimborso reinv.") -> 0
A21: 2053: valore netto finale | F21: =F70 -> 229132.96 | G21: =G70 -> 206816.27 | H21: =H70 -> 185862.28 | I21: =I70 -> 166942 | J21: =J70 -> 201745.38 | K21: =K70 -> 196421.23 | L21: =L70 -> 194246.17 | M21: =M70 -> 192103.27 | ... U21: =U70 -> 150576.55
A22: 2053: XIRR prima del bollo | F22: =XIRR(F$515:F$548,$C$515:$C$548) -> 0.05424244 | G22: =XIRR(G$515:G$548,$C$515:$C$548) -> 0.045555551 | H22: =XIRR(H$515:H$548,$C$515:$C$548) -> 0.036708501 | I22: =XIRR(I$515:I$548,$C$515:$C$548) -> 0.02803581 | J22: =XIRR(J$515:J$548,$C$515:$C$548) -> 0.043480486 | K22: =XIRR(K$515:K$548,$C$515:$C$548) -> 0.04125782 | L22: =XIRR(L$515:L$548,$C$515:$C$548) -> 0.040336383 | M22: =XIRR(M$515:M$548,$C$515:$C$548) -> 0.039420755 | ... U22: =XIRR(U$515:U$548,$C$515:$C$548) -> 0.01991141
A23: 2053: XIRR dopo il bollo | F23: =XIRR(F$515:F$564,$C$515:$C$564) -> 0.052045835 | G23: =XIRR(G$515:G$564,$C$515:$C$564) -> 0.043530076 | H23: =XIRR(H$515:H$564,$C$515:$C$564) -> 0.034823521 | I23: =XIRR(I$515:I$564,$C$515:$C$564) -> 0.026268684
A24: 2053: prelievo annuo che lascia 200.000 € di valore di mercato a H anni | F24: =(F18+F20+F21-'1 - Titoli e shock'!$B$7)/'1 - Titoli e shock'!$B$11 -> 11363.167 | G24: =(G18+G20+G21-'1 - Titoli e shock'!$B$7)/'1 - Titoli e shock'!$B$11 -> 9131.4974 | H24: =(H18+H20+H21-'1 - Titoli e shock'!$B$7)/'1 - Titoli e shock'!$B$11 -> 7036.0994 | I24: =(I18+I20+I21-'1 - Titoli e shock'!$B$7)/'1 - Titoli e shock'!$B$11 -> 5144.0707 | J24: =(J18+J20+J21-'1 - Titoli e shock'!$B$7)/'1 - Titoli e shock'!$B$11 -> 8624.409 | K24: =(K18+K20+K21-'1 - Titoli e shock'!$B$7)/'1 - Titoli e shock'!$B$11 -> 8091.9942 | L24: =(L18+L20+L21-'1 - Titoli e shock'!$B$7)/'1 - Titoli e shock'!$B$11 -> 7874.4876 | M24: =(M18+M20+M21-'1 - Titoli e shock'!$B$7)/'1 - Titoli e shock'!$B$11 -> 7660.1978 | ... U24: =(U18+U20+U21-'1 - Titoli e shock'!$B$7)/'1 - Titoli e shock'!$B$11 -> 3507.5263
A25: Differenza XIRR (2053 − scaletta), punti | F25: =(F22-F14)*100 -> 2.042236 | G25: =(G22-G14)*100 -> 0.80780397 | H25: =(H22-H14)*100 -> -0.43662205 | I25: =(I22-I14)*100 -> -1.6577693 | J25: =(J22-J14)*100 -> 0.50980975 | K25: =(K22-K14)*100 -> 0.197429 | L25: =(L22-L14)*100 -> 0.069343555 | M25: =(M22-M14)*100 -> -0.058101829 | ... U25: =(U22-U14)*100 -> -2.8184168
A26: Δ in ordine crescente | F26: =SMALL($F$5:$U$5,1) -> -1 | G26: =SMALL($F$5:$U$5,2) -> 0 | H26: =SMALL($F$5:$U$5,3) -> 0.25 | I26: =SMALL($F$5:$U$5,4) -> 0.5 | J26: =SMALL($F$5:$U$5,5) -> 0.6 | K26: =SMALL($F$5:$U$5,6) -> 0.7 | L26: =SMALL($F$5:$U$5,7) -> 0.8 | M26: =SMALL($F$5:$U$5,8) -> 0.9 | N26: =SMALL($F$5:$U$5,9) -> 1 | O26: =SMALL($F$5:$U$5,10) -> 1.1 | P26: =SMALL($F$5:$U$5,11) -> 1.2 | Q26: =SMALL($F$5:$U$5,12) -> 1.3 | R26: =SMALL($F$5:$U$5,13) -> 1.4 | S26: =SMALL($F$5:$U$5,14) -> 1.5 | T26: =SMALL($F$5:$U$5,15) -> 2 | U26: =SMALL($F$5:$U$5,16) -> 3
A27: Differenza in ordine | F27: =INDEX($F$25:$U$25,MATCH(F26,$F$5:$U$5,0)) -> 2.042236 | G27: =INDEX($F$25:$U$25,MATCH(G26,$F$5:$U$5,0)) -> 0.80780397 | H27: =INDEX($F$25:$U$25,MATCH(H26,$F$5:$U$5,0)) -> 0.50980975 | I27: =INDEX($F$25:$U$25,MATCH(I26,$F$5:$U$5,0)) -> 0.197429 | J27: =INDEX($F$25:$U$25,MATCH(J26,$F$5:$U$5,0)) -> 0.069343555 | K27: =INDEX($F$25:$U$25,MATCH(K26,$F$5:$U$5,0)) -> -0.058101829 | L27: =INDEX($F$25:$U$25,MATCH(L26,$F$5:$U$5,0)) -> -0.18490959 | M27: =INDEX($F$25:$U$25,MATCH(M26,$F$5:$U$5,0)) -> -0.31108218 | ... U27: =INDEX($F$25:$U$25,MATCH(U26,$F$5:$U$5,0)) -> -2.8184168
A28: Pareggio: passaggio di segno fra due Δ vicini | F28: =IF(AND(F27>=0,G27<0),F26+(G26-F26)*F27/(F27-G27),"") | G28: =IF(AND(G27>=0,H27<0),G26+(H26-G26)*G27/(G27-H27),"") | H28: =IF(AND(H27>=0,I27<0),H26+(I26-H26)*H27/(H27-I27),"") | I28: =IF(AND(I27>=0,J27<0),I26+(J26-I26)*I27/(I27-J27),"") | J28: =IF(AND(J27>=0,K27<0),J26+(K26-J26)*J27/(J27-K27),"") -> 0.65441041 | K28: =IF(AND(K27>=0,L27<0),K26+(L26-K26)*K27/(K27-L27),"") | L28: =IF(AND(L27>=0,M27<0),L26+(M26-L26)*L27/(L27-M27),"") | M28: =IF(AND(M27>=0,N27<0),M26+(N26-M26)*M27/(M27-N27),"") | ... T28: =IF(AND(T27>=0,U27<0),T26+(U26-T26)*T27/(T27-U27),"")
A29: Pareggio scaletta contro 2053 (Δ in punti) | F29: =IF(COUNT(F28:T28)=0,"n/d",MIN(F28:T28)) -> 0.65441041
A32: Appoggio: titoli della scaletta (righe 34-43) e titolo unico 2053 (riga 44)
A33: Titolo | B33: Scadenza | C33: Quota di nominale (nominale/100) | D33: Importo reinvestito alla pari | E33: Fine del reinvestimento a 10 anni | F33: Vita residua a fine orizzonte | G33: Rendimento di curva a fine orizzonte | H33: Frazione di cedola maturata a fine orizzonte | I33: Rateo lordo a fine orizzonte
A34: ='1 - Titoli e shock'!A21 -> BTP 2,70% ott 2027 | B34: ='1 - Titoli e shock'!D21 -> 46675 | C34: ='1 - Titoli e shock'!$B$7/10/('1 - Titoli e shock'!E21+'1 - Titoli e shock'!I21) -> 200.83211 | D34: =C34*(100-'1 - Titoli e shock'!$B$8*MAX(0,100-'1 - Titoli e shock'!E21)) -> 20072.065 | E34: =EDATE(B34,120) -> 50328 | F34: =(B34-'1 - Titoli e shock'!$B$17)/365.25 -> -9.0130048 | G34: =IF(F34<='1 - Titoli e shock'!$P$21,'1 - Titoli e shock'!$K$21,IF(F34>='1 - Titoli e shock'!$P$35,'1 - Titoli e shock'!$K$35,INDEX('1 - Titoli e shock'!$K$21:$K$35,MATCH(F34,'1 - Titoli e shock'!$P$21:$P$35,1))+(INDEX('1 - Titoli e shock'!$K$21:$K$35,MATCH(F34,'1 - Titoli e shock'!$P$21:$P$35,1)+1)-INDEX('1 - Titoli e shock'!$K$21:$K$35,MATCH(F34,'1 - Titoli e shock'!$P$21:$P$35,1)))*(F34-INDEX('1 - Titoli e shock'!$P$21:$P$35,MATCH(F34,'1 - Titoli e shock'!$P$21:$P$35,1)))/(INDEX('1 - Titoli e shock'!$P$21:$P$35,MATCH(F34,'1 - Titoli e shock'!$P$21:$P$35,1)+1)-INDEX('1 - Titoli e shock'!$P$21:$P$35,MATCH(F34,'1 - Titoli e shock'!$P$21:$P$35,1))))) -> 0.031842376 | H34: =IF(B34<='1 - Titoli e shock'!$B$17,('1 - Titoli e shock'!$B$17-EDATE(B34,6*INT(DATEDIF(B34,'1 - Titoli e shock'!$B$17,"m")/6)))/(EDATE(B34,6*INT(DATEDIF(B34,'1 - Titoli e shock'!$B$17,"m")/6)+6)-EDATE(B34,6*INT(DATEDIF(B34,'1 - Titoli e shock'!$B$17,"m")/6))),0) -> 0.021978022 | I34: =IF(B34>'1 - Titoli e shock'!$B$17,'1 - Titoli e shock'!C21*100/2*COUPDAYBS('1 - Titoli e shock'!$B$17,B34,2,1)/COUPDAYS('1 - Titoli e shock'!$B$17,B34,2,1),0) -> 0
A35: ='1 - Titoli e shock'!A22 -> BTP 2,80% dic 2028 | B35: ='1 - Titoli e shock'!D22 -> 47088 | C35: ='1 - Titoli e shock'!$B$7/10/('1 - Titoli e shock'!E22+'1 - Titoli e shock'!I22) -> 200.25826 | D35: =C35*(100-'1 - Titoli e shock'!$B$8*MAX(0,100-'1 - Titoli e shock'!E22)) -> 19995.787 | E35: =EDATE(B35,120) -> 50740 | F35: =(B35-'1 - Titoli e shock'!$B$17)/365.25 -> -7.8822724 | G35: =IF(F35<='1 - Titoli e shock'!$P$21,'1 - Titoli e shock'!$K$21,IF(F35>='1 - Titoli e shock'!$P$35,'1 - Titoli e shock'!$K$35,INDEX('1 - Titoli e shock'!$K$21:$K$35,MATCH(F35,'1 - Titoli e shock'!$P$21:$P$35,1))+(INDEX('1 - Titoli e shock'!$K$21:$K$35,MATCH(F35,'1 - Titoli e shock'!$P$21:$P$35,1)+1)-INDEX('1 - Titoli e shock'!$K$21:$K$35,MATCH(F35,'1 - Titoli e shock'!$P$21:$P$35,1)))*(F35-INDEX('1 - Titoli e shock'!$P$21:$P$35,MATCH(F35,'1 - Titoli e shock'!$P$21:$P$35,1)))/(INDEX('1 - Titoli e shock'!$P$21:$P$35,MATCH(F35,'1 - Titoli e shock'!$P$21:$P$35,1)+1)-INDEX('1 - Titoli e shock'!$P$21:$P$35,MATCH(F35,'1 - Titoli e shock'!$P$21:$P$35,1))))) -> 0.031842376 | H35: =IF(B35<='1 - Titoli e shock'!$B$17,('1 - Titoli e shock'!$B$17-EDATE(B35,6*INT(DATEDIF(B35,'1 - Titoli e shock'!$B$17,"m")/6)))/(EDATE(B35,6*INT(DATEDIF(B35,'1 - Titoli e shock'!$B$17,"m")/6)+6)-EDATE(B35,6*INT(DATEDIF(B35,'1 - Titoli e shock'!$B$17,"m")/6))),0) -> 0.76502732 | I35: =IF(B35>'1 - Titoli e shock'!$B$17,'1 - Titoli e shock'!C22*100/2*COUPDAYBS('1 - Titoli e shock'!$B$17,B35,2,1)/COUPDAYS('1 - Titoli e shock'!$B$17,B35,2,1),0) -> 0
A36: ='1 - Titoli e shock'!A23 -> BTP 3,00% ott 2029 | B36: ='1 - Titoli e shock'!D23 -> 47392 | C36: ='1 - Titoli e shock'!$B$7/10/('1 - Titoli e shock'!E23+'1 - Titoli e shock'!I23) -> 203.19349 | D36: =C36*(100-'1 - Titoli e shock'!$B$8*MAX(0,100-'1 - Titoli e shock'!E23)) -> 20275.662 | E36: =EDATE(B36,120) -> 51044 | F36: =(B36-'1 - Titoli e shock'!$B$17)/365.25 -> -7.0499658 | G36: =IF(F36<='1 - Titoli e shock'!$P$21,'1 - Titoli e shock'!$K$21,IF(F36>='1 - Titoli e shock'!$P$35,'1 - Titoli e shock'!$K$35,INDEX('1 - Titoli e shock'!$K$21:$K$35,MATCH(F36,'1 - Titoli e shock'!$P$21:$P$35,1))+(INDEX('1 - Titoli e shock'!$K$21:$K$35,MATCH(F36,'1 - Titoli e shock'!$P$21:$P$35,1)+1)-INDEX('1 - Titoli e shock'!$K$21:$K$35,MATCH(F36,'1 - Titoli e shock'!$P$21:$P$35,1)))*(F36-INDEX('1 - Titoli e shock'!$P$21:$P$35,MATCH(F36,'1 - Titoli e shock'!$P$21:$P$35,1)))/(INDEX('1 - Titoli e shock'!$P$21:$P$35,MATCH(F36,'1 - Titoli e shock'!$P$21:$P$35,1)+1)-INDEX('1 - Titoli e shock'!$P$21:$P$35,MATCH(F36,'1 - Titoli e shock'!$P$21:$P$35,1))))) -> 0.031842376 | H36: =IF(B36<='1 - Titoli e shock'!$B$17,('1 - Titoli e shock'!$B$17-EDATE(B36,6*INT(DATEDIF(B36,'1 - Titoli e shock'!$B$17,"m")/6)))/(EDATE(B36,6*INT(DATEDIF(B36,'1 - Titoli e shock'!$B$17,"m")/6)+6)-EDATE(B36,6*INT(DATEDIF(B36,'1 - Titoli e shock'!$B$17,"m")/6))),0) -> 0.098901099 | I36: =IF(B36>'1 - Titoli e shock'!$B$17,'1 - Titoli e shock'!C23*100/2*COUPDAYBS('1 - Titoli e shock'!$B$17,B36,2,1)/COUPDAYS('1 - Titoli e shock'!$B$17,B36,2,1),0) -> 0
A37: ='1 - Titoli e shock'!A24 -> BTP 2,70% ott 2030 | B37: ='1 - Titoli e shock'!D24 -> 47757 | C37: ='1 - Titoli e shock'!$B$7/10/('1 - Titoli e shock'!E24+'1 - Titoli e shock'!I24) -> 207.95746 | D37: =C37*(100-'1 - Titoli e shock'!$B$8*MAX(0,100-'1 - Titoli e shock'!E24)) -> 20692.807 | E37: =EDATE(B37,120) -> 51410 | F37: =(B37-'1 - Titoli e shock'!$B$17)/365.25 -> -6.0506502 | G37: =IF(F37<='1 - Titoli e shock'!$P$21,'1 - Titoli e shock'!$K$21,IF(F37>='1 - Titoli e shock'!$P$35,'1 - Titoli e shock'!$K$35,INDEX('1 - Titoli e shock'!$K$21:$K$35,MATCH(F37,'1 - Titoli e shock'!$P$21:$P$35,1))+(INDEX('1 - Titoli e shock'!$K$21:$K$35,MATCH(F37,'1 - Titoli e shock'!$P$21:$P$35,1)+1)-INDEX('1 - Titoli e shock'!$K$21:$K$35,MATCH(F37,'1 - Titoli e shock'!$P$21:$P$35,1)))*(F37-INDEX('1 - Titoli e shock'!$P$21:$P$35,MATCH(F37,'1 - Titoli e shock'!$P$21:$P$35,1)))/(INDEX('1 - Titoli e shock'!$P$21:$P$35,MATCH(F37,'1 - Titoli e shock'!$P$21:$P$35,1)+1)-INDEX('1 - Titoli e shock'!$P$21:$P$35,MATCH(F37,'1 - Titoli e shock'!$P$21:$P$35,1))))) -> 0.031842376 | H37: =IF(B37<='1 - Titoli e shock'!$B$17,('1 - Titoli e shock'!$B$17-EDATE(B37,6*INT(DATEDIF(B37,'1 - Titoli e shock'!$B$17,"m")/6)))/(EDATE(B37,6*INT(DATEDIF(B37,'1 - Titoli e shock'!$B$17,"m")/6)+6)-EDATE(B37,6*INT(DATEDIF(B37,'1 - Titoli e shock'!$B$17,"m")/6))),0) -> 0.098901099 | I37: =IF(B37>'1 - Titoli e shock'!$B$17,'1 - Titoli e shock'!C24*100/2*COUPDAYBS('1 - Titoli e shock'!$B$17,B37,2,1)/COUPDAYS('1 - Titoli e shock'!$B$17,B37,2,1),0) -> 0
