Workbook

Sheet 0 - Indice
A1: Simulatore BTP Valore e BTP Valore Insieme — ottobre 2026
A2: Strumento informativo / divulgativo. NON è consulenza finanziaria. I valori sono indicativi al 2026 e vanno verificati col tuo consulente.
A4: Indice
A5: 1 - Il 16 ottobre | B5: Inserisci i tassi annunciati dal MEF e il BTP a 5 anni del giorno: rendimenti e verdetto
A6: 2 - Previsione | B6: Come ho costruito la forchetta del 25/09/2026: emissioni passate e mercato
A7: 3 - Gemelli | B7: Flussi anno per anno, bollo e reinvestimento delle cedole
A8: 4 - Vendere prima | B8: Prezzo dei due titoli dopo 1-4 anni se i tassi si muovono
A9: 5 - Alternative | B9: BTP ordinario, Valore 2032, BTP Più, Italia Sì, BOT, buoni postali al 25/09/2026
A11: Come usare
A12: 1. Le celle GIALLE sono input — modificale coi tuoi numeri.
A13: 2. Le celle VERDI sono output — si aggiornano automaticamente.
A14: 3. Tutti i numeri di default sono al 2026 da fonti pubbliche.
A15: 4. Niente codice nascosto: l'Excel è solo formule modificabili.
A17: Fonti dati
A18: • MEF, comunicato stampa n. 104 del 25/09/2026 (doppia emissione, 19-23/10, tassi minimi il 16/10)
A19: • MEF, comunicati delle emissioni BTP Valore 2023-2026 e risultati d'asta BTP 5 e 10 anni (Dipartimento del Tesoro)
A20: • Borsa Italiana, prezzi MOT del 25/09/2026 (BTP giu-2031, feb-2031, Valore mar-2032, Più feb-2033, Italia Sì)
A21: • BCE, decisione del 10/09/2026; ISTAT, prezzi al consumo agosto 2026
A22: • CDP, fogli informativi Buoni fruttiferi postali (luglio-settembre 2026)
A23: • Calcoli: rendimento effettivo annuo, imposta 12,5%, bollo 0,20% annuo
A25: Aggiornamenti: github.com/marcofire-it/marco-fire-simulatori

Sheet 1 - Il 16 ottobre
A1: Il 16 ottobre: i tassi annunciati convengono?
A2: Strumento informativo / divulgativo. NON è consulenza finanziaria. I valori sono indicativi al 2026 e vanno verificati col tuo consulente.
A4: Input — dal comunicato MEF del 16 ottobre e dalla Borsa di quel giorno
A5: Tasso cedolare annuo, anno 1 | B5: 0.037 | C5: Tassi minimi garantiti del comunicato MEF n. 110 del 16/10/2026 (ISIN IT0005735201). A fine collocamento possono solo salire: se salgono, scrivili qui
A6: Tasso cedolare annuo, anno 2 | B6: 0.037
A7: Tasso cedolare annuo, anno 3 | B7: 0.041
A8: Tasso cedolare annuo, anno 4 | B8: 0.041
A9: Tasso cedolare annuo, anno 5 | B9: 0.047
A10: Valore Insieme: cedola unica annunciata (% del capitale, lorda) | B10: 0.2225 | C10: 22,25% minimo garantito, comunicato MEF n. 110 del 16/10/2026 (ISIN IT0005735227). Se svuoti la cella, il foglio usa la cedola equivalente al Valore trimestrale
A11: Rendimento lordo BTP 3,95% feb-2032 su Borsa Italiana, quel giorno | B11: 0.0401 | C11: BTP 3,95% feb-2032 (IT0005733636): 4,01% lordo su Borsa Italiana il 16/10/2026, prezzo di riferimento 99,90. Al 25/09 il riferimento era il BTP giu-2031: 3,99% sul prezzo MOT 96,59
A12: Aliquota imposta titoli di Stato | B12: 0.125
A13: Capitale investito | B13: 10000
A15: Risultati
A16: Voce | B16: BTP Valore | C16: Valore Insieme
A17: Rendimento effettivo annuo lordo | B17: =(1+IRR(D40:D60))^4-1 -> 0.041024884 | C17: =IF(ISBLANK(B10),B17,(1+B10)^(1/5)-1) -> 0.040997709
A18: Rendimento effettivo annuo netto (imposta, senza bollo) | B18: =(1+IRR(E40:E60))^4-1 -> 0.035850135 | C18: =(1+C19*(1-B12))^(1/5)-1 -> 0.03621736
A19: Interessi lordi in 5 anni (% del capitale) | B19: =SUM(B5:B9) -> 0.203 | C19: =IF(ISBLANK(B10),(1+B17)^5-1,B10) -> 0.2225
A20: Interessi lordi in 5 anni, in euro | B20: =B19*B13 -> 2030 | C20: =C19*B13 -> 2225
A21: Interessi netti in 5 anni, in euro | B21: =B20*(1-B12) -> 1776.25 | C21: =C20*(1-B12) -> 1946.875
A22: Media semplice delle cedole (NON è il rendimento) | B22: =AVERAGE(B5:B9) -> 0.0406
A23: Scarto sul BTP ordinario (punti percentuali) | B23: =(B17-B11)*100 -> 0.092488434 | C23: =(C17-B11)*100 -> 0.08977086
A24: VERDETTO | B24: =IF(B23<-0.05,"ROSSO",IF(B23<=0.1,"GIALLO","VERDE")) -> GIALLO | C24: =IF(C23<-0.05,"ROSSO",IF(C23<=0.1,"GIALLO","VERDE")) -> GIALLO
A25: ROSSO: più di 0,05 punti sotto il BTP ordinario (meglio il BTP già quotato). GIALLO: da 0,05 sotto a 0,10 sopra (conviene per i vantaggi accessori: zero commissioni, quantità garantita, forma dei flussi). VERDE: oltre 0,10 sopra (il Tesoro paga un premio).
A26: I tassi minimi del 16 ottobre possono solo essere confermati o alzati a fine collocamento.
A38: Flussi trimestrali per 100 € (motore del calcolo, non modificare)
A39: Trimestre | B39: Anno | C39: Tasso annuo | D39: Flusso lordo | E39: Flusso netto
A40: 0 | B40: 0 | D40: -100 | E40: -100
A41: 1 | B41: =ROUNDUP(A41/4,0) -> 1 | C41: =INDEX($B$5:$B$9,B41) -> 0.037 | D41: =100*C41/4 -> 0.925 | E41: =100*C41/4*(1-$B$12) -> 0.809375
A42: 2 | B42: =ROUNDUP(A42/4,0) -> 1 | C42: =INDEX($B$5:$B$9,B42) -> 0.037 | D42: =100*C42/4 -> 0.925 | E42: =100*C42/4*(1-$B$12) -> 0.809375
A43: 3 | B43: =ROUNDUP(A43/4,0) -> 1 | C43: =INDEX($B$5:$B$9,B43) -> 0.037 | D43: =100*C43/4 -> 0.925 | E43: =100*C43/4*(1-$B$12) -> 0.809375
A44: 4 | B44: =ROUNDUP(A44/4,0) -> 1 | C44: =INDEX($B$5:$B$9,B44) -> 0.037 | D44: =100*C44/4 -> 0.925 | E44: =100*C44/4*(1-$B$12) -> 0.809375
A45: 5 | B45: =ROUNDUP(A45/4,0) -> 2 | C45: =INDEX($B$5:$B$9,B45) -> 0.037 | D45: =100*C45/4 -> 0.925 | E45: =100*C45/4*(1-$B$12) -> 0.809375
A46: 6 | B46: =ROUNDUP(A46/4,0) -> 2 | C46: =INDEX($B$5:$B$9,B46) -> 0.037 | D46: =100*C46/4 -> 0.925 | E46: =100*C46/4*(1-$B$12) -> 0.809375
A47: 7 | B47: =ROUNDUP(A47/4,0) -> 2 | C47: =INDEX($B$5:$B$9,B47) -> 0.037 | D47: =100*C47/4 -> 0.925 | E47: =100*C47/4*(1-$B$12) -> 0.809375
A48: 8 | B48: =ROUNDUP(A48/4,0) -> 2 | C48: =INDEX($B$5:$B$9,B48) -> 0.037 | D48: =100*C48/4 -> 0.925 | E48: =100*C48/4*(1-$B$12) -> 0.809375
A49: 9 | B49: =ROUNDUP(A49/4,0) -> 3 | C49: =INDEX($B$5:$B$9,B49) -> 0.041 | D49: =100*C49/4 -> 1.025 | E49: =100*C49/4*(1-$B$12) -> 0.896875
A50: 10 | B50: =ROUNDUP(A50/4,0) -> 3 | C50: =INDEX($B$5:$B$9,B50) -> 0.041 | D50: =100*C50/4 -> 1.025 | E50: =100*C50/4*(1-$B$12) -> 0.896875
A51: 11 | B51: =ROUNDUP(A51/4,0) -> 3 | C51: =INDEX($B$5:$B$9,B51) -> 0.041 | D51: =100*C51/4 -> 1.025 | E51: =100*C51/4*(1-$B$12) -> 0.896875
A52: 12 | B52: =ROUNDUP(A52/4,0) -> 3 | C52: =INDEX($B$5:$B$9,B52) -> 0.041 | D52: =100*C52/4 -> 1.025 | E52: =100*C52/4*(1-$B$12) -> 0.896875
... A59: 19 | B59: =ROUNDUP(A59/4,0) -> 5 | C59: =INDEX($B$5:$B$9,B59) -> 0.047 | D59: =100*C59/4 -> 1.175 | E59: =100*C59/4*(1-$B$12) -> 1.028125
...

Sheet 2 - Previsione
A1: La previsione del 25/09/2026: a che tassi dovrebbe uscire il BTP Valore
A2: Strumento informativo / divulgativo. NON è consulenza finanziaria. I valori sono indicativi al 2026 e vanno verificati col tuo consulente.
A4: Calibrazione: tassi MINIMI del Valore contro BTP di pari durata alle aste MEF
A5: Emissione | B5: Rend. effettivo dei minimi | C5: BTP pari durata (aste MEF) | D5: Scarto (punti) | E5: Premio fedeltà | F5: Nota
A6: Ottobre 2023, 5 anni | B6: 0.0441 | C6: 0.0438 | D6: =(B6-C6)*100 -> 0.03 | E6: 0,5% | F6: Unico precedente a 5 anni
A7: Febbraio 2024, 6 anni | B7: 0.0376 | C7: 0.0348 | D7: =(B7-C7)*100 -> 0.28 | E7: 0,7%
A8: Maggio 2024, 6 anni | B8: 0.0378 | C8: 0.0349 | D8: =(B8-C8)*100 -> 0.29 | E8: 0,8%
A9: Febbraio 2025, BTP Più, 8 anni | B9: 0.0321 | C9: 0.0326 | D9: =(B9-C9)*100 -> -0.05 | E9: nessuno | F9: Con rimborso anticipato al 4° anno
A10: Ottobre 2025, 7 anni | B10: 0.0325 | C10: 0.0307 | D10: =(B10-C10)*100 -> 0.18 | E10: 0,8%
A11: Marzo 2026, 6 anni | B11: 0.0307 | C11: 0.0277 | D11: =(B11-C11)*100 -> 0.3 | E11: 0,8% | F11: Minimi poi alzati: definitivo 3,34%
A12: Scarto medio, premio incluso | D12: =AVERAGE(D6:D11) -> 0.17166667
A13: Scarto medio senza premio (stima) | D13: 0.08
A14: Giugno 2023 escluso: dato d'asta di riferimento non reperito. Interpolazione lineare fra BTP 5 e 10 anni sulla durata del Valore. Il premio fedeltà valeva circa 0,09-0,12 punti l'anno: nella nuova emissione non c'è.
A16: Forchetta
A17: Ancora: BTP ordinario ~5 anni al 25/09/2026 | B17: 0.04
A18: Ipotesi A — come l'unico precedente a 5 anni (0 punti) | B18: =B17 -> 0.04
A19: Ipotesi B — scarto storico senza premio | B19: =B17+D13/100 -> 0.0408
A20: Ipotesi C — il premio spostato dentro le cedole | B20: =B17+D12/100 -> 0.041716667
A21: Forchetta prevista (arrotondata) | B21: 3,90% - 4,20%, centro ≈ 4,05%
A22: Cedola unica equivalente del Valore Insieme, al centro | B22: =(1+0.0405)^5-1 -> 0.21958036
A24: Se il mercato si muove fino al 16 ottobre
A25: Scenario | B25: BTP 5 anni | C25: Forchetta bassa | D25: Forchetta alta
A26: Rendimenti −0,30 punti | B26: =$B$17+(-0.003) -> 0.037 | C26: =B26-0.001 -> 0.036 | D26: =B26+0.002 -> 0.039
A27: Rendimenti fermi | B27: =$B$17+(0) -> 0.04 | C27: =B27-0.001 -> 0.039 | D27: =B27+0.002 -> 0.042
A28: Rendimenti +0,30 punti | B28: =$B$17+(0.003) -> 0.043 | C28: =B28-0.001 -> 0.042 | D28: =B28+0.002 -> 0.045

Sheet 3 - Gemelli
A1: I due gemelli anno per anno: cedole, imposta, bollo, reinvestimento
A2: Strumento informativo / divulgativo. NON è consulenza finanziaria. I valori sono indicativi al 2026 e vanno verificati col tuo consulente.
A4: Capitale | B4: ='1 - Il 16 ottobre'!B13 -> 10000
A5: Rendimento effettivo lordo (dal foglio 1) | B5: ='1 - Il 16 ottobre'!B17 -> 0.041024884
A6: Bollo annuo sul dossier titoli | B6: 0.002
A7: Tasso netto a cui reinvesti le cedole | B7: 0.0358 | C7: Se i tassi salgono, alzalo: il trimestrale passa davanti. Se scendono, abbassalo.
A9: Anno | B9: Valore: cedole lorde | C9: Valore: cedole nette | D9: Valore: bollo | E9: Insieme: incassato | F9: Insieme: valore a fine anno | G9: Insieme: bollo (sul valore)
A10: 1 | B10: =$B$4*INDEX('1 - Il 16 ottobre'!$B$5:$B$9,A10) -> 370 | C10: =B10*(1-'1 - Il 16 ottobre'!$B$12) -> 323.75 | D10: =$B$4*$B$6 -> 20 | E10: =0 -> 0 | F10: =$B$4*(1+'1 - Il 16 ottobre'!$C$17)^A10 -> 10409.977 | G10: =F10*$B$6 -> 20.819954
A11: 2 | B11: =$B$4*INDEX('1 - Il 16 ottobre'!$B$5:$B$9,A11) -> 370 | C11: =B11*(1-'1 - Il 16 ottobre'!$B$12) -> 323.75 | D11: =$B$4*$B$6 -> 20 | E11: =0 -> 0 | F11: =$B$4*(1+'1 - Il 16 ottobre'!$C$17)^A11 -> 10836.762 | G11: =F11*$B$6 -> 21.673525
A12: 3 | B12: =$B$4*INDEX('1 - Il 16 ottobre'!$B$5:$B$9,A12) -> 410 | C12: =B12*(1-'1 - Il 16 ottobre'!$B$12) -> 358.75 | D12: =$B$4*$B$6 -> 20 | E12: =0 -> 0 | F12: =$B$4*(1+'1 - Il 16 ottobre'!$C$17)^A12 -> 11281.045 | G12: =F12*$B$6 -> 22.562089
A13: 4 | B13: =$B$4*INDEX('1 - Il 16 ottobre'!$B$5:$B$9,A13) -> 410 | C13: =B13*(1-'1 - Il 16 ottobre'!$B$12) -> 358.75 | D13: =$B$4*$B$6 -> 20 | E13: =0 -> 0 | F13: =$B$4*(1+'1 - Il 16 ottobre'!$C$17)^A13 -> 11743.542 | G13: =F13*$B$6 -> 23.487083
A14: 5 | B14: =$B$4*INDEX('1 - Il 16 ottobre'!$B$5:$B$9,A14) -> 470 | C14: =B14*(1-'1 - Il 16 ottobre'!$B$12) -> 411.25 | D14: =$B$4*$B$6 -> 20 | E14: =$B$4*'1 - Il 16 ottobre'!$C$19 -> 2225 | F14: =$B$4*(1+'1 - Il 16 ottobre'!$C$17)^A14 -> 12225 | G14: =F14*$B$6 -> 24.45
A15: Totale | B15: =SUM(B10:B14) -> 2030 | C15: =SUM(C10:C14) -> 1776.25 | D15: =SUM(D10:D14) -> 100 | E15: =SUM(E10:E14) -> 2225 | G15: =SUM(G10:G14) -> 112.99265
A16: Bollo del Valore Insieme calcolato sul valore di mercato a tassi fermi (DM 24/05/2012: valore di mercato, in mancanza nominale o rimborso). Da verificare sulla scheda informativa MEF.
A18: Reinvestimento: quanto hai alla scadenza, netto di imposta (senza bollo)
A19: BTP Valore, cedole nette reinvestite al tasso di B7 | B19: =B4+B4/100*SUMPRODUCT('1 - Il 16 ottobre'!E41:E60-('1 - Il 16 ottobre'!A41:A60=20)*100,(1+B7)^((20-'1 - Il 16 ottobre'!A41:A60)/4)) -> 11925.503
A20: Valore Insieme, capitale + cedola unica netta | B20: =B4+B4*'1 - Il 16 ottobre'!C19*(1-'1 - Il 16 ottobre'!B12) -> 11946.875
A21: Differenza (positivo = meglio il trimestrale) | B21: =B19-B20 -> -21.371537
A22: Ogni cedola netta trimestrale reinvestita dal giorno in cui la incassi fino alla scadenza, al tasso annuo di B7.

Sheet 4 - Vendere prima
A1: Se vendi prima: prezzo dei due gemelli (per 100 di nominale)
A2: Strumento informativo / divulgativo. NON è consulenza finanziaria. I valori sono indicativi al 2026 e vanno verificati col tuo consulente.
A4: Rendimento di partenza (dal foglio 1) | B4: ='1 - Il 16 ottobre'!B17 -> 0.041024884
A6: Anni trascorsi | B6: Variazione dei tassi (punti) | C6: Prezzo BTP Valore (corso secco, dopo la cedola) | D6: Valore Insieme: valore con gli interessi maturati | E6: Differenza
A7: 0 | B7: -1 | C7: =SUMPRODUCT(('1 - Il 16 ottobre'!$A$41:$A$60>4*A7)*'1 - Il 16 ottobre'!$D$41:$D$60/(1+($B$4+B7/100))^(('1 - Il 16 ottobre'!$A$41:$A$60-4*A7)/4)) -> 104.51927 | D7: =100*(1+'1 - Il 16 ottobre'!$C$19)/(1+($B$4+B7/100))^(5-A7) -> 104.93084 | E7: =D7-C7 -> 0.41156708
A8: 0 | B8: -0.5 | C8: =SUMPRODUCT(('1 - Il 16 ottobre'!$A$41:$A$60>4*A8)*'1 - Il 16 ottobre'!$D$41:$D$60/(1+($B$4+B8/100))^(('1 - Il 16 ottobre'!$A$41:$A$60-4*A8)/4)) -> 102.2278 | D8: =100*(1+'1 - Il 16 ottobre'!$C$19)/(1+($B$4+B8/100))^(5-A8) -> 102.4231 | E8: =D8-C8 -> 0.19530096
A9: 0 | B9: 0 | C9: =SUMPRODUCT(('1 - Il 16 ottobre'!$A$41:$A$60>4*A9)*'1 - Il 16 ottobre'!$D$41:$D$60/(1+($B$4+B9/100))^(('1 - Il 16 ottobre'!$A$41:$A$60-4*A9)/4)) -> 100 | D9: =100*(1+'1 - Il 16 ottobre'!$C$19)/(1+($B$4+B9/100))^(5-A9) -> 99.986948 | E9: =D9-C9 -> -0.013051718
A10: 0 | B10: 0.5 | C10: =SUMPRODUCT(('1 - Il 16 ottobre'!$A$41:$A$60>4*A10)*'1 - Il 16 ottobre'!$D$41:$D$60/(1+($B$4+B10/100))^(('1 - Il 16 ottobre'!$A$41:$A$60-4*A10)/4)) -> 97.833779 | D10: =100*(1+'1 - Il 16 ottobre'!$C$19)/(1+($B$4+B10/100))^(5-A10) -> 97.619996 | E10: =D10-C10 -> -0.21378234
A11: 0 | B11: 1 | C11: =SUMPRODUCT(('1 - Il 16 ottobre'!$A$41:$A$60>4*A11)*'1 - Il 16 ottobre'!$D$41:$D$60/(1+($B$4+B11/100))^(('1 - Il 16 ottobre'!$A$41:$A$60-4*A11)/4)) -> 95.727136 | D11: =100*(1+'1 - Il 16 ottobre'!$C$19)/(1+($B$4+B11/100))^(5-A11) -> 95.319965 | E11: =D11-C11 -> -0.40717062
A12: 1 | B12: -1 | C12: =SUMPRODUCT(('1 - Il 16 ottobre'!$A$41:$A$60>4*A12)*'1 - Il 16 ottobre'!$D$41:$D$60/(1+($B$4+B12/100))^(('1 - Il 16 ottobre'!$A$41:$A$60-4*A12)/4)) -> 104.01919 | D12: =100*(1+'1 - Il 16 ottobre'!$C$19)/(1+($B$4+B12/100))^(5-A12) -> 108.1863 | E12: =D12-C12 -> 4.1671089
A13: 1 | B13: -0.5 | C13: =SUMPRODUCT(('1 - Il 16 ottobre'!$A$41:$A$60>4*A13)*'1 - Il 16 ottobre'!$D$41:$D$60/(1+($B$4+B13/100))^(('1 - Il 16 ottobre'!$A$41:$A$60-4*A13)/4)) -> 102.16093 | D13: =100*(1+'1 - Il 16 ottobre'!$C$19)/(1+($B$4+B13/100))^(5-A13) -> 106.11288 | E13: =D13-C13 -> 3.9519526
A14: 1 | B14: 0 | C14: =SUMPRODUCT(('1 - Il 16 ottobre'!$A$41:$A$60>4*A14)*'1 - Il 16 ottobre'!$D$41:$D$60/(1+($B$4+B14/100))^(('1 - Il 16 ottobre'!$A$41:$A$60-4*A14)/4)) -> 100.34604 | D14: =100*(1+'1 - Il 16 ottobre'!$C$19)/(1+($B$4+B14/100))^(5-A14) -> 104.0889 | E14: =D14-C14 -> 3.7428581
A15: 1 | B15: 0.5 | C15: =SUMPRODUCT(('1 - Il 16 ottobre'!$A$41:$A$60>4*A15)*'1 - Il 16 ottobre'!$D$41:$D$60/(1+($B$4+B15/100))^(('1 - Il 16 ottobre'!$A$41:$A$60-4*A15)/4)) -> 98.573306 | D15: =100*(1+'1 - Il 16 ottobre'!$C$19)/(1+($B$4+B15/100))^(5-A15) -> 102.11295 | E15: =D15-C15 -> 3.5396393
A16: 1 | B16: 1 | C16: =SUMPRODUCT(('1 - Il 16 ottobre'!$A$41:$A$60>4*A16)*'1 - Il 16 ottobre'!$D$41:$D$60/(1+($B$4+B16/100))^(('1 - Il 16 ottobre'!$A$41:$A$60-4*A16)/4)) -> 96.841539 | D16: =100*(1+'1 - Il 16 ottobre'!$C$19)/(1+($B$4+B16/100))^(5-A16) -> 100.18366 | E16: =D16-C16 -> 3.3421166
A17: 2 | B17: -1 | C17: =SUMPRODUCT(('1 - Il 16 ottobre'!$A$41:$A$60>4*A17)*'1 - Il 16 ottobre'!$D$41:$D$60/(1+($B$4+B17/100))^(('1 - Il 16 ottobre'!$A$41:$A$60-4*A17)/4)) -> 103.5036 | D17: =100*(1+'1 - Il 16 ottobre'!$C$19)/(1+($B$4+B17/100))^(5-A17) -> 111.54277 | E17: =D17-C17 -> 8.039166
A18: 2 | B18: -0.5 | C18: =SUMPRODUCT(('1 - Il 16 ottobre'!$A$41:$A$60>4*A18)*'1 - Il 16 ottobre'!$D$41:$D$60/(1+($B$4+B18/100))^(('1 - Il 16 ottobre'!$A$41:$A$60-4*A18)/4)) -> 102.09165 | D18: =100*(1+'1 - Il 16 ottobre'!$C$19)/(1+($B$4+B18/100))^(5-A18) -> 109.93559 | E18: =D18-C18 -> 7.8439373
... A31: 4 | B31: 1 | C31: =SUMPRODUCT(('1 - Il 16 ottobre'!$A$41:$A$60>4*A31)*'1 - Il 16 ottobre'!$D$41:$D$60/(1+($B$4+B31/100))^(('1 - Il 16 ottobre'!$A$41:$A$60-4*A31)/4)) -> 99.70173 | D31: =100*(1+'1 - Il 16 ottobre'!$C$19)/(1+($B$4+B31/100))^(5-A31) -> 116.31504 | E31: =D31-C31 -> 16.613309
A33: Anno 0 = subito dopo l'acquisto a 100. Per il Valore Insieme è il valore comprensivo degli interessi maturati: in Borsa il prezzo potrebbe restare vicino a 100 con gli interessi conteggiati a parte (rateo). La parte maturata è interesse, non guadagno. In vendita anticipata l'imposta sugli interessi maturati e la plus/minusvalenza si calcolano separatamente (per analogia con i titoli senza cedola: da confermare sulla scheda MEF).

Sheet 5 - Alternative
A1: Le alternative al 25/09/2026
A2: Strumento informativo / divulgativo. NON è consulenza finanziaria. I valori sono indicativi al 2026 e vanno verificati col tuo consulente.
A4: Strumento | B4: Prezzo / condizione al 25/09/2026 | C4: Rendimento lordo | D4: Rendimento netto | E4: Scadenza | F4: Nota
A5: BTP ordinario 3,15% giugno 2031 | B5: 96,59 (MOT) | C5: 0.0399 | D5: 0.035 | E5: 2031 | F5: Commissione di acquisto a carico
A6: BTP Valore marzo 2032 (sul mercato) | B6: 95,44 (MOT) | C6: 0.0424 | D6: 0.0371 | E6: 2032 | F6: Senza premio fedeltà: spetta solo a chi lo ha sottoscritto
A7: BTP Più febbraio 2033 (sul mercato) | B7: 94,69 (MOT) | C7: 0.0437 | D7: 0.0383 | E7: 2033 | F7: Rimborso anticipato solo per i sottoscrittori all'emissione
A8: BTP Italia Sì giugno 2031 | B8: 100,04 (MOT) | C8: dipende dall'inflazione | E8: 2031 | F8: 1,60% reale + inflazione italiana: dipende dall'inflazione
A9: BOT 12 mesi | B9: asta del 09/09/2026 | C9: 0.0301 | D9: 0.0263 | E9: 2027 | F9: Rendimento effettivo annuo
A10: Buono Premium CDP 1 anno | B10: solo nuova liquidità, entro il 05/11/2026 | C10: 0.0325 | D10: 0.0284 | E10: 2027 | F10: Zero interessi se rimborsato prima
A11: Buono fruttifero postale ordinario | B11: a 5 anni | C11: 0.009 | D11: 0.0079 | E11: rimborsabile | F11: Nessun rischio di prezzo
A12: Nuovo BTP Valore, previsione centrale | B12: a 100 in collocamento | C12: 0.0405 | D12: 0.0354 | E12: 2031 | F12: Previsione mia del 25/09, non un dato
A13: Nuovo BTP Valore, tassi minimi del 16/10 | B13: a 100 in collocamento, 19-23/10/2026 | C13: 0.041 | D13: 0.0359 | E13: 2031 | F13: Calcolo mio sul comunicato MEF n. 110 del 16/10/2026
A14: Inflazione di pareggio: nuovo Valore contro BTP Italia Sì comprato oggi a ~100
A15: Rendimento lordo del nuovo Valore (dal foglio 1) | B15: ='1 - Il 16 ottobre'!B17 -> 0.041024884
A16: Tasso reale del BTP Italia Sì | B16: 0.016
A17: Inflazione media annua di pareggio | B17: =(1+B15)/(1+B16)-1 -> 0.024630792
A18: Sopra questa inflazione media rende di più l'indicizzato, sotto il tasso fisso. Calcolo lordo, semplificato.
A20: Rendimenti dei titoli quotati: calcolo mio sui prezzi MOT del 25/09/2026, regolamento 29/09/2026, netto prudente (12,5% anche sullo sconto sotto la pari). I prezzi cambiano ogni giorno.
