Workbook

Sheet 0 - Indice
A1: Simulatore BTP Italia Si vs altri BTP retail (giugno 2026)
A2: Strumento informativo / divulgativo. NON è consulenza finanziaria. I valori sono indicativi al 2026 e vanno verificati col tuo consulente.
A4: Indice
A5: 1 - Parametri | B5: Input centralizzati (modifica QUI dopo annuncio MEF 12 giu)
A6: 2 - BTP Italia Si | B6: Rendimento Si in 4 scenari inflazione FOI
A7: 3 - BTP Italia classico | B7: ="Capitale rivalutato + cedola reale "&SUBSTITUTE(ROUND('1 - Parametri'!B12*100,1)&"",".",",")&"% (giu 2030)"
A8: 4 - BTP Valore | B8: ="Step-up "&SUBSTITUTE(ROUND('1 - Parametri'!B15*100,2)&"",".",",")&"/"&SUBSTITUTE(ROUND('1 - Parametri'!B16*100,2)&"",".",",")&"/"&SUBSTITUTE(ROUND('1 - Parametri'!B17*100,2)&"",".",",")&" + YTM a prezzo MOT "&SUBSTITUTE(ROUND('1 - Parametri'!B64,2)&"",".",",")
A9: 5 - BTP Futura | B9: ="Storico 4a emissione + YTM a prezzo MOT "&SUBSTITUTE(ROUND('1 - Parametri'!B66,2)&"",".",",")
A10: 6 - BTP nominali | B10: Curva 2y/5y/10y rendimenti fissi
A11: 7 - MATRICE COMPARATIVA | B11: 6 strumenti x 4 scenari (rendimenti REALI netti)
A12: 8 - Break-even | B12: Soglia inflazione per ogni avversario
A13: 9 - 4 profili FIRE | B13: Allocazione consigliata
A14: 10 - Calcolatore | B14: Tuo profilo personale - raccomandazione automatica
A15: 11 - Flusso cedolare | B15: Calendario semestrale: quanto incassi e quando, cedola per cedola
A17: Come usare
A18: 1. Le celle GIALLE sono input — modificale coi tuoi numeri.
A19: 2. Le celle VERDI sono output — si aggiornano automaticamente.
A20: 3. Tutti i numeri di default sono al 2026 da fonti pubbliche.
A21: 4. Niente codice nascosto: l'Excel è solo formule modificabili.
A23: Fonti dati
A24: • MEF Dipartimento del Tesoro - Annuncio BTP Italia Si dal 15 al 19 giugno 2026
A25: ="• MEF - BTP Italia marzo 2028 (IT0005532723, scad. 14/03/2028) tasso reale "&SUBSTITUTE(ROUND('1 - Parametri'!B11*100,1)&"",".",",")&"%; giugno 2030 (IT0005497000) tasso reale "&SUBSTITUTE(ROUND('1 - Parametri'!B12*100,1)&"",".",",")&"%"
A26: ="• MEF - BTP Valore marzo 2026 (IT0005696338) step-up DEFINITIVI "&SUBSTITUTE(ROUND('1 - Parametri'!B15*100,2)&"",".",",")&"/"&SUBSTITUTE(ROUND('1 - Parametri'!B16*100,2)&"",".",",")&"/"&SUBSTITUTE(ROUND('1 - Parametri'!B17*100,2)&"",".",",")&"% + premio "&SUBSTITUTE(ROUND('1 - Parametri'!B18*100,1)&"",".",",")&"%, scadenza 10 mar 2032"
A27: ="• MEF - BTP Futura 4a emissione nov 2021 (IT0005466351), "&'1 - Parametri'!B27&" anni step-up DEFINITIVI "&SUBSTITUTE(ROUND('1 - Parametri'!B22*100,2)&"",".",",")&"/"&SUBSTITUTE(ROUND('1 - Parametri'!B23*100,2)&"",".",",")&"/"&SUBSTITUTE(ROUND('1 - Parametri'!B24*100,2)&"",".",",")&"% + doppio premio PIL (solo sottoscrittori originali), scadenza 16 nov 2033"
A28: ="• Borsa Italiana MOT - prezzi ufficiali correnti (foglio 1 - Parametri): mar 2028 "&SUBSTITUTE(ROUND('1 - Parametri'!B46,2)&"",".",",")&"; giu 2030 "&SUBSTITUTE(ROUND('1 - Parametri'!B48,2)&"",".",",")&"; Valore "&SUBSTITUTE(ROUND('1 - Parametri'!B64,2)&"",".",",")&"; Futura "&SUBSTITUTE(ROUND('1 - Parametri'!B66,2)&"",".",",")
A29: • MEF Tesoro - Calendario aste BTP nominali maggio 2026 (asta 13 e 28 maggio)
A30: • Banca d'Italia - Risultati aste BTP nominali 2026 (rendimenti curva 2y-10y)
A31: • ISTAT - Indice FOI per famiglie operai e impiegati (escluso tabacchi) - meccanismo BTP Italia
A32: • Eurostat - HICP eurozona per BTPi (non incluso in matrice; alternativa istituzionale)
A33: • Borsa Italiana MOT - mercato secondario BTP retail (liquidita' supportata da Dealer MEF)
A35: Aggiornamenti: github.com/marcofire-it/marco-fire-simulatori

Sheet 1 - Parametri
A1: PARAMETRI CENTRALIZZATI (modifica QUI, tutto il resto si aggiorna)
A2: Strumento informativo / divulgativo. NON è consulenza finanziaria. I valori sono indicativi al 2026 e vanno verificati col tuo consulente.
A4: BTP Italia Si - emissione 15-19 giugno 2026
A5: Tasso fisso reale annuo (possibile rialzo a chiusura 19/06) | B5: 0.016 | D5: Tasso minimo garantito annunciato dal MEF in apertura emissione. Puo' essere rivisto AL RIALZO (mai al ribasso) alla chiusura del collocamento, ven 19/06/2026 ore 13. Se rivisto, aggiorna SOLO questa cella e tutte le simulazioni si ricalcolano.
A6: Durata (anni) | B6: 5 | D6: ="Fissa: "&B6&" anni"
A7: Premio fedelta' finale | B7: 0.006 | D7: ="Confermato MEF: "&SUBSTITUTE(ROUND(B7*100,1)&"",".",",")&"% del capitale (solo se mantenuto a scadenza)"
A8: Tassazione titoli di stato | B8: 0.125 | D8: ="Aliquota "&SUBSTITUTE(ROUND(B8*100,1)&"",".",",")&"% su cedole + premio finale"
A10: BTP Italia classico in essere (riferimenti secondario MOT)
A11: BTP Italia mar 2028 - cedola reale annua | B11: 0.02 | D11: ="MEF IT0005532723, scadenza 14/03/2028: tasso reale "&SUBSTITUTE(ROUND(B11*100,1)&"",".",",")&"% sul prospetto (rendimento per chi compra a 100)."
A12: BTP Italia giu 2030 - cedola reale annua | B12: 0.016 | D12: ="MEF IT0005497000, scadenza 28/06/2030: tasso reale "&SUBSTITUTE(ROUND(B12*100,1)&"",".",",")&"% sul prospetto"
A14: BTP Valore (7a emissione marzo 2026, ISIN IT0005696338, secondario)
A15: Cedola step-up anni 1-2 | B15: 0.026 | D15: ="MEF: "&SUBSTITUTE(ROUND(B15*100,2)&"",".",",")&"% definitivo (cedole trimestrali)"
A16: Cedola step-up anni 3-4 | B16: 0.032 | D16: ="MEF: "&SUBSTITUTE(ROUND(B16*100,2)&"",".",",")&"% definitivo (il 2,80 era il minimo garantito pre-collocamento)"
A17: Cedola step-up anni 5-6 | B17: 0.038 | D17: ="MEF: "&SUBSTITUTE(ROUND(B17*100,2)&"",".",",")&"% (definitivo)"
A18: Premio fedelta' | B18: 0.008 | D18: ="MEF: "&SUBSTITUTE(ROUND(B18*100,1)&"",".",",")&"% del capitale a scadenza (solo sottoscrittori in collocamento)"
A19: Durata (anni) | B19: 6 | D19: Scadenza 10 mar 2032
A21: BTP Futura 4a emissione nov 2021 (sospeso, ISIN IT0005466351 sul MOT)
A22: Cedola step-up anni 1-4 | B22: 0.0075 | D22: ="MEF 4a emissione nov 2021, step DEFINITIVI: "&SUBSTITUTE(ROUND(B22*100,2)&"",".",",")&"% (NON 0,35 = 2a emissione)"
A23: Cedola step-up anni 5-8 | B23: 0.0135 | D23: ="MEF definitivo: "&SUBSTITUTE(ROUND(B23*100,2)&"",".",",")&"% (anni 5-8)"
A24: Cedola step-up anni 9-12 | B24: 0.017 | D24: ="MEF definitivo: "&SUBSTITUTE(ROUND(B24*100,2)&"",".",",")&"% (anni 9-12)"
A25: Premio fedelta' min (PIL) | B25: 0.004 | D25: ="Floor "&SUBSTITUTE(ROUND(B25*100,1)&"",".",",")&"% se PIL nominale basso (solo sottoscrittori originali)"
A26: Premio fedelta' max (PIL) | B26: 0.03 | D26: ="Cap "&SUBSTITUTE(ROUND(B26*100,1)&"",".",",")&"% se PIL nominale alto (solo sottoscrittori originali)"
A27: Durata (anni) | B27: 12 | D27: 4a emissione (4+4+4 step-up), scadenza 16/11/2033
A29: BTP nominali - curva 2026 (asta MEF)
A30: BTP 2y - rendimento lordo (feb 2028) | B30: 0.028 | D30: ="MEF asta: "&SUBSTITUTE(ROUND(B30*100,2)&"",".",",")&"%"
A31: BTP 3y - rendimento lordo (mar 2029) | B31: 0.029 | D31: ="MEF asta: "&SUBSTITUTE(ROUND(B31*100,2)&"",".",",")&"%"
A32: BTP 5y - rendimento lordo (stima) | B32: 0.0313 | D32: Stima interpolata 2y-7y curva 2026
A33: BTP 7y - rendimento lordo (mar 2033) | B33: 0.0344 | D33: ="MEF asta: "&SUBSTITUTE(ROUND(B33*100,2)&"",".",",")&"%"
A34: BTP 10y - rendimento lordo (feb 2036) | B34: 0.0374 | D34: ="MEF asta: "&SUBSTITUTE(ROUND(B34*100,2)&"",".",",")&"%"
A36: ="Scenari inflazione FOI media "&B6&" anni (per simulazioni)"
A37: Scenario 1: Disinflazione | B37: 0.01 | D37: ="BCE stretta riuscita - inflazione "&SUBSTITUTE(ROUND(B37*100,1)&"",".",",")&"%"
A38: Scenario 2: Base BCE | B38: 0.02 | D38: ="Target "&SUBSTITUTE(ROUND(B38*100,1)&"",".",",")&"% medio termine"
A39: Scenario 3: Persistente | B39: 0.03 | D39: ="Inflazione strutturale "&SUBSTITUTE(ROUND(B39*100,1)&"",".",",")&"%"
A40: Scenario 4: Stress geopol. | B40: 0.045 | D40: ="Brent 120 USD persistente - "&SUBSTITUTE(ROUND(B40*100,1)&"",".",",")&"%"
A42: Setup simulazioni
A43: Capitale investito (EUR) | B43: 10000 | D43: Importo scalabile per tutte le simulazioni
A45: BTP Italia classico - PREZZI MOT (YTM reale effettivo per chi compra al secondario)
A46: Prezzo secondario BTP Italia mar 2028 | B46: 101.83 | C46: Anni residui | D46: 1.8
A47: ="Quotazione ufficiale MOT corrente: "&SUBSTITUTE(ROUND(B46,2)&"",".",",")&" (100 = par). Aggiorna col valore corrente quando cambia il mercato."
A48: Prezzo secondario BTP Italia giu 2030 | B48: 101.86 | C48: Anni residui | D48: 4
...

Sheet 2 - BTP Italia Si
A1: BTP Italia Si - rendimento netto in 4 scenari inflazione FOI
A2: Strumento informativo / divulgativo. NON è consulenza finanziaria. I valori sono indicativi al 2026 e vanno verificati col tuo consulente.
A4: Input (da foglio Parametri)
A5: Tasso fisso reale annuo | B5: ='1 - Parametri'!B5
A6: Durata (anni) | B6: ='1 - Parametri'!B6
A7: Premio fedelta' finale | B7: ='1 - Parametri'!B7
A8: Tassazione | B8: ='1 - Parametri'!B8
A9: Capitale investito (EUR) | B9: ='1 - Parametri'!B43
A11: Cedola annua lorda = fisso + inflazione FOI media
A12: Scenario inflazione | B12: Infl. FOI media | C12: Cedola lorda annua | D12: Cedola netta annua | E12: Importo netto su cap.
A13: ="1 - Disinflazione "&SUBSTITUTE(ROUND('1 - Parametri'!B37*100,1)&"",".",",")&"%" | B13: ='1 - Parametri'!B37 | C13: =$B$5+B13 | D13: =C13*(1-$B$8) | E13: =$B$9*D13
A14: ="2 - Base BCE "&SUBSTITUTE(ROUND('1 - Parametri'!B38*100,1)&"",".",",")&"%" | B14: ='1 - Parametri'!B38 | C14: =$B$5+B14 | D14: =C14*(1-$B$8) | E14: =$B$9*D14
A15: ="3 - Persistente "&SUBSTITUTE(ROUND('1 - Parametri'!B39*100,1)&"",".",",")&"%" | B15: ='1 - Parametri'!B39 | C15: =$B$5+B15 | D15: =C15*(1-$B$8) | E15: =$B$9*D15
A16: ="4 - Stress geopol. "&SUBSTITUTE(ROUND('1 - Parametri'!B40*100,1)&"",".",",")&"%" | B16: ='1 - Parametri'!B40 | C16: =$B$5+B16 | D16: =C16*(1-$B$8) | E16: =$B$9*D16
A18: ="Rendimento totale finale "&'1 - Parametri'!B6&" anni (netto, con premio "&SUBSTITUTE(ROUND('1 - Parametri'!B7*100,1)&"",".",",")&"%)"
A19: Scenario | B19: ="Cedole nette tot "&$B$6&"y" | C19: Premio netto fedelta' | D19: Tot. netto incassato | E19: IRR nom netto annuo (lineare) | F19: IRR reale netto
A20: ="1 - Disinflazione "&SUBSTITUTE(ROUND('1 - Parametri'!B37*100,1)&"",".",",")&"%" | B20: =E13*$B$6 | C20: =$B$9*$B$7*(1-$B$8) | D20: =B20+C20 | E20: =ROUND(($B$5+$B$7/$B$6+B13)*(1-$B$8),6) | F20: =E20-B13
A21: ="2 - Base BCE "&SUBSTITUTE(ROUND('1 - Parametri'!B38*100,1)&"",".",",")&"%" | B21: =E14*$B$6 | C21: =$B$9*$B$7*(1-$B$8) | D21: =B21+C21 | E21: =ROUND(($B$5+$B$7/$B$6+B14)*(1-$B$8),6) | F21: =E21-B14
A22: ="3 - Persistente "&SUBSTITUTE(ROUND('1 - Parametri'!B39*100,1)&"",".",",")&"%" | B22: =E15*$B$6 | C22: =$B$9*$B$7*(1-$B$8) | D22: =B22+C22 | E22: =ROUND(($B$5+$B$7/$B$6+B15)*(1-$B$8),6) | F22: =E22-B15
A23: ="4 - Stress geopol. "&SUBSTITUTE(ROUND('1 - Parametri'!B40*100,1)&"",".",",")&"%" | B23: =E16*$B$6 | C23: =$B$9*$B$7*(1-$B$8) | D23: =B23+C23 | E23: =ROUND(($B$5+$B$7/$B$6+B16)*(1-$B$8),6) | F23: =E23-B16
A25: NOTA: BTP Italia Si NON rivaluta il capitale (resta a 100)
A26: Differenza chiave vs BTP Italia classico: qui l'inflazione alimenta solo la cedola, il capitale a scadenza torna nominale.

Sheet 3 - BTP Italia classico
A1: BTP Italia classico - capitale rivalutato per inflazione FOI
A2: Strumento informativo / divulgativo. NON è consulenza finanziaria. I valori sono indicativi al 2026 e vanno verificati col tuo consulente.
A4: Input (BTP Italia giugno 2030 come riferimento)
A5: Tasso reale annuo (giu 2030) | B5: ='1 - Parametri'!B12
A6: Durata residua simulata (anni) | B6: 5
A7: Tassazione | B7: ='1 - Parametri'!B8
A8: Capitale investito (EUR) | B8: ='1 - Parametri'!B43
A10: Meccanismo classico: cedola reale + capitale rivalutato
A11: Scenario inflazione | B11: ="FOI cumulata "&$B$6&"y" | C11: Capitale rivalutato | D11: ="Cedole nette "&$B$6&"y (su cap. rivalut.)" | E11: ="Tot. netto "&$B$6&"y (cedole + rivalut.)"
A12: ="1 - Disinflazione "&SUBSTITUTE(ROUND('1 - Parametri'!B37*100,1)&"",".",",")&"%" | B12: ='1 - Parametri'!B37 | C12: =$B$8*(1+B12)^$B$6 | D12: =$B$5*$B$8*((1+B12)^$B$6-1)/B12*(1-$B$7) | E12: =(C12-$B$8)*(1-$B$7)+D12
A13: ="2 - Base BCE "&SUBSTITUTE(ROUND('1 - Parametri'!B38*100,1)&"",".",",")&"%" | B13: ='1 - Parametri'!B38 | C13: =$B$8*(1+B13)^$B$6 | D13: =$B$5*$B$8*((1+B13)^$B$6-1)/B13*(1-$B$7) | E13: =(C13-$B$8)*(1-$B$7)+D13
A14: ="3 - Persistente "&SUBSTITUTE(ROUND('1 - Parametri'!B39*100,1)&"",".",",")&"%" | B14: ='1 - Parametri'!B39 | C14: =$B$8*(1+B14)^$B$6 | D14: =$B$5*$B$8*((1+B14)^$B$6-1)/B14*(1-$B$7) | E14: =(C14-$B$8)*(1-$B$7)+D14
A15: ="4 - Stress geopol. "&SUBSTITUTE(ROUND('1 - Parametri'!B40*100,1)&"",".",",")&"%" | B15: ='1 - Parametri'!B40 | C15: =$B$8*(1+B15)^$B$6 | D15: =$B$5*$B$8*((1+B15)^$B$6-1)/B15*(1-$B$7) | E15: =(C15-$B$8)*(1-$B$7)+D15
A17: IRR netto annuo a confronto
A18: Scenario | B18: ="Tot. netto "&$B$6&"y" | C18: IRR netto annuo
A19: ="1 - Disinflazione "&SUBSTITUTE(ROUND('1 - Parametri'!B37*100,1)&"",".",",")&"%" | B19: =E12 | C19: =((E12+$B$8)/$B$8)^(1/$B$6)-1
A20: ="2 - Base BCE "&SUBSTITUTE(ROUND('1 - Parametri'!B38*100,1)&"",".",",")&"%" | B20: =E13 | C20: =((E13+$B$8)/$B$8)^(1/$B$6)-1
A21: ="3 - Persistente "&SUBSTITUTE(ROUND('1 - Parametri'!B39*100,1)&"",".",",")&"%" | B21: =E14 | C21: =((E14+$B$8)/$B$8)^(1/$B$6)-1
A22: ="4 - Stress geopol. "&SUBSTITUTE(ROUND('1 - Parametri'!B40*100,1)&"",".",",")&"%" | B22: =E15 | C22: =((E15+$B$8)/$B$8)^(1/$B$6)-1
A24: NOTA: vantaggio classico vs Si quando inflazione e' alta (capitale +)
A25: Classico: l'inflazione cresce IL CAPITALE (effetto compounding). Si: l'inflazione cresce SOLO la cedola annua. Trade-off: sul secondario il classico si paga al prezzo MOT corrente (vedi foglio Parametri) e chi compra usato NON ha il premio fedelta'.

Sheet 4 - BTP Valore
A1: BTP Valore (marzo 2026) - step-up 2+2+2 cedole trimestrali
A2: Strumento informativo / divulgativo. NON è consulenza finanziaria. I valori sono indicativi al 2026 e vanno verificati col tuo consulente.
A4: Input
A5: Cedola anni 1-2 | B5: ='1 - Parametri'!B15
A6: Cedola anni 3-4 | B6: ='1 - Parametri'!B16
A7: Cedola anni 5-6 | B7: ='1 - Parametri'!B17
A8: Premio fedelta' | B8: ='1 - Parametri'!B18
A9: Durata (anni) | B9: ='1 - Parametri'!B19
A10: Tassazione | B10: ='1 - Parametri'!B8
A11: Capitale investito | B11: ='1 - Parametri'!B43
A13: Cedole nette per fase step-up
A14: Fase | B14: Cedola lorda annua | C14: Cedola netta annua | D14: Importo netto x anno | E14: Importo netto x fase (2y)
A15: ="Anni 1-2 ("&SUBSTITUTE(ROUND(B5*100,2)&"",".",",")&"%)" | B15: =B5 | C15: =B5*(1-$B$10) | D15: =$B$11*C15 | E15: =D15*2
A16: ="Anni 3-4 ("&SUBSTITUTE(ROUND(B6*100,2)&"",".",",")&"%)" | B16: =B6 | C16: =B6*(1-$B$10) | D16: =$B$11*C16 | E16: =D16*2
A17: ="Anni 5-6 ("&SUBSTITUTE(ROUND(B7*100,2)&"",".",",")&"%)" | B17: =B7 | C17: =B7*(1-$B$10) | D17: =$B$11*C17 | E17: =D17*2
A19: ="Rendimento totale netto "&B9&" anni"
A20: ="Tot. cedole nette "&B9&"y" | B20: =E15+E16+E17
A21: Premio fedelta' netto | B21: =B11*B8*(1-B10)
A22: ="Tot. netto "&B9&"y" | B22: =B20+B21
A23: IRR nom netto annuo (lineare) | B23: =ROUND(((B5+B6+B7)/3+B8/B9)*(1-B10),6)
A25: NOTA: il BTP Valore NON e' indicizzato all'inflazione
A26: Cedole step-up FISSE in nominale. In inflazione alta perde potere d'acquisto reale. Vantaggio: cedola trimestrale (vs semestrale altri BTP) per pianificazione cassa.
A28: ="Comprato OGGI sul MOT - YTM a prezzo "&SUBSTITUTE(ROUND('1 - Parametri'!B64,2)&"",".",",")&IF('1 - Parametri'!B64<100," (sotto la pari)",IF('1 - Parametri'!B64>100," (sopra la pari)"," (alla pari)"))
A29: Prezzo MOT corrente (vedi foglio Parametri) | B29: ='1 - Parametri'!B64
A30: Anni residui (scad. 10/03/2032) | B30: ='1 - Parametri'!D64
A31: Cedola media residua (step pesati sugli anni rimasti) | B31: =(B5*MAX(0,B30-4)+B6*MIN(2,MAX(0,B30-2))+B7*MIN(2,B30))/B30
A32: YTM lordo (formula bond equivalent yield) | B32: =(B31*100+(100-B29)/B30)/((100+B29)/2)+'1 - Parametri'!B78
A33: ="YTM netto (tassazione "&SUBSTITUTE(ROUND(B10*100,1)&"",".",",")&"%)" | B33: =B32*(1-B10)
A34: ="Prezzo MOT corrente "&SUBSTITUTE(ROUND(B29,2)&"",".",",")&": YTM lordo ~"&SUBSTITUTE(ROUND(B32*100,2)&"",".",",")&"% vs media cedole residue ~"&SUBSTITUTE(ROUND(B31*100,2)&"",".",",")&"%. Se il prezzo e' sotto la pari il YTM supera la media cedole (sconto), se sopra la riduce. ATTENZIONE: il premio fedelta' "&SUBSTITUTE(ROUND(B8*100,1)&"",".",",")&"% NON spetta a chi compra sul MOT (solo sottoscrittori in collocamento), percio' il YTM qui sopra NON lo include."
A36: IRR reale netto per scenario (da YTM MOT)
A37: Scenario inflazione | B37: Infl. FOI media | C37: IRR reale netto (YTM netto - FOI)
A38: ="1 - Disinflazione "&SUBSTITUTE(ROUND('1 - Parametri'!B37*100,1)&"",".",",")&"%" | B38: ='1 - Parametri'!B37 | C38: =$B$33-B38
A39: ="2 - Base BCE "&SUBSTITUTE(ROUND('1 - Parametri'!B38*100,1)&"",".",",")&"%" | B39: ='1 - Parametri'!B38 | C39: =$B$33-B39
A40: ="3 - Persistente "&SUBSTITUTE(ROUND('1 - Parametri'!B39*100,1)&"",".",",")&"%" | B40: ='1 - Parametri'!B39 | C40: =$B$33-B40
A41: ="4 - Stress geopol. "&SUBSTITUTE(ROUND('1 - Parametri'!B40*100,1)&"",".",",")&"%" | B41: ='1 - Parametri'!B40 | C41: =$B$33-B41

Sheet 5 - BTP Futura
A1: BTP Futura - sospeso, ricostruzione storica 4a emissione 12y
A2: Strumento informativo / divulgativo. NON è consulenza finanziaria. I valori sono indicativi al 2026 e vanno verificati col tuo consulente.
A4: Input
A5: Cedola anni 1-4 | B5: ='1 - Parametri'!B22
A6: Cedola anni 5-8 | B6: ='1 - Parametri'!B23
A7: Cedola anni 9-12 | B7: ='1 - Parametri'!B24
A8: Premio min (PIL basso) | B8: ='1 - Parametri'!B25
A9: Premio max (PIL alto) | B9: ='1 - Parametri'!B26
A10: Durata (anni) | B10: ='1 - Parametri'!B27
A11: Tassazione | B11: ='1 - Parametri'!B8
A12: Capitale | B12: ='1 - Parametri'!B43
A14: Scenari di PIL nominale e premio fedelta'
A15: Scenario PIL nominale medio | B15: PIL nom. medio | C15: Premio fed. atteso | D15: ="Cedole nette "&$B$10&"y" | E15: ="Tot. netto "&$B$10&"y" | F15: IRR nom netto annuo (lineare)
A16: ="Bassa (PIL "&SUBSTITUTE(ROUND(B16*100,1)&"",".",",")&"%)" | B16: 0.015 | C16: =MAX($B$8,MIN($B$9,0.4*B16)) | D16: =$B$12*(4*$B$5+4*$B$6+4*$B$7)*(1-$B$11) | E16: =D16+$B$12*C16*(1-$B$11) | F16: =E16/$B$12/$B$10
A17: ="Base (PIL "&SUBSTITUTE(ROUND(B17*100,1)&"",".",",")&"%)" | B17: 0.03 | C17: =MAX($B$8,MIN($B$9,0.4*B17)) | D17: =$B$12*(4*$B$5+4*$B$6+4*$B$7)*(1-$B$11) | E17: =D17+$B$12*C17*(1-$B$11) | F17: =E17/$B$12/$B$10
A18: ="Alta (PIL "&SUBSTITUTE(ROUND(B18*100,1)&"",".",",")&"%)" | B18: 0.045 | C18: =MAX($B$8,MIN($B$9,0.4*B18)) | D18: =$B$12*(4*$B$5+4*$B$6+4*$B$7)*(1-$B$11) | E18: =D18+$B$12*C18*(1-$B$11) | F18: =E18/$B$12/$B$10
A20: NOTA: BTP Futura NON e' piu' emesso dal 2021 (ricostruzione storica = contesto)
A21: ="La tabella sopra RICOSTRUISCE il collocamento nov 2021 (chi sottoscrisse a 100 con premio PIL). Struttura step-up 4+4+4 anni DEFINITIVA 4a emissione (1-4: "&SUBSTITUTE(ROUND(B5*100,2)&"",".",",")&"%, 5-8: "&SUBSTITUTE(ROUND(B6*100,2)&"",".",",")&"%, 9-12: "&SUBSTITUTE(ROUND(B7*100,2)&"",".",",")&"%). Per chi compra OGGI vale la sezione qui sotto: prezzo MOT "&SUBSTITUTE(ROUND(B24,2)&"",".",",")&" e NIENTE premio PIL."
A23: ="Comprato OGGI sul MOT - prezzo "&SUBSTITUTE(ROUND(B24,2)&"",".",",")&" → YTM lordo ~"&SUBSTITUTE(ROUND(B27*100,2)&"",".",",")&"%"
A24: Prezzo MOT corrente (vedi foglio Parametri) | B24: ='1 - Parametri'!B66
A25: Anni residui (scad. 16/11/2033) | B25: ='1 - Parametri'!D66
A26: Cedola media residua (step pesati sugli anni rimasti) | B26: =(B5*MAX(0,B25-8)+B6*MIN(4,MAX(0,B25-4))+B7*MIN(4,B25))/B25
A27: YTM lordo (formula bond equivalent yield) | B27: =(B26*100+(100-B24)/B25)/((100+B24)/2)+'1 - Parametri'!B79
A28: ="YTM netto (tassazione "&SUBSTITUTE(ROUND(B11*100,1)&"",".",",")&"%)" | B28: =B27*(1-B11)
A29: ="Lo sconto/premio sul prezzo MOT corrente ("&SUBSTITUTE(ROUND(B24,2)&"",".",",")&") si somma alle cedole: parte del rendimento arriva dal capital gain a scadenza (100 - "&SUBSTITUTE(ROUND(B24,2)&"",".",",")&" su "&SUBSTITUTE(ROUND(B25,1)&"",".",",")&" anni). ATTENZIONE: il doppio premio PIL spetta SOLO ai sottoscrittori originali del nov 2021, NON a chi compra sul MOT — il YTM qui sopra correttamente lo esclude."
A31: IRR reale netto per scenario (da YTM MOT)
A32: Scenario inflazione | B32: Infl. FOI media | C32: IRR reale netto (YTM netto - FOI)
A33: ="1 - Disinflazione "&SUBSTITUTE(ROUND('1 - Parametri'!B37*100,1)&"",".",",")&"%" | B33: ='1 - Parametri'!B37 | C33: =$B$28-B33
A34: ="2 - Base BCE "&SUBSTITUTE(ROUND('1 - Parametri'!B38*100,1)&"",".",",")&"%" | B34: ='1 - Parametri'!B38 | C34: =$B$28-B34
A35: ="3 - Persistente "&SUBSTITUTE(ROUND('1 - Parametri'!B39*100,1)&"",".",",")&"%" | B35: ='1 - Parametri'!B39 | C35: =$B$28-B35
A36: ="4 - Stress geopol. "&SUBSTITUTE(ROUND('1 - Parametri'!B40*100,1)&"",".",",")&"%" | B36: ='1 - Parametri'!B40 | C36: =$B$28-B36

Sheet 6 - BTP nominali
A1: BTP nominali - curva tassi 2026 (cedola fissa, NO inflazione)
A2: Strumento informativo / divulgativo. NON è consulenza finanziaria. I valori sono indicativi al 2026 e vanno verificati col tuo consulente.
A4: Input curva (da foglio Parametri)
A5: Scadenza | B5: Rendimento lordo | C5: Cedola netta annua | D5: Tot. cedole nette a scad. | E5: Cedola netta annua EUR
A6: Tassazione titoli di Stato applicata | B6: ='1 - Parametri'!B8
A7: Capitale (default Parametri) | B7: ='1 - Parametri'!B43
B8: Rendim. lordo (curva)
A9: 2 anni (feb 2028) | B9: ='1 - Parametri'!B30 | C9: =B9*(1-$B$6) | D9: =$B$7*C9*2 | E9: =$B$7*C9
A10: 3 anni (mar 2029) | B10: ='1 - Parametri'!B31 | C10: =B10*(1-$B$6) | D10: =$B$7*C10*3 | E10: =$B$7*C10
A11: 5 anni (stima) | B11: ='1 - Parametri'!B32 | C11: =B11*(1-$B$6) | D11: =$B$7*C11*5 | E11: =$B$7*C11
A12: 7 anni (mar 2033) | B12: ='1 - Parametri'!B33 | C12: =B12*(1-$B$6) | D12: =$B$7*C12*7 | E12: =$B$7*C12
A13: 10 anni (feb 2036) | B13: ='1 - Parametri'!B34 | C13: =B13*(1-$B$6) | D13: =$B$7*C13*10 | E13: =$B$7*C13
A16: NOTA: BTP nominali NON proteggono dall'inflazione
A17: Rendimento certo in nominale. Se inflazione > rendimento, perdi potere d'acquisto. Vantaggio: rendimento bloccato a scadenza, e possibile plusvalenza se i tassi BCE scendono.

Sheet 7 - MATRICE COMPARATIVA
A1: MATRICE: rendimento REALE netto annuo - 6 strumenti x 4 scenari
A2: Strumento informativo / divulgativo. NON è consulenza finanziaria. I valori sono indicativi al 2026 e vanno verificati col tuo consulente.
A4: Tutti i valori sono IRR REALI annui netti (lordo - tasse - inflazione)
A5: Strumento | B5: ="Infl. "&SUBSTITUTE(ROUND('1 - Parametri'!B37*100,1)&"",".",",")&"%" | C5: ="Infl. "&SUBSTITUTE(ROUND('1 - Parametri'!B38*100,1)&"",".",",")&"%" | D5: ="Infl. "&SUBSTITUTE(ROUND('1 - Parametri'!B39*100,1)&"",".",",")&"%" | E5: ="Infl. "&SUBSTITUTE(ROUND('1 - Parametri'!B40*100,1)&"",".",",")&"%"
A6: ="BTP Italia Si ("&SUBSTITUTE(ROUND('1 - Parametri'!B5*100,1)&"",".",",")&"% + FOI)" | B6: =ROUND(('1 - Parametri'!B5+('1 - Parametri'!B7/'1 - Parametri'!B6)+'1 - Parametri'!B37)*(1-'1 - Parametri'!B8)-'1 - Parametri'!B37,6) | C6: =ROUND(('1 - Parametri'!B5+('1 - Parametri'!B7/'1 - Parametri'!B6)+'1 - Parametri'!B38)*(1-'1 - Parametri'!B8)-'1 - Parametri'!B38,6) | D6: =ROUND(('1 - Parametri'!B5+('1 - Parametri'!B7/'1 - Parametri'!B6)+'1 - Parametri'!B39)*(1-'1 - Parametri'!B8)-'1 - Parametri'!B39,6) | E6: =ROUND(('1 - Parametri'!B5+('1 - Parametri'!B7/'1 - Parametri'!B6)+'1 - Parametri'!B40)*(1-'1 - Parametri'!B8)-'1 - Parametri'!B40,6)
A7: BTP Italia classico (YTM reale MOT) | B7: ='1 - Parametri'!B56*(1-'1 - Parametri'!B8)-'1 - Parametri'!B8*'1 - Parametri'!B37 | C7: ='1 - Parametri'!B56*(1-'1 - Parametri'!B8)-'1 - Parametri'!B8*'1 - Parametri'!B38 | D7: ='1 - Parametri'!B56*(1-'1 - Parametri'!B8)-'1 - Parametri'!B8*'1 - Parametri'!B39 | E7: ='1 - Parametri'!B56*(1-'1 - Parametri'!B8)-'1 - Parametri'!B8*'1 - Parametri'!B40
A8: ="BTP Valore (YTM lordo MOT ~"&SUBSTITUTE(ROUND('4 - BTP Valore'!$B$32*100,2)&"",".",",")&"%)" | B8: ='4 - BTP Valore'!$B$32*(1-'1 - Parametri'!B8)-'1 - Parametri'!B37 | C8: ='4 - BTP Valore'!$B$32*(1-'1 - Parametri'!B8)-'1 - Parametri'!B38 | D8: ='4 - BTP Valore'!$B$32*(1-'1 - Parametri'!B8)-'1 - Parametri'!B39 | E8: ='4 - BTP Valore'!$B$32*(1-'1 - Parametri'!B8)-'1 - Parametri'!B40
A9: ="BTP Futura (YTM lordo MOT ~"&SUBSTITUTE(ROUND('5 - BTP Futura'!$B$27*100,2)&"",".",",")&"%)" | B9: ='5 - BTP Futura'!$B$27*(1-'1 - Parametri'!B8)-'1 - Parametri'!B37 | C9: ='5 - BTP Futura'!$B$27*(1-'1 - Parametri'!B8)-'1 - Parametri'!B38 | D9: ='5 - BTP Futura'!$B$27*(1-'1 - Parametri'!B8)-'1 - Parametri'!B39 | E9: ='5 - BTP Futura'!$B$27*(1-'1 - Parametri'!B8)-'1 - Parametri'!B40
A10: ="BTP nominale 5y ("&SUBSTITUTE(ROUND('1 - Parametri'!B32*100,2)&"",".",",")&"% lordo)" | B10: ='1 - Parametri'!B32*(1-'1 - Parametri'!B8)-'1 - Parametri'!B37 | C10: ='1 - Parametri'!B32*(1-'1 - Parametri'!B8)-'1 - Parametri'!B38 | D10: ='1 - Parametri'!B32*(1-'1 - Parametri'!B8)-'1 - Parametri'!B39 | E10: ='1 - Parametri'!B32*(1-'1 - Parametri'!B8)-'1 - Parametri'!B40
A11: ="BTP nominale 10y ("&SUBSTITUTE(ROUND('1 - Parametri'!B34*100,2)&"",".",",")&"% lordo)" | B11: ='1 - Parametri'!B34*(1-'1 - Parametri'!B8)-'1 - Parametri'!B37 | C11: ='1 - Parametri'!B34*(1-'1 - Parametri'!B8)-'1 - Parametri'!B38 | D11: ='1 - Parametri'!B34*(1-'1 - Parametri'!B8)-'1 - Parametri'!B39 | E11: ='1 - Parametri'!B34*(1-'1 - Parametri'!B8)-'1 - Parametri'!B40
A13: Heatmap: VERDE = miglior rendimento REALE per scenario / ROSSO = peggior
A14: NOTA DI METODO - heatmap per colonna: VERDE = miglior rendimento REALE dello scenario, ROSSO = peggiore. Il tasso del Si e' REALE (si somma al FOI), quindi il suo rendimento reale resta stabile tra gli scenari; gli strumenti a cedola nominale fissa perdono rendimento reale al crescere dell'inflazione. Valore e Futura sono valutati allo YTM da prezzo MOT (comprati OGGI, senza premi fedelta'/PIL). Il vincitore di ogni scenario dipende dai parametri correnti del foglio 1 - Parametri.

Sheet 8 - Break-even
A1: Break-even: a quale inflazione media il BTP Italia Si batte ogni avversario
A2: Strumento informativo / divulgativo. NON è consulenza finanziaria. I valori sono indicativi al 2026 e vanno verificati col tuo consulente.
A4: Avversari a cedola FISSA nominale (break-even basato su inflazione)
A5: Avversario | B5: Rendimento lordo | C5: Rend. netto (dopo tasse) | D5: Soglia infl. break-even (lorda) | E5: Verdetto
A6: BTP nominale 2y | B6: ='1 - Parametri'!B30 | C6: =B6*(1-'1 - Parametri'!B8) | D6: =B6-('1 - Parametri'!B5+'1 - Parametri'!B7/'1 - Parametri'!B6) | E6: =IF(D6<=0,"Si vince SEMPRE",IF(D6>='1 - Parametri'!B40,"Si perde quasi sempre","Si vince se FOI > "&SUBSTITUTE(ROUND(D6*100,2)&"",".",",")&"%"))
A7: BTP nominale 3y | B7: ='1 - Parametri'!B31 | C7: =B7*(1-'1 - Parametri'!B8) | D7: =B7-('1 - Parametri'!B5+'1 - Parametri'!B7/'1 - Parametri'!B6) | E7: =IF(D7<=0,"Si vince SEMPRE",IF(D7>='1 - Parametri'!B40,"Si perde quasi sempre","Si vince se FOI > "&SUBSTITUTE(ROUND(D7*100,2)&"",".",",")&"%"))
A8: BTP nominale 5y | B8: ='1 - Parametri'!B32 | C8: =B8*(1-'1 - Parametri'!B8) | D8: =B8-('1 - Parametri'!B5+'1 - Parametri'!B7/'1 - Parametri'!B6) | E8: =IF(D8<=0,"Si vince SEMPRE",IF(D8>='1 - Parametri'!B40,"Si perde quasi sempre","Si vince se FOI > "&SUBSTITUTE(ROUND(D8*100,2)&"",".",",")&"%"))
A9: BTP nominale 7y | B9: ='1 - Parametri'!B33 | C9: =B9*(1-'1 - Parametri'!B8) | D9: =B9-('1 - Parametri'!B5+'1 - Parametri'!B7/'1 - Parametri'!B6) | E9: =IF(D9<=0,"Si vince SEMPRE",IF(D9>='1 - Parametri'!B40,"Si perde quasi sempre","Si vince se FOI > "&SUBSTITUTE(ROUND(D9*100,2)&"",".",",")&"%"))
A10: BTP nominale 10y | B10: ='1 - Parametri'!B34 | C10: =B10*(1-'1 - Parametri'!B8) | D10: =B10-('1 - Parametri'!B5+'1 - Parametri'!B7/'1 - Parametri'!B6) | E10: =IF(D10<=0,"Si vince SEMPRE",IF(D10>='1 - Parametri'!B40,"Si perde quasi sempre","Si vince se FOI > "&SUBSTITUTE(ROUND(D10*100,2)&"",".",",")&"%"))
A11: ="BTP Valore (YTM lordo MOT, prezzo "&SUBSTITUTE(ROUND('1 - Parametri'!B64,2)&"",".",",")&")" | B11: ='4 - BTP Valore'!B32 | C11: =B11*(1-'1 - Parametri'!B8) | D11: =B11-('1 - Parametri'!B5+'1 - Parametri'!B7/'1 - Parametri'!B6) | E11: =IF(D11<=0,"Si vince SEMPRE",IF(D11>='1 - Parametri'!B40,"Si perde quasi sempre","Si vince se FOI > "&SUBSTITUTE(ROUND(D11*100,2)&"",".",",")&"%"))
A12: ="BTP Futura (YTM lordo MOT, prezzo "&SUBSTITUTE(ROUND('1 - Parametri'!B66,2)&"",".",",")&")" | B12: ='5 - BTP Futura'!B27 | C12: =B12*(1-'1 - Parametri'!B8) | D12: =B12-('1 - Parametri'!B5+'1 - Parametri'!B7/'1 - Parametri'!B6) | E12: =IF(D12<=0,"Si vince SEMPRE",IF(D12>='1 - Parametri'!B40,"Si perde quasi sempre","Si vince se FOI > "&SUBSTITUTE(ROUND(D12*100,2)&"",".",",")&"%"))
A14: BTP Italia classico: confronto diverso (capitale rivalutato, no break-even classico)
A15: Avversario | B15: YTM reale NETTO (MOT) | C15: Sì reale netto | D15: Vantaggio Sì (pp) | E15: Verdetto
A16: BTP Italia classico mar 2028 (YTM REALE da prezzo MOT) | B16: ='1 - Parametri'!B50*(1-'1 - Parametri'!B8) | C16: =('1 - Parametri'!B5+'1 - Parametri'!B7/'1 - Parametri'!B6)*(1-'1 - Parametri'!B8) | D16: =C16-B16 | E16: =IF(D16>=0,"Sì vince (vantaggio "&ROUND(D16*100,2)&"pp)","Classico vince (gap "&ROUND(-D16*100,2)&"pp)")
A17: BTP Italia classico giu 2030 (YTM REALE da prezzo MOT) | B17: ='1 - Parametri'!B52*(1-'1 - Parametri'!B8) | C17: =('1 - Parametri'!B5+'1 - Parametri'!B7/'1 - Parametri'!B6)*(1-'1 - Parametri'!B8) | D17: =C17-B17 | E17: =IF(D17>=0,"Sì vince (vantaggio "&ROUND(D17*100,2)&"pp)","Classico vince (gap "&ROUND(-D17*100,2)&"pp)")
A18: BTP Italia classico MEDIA 2 ISIN (YTM reale NETTO medio) | B18: ='1 - Parametri'!B56*(1-'1 - Parametri'!B8) | C18: =('1 - Parametri'!B5+'1 - Parametri'!B7/'1 - Parametri'!B6)*(1-'1 - Parametri'!B8) | D18: =C18-B18 | E18: =IF(D18>=0,"Sì vince (vantaggio "&ROUND(D18*100,2)&"pp)","Classico vince (gap "&ROUND(-D18*100,2)&"pp)")
A19: ="ATTENZIONE: usato YTM REALE EFFETTIVO calcolato dal prezzo MOT (non cedola del prospetto). Se sul secondario il classico quota SOPRA par, il YTM reale si abbassa, specie per scadenze brevi. Coi prezzi MOT correnti: mar 2028 a "&SUBSTITUTE(ROUND('1 - Parametri'!B46,2)&"",".",",")&" → YTM reale ~"&SUBSTITUTE(ROUND('1 - Parametri'!B50*100,2)&"",".",",")&"%; giu 2030 a "&SUBSTITUTE(ROUND('1 - Parametri'!B48,2)&"",".",",")&" → ~"&SUBSTITUTE(ROUND('1 - Parametri'!B52*100,2)&"",".",",")&"%. Vai al foglio Parametri righe 46-56 per modificare i prezzi MOT."
A21: ="BTP Futura comprato OGGI sul MOT a "&SUBSTITUTE(ROUND('1 - Parametri'!B66,2)&"",".",",")&": YTM lordo ~"&SUBSTITUTE(ROUND('5 - BTP Futura'!B27*100,2)&"",".",",")&"% con cedole step-up "&SUBSTITUTE(ROUND('1 - Parametri'!B22*100,2)&"",".",",")&"/"&SUBSTITUTE(ROUND('1 - Parametri'!B23*100,2)&"",".",",")&"/"&SUBSTITUTE(ROUND('1 - Parametri'!B24*100,2)&"",".",",")&"%. Soglia break-even FOI ~"&SUBSTITUTE(ROUND(D12*100,2)&"",".",",")&"% (col. D): sotto la soglia vince il Futura, sopra vince il Si; se la soglia e' negativa il Si vince sempre. Il doppio premio PIL NON spetta a chi compra sul MOT (solo sottoscrittori originali nov 2021)."

Sheet 9 - 4 profili FIRE
A1: 4 profili FIRE - allocazione consigliata tra i 5 strumenti
A2: Strumento informativo / divulgativo. NON è consulenza finanziaria. I valori sono indicativi al 2026 e vanno verificati col tuo consulente.
A4: Allocazione (% del cuscinetto bond del portafoglio)
A5: Profilo | B5: BTP Italia Si | C5: BTP Italia clas. | D5: BTP Valore | E5: BTP nominale 5y | F5: BTP nominale 10y
A6: Giovane 25-34 | B6: 0.2 | C6: 0.1 | D6: 0.2 | E6: 0.3 | F6: 0.2
A7: Mezza età 35-49 | B7: 0.25 | C7: 0.15 | D7: 0.2 | E7: 0.25 | F7: 0.15
A8: Over 50 pre-FIRE | B8: 0.3 | C8: 0.3 | D8: 0.2 | E8: 0.15 | F8: 0.05
A9: FIRE in decumulo | B9: 0.25 | C9: 0.35 | D9: 0.15 | E9: 0.15 | F9: 0.1
A11: Razionale per profilo
A12: Giovane: peso nominali alto (tassi sopra inflazione attesa), Si come 'difesa' inflazione.
A13: Mezza eta': bilanciato, Si cresce per protezione potere d'acquisto.
A14: Over 50: peso classico alto per crescita capitale; Si per cedola decrescente in real terms.
A15: Decumulo: priorita' capitale rivalutato (classico) + reddito stabile (Si + Valore).

Sheet 10 - Calcolatore personale
A1: Calcolatore: quale BTP scegliere in base ai tuoi parametri
A2: Strumento informativo / divulgativo. NON è consulenza finanziaria. I valori sono indicativi al 2026 e vanno verificati col tuo consulente.
A4: Input personali
A5: Tuo capitale (EUR) | B5: 20000
A6: Tuo orizzonte temporale (anni) | B6: 7
A7: Tua aspettativa inflazione FOI media (%) | B7: 0.025
A8: Tua aliquota IRPEF marginale (info) | B8: 0.33
A10: Rendimento REALE netto atteso per strumento
A11: Strumento | B11: Rend. reale annuo | C11: Idoneo al tuo orizzonte
A12: BTP Italia Si | B12: =('1 - Parametri'!B5+'1 - Parametri'!B7/'1 - Parametri'!B6)*(1-'1 - Parametri'!B8)-'1 - Parametri'!B8*B7 | C12: =IF(B6>=5,"SI","NO - troppo lungo")
A13: BTP Italia clas. (YTM MOT) | B13: ='1 - Parametri'!B56*(1-'1 - Parametri'!B8)-'1 - Parametri'!B8*B7 | C13: =IF(B6>=5,"SI","NO - troppo lungo")
A14: BTP Valore (YTM MOT) | B14: ='4 - BTP Valore'!B32*(1-'1 - Parametri'!B8)-B7 | C14: =IF(B6>=6,"SI","NO - troppo lungo")
A15: BTP nominale 5y | B15: ='1 - Parametri'!B32*(1-'1 - Parametri'!B8)-B7 | C15: =IF(B6>=5,"SI","NO - troppo lungo")
A16: BTP nominale 10y | B16: ='1 - Parametri'!B34*(1-'1 - Parametri'!B8)-B7 | C16: =IF(B6>=10,"SI","NO - troppo lungo")
A18: Raccomandazione automatica (strumento con rendimento reale max)
A19: Miglior strumento | B19: =INDEX(A12:A16,MATCH(MAX(B12:B16),B12:B16,0))
A20: Rendimento reale atteso annuo | B20: =MAX(B12:B16)
A21: Valore finale (con cap. + reale) | B21: =B5*(1+B20)^B6
A23: Raccomandazione algoritmica basata sul rendimento reale max. NON e' consulenza finanziaria. Considera anche liquidita', diversificazione, necessita' di reddito cedolare periodico.

Sheet 11 - Flusso cedolare
A1: BTP Italia Si - flusso cedolare semestrale (quanto incassi, quando)
A2: Strumento informativo / divulgativo. NON è consulenza finanziaria. I valori sono indicativi al 2026 e vanno verificati col tuo consulente.
A4: Input (tasso/premio/tassazione dal foglio Parametri; FOI modificabile QUI)
A5: Tasso fisso reale annuo | B5: ='1 - Parametri'!B5
A6: Premio fedelta' finale | B6: ='1 - Parametri'!B7
A7: Tassazione | B7: ='1 - Parametri'!B8
A8: Capitale investito (EUR) | B8: ='1 - Parametri'!B43
A9: Inflazione FOI media (scenario) | B9: 0.02 | C9: GIALLO = modificabile: 0,01 / 0,02 / 0,03 / 0,045
A11: Calendario cedole semestrali nette (convenzione lineare, FOI media costante)
A12: Stacco | B12: Data | C12: Cedola lorda | D12: Imposta | E12: Cedola netta | F12: Cumulato netto | G12: Flusso di cassa
A13: 1/10 | B13: 46371 | C13: =($B$5+$B$9)/2*$B$8 | D13: =C13*$B$7 | E13: =C13-D13 | F13: =E13 | G13: =E13
A14: 2/10 | B14: 46553 | C14: =($B$5+$B$9)/2*$B$8 | D14: =C14*$B$7 | E14: =C14-D14 | F14: =F13+E14 | G14: =E14
A15: 3/10 | B15: 46736 | C15: =($B$5+$B$9)/2*$B$8 | D15: =C15*$B$7 | E15: =C15-D15 | F15: =F14+E15 | G15: =E15
A16: 4/10 | B16: 46919 | C16: =($B$5+$B$9)/2*$B$8 | D16: =C16*$B$7 | E16: =C16-D16 | F16: =F15+E16 | G16: =E16
A17: 5/10 | B17: 47102 | C17: =($B$5+$B$9)/2*$B$8 | D17: =C17*$B$7 | E17: =C17-D17 | F17: =F16+E17 | G17: =E17
A18: 6/10 | B18: 47284 | C18: =($B$5+$B$9)/2*$B$8 | D18: =C18*$B$7 | E18: =C18-D18 | F18: =F17+E18 | G18: =E18
A19: 7/10 | B19: 47467 | C19: =($B$5+$B$9)/2*$B$8 | D19: =C19*$B$7 | E19: =C19-D19 | F19: =F18+E19 | G19: =E19
A20: 8/10 | B20: 47649 | C20: =($B$5+$B$9)/2*$B$8 | D20: =C20*$B$7 | E20: =C20-D20 | F20: =F19+E20 | G20: =E20
A21: 9/10 | B21: 47832 | C21: =($B$5+$B$9)/2*$B$8 | D21: =C21*$B$7 | E21: =C21-D21 | F21: =F20+E21 | G21: =E21
A22: 10/10 | B22: 48014 | C22: =($B$5+$B$9)/2*$B$8 | D22: =C22*$B$7 | E22: =C22-D22 | F22: =F21+E22 | G22: =E22
A23: Premio | B23: 48014 | C23: =$B$8*$B$6 | D23: =C23*$B$7 | E23: =C23-D23 | F23: =F22+E23 | G23: =E23
A24: Acquisto | B24: 46192 | G24: =-$B$8
A25: Rimborso | B25: 48014 | G25: =$B$8
A26: TOTALE NETTO 5 ANNI (cedole + premio) | F26: =F23
A28: IRR dai flussi di cassa
A29: IRR nominale netto EFFETTIVO (XIRR composto sui flussi) | F29: =XIRR(G13:G25,B13:B25)
A30: IRR nominale netto LINEARE (convenzione fogli 2-7) | F30: =ROUND(($B$5+$B$6/'1 - Parametri'!B6+$B$9)*(1-$B$7),6)
A31: IRR REALE netto effettivo (XIRR - FOI media) | F31: =F29-$B$9
A33: Note metodologiche
A34: Date indicative: godimento giugno 2026, cedole semestrali dicembre/giugno (15 del mese convenzionale; acquisto = chiusura collocamento 19/06/2026). Il FOI media e' un'ipotesi di scenario: le cedole effettive varieranno semestre per semestre con l'inflazione FOI rilevata da ISTAT. Il premio fedelta' spetta solo a chi sottoscrive in collocamento e tiene fino a scadenza. XIRR = rendimento composto effettivo sui flussi datati; differisce di pochi centesimi dall'IRR lineare divulgativo usato negli altri fogli (che non compone i reinvestimenti).

Sheet 12 - Switch
A1: Switch: conviene vendere un vecchio BTP Italia per il nuovo Si?
A2: Strumento informativo / divulgativo. NON è consulenza finanziaria. I valori sono indicativi al 2026 e vanno verificati col tuo consulente.
A4: Il tuo vecchio BTP Italia (quello che valuti di vendere)
A5: Nominale posseduto (EUR) | B5: 10000
A6: Prezzo MOT attuale (su 100) | B6: 101.4
A7: Tasso reale del vecchio (% annuo) | B7: 0.0185
A8: Anni residui alla scadenza | B8: 6
A10: Il nuovo BTP Italia Si (in emissione, a 100)
A11: Tasso reale | B11: ='1 - Parametri'!B5
A12: Premio fedelta' (a scadenza) | B12: ='1 - Parametri'!B7
A13: Durata (anni) | B13: ='1 - Parametri'!B6
A14: Rendimento reale annuo (comprato a 100) | B14: =B11+B12/B13
A16: Confronto: rendimento reale annuo DA OGGI
A17: Vecchio, tenuto a scadenza (sul prezzo attuale) | B17: =(B7*100+(100-B6)/B8)/B6
A18: Nuovo Si (comprato a 100) | B18: =B14
A19: Differenza annua (Si - vecchio) | B19: =B18-B17
A20: Vantaggio stimato dello switch (su 5 anni) | B20: =B19*B13*(B5*B6/100)
A22: Verdetto
A23: Conviene lo switch? | B23: =IF(B18>B17,"SI - valuta lo switch","NO - tieni il vecchio")
A24: Prezzo di indifferenza del vecchio | B24: =(B7*100+100/B8)/(B18+1/B8)
A26: Logica: confronta il rendimento reale annuo che otterresti DA OGGI tenendo il vecchio (penalizzato se quota sopra 100, perche' a scadenza torna a 100) contro il Si comprato a 100. Se il vecchio quota SOPRA il prezzo di indifferenza, lo switch inizia ad avere senso.
A29: Attenzione: vendendo il vecchio perdi il rateo/rivalutazione gia' maturati e il suo premio fedelta'; paghi spread ed esecuzione. Per piccoli importi il vantaggio e' spesso di pochi euro. Stima semplificata (rendimento 'semplice', cedole non reinvestite). NON e' consulenza finanziaria.
A32: Dati grafico break-even (prezzo del vecchio -> rendimento reale)
A33: Prezzo vecchio | B33: Vecchio (rend. reale) | C33: Nuovo Si (rend. reale)
A34: 98 | B34: =(B$7*100+(100-A34)/B$8)/A34 | C34: =B$14
A35: 99 | B35: =(B$7*100+(100-A35)/B$8)/A35 | C35: =B$14
A36: 100 | B36: =(B$7*100+(100-A36)/B$8)/A36 | C36: =B$14
A37: 101 | B37: =(B$7*100+(100-A37)/B$8)/A37 | C37: =B$14
A38: 102 | B38: =(B$7*100+(100-A38)/B$8)/A38 | C38: =B$14
A39: 103 | B39: =(B$7*100+(100-A39)/B$8)/A39 | C39: =B$14
A40: 104 | B40: =(B$7*100+(100-A40)/B$8)/A40 | C40: =B$14
A41: 105 | B41: =(B$7*100+(100-A41)/B$8)/A41 | C41: =B$14
