Workbook

Sheet 0-Indice
A1: Marco FIRE — La strategia a secchi (caso Roberta, 2026)
A2: Strumento informativo / divulgativo. NON è consulenza finanziaria. I valori sono indicativi al 2026 e vanno verificati col tuo consulente.
A4: Indice
A5: 1-Input | B5: I 18 input del caso, stato abitativo compreso
A6: P-Parametri | B6: Parametri normativi e di fonte, referenziati da tutti i fogli
A7: 2-Caso | B7: Scheda-caso: accumulo, latente, ISTAT e affitti figurativi, tre scale
A8: 3-Liquidita | B8: I sei strumenti del secchio 1, la copertura vera, il bollo
A9: 4-Griglia | B9: Griglia madre: costo del secchio per orizzonte, taglia e strumento
A10: 5-Roberta | B10: Il motore del caso: spesa massima sostenibile, costo, autonomia
A11: 6-Banda | B11: Le dodici perturbazioni sul costo di due anni di secchio
A12: 7-Refill | B12: Il refill anno per anno e la quota azionaria (rossa sopra l'80%)
A13: 8-Kitces | B13: L'identita' di Kitces con la convenzione del prelievo come input
A14: 9-ETF-unico | B14: Tre sacche separate contro un ETF multi-asset, coi termini negativi
A15: 10-Benz | B15: La regola di Benz: secchio sulla spesa o sul fabbisogno netto
A16: 11-Verifica | B16: Cruscotto, controlli e lista degli anti-residui
A18: Come usare
A19: 1. Le celle GIALLE sono input — modificale coi tuoi numeri.
A20: 2. Le celle VERDI sono output — si aggiornano automaticamente.
A21: 3. Tutti i numeri di default sono al 2026 da fonti pubbliche.
A22: 4. Niente codice nascosto: l'Excel è solo formule modificabili.
A24: Fonti dati
A25: • Banca d'Italia, «Banche e moneta: serie nazionali», tav. 2.7 (MIR0700), giugno 2026 — depositi con durata prestabilita delle famiglie
A26: • MEF, Dipartimento del Tesoro — «Risultati Asta: BOT 12 MESI» del 09/09/2026, ISIN IT0005730681, durata 365 gg, emissione 14/9/2026, scadenza 14/9/2027 (prezzo medio ponderato e prezzo fiscale 97,080; rendimento medio ponderato 2,967%; rendimento lordo composto 2,966%; base annua 360 gg). Gate di produzione CHIUSO il 9 settembre 2026
A27: • Borsa Italiana — MOT, prezzi del 9/9/2026 dei quattro BTP del paniere di canale: IT0003535157 (5,00% 1/8/2034) 106,58; IT0003256820 (5,75% 1/2/2033) 110,69; IT0001444378 (6,00% 1/5/2031) 110,19; IT0005595803 (3,45% 15/7/2031) 99,16. YTM medio 3,81%. Gate di produzione CHIUSO il 9 settembre 2026
A28: • BCE — €STR del 7 settembre 2026, 2,188%
A29: • ISTAT, «Le spese per i consumi delle famiglie — Anno 2024», comunicato del 7/10/2025
A30: • Bollo: art. 9 commi 3 e 4 della Tariffa, Parte I, Allegato 3 al D.Lgs. 1/8/2025 n. 123 (GU n. 186 del 12/08/2025, S.O. 29/L), in applicazione dal 1° gennaio 2026
... A37: Aggiornamenti: github.com/marcofire-it/marco-fire-simulatori

Sheet 1-Input
A1: Gli input del caso — cambia una cella gialla e tutti i verdi si muovono
A2: Strumento informativo / divulgativo. NON è consulenza finanziaria. I valori sono indicativi al 2026 e vanno verificati col tuo consulente.
A4: INPUT DEL CASO
A5: (1) Anno di nascita di Roberta | B5: 1979
A6: (2) Eta' oggi (2026) | B6: 47
A7: (3) Accumulo — primo anno / ultimo anno | B7: 2011 | C7: 2026
A8: (4) Versamento annuo, euro reali costanti | B8: 6500
A9: (5) Vendita dell'appartamento — netto incassato / anno | B9: 240000 | C9: 2018
A10: (6) Spesa netta annua, DI CASSA | B10: 19800
A11: (7) Orizzonte — eta' finale | B11: 92
A12: (8) Pensione netta annua / dal quale anno del piano | B12: 11102 | C12: 23
A13: (9) Estremo alto della banda della pensione | B13: 12935
A14: (10) Rendimento reale del portafoglio — menu 2% / 3% / 4% | B14: 0.03
A15: (11) Anni di spesa nel secchio 1 (N) | B15: 2
A16: (12) Regola di dimensionamento: 1 = N x spesa · 0 = N x fabbisogno netto (Benz) | B16: 1
A17: (13) STATO ABITATIVO: 1 = casa senza costi · 0 = in affitto o con mutuo | B17: 1
A18: (14) Peso dell'affitto figurativo usato nel confronto ISTAT (0 = calcolato dal foglio 2) | B18: 0
A19: (15) Netto annuo da lavoro durante l'accumulo / lordo di carriera | B19: 22215.65 | C19: 28000
A20: (16) Identita' di Kitces — convenzione del prelievo: 1 = fine anno · 0 = inizio anno | B20: 1
A21: (17) Sovraccosto di TER dell'ETF multi-asset (punti percentuali) | B21: 0.001
A22: (18) Strumento del secchio 1: 1 = conto deposito · 2 = ETF monetario · 3 = BOT 12 mesi | B22: 1
A24: DERIVATI — non si toccano
A26: Orizzonte in anni | B26: ='1-Input'!$B$11-'1-Input'!$B$6 -> 45
A27: Rendimento reale della liquidita' scelta (al LORDO del bollo) | B27: =ROUND(IF('1-Input'!$B$22=3,'3-Liquidita'!$F$7,IF('1-Input'!$B$22=2,'3-Liquidita'!$F$11,'3-Liquidita'!$F$9)),4) -> -0.0036
A28: Anni di accumulo | B28: ='1-Input'!$C$7-'1-Input'!$B$7+1 -> 16
A29: Anni di capitalizzazione del netto della vendita | B29: ='1-Input'!$C$7-'1-Input'!$C$9 -> 8
A30: Anno di decorrenza della pensione (68 anni e 10 mesi — proiezione RGS) | B30: ='1-Input'!$B$5+'1-Input'!$B$6+'1-Input'!$C$12-1 -> 2048
A32: CONVENZIONE DICHIARATA — il prelievo e' a INIZIO anno, il secchio 1 si ricarica dal portafoglio PRIMA della crescita dell'anno, il bollo si paga a FINE anno sul patrimonio dopo la crescita e grava prima sul portafoglio e poi sul secchio. La base di costo si scorpora INSIEME al patrimonio quando si crea il secchio 1 (quinto errore di famiglia): base del portafoglio = base totale x portafoglio / patrimonio.
A33: UNA SOLA REGOLA DI REFILL in tutto il file: ogni anno il secchio 1 viene riportato al suo target vendendo dal portafoglio, per quanto il portafoglio consente. La regola riempie e non svuota mai: quando il target scende (perche' arriva la pensione), l'eccedenza resta nel secchio. Il foglio 10 misura quanto vale quella scelta.
A34: REFRESH GENNAIO 2027 — i tassi del foglio P sono una fotografia di settembre 2026. GATE CHIUSO IL 9 SETTEMBRE 2026: l'asta BOT 12 mesi del 09/09/2026 (ISIN IT0005730681, prezzo fiscale 97,080, rendimento medio ponderato 2,967%) e' stata pubblicata e sostituisce in P-Parametri quella del 12/08/2026. Il prossimo riallineamento e' il refresh di gennaio 2027.
A35: FISCALITA' — 26% sul capital gain, 12,5% sui titoli di Stato, 0,20% di bollo sono le aliquote in vigore nel 2026: una FOTOGRAFIA, non una regola eterna. Il D.Lgs. 117/2026 ricodifica il TUIR con effetti dal 1° gennaio 2027 (art. 377); e' una ricodificazione, non una soppressione, ma i rinvii per numero d'articolo cambiano.

Sheet P-Parametri
A1: Parametri normativi e di fonte
A2: Strumento informativo / divulgativo. NON è consulenza finanziaria. I valori sono indicativi al 2026 e vanno verificati col tuo consulente.
A3: Le uniche costanti del modello, oltre agli input, stanno qui. Tutti gli altri fogli le referenziano.
A5: Fiscalita' finanziaria 2026 — fotografia, non regime stabile
A6: Capital gain (redditi di capitale e diversi da ETF e azioni) | B6: 0.26
A7: Titoli di Stato ed equiparati | B7: 0.125
A8: Bollo su prodotti finanziari e depositi (art. 9 c. 4) | B8: 0.002
A9: Bollo fisso su conto corrente e libretto / soglia di esenzione (art. 9 c. 3) | B9: 34.2 | C9: 5000
A10: Inflazione attesa (canone del canale) | B10: 0.02
A12: Tassi della liquidita' — settembre 2026
A13: €STR (BCE, 7/9/2026) / TER dell'ETF monetario | B13: 0.02188 | C13: 0.001
A14: Conto deposito famiglie: fino a 1 anno / oltre 1 anno (Banca d'Italia tav. 2.7) | B14: 0.0222 | C14: 0.0269
A15: BOT 12 mesi — prezzo fiscale d'asta / rendimento medio ponderato / giorni | B15: 97.08 | C15: 0.02967 | D15: 365 | E15: MEF, «Risultati Asta: BOT 12 MESI» del 09/09/2026 — ISIN IT0005730681, durata 365 gg, emissione 14/9/2026, scadenza 14/9/2027, prezzo medio ponderato e prezzo fiscale 97,080, rendimento medio ponderato 2,967% (semplice lordo, base annua 360 gg), rendimento lordo composto 2,966%, copertura 1,39. Gate di produzione CHIUSO il 9 settembre 2026: sostituisce l'asta del 12/08/2026 (IT0005729220, 97,277 / 2,768%).
A16: Buono fruttifero postale — rendimento nei primi quattro anni | B16: 0.0075
A17: BTP a medio termine — rendimento a scadenza lordo (paniere MOT 9/9/2026) | B17: 0.0381 | E17: Media dei quattro BTP del paniere di canale, prezzi Borsa Italiana-MOT del 9/9/2026: IT0003535157 5,00% 1/8/2034 a 106,58 (YTM 4,056%); IT0003256820 5,75% 1/2/2033 a 110,69 (3,879%); IT0001444378 6,00% 1/5/2031 a 110,19 (3,629%); IT0005595803 3,45% 15/7/2031 a 99,16 (3,672%). Media 3,8088%, arrotondata a 3,81%. YTM ricalcolati con date di scadenza esatte, regolamento 9/9/2026, rateo ACT/ACT incluso e capitalizzazione annuale su base 365 (regola di canale). Gate di produzione CHIUSO il 9 settembre 2026: sostituisce il paniere del 14/8/2026 (media 3,49%).
A18: Conto corrente — rendimento reale netto dichiarato (bollo fisso su giacenza media) | B18: -0.0204
A20: ISTAT — spese per consumi delle famiglie, anno 2024 (7/10/2025)
A21: Spesa media mensile, totale Italia | B21: 2755.09
A22: Divisione «Abitazione, acqua, elettricita', gas» | B22: 984.42
A23: di cui affitti figurativi | B23: 617.39
A24: Quota della divisione abitazione per le famiglie monocomponente | B24: 0.439
A25: Persona sola fra 35 e 64 anni — spesa media mensile | B25: 2096.96
A26: Ipotesi alternativa: rapporto affitti figurativi / divisione per i single | B26: 0.55
A28: Mercati — ipotesi dichiarate degli scenari illustrativi
A29: Azionario negli anni normali / obbligazionario (reale) | B29: 0.068512 | C29: 0.005
A30: I due crolli — primo / secondo | B30: -0.35 | C30: -0.2
A31: Allocazione di Kitces — azioni / obbligazioni / liquidita' | B31: 0.6 | C31: 0.3 | D31: 0.1
A33: Pfeiffer-Salter-Evensky — le commissioni evitate
A34: Commissioni col secchio / senza secchio / orizzonte (dollari, 30 anni) | B34: 2580 | C34: 21600 | D34: 30
A35: Costo unitario dell'eseguito nello studio (dollari) | B35: 30
A36: Eseguiti evitati all'anno = (senza - col secchio) / anni / costo unitario | B36: =(C34-B34)/D34/B35 -> 21.133333
A38: Estrada 2019 — 21 paesi, 115 anni, 86 finestre trentennali
A39: Portafoglio 100% azionario — tasso di fallimento medio | B39: 0.278
A40: Regole a secchi BR-1 / BR-2 / BR-3 | B40: 0.316 | C40: 0.316 | D40: 0.301
A41: Titoli a breve italiani dal 1900 — reale geometrico / minimo annuo | B41: -0.035 | C41: -0.766
A43: Sweep delle 1.980 permutazioni — RISULTATI DICHIARATI, non ricalcolati qui
A44: Permutazioni dei due crolli (45 x 44 coppie ordinate) | B44: 1980
A45: Braccio A, total return — fallimenti / patrimonio medio | B45: 0.117 | C45: 249674
A46: Braccio B, secchio dentro — 1 anno / 5 anni | B46: 0.137 | C46: 0.191
A47: Braccio D, secchio aggiunto — 1 anno / 5 anni / patrimonio medio a 5 anni | B47: 0.197 | C47: 0.721 | D47: 24923
...

Sheet 2-Caso
A1: La scheda-caso: da dove vengono i quattrocentotrentanovemila
A2: Strumento informativo / divulgativo. NON è consulenza finanziaria. I valori sono indicativi al 2026 e vanno verificati col tuo consulente.
A4: ACCUMULO E ORIGINE DEL CAPITALE — la latente e' DERIVATA, non postulata
A5: Versamento annuo, euro reali costanti | B5: ='1-Input'!$B$8 -> 6500
A6: Anni di accumulo (2011-2026) | B6: ='1-Input'!$B$28 -> 16
A7: Montante dei versamenti — rendita anticipata al rendimento reale | B7: =B5*(((1+'1-Input'!$B$14)^B6-1)/'1-Input'!$B$14)*(1+'1-Input'!$B$14) -> 134950.32
A8: Base di costo dei versamenti | B8: =B5*B6 -> 104000
A9: Vendita dell'appartamento nel 2018 — netto di mutuo residuo, imposte e spese | B9: ='1-Input'!$B$9 -> 240000
A10: Capitalizzato al rendimento reale fino a oggi | B10: =B9*(1+'1-Input'!$B$14)^'1-Input'!$B$29 -> 304024.82
A11: Base di costo del capitale immobiliare reinvestito | B11: =B9 -> 240000
A12: PATRIMONIO INVESTITO AL 2026 | B12: =B7+B10 -> 438975.14
A13: BASE DI COSTO FISCALE | B13: =B8+B11 -> 344000
A14: PLUSVALENZA LATENTE | B14: =MAX(0,(B12-B13)/B12) -> 0.21635653
A15: Fattore di lordizzazione G = 1 / (1 - capital gain x latente) | B15: =1/(1-'P-Parametri'!$B$6*B14) -> 1.0596057
A16: Aliquota effettiva sulla vendita (capital gain x latente) | B16: ='P-Parametri'!$B$6*B14 -> 0.056252699
A17: Tasso di risparmio implicito sul netto da lavoro | B17: =B5/'1-Input'!$B$19 -> 0.29258653
A18: Di che cosa viveva mentre risparmiava (netto meno versamento) | B18: ='1-Input'!$B$19-B5 -> 15715.65
A19: Salto fra il tenore di vita in accumulo e quello in decumulo | B19: ='1-Input'!$B$10-B18 -> 4084.35
A21: IL VINCOLO ARITMETICO. Tre parametri — quando comincia l'accumulo, quanto Roberta versa e a quanto ha venduto — sono scelti insieme per far tornare un numero solo, il patrimonio di oggi. E' una CALIBRAZIONE dichiarata, non una previsione. Quello che il conto deve dimostrare non e' che i numeri tornano, ma che il tasso di risparmio che ne esce e' possibile. Gli ingressi sono tondi e dichiarati (16 anni, 6.500 euro, 240.000 euro, 8 anni), le uscite sono frastagliate: non c'e' nessun sistema da risolvere.
A22: LA BIOGRAFIA CHE RENDE POSSIBILE IL CONTO. Appartamento comprato nel 2004 con un mutuo, estinto alla vendita del 2018; dal 2011 Roberta vive nella casa di famiglia e il vecchio appartamento e' affittato. Dal 2011 al 2018 il canone incassato e la rata ancora pagata sono trattati come PARTITA DI GIRO: si compensano, e il conto qui sopra non li porta. I 240.000 euro sono NETTI di mutuo residuo, imposte e spese. La plusvalenza immobiliare non e' tassata: l'immobile e' posseduto da piu' di cinque anni.
A24: STATO ABITATIVO E DENOMINATORE ISTAT — il quarto errore di famiglia
A25: Stato abitativo dichiarato | B25: =IF('1-Input'!$B$17=1,"casa senza costi abitativi","in affitto o con mutuo") -> casa senza costi abitativi
A26: Persona sola 35-64 anni — spesa media mensile ISTAT 2024 (affitto figurativo INCLUSO) | B26: ='P-Parametri'!$B$25 -> 2096.96
A27: Affitti figurativi in quota della spesa totale (media nazionale) | B27: ='P-Parametri'!$B$23/'P-Parametri'!$B$21 -> 0.22409068
A28: Affitti figurativi in quota della divisione abitazione | B28: ='P-Parametri'!$B$23/'P-Parametri'!$B$22 -> 0.62716117
A30: Ipotesi sul peso dell'affitto figurativo | B30: Peso | C30: Spesa di CASSA equivalente (mese)
A31: Quota nazionale su tutte le famiglie (limite alto della cassa) | B31: ='P-Parametri'!$B$23/'P-Parametri'!$B$21 -> 0.22409068 | C31: =B26*(1-B31) -> 1627.0508
A32: Quota CALCOLATA per la monocomponente (43,9% per 62,72%) | B32: ='P-Parametri'!$B$24*B28 -> 0.27532375 | C32: =B26*(1-B32) -> 1519.6171
A33: Se per i single il rapporto scendesse al 55% della divisione | B33: ='P-Parametri'!$B$24*'P-Parametri'!$B$26 -> 0.24145 | C33: =B26*(1-B33) -> 1590.649
A35: FORBICE DELLA SPESA DI CASSA — minimo / massimo (euro/mese) | B35: =MIN(C31:C33) -> 1519.6171 | C35: =MAX(C31:C33) -> 1627.0508
A36: Peso effettivamente usato nel confronto (0 nell'input = quello calcolato) | B36: =IF('1-Input'!$B$18=0,B32,'1-Input'!$B$18) -> 0.27532375
A37: DENOMINATORE OMOGENEO alla spesa di Roberta | B37: =IF('1-Input'!$B$17=1,B26*(1-B36),B26) -> 1519.6171
A38: Spesa di cassa di Roberta (euro/mese) | B38: ='1-Input'!$B$10/12 -> 1650
A39: Scarto contro il denominatore omogeneo | B39: =B38-B37 -> 130.3829 | C39: =B38/B37-1 -> 0.085799837
A40: VERDETTO | B40: =IF('1-Input'!$B$17<>1,IF(B38>B37,"SOPRA la media ISTAT piena","SOTTO la media ISTAT piena"),IF(B38>MAX(C31:C33),"SOPRA la forbice della media di cassa",IF(B38<MIN(C31:C33),"SOTTO la forbice della media di cassa","DENTRO la forbice della media di cassa"))) -> SOPRA la forbice della media di cassa
A42: PERCHE' LO STATO ABITATIVO E' UN INPUT E NON UN DETTAGLIO. L'aggregato ISTAT «spesa media mensile per consumi» include gli AFFITTI FIGURATIVI, che non sono un esborso di cassa: nel 2024 valgono 617,39 euro su 2.755,09, cioe' il 22,41% della spesa e il 62,72% della divisione abitazione. Confrontare quella media con un prelievo, con una pensione o con un fabbisogno e' omogeneo SOLO se si dichiara lo stato abitativo. Metti 0 nell'input (13) e il confronto passa sul dato pieno: e' quello giusto per chi un affitto lo paga davvero.
A43: Con lo stato abitativo dichiarato, Roberta a 1.650 euro al mese sta SOPRA la media di cassa di chi vive nella sua stessa condizione, non sotto. E' il numero scomodo, e si pubblica: il 29,3% di risparmio non viene dalla frugalita', viene dal fatto che dal 2011 non paga la casa.
A45: LE TRE SCALE DEL TASSO DI PRELIEVO — anno 1, senza secchio
A46: Scala | B46: Importo | C46: Sul patrimonio
A47: Cassa — quello che Roberta spende | B47: ='1-Input'!$B$10 -> 19800 | C47: =B47/B12 -> 0.04510506
...

Sheet 3-Liquidita
A1: La liquidita' italiana: quanto rende davvero e quanto copre davvero
A2: Strumento informativo / divulgativo. NON è consulenza finanziaria. I valori sono indicativi al 2026 e vanno verificati col tuo consulente.
A4: I SEI STRUMENTI DEL SECCHIO 1 — netti d'imposta, di bollo e di inflazione
A6: Strumento | B6: Lordo | C6: Aliquota | D6: Netto d'imposta | E6: Bollo | F6: Reale al LORDO del bollo | G6: Reale netto di tutto | H6: Differenziale contro il portafoglio
A7: BOT 12 mesi (asta MEF 09/09/2026, ISIN IT0005730681) | B7: ='P-Parametri'!$C$15 -> 0.02967 | C7: ='P-Parametri'!$B$7 -> 0.125 | D7: =((100-'P-Parametri'!$B$7*(100-'P-Parametri'!$B$15))/'P-Parametri'!$B$15-1)*365/'P-Parametri'!$D$15 -> 0.0263185 | E7: ='P-Parametri'!$B$8 -> 0.002 | F7: =D7-'P-Parametri'!$B$10 -> 0.0063185002 | G7: =D7-E7-'P-Parametri'!$B$10 -> 0.0043185002 | H7: ='1-Input'!$B$14-F7 -> 0.0236815
A8: Conto deposito famiglie, oltre 1 anno | B8: ='P-Parametri'!$C$14 -> 0.0269 | C8: ='P-Parametri'!$B$6 -> 0.26 | D8: =B8*(1-C8) -> 0.019906 | E8: ='P-Parametri'!$B$8 -> 0.002 | F8: =D8-'P-Parametri'!$B$10 -> -9.4e-05 | G8: =D8-E8-'P-Parametri'!$B$10 -> -0.002094 | H8: ='1-Input'!$B$14-F8 -> 0.030094
A9: Conto deposito famiglie, fino a 1 anno | B9: ='P-Parametri'!$B$14 -> 0.0222 | C9: ='P-Parametri'!$B$6 -> 0.26 | D9: =B9*(1-C9) -> 0.016428 | E9: ='P-Parametri'!$B$8 -> 0.002 | F9: =D9-'P-Parametri'!$B$10 -> -0.003572 | G9: =D9-E9-'P-Parametri'!$B$10 -> -0.005572 | H9: ='1-Input'!$B$14-F9 -> 0.033572
A10: Buono fruttifero postale, primi quattro anni | B10: ='P-Parametri'!$B$16 -> 0.0075 | C10: ='P-Parametri'!$B$7 -> 0.125 | D10: =B10*(1-C10) -> 0.0065625 | E10: ='P-Parametri'!$B$8 -> 0.002 | F10: =D10-'P-Parametri'!$B$10 -> -0.0134375 | G10: =D10-E10-'P-Parametri'!$B$10 -> -0.0154375 | H10: ='1-Input'!$B$14-F10 -> 0.0434375
A11: ETF monetario (€STR meno TER) | B11: ='P-Parametri'!$B$13-'P-Parametri'!$C$13 -> 0.02088 | C11: ='P-Parametri'!$B$6 -> 0.26 | D11: =B11*(1-C11) -> 0.0154512 | E11: ='P-Parametri'!$B$8 -> 0.002 | F11: =D11-'P-Parametri'!$B$10 -> -0.0045488 | G11: =D11-E11-'P-Parametri'!$B$10 -> -0.0065488 | H11: ='1-Input'!$B$14-F11 -> 0.0345488
A12: Conto corrente (bollo fisso: valore reale dichiarato) | B12: =0 -> 0 | C12: ='P-Parametri'!$B$6 -> 0.26 | D12: =B12*(1-C12) -> 0 | E12: ='P-Parametri'!$B$9 -> 34.2 | F12: =-'P-Parametri'!$B$10 -> -0.02 | G12: ='P-Parametri'!$B$18 -> -0.0204 | H12: ='1-Input'!$B$14-F12 -> 0.05
A13: BTP a medio termine (paniere MOT 9/9/2026, media di quattro titoli) | B13: ='P-Parametri'!$B$17 -> 0.0381 | C13: ='P-Parametri'!$B$7 -> 0.125 | D13: =B13*(1-C13) -> 0.0333375 | E13: ='P-Parametri'!$B$8 -> 0.002 | F13: =D13-'P-Parametri'!$B$10 -> 0.0133375 | G13: =D13-E13-'P-Parametri'!$B$10 -> 0.0113375 | H13: ='1-Input'!$B$14-F13 -> 0.0166625
A15: IL BOLLO SI ELIDE. Nel differenziale (colonna H) i rendimenti sono al LORDO del bollo su ENTRAMBE le gambe, perche' lo 0,20% colpisce identico il portafoglio e la liquidita'. Nel motore del caso il bollo e' addebitato a parte, ogni anno, su tutto il patrimonio: usare li' il rendimento gia' netto di bollo sarebbe un DOPPIO CONTEGGIO (primo errore di famiglia) e gonfierebbe il costo del secchio di circa un decimo.
A16: Il netto del BOT non e' il rendimento moltiplicato per 0,875: e' la ritenuta del 12,5% sullo scarto d'emissione, cioe' su 100 meno il prezzo d'asta, riportata al prezzo pagato e annualizzata sui giorni effettivi. E' per questo che la colonna D e' una formula sul prezzo e non sul rendimento. FONTE AGGIORNATA: asta MEF del 09/09/2026, ISIN IT0005730681, prezzo fiscale 97,080 su 365 giorni, rendimento medio ponderato 2,967% (base annua 360 gg). Gate di produzione CHIUSO il 9 settembre 2026.
A18: LA COPERTURA VERA — otto anni di spesa, e dove li tieni conta
A19: Anni di spesa messi da parte (sulla carta) | B19: 8
A20: Montante corrispondente | B20: =B19*'1-Input'!$B$10 -> 158400
A21: Dove stanno gli otto anni | B21: Rendimento reale netto di tutto | C21: Anni di spesa effettivamente coperti
A22: Conto corrente | B22: =G12 -> -0.0204 | C22: =IF(ABS(B22)<0.0000001,$B$19,-LN(1-$B$19*B22/(1+B22))/LN(1+B22)) -> 7.4762355
A23: ETF monetario | B23: =G11 -> -0.0065488 | C23: =IF(ABS(B23)<0.0000001,$B$19,-LN(1-$B$19*B23/(1+B23))/LN(1+B23)) -> 7.8218597
A24: Conto deposito fino a 1 anno | B24: =G9 -> -0.005572 | C24: =IF(ABS(B24)<0.0000001,$B$19,-LN(1-$B$19*B24/(1+B24))/LN(1+B24)) -> 7.8477859
A25: BOT 12 mesi | B25: =G7 -> 0.0043185002 | C25: =IF(ABS(B25)<0.0000001,$B$19,-LN(1-$B$19*B25/(1+B25))/LN(1+B25)) -> 8.1233219
A26: BTP a medio termine | B26: =G13 -> 0.0113375 | C26: =IF(ABS(B26)<0.0000001,$B$19,-LN(1-$B$19*B26/(1+B26))/LN(1+B26)) -> 8.334666
A27: FORBICE — peggiore / migliore / differenza in anni | B27: =MIN(C22:C26) -> 7.4762355 | C27: =MAX(C22:C26) -> 8.334666 | D27: =C27-B27 -> 0.85843053
A28: FORBICE IN EURO — anni pieni per la spesa annua | B28: =D27*'1-Input'!$B$10 -> 16996.925
A29: FORBICE IN EURO — con gli anni arrotondati al centesimo, come vanno a schermo | B29: =(ROUND(C27,2)-ROUND(B27,2))*'1-Input'!$B$10 -> 16830
A30: Il numero della forbice in euro dipende da quanto si arrotondano gli anni PRIMA di moltiplicare: con gli anni pieni e' la riga 28, con gli anni arrotondati al centesimo (7,48 e 8,33 dopo la rilevazione MOT del 9/9/2026) e' la riga 29. La riga 28 e' il motore; la riga 29 e' il numero che si ottiene dai due valori pubblicati. Le due letture differiscono di alcune centinaia di euro e la differenza va dichiarata, non nascosta.
A32: IL BOLLO SULLA NORMA
A33: Conto corrente e libretto — imposta fissa / esenzione sotto la giacenza media | B33: ='P-Parametri'!$B$9 -> 34.2 | C33: ='P-Parametri'!$C$9 -> 5000
A34: Conto deposito e dossier titoli — aliquota annua | B34: ='P-Parametri'!$B$8 -> 0.002
A35: PAREGGIO fra il fisso e la percentuale | B35: ='P-Parametri'!$B$9/'P-Parametri'!$B$8 -> 17100
A36: Bollo annuo sul secchio 1 di Roberta | B36: ='P-Parametri'!$B$8*'1-Input'!$B$15*'1-Input'!$B$10 -> 79.2
A38: L'ATTRITO CHE NESSUNO CONTA — il 26% sugli interessi, ogni anno
A39: Interessi lordi annui del secchio 1 (conto deposito fino a 1 anno) | B39: ='1-Input'!$B$15*'1-Input'!$B$10*'P-Parametri'!$B$14 -> 879.12
A40: Imposta annua sugli interessi | B40: =B39*'P-Parametri'!$B$6 -> 228.5712
A41: Capitalizzata sull'orizzonte al rendimento reale (rendita anticipata) | B41: =B40*(((1+'1-Input'!$B$14)^'1-Input'!$B$26-1)/'1-Input'!$B$14)*(1+'1-Input'!$B$14) -> 21828.883
A43: LA SOGLIA DI EVENSKY — quanto dovrebbe costare un eseguito
A44: Commissioni nello studio: col secchio / senza / orizzonte (dollari) | B44: ='P-Parametri'!$B$34 -> 2580 | C44: ='P-Parametri'!$C$34 -> 21600 | D44: ='P-Parametri'!$D$34 -> 30
A45: Eseguiti evitati all'anno | B45: ='P-Parametri'!$B$36 -> 21.133333
A46: Costo annuo del secchio, PER ANNO di spesa messo in liquidita' | B46: =1*'1-Input'!$B$10*H9 -> 664.7256
A47: COMMISSIONE DI PAREGGIO PER ESEGUITO | B47: =B46/B45 -> 31.453893
...

Sheet 4-Griglia
A1: La griglia madre: quanto costa il secchio, per orizzonte, taglia e strumento
A2: Strumento informativo / divulgativo. NON è consulenza finanziaria. I valori sono indicativi al 2026 e vanno verificati col tuo consulente.
A3: PARAMETRI IN TESTA: patrimonio di un milione, euro reali, portafoglio al rendimento reale dell'input (10), secchio 1 = N per la spesa annua, prelievo a inizio anno dal secchio, refill annuale dal portafoglio finche' il portafoglio lo consente. NESSUNA IMPOSTA E NESSUN BOLLO in questa griglia: e' fatta per essere ricostruibile da chi guarda con cinque colonne di foglio di calcolo. Il costo VERO del secchio e' piu' alto, perche' l'imposta sugli interessi si paga ogni anno mentre quella sulla plusvalenza si paga alla vendita: il conto completo e' nel foglio 5.
A5: Patrimonio della griglia | B5: 1000000
A6: Rendimento reale del portafoglio | B6: ='1-Input'!$B$14 -> 0.03
A7: Liquidita' — conto deposito fino a 1 anno / BOT 12 mesi (reale, lordo bollo) | B7: =ROUND('3-Liquidita'!$F$9,4) -> -0.0036 | C7: =ROUND('3-Liquidita'!$F$7,4) -> 0.0063
A9: IL COSTO IN PUNTI DI TASSO DI PRELIEVO
A10: Orizzonte e strumento | B10: N = 1 | C10: N = 2 | D10: N = 3 | E10: N = 5
A11: 20 anni — conto deposito | B11: =($B$165-$B$212)/$B$5*100 -> 0.19871671 | C11: =($B$165-$B$259)/$B$5*100 -> 0.37848237 | D11: =($B$165-$B$306)/$B$5*100 -> 0.5413069 | E11: =($B$165-$B$353)/$B$5*100 -> 0.8226666
A12: 20 anni — BOT 12 mesi | B12: =($B$400-$B$447)/$B$5*100 -> 0.14140074 | C12: =($B$400-$B$494)/$B$5*100 -> 0.27145238 | D12: =($B$400-$B$541)/$B$5*100 -> 0.390973 | E12: =($B$400-$B$588)/$B$5*100 -> 0.60116229
A13: 30 anni — conto deposito | B13: =($B$635-$B$682)/$B$5*100 -> 0.15329235 | C13: =($B$635-$B$729)/$B$5*100 -> 0.29429983 | D13: =($B$635-$B$776)/$B$5*100 -> 0.42427087 | E13: =($B$635-$B$823)/$B$5*100 -> 0.65526362
A14: 30 anni — BOT 12 mesi | B14: =($B$870-$B$917)/$B$5*100 -> 0.10910609 | C14: =($B$870-$B$964)/$B$5*100 -> 0.21121928 | D14: =($B$870-$B$1011)/$B$5*100 -> 0.30683681 | E14: =($B$870-$B$1058)/$B$5*100 -> 0.480306
A15: 40 anni — conto deposito | B15: =($B$1105-$B$1152)/$B$5*100 -> 0.13098386 | C15: =($B$1105-$B$1199)/$B$5*100 -> 0.2523985 | D15: =($B$1105-$B$1246)/$B$5*100 -> 0.36518301 | E15: =($B$1105-$B$1293)/$B$5*100 -> 0.56802685
A16: 40 anni — BOT 12 mesi | B16: =($B$1340-$B$1387)/$B$5*100 -> 0.093239294 | C16: =($B$1340-$B$1434)/$B$5*100 -> 0.18120477 | D16: =($B$1340-$B$1481)/$B$5*100 -> 0.26426375 | E16: =($B$1340-$B$1528)/$B$5*100 -> 0.41695144
A18: LO STESSO COSTO IN PERCENTUALE DELLA SPESA — la lettura che si applica a se'
A19: Orizzonte e strumento | B19: N = 1 | C19: N = 2 | D19: N = 3 | E19: N = 5
A20: 20 anni — conto deposito | B20: =($B$165-$B$212)/$B$165 -> 0.030450949 | C20: =($B$165-$B$259)/$B$165 -> 0.057997879 | D20: =($B$165-$B$306)/$B$165 -> 0.082948782 | E20: =($B$165-$B$353)/$B$165 -> 0.12606378
A21: 20 anni — BOT 12 mesi | B21: =($B$400-$B$447)/$B$400 -> 0.021667965 | C21: =($B$400-$B$494)/$B$400 -> 0.041596817 | D21: =($B$400-$B$541)/$B$400 -> 0.059911917 | E21: =($B$400-$B$588)/$B$400 -> 0.092120901
A22: 30 anni — conto deposito | B22: =($B$635-$B$682)/$B$635 -> 0.030947357 | C22: =($B$635-$B$729)/$B$635 -> 0.059414588 | D22: =($B$635-$B$776)/$B$635 -> 0.085653731 | E22: =($B$635-$B$823)/$B$635 -> 0.1322876
A23: 30 anni — BOT 12 mesi | B23: =($B$870-$B$917)/$B$870 -> 0.022026834 | C23: =($B$870-$B$964)/$B$870 -> 0.042641908 | D23: =($B$870-$B$1011)/$B$870 -> 0.06194561 | E23: =($B$870-$B$1058)/$B$870 -> 0.096966358
A24: 40 anni — conto deposito | B24: =($B$1105-$B$1152)/$B$1105 -> 0.03118492 | C24: =($B$1105-$B$1199)/$B$1105 -> 0.060091578 | D24: =($B$1105-$B$1246)/$B$1105 -> 0.086943556 | E24: =($B$1105-$B$1293)/$B$1105 -> 0.13523705
A25: 40 anni — BOT 12 mesi | B25: =($B$1340-$B$1387)/$B$1340 -> 0.022198612 | C25: =($B$1340-$B$1434)/$B$1340 -> 0.043141622 | D25: =($B$1340-$B$1481)/$B$1340 -> 0.062916483 | E25: =($B$1340-$B$1528)/$B$1340 -> 0.099268697
A26: IL QUARTO DI COSTO CHE DIPENDE SOLO DALLO STRUMENTO (30 anni, N = 2) | B26: =($B$635-$B$729)/$B$635 -> 0.059414588 | C26: =($B$870-$B$964)/$B$870 -> 0.042641908 | D26: =1-C26/B26 -> 0.28229902
A28: IL COSTO NON E' ADDITIVO — costo marginale del singolo anno (30 anni, conto deposito)
A29: Anno di liquidita' aggiunto | B29: 1° | C29: 2° | D29: 3° | E29: 4° | F29: 5°
A30: Costo cumulato in % della spesa | B30: =($B$635-$B$682)/$B$635 -> 0.030947357 | C30: =($B$635-$B$729)/$B$635 -> 0.059414588 | D30: =($B$635-$B$776)/$B$635 -> 0.085653731 | E30: =($B$635-$B$2945)/$B$635 -> 0.10988203 | F30: =($B$635-$B$823)/$B$635 -> 0.1322876
A31: Costo marginale in % della spesa | B31: =B30 -> 0.030947357 | C31: =C30-B30 -> 0.028467231 | D31: =D30-C30 -> 0.026239143 | E31: =E30-D30 -> 0.024228296 | F31: =F30-E30 -> 0.022405571
A32: Cinque anni non costano cinque volte il primo: il costo marginale decresce, perche' ogni anno aggiunto di liquidita' sostituisce una parte di portafoglio che avrebbe avuto meno tempo per lavorare.
A34: LO STESSO COSTO IN EURO CUMULATI — gap di patrimonio a spesa uguale
A35: Orizzonte | B35: N = 1 | C35: N = 2 | D35: N = 3 | E35: N = 5
A36: 30 anni | B36: =$B$1578 -> 74999.76 | C36: =$B$1624 -> 143539.79 | D36: =$B$1670 -> 205995.38 | E36: =$B$1716 -> 314079.38
A37: 40 anni | B37: =$B$1762 -> 101591.26 | C37: =$B$1808 -> 195249.37 | D37: =$B$1854 -> 281434.35 | E37: =$B$1900 -> 432952.21
A38: Il gap e' misurato a SPESA UGUALE: si tiene la spesa che il portafoglio senza secchio sostiene per l'intero orizzonte e si guarda quanto manca all'arrivo con il secchio. E' la stessa cosa del costo in punti, letta in euro invece che in tasso.
A40: GLI ANNI DI AUTONOMIA — a spesa fissa, quanto dura il capitale
A41: Orizzonte | B41: N = 0 | C41: N = 1 | D41: N = 2 | E41: N = 3 | F41: N = 5
A42: 20 anni | B42: =$B$1970 -> 20 | C42: =$B$2036 -> 19 | D42: =$B$2102 -> 18 | E42: =$B$2168 -> 17 | F42: =$B$2234 -> 16
A43: 30 anni | B43: =$B$2300 -> 30 | C43: =$B$2366 -> 28 | D43: =$B$2432 -> 27 | E43: =$B$2498 -> 26 | F43: =$B$2564 -> 24
A44: 40 anni | B44: =$B$2630 -> 40 | C44: =$B$2696 -> 37 | D44: =$B$2762 -> 35 | E44: =$B$2828 -> 33 | F44: =$B$2894 -> 31
A120: GRIGLIA — orizzonte 20 anni · conto deposito · N = 0
B121: =0.03*$B$5 -> 30000 | E121: =0.075*$B$5 -> 75000 | H121: =IFERROR(E121-E164*(E121-B121)/(E164-B164),E121) -> 65257.969 | K121: =IFERROR(H121-H164*(H121-E121)/(H164-E164),H121) -> 65257.969 | N121: =IFERROR(K121-K164*(K121-H121)/(K164-H164),K121) -> 65257.969 | Q121: =IFERROR(N121-N164*(N121-K121)/(N164-K164),N121) -> 65257.969
...

Sheet 5-Roberta
A1: Il motore del caso: quanto puo' spendere Roberta, e quanto le costa il secchio
A2: Strumento informativo / divulgativo. NON è consulenza finanziaria. I valori sono indicativi al 2026 e vanno verificati col tuo consulente.
A4: Rendimento reale — basso / centrale / alto | B4: ='1-Input'!$B$14-0.01 -> 0.02 | C4: ='1-Input'!$B$14 -> 0.03 | D4: ='1-Input'!$B$14+0.01 -> 0.04
A6: SPESA MASSIMA SOSTENIBILE SU TUTTO L'ORIZZONTE
A7: Rendimento reale | B7: N = 0 | C7: N = 1 | D7: N = 2 | E7: N = 3 | F7: N = 5
A8: =$B$4 -> 0.02 | B8: ='5-Roberta'!$B$173 -> 17222.185 | C8: ='5-Roberta'!$B$228 -> 16926.34 | D8: ='5-Roberta'!$B$283 -> 16656.5 | E8: ='5-Roberta'!$B$338 -> 16412.124 | F8: ='5-Roberta'!$B$393 -> 16001.832
A9: =$C$4 -> 0.03 | B9: ='5-Roberta'!$B$448 -> 18844.494 | C9: ='5-Roberta'!$B$503 -> 18374.499 | D9: ='5-Roberta'!$B$558 -> 17944.672 | E9: ='5-Roberta'!$B$613 -> 17554.719 | F9: ='5-Roberta'!$B$668 -> 16889.427
A10: =$D$4 -> 0.04 | B10: ='5-Roberta'!$B$723 -> 20684.87 | C10: ='5-Roberta'!$B$778 -> 20010.465 | D10: ='5-Roberta'!$B$833 -> 19396.385 | E10: ='5-Roberta'!$B$888 -> 18838.514 | F10: ='5-Roberta'!$B$943 -> 17883.64
A12: IL COSTO DEL SECCHIO — al rendimento centrale
A13: Anni di spesa in liquidita' | B13: Spesa massima | C13: Costo | D13: In % del tenore di vita
A14: nessun secchio | B14: ='5-Roberta'!$B$448 -> 18844.494 | C14: =0 -> 0 | D14: =0 -> 0
A15: 1 anni | B15: ='5-Roberta'!$B$503 -> 18374.499 | C15: ='5-Roberta'!$B$448-'5-Roberta'!$B$503 -> 469.99447 | D15: =C15/'5-Roberta'!$B$448 -> 0.024940679
A16: 2 anni | B16: ='5-Roberta'!$B$558 -> 17944.672 | C16: ='5-Roberta'!$B$448-'5-Roberta'!$B$558 -> 899.82149 | D16: =C16/'5-Roberta'!$B$448 -> 0.047749836
A17: 3 anni | B17: ='5-Roberta'!$B$613 -> 17554.719 | C17: ='5-Roberta'!$B$448-'5-Roberta'!$B$613 -> 1289.7749 | D17: =C17/'5-Roberta'!$B$448 -> 0.068443065
A18: 5 anni | B18: ='5-Roberta'!$B$668 -> 16889.427 | C18: ='5-Roberta'!$B$448-'5-Roberta'!$B$668 -> 1955.0667 | D18: =C18/'5-Roberta'!$B$448 -> 0.10374737
A20: GLI ANNI DI AUTONOMIA, ALLA SPESA VERA DI ROBERTA
A21: Anni di spesa in liquidita' | B21: Il capitale dura | C21: Roberta arriva a | D21: Imposta cumulata | E21: Bollo cumulato | F21: Totale
A22: nessun secchio | B22: =$B$1003 -> 36 | C22: ='1-Input'!$B$6+B22 -> 83 | D22: =$C$1003 -> 75952.558 | E22: =$D$1003 -> 15039.866 | F22: =D22+E22 -> 90992.424
A23: 1 anni | B23: =$B$1059 -> 33 | C23: ='1-Input'!$B$6+B23 -> 80 | D23: =$C$1059 -> 67781.676 | E23: =$D$1059 -> 13895.81 | F23: =D23+E23 -> 81677.486
A24: 2 anni | B24: =$B$1115 -> 31 | C24: ='1-Input'!$B$6+B24 -> 78 | D24: =$C$1115 -> 59757.502 | E24: =$D$1115 -> 13004.248 | F24: =D24+E24 -> 72761.75
A25: 3 anni | B25: =$B$1171 -> 29 | C25: ='1-Input'!$B$6+B25 -> 76 | D25: =$C$1171 -> 53254.378 | E25: =$D$1171 -> 12299.503 | F25: =D25+E25 -> 65553.881
A26: 5 anni | B26: =$B$1227 -> 26 | C26: ='1-Input'!$B$6+B26 -> 73 | D26: =$C$1227 -> 42610.611 | E26: =$D$1227 -> 11235.217 | F26: =D26+E26 -> 53845.828
A27: RISPARMIO D'IMPOSTA COL SECCHIO DA DUE ANNI | B27: =D22-D24 -> 16195.056
A28: Non e' un risparmio: col secchio Roberta paga meno imposta perche' ha meno, e per cinque anni in meno. Il totale della colonna F scende insieme al patrimonio.
A30: IL CONTO CHE VA FATTO FINO IN FONDO — il piano non regge nemmeno senza secchio
A31: Spesa massima sostenibile senza secchio | B31: ='5-Roberta'!$B$448 -> 18844.494
A32: Spesa effettiva di Roberta | B32: ='1-Input'!$B$10 -> 19800
A33: DI QUANTO E' CORTA, ogni anno | B33: =B32-B31 -> 955.5063 | C33: =B33/B31 -> 0.050704801
A34: Costo del secchio da due anni | B34: ='5-Roberta'!$B$448-'5-Roberta'!$B$558 -> 899.82149
A35: Il costo del secchio in quota di quanto le manca | B35: =B34/B33 -> 0.9417222
A37: LE TRE LEVE VERE — e nessuna e' il secchio
A38: Leva | B38: Effetto | C38: Basta?
A39: Tagliare la spesa fino al sostenibile | B39: =-B33 -> -955.5063 | C39: ="si per costruzione" -> si per costruzione
A40: Accettare piu' rischio — rendimento reale alto, senza secchio | B40: ='5-Roberta'!$B$723-'1-Input'!$B$10 -> 884.86977 | C40: =IF('5-Roberta'!$B$723>='1-Input'!$B$10,"si","no") -> si
A41: Rendimento reale alto, con un anno di secchio | B41: ='5-Roberta'!$B$778-'1-Input'!$B$10 -> 210.46481 | C41: =IF('5-Roberta'!$B$778>='1-Input'!$B$10,"si","no") -> si
A42: Rendimento reale alto, con due anni di secchio | B42: ='5-Roberta'!$B$833-'1-Input'!$B$10 -> -403.61481 | C42: =IF('5-Roberta'!$B$833>='1-Input'!$B$10,"si","no") -> no
A43: Rendimento reale basso, senza secchio | B43: ='5-Roberta'!$B$173-'1-Input'!$B$10 -> -2577.8152 | C43: =IF('5-Roberta'!$B$173>='1-Input'!$B$10,"si","no") -> no
A44: Al rendimento basso Roberta non ce la fa in nessuna configurazione. Al rendimento alto ce la fa senza secchio — e la colonna «Basta?» dice da sola fino a quale taglia di secchio regge: e' un risultato del motore, non una frase.
A120: CASO ROBERTA — rendimento reale 2% · N = 0
A121: spesa provata → | B121: =0.038*'2-Caso'!$B$12 -> 16681.055 | I121: =0.05*'2-Caso'!$B$12 -> 21948.757 | P121: =IFERROR(I121-I172*(I121-B121)/(I172-B172),I121) -> 17301.136 | W121: =IFERROR(P121-P172*(P121-I121)/(P172-I172),P121) -> 17208.87 | AD121: =IFERROR(W121-W172*(W121-P121)/(W172-P172),W121) -> 17222.185 | AK121: =IFERROR(AD121-AD172*(AD121-W121)/(AD172-W172),AD121) -> 17222.185
...

Sheet 6-Banda
A1: La banda di sensibilita': quanto costano davvero due anni di secchio
A2: Strumento informativo / divulgativo. NON è consulenza finanziaria. I valori sono indicativi al 2026 e vanno verificati col tuo consulente.
A3: Dodici scenari, UNA VARIABILE ALLA VOLTA. Il costo del secchio e' la differenza fra la spesa massima sostenibile senza secchio e quella con due anni di spesa in liquidita': entrambe ricalcolate da capo in ogni scenario.
A5: IL COSTO DI DUE ANNI DI SECCHIO IN DODICI SCENARI
A6: Perturbazione | B6: Spesa max senza secchio | C6: Spesa max con due anni | D6: Costo | E6: In % del tenore di vita
A7: Caso base | B7: ='5-Roberta'!$B$448 -> 18844.494 | C7: ='5-Roberta'!$B$558 -> 17944.672 | D7: =B7-C7 -> 899.82149 | E7: =D7/B7 -> 0.047749836
A8: Liquidita' in ETF monetario | B8: =$B$173 -> 18844.494 | C8: =$B$228 -> 17915.933 | D8: =B8-C8 -> 928.56025 | E8: =D8/B8 -> 0.049274884
A9: Liquidita' in BOT 12 mesi | B9: =$B$283 -> 18844.494 | C9: =$B$338 -> 18267.075 | D9: =B9-C9 -> 577.41858 | E9: =D9/B9 -> 0.030641236
A10: Pensione dal 22° anno | B10: =$B$393 -> 19087.26 | C10: =$B$448 -> 18174.982 | D10: =B10-C10 -> 912.27801 | E10: =D10/B10 -> 0.047795126
A11: Pensione dal 24° anno | B11: =$B$503 -> 18607.464 | C11: =$B$558 -> 17719.803 | D11: =B11-C11 -> 887.66175 | E11: =D11/B11 -> 0.047704606
A12: Pensione all'estremo alto della banda | B12: =$B$613 -> 19541.001 | C12: =$B$668 -> 18617.289 | D12: =B12-C12 -> 923.71179 | E12: =D12/B12 -> 0.047270444
A13: Orizzonte a 90 anni | B13: =$B$723 -> 19043.646 | C13: =$B$778 -> 18140.092 | D13: =B13-C13 -> 903.55308 | E13: =D13/B13 -> 0.047446434
A14: Orizzonte a 95 anni | B14: =$B$833 -> 18580.533 | C14: =$B$888 -> 17685.519 | D14: =B14-C14 -> 895.014 | E14: =D14/B14 -> 0.048169447
A15: Nessuna plusvalenza latente | B15: =$B$943 -> 19492.526 | C15: =$B$998 -> 18520.196 | D15: =B15-C15 -> 972.33033 | E15: =D15/B15 -> 0.049882212
A16: Latente al 37,5% invece che al 21,64% | B16: =$B$1053 -> 18364.455 | C16: =$B$1108 -> 17516.752 | D16: =B16-C16 -> 847.7032 | E16: =D16/B16 -> 0.046159997
A17: Rendimento reale basso | B17: ='5-Roberta'!$B$173 -> 17222.185 | C17: ='5-Roberta'!$B$283 -> 16656.5 | D17: =B17-C17 -> 565.68443 | E17: =D17/B17 -> 0.032846264
A18: Rendimento reale alto | B18: ='5-Roberta'!$B$723 -> 20684.87 | C18: ='5-Roberta'!$B$833 -> 19396.385 | D18: =B18-C18 -> 1288.4846 | E18: =D18/B18 -> 0.062291162
A20: BANDA DEL COSTO — minimo / massimo | B20: =MIN(D7:D18) -> 565.68443 | C20: =MAX(D7:D18) -> 1288.4846
A21: BANDA IN % DEL TENORE DI VITA — minimo / massimo | B21: =MIN(E7:E18) -> 0.030641236 | C21: =MAX(E7:E18) -> 0.062291162
A22: Scarto massimo delle perturbazioni DIVERSE da strumento e rendimento | B22: =MAX(ABS(D10-D7),ABS(D11-D7),ABS(D12-D7),ABS(D13-D7),ABS(D14-D7),ABS(D15-D7),ABS(D16-D7)) -> 72.508844
A23: Leva «dove tieni la liquidita'» — da / a | B23: =D8-D7 -> 28.738761 | C23: =D9-D7 -> -322.40291
A24: Leva «quanto rende il portafoglio» — da / a | B24: =D17-D7 -> -334.13706 | C24: =D18-D7 -> 388.66309
A26: Il costo si muove per DUE SOLE RAGIONI: dove tieni la liquidita' e quanto rende il portafoglio. Tutte le altre sette perturbazioni — quando arriva la pensione, quanto vale, se muori a 90 o a 95, quanta plusvalenza latente hai — lo spostano di meno di cento euro. La riga «scarto massimo» sopra lo misura invece di affermarlo.
A120: BANDA — Liquidita' in ETF monetario · N = 0
A121: spesa provata → | B121: =0.038*'2-Caso'!$B$12 -> 16681.055 | I121: =0.05*'2-Caso'!$B$12 -> 21948.757 | P121: =IFERROR(I121-I172*(I121-B121)/(I172-B172),I121) -> 19095.04 | W121: =IFERROR(P121-P172*(P121-I121)/(P172-I172),P121) -> 18838.764 | AD121: =IFERROR(W121-W172*(W121-P121)/(W172-P172),W121) -> 18845.547 | AK121: =IFERROR(AD121-AD172*(AD121-W121)/(AD172-W172),AD121) -> 18844.494
A122: anno | B122: latente | C122: lordo venduto | D122: secchio ante bollo | E122: portaf. ante bollo | F122: secchio 1 | G122: portafoglio | H122: base di costo | I122: latente | J122: lordo venduto | K122: secchio ante bollo | L122: portaf. ante bollo | M122: secchio 1 | N122: portafoglio | O122: base di costo | P122: latente | Q122: lordo venduto | R122: secchio ante bollo | S122: portaf. ante bollo | T122: secchio 1 | U122: portafoglio | V122: base di costo | W122: latente | X122: lordo venduto | Y122: secchio ante bollo | Z122: portaf. ante bollo | AA122: secchio 1 | AB122: portafoglio | AC122: base di costo | AD122: latente | AE122: lordo venduto | AF122: secchio ante bollo | AG122: portaf. ante bollo | AH122: secchio 1 | AI122: portafoglio | AJ122: base di costo | AK122: latente | AL122: lordo venduto | AM122: secchio ante bollo | AN122: portaf. ante bollo | AO122: secchio 1 | AP122: portafoglio | AQ122: base di costo
A123: 0 | F123: =MIN(0*B121,'2-Caso'!$B$12) -> 0 | G123: ='2-Caso'!$B$12-F123 -> 438975.14 | H123: ='2-Caso'!$B$13*G123/'2-Caso'!$B$12 -> 344000 | M123: =MIN(0*I121,'2-Caso'!$B$12) -> 0 | N123: ='2-Caso'!$B$12-M123 -> 438975.14 | O123: ='2-Caso'!$B$13*N123/'2-Caso'!$B$12 -> 344000 | T123: =MIN(0*P121,'2-Caso'!$B$12) -> 0 | U123: ='2-Caso'!$B$12-T123 -> 438975.14 | V123: ='2-Caso'!$B$13*U123/'2-Caso'!$B$12 -> 344000 | AA123: =MIN(0*W121,'2-Caso'!$B$12) -> 0 | AB123: ='2-Caso'!$B$12-AA123 -> 438975.14 | AC123: ='2-Caso'!$B$13*AB123/'2-Caso'!$B$12 -> 344000 | AH123: =MIN(0*AD121,'2-Caso'!$B$12) -> 0 | AI123: ='2-Caso'!$B$12-AH123 -> 438975.14 | AJ123: ='2-Caso'!$B$13*AI123/'2-Caso'!$B$12 -> 344000 | AO123: =MIN(0*AK121,'2-Caso'!$B$12) -> 0 | AP123: ='2-Caso'!$B$12-AO123 -> 438975.14 | AQ123: ='2-Caso'!$B$13*AP123/'2-Caso'!$B$12 -> 344000
A124: =1 -> 1 | B124: =IF($A124>'1-Input'!$B$26,0,IF(G123<=0,0,MAX(0,(G123-H123)/G123))) -> 0.21635653 | C124: =IF($A124>'1-Input'!$B$26,0,(MAX(0,B121-IF($A124>='1-Input'!$C$12,'1-Input'!$B$12,0))-MIN(MAX(F123,0),MAX(0,B121-IF($A124>='1-Input'!$C$12,'1-Input'!$B$12,0))))*(1/(1-'P-Parametri'!$B$6*B124))+MIN(MAX(0,G123-(MAX(0,B121-IF($A124>='1-Input'!$C$12,'1-Input'!$B$12,0))-MIN(MAX(F123,0),MAX(0,B121-IF($A124>='1-Input'!$C$12,'1-Input'!$B$12,0))))*(1/(1-'P-Parametri'!$B$6*B124))),MAX(0,0*B121-(F123-MIN(MAX(F123,0),MAX(0,B121-IF($A124>='1-Input'!$C$12,'1-Input'!$B$12,0)))))*(1/(1-'P-Parametri'!$B$6*B124)))) -> 17675.341 | D124: =IF($A124>'1-Input'!$B$26,F123,(F123-MAX(0,B121-IF($A124>='1-Input'!$C$12,'1-Input'!$B$12,0))+C124*(1-'P-Parametri'!$B$6*B124))*(1+ROUND('3-Liquidita'!$F$11,4))) -> -3.6216079e-12 | E124: =IF($A124>'1-Input'!$B$26,G123,(G123-C124)*(1+'5-Roberta'!$C$4)) -> 433938.79 | F124: =IF($A124>'1-Input'!$B$26,D124,D124-'P-Parametri'!$B$8*(E124+D124)+MIN(MAX(E124,0),'P-Parametri'!$B$8*(E124+D124))) -> -3.6379788e-12 | G124: =IF($A124>'1-Input'!$B$26,E124,E124-MIN(MAX(E124,0),'P-Parametri'!$B$8*(E124+D124))) -> 433070.92 | H124: =IF($A124>'1-Input'!$B$26,H123,H123-C124*(1-B124)) -> 330148.83 | I124: =IF($A124>'1-Input'!$B$26,0,IF(N123<=0,0,MAX(0,(N123-O123)/N123))) -> 0.21635653 | J124: =IF($A124>'1-Input'!$B$26,0,(MAX(0,I121-IF($A124>='1-Input'!$C$12,'1-Input'!$B$12,0))-MIN(MAX(M123,0),MAX(0,I121-IF($A124>='1-Input'!$C$12,'1-Input'!$B$12,0))))*(1/(1-'P-Parametri'!$B$6*I124))+MIN(MAX(0,N123-(MAX(0,I121-IF($A124>='1-Input'!$C$12,'1-Input'!$B$12,0))-MIN(MAX(M123,0),MAX(0,I121-IF($A124>='1-Input'!$C$12,'1-Input'!$B$12,0))))*(1/(1-'P-Parametri'!$B$6*I124))),MAX(0,0*I121-(M123-MIN(MAX(M123,0),MAX(0,I121-IF($A124>='1-Input'!$C$12,'1-Input'!$B$12,0)))))*(1/(1-'P-Parametri'!$B$6*I124)))) -> 23257.028 | K124: =IF($A124>'1-Input'!$B$26,M123,(M123-MAX(0,I121-IF($A124>='1-Input'!$C$12,'1-Input'!$B$12,0))+J124*(1-'P-Parametri'!$B$6*I124))*(1+ROUND('3-Liquidita'!$F$11,4))) -> 0 | L124: =IF($A124>'1-Input'!$B$26,N123,(N123-J124)*(1+'5-Roberta'!$C$4)) -> 428189.66 | M124: =IF($A124>'1-Input'!$B$26,K124,K124-'P-Parametri'!$B$8*(L124+K124)+MIN(MAX(L124,0),'P-Parametri'!$B$8*(L124+K124))) -> 0 | N124: =IF($A124>'1-Input'!$B$26,L124,L124-MIN(MAX(L124,0),'P-Parametri'!$B$8*(L124+K124))) -> 427333.28 | O124: =IF($A124>'1-Input'!$B$26,O123,O123-J124*(1-I124)) -> 325774.78 | P124: =IF($A124>'1-Input'!$B$26,0,IF(U123<=0,0,MAX(0,(U123-V123)/U123))) -> 0.21635653 | Q124: =IF($A124>'1-Input'!$B$26,0,(MAX(0,P121-IF($A124>='1-Input'!$C$12,'1-Input'!$B$12,0))-MIN(MAX(T123,0),MAX(0,P121-IF($A124>='1-Input'!$C$12,'1-Input'!$B$12,0))))*(1/(1-'P-Parametri'!$B$6*P124))+MIN(MAX(0,U123-(MAX(0,P121-IF($A124>='1-Input'!$C$12,'1-Input'!$B$12,0))-MIN(MAX(T123,0),MAX(0,P121-IF($A124>='1-Input'!$C$12,'1-Input'!$B$12,0))))*(1/(1-'P-Parametri'!$B$6*P124))),MAX(0,0*P121-(T123-MIN(MAX(T123,0),MAX(0,P121-IF($A124>='1-Input'!$C$12,'1-Input'!$B$12,0)))))*(1/(1-'P-Parametri'!$B$6*P124)))) -> 20233.212 | R124: =IF($A124>'1-Input'!$B$26,T123,(T123-MAX(0,P121-IF($A124>='1-Input'!$C$12,'1-Input'!$B$12,0))+Q124*(1-'P-Parametri'!$B$6*P124))*(1+ROUND('3-Liquidita'!$F$11,4))) -> 0 | S124: =IF($A124>'1-Input'!$B$26,U123,(U123-Q124)*(1+'5-Roberta'!$C$4)) -> 431304.19 | T124: =IF($A124>'1-Input'!$B$26,R124,R124-'P-Parametri'!$B$8*(S124+R124)+MIN(MAX(S124,0),'P-Parametri'!$B$8*(S124+R124))) -> 0 | U124: =IF($A124>'1-Input'!$B$26,S124,S124-MIN(MAX(S124,0),'P-Parametri'!$B$8*(S124+R124))) -> 430441.58 | V124: =IF($A124>'1-Input'!$B$26,V123,V123-Q124*(1-P124)) -> 328144.38 | W124: =IF($A124>'1-Input'!$B$26,0,IF(AB123<=0,0,MAX(0,(AB123-AC123)/AB123))) -> 0.21635653 | X124: =IF($A124>'1-Input'!$B$26,0,(MAX(0,W121-IF($A124>='1-Input'!$C$12,'1-Input'!$B$12,0))-MIN(MAX(AA123,0),MAX(0,W121-IF($A124>='1-Input'!$C$12,'1-Input'!$B$12,0))))*(1/(1-'P-Parametri'!$B$6*W124))+MIN(MAX(0,AB123-(MAX(0,W121-IF($A124>='1-Input'!$C$12,'1-Input'!$B$12,0))-MIN(MAX(AA123,0),MAX(0,W121-IF($A124>='1-Input'!$C$12,'1-Input'!$B$12,0))))*(1/(1-'P-Parametri'!$B$6*W124))),MAX(0,0*W121-(AA123-MIN(MAX(AA123,0),MAX(0,W121-IF($A124>='1-Input'!$C$12,'1-Input'!$B$12,0)))))*(1/(1-'P-Parametri'!$B$6*W124)))) -> 19961.661 | Y124: =IF($A124>'1-Input'!$B$26,AA123,(AA123-MAX(0,W121-IF($A124>='1-Input'!$C$12,'1-Input'!$B$12,0))+X124*(1-'P-Parametri'!$B$6*W124))*(1+ROUND('3-Liquidita'!$F$11,4))) -> 0 | Z124: =IF($A124>'1-Input'!$B$26,AB123,(AB123-X124)*(1+'5-Roberta'!$C$4)) -> 431583.88 | AA124: =IF($A124>'1-Input'!$B$26,Y124,Y124-'P-Parametri'!$B$8*(Z124+Y124)+MIN(MAX(Z124,0),'P-Parametri'!$B$8*(Z124+Y124))) -> 0 | AB124: =IF($A124>'1-Input'!$B$26,Z124,Z124-MIN(MAX(Z124,0),'P-Parametri'!$B$8*(Z124+Y124))) -> 430720.72 | AC124: =IF($A124>'1-Input'!$B$26,AC123,AC123-X124*(1-W124)) -> 328357.17 | AD124: =IF($A124>'1-Input'!$B$26,0,IF(AI123<=0,0,MAX(0,(AI123-AJ123)/AI123))) -> 0.21635653 | AE124: =IF($A124>'1-Input'!$B$26,0,(MAX(0,AD121-IF($A124>='1-Input'!$C$12,'1-Input'!$B$12,0))-MIN(MAX(AH123,0),MAX(0,AD121-IF($A124>='1-Input'!$C$12,'1-Input'!$B$12,0))))*(1/(1-'P-Parametri'!$B$6*AD124))+MIN(MAX(0,AI123-(MAX(0,AD121-IF($A124>='1-Input'!$C$12,'1-Input'!$B$12,0))-MIN(MAX(AH123,0),MAX(0,AD121-IF($A124>='1-Input'!$C$12,'1-Input'!$B$12,0))))*(1/(1-'P-Parametri'!$B$6*AD124))),MAX(0,0*AD121-(AH123-MIN(MAX(AH123,0),MAX(0,AD121-IF($A124>='1-Input'!$C$12,'1-Input'!$B$12,0)))))*(1/(1-'P-Parametri'!$B$6*AD124)))) -> 19968.849 | AF124: =IF($A124>'1-Input'!$B$26,AH123,(AH123-MAX(0,AD121-IF($A124>='1-Input'!$C$12,'1-Input'!$B$12,0))+AE124*(1-'P-Parametri'!$B$6*AD124))*(1+ROUND('3-Liquidita'!$F$11,4))) -> 0 | AG124: =IF($A124>'1-Input'!$B$26,AI123,(AI123-AE124)*(1+'5-Roberta'!$C$4)) -> 431576.48 | AH124: =IF($A124>'1-Input'!$B$26,AF124,AF124-'P-Parametri'!$B$8*(AG124+AF124)+MIN(MAX(AG124,0),'P-Parametri'!$B$8*(AG124+AF124))) -> 0 | AI124: =IF($A124>'1-Input'!$B$26,AG124,AG124-MIN(MAX(AG124,0),'P-Parametri'!$B$8*(AG124+AF124))) -> 430713.33 | AJ124: =IF($A124>'1-Input'!$B$26,AJ123,AJ123-AE124*(1-AD124)) -> 328351.54 | AK124: =IF($A124>'1-Input'!$B$26,0,IF(AP123<=0,0,MAX(0,(AP123-AQ123)/AP123))) -> 0.21635653 | AL124: =IF($A124>'1-Input'!$B$26,0,(MAX(0,AK121-IF($A124>='1-Input'!$C$12,'1-Input'!$B$12,0))-MIN(MAX(AO123,0),MAX(0,AK121-IF($A124>='1-Input'!$C$12,'1-Input'!$B$12,0))))*(1/(1-'P-Parametri'!$B$6*AK124))+MIN(MAX(0,AP123-(MAX(0,AK121-IF($A124>='1-Input'!$C$12,'1-Input'!$B$12,0))-MIN(MAX(AO123,0),MAX(0,AK121-IF($A124>='1-Input'!$C$12,'1-Input'!$B$12,0))))*(1/(1-'P-Parametri'!$B$6*AK124))),MAX(0,0*AK121-(AO123-MIN(MAX(AO123,0),MAX(0,AK121-IF($A124>='1-Input'!$C$12,'1-Input'!$B$12,0)))))*(1/(1-'P-Parametri'!$B$6*AK124)))) -> 19967.733 | AM124: =IF($A124>'1-Input'!$B$26,AO123,(AO123-MAX(0,AK121-IF($A124>='1-Input'!$C$12,'1-Input'!$B$12,0))+AL124*(1-'P-Parametri'!$B$6*AK124))*(1+ROUND('3-Liquidita'!$F$11,4))) -> 0 | AN124: =IF($A124>'1-Input'!$B$26,AP123,(AP123-AL124)*(1+'5-Roberta'!$C$4)) -> 431577.63 | AO124: =IF($A124>'1-Input'!$B$26,AM124,AM124-'P-Parametri'!$B$8*(AN124+AM124)+MIN(MAX(AN124,0),'P-Parametri'!$B$8*(AN124+AM124))) -> 0 | AP124: =IF($A124>'1-Input'!$B$26,AN124,AN124-MIN(MAX(AN124,0),'P-Parametri'!$B$8*(AN124+AM124))) -> 430714.47 | AQ124: =IF($A124>'1-Input'!$B$26,AQ123,AQ123-AL124*(1-AK124)) -> 328352.42
A125: =2 -> 2 | B125: =IF($A125>'1-Input'!$B$26,0,IF(G124<=0,0,MAX(0,(G124-H124)/G124))) -> 0.23765641 | C125: =IF($A125>'1-Input'!$B$26,0,(MAX(0,B121-IF($A125>='1-Input'!$C$12,'1-Input'!$B$12,0))-MIN(MAX(F124,0),MAX(0,B121-IF($A125>='1-Input'!$C$12,'1-Input'!$B$12,0))))*(1/(1-'P-Parametri'!$B$6*B125))+MIN(MAX(0,G124-(MAX(0,B121-IF($A125>='1-Input'!$C$12,'1-Input'!$B$12,0))-MIN(MAX(F124,0),MAX(0,B121-IF($A125>='1-Input'!$C$12,'1-Input'!$B$12,0))))*(1/(1-'P-Parametri'!$B$6*B125))),MAX(0,0*B121-(F124-MIN(MAX(F124,0),MAX(0,B121-IF($A125>='1-Input'!$C$12,'1-Input'!$B$12,0)))))*(1/(1-'P-Parametri'!$B$6*B125)))) -> 17779.673 | D125: =IF($A125>'1-Input'!$B$26,F124,(F124-MAX(0,B121-IF($A125>='1-Input'!$C$12,'1-Input'!$B$12,0))+C125*(1-'P-Parametri'!$B$6*B125))*(1+ROUND('3-Liquidita'!$F$11,4))) -> 0 | E125: =IF($A125>'1-Input'!$B$26,G124,(G124-C125)*(1+'5-Roberta'!$C$4)) -> 427749.98 | F125: =IF($A125>'1-Input'!$B$26,D125,D125-'P-Parametri'!$B$8*(E125+D125)+MIN(MAX(E125,0),'P-Parametri'!$B$8*(E125+D125))) -> 0 | G125: =IF($A125>'1-Input'!$B$26,E125,E125-MIN(MAX(E125,0),'P-Parametri'!$B$8*(E125+D125))) -> 426894.48 | H125: =IF($A125>'1-Input'!$B$26,H124,H124-C125*(1-B125)) -> 316594.61 | I125: =IF($A125>'1-Input'!$B$26,0,IF(N124<=0,0,MAX(0,(N124-O124)/N124))) -> 0.23765641 | J125: =IF($A125>'1-Input'!$B$26,0,(MAX(0,I121-IF($A125>='1-Input'!$C$12,'1-Input'!$B$12,0))-MIN(MAX(M124,0),MAX(0,I121-IF($A125>='1-Input'!$C$12,'1-Input'!$B$12,0))))*(1/(1-'P-Parametri'!$B$6*I125))+MIN(MAX(0,N124-(MAX(0,I121-IF($A125>='1-Input'!$C$12,'1-Input'!$B$12,0))-MIN(MAX(M124,0),MAX(0,I121-IF($A125>='1-Input'!$C$12,'1-Input'!$B$12,0))))*(1/(1-'P-Parametri'!$B$6*I125))),MAX(0,0*I121-(M124-MIN(MAX(M124,0),MAX(0,I121-IF($A125>='1-Input'!$C$12,'1-Input'!$B$12,0)))))*(1/(1-'P-Parametri'!$B$6*I125)))) -> 23394.307 | K125: =IF($A125>'1-Input'!$B$26,M124,(M124-MAX(0,I121-IF($A125>='1-Input'!$C$12,'1-Input'!$B$12,0))+J125*(1-'P-Parametri'!$B$6*I125))*(1+ROUND('3-Liquidita'!$F$11,4))) -> 0 | L125: =IF($A125>'1-Input'!$B$26,N124,(N124-J125)*(1+'5-Roberta'!$C$4)) -> 416057.14 | M125: =IF($A125>'1-Input'!$B$26,K125,K125-'P-Parametri'!$B$8*(L125+K125)+MIN(MAX(L125,0),'P-Parametri'!$B$8*(L125+K125))) -> 0 | N125: =IF($A125>'1-Input'!$B$26,L125,L125-MIN(MAX(L125,0),'P-Parametri'!$B$8*(L125+K125))) -> 415225.02 | O125: =IF($A125>'1-Input'!$B$26,O124,O124-J125*(1-I125)) -> 307940.28 | P125: =IF($A125>'1-Input'!$B$26,0,IF(U124<=0,0,MAX(0,(U124-V124)/U124))) -> 0.23765641 | Q125: =IF($A125>'1-Input'!$B$26,0,(MAX(0,P121-IF($A125>='1-Input'!$C$12,'1-Input'!$B$12,0))-MIN(MAX(T124,0),MAX(0,P121-IF($A125>='1-Input'!$C$12,'1-Input'!$B$12,0))))*(1/(1-'P-Parametri'!$B$6*P125))+MIN(MAX(0,U124-(MAX(0,P121-IF($A125>='1-Input'!$C$12,'1-Input'!$B$12,0))-MIN(MAX(T124,0),MAX(0,P121-IF($A125>='1-Input'!$C$12,'1-Input'!$B$12,0))))*(1/(1-'P-Parametri'!$B$6*P125))),MAX(0,0*P121-(T124-MIN(MAX(T124,0),MAX(0,P121-IF($A125>='1-Input'!$C$12,'1-Input'!$B$12,0)))))*(1/(1-'P-Parametri'!$B$6*P125)))) -> 20352.643 | R125: =IF($A125>'1-Input'!$B$26,T124,(T124-MAX(0,P121-IF($A125>='1-Input'!$C$12,'1-Input'!$B$12,0))+Q125*(1-'P-Parametri'!$B$6*P125))*(1+ROUND('3-Liquidita'!$F$11,4))) -> 3.6216079e-12 | S125: =IF($A125>'1-Input'!$B$26,U124,(U124-Q125)*(1+'5-Roberta'!$C$4)) -> 422391.6 | T125: =IF($A125>'1-Input'!$B$26,R125,R125-'P-Parametri'!$B$8*(S125+R125)+MIN(MAX(S125,0),'P-Parametri'!$B$8*(S125+R125))) -> 3.6379788e-12 | U125: =IF($A125>'1-Input'!$B$26,S125,S125-MIN(MAX(S125,0),'P-Parametri'!$B$8*(S125+R125))) -> 421546.82 | V125: =IF($A125>'1-Input'!$B$26,V124,V124-Q125*(1-P125)) -> 312628.67 | W125: =IF($A125>'1-Input'!$B$26,0,IF(AB124<=0,0,MAX(0,(AB124-AC124)/AB124))) -> 0.23765641 | X125: =IF($A125>'1-Input'!$B$26,0,(MAX(0,W121-IF($A125>='1-Input'!$C$12,'1-Input'!$B$12,0))-MIN(MAX(AA124,0),MAX(0,W121-IF($A125>='1-Input'!$C$12,'1-Input'!$B$12,0))))*(1/(1-'P-Parametri'!$B$6*W125))+MIN(MAX(0,AB124-(MAX(0,W121-IF($A125>='1-Input'!$C$12,'1-Input'!$B$12,0))-MIN(MAX(AA124,0),MAX(0,W121-IF($A125>='1-Input'!$C$12,'1-Input'!$B$12,0))))*(1/(1-'P-Parametri'!$B$6*W125))),MAX(0,0*W121-(AA124-MIN(MAX(AA124,0),MAX(0,W121-IF($A125>='1-Input'!$C$12,'1-Input'!$B$12,0)))))*(1/(1-'P-Parametri'!$B$6*W125)))) -> 20079.489 | Y125: =IF($A125>'1-Input'!$B$26,AA124,(AA124-MAX(0,W121-IF($A125>='1-Input'!$C$12,'1-Input'!$B$12,0))+X125*(1-'P-Parametri'!$B$6*W125))*(1+ROUND('3-Liquidita'!$F$11,4))) -> 0 | Z125: =IF($A125>'1-Input'!$B$26,AB124,(AB124-X125)*(1+'5-Roberta'!$C$4)) -> 422960.46 | AA125: =IF($A125>'1-Input'!$B$26,Y125,Y125-'P-Parametri'!$B$8*(Z125+Y125)+MIN(MAX(Z125,0),'P-Parametri'!$B$8*(Z125+Y125))) -> 0 | AB125: =IF($A125>'1-Input'!$B$26,Z125,Z125-MIN(MAX(Z125,0),'P-Parametri'!$B$8*(Z125+Y125))) -> 422114.54 | AC125: =IF($A125>'1-Input'!$B$26,AC124,AC124-X125*(1-W125)) -> 313049.71 | AD125: =IF($A125>'1-Input'!$B$26,0,IF(AI124<=0,0,MAX(0,(AI124-AJ124)/AI124))) -> 0.23765641 | AE125: =IF($A125>'1-Input'!$B$26,0,(MAX(0,AD121-IF($A125>='1-Input'!$C$12,'1-Input'!$B$12,0))-MIN(MAX(AH124,0),MAX(0,AD121-IF($A125>='1-Input'!$C$12,'1-Input'!$B$12,0))))*(1/(1-'P-Parametri'!$B$6*AD125))+MIN(MAX(0,AI124-(MAX(0,AD121-IF($A125>='1-Input'!$C$12,'1-Input'!$B$12,0))-MIN(MAX(AH124,0),MAX(0,AD121-IF($A125>='1-Input'!$C$12,'1-Input'!$B$12,0))))*(1/(1-'P-Parametri'!$B$6*AD125))),MAX(0,0*AD121-(AH124-MIN(MAX(AH124,0),MAX(0,AD121-IF($A125>='1-Input'!$C$12,'1-Input'!$B$12,0)))))*(1/(1-'P-Parametri'!$B$6*AD125)))) -> 20086.719 | AF125: =IF($A125>'1-Input'!$B$26,AH124,(AH124-MAX(0,AD121-IF($A125>='1-Input'!$C$12,'1-Input'!$B$12,0))+AE125*(1-'P-Parametri'!$B$6*AD125))*(1+ROUND('3-Liquidita'!$F$11,4))) -> 0 | AG125: =IF($A125>'1-Input'!$B$26,AI124,(AI124-AE125)*(1+'5-Roberta'!$C$4)) -> 422945.41 | AH125: =IF($A125>'1-Input'!$B$26,AF125,AF125-'P-Parametri'!$B$8*(AG125+AF125)+MIN(MAX(AG125,0),'P-Parametri'!$B$8*(AG125+AF125))) -> 0 | AI125: =IF($A125>'1-Input'!$B$26,AG125,AG125-MIN(MAX(AG125,0),'P-Parametri'!$B$8*(AG125+AF125))) -> 422099.52 | AJ125: =IF($A125>'1-Input'!$B$26,AJ124,AJ124-AE125*(1-AD125)) -> 313038.56 | AK125: =IF($A125>'1-Input'!$B$26,0,IF(AP124<=0,0,MAX(0,(AP124-AQ124)/AP124))) -> 0.23765641 | AL125: =IF($A125>'1-Input'!$B$26,0,(MAX(0,AK121-IF($A125>='1-Input'!$C$12,'1-Input'!$B$12,0))-MIN(MAX(AO124,0),MAX(0,AK121-IF($A125>='1-Input'!$C$12,'1-Input'!$B$12,0))))*(1/(1-'P-Parametri'!$B$6*AK125))+MIN(MAX(0,AP124-(MAX(0,AK121-IF($A125>='1-Input'!$C$12,'1-Input'!$B$12,0))-MIN(MAX(AO124,0),MAX(0,AK121-IF($A125>='1-Input'!$C$12,'1-Input'!$B$12,0))))*(1/(1-'P-Parametri'!$B$6*AK125))),MAX(0,0*AK121-(AO124-MIN(MAX(AO124,0),MAX(0,AK121-IF($A125>='1-Input'!$C$12,'1-Input'!$B$12,0)))))*(1/(1-'P-Parametri'!$B$6*AK125)))) -> 20085.596 | AM125: =IF($A125>'1-Input'!$B$26,AO124,(AO124-MAX(0,AK121-IF($A125>='1-Input'!$C$12,'1-Input'!$B$12,0))+AL125*(1-'P-Parametri'!$B$6*AK125))*(1+ROUND('3-Liquidita'!$F$11,4))) -> 0 | AN125: =IF($A125>'1-Input'!$B$26,AP124,(AP124-AL125)*(1+'5-Roberta'!$C$4)) -> 422947.74 | AO125: =IF($A125>'1-Input'!$B$26,AM125,AM125-'P-Parametri'!$B$8*(AN125+AM125)+MIN(MAX(AN125,0),'P-Parametri'!$B$8*(AN125+AM125))) -> 0 | AP125: =IF($A125>'1-Input'!$B$26,AN125,AN125-MIN(MAX(AN125,0),'P-Parametri'!$B$8*(AN125+AM125))) -> 422101.85 | AQ125: =IF($A125>'1-Input'!$B$26,AQ124,AQ124-AL125*(1-AK125)) -> 313040.29
