Workbook

Sheet 0-Indice
A1: Marco FIRE — Coast FIRE: il fabbisogno residuo (caso Matteo, 2026)
A2: Strumento informativo / divulgativo. NON è consulenza finanziaria. I valori sono indicativi al 2026 e vanno verificati col tuo consulente.
A4: Indice
A5: 1-Input | B5: I 21 input del caso, stato abitativo compreso, e i derivati
A6: P-Parametri | B6: Parametri normativi e di fonte: aliquote, tassi di sostituzione RGS, ISTAT
A7: 2-Cruscotto | B7: I due verdetti affiancati: il gap in banda e il fabbisogno residuo
A8: 3-Griglia | B8: Capitale necessario oggi e gap, per tasso × anni mancanti
A9: 4-Traiettoria | B9: Anno per anno: bollo, montante, dispersione, accumulazione contro distribuzione
A10: 5-Caso | B10: Motore fiscale, le due chiusure sull'anzianita', il vincolo aritmetico
A11: 6-Anticipata | B11: La soglia di importo della porta breve e la via della previdenza complementare
A12: 7-Denominatori | B12: La spesa ISTAT, l'affitto figurativo e la spesa del caso: i due metri
A13: 8-Fabbisogno | B13: Il capitale che serve davvero, la scala del taglio, i versamenti residui
A14: 9-Ordine | B14: L'ordine dei rendimenti: riordinali e guarda il totale non muoversi
A16: Come usare
A17: 1. Le celle GIALLE sono input — modificale coi tuoi numeri.
A18: 2. Le celle VERDI sono output — si aggiornano automaticamente.
A19: 3. Tutti i numeri di default sono al 2026 da fonti pubbliche.
A20: 4. Niente codice nascosto: l'Excel è solo formule modificabili.
A22: Fonti dati
A23: • Ragioneria generale dello Stato, «Le tendenze di medio-lungo periodo del sistema pensionistico e socio-sanitario — Aggiornamento 2025», Rapporto n. 26, Capitolo 6: Tab. 6.1 p. 166 (tassi di sostituzione lordi, eta' e anzianita'), Tab. 6.3 p. 173 (netti), Tab. 6.2.a p. 168 (sensitivita'), p. 160 (eta' di ingresso e carriere discontinue)
A24: • IRPEF 2026 (23% / 33% / 43%) — L. 199/2025; detrazioni art. 13 TUIR c. 1, 1.1, 3 e 3-bis; ulteriore detrazione L. 207/2024 art. 1 c. 6
A25: • INPS, circolare n. 153 del 19/12/2025 e Allegato n. 2: assegno sociale 546,24 €/mese; importo soglia 2026 della pensione anticipata contributiva 1.638,72 €/mese (valori provvisori)
A26: • ISTAT, «Le spese per i consumi delle famiglie — Anno 2024», 7/10/2025, prospetto p. 15: persona sola 65 anni e piu' 1.794,07 €/mese; glossario, voce «Affitto figurativo» (componente NON monetaria)
A27: • Imposta di bollo 0,20% sul valore di mercato di fine anno — art. 13 c. 2-ter Tariffa Parte I, DPR 642/1972; esclusi i fondi pensione
A28: • Capital gain 26% — art. 3 c. 1 D.L. 66/2014; titoli di Stato 12,5%
... A33: Aggiornamenti: github.com/marcofire-it/marco-fire-simulatori

Sheet 1-Input
A1: Gli input del caso — cambia una cella gialla e tutti i verdi si muovono
A2: Strumento informativo / divulgativo. NON è consulenza finanziaria. I valori sono indicativi al 2026 e vanno verificati col tuo consulente.
A4: INPUT
A5: (1) Eta' attuale | B5: 35
A6: (2) Anno di nascita | B6: 1991
A7: (3) Eta' di ingresso nel mercato del lavoro | B7: 25
A8: (4) Capitale investito oggi | B8: 180000
A9: (5) Retribuzione lorda annua (RAL) | B9: 44000
A10: (6) Obiettivo dichiarato | B10: 800000
A11: (7) Rendimento reale NETTO del coast — menu 2,31 / 2,45 / 3,00 / 3,30 / 4,00 / 4,78 / 5,00 / 7,00% | B11: 0.033
A12: (8) Pavimento prudente (convenzione di canale) | B12: 0.03
A13: (9) STATO ABITATIVO — 1 = vive in AFFITTO (tutta la spesa e' cassa), 0 = casa di proprieta' | B13: 1
A14: (10) Se proprietario: quota della divisione abitazione che e' affitto figurativo | B14: 0.6667
A15: (11) Chiusura sull'anzianita' — 1 = analista (carriera continua), 0 = RGS p. 160 (carriera discontinua) | B15: 1
A16: (12) Fattore di realismo sulla pensione (cursore 0-120%) | B16: 1
... A25: (21) Per quanti anni versare, per chiudere il buco | B25: 10
A26: LO STATO ABITATIVO E' UNA VARIABILE OBBLIGATORIA DELLA SCHEDA-CASO, non un dettaglio. La spesa media ISTAT include gli affitti figurativi, che sono una componente NON MONETARIA: confrontarla con una pensione, che invece e' cassa, e' omogeneo solo se si dichiara come si vive. Nel caso di questo video Matteo VIVE IN AFFITTO, quindi la sua spesa e' tutta monetaria e il confronto e' diretto. Metti 0 e guarda il foglio 7: il denominatore si accorcia e la copertura sale.
A28: DERIVATI — nessuna costante, tutto ricalcolato
A29: Grandezza | B29: Valore | E29: Come si ottiene
A30: Rendimento reale LORDO implicito del coast | B30: =(1+B11)/((1-'P-Parametri'!$B$41)*(1-B22))-1 -> 0.037144429 | E30: si sceglie il netto, si deriva il lordo: i costi si tolgono una volta sola
A31: Rendimento reale LORDO implicito del pavimento | B31: =(1+B12)/((1-'P-Parametri'!$B$41)*(1-B22))-1 -> 0.034132393
A32: Rendimento REALIZZATO netto dell'azionario mondiale (per guardare indietro) | B32: =(1+'P-Parametri'!$B$44)*(1-'P-Parametri'!$B$41)*(1-B22)-1 -> 0.047796208 | E32: 5,20% lordo 1900-2024, al netto di TER e bollo contati una volta sola
A33: Eta' dell'anticipata contributiva (vecchiaia - 3 anni + finestra di 3 mesi) | B33: ='P-Parametri'!$B$30-'P-Parametri'!$B$31+'P-Parametri'!$C$31 -> 66.95
A34: Eta' di uscita selezionata | B34: =IF(B24=1,'P-Parametri'!$B$30,B33) -> 69.7
A35: Anni mancanti alla pensione (n del coast) | B35: =B34-B5 -> 34.7
A36: Anzianita' contributiva all'uscita, con carriera continua | B36: =B34-B7 -> 44.7
A37: Anzianita' della chiusura adottata | B37: =IF(B15=1,B36,IF(B24=1,'P-Parametri'!$B$26,'P-Parametri'!$B$29)) -> 44.7 | E37: con la chiusura RGS di p. 160 l'anzianita' tabellata non si tocca
A38: Coda di decumulo (dall'uscita all'eta' terminale) | B38: ='P-Parametri'!$B$60-B34 -> 22.3
A39: Anni di accumulo alle spalle (dall'ingresso a oggi) | B39: =B5-B7 -> 10
A40: Anni mancanti sulla porta lunga / sulla porta breve | B40: ='P-Parametri'!$B$30-B5 -> 34.7 | C40: =B33-B5 -> 31.95
A42: CONVENZIONI DICHIARATE. Tutto e' in euro reali di oggi (inflazione di modello 2%) e al netto delle imposte, salvo dove e' scritto «lordo». I versamenti in accumulo entrano a FINE anno; il prelievo in decumulo e' ANTICIPATO (inizio anno). Il tasso di decumulo del 3,00% e' una CONVENZIONE ereditata dal catalogo e non e' netto secondo la disciplina dei costi applicata all'accumulo: la riga di stress al 2,45% e' nel foglio 8.
A43: IPOTESI DI MODELLO, DICHIARATA: la retribuzione lorda e' costante in EURO REALI dai 25 anni all'uscita. Il tasso di risparmio che ne discende e' un EQUIVALENTE COSTANTE, non il risparmio effettivo di ogni singolo anno. Una carriera crescente 28.000 -> 44.000 abbassa il tasso di sostituzione e alza il tasso di risparmio dei primi anni: il foglio 5 mostra la sensibilita'.

Sheet P-Parametri
A1: Parametri normativi e di fonte
A2: Strumento informativo / divulgativo. NON è consulenza finanziaria. I valori sono indicativi al 2026 e vanno verificati col tuo consulente.
A3: Le uniche costanti del modello, oltre agli input gialli del foglio 1, stanno qui. Tutti gli altri fogli le referenziano: non c'e' nessun valore incollato nelle celle verdi.
A5: IRPEF 2026 (L. 199/2025) e detrazioni — fotografia di oggi
A6: Primo scaglione — limite / aliquota | B6: 28000 | C6: 0.23
A7: Secondo scaglione — limite / aliquota | B7: 50000 | C7: 0.33
A8: Terzo scaglione — aliquota oltre il secondo limite | C8: 0.43
A9: Imposta cumulata fino al primo scaglione | B9: =B6*C6 -> 6440
A10: Imposta cumulata fino al secondo scaglione | B10: =B9+(B7-B6)*C7 -> 13700
A11: Addizionali regionali e comunali (ipotesi di canale) | B11: 0.02
A12: Detrazione lavoro dipendente — importo fino alla soglia bassa / soglia | B12: 1955 | C12: 15000
A13: Detrazione lavoro 15.000-28.000 — base / incremento / ampiezza | B13: 1910 | C13: 1190 | D13: 13000
A14: Detrazione lavoro 28.000-50.000 — base / ampiezza | B14: 1910 | C14: 22000
A15: Detrazione art. 13 comma 1.1 — importo / da / a | B15: 65 | C15: 25000 | D15: 35000
A16: Ulteriore detrazione L. 207/2024 c. 6 — importo / soglia / plateau / azzeramento | B16: 1000 | C16: 20000 | D16: 32000 | E16: 40000
A17: Detrazione da pensione — importo massimo / soglia bassa | B17: 1955 | C17: 8500
A18: Detrazione da pensione 8.500-28.000 — base / incremento / ampiezza | B18: 700 | C18: 1255 | D18: 19500
A19: Detrazione da pensione 28.000-50.000 — base / ampiezza | B19: 700 | C19: 22000
A20: Detrazione art. 13 comma 3-bis — importo / da / a | B20: 50 | C20: 25000 | D20: 29000
A21: Contributi a carico del lavoratore | B21: 0.0919
A23: Previdenza obbligatoria — PROIEZIONI RGS, non norme
A24: Tasso di sostituzione NETTO tabellato, vecchiaia 2060 (Tab. 6.3, p. 173) | B24: 0.728
A25: Tasso di sostituzione LORDO tabellato, vecchiaia 2060 (Tab. 6.1, p. 166) | B25: 0.676
A26: Anzianita' contributiva RGS della riga Vecchiaia (39 anni e 8 mesi) | B26: 39.6667
A27: Tasso di sostituzione NETTO tabellato, anticipato 2060 (Tab. 6.3) | B27: 0.63
A28: Tasso di sostituzione LORDO tabellato, anticipato 2060 (Tab. 6.1) | B28: 0.571
A29: Anzianita' RGS della riga Pensionamento anticipato (36 anni e 11 mesi) | B29: 36.9167
A30: Eta' di vecchiaia proiettata per la coorte (69 anni e 8 mesi) | B30: 69.7
A31: Anticipata contributiva — anni sotto la vecchiaia / finestra (anni) | B31: 3 | C31: 0.25
A32: Assegno sociale 2026 (€/mese, valore provvisorio) | B32: 546.24
A33: Soglia di importo — moltiplicatore fino al 2029 / dal 2030 / anno del salto | B33: 3 | C33: 3.2 | D33: 2030
A34: Mensilita' della pensione ai fini della soglia di importo | B34: 13
A35: Via della previdenza complementare — anni di contributi in piu' dal 2025 / dal 2030 | B35: 5 | C35: 5
A36: Requisito della pensione anticipata ordinaria al 2060 (45 anni e 9 mesi) | B36: 45.75
A38: Fiscalita' finanziaria e costi
A39: Imposta sostitutiva sulle plusvalenze | B39: 0.26
A40: Imposta di bollo — aliquota ordinaria | B40: 0.002
A41: TER dell'ETF azionario globale (ipotesi di canale) | B41: 0.002
A43: Mercato — rendimenti REALI LORDI, con la finestra dichiarata
A44: Azionario mondiale, storico realizzato 1900-2024 | B44: 0.052
...

Sheet 2-Cruscotto
A1: I due verdetti, affiancati
A2: Strumento informativo / divulgativo. NON è consulenza finanziaria. I valori sono indicativi al 2026 e vanno verificati col tuo consulente.
A4: VERDETTO A — sul numero che si e' dato
A5: Capitale necessario oggi, al tasso del coast e sulla porta lunga | B5: ='1-Input'!$B$10/(1+'1-Input'!$B$11)^('P-Parametri'!$B$30-'1-Input'!$B$5) -> 259303.77
A6: Capitale attuale | B6: ='1-Input'!$B$8 -> 180000
A7: IL GAP, al tasso del coast e sulla porta lunga | B7: =B5-B6 -> 79303.77
A8: Il gap in percentuale di quel che servirebbe | B8: =B7/B5 -> 0.30583346
A9: LA BANDA DEL GAP — dal minimo al massimo delle quattro letture | B9: ='3-Griglia'!$B$43 -> 79303.77 | C9: ='3-Griglia'!$C$43 -> 131129.12
A10: La lettura al pavimento prudente, porta lunga | B10: ='3-Griglia'!$B$40 -> 106839.06 | F10: il gap non va mai detto senza il tasso accanto: e' una banda, non un numero
A11: Tasso di pareggio, porta lunga / porta breve | B11: ='3-Griglia'!$B$44 -> 0.043924504 | C11: ='3-Griglia'!$B$45 -> 0.04779417
A12: Rendimento reale netto storico dell'azionario mondiale | B12: ='1-Input'!$B$32 -> 0.047796208
A13: Versamento annuo per chiudere il buco, sul numero di anni scelto | B13: ='8-Fabbisogno'!$B$65 -> 9439.7144
A14: VERDETTO A | B14: =IF(B7<=0,"SI' — il capitale attuale basta","NO — al canone di questo canale il capitale attuale non basta") -> NO — al canone di questo canale il capitale attuale non basta
A16: VERDETTO B — sul fabbisogno che resta dopo la pensione
A17: Pensione netta proiettata, chiusura adottata | B17: ='5-Caso'!$D$19 -> 24323.385
A18: La stessa, al mese | B18: =B17/12 -> 2026.9487
A19: Spesa del caso, €/anno e €/mese | B19: ='5-Caso'!$B$55 -> 15190.393 | C19: ='5-Caso'!$B$55/12 -> 1265.8661
A20: COPERTURA DELLA PENSIONE SULLA SPESA DEL CASO | B20: =B17/'5-Caso'!$B$55 -> 1.6012348 | F20: il denominatore e' un dato del caso, non un aggregato nazionale
A21: Copertura sulla spesa media ISTAT — banda, dal basso all'alto | B21: ='7-Denominatori'!$B$33 -> 1.0025867 | C21: ='7-Denominatori'!$C$33 -> 1.1664009
A22: Capitale coast necessario oggi per la spesa attesa del foglio 1 | B22: ='8-Fabbisogno'!$D$20 -> 40484.001
A23: Il capitale attuale copre il fabbisogno residuo? | B23: =IF(B22<=0,"SI' — la pensione da sola copre quella spesa",IF(B6>=B22,"SI'","NO")) -> SI'
A24: Semaforo — copre al tasso del coast, al pavimento e allo stress? | B24: =IF(AND('1-Input'!$B$8>=MAX(0,'8-Fabbisogno'!$C$20)/(1+'1-Input'!$B$12)^'1-Input'!$B$35,'1-Input'!$B$8>=MAX(0,'8-Fabbisogno'!$C$20)/(1+'P-Parametri'!$B$51)^'1-Input'!$B$35),"VERDE — copre anche nelle letture prudenti",IF('1-Input'!$B$8>=B22,"GIALLO — copre solo al tasso del coast","ROSSO — non copre")) -> VERDE — copre anche nelle letture prudenti
A26: IL MONTANTE, E QUANTO COSTA TENERLO FERMO
A27: Montante alla pensione, coast puro | B27: ='1-Input'!$B$8*(1+'1-Input'!$B$11)^'1-Input'!$B$35 -> 555333.23
A28: Montante al pavimento prudente | B28: ='1-Input'!$B$8*(1+'1-Input'!$B$12)^'1-Input'!$B$35 -> 502023.68
A29: Bollo cumulato su tutto l'orizzonte | B29: ='4-Traiettoria'!$B$46 -> 23541.206
A30: Bollo del primo anno | B30: ='4-Traiettoria'!$B$44 -> 372.62525
A31: Banda al 90% del rendimento annualizzato (pavimento) — basso / alto | B31: ='4-Traiettoria'!$B$60 -> -0.018851634 | C31: ='4-Traiettoria'!$B$61 -> 0.081283969
A32: L'ordine dei rendimenti conta? Scarto fra i tre ordini | B32: ='9-Ordine'!$B$45 -> 0
A34: COME LEGGERE QUESTO FOGLIO. Il verdetto A e il verdetto B rispondono a due domande diverse. Il primo dice se il capitale basta all'obiettivo che il risparmiatore si e' dato; il secondo dice quanto capitale serve DAVVERO, cioe' oltre a cio' che gia' esiste — e cio' che gia' esiste, in Italia, e' una pensione pubblica obbligatoria che nessun calcolatore americano mette nel conto. La pensione e' la ragione per cui il numero da raggiungere e' molto piu' piccolo di quello dei calcolatori, non la ragione per cui non serve raggiungerlo.
A35: Ogni numero di questo foglio e' una formula che ricalcola dagli input gialli del foglio 1 e dai parametri del foglio P. Cambia lo stato abitativo, la chiusura sull'anzianita', il tasso o l'eta' di ingresso e guarda dove va il verdetto: e' il modo per vedere quanta parte del risultato e' un dato e quanta e' un'ipotesi.

Sheet 3-Griglia
A1: Capitale necessario oggi, e il gap: tasso × anni mancanti
A2: Strumento informativo / divulgativo. NON è consulenza finanziaria. I valori sono indicativi al 2026 e vanno verificati col tuo consulente.
A4: GRIGLIA A — capitale necessario oggi per l'obiettivo dichiarato
A5: Rendimento reale netto \ anni mancanti | B5: 10 | C5: 20 | D5: 25 | E5: porta breve | F5: 32 (il draft) | G5: porta lunga | H5: 35 | I5: Nota
A6: 2,31% — prelievo sicuro Anarkulova (stress) | B6: ='1-Input'!$B$10/(1+'P-Parametri'!$B$51)^(10) -> 636662.31 | C6: ='1-Input'!$B$10/(1+'P-Parametri'!$B$51)^(20) -> 506673.62 | D6: ='1-Input'!$B$10/(1+'P-Parametri'!$B$51)^(25) -> 451999.41 | E6: ='1-Input'!$B$10/(1+'P-Parametri'!$B$51)^('1-Input'!$B$33-'1-Input'!$B$5) -> 385662.3 | F6: ='1-Input'!$B$10/(1+'P-Parametri'!$B$51)^(32) -> 385222.17 | G6: ='1-Input'!$B$10/(1+'P-Parametri'!$B$51)^('P-Parametri'!$B$30-'1-Input'!$B$5) -> 362186.66 | H6: ='1-Input'!$B$10/(1+'P-Parametri'!$B$51)^(35) -> 359713.74
A7: 3,00% — pavimento prudente, convenzione di canale | B7: ='1-Input'!$B$10/(1+'1-Input'!$B$12)^(10) -> 595275.13 | C7: ='1-Input'!$B$10/(1+'1-Input'!$B$12)^(20) -> 442940.6 | D7: ='1-Input'!$B$10/(1+'1-Input'!$B$12)^(25) -> 382084.46 | E7: ='1-Input'!$B$10/(1+'1-Input'!$B$12)^('1-Input'!$B$33-'1-Input'!$B$5) -> 311129.12 | F7: ='1-Input'!$B$10/(1+'1-Input'!$B$12)^(32) -> 310669.63 | G7: ='1-Input'!$B$10/(1+'1-Input'!$B$12)^('P-Parametri'!$B$30-'1-Input'!$B$5) -> 286839.06 | H7: ='1-Input'!$B$10/(1+'1-Input'!$B$12)^(35) -> 284306.72
A8: 3,30% — IL TASSO DEL COAST (100% azionario globale) | B8: ='1-Input'!$B$10/(1+'1-Input'!$B$11)^(10) -> 578211.56 | C8: ='1-Input'!$B$10/(1+'1-Input'!$B$11)^(20) -> 417910.76 | D8: ='1-Input'!$B$10/(1+'1-Input'!$B$11)^(25) -> 355289.15 | E8: ='1-Input'!$B$10/(1+'1-Input'!$B$11)^('1-Input'!$B$33-'1-Input'!$B$5) -> 283520.66 | F8: ='1-Input'!$B$10/(1+'1-Input'!$B$11)^(32) -> 283060.78 | G8: ='1-Input'!$B$10/(1+'1-Input'!$B$11)^('P-Parametri'!$B$30-'1-Input'!$B$5) -> 259303.77 | H8: ='1-Input'!$B$10/(1+'1-Input'!$B$11)^(35) -> 256790.37
A9: 4,00% | B9: ='1-Input'!$B$10/(1+0.04)^(10) -> 540451.34 | C9: ='1-Input'!$B$10/(1+0.04)^(20) -> 365109.56 | D9: ='1-Input'!$B$10/(1+0.04)^(25) -> 300093.44 | E9: ='1-Input'!$B$10/(1+0.04)^('1-Input'!$B$33-'1-Input'!$B$5) -> 228494 | F9: ='1-Input'!$B$10/(1+0.04)^(32) -> 228046.35 | G9: ='1-Input'!$B$10/(1+0.04)^('P-Parametri'!$B$30-'1-Input'!$B$5) -> 205131.86 | H9: ='1-Input'!$B$10/(1+0.04)^(35) -> 202732.38
A10: 4,78% — storico realizzato mondiale, al netto | B10: ='1-Input'!$B$10/(1+'1-Input'!$B$32)^(10) -> 501558.69 | C10: ='1-Input'!$B$10/(1+'1-Input'!$B$32)^(20) -> 314451.4 | D10: ='1-Input'!$B$10/(1+'1-Input'!$B$32)^(25) -> 248982.85 | E10: ='1-Input'!$B$10/(1+'1-Input'!$B$32)^('1-Input'!$B$33-'1-Input'!$B$5) -> 179988.81 | F10: ='1-Input'!$B$10/(1+'1-Input'!$B$32)^(32) -> 179569.13 | G10: ='1-Input'!$B$10/(1+'1-Input'!$B$32)^('P-Parametri'!$B$30-'1-Input'!$B$5) -> 158301.22 | H10: ='1-Input'!$B$10/(1+'1-Input'!$B$32)^(35) -> 156099.39
A11: 5,00% — il «prudente» dei calcolatori | B11: ='1-Input'!$B$10/(1+0.05)^(10) -> 491130.6 | C11: ='1-Input'!$B$10/(1+0.05)^(20) -> 301511.59 | D11: ='1-Input'!$B$10/(1+0.05)^(25) -> 236242.22 | E11: ='1-Input'!$B$10/(1+0.05)^('1-Input'!$B$33-'1-Input'!$B$5) -> 168303.01 | F11: ='1-Input'!$B$10/(1+0.05)^(32) -> 167892.93 | G11: ='1-Input'!$B$10/(1+0.05)^('P-Parametri'!$B$30-'1-Input'!$B$5) -> 147170.68 | H11: ='1-Input'!$B$10/(1+0.05)^(35) -> 145032.23
A12: 7,00% — l'«ottimista» dei calcolatori | B12: ='1-Input'!$B$10/(1+0.07)^(10) -> 406679.43 | C12: ='1-Input'!$B$10/(1+0.07)^(20) -> 206735.2 | D12: ='1-Input'!$B$10/(1+0.07)^(25) -> 147399.34 | E12: ='1-Input'!$B$10/(1+0.07)^('1-Input'!$B$33-'1-Input'!$B$5) -> 92103.957 | F12: ='1-Input'!$B$10/(1+0.07)^(32) -> 91792.902 | G12: ='1-Input'!$B$10/(1+0.07)^('P-Parametri'!$B$30-'1-Input'!$B$5) -> 76466.797 | H12: ='1-Input'!$B$10/(1+0.07)^(35) -> 74930.351
A14: Le colonne «porta breve» e «porta lunga» sono la banda dell'orizzonte: per chi ha 35 anni oggi nessuna delle due porte e' a 67 anni.
A16: GRIGLIA B — il gap: quanto manca al capitale di oggi
A17: Rendimento reale netto \ anni mancanti | B17: 10 | C17: 20 | D17: 25 | E17: porta breve | F17: 32 (il draft) | G17: porta lunga | H17: 35
A18: 2,31% — prelievo sicuro Anarkulova (stress) | B18: ='1-Input'!$B$10/(1+'P-Parametri'!$B$51)^(10)-'1-Input'!$B$8 -> 456662.31 | C18: ='1-Input'!$B$10/(1+'P-Parametri'!$B$51)^(20)-'1-Input'!$B$8 -> 326673.62 | D18: ='1-Input'!$B$10/(1+'P-Parametri'!$B$51)^(25)-'1-Input'!$B$8 -> 271999.41 | E18: ='1-Input'!$B$10/(1+'P-Parametri'!$B$51)^('1-Input'!$B$33-'1-Input'!$B$5)-'1-Input'!$B$8 -> 205662.3 | F18: ='1-Input'!$B$10/(1+'P-Parametri'!$B$51)^(32)-'1-Input'!$B$8 -> 205222.17 | G18: ='1-Input'!$B$10/(1+'P-Parametri'!$B$51)^('P-Parametri'!$B$30-'1-Input'!$B$5)-'1-Input'!$B$8 -> 182186.66 | H18: ='1-Input'!$B$10/(1+'P-Parametri'!$B$51)^(35)-'1-Input'!$B$8 -> 179713.74
A19: 3,00% — pavimento prudente, convenzione di canale | B19: ='1-Input'!$B$10/(1+'1-Input'!$B$12)^(10)-'1-Input'!$B$8 -> 415275.13 | C19: ='1-Input'!$B$10/(1+'1-Input'!$B$12)^(20)-'1-Input'!$B$8 -> 262940.6 | D19: ='1-Input'!$B$10/(1+'1-Input'!$B$12)^(25)-'1-Input'!$B$8 -> 202084.46 | E19: ='1-Input'!$B$10/(1+'1-Input'!$B$12)^('1-Input'!$B$33-'1-Input'!$B$5)-'1-Input'!$B$8 -> 131129.12 | F19: ='1-Input'!$B$10/(1+'1-Input'!$B$12)^(32)-'1-Input'!$B$8 -> 130669.63 | G19: ='1-Input'!$B$10/(1+'1-Input'!$B$12)^('P-Parametri'!$B$30-'1-Input'!$B$5)-'1-Input'!$B$8 -> 106839.06 | H19: ='1-Input'!$B$10/(1+'1-Input'!$B$12)^(35)-'1-Input'!$B$8 -> 104306.72
A20: 3,30% — IL TASSO DEL COAST (100% azionario globale) | B20: ='1-Input'!$B$10/(1+'1-Input'!$B$11)^(10)-'1-Input'!$B$8 -> 398211.56 | C20: ='1-Input'!$B$10/(1+'1-Input'!$B$11)^(20)-'1-Input'!$B$8 -> 237910.76 | D20: ='1-Input'!$B$10/(1+'1-Input'!$B$11)^(25)-'1-Input'!$B$8 -> 175289.15 | E20: ='1-Input'!$B$10/(1+'1-Input'!$B$11)^('1-Input'!$B$33-'1-Input'!$B$5)-'1-Input'!$B$8 -> 103520.66 | F20: ='1-Input'!$B$10/(1+'1-Input'!$B$11)^(32)-'1-Input'!$B$8 -> 103060.78 | G20: ='1-Input'!$B$10/(1+'1-Input'!$B$11)^('P-Parametri'!$B$30-'1-Input'!$B$5)-'1-Input'!$B$8 -> 79303.77 | H20: ='1-Input'!$B$10/(1+'1-Input'!$B$11)^(35)-'1-Input'!$B$8 -> 76790.37
A21: 4,00% | B21: ='1-Input'!$B$10/(1+0.04)^(10)-'1-Input'!$B$8 -> 360451.34 | C21: ='1-Input'!$B$10/(1+0.04)^(20)-'1-Input'!$B$8 -> 185109.56 | D21: ='1-Input'!$B$10/(1+0.04)^(25)-'1-Input'!$B$8 -> 120093.44 | E21: ='1-Input'!$B$10/(1+0.04)^('1-Input'!$B$33-'1-Input'!$B$5)-'1-Input'!$B$8 -> 48493.998 | F21: ='1-Input'!$B$10/(1+0.04)^(32)-'1-Input'!$B$8 -> 48046.352 | G21: ='1-Input'!$B$10/(1+0.04)^('P-Parametri'!$B$30-'1-Input'!$B$5)-'1-Input'!$B$8 -> 25131.858 | H21: ='1-Input'!$B$10/(1+0.04)^(35)-'1-Input'!$B$8 -> 22732.377
A22: 4,78% — storico realizzato mondiale, al netto | B22: ='1-Input'!$B$10/(1+'1-Input'!$B$32)^(10)-'1-Input'!$B$8 -> 321558.69 | C22: ='1-Input'!$B$10/(1+'1-Input'!$B$32)^(20)-'1-Input'!$B$8 -> 134451.4 | D22: ='1-Input'!$B$10/(1+'1-Input'!$B$32)^(25)-'1-Input'!$B$8 -> 68982.846 | E22: ='1-Input'!$B$10/(1+'1-Input'!$B$32)^('1-Input'!$B$33-'1-Input'!$B$5)-'1-Input'!$B$8 -> -11.187543 | F22: ='1-Input'!$B$10/(1+'1-Input'!$B$32)^(32)-'1-Input'!$B$8 -> -430.87335 | G22: ='1-Input'!$B$10/(1+'1-Input'!$B$32)^('P-Parametri'!$B$30-'1-Input'!$B$5)-'1-Input'!$B$8 -> -21698.784 | H22: ='1-Input'!$B$10/(1+'1-Input'!$B$32)^(35)-'1-Input'!$B$8 -> -23900.611
A23: 5,00% — il «prudente» dei calcolatori | B23: ='1-Input'!$B$10/(1+0.05)^(10)-'1-Input'!$B$8 -> 311130.6 | C23: ='1-Input'!$B$10/(1+0.05)^(20)-'1-Input'!$B$8 -> 121511.59 | D23: ='1-Input'!$B$10/(1+0.05)^(25)-'1-Input'!$B$8 -> 56242.217 | E23: ='1-Input'!$B$10/(1+0.05)^('1-Input'!$B$33-'1-Input'!$B$5)-'1-Input'!$B$8 -> -11696.991 | F23: ='1-Input'!$B$10/(1+0.05)^(32)-'1-Input'!$B$8 -> -12107.067 | G23: ='1-Input'!$B$10/(1+0.05)^('P-Parametri'!$B$30-'1-Input'!$B$5)-'1-Input'!$B$8 -> -32829.316 | H23: ='1-Input'!$B$10/(1+0.05)^(35)-'1-Input'!$B$8 -> -34967.772
A24: 7,00% — l'«ottimista» dei calcolatori | B24: ='1-Input'!$B$10/(1+0.07)^(10)-'1-Input'!$B$8 -> 226679.43 | C24: ='1-Input'!$B$10/(1+0.07)^(20)-'1-Input'!$B$8 -> 26735.202 | D24: ='1-Input'!$B$10/(1+0.07)^(25)-'1-Input'!$B$8 -> -32600.658 | E24: ='1-Input'!$B$10/(1+0.07)^('1-Input'!$B$33-'1-Input'!$B$5)-'1-Input'!$B$8 -> -87896.043 | F24: ='1-Input'!$B$10/(1+0.07)^(32)-'1-Input'!$B$8 -> -88207.098 | G24: ='1-Input'!$B$10/(1+0.07)^('P-Parametri'!$B$30-'1-Input'!$B$5)-'1-Input'!$B$8 -> -103533.2 | H24: ='1-Input'!$B$10/(1+0.07)^(35)-'1-Input'!$B$8 -> -105069.65
A27: GRIGLIA C — il gap in percentuale del capitale che servirebbe
A28: Rendimento reale netto \ anni mancanti | B28: 10 | C28: 20 | D28: 25 | E28: porta breve | F28: 32 (il draft) | G28: porta lunga | H28: 35
A29: 2,31% — prelievo sicuro Anarkulova (stress) | B29: =1-'1-Input'!$B$8/('1-Input'!$B$10/(1+'P-Parametri'!$B$51)^(10)) -> 0.71727555 | C29: =1-'1-Input'!$B$8/('1-Input'!$B$10/(1+'P-Parametri'!$B$51)^(20)) -> 0.64474172 | D29: =1-'1-Input'!$B$8/('1-Input'!$B$10/(1+'P-Parametri'!$B$51)^(25)) -> 0.60176939 | E29: =1-'1-Input'!$B$8/('1-Input'!$B$10/(1+'P-Parametri'!$B$51)^('1-Input'!$B$33-'1-Input'!$B$5)) -> 0.53327042 | F29: =1-'1-Input'!$B$8/('1-Input'!$B$10/(1+'P-Parametri'!$B$51)^(32)) -> 0.53273718 | G29: =1-'1-Input'!$B$8/('1-Input'!$B$10/(1+'P-Parametri'!$B$51)^('P-Parametri'!$B$30-'1-Input'!$B$5)) -> 0.50301869 | H29: =1-'1-Input'!$B$8/('1-Input'!$B$10/(1+'P-Parametri'!$B$51)^(35)) -> 0.4996021
A30: 3,00% — pavimento prudente, convenzione di canale | B30: =1-'1-Input'!$B$8/('1-Input'!$B$10/(1+'1-Input'!$B$12)^(10)) -> 0.69761881 | C30: =1-'1-Input'!$B$8/('1-Input'!$B$10/(1+'1-Input'!$B$12)^(20)) -> 0.59362497 | D30: =1-'1-Input'!$B$8/('1-Input'!$B$10/(1+'1-Input'!$B$12)^(25)) -> 0.52889997 | E30: =1-'1-Input'!$B$8/('1-Input'!$B$10/(1+'1-Input'!$B$12)^('1-Input'!$B$33-'1-Input'!$B$5)) -> 0.42146206 | F30: =1-'1-Input'!$B$8/('1-Input'!$B$10/(1+'1-Input'!$B$12)^(32)) -> 0.42060638 | G30: =1-'1-Input'!$B$8/('1-Input'!$B$10/(1+'1-Input'!$B$12)^('P-Parametri'!$B$30-'1-Input'!$B$5)) -> 0.3724704 | H30: =1-'1-Input'!$B$8/('1-Input'!$B$10/(1+'1-Input'!$B$12)^(35)) -> 0.36688095
A31: 3,30% — IL TASSO DEL COAST (100% azionario globale) | B31: =1-'1-Input'!$B$8/('1-Input'!$B$10/(1+'1-Input'!$B$11)^(10)) -> 0.68869526 | C31: =1-'1-Input'!$B$8/('1-Input'!$B$10/(1+'1-Input'!$B$11)^(20)) -> 0.56928604 | D31: =1-'1-Input'!$B$8/('1-Input'!$B$10/(1+'1-Input'!$B$11)^(25)) -> 0.4933704 | E31: =1-'1-Input'!$B$8/('1-Input'!$B$10/(1+'1-Input'!$B$11)^('1-Input'!$B$33-'1-Input'!$B$5)) -> 0.36512564 | F31: =1-'1-Input'!$B$8/('1-Input'!$B$10/(1+'1-Input'!$B$11)^(32)) -> 0.36409417 | G31: =1-'1-Input'!$B$8/('1-Input'!$B$10/(1+'1-Input'!$B$11)^('P-Parametri'!$B$30-'1-Input'!$B$5)) -> 0.30583346 | H31: =1-'1-Input'!$B$8/('1-Input'!$B$10/(1+'1-Input'!$B$11)^(35)) -> 0.29903914
A32: 4,00% | B32: =1-'1-Input'!$B$8/('1-Input'!$B$10/(1+0.04)^(10)) -> 0.66694504 | C32: =1-'1-Input'!$B$8/('1-Input'!$B$10/(1+0.04)^(20)) -> 0.50699729 | D32: =1-'1-Input'!$B$8/('1-Input'!$B$10/(1+0.04)^(25)) -> 0.40018683 | E32: =1-'1-Input'!$B$8/('1-Input'!$B$10/(1+0.04)^('1-Input'!$B$33-'1-Input'!$B$5)) -> 0.21223314 | F32: =1-'1-Input'!$B$8/('1-Input'!$B$10/(1+0.04)^(32)) -> 0.21068678 | G32: =1-'1-Input'!$B$8/('1-Input'!$B$10/(1+0.04)^('P-Parametri'!$B$30-'1-Input'!$B$5)) -> 0.12251563 | H32: =1-'1-Input'!$B$8/('1-Input'!$B$10/(1+0.04)^(35)) -> 0.11212998
A33: 4,78% — storico realizzato mondiale, al netto | B33: =1-'1-Input'!$B$8/('1-Input'!$B$10/(1+'1-Input'!$B$32)^(10)) -> 0.64111877 | C33: =1-'1-Input'!$B$8/('1-Input'!$B$10/(1+'1-Input'!$B$32)^(20)) -> 0.42757451 | D33: =1-'1-Input'!$B$8/('1-Input'!$B$10/(1+'1-Input'!$B$32)^(25)) -> 0.27705863 | E33: =1-'1-Input'!$B$8/('1-Input'!$B$10/(1+'1-Input'!$B$32)^('1-Input'!$B$33-'1-Input'!$B$5)) -> -6.2156879e-05 | F33: =1-'1-Input'!$B$8/('1-Input'!$B$10/(1+'1-Input'!$B$32)^(32)) -> -0.0023994846 | G33: =1-'1-Input'!$B$8/('1-Input'!$B$10/(1+'1-Input'!$B$32)^('P-Parametri'!$B$30-'1-Input'!$B$5)) -> -0.13707276 | H33: =1-'1-Input'!$B$8/('1-Input'!$B$10/(1+'1-Input'!$B$32)^(35)) -> -0.1531115
A34: 5,00% — il «prudente» dei calcolatori | B34: =1-'1-Input'!$B$8/('1-Input'!$B$10/(1+0.05)^(10)) -> 0.63349871 | C34: =1-'1-Input'!$B$8/('1-Input'!$B$10/(1+0.05)^(20)) -> 0.40300802 | D34: =1-'1-Input'!$B$8/('1-Input'!$B$10/(1+0.05)^(25)) -> 0.23807014 | E34: =1-'1-Input'!$B$8/('1-Input'!$B$10/(1+0.05)^('1-Input'!$B$33-'1-Input'!$B$5)) -> -0.069499592 | F34: =1-'1-Input'!$B$8/('1-Input'!$B$10/(1+0.05)^(32)) -> -0.07211183 | G34: =1-'1-Input'!$B$8/('1-Input'!$B$10/(1+0.05)^('P-Parametri'!$B$30-'1-Input'!$B$5)) -> -0.22306967 | H34: =1-'1-Input'!$B$8/('1-Input'!$B$10/(1+0.05)^(35)) -> -0.24110346
A35: 7,00% — l'«ottimista» dei calcolatori | B35: =1-'1-Input'!$B$8/('1-Input'!$B$10/(1+0.07)^(10)) -> 0.55739094 | C35: =1-'1-Input'!$B$8/('1-Input'!$B$10/(1+0.07)^(20)) -> 0.129321 | D35: =1-'1-Input'!$B$8/('1-Input'!$B$10/(1+0.07)^(25)) -> -0.22117234 | E35: =1-'1-Input'!$B$8/('1-Input'!$B$10/(1+0.07)^('1-Input'!$B$33-'1-Input'!$B$5)) -> -0.95431342 | F35: =1-'1-Input'!$B$8/('1-Input'!$B$10/(1+0.07)^(32)) -> -0.96093593 | G35: =1-'1-Input'!$B$8/('1-Input'!$B$10/(1+0.07)^('P-Parametri'!$B$30-'1-Input'!$B$5)) -> -1.3539628 | H35: =1-'1-Input'!$B$8/('1-Input'!$B$10/(1+0.07)^(35)) -> -1.4022308
A38: LA BANDA DEL GAP, E IL TASSO DI PAREGGIO
A39: Gap al tasso del coast, porta lunga | B39: ='1-Input'!$B$10/(1+'1-Input'!$B$11)^('P-Parametri'!$B$30-'1-Input'!$B$5)-'1-Input'!$B$8 -> 79303.77
A40: Gap al pavimento prudente, porta lunga | B40: ='1-Input'!$B$10/(1+'1-Input'!$B$12)^('P-Parametri'!$B$30-'1-Input'!$B$5)-'1-Input'!$B$8 -> 106839.06
A41: Gap al tasso del coast, porta breve | B41: ='1-Input'!$B$10/(1+'1-Input'!$B$11)^('1-Input'!$B$33-'1-Input'!$B$5)-'1-Input'!$B$8 -> 103520.66
A42: Gap al pavimento prudente, porta breve | B42: ='1-Input'!$B$10/(1+'1-Input'!$B$12)^('1-Input'!$B$33-'1-Input'!$B$5)-'1-Input'!$B$8 -> 131129.12
A43: LA BANDA DEL GAP — minimo / massimo | B43: =MIN(B39:B42) -> 79303.77 | C43: =MAX(B39:B42) -> 131129.12
A44: Tasso di pareggio sulla porta lunga (senza versare piu' nulla) | B44: =('1-Input'!$B$10/'1-Input'!$B$8)^(1/('P-Parametri'!$B$30-'1-Input'!$B$5))-1 -> 0.043924504
A45: Tasso di pareggio sulla porta breve | B45: =('1-Input'!$B$10/'1-Input'!$B$8)^(1/('1-Input'!$B$33-'1-Input'!$B$5))-1 -> 0.04779417
A46: Rendimento reale netto storico dell'azionario mondiale, per confronto | B46: ='1-Input'!$B$32 -> 0.047796208
A47: Margine sulla porta lunga / sulla porta breve, in punti base | B47: =(B46-B44)*10000 -> 38.717044 | C47: =(B46-B45)*10000 -> 0.020383616
...

Sheet 4-Traiettoria
A1: Anno per anno: quanto costa tenere fermo il capitale
A2: Strumento informativo / divulgativo. NON è consulenza finanziaria. I valori sono indicativi al 2026 e vanno verificati col tuo consulente.
A4: TRAIETTORIA DEL COAST PURO — nessun versamento, nessun prelievo
A5: Anno | B5: Eta' | C5: Quota di anno | D5: Patrimonio a inizio anno | E5: Rendimento lordo | F5: Costo TER | G5: Bollo dell'anno | H5: Bollo cumulato | I5: Patrimonio a fine anno
A6: ='P-Parametri'!$B$68+0 -> 2026 | B6: ='1-Input'!$B$5+0 -> 35 | C6: =MAX(0,MIN(1,'1-Input'!$B$35-0)) -> 1 | D6: ='1-Input'!$B$8 -> 180000 | E6: =D6*((1+'1-Input'!$B$30)^C6-1) -> 6685.9972 | F6: =(D6+E6)*(1-(1-'P-Parametri'!$B$41)^C6) -> 373.37199 | G6: =(D6+E6-F6)*(1-(1-'1-Input'!$B$22)^C6) -> 372.62525 | H6: =G6 -> 372.62525 | I6: =D6+E6-F6-G6 -> 185940
A7: ='P-Parametri'!$B$68+1 -> 2027 | B7: ='1-Input'!$B$5+1 -> 36 | C7: =MAX(0,MIN(1,'1-Input'!$B$35-1)) -> 1 | D7: =I6 -> 185940 | E7: =D7*((1+'1-Input'!$B$30)^C7-1) -> 6906.6352 | F7: =(D7+E7)*(1-(1-'P-Parametri'!$B$41)^C7) -> 385.69327 | G7: =(D7+E7-F7)*(1-(1-'1-Input'!$B$22)^C7) -> 384.92188 | H7: =H6+G7 -> 757.54713 | I7: =D7+E7-F7-G7 -> 192076.02
A8: ='P-Parametri'!$B$68+2 -> 2028 | B8: ='1-Input'!$B$5+2 -> 37 | C8: =MAX(0,MIN(1,'1-Input'!$B$35-2)) -> 1 | D8: =I7 -> 192076.02 | E8: =D8*((1+'1-Input'!$B$30)^C8-1) -> 7134.5541 | F8: =(D8+E8)*(1-(1-'P-Parametri'!$B$41)^C8) -> 398.42115 | G8: =(D8+E8-F8)*(1-(1-'1-Input'!$B$22)^C8) -> 397.62431 | H8: =H7+G8 -> 1155.1714 | I8: =D8+E8-F8-G8 -> 198414.53
A9: ='P-Parametri'!$B$68+3 -> 2029 | B9: ='1-Input'!$B$5+3 -> 38 | C9: =MAX(0,MIN(1,'1-Input'!$B$35-3)) -> 1 | D9: =I8 -> 198414.53 | E9: =D9*((1+'1-Input'!$B$30)^C9-1) -> 7369.9944 | F9: =(D9+E9)*(1-(1-'P-Parametri'!$B$41)^C9) -> 411.56905 | G9: =(D9+E9-F9)*(1-(1-'1-Input'!$B$22)^C9) -> 410.74591 | H9: =H8+G9 -> 1565.9173 | I9: =D9+E9-F9-G9 -> 204962.21
A10: ='P-Parametri'!$B$68+4 -> 2030 | B10: ='1-Input'!$B$5+4 -> 39 | C10: =MAX(0,MIN(1,'1-Input'!$B$35-4)) -> 1 | D10: =I9 -> 204962.21 | E10: =D10*((1+'1-Input'!$B$30)^C10-1) -> 7613.2042 | F10: =(D10+E10)*(1-(1-'P-Parametri'!$B$41)^C10) -> 425.15082 | G10: =(D10+E10-F10)*(1-(1-'1-Input'!$B$22)^C10) -> 424.30052 | H10: =H9+G10 -> 1990.2179 | I10: =D10+E10-F10-G10 -> 211725.96
A11: ='P-Parametri'!$B$68+5 -> 2031 | B11: ='1-Input'!$B$5+5 -> 40 | C11: =MAX(0,MIN(1,'1-Input'!$B$35-5)) -> 1 | D11: =I10 -> 211725.96 | E11: =D11*((1+'1-Input'!$B$30)^C11-1) -> 7864.44 | F11: =(D11+E11)*(1-(1-'P-Parametri'!$B$41)^C11) -> 439.1808 | G11: =(D11+E11-F11)*(1-(1-'1-Input'!$B$22)^C11) -> 438.30244 | H11: =H10+G11 -> 2428.5203 | I11: =D11+E11-F11-G11 -> 218712.92
A12: ='P-Parametri'!$B$68+6 -> 2032 | B12: ='1-Input'!$B$5+6 -> 41 | C12: =MAX(0,MIN(1,'1-Input'!$B$35-6)) -> 1 | D12: =I11 -> 218712.92 | E12: =D12*((1+'1-Input'!$B$30)^C12-1) -> 8123.9665 | F12: =(D12+E12)*(1-(1-'P-Parametri'!$B$41)^C12) -> 453.67377 | G12: =(D12+E12-F12)*(1-(1-'1-Input'!$B$22)^C12) -> 452.76642 | H12: =H11+G12 -> 2881.2867 | I12: =D12+E12-F12-G12 -> 225930.44
A13: ='P-Parametri'!$B$68+7 -> 2033 | B13: ='1-Input'!$B$5+7 -> 42 | C13: =MAX(0,MIN(1,'1-Input'!$B$35-7)) -> 1 | D13: =I12 -> 225930.44 | E13: =D13*((1+'1-Input'!$B$30)^C13-1) -> 8392.0574 | F13: =(D13+E13)*(1-(1-'P-Parametri'!$B$41)^C13) -> 468.645 | G13: =(D13+E13-F13)*(1-(1-'1-Input'!$B$22)^C13) -> 467.70771 | H13: =H12+G13 -> 3348.9944 | I13: =D13+E13-F13-G13 -> 233386.15
A14: ='P-Parametri'!$B$68+8 -> 2034 | B14: ='1-Input'!$B$5+8 -> 43 | C14: =MAX(0,MIN(1,'1-Input'!$B$35-8)) -> 1 | D14: =I13 -> 233386.15 | E14: =D14*((1+'1-Input'!$B$30)^C14-1) -> 8668.9953 | F14: =(D14+E14)*(1-(1-'P-Parametri'!$B$41)^C14) -> 484.11029 | G14: =(D14+E14-F14)*(1-(1-'1-Input'!$B$22)^C14) -> 483.14207 | H14: =H13+G14 -> 3832.1365 | I14: =D14+E14-F14-G14 -> 241087.89
A15: ='P-Parametri'!$B$68+9 -> 2035 | B15: ='1-Input'!$B$5+9 -> 44 | C15: =MAX(0,MIN(1,'1-Input'!$B$35-9)) -> 1 | D15: =I14 -> 241087.89 | E15: =D15*((1+'1-Input'!$B$30)^C15-1) -> 8955.0721 | F15: =(D15+E15)*(1-(1-'P-Parametri'!$B$41)^C15) -> 500.08593 | G15: =(D15+E15-F15)*(1-(1-'1-Input'!$B$22)^C15) -> 499.08576 | H15: =H14+G15 -> 4331.2223 | I15: =D15+E15-F15-G15 -> 249043.79
A16: ='P-Parametri'!$B$68+10 -> 2036 | B16: ='1-Input'!$B$5+10 -> 45 | C16: =MAX(0,MIN(1,'1-Input'!$B$35-10)) -> 1 | D16: =I15 -> 249043.79 | E16: =D16*((1+'1-Input'!$B$30)^C16-1) -> 9250.5895 | F16: =(D16+E16)*(1-(1-'P-Parametri'!$B$41)^C16) -> 516.58876 | G16: =(D16+E16-F16)*(1-(1-'1-Input'!$B$22)^C16) -> 515.55559 | H16: =H15+G16 -> 4846.7779 | I16: =D16+E16-F16-G16 -> 257262.24
A17: ='P-Parametri'!$B$68+11 -> 2037 | B17: ='1-Input'!$B$5+11 -> 46 | C17: =MAX(0,MIN(1,'1-Input'!$B$35-11)) -> 1 | D17: =I16 -> 257262.24 | E17: =D17*((1+'1-Input'!$B$30)^C17-1) -> 9555.8589 | F17: =(D17+E17)*(1-(1-'P-Parametri'!$B$41)^C17) -> 533.63619 | G17: =(D17+E17-F17)*(1-(1-'1-Input'!$B$22)^C17) -> 532.56892 | H17: =H16+G17 -> 5379.3468 | I17: =D17+E17-F17-G17 -> 265751.89
A18: ='P-Parametri'!$B$68+12 -> 2038 | B18: ='1-Input'!$B$5+12 -> 47 | C18: =MAX(0,MIN(1,'1-Input'!$B$35-12)) -> 1 | D18: =I17 -> 265751.89 | E18: =D18*((1+'1-Input'!$B$30)^C18-1) -> 9871.2023 | F18: =(D18+E18)*(1-(1-'P-Parametri'!$B$41)^C18) -> 551.24619 | G18: =(D18+E18-F18)*(1-(1-'1-Input'!$B$22)^C18) -> 550.14369 | H18: =H17+G18 -> 5929.4905 | I18: =D18+E18-F18-G18 -> 274521.7
A19: ='P-Parametri'!$B$68+13 -> 2039 | B19: ='1-Input'!$B$5+13 -> 48 | C19: =MAX(0,MIN(1,'1-Input'!$B$35-13)) -> 1 | D19: =I18 -> 274521.7 | E19: =D19*((1+'1-Input'!$B$30)^C19-1) -> 10196.952 | F19: =(D19+E19)*(1-(1-'P-Parametri'!$B$41)^C19) -> 569.43731 | G19: =(D19+E19-F19)*(1-(1-'1-Input'!$B$22)^C19) -> 568.29844 | H19: =H18+G19 -> 6497.7889 | I19: =D19+E19-F19-G19 -> 283580.92
A20: ='P-Parametri'!$B$68+14 -> 2040 | B20: ='1-Input'!$B$5+14 -> 49 | C20: =MAX(0,MIN(1,'1-Input'!$B$35-14)) -> 1 | D20: =I19 -> 283580.92 | E20: =D20*((1+'1-Input'!$B$30)^C20-1) -> 10533.451 | F20: =(D20+E20)*(1-(1-'P-Parametri'!$B$41)^C20) -> 588.22874 | G20: =(D20+E20-F20)*(1-(1-'1-Input'!$B$22)^C20) -> 587.05228 | H20: =H19+G20 -> 7084.8412 | I20: =D20+E20-F20-G20 -> 292939.09
A21: ='P-Parametri'!$B$68+15 -> 2041 | B21: ='1-Input'!$B$5+15 -> 50 | C21: =MAX(0,MIN(1,'1-Input'!$B$35-15)) -> 1 | D21: =I20 -> 292939.09 | E21: =D21*((1+'1-Input'!$B$30)^C21-1) -> 10881.055 | F21: =(D21+E21)*(1-(1-'P-Parametri'!$B$41)^C21) -> 607.64029 | G21: =(D21+E21-F21)*(1-(1-'1-Input'!$B$22)^C21) -> 606.42501 | H21: =H20+G21 -> 7691.2662 | I21: =D21+E21-F21-G21 -> 302606.08
A22: ='P-Parametri'!$B$68+16 -> 2042 | B22: ='1-Input'!$B$5+16 -> 51 | C22: =MAX(0,MIN(1,'1-Input'!$B$35-16)) -> 1 | D22: =I21 -> 302606.08 | E22: =D22*((1+'1-Input'!$B$30)^C22-1) -> 11240.13 | F22: =(D22+E22)*(1-(1-'P-Parametri'!$B$41)^C22) -> 627.69242 | G22: =(D22+E22-F22)*(1-(1-'1-Input'!$B$22)^C22) -> 626.43703 | H22: =H21+G22 -> 8317.7032 | I22: =D22+E22-F22-G22 -> 312592.08
A23: ='P-Parametri'!$B$68+17 -> 2043 | B23: ='1-Input'!$B$5+17 -> 52 | C23: =MAX(0,MIN(1,'1-Input'!$B$35-17)) -> 1 | D23: =I22 -> 312592.08 | E23: =D23*((1+'1-Input'!$B$30)^C23-1) -> 11611.054 | F23: =(D23+E23)*(1-(1-'P-Parametri'!$B$41)^C23) -> 648.40627 | G23: =(D23+E23-F23)*(1-(1-'1-Input'!$B$22)^C23) -> 647.10946 | H23: =H22+G23 -> 8964.8127 | I23: =D23+E23-F23-G23 -> 322907.62
A24: ='P-Parametri'!$B$68+18 -> 2044 | B24: ='1-Input'!$B$5+18 -> 53 | C24: =MAX(0,MIN(1,'1-Input'!$B$35-18)) -> 1 | D24: =I23 -> 322907.62 | E24: =D24*((1+'1-Input'!$B$30)^C24-1) -> 11994.219 | F24: =(D24+E24)*(1-(1-'P-Parametri'!$B$41)^C24) -> 669.80368 | G24: =(D24+E24-F24)*(1-(1-'1-Input'!$B$22)^C24) -> 668.46407 | H24: =H23+G24 -> 9633.2768 | I24: =D24+E24-F24-G24 -> 333563.57
A25: ='P-Parametri'!$B$68+19 -> 2045 | B25: ='1-Input'!$B$5+19 -> 54 | C25: =MAX(0,MIN(1,'1-Input'!$B$35-19)) -> 1 | D25: =I24 -> 333563.57 | E25: =D25*((1+'1-Input'!$B$30)^C25-1) -> 12390.028 | F25: =(D25+E25)*(1-(1-'P-Parametri'!$B$41)^C25) -> 691.9072 | G25: =(D25+E25-F25)*(1-(1-'1-Input'!$B$22)^C25) -> 690.52338 | H25: =H24+G25 -> 10323.8 | I25: =D25+E25-F25-G25 -> 344571.17
A26: ='P-Parametri'!$B$68+20 -> 2046 | B26: ='1-Input'!$B$5+20 -> 55 | C26: =MAX(0,MIN(1,'1-Input'!$B$35-20)) -> 1 | D26: =I25 -> 344571.17 | E26: =D26*((1+'1-Input'!$B$30)^C26-1) -> 12798.899 | F26: =(D26+E26)*(1-(1-'P-Parametri'!$B$41)^C26) -> 714.74014 | G26: =(D26+E26-F26)*(1-(1-'1-Input'!$B$22)^C26) -> 713.31066 | H26: =H25+G26 -> 11037.111 | I26: =D26+E26-F26-G26 -> 355942.02
A27: ='P-Parametri'!$B$68+21 -> 2047 | B27: ='1-Input'!$B$5+21 -> 56 | C27: =MAX(0,MIN(1,'1-Input'!$B$35-21)) -> 1 | D27: =I26 -> 355942.02 | E27: =D27*((1+'1-Input'!$B$30)^C27-1) -> 13221.263 | F27: =(D27+E27)*(1-(1-'P-Parametri'!$B$41)^C27) -> 738.32656 | G27: =(D27+E27-F27)*(1-(1-'1-Input'!$B$22)^C27) -> 736.84991 | H27: =H26+G27 -> 11773.961 | I27: =D27+E27-F27-G27 -> 367688.1
A28: ='P-Parametri'!$B$68+22 -> 2048 | B28: ='1-Input'!$B$5+22 -> 57 | C28: =MAX(0,MIN(1,'1-Input'!$B$35-22)) -> 1 | D28: =I27 -> 367688.1 | E28: =D28*((1+'1-Input'!$B$30)^C28-1) -> 13657.565 | F28: =(D28+E28)*(1-(1-'P-Parametri'!$B$41)^C28) -> 762.69134 | G28: =(D28+E28-F28)*(1-(1-'1-Input'!$B$22)^C28) -> 761.16595 | H28: =H27+G28 -> 12535.127 | I28: =D28+E28-F28-G28 -> 379821.81
A29: ='P-Parametri'!$B$68+23 -> 2049 | B29: ='1-Input'!$B$5+23 -> 58 | C29: =MAX(0,MIN(1,'1-Input'!$B$35-23)) -> 1 | D29: =I28 -> 379821.81 | E29: =D29*((1+'1-Input'!$B$30)^C29-1) -> 14108.264 | F29: =(D29+E29)*(1-(1-'P-Parametri'!$B$41)^C29) -> 787.86015 | G29: =(D29+E29-F29)*(1-(1-'1-Input'!$B$22)^C29) -> 786.28443 | H29: =H28+G29 -> 13321.411 | I29: =D29+E29-F29-G29 -> 392355.93
A30: ='P-Parametri'!$B$68+24 -> 2050 | B30: ='1-Input'!$B$5+24 -> 59 | C30: =MAX(0,MIN(1,'1-Input'!$B$35-24)) -> 1 | D30: =I29 -> 392355.93 | E30: =D30*((1+'1-Input'!$B$30)^C30-1) -> 14573.837 | F30: =(D30+E30)*(1-(1-'P-Parametri'!$B$41)^C30) -> 813.85954 | G30: =(D30+E30-F30)*(1-(1-'1-Input'!$B$22)^C30) -> 812.23182 | H30: =H29+G30 -> 14133.643 | I30: =D30+E30-F30-G30 -> 405303.68
A31: ='P-Parametri'!$B$68+25 -> 2051 | B31: ='1-Input'!$B$5+25 -> 60 | C31: =MAX(0,MIN(1,'1-Input'!$B$35-25)) -> 1 | D31: =I30 -> 405303.68 | E31: =D31*((1+'1-Input'!$B$30)^C31-1) -> 15054.774 | F31: =(D31+E31)*(1-(1-'P-Parametri'!$B$41)^C31) -> 840.7169 | G31: =(D31+E31-F31)*(1-(1-'1-Input'!$B$22)^C31) -> 839.03547 | H31: =H30+G31 -> 14972.678 | I31: =D31+E31-F31-G31 -> 418678.7
A32: ='P-Parametri'!$B$68+26 -> 2052 | B32: ='1-Input'!$B$5+26 -> 61 | C32: =MAX(0,MIN(1,'1-Input'!$B$35-26)) -> 1 | D32: =I31 -> 418678.7 | E32: =D32*((1+'1-Input'!$B$30)^C32-1) -> 15551.581 | F32: =(D32+E32)*(1-(1-'P-Parametri'!$B$41)^C32) -> 868.46056 | G32: =(D32+E32-F32)*(1-(1-'1-Input'!$B$22)^C32) -> 866.72364 | H32: =H31+G32 -> 15839.402 | I32: =D32+E32-F32-G32 -> 432495.09
A33: ='P-Parametri'!$B$68+27 -> 2053 | B33: ='1-Input'!$B$5+27 -> 62 | C33: =MAX(0,MIN(1,'1-Input'!$B$35-27)) -> 1 | D33: =I32 -> 432495.09 | E33: =D33*((1+'1-Input'!$B$30)^C33-1) -> 16064.783 | F33: =(D33+E33)*(1-(1-'P-Parametri'!$B$41)^C33) -> 897.11976 | G33: =(D33+E33-F33)*(1-(1-'1-Input'!$B$22)^C33) -> 895.32552 | H33: =H32+G33 -> 16734.728 | I33: =D33+E33-F33-G33 -> 446767.43
A34: ='P-Parametri'!$B$68+28 -> 2054 | B34: ='1-Input'!$B$5+28 -> 63 | C34: =MAX(0,MIN(1,'1-Input'!$B$35-28)) -> 1 | D34: =I33 -> 446767.43 | E34: =D34*((1+'1-Input'!$B$30)^C34-1) -> 16594.921 | F34: =(D34+E34)*(1-(1-'P-Parametri'!$B$41)^C34) -> 926.72471 | G34: =(D34+E34-F34)*(1-(1-'1-Input'!$B$22)^C34) -> 924.87126 | H34: =H33+G34 -> 17659.599 | I34: =D34+E34-F34-G34 -> 461510.76
A35: ='P-Parametri'!$B$68+29 -> 2055 | B35: ='1-Input'!$B$5+29 -> 64 | C35: =MAX(0,MIN(1,'1-Input'!$B$35-29)) -> 1 | D35: =I34 -> 461510.76 | E35: =D35*((1+'1-Input'!$B$30)^C35-1) -> 17142.554 | F35: =(D35+E35)*(1-(1-'P-Parametri'!$B$41)^C35) -> 957.30662 | G35: =(D35+E35-F35)*(1-(1-'1-Input'!$B$22)^C35) -> 955.39201 | H35: =H34+G35 -> 18614.991 | I35: =D35+E35-F35-G35 -> 476740.61
A36: ='P-Parametri'!$B$68+30 -> 2056 | B36: ='1-Input'!$B$5+30 -> 65 | C36: =MAX(0,MIN(1,'1-Input'!$B$35-30)) -> 1 | D36: =I35 -> 476740.61 | E36: =D36*((1+'1-Input'!$B$30)^C36-1) -> 17708.258 | F36: =(D36+E36)*(1-(1-'P-Parametri'!$B$41)^C36) -> 988.89774 | G36: =(D36+E36-F36)*(1-(1-'1-Input'!$B$22)^C36) -> 986.91995 | H36: =H35+G36 -> 19601.911 | I36: =D36+E36-F36-G36 -> 492473.05
A37: ='P-Parametri'!$B$68+31 -> 2057 | B37: ='1-Input'!$B$5+31 -> 66 | C37: =MAX(0,MIN(1,'1-Input'!$B$35-31)) -> 1 | D37: =I36 -> 492473.05 | E37: =D37*((1+'1-Input'!$B$30)^C37-1) -> 18292.63 | F37: =(D37+E37)*(1-(1-'P-Parametri'!$B$41)^C37) -> 1021.5314 | G37: =(D37+E37-F37)*(1-(1-'1-Input'!$B$22)^C37) -> 1019.4883 | H37: =H36+G37 -> 20621.399 | I37: =D37+E37-F37-G37 -> 508724.66
A38: ='P-Parametri'!$B$68+32 -> 2058 | B38: ='1-Input'!$B$5+32 -> 67 | C38: =MAX(0,MIN(1,'1-Input'!$B$35-32)) -> 1 | D38: =I37 -> 508724.66 | E38: =D38*((1+'1-Input'!$B$30)^C38-1) -> 18896.287 | F38: =(D38+E38)*(1-(1-'P-Parametri'!$B$41)^C38) -> 1055.2419 | G38: =(D38+E38-F38)*(1-(1-'1-Input'!$B$22)^C38) -> 1053.1314 | H38: =H37+G38 -> 21674.53 | I38: =D38+E38-F38-G38 -> 525512.58
A39: ='P-Parametri'!$B$68+33 -> 2059 | B39: ='1-Input'!$B$5+33 -> 68 | C39: =MAX(0,MIN(1,'1-Input'!$B$35-33)) -> 1 | D39: =I38 -> 525512.58 | E39: =D39*((1+'1-Input'!$B$30)^C39-1) -> 19519.865 | F39: =(D39+E39)*(1-(1-'P-Parametri'!$B$41)^C39) -> 1090.0649 | G39: =(D39+E39-F39)*(1-(1-'1-Input'!$B$22)^C39) -> 1087.8848 | H39: =H38+G39 -> 22762.415 | I39: =D39+E39-F39-G39 -> 542854.49
A40: ='P-Parametri'!$B$68+34 -> 2060 | B40: ='1-Input'!$B$5+34 -> 69 | C40: =MAX(0,MIN(1,'1-Input'!$B$35-34)) -> 0.7 | D40: =I39 -> 542854.49 | E40: =D40*((1+'1-Input'!$B$30)^C40-1) -> 14037.411 | F40: =(D40+E40)*(1-(1-'P-Parametri'!$B$41)^C40) -> 779.88276 | G40: =(D40+E40-F40)*(1-(1-'1-Input'!$B$22)^C40) -> 778.7906 | H40: =H39+G40 -> 23541.206 | I40: =D40+E40-F40-G40 -> 555333.23
A41: ='P-Parametri'!$B$68+35 -> 2061 | B41: ='1-Input'!$B$5+35 -> 70 | C41: =MAX(0,MIN(1,'1-Input'!$B$35-35)) -> 0 | D41: =I40 -> 555333.23 | E41: =D41*((1+'1-Input'!$B$30)^C41-1) -> 0 | F41: =(D41+E41)*(1-(1-'P-Parametri'!$B$41)^C41) -> 0 | G41: =(D41+E41-F41)*(1-(1-'1-Input'!$B$22)^C41) -> 0 | H41: =H40+G41 -> 23541.206 | I41: =D41+E41-F41-G41 -> 555333.23
...

Sheet 5-Caso
A1: Il caso: dal lordo al netto, la pensione in due chiusure, il vincolo aritmetico
A2: Strumento informativo / divulgativo. NON è consulenza finanziaria. I valori sono indicativi al 2026 e vanno verificati col tuo consulente.
A4: IL MOTORE FISCALE — dalla RAL al netto (IRPEF 2026)
A5: Retribuzione lorda annua | B5: ='1-Input'!$B$9 -> 44000
A6: Contributi a carico del lavoratore | B6: =B5*'P-Parametri'!$B$21 -> 4043.6
A7: Imponibile IRPEF | B7: =B5-B6 -> 39956.4
A8: IRPEF lorda | B8: =IF(B7<='P-Parametri'!$B$6,'P-Parametri'!$C$6*B7,IF(B7<='P-Parametri'!$B$7,'P-Parametri'!$B$9+'P-Parametri'!$C$7*(B7-'P-Parametri'!$B$6),'P-Parametri'!$B$10+'P-Parametri'!$C$8*(B7-'P-Parametri'!$B$7))) -> 10385.612
A9: Detrazione per lavoro dipendente (art. 13 c. 1) | B9: =IF(B7<='P-Parametri'!$C$12,'P-Parametri'!$B$12,IF(B7<='P-Parametri'!$B$6,'P-Parametri'!$B$13+'P-Parametri'!$C$13*('P-Parametri'!$B$6-B7)/'P-Parametri'!$D$13,IF(B7<='P-Parametri'!$B$7,'P-Parametri'!$B$14*('P-Parametri'!$B$7-B7)/'P-Parametri'!$C$14,0))) -> 871.96709
A10: Detrazione art. 13 c. 1.1 (+65 € fra 25.000 e 35.000) | B10: =IF(AND(B7>'P-Parametri'!$C$15,B7<='P-Parametri'!$D$15),'P-Parametri'!$B$15,0) -> 0
A11: Ulteriore detrazione L. 207/2024 c. 6 | B11: =IF(B7<='P-Parametri'!$C$16,0,IF(B7<='P-Parametri'!$D$16,'P-Parametri'!$B$16,IF(B7<'P-Parametri'!$E$16,'P-Parametri'!$B$16*('P-Parametri'!$E$16-B7)/('P-Parametri'!$E$16-'P-Parametri'!$D$16),0))) -> 5.45
A12: IRPEF netta | B12: =MAX(0,B8-B9-B10-B11) -> 9508.1949
A13: Addizionali (non dovute se l'IRPEF netta e' zero) | B13: =IF(B12<=0,0,'P-Parametri'!$B$11*B7) -> 799.128
A14: NETTO ANNUO | B14: =B7-B12-B13 -> 29649.077
A15: Netto mensile | B15: =B14/12 -> 2470.7564
A17: LA PENSIONE — DUE CHIUSURE SULL'ANZIANITA', ENTRAMBE COMPATIBILI CON LA FONTE
A18: Chiusura sull'anzianita' | B18: Anzianita' all'uscita | C18: Tasso di sostituzione netto | D18: Pensione netta €/anno | E18: €/mese | F18: Copertura della spesa ISTAT | G18: Copertura della spesa del caso
A19: ADOTTATA (input 11) | B19: ='1-Input'!$B$37 -> 44.7 | C19: =IF('1-Input'!$B$15=1,IF('1-Input'!$B$24=1,'P-Parametri'!$B$24,'P-Parametri'!$B$27)*'1-Input'!$B$37/IF('1-Input'!$B$24=1,'P-Parametri'!$B$26,'P-Parametri'!$B$29),IF('1-Input'!$B$24=1,'P-Parametri'!$B$24,'P-Parametri'!$B$27)) -> 0.82037578 | D19: =B14*C19*'1-Input'!$B$16 -> 24323.385 | E19: =D19/12 -> 2026.9487 | F19: =D19/'7-Denominatori'!$B$6 -> 1.1298047 | G19: =D19/B55 -> 1.6012348
A20: Le quattro chiusure a confronto — la banda del verdetto B
A21: 1) Analista — ingresso a 25, carriera continua, scalatura lineare dell'anzianita' (la scalatura e' dell'analista, non della Ragioneria) | B21: ='P-Parametri'!$B$30-'1-Input'!$B$7 -> 44.7 | C21: ='P-Parametri'!$B$24*B21/'P-Parametri'!$B$26 -> 0.82037578 | D21: =B14*C21 -> 24323.385 | E21: =D21/12 -> 2026.9487 | F21: =D21/'7-Denominatori'!$B$6 -> 1.1298047 | G21: =D21/B55 -> 1.6012348
A22: 2) RGS p. 160 — ingresso a 25 con CARRIERA DISCONTINUA e perdita di contribuzione: l'anzianita' tabellata di 39 anni e 8 mesi non si tocca, e nemmeno il tasso di sostituzione | B22: ='P-Parametri'!$B$26 -> 39.6667 | C22: ='P-Parametri'!$B$24 -> 0.728 | D22: =B14*C22 -> 21584.528 | E22: =D22/12 -> 1798.7107 | F22: =D22/'7-Denominatori'!$B$6 -> 1.0025867 | G22: =D22/B55 -> 1.4209329
A23: 3) Controprova lordo -> netto: il netto che il regime fiscale di oggi produrrebbe sulla pensione lorda scalata | B23: =B21 -> 44.7 | C23: =D23/B14 -> 0.84694904 | D23: =B32 -> 25111.257 | E23: =D23/12 -> 2092.6048 | F23: =D23/'7-Denominatori'!$B$6 -> 1.1664009 | G23: =D23/B55 -> 1.6531013
A24: 4) Ingresso a 22 anni, carriera continua (l'estremo alto) | B24: ='P-Parametri'!$B$30-22 -> 47.7 | C24: ='P-Parametri'!$B$24*B24/'P-Parametri'!$B$26 -> 0.87543456 | D24: =B14*C24 -> 25955.827 | E24: =D24/12 -> 2162.9856 | F24: =D24/'7-Denominatori'!$B$6 -> 1.2056305 | G24: =D24/B55 -> 1.7087002
A25: L'ANZIANITA' CONTRIBUTIVA E' UN'IPOTESI, NON UN DATO. La Ragioneria, a p. 160, scrive che «eta' di ingresso inferiori sono compatibili con i calcoli rappresentati nella misura in cui si assumono carriere discontinue con perdita di contribuzione corrispondente al periodo di anticipo»: un ingresso a 25 anni con cinque anni di contribuzione persa sta GIA' DENTRO le tabelle, con l'anzianita' di 39 anni e 8 mesi e il tasso di sostituzione netto tabellato non toccato. La riga 1 e la riga 2 sono entrambe autorizzate dalla fonte, e producono da sole tutta la larghezza della banda.
A27: CONTROPROVA LORDO -> NETTO SULLA PENSIONE
A28: Tasso di sostituzione LORDO scalato | B28: ='P-Parametri'!$B$25*B21/'P-Parametri'!$B$26 -> 0.76177751
A29: Pensione lorda annua | B29: ='1-Input'!$B$9*B28 -> 33518.21
A30: IRPEF lorda sulla pensione | B30: =IF(B29<='P-Parametri'!$B$6,'P-Parametri'!$C$6*B29,IF(B29<='P-Parametri'!$B$7,'P-Parametri'!$B$9+'P-Parametri'!$C$7*(B29-'P-Parametri'!$B$6),'P-Parametri'!$B$10+'P-Parametri'!$C$8*(B29-'P-Parametri'!$B$7))) -> 8261.0095
A31: Detrazione per redditi di pensione (art. 13 c. 3 e 3-bis) | B31: =IF(B29<='P-Parametri'!$C$17,'P-Parametri'!$B$17,IF(B29<='P-Parametri'!$B$6,'P-Parametri'!$B$18+'P-Parametri'!$C$18*('P-Parametri'!$B$6-B29)/'P-Parametri'!$D$18,IF(B29<='P-Parametri'!$B$7,'P-Parametri'!$B$19*('P-Parametri'!$B$7-B29)/'P-Parametri'!$C$19,0)))+IF(AND(B29>'P-Parametri'!$C$20,B29<'P-Parametri'!$D$20),'P-Parametri'!$B$20,0) -> 524.42058
A32: NETTO della pensione per via fiscale diretta | B32: =B29-MAX(0,B30-B31)-IF(MAX(0,B30-B31)<=0,0,'P-Parametri'!$B$11*B29) -> 25111.257
A33: Scarto rispetto al metodo adottato (netto di oggi × TS netto scalato) | B33: =B32/D21-1 -> 0.03239157
A34: Pensione LORDA mensile della porta breve, su 13 mensilita' | B34: ='1-Input'!$B$9*'P-Parametri'!$B$28*('P-Parametri'!$B$30-'P-Parametri'!$B$31+'P-Parametri'!$C$31-'1-Input'!$B$7)/'P-Parametri'!$B$29/'P-Parametri'!$B$34 -> 2196.1122
A35: Il modello CONGELA GLI SCAGLIONI IRPEF in euro reali fino al 2060, che e' esattamente l'ipotesi che la Ragioneria dichiara di aver evitato costruendo i coefficienti di raccordo netto/lordo. La controprova qui sopra e' quindi un risultato di QUESTO modello — il netto che il regime fiscale di oggi produrrebbe su quella pensione — e non una conferma della fonte.
A37: COERENZA DEL CASO — IL VINCOLO ARITMETICO 180.000 = R × s(35 − i; rho)
A38: Eta' di ingresso, capitale a 35 anni e tasso di risparmio non sono tre scelte indipendenti: sono tre facce della stessa equazione. Fissati due qualsiasi, il terzo e' determinato. E l'eta' di ingresso decide anche la pensione, perche' fissa l'anzianita' contributiva. L'accumulo e' un fatto passato: il tasso con cui lo si ricostruisce e' quello REALIZZATO, non quello prospettico.
A39: Eta' di ingresso | B39: Anni di accumulo | C39: R richiesto @ pavimento | D39: in % del netto | E39: R richiesto @ realizzato | F39: in % del netto | G39: Anzianita' a 69a8m | H39: TS netto scalato | I39: Il caso esiste?
A40: =22 -> 22 | B40: ='1-Input'!$B$5-A40 -> 13 | C40: ='1-Input'!$B$8/(IF('1-Input'!$B$12=0,B40,((1+'1-Input'!$B$12)^B40-1)/'1-Input'!$B$12)) -> 11525.318 | D40: =C40/$B$14 -> 0.38872434 | E40: ='1-Input'!$B$8/(IF('1-Input'!$B$32=0,B40,((1+'1-Input'!$B$32)^B40-1)/'1-Input'!$B$32)) -> 10305.323 | F40: =E40/$B$14 -> 0.34757653 | G40: ='P-Parametri'!$B$30-A40 -> 47.7 | H40: ='P-Parametri'!$B$24*G40/'P-Parametri'!$B$26 -> 0.87543456 | I40: =IF(F40>=1,"IMPOSSIBILE — oltre il 100% del netto",IF(F40>0.7,"ALLARME — sopra il 70% del netto","possibile")) -> possibile
A41: =23 -> 23 | B41: ='1-Input'!$B$5-A41 -> 12 | C41: ='1-Input'!$B$8/(IF('1-Input'!$B$12=0,B41,((1+'1-Input'!$B$12)^B41-1)/'1-Input'!$B$12)) -> 12683.175 | D41: =C41/$B$14 -> 0.4277764 | E41: ='1-Input'!$B$8/(IF('1-Input'!$B$32=0,B41,((1+'1-Input'!$B$32)^B41-1)/'1-Input'!$B$32)) -> 11453.619 | F41: =E41/$B$14 -> 0.38630608 | G41: ='P-Parametri'!$B$30-A41 -> 46.7 | H41: ='P-Parametri'!$B$24*G41/'P-Parametri'!$B$26 -> 0.85708163 | I41: =IF(F41>=1,"IMPOSSIBILE — oltre il 100% del netto",IF(F41>0.7,"ALLARME — sopra il 70% del netto","possibile")) -> possibile
A42: =24 -> 24 | B42: ='1-Input'!$B$5-A42 -> 11 | C42: ='1-Input'!$B$8/(IF('1-Input'!$B$12=0,B42,((1+'1-Input'!$B$12)^B42-1)/'1-Input'!$B$12)) -> 14053.941 | D42: =C42/$B$14 -> 0.47400938 | E42: ='1-Input'!$B$8/(IF('1-Input'!$B$32=0,B42,((1+'1-Input'!$B$32)^B42-1)/'1-Input'!$B$32)) -> 12816.594 | F42: =E42/$B$14 -> 0.43227632 | G42: ='P-Parametri'!$B$30-A42 -> 45.7 | H42: ='P-Parametri'!$B$24*G42/'P-Parametri'!$B$26 -> 0.83872871 | I42: =IF(F42>=1,"IMPOSSIBILE — oltre il 100% del netto",IF(F42>0.7,"ALLARME — sopra il 70% del netto","possibile")) -> possibile
A43: =25 -> 25 | B43: ='1-Input'!$B$5-A43 -> 10 | C43: ='1-Input'!$B$8/(IF('1-Input'!$B$12=0,B43,((1+'1-Input'!$B$12)^B43-1)/'1-Input'!$B$12)) -> 15701.491 | D43: =C43/$B$14 -> 0.52957774 | E43: ='1-Input'!$B$8/(IF('1-Input'!$B$32=0,B43,((1+'1-Input'!$B$32)^B43-1)/'1-Input'!$B$32)) -> 14458.684 | F43: =E43/$B$14 -> 0.48766052 | G43: ='P-Parametri'!$B$30-A43 -> 44.7 | H43: ='P-Parametri'!$B$24*G43/'P-Parametri'!$B$26 -> 0.82037578 | I43: =IF(F43>=1,"IMPOSSIBILE — oltre il 100% del netto",IF(F43>0.7,"ALLARME — sopra il 70% del netto","possibile")) -> possibile
A44: =26 -> 26 | B44: ='1-Input'!$B$5-A44 -> 9 | C44: ='1-Input'!$B$8/(IF('1-Input'!$B$12=0,B44,((1+'1-Input'!$B$12)^B44-1)/'1-Input'!$B$12)) -> 17718.094 | D44: =C44/$B$14 -> 0.59759345 | E44: ='1-Input'!$B$8/(IF('1-Input'!$B$32=0,B44,((1+'1-Input'!$B$32)^B44-1)/'1-Input'!$B$32)) -> 16472.962 | F44: =E44/$B$14 -> 0.55559781 | G44: ='P-Parametri'!$B$30-A44 -> 43.7 | H44: ='P-Parametri'!$B$24*G44/'P-Parametri'!$B$26 -> 0.80202286 | I44: =IF(F44>=1,"IMPOSSIBILE — oltre il 100% del netto",IF(F44>0.7,"ALLARME — sopra il 70% del netto","possibile")) -> possibile
...

Sheet 6-Anticipata
A1: La porta breve: la soglia di importo dell'anticipata contributiva
A2: Strumento informativo / divulgativo. NON è consulenza finanziaria. I valori sono indicativi al 2026 e vanno verificati col tuo consulente.
A4: IL TEST DI IMPORTO
A5: Eta' della porta breve (vecchiaia meno tre anni, piu' la finestra) | B5: ='1-Input'!$B$33 -> 66.95
A6: Anno di decorrenza | B6: ='1-Input'!$B$6+B5 -> 2057.95
A7: Anzianita' contributiva alla porta breve | B7: =B5-'1-Input'!$B$7 -> 41.95
A8: Tasso di sostituzione LORDO scalato sull'anticipata | B8: ='P-Parametri'!$B$28*B7/'P-Parametri'!$B$29 -> 0.64885133
A9: Pensione lorda annua della porta breve | B9: ='1-Input'!$B$9*B8 -> 28549.459
A10: Pensione lorda mensile, su 13 mensilita' | B10: =B9/'P-Parametri'!$B$34 -> 2196.1122
A11: Soglia 2026 = moltiplicatore attuale × assegno sociale | B11: ='P-Parametri'!$B$33*'P-Parametri'!$B$32 -> 1638.72
A12: Soglia in euro di oggi dopo il salto del moltiplicatore | B12: ='P-Parametri'!$C$33*'P-Parametri'!$B$32 -> 1747.968
A13: Anni di indicizzazione dalla base al pensionamento | B13: =B6-'P-Parametri'!$B$68 -> 31.95
A14: SOGLIA PROIETTATA all'anno di decorrenza | B14: =B11*(1+'1-Input'!$B$19)^B13*('P-Parametri'!$C$33/'P-Parametri'!$B$33) -> 2402.1569
A15: Margine della pensione sulla soglia | B15: =B10/B14-1 -> -0.085774869
A16: Semaforo | B16: =IF(B10>=B14,"VERDE — la porta breve resta aperta","ROSSO — la porta breve si chiude: la pensione non raggiunge la soglia") -> ROSSO — la porta breve si chiude: la pensione non raggiunge la soglia
A17: PUNTO DI INDIFFERENZA sulla crescita reale del PIL | B17: =(B10/(B11*('P-Parametri'!$C$33/'P-Parametri'!$B$33)))^(1/B13)-1 -> 0.00716907
A18: La soglia si indicizza sulla media mobile quinquennale del tasso di crescita del PIL, senza sospensioni: si rivaluta anche fra il 2026 e l'anno del salto, e il salto del moltiplicatore e' un fattore che si somma all'indicizzazione, non la sostituisce. Ipotesi dichiarata: l'indicizzazione e' letta come REALE, coerentemente col fatto che tutto il modello e' in euro reali. Se fosse nominale, la soglia crescerebbe di piu' e la porta si chiuderebbe prima.
A20: LA SCALA DELLA CRESCITA DEL PIL
A21: Crescita reale del PIL | B21: Soglia proiettata (euro di oggi) | C21: Pensione lorda mensile | D21: Esito
A22: =0 -> 0 | B22: =$B$11*(1+A22)^$B$13*('P-Parametri'!$C$33/'P-Parametri'!$B$33) -> 1747.968 | C22: =$B$10 -> 2196.1122 | D22: =IF(C22>B22+0.5,"passa",IF(ABS(C22-B22)<=0.5,"punto di indifferenza","non passa")) -> passa
A23: =0.005 -> 0.005 | B23: =$B$11*(1+A23)^$B$13*('P-Parametri'!$C$33/'P-Parametri'!$B$33) -> 2049.9306 | C23: =$B$10 -> 2196.1122 | D23: =IF(C23>B23+0.5,"passa",IF(ABS(C23-B23)<=0.5,"punto di indifferenza","non passa")) -> passa
A24: =$B$17 -> 0.00716907 | B24: =$B$11*(1+A24)^$B$13*('P-Parametri'!$C$33/'P-Parametri'!$B$33) -> 2196.1122 | C24: =$B$10 -> 2196.1122 | D24: =IF(C24>B24+0.5,"passa",IF(ABS(C24-B24)<=0.5,"punto di indifferenza","non passa")) -> punto di indifferenza
A25: =0.01 -> 0.01 | B25: =$B$11*(1+A25)^$B$13*('P-Parametri'!$C$33/'P-Parametri'!$B$33) -> 2402.1569 | C25: =$B$10 -> 2196.1122 | D25: =IF(C25>B25+0.5,"passa",IF(ABS(C25-B25)<=0.5,"punto di indifferenza","non passa")) -> non passa
A26: =0.015 -> 0.015 | B26: =$B$11*(1+A26)^$B$13*('P-Parametri'!$C$33/'P-Parametri'!$B$33) -> 2812.7007 | C26: =$B$10 -> 2196.1122 | D26: =IF(C26>B26+0.5,"passa",IF(ABS(C26-B26)<=0.5,"punto di indifferenza","non passa")) -> non passa
A28: LA SECONDA VIA PER SUPERARE LA SOGLIA
A29: Rendita annua da previdenza complementare che si vuole computare | B29: 0
A30: Rendita mensile, su 13 mensilita' | B30: =B29/'P-Parametri'!$B$34 -> 0
A31: Pensione mensile computata, con la rendita | B31: =B10+B30 -> 2196.1122
A32: Requisito contributivo maggiorato richiesto da questa via | B32: =20+'P-Parametri'!$B$35+'P-Parametri'!$C$35 -> 30
A33: Anzianita' del caso alla porta breve — soddisfa il requisito maggiorato? | B33: =IF(B7>=B32,"si'","no") -> si'
A34: Con la rendita computata, la porta breve si apre? | B34: =IF(AND(B7>=B32,B31>=B14),"si', ma con il divieto di cumulo fra pensione e reddito da lavoro","no") -> no
A35: La fonte descrive una seconda via: la rendita maturata nella previdenza complementare puo' essere computata per raggiungere la soglia di importo minimo. E' subordinata a un incremento del requisito contributivo minimo di cinque anni dal 2025 e di altri cinque dal 2030, e al DIVIETO DI CUMULO fra pensione e reddito da lavoro. Nel caso di questo video il capitale sta in ETF e non in un fondo pensione, quindi questa via non si applica: la cella gialla e' zero. Un fondo pensione non fa risparmiare soltanto lo 0,20% l'anno di bollo — la sua rendita puo' contare per aprire la porta breve.
A36: I requisiti e le soglie oltre il 2026 sono PROIEZIONI della Ragioneria generale dello Stato, non norme in vigore. Il moltiplicatore della soglia si e' gia' mosso una volta: assumere che resti fermo per trent'anni e' un'ipotesi, non un dato.

Sheet 7-Denominatori
A1: Due denominatori, non uno: la spesa ISTAT e la spesa del caso
A2: Strumento informativo / divulgativo. NON è consulenza finanziaria. I valori sono indicativi al 2026 e vanno verificati col tuo consulente.
A4: IL DENOMINATORE ISTAT, E QUANTO DI ESSO E' DAVVERO CASSA
A5: Spesa media mensile — persona sola 65 anni e piu' (come pubblicata) | B5: ='P-Parametri'!$B$54 -> 1794.07
A6: La stessa, su base annua | B6: =B5*12 -> 21528.84
A7: Peso della divisione «Abitazione, acqua, elettricita', gas» | B7: ='P-Parametri'!$B$55 -> 0.482
A8: La divisione abitazione, in euro al mese | B8: =B5*B7 -> 864.74174
A9: Quota della divisione che e' affitto figurativo (non monetaria) | B9: ='1-Input'!$B$14 -> 0.6667
A10: Componente NON MONETARIA, in euro al mese | B10: =IF('1-Input'!$B$13=1,0,B8*B9) -> 0
A11: Stato abitativo del caso | B11: =IF('1-Input'!$B$13=1,"AFFITTO — la spesa e' tutta monetaria","CASA DI PROPRIETA' — una parte della spesa non e' cassa") -> AFFITTO — la spesa e' tutta monetaria
A12: DENOMINATORE IN CASSA, €/anno | B12: =(B5-B10)*12 -> 21528.84
A13: Denominatore in cassa, €/mese | B13: =B12/12 -> 1794.07
A14: L'aggregato ISTAT «spesa media mensile per consumi» INCLUDE GLI AFFITTI FIGURATIVI. Glossario del report: «e' una componente non monetaria della spesa per consumi delle famiglie che vivono in abitazione di proprieta', usufrutto o in uso gratuito [...]; rappresenta il costo che queste dovrebbero sostenere per prendere in affitto un'unita' abitativa con caratteristiche identiche a quella in cui vivono». Chi ha la casa pagata NON spende in cassa quella cifra. Confrontare una pensione — che e' cassa — con questo aggregato e' omogeneo SOLO se si dichiara lo stato abitativo. Nel caso di questo video lo stato abitativo e' l'affitto, quindi il confronto e' diretto e la riga 10 vale zero.
A16: LA SENSIBILITA' ALLO STATO ABITATIVO
A17: Ipotesi sulla componente non monetaria | B17: Spesa in cassa €/mese | C17: Spesa in cassa €/anno | D17: Copertura della pensione adottata
