Workbook

Sheet 0 - Indice
A1: Quanto ti costa l'auto in libertà — il simulatore (ottobre 2026)
A2: Strumento informativo / divulgativo. NON è consulenza finanziaria. I valori sono indicativi al 2026 e vanno verificati col tuo consulente.
A4: Indice
A5: 1 - Il tuo profilo | B5: Chi sei: età, km, stipendio, spese, capitale, prezzi dell'energia; spesa totale, tasso di risparmio, capitale netto
A6: 2 - Le opzioni | B6: Le opzioni: rate, maxirata, contanti, usata, noleggio, tenere l'auto di oggi, senza auto; €/mese per sempre
A7: 3 - Il costo opportunità | B7: Il costo opportunità: la differenza di spesa diventa capitale ed entrata al mese, al netto di bollo e imposte
A8: 4 - Abitudine o contratto | B8: Abitudine o contratto: cambiarla spesso, il credito, l'eccedenza; il contratto «da 199 €»; la soglia dell'officina
A9: 5 - Senza auto | B9: Senza auto: abbonamento, noleggi e taxi in tre profili; quante giornate di noleggio paga il margine
A10: 6 - Elettrico o termico | B10: Elettrico o termico: differenza di valore attuale e km all'anno di pareggio
A12: Come usare
A13: 1. Le celle GIALLE sono input — modificale coi tuoi numeri.
A14: 2. Le celle VERDI sono output — si aggiornano automaticamente.
A15: 3. Tutti i numeri di default sono al 2026 da fonti pubbliche.
A16: 4. Niente codice nascosto: l'Excel è solo formule modificabili.
A18: Fonti dati
A19: • F-01 — Agenzia delle Entrate, tabelle nazionali dei costi chilometrici 2026 (GU n. 297 del 23/12/2025, S.O. n. 40) — https://www.gazzettaufficiale.it/eli/gu/2025/12/23/297/so/40/sg/pdf — accesso 08/10/2026
A20: • F-03 — MASE-DGSAIE, prezzi medi settimanali dei carburanti (benzina, media 2026 al 05/10/2026) — https://sisen.mase.gov.it/dgsaie/api/v1/weekly-prices/report/export?format=CSV&lang=it — accesso 08/10/2026
A21: • F-04 — IVASS, IPER II trimestre 2026, comunicazione statistica n. 7/2026 del 24/09/2026 (RC auto, donne 35-44 anni) — https://www.ivass.it/pubblicazioni-e-statistiche/statistiche/comunicazioni-statistiche/2026/cs-n-7-2026/ — accesso 08/10/2026
A22: • F-05 — MEF, decreto tassi effettivi globali medi ottobre-dicembre 2026 (soglie di usura) — https://www.dt.mef.gov.it/export/sites/sitodt/modules/documenti_it/prevenzione_reati_finanziari/antiusura/decreto-tassi-usura-ottobre-dicembre-2026.pdf — accesso 08/10/2026
A23: • F-06 — BCE, statistiche sui tassi bancari, Italia, credito al consumo, nuove operazioni (agosto 2026: tasso 9,12%) — https://data.ecb.europa.eu (serie M.IT.B.A2B.A.R.A.2250.EUR.N) — accesso 08/10/2026
A24: • F-08 — Eurostat nrg_pc_204, elettricità per le famiglie, Italia, 2.500-4.999 kWh, tutte le imposte, 2025-S2 — https://ec.europa.eu/eurostat/databrowser/view/nrg_pc_204/default/table — accesso 08/10/2026
... A46: Sono ipotesi, non consulenza: i prezzi delle auto, i residui e i canoni sono stime. Cambiali con i preventivi veri.

Sheet 1 - Il tuo profilo
A1: Il tuo profilo: chi sei, quanto guadagni, quanto spendi
A2: Strumento informativo / divulgativo. NON è consulenza finanziaria. I valori sono indicativi al 2026 e vanno verificati col tuo consulente.
A3: Valori di partenza: Valentina, 36 anni, single, dipendente, in affitto in un comune medio del Nord Est. Valentina non esiste: è un caso costruito con dati veri. Sostituisci i gialli con i tuoi numeri.
A5: Chi sei e quanto guidi
A6: Età oggi | B6: 36
A7: Età a cui misuri il capitale | B7: 66 | C7: Fra 30 anni, prima dell'età di pensione: il capitale si aggiunge alla pensione, non la sostituisce
A8: Anni di confronto | B8: ='1 - Il tuo profilo'!$B$7-'1 - Il tuo profilo'!$B$6 -> 30
A9: Km all'anno | B9: 12000 | C9: Valentina: 12.000 km, casa-lavoro 18 km a tratta
A10: Orizzonte del confronto fra le opzioni | B10: 10 anni | C10: Fisso: è la struttura del motore (flussi anno per anno, opzioni a ciclo ripetute fino a 10 anni)
A12: Mercati e regole del canale
A13: Rendimento reale del capitale (60/40) | B13: 0.03 | C13: Canone del canale: 3% oltre l'inflazione. È anche il tasso di sconto dei flussi
A14: Inflazione | B14: 0.02 | C14: Serve solo a deflazionare rate e canoni fissi in euro nominali
A15: Prelievo annuo dal capitale | B15: 0.03 | C15: Valori del canale: 4% (25 volte la spesa), 3% (33,3 volte, principale), 2,31% (43,3 volte)
A17: Entrate e spese (euro all'anno)
A18: Stipendio netto annuo | B18: 27326.6 | C18: Valentina: RAL 38.000 → netto 27.326,60 (controllo in fondo al foglio)
A19: Affitto annuo | B19: 6000 | C19: 500 €/mese: canone medio dei nuovi contratti nei comuni non ad alta tensione abitativa del Nord Est (F-13: 504 €/mese)
A20: Utenze, condominio e piccola manutenzione di casa | B20: 1800 | C20: 150 €/mese (ipotesi). Tetto ISTAT: non più di 339,17 €/mese = 4.070 €/anno (F-12, calcolo in fondo al foglio)
A21: Tutte le altre spese (cibo, vestiti, salute, svago…) | B21: 11948.87 | C21: ISTAT 2025, persona sola 35-64 anni, mediana riscalata, senza casa e trasporti (F-12, calcolo in fondo al foglio)
A22: Capitale già investito oggi | B22: 60000
A24: Energia e costi fissi dell'auto
A25: Benzina, €/litro | B25: 1.84995 | C25: Media 2026 al 05/10/2026 (F-03). Banda dell'anno 1,626-2,156
A26: Elettricità a casa, €/kWh | B26: 0.2966 | C26: Famiglie 2.500-4.999 kWh, tutte le imposte, 2025-S2 (F-08)
A27: Ricarica alla colonnina, €/kWh | B27: 0.6 | C27: Ipotesi: nessuna fonte primaria, banda 0,45-0,80
A28: Quota di ricarica alla colonnina (elettrica, caso base) | B28: 0.1 | C28: 90% a casa, 10% alla colonnina
A29: Assicurazione obbligatoria (RC), €/anno | B29: 409.2 | C29: Premio medio donne 35-44 anni, II trimestre 2026 (F-04)
A30: Bollo, € per kW | B30: 2.58 | C30: Euro 4 e oltre, fino a 100 kW (F-14)
A31: Revisione, € (4° anno, poi ogni 2) | B31: 79.02 | C31: Tariffa dei centri privati (ipotesi; in Motorizzazione 45 €, F-18)
A32: Furto-incendio dell'auto nuova, €/anno | B32: 250 | C32: Ipotesi, solo nei primi anni dell'auto nuova (anni nel foglio 2)
A33: Valore dell'auto di oggi, se la vendi | B33: 3000 | C33: Benzina di 13 anni: «qualche migliaio di euro»
A35: Risultati
A36: L'auto di oggi, primo anno (€/anno) | B36: ='2 - Le opzioni'!$L$364 -> 3462.761 | C36: Benzina, assicurazione, bollo, revisione e manutenzione del prossimo anno (foglio 2, opzione F10)
A37: L'auto di oggi, al mese | B37: ='1 - Il tuo profilo'!$B$36/12 -> 288.56342
A38: Spesa totale annua | B38: ='1 - Il tuo profilo'!$B$19+'1 - Il tuo profilo'!$B$20+'1 - Il tuo profilo'!$B$21+'1 - Il tuo profilo'!$B$36 -> 23211.631
A39: Risparmio annuo | B39: ='1 - Il tuo profilo'!$B$18-'1 - Il tuo profilo'!$B$38 -> 4114.969
A40: Tasso di risparmio | B40: ='1 - Il tuo profilo'!$B$39/'1 - Il tuo profilo'!$B$18 -> 0.15058474
A41: Anni di risparmio che spiegano il capitale di oggi | B41: =IF('1 - Il tuo profilo'!$B$39<=0,"risparmio nullo",NPER('1 - Il tuo profilo'!$B$13,-'1 - Il tuo profilo'!$B$39,0,'1 - Il tuo profilo'!$B$22)) -> 12.275699 | C41: Quanti anni di questo risparmio, investito al rendimento reale, servono per arrivare al capitale di oggi
A42: Capitale netto all'età scelta | B42: =(((('1 - Il tuo profilo'!$B$22)*INDEX('3 - Il costo opportunità'!$B$74:$B$134,('1 - Il tuo profilo'!$B$8)+1)+('1 - Il tuo profilo'!$B$39)*INDEX('3 - Il costo opportunità'!$C$74:$C$134,('1 - Il tuo profilo'!$B$8)+1))-'3 - Il costo opportunità'!$B$8*MAX(0,(('1 - Il tuo profilo'!$B$22)*INDEX('3 - Il costo opportunità'!$B$74:$B$134,('1 - Il tuo profilo'!$B$8)+1)+('1 - Il tuo profilo'!$B$39)*INDEX('3 - Il costo opportunità'!$C$74:$C$134,('1 - Il tuo profilo'!$B$8)+1))-(('1 - Il tuo profilo'!$B$22)+('1 - Il tuo profilo'!$B$39)*INDEX('3 - Il costo opportunità'!$D$74:$D$134,('1 - Il tuo profilo'!$B$8)+1))))/(1+'1 - Il tuo profilo'!$B$14)^('1 - Il tuo profilo'!$B$8)) -> 287016.89 | C42: Capitale di oggi + risparmio di oggi, al netto di bollo e imposta (foglio 3) | H42: =FV('1 - Il tuo profilo'!$B$13,'1 - Il tuo profilo'!$B$8,-('1 - Il tuo profilo'!$B$39),-('1 - Il tuo profilo'!$B$22)) -> 341407.11
A43: Entrata netta al mese, al prelievo scelto | B43: ='1 - Il tuo profilo'!$B$42*'1 - Il tuo profilo'!$B$15/12 -> 717.54222
A48: Controllo: il netto dalla RAL (dipendente, 2026)
A49: Retribuzione annua lorda (RAL) | B49: 38000
...

Sheet 2 - Le opzioni
A1: Le opzioni: quanto costa davvero ogni modo di avere (o non avere) l'auto
A2: Strumento informativo / divulgativo. NON è consulenza finanziaria. I valori sono indicativi al 2026 e vanno verificati col tuo consulente.
A3: Euro di oggi (2026), valore residuo sottratto, flussi scontati al rendimento reale del foglio 1. €/mese = rata annua equivalente / 12: è quanto l'auto ti costa ogni mese, per sempre.
A5: L'auto nuova a benzina (opzioni A, B, C)
A6: Prezzo di strada, IVA inclusa | B6: 19000 | C6: Ipotesi: segmento B. Prezzo medio 2025 delle berline B immatricolate: 20.657 € (F-20)
A7: Potenza, kW | B7: 70
A8: Consumo reale, litri per 100 km | B8: 5.6
A10: L'usata (opzione D): la stessa auto, qualche anno dopo
A11: Età dell'usata quando la compri | B11: 4
A12: Ricarico del rivenditore sul valore di mercato | B12: 0.2 | C12: Ipotesi, banda 0-30%
A13: Prezzo dell'usata (calcolato) | B13: ='2 - Le opzioni'!$B$6*IF('2 - Le opzioni'!$B$11>=MAX('2 - Le opzioni'!$B$67:$K$67),0,INDEX('2 - Le opzioni'!$B$68:$K$68,MATCH('2 - Le opzioni'!$B$11,'2 - Le opzioni'!$B$67:$K$67,1))+(INDEX('2 - Le opzioni'!$B$68:$K$68,MATCH('2 - Le opzioni'!$B$11,'2 - Le opzioni'!$B$67:$K$67,1)+1)-INDEX('2 - Le opzioni'!$B$68:$K$68,MATCH('2 - Le opzioni'!$B$11,'2 - Le opzioni'!$B$67:$K$67,1)))*('2 - Le opzioni'!$B$11-INDEX('2 - Le opzioni'!$B$67:$K$67,MATCH('2 - Le opzioni'!$B$11,'2 - Le opzioni'!$B$67:$K$67,1)))/(INDEX('2 - Le opzioni'!$B$67:$K$67,MATCH('2 - Le opzioni'!$B$11,'2 - Le opzioni'!$B$67:$K$67,1)+1)-INDEX('2 - Le opzioni'!$B$67:$K$67,MATCH('2 - Le opzioni'!$B$11,'2 - Le opzioni'!$B$67:$K$67,1))))*(1+'2 - Le opzioni'!$B$12) -> 12540
A14: Stessa potenza e stesso consumo della nuova. Prezzo = prezzo della nuova × valore residuo all'età scelta × (1 + ricarico).
A16: L'auto di oggi (opzione F)
A17: Età dell'auto di oggi | B17: 13
A18: Potenza, kW | B18: 51
A19: Consumo reale, litri per 100 km | B19: 6.5
A20: Valore di rivendita (ipotesi): quello del foglio 1 oggi, poi giù in linea retta fino a 500 € a 18 anni e a zero a 23.
A22: Ibrida ed elettrica
A23: Ibrida: prezzo di strada | B23: 23000
A24: Ibrida: potenza, kW | B24: 70
A25: Ibrida: consumo, litri per 100 km | B25: 4.6
A26: Ibrida nuova: quota di bollo nei primi anni | B26: 0.5 | C26: Esempio regionale: metà bollo (F-14). Le regole cambiano da Regione a Regione
A27: Ibrida nuova: anni di bollo ridotto | B27: 5
A28: Elettrica: prezzo di strada | B28: 26000
A29: Elettrica: potenza, kW | B29: 85
A30: Elettrica: consumo alla presa, kWh per 100 km | B30: 17
A31: Elettrica: anni senza bollo | B31: 5 | C31: Regola nazionale (ipotesi); alcune Regioni esentano più a lungo
A32: Elettrica: quota di bollo dopo | B32: 0.25
A33: Elettrica «colonnina»: quota di ricarica pubblica | B33: 0.8 | C33: Scenario dell'opzione C-el-pub: 20% a casa, 80% alla colonnina
A35: Credito: rate e maxirata
A36: Tasso del finanziamento (TAN) | B36: 0.0912 | C36: Credito al consumo, nuove operazioni, agosto 2026 (F-06)
A37: Spese di istruttoria | B37: 300 | C37: Ipotesi
A38: Finanziamento classico: mesi | B38: 60
A39: Maxirata: mesi | B39: 36 | C39: Scegli 36, 48 o 60: la maxirata rinnovata si ripete a ogni scadenza
A40: Maxirata: rata finale, % del prezzo | B40: 0.55 | C40: Ipotesi, uguale al contratto-tipo «da 199 €» del foglio 4
A41: Maxirata: rata finale in euro | B41: ='2 - Le opzioni'!$B$40*'2 - Le opzioni'!$B$6 -> 10450
A42: Maxirata: anni del ciclo | B42: ='2 - Le opzioni'!$B$39/12 -> 3
A43: Rifinanziamento della rata finale: mesi | B43: 48 | C43: Opzione B2, allo stesso tasso
A44: Riparazioni addebitate alla riconsegna | B44: 400 | C44: Ipotesi, maxirata con restituzione e noleggio
A46: Noleggio a lungo termine (opzione E)
...

Sheet 3 - Il costo opportunità
A1: Il costo opportunità: la differenza di spesa, investita, quanto diventa
A2: Strumento informativo / divulgativo. NON è consulenza finanziaria. I valori sono indicativi al 2026 e vanno verificati col tuo consulente.
A3: Capitali ed entrate AL NETTO del bollo titoli e dell'imposta sui guadagni, in euro di oggi. Ogni differenza di spesa si immagina versata ogni mese in un portafoglio 60/40, per gli anni scelti nel foglio 1.
A5: Le tue scelte
A6: Opzione di riferimento (la più economica che useresti davvero) | B6: D | C6: Codici nella tabella qui sotto (D = usata in contanti)
A7: Bollo titoli, % del valore ogni anno | B7: 0.002 | C7: Imposta di bollo sul deposito titoli
A8: Imposta media sui guadagni | B8: 0.206 | C8: Portafoglio 60/40: 60% × 26% (azioni) + 40% × 12,5% (titoli di Stato) = 20,6%
A9: Anni di accumulo (dal foglio 1) | B9: ='1 - Il tuo profilo'!$B$8 -> 30
A10: Prelievo annuo (dal foglio 1) | B10: ='1 - Il tuo profilo'!$B$15 -> 0.03
A12: Traduttore: 1 € al mese in più di spesa, per sempre
A13: Prelievo | B13: 0.04 | C13: capitale in più che serve | D13: =12/'3 - Il costo opportunità'!$B$13 -> 300
A14: Prelievo | B14: 0.03 | C14: capitale in più che serve | D14: =12/'3 - Il costo opportunità'!$B$14 -> 400
A15: Prelievo | B15: 0.0231 | C15: capitale in più che serve | D15: =12/'3 - Il costo opportunità'!$B$15 -> 519.48052
A16: Ogni euro al mese di spesa fissa chiede 300 € di capitale al 4%, 400 € al 3% (canone del canale), 519,48 € al 2,31%.
A18: Prova con una cifra
A19: Spesa in più, € al mese | B19: 100
A20: Capitale netto che avresti alla fine | B20: =SIGN('3 - Il costo opportunità'!$B$19*12)*((((0)*INDEX('3 - Il costo opportunità'!$B$74:$B$134,('3 - Il costo opportunità'!$B$9)+1)+(ABS('3 - Il costo opportunità'!$B$19*12))*INDEX('3 - Il costo opportunità'!$C$74:$C$134,('3 - Il costo opportunità'!$B$9)+1))-'3 - Il costo opportunità'!$B$8*MAX(0,((0)*INDEX('3 - Il costo opportunità'!$B$74:$B$134,('3 - Il costo opportunità'!$B$9)+1)+(ABS('3 - Il costo opportunità'!$B$19*12))*INDEX('3 - Il costo opportunità'!$C$74:$C$134,('3 - Il costo opportunità'!$B$9)+1))-((0)+(ABS('3 - Il costo opportunità'!$B$19*12))*INDEX('3 - Il costo opportunità'!$D$74:$D$134,('3 - Il costo opportunità'!$B$9)+1))))/(1+'1 - Il tuo profilo'!$B$14)^('3 - Il costo opportunità'!$B$9)) -> 49953.94 | N20: =FV('1 - Il tuo profilo'!$B$13,'3 - Il costo opportunità'!$B$9,-('3 - Il costo opportunità'!$B$19*12),-(0)) -> 57090.499
A21: Entrata in più al mese, netta, al prelievo scelto | B21: ='3 - Il costo opportunità'!$B$20*'3 - Il costo opportunità'!$B$10/12 -> 124.88485
A22: Capitale in più che serve per sempre, al prelievo scelto | B22: ='3 - Il costo opportunità'!$B$19*12/'3 - Il costo opportunità'!$B$10 -> 40000
A24: Tutte le opzioni a confronto (12 colonne verdi; i valori lordi di controllo sono nelle colonne nascoste)
A25: Cod | B25: Opzione | C25: €/mese equivalenti | D25: Differenza dal riferimento, €/mese | E25: Capitale netto perso in 10 anni | F25: Capitale netto perso a fine accumulo | G25: Entrata netta persa, €/mese | H25: Spesa annua totale | I25: Risparmio annuo | J25: Tasso di risparmio | K25: Capitale netto a fine accumulo | L25: Entrata netta al mese | N25: Controllo: Δ capitale lordo 10 anni | O25: Controllo: Δ capitale lordo fine accumulo | P25: Controllo: Δ entrata lorda | Q25: Controllo: Capitale lordo fine accumulo | R25: Controllo: Entrata lorda
A26: A | B26: Nuova benzina, finanziamento classico | C26: ='2 - Le opzioni'!$L$224 -> 358.70959 | D26: =C26-INDEX('3 - Il costo opportunità'!$C$26:$C$44,MATCH('3 - Il costo opportunità'!$B$6,'3 - Il costo opportunità'!$A$26:$A$44,0)) -> 52.754561 | E26: =SIGN(D26*12)*((((0)*INDEX('3 - Il costo opportunità'!$B$74:$B$134,(10)+1)+(ABS(D26*12))*INDEX('3 - Il costo opportunità'!$C$74:$C$134,(10)+1))-'3 - Il costo opportunità'!$B$8*MAX(0,((0)*INDEX('3 - Il costo opportunità'!$B$74:$B$134,(10)+1)+(ABS(D26*12))*INDEX('3 - Il costo opportunità'!$C$74:$C$134,(10)+1))-((0)+(ABS(D26*12))*INDEX('3 - Il costo opportunità'!$D$74:$D$134,(10)+1))))/(1+'1 - Il tuo profilo'!$B$14)^(10)) -> 6958.4556 | F26: =SIGN(D26*12)*((((0)*INDEX('3 - Il costo opportunità'!$B$74:$B$134,('3 - Il costo opportunità'!$B$9)+1)+(ABS(D26*12))*INDEX('3 - Il costo opportunità'!$C$74:$C$134,('3 - Il costo opportunità'!$B$9)+1))-'3 - Il costo opportunità'!$B$8*MAX(0,((0)*INDEX('3 - Il costo opportunità'!$B$74:$B$134,('3 - Il costo opportunità'!$B$9)+1)+(ABS(D26*12))*INDEX('3 - Il costo opportunità'!$C$74:$C$134,('3 - Il costo opportunità'!$B$9)+1))-((0)+(ABS(D26*12))*INDEX('3 - Il costo opportunità'!$D$74:$D$134,('3 - Il costo opportunità'!$B$9)+1))))/(1+'1 - Il tuo profilo'!$B$14)^('3 - Il costo opportunità'!$B$9)) -> 26352.982 | G26: =F26*'3 - Il costo opportunità'!$B$10/12 -> 65.882454 | H26: =('1 - Il tuo profilo'!$B$19+'1 - Il tuo profilo'!$B$20+'1 - Il tuo profilo'!$B$21)+C26*12 -> 24053.385 | I26: ='1 - Il tuo profilo'!$B$18-H26 -> 3273.2149 | J26: =I26/'1 - Il tuo profilo'!$B$18 -> 0.11978127 | K26: =(((('1 - Il tuo profilo'!$B$22)*INDEX('3 - Il costo opportunità'!$B$74:$B$134,('3 - Il costo opportunità'!$B$9)+1)+(I26)*INDEX('3 - Il costo opportunità'!$C$74:$C$134,('3 - Il costo opportunità'!$B$9)+1))-'3 - Il costo opportunità'!$B$8*MAX(0,(('1 - Il tuo profilo'!$B$22)*INDEX('3 - Il costo opportunità'!$B$74:$B$134,('3 - Il costo opportunità'!$B$9)+1)+(I26)*INDEX('3 - Il costo opportunità'!$C$74:$C$134,('3 - Il costo opportunità'!$B$9)+1))-(('1 - Il tuo profilo'!$B$22)+(I26)*INDEX('3 - Il costo opportunità'!$D$74:$D$134,('3 - Il costo opportunità'!$B$9)+1))))/(1+'1 - Il tuo profilo'!$B$14)^('3 - Il costo opportunità'!$B$9)) -> 251976.11 | L26: =K26*'3 - Il costo opportunità'!$B$10/12 -> 629.94027 | N26: =FV('1 - Il tuo profilo'!$B$13,10,-D26*12) -> 7257.2631 | O26: =FV('1 - Il tuo profilo'!$B$13,'3 - Il costo opportunità'!$B$9,-D26*12) -> 30117.842 | P26: =O26*'3 - Il costo opportunità'!$B$10/12 -> 75.294605 | Q26: =FV('1 - Il tuo profilo'!$B$13,'3 - Il costo opportunità'!$B$9,-(I26),-('1 - Il tuo profilo'!$B$22)) -> 301360.31 | R26: =Q26*'3 - Il costo opportunità'!$B$10/12 -> 753.40077
A27: B1 | B27: Maxirata, poi riscatto pagando la rata finale | C27: ='2 - Le opzioni'!$L$262 -> 357.68378 | D27: =C27-INDEX('3 - Il costo opportunità'!$C$26:$C$44,MATCH('3 - Il costo opportunità'!$B$6,'3 - Il costo opportunità'!$A$26:$A$44,0)) -> 51.728751 | E27: =SIGN(D27*12)*((((0)*INDEX('3 - Il costo opportunità'!$B$74:$B$134,(10)+1)+(ABS(D27*12))*INDEX('3 - Il costo opportunità'!$C$74:$C$134,(10)+1))-'3 - Il costo opportunità'!$B$8*MAX(0,((0)*INDEX('3 - Il costo opportunità'!$B$74:$B$134,(10)+1)+(ABS(D27*12))*INDEX('3 - Il costo opportunità'!$C$74:$C$134,(10)+1))-((0)+(ABS(D27*12))*INDEX('3 - Il costo opportunità'!$D$74:$D$134,(10)+1))))/(1+'1 - Il tuo profilo'!$B$14)^(10)) -> 6823.1488 | F27: =SIGN(D27*12)*((((0)*INDEX('3 - Il costo opportunità'!$B$74:$B$134,('3 - Il costo opportunità'!$B$9)+1)+(ABS(D27*12))*INDEX('3 - Il costo opportunità'!$C$74:$C$134,('3 - Il costo opportunità'!$B$9)+1))-'3 - Il costo opportunità'!$B$8*MAX(0,((0)*INDEX('3 - Il costo opportunità'!$B$74:$B$134,('3 - Il costo opportunità'!$B$9)+1)+(ABS(D27*12))*INDEX('3 - Il costo opportunità'!$C$74:$C$134,('3 - Il costo opportunità'!$B$9)+1))-((0)+(ABS(D27*12))*INDEX('3 - Il costo opportunità'!$D$74:$D$134,('3 - Il costo opportunità'!$B$9)+1))))/(1+'1 - Il tuo profilo'!$B$14)^('3 - Il costo opportunità'!$B$9)) -> 25840.549 | G27: =F27*'3 - Il costo opportunità'!$B$10/12 -> 64.601373 | H27: =('1 - Il tuo profilo'!$B$19+'1 - Il tuo profilo'!$B$20+'1 - Il tuo profilo'!$B$21)+C27*12 -> 24041.075 | I27: ='1 - Il tuo profilo'!$B$18-H27 -> 3285.5246 | J27: =I27/'1 - Il tuo profilo'!$B$18 -> 0.12023174 | K27: =(((('1 - Il tuo profilo'!$B$22)*INDEX('3 - Il costo opportunità'!$B$74:$B$134,('3 - Il costo opportunità'!$B$9)+1)+(I27)*INDEX('3 - Il costo opportunità'!$C$74:$C$134,('3 - Il costo opportunità'!$B$9)+1))-'3 - Il costo opportunità'!$B$8*MAX(0,(('1 - Il tuo profilo'!$B$22)*INDEX('3 - Il costo opportunità'!$B$74:$B$134,('3 - Il costo opportunità'!$B$9)+1)+(I27)*INDEX('3 - Il costo opportunità'!$C$74:$C$134,('3 - Il costo opportunità'!$B$9)+1))-(('1 - Il tuo profilo'!$B$22)+(I27)*INDEX('3 - Il costo opportunità'!$D$74:$D$134,('3 - Il costo opportunità'!$B$9)+1))))/(1+'1 - Il tuo profilo'!$B$14)^('3 - Il costo opportunità'!$B$9)) -> 252488.54 | L27: =K27*'3 - Il costo opportunità'!$B$10/12 -> 631.22135 | N27: =FV('1 - Il tuo profilo'!$B$13,10,-D27*12) -> 7116.146 | O27: =FV('1 - Il tuo profilo'!$B$13,'3 - Il costo opportunità'!$B$9,-D27*12) -> 29532.202 | P27: =O27*'3 - Il costo opportunità'!$B$10/12 -> 73.830506 | Q27: =FV('1 - Il tuo profilo'!$B$13,'3 - Il costo opportunità'!$B$9,-(I27),-('1 - Il tuo profilo'!$B$22)) -> 301945.95 | R27: =Q27*'3 - Il costo opportunità'!$B$10/12 -> 754.86487
A28: B2 | B28: Maxirata, poi rata finale rifinanziata | C28: ='2 - Le opzioni'!$L$281 -> 367.77877 | D28: =C28-INDEX('3 - Il costo opportunità'!$C$26:$C$44,MATCH('3 - Il costo opportunità'!$B$6,'3 - Il costo opportunità'!$A$26:$A$44,0)) -> 61.823738 | E28: =SIGN(D28*12)*((((0)*INDEX('3 - Il costo opportunità'!$B$74:$B$134,(10)+1)+(ABS(D28*12))*INDEX('3 - Il costo opportunità'!$C$74:$C$134,(10)+1))-'3 - Il costo opportunità'!$B$8*MAX(0,((0)*INDEX('3 - Il costo opportunità'!$B$74:$B$134,(10)+1)+(ABS(D28*12))*INDEX('3 - Il costo opportunità'!$C$74:$C$134,(10)+1))-((0)+(ABS(D28*12))*INDEX('3 - Il costo opportunità'!$D$74:$D$134,(10)+1))))/(1+'1 - Il tuo profilo'!$B$14)^(10)) -> 8154.7022 | F28: =SIGN(D28*12)*((((0)*INDEX('3 - Il costo opportunità'!$B$74:$B$134,('3 - Il costo opportunità'!$B$9)+1)+(ABS(D28*12))*INDEX('3 - Il costo opportunità'!$C$74:$C$134,('3 - Il costo opportunità'!$B$9)+1))-'3 - Il costo opportunità'!$B$8*MAX(0,((0)*INDEX('3 - Il costo opportunità'!$B$74:$B$134,('3 - Il costo opportunità'!$B$9)+1)+(ABS(D28*12))*INDEX('3 - Il costo opportunità'!$C$74:$C$134,('3 - Il costo opportunità'!$B$9)+1))-((0)+(ABS(D28*12))*INDEX('3 - Il costo opportunità'!$D$74:$D$134,('3 - Il costo opportunità'!$B$9)+1))))/(1+'1 - Il tuo profilo'!$B$14)^('3 - Il costo opportunità'!$B$9)) -> 30883.393 | G28: =F28*'3 - Il costo opportunità'!$B$10/12 -> 77.208482 | H28: =('1 - Il tuo profilo'!$B$19+'1 - Il tuo profilo'!$B$20+'1 - Il tuo profilo'!$B$21)+C28*12 -> 24162.215 | I28: ='1 - Il tuo profilo'!$B$18-H28 -> 3164.3848 | J28: =I28/'1 - Il tuo profilo'!$B$18 -> 0.1157987 | K28: =(((('1 - Il tuo profilo'!$B$22)*INDEX('3 - Il costo opportunità'!$B$74:$B$134,('3 - Il costo opportunità'!$B$9)+1)+(I28)*INDEX('3 - Il costo opportunità'!$C$74:$C$134,('3 - Il costo opportunità'!$B$9)+1))-'3 - Il costo opportunità'!$B$8*MAX(0,(('1 - Il tuo profilo'!$B$22)*INDEX('3 - Il costo opportunità'!$B$74:$B$134,('3 - Il costo opportunità'!$B$9)+1)+(I28)*INDEX('3 - Il costo opportunità'!$C$74:$C$134,('3 - Il costo opportunità'!$B$9)+1))-(('1 - Il tuo profilo'!$B$22)+(I28)*INDEX('3 - Il costo opportunità'!$D$74:$D$134,('3 - Il costo opportunità'!$B$9)+1))))/(1+'1 - Il tuo profilo'!$B$14)^('3 - Il costo opportunità'!$B$9)) -> 247445.7 | L28: =K28*'3 - Il costo opportunità'!$B$10/12 -> 618.61425 | N28: =FV('1 - Il tuo profilo'!$B$13,10,-D28*12) -> 8504.8784 | O28: =FV('1 - Il tuo profilo'!$B$13,'3 - Il costo opportunità'!$B$9,-D28*12) -> 35295.48 | P28: =O28*'3 - Il costo opportunità'!$B$10/12 -> 88.238701 | Q28: =FV('1 - Il tuo profilo'!$B$13,'3 - Il costo opportunità'!$B$9,-(I28),-('1 - Il tuo profilo'!$B$22)) -> 296182.67 | R28: =Q28*'3 - Il costo opportunità'!$B$10/12 -> 740.45668
A29: B3 alto | B29: Maxirata rinnovata, eccedenza persa (alto) | C29: ='2 - Le opzioni'!$L$300 -> 533.50587 | D29: =C29-INDEX('3 - Il costo opportunità'!$C$26:$C$44,MATCH('3 - Il costo opportunità'!$B$6,'3 - Il costo opportunità'!$A$26:$A$44,0)) -> 227.55084 | E29: =SIGN(D29*12)*((((0)*INDEX('3 - Il costo opportunità'!$B$74:$B$134,(10)+1)+(ABS(D29*12))*INDEX('3 - Il costo opportunità'!$C$74:$C$134,(10)+1))-'3 - Il costo opportunità'!$B$8*MAX(0,((0)*INDEX('3 - Il costo opportunità'!$B$74:$B$134,(10)+1)+(ABS(D29*12))*INDEX('3 - Il costo opportunità'!$C$74:$C$134,(10)+1))-((0)+(ABS(D29*12))*INDEX('3 - Il costo opportunità'!$D$74:$D$134,(10)+1))))/(1+'1 - Il tuo profilo'!$B$14)^(10)) -> 30014.512 | F29: =SIGN(D29*12)*((((0)*INDEX('3 - Il costo opportunità'!$B$74:$B$134,('3 - Il costo opportunità'!$B$9)+1)+(ABS(D29*12))*INDEX('3 - Il costo opportunità'!$C$74:$C$134,('3 - Il costo opportunità'!$B$9)+1))-'3 - Il costo opportunità'!$B$8*MAX(0,((0)*INDEX('3 - Il costo opportunità'!$B$74:$B$134,('3 - Il costo opportunità'!$B$9)+1)+(ABS(D29*12))*INDEX('3 - Il costo opportunità'!$C$74:$C$134,('3 - Il costo opportunità'!$B$9)+1))-((0)+(ABS(D29*12))*INDEX('3 - Il costo opportunità'!$D$74:$D$134,('3 - Il costo opportunità'!$B$9)+1))))/(1+'1 - Il tuo profilo'!$B$14)^('3 - Il costo opportunità'!$B$9)) -> 113670.61 | G29: =F29*'3 - Il costo opportunità'!$B$10/12 -> 284.17652 | H29: =('1 - Il tuo profilo'!$B$19+'1 - Il tuo profilo'!$B$20+'1 - Il tuo profilo'!$B$21)+C29*12 -> 26150.94 | I29: ='1 - Il tuo profilo'!$B$18-H29 -> 1175.6596 | J29: =I29/'1 - Il tuo profilo'!$B$18 -> 0.043022535 | K29: =(((('1 - Il tuo profilo'!$B$22)*INDEX('3 - Il costo opportunità'!$B$74:$B$134,('3 - Il costo opportunità'!$B$9)+1)+(I29)*INDEX('3 - Il costo opportunità'!$C$74:$C$134,('3 - Il costo opportunità'!$B$9)+1))-'3 - Il costo opportunità'!$B$8*MAX(0,(('1 - Il tuo profilo'!$B$22)*INDEX('3 - Il costo opportunità'!$B$74:$B$134,('3 - Il costo opportunità'!$B$9)+1)+(I29)*INDEX('3 - Il costo opportunità'!$C$74:$C$134,('3 - Il costo opportunità'!$B$9)+1))-(('1 - Il tuo profilo'!$B$22)+(I29)*INDEX('3 - Il costo opportunità'!$D$74:$D$134,('3 - Il costo opportunità'!$B$9)+1))))/(1+'1 - Il tuo profilo'!$B$14)^('3 - Il costo opportunità'!$B$9)) -> 164658.48 | L29: =K29*'3 - Il costo opportunità'!$B$10/12 -> 411.64621 | N29: =FV('1 - Il tuo profilo'!$B$13,10,-D29*12) -> 31303.384 | O29: =FV('1 - Il tuo profilo'!$B$13,'3 - Il costo opportunità'!$B$9,-D29*12) -> 129909.91 | P29: =O29*'3 - Il costo opportunità'!$B$10/12 -> 324.77477 | Q29: =FV('1 - Il tuo profilo'!$B$13,'3 - Il costo opportunità'!$B$9,-(I29),-('1 - Il tuo profilo'!$B$22)) -> 201568.24 | R29: =Q29*'3 - Il costo opportunità'!$B$10/12 -> 503.92061
A30: B3 basso | B30: Maxirata rinnovata, eccedenza riconosciuta (basso) | C30: ='2 - Le opzioni'!$L$319 -> 481.39775 | D30: =C30-INDEX('3 - Il costo opportunità'!$C$26:$C$44,MATCH('3 - Il costo opportunità'!$B$6,'3 - Il costo opportunità'!$A$26:$A$44,0)) -> 175.44272 | E30: =SIGN(D30*12)*((((0)*INDEX('3 - Il costo opportunità'!$B$74:$B$134,(10)+1)+(ABS(D30*12))*INDEX('3 - Il costo opportunità'!$C$74:$C$134,(10)+1))-'3 - Il costo opportunità'!$B$8*MAX(0,((0)*INDEX('3 - Il costo opportunità'!$B$74:$B$134,(10)+1)+(ABS(D30*12))*INDEX('3 - Il costo opportunità'!$C$74:$C$134,(10)+1))-((0)+(ABS(D30*12))*INDEX('3 - Il costo opportunità'!$D$74:$D$134,(10)+1))))/(1+'1 - Il tuo profilo'!$B$14)^(10)) -> 23141.324 | F30: =SIGN(D30*12)*((((0)*INDEX('3 - Il costo opportunità'!$B$74:$B$134,('3 - Il costo opportunità'!$B$9)+1)+(ABS(D30*12))*INDEX('3 - Il costo opportunità'!$C$74:$C$134,('3 - Il costo opportunità'!$B$9)+1))-'3 - Il costo opportunità'!$B$8*MAX(0,((0)*INDEX('3 - Il costo opportunità'!$B$74:$B$134,('3 - Il costo opportunità'!$B$9)+1)+(ABS(D30*12))*INDEX('3 - Il costo opportunità'!$C$74:$C$134,('3 - Il costo opportunità'!$B$9)+1))-((0)+(ABS(D30*12))*INDEX('3 - Il costo opportunità'!$D$74:$D$134,('3 - Il costo opportunità'!$B$9)+1))))/(1+'1 - Il tuo profilo'!$B$14)^('3 - Il costo opportunità'!$B$9)) -> 87640.553 | G30: =F30*'3 - Il costo opportunità'!$B$10/12 -> 219.10138 | H30: =('1 - Il tuo profilo'!$B$19+'1 - Il tuo profilo'!$B$20+'1 - Il tuo profilo'!$B$21)+C30*12 -> 25525.643 | I30: ='1 - Il tuo profilo'!$B$18-H30 -> 1800.957 | J30: =I30/'1 - Il tuo profilo'!$B$18 -> 0.065904904 | K30: =(((('1 - Il tuo profilo'!$B$22)*INDEX('3 - Il costo opportunità'!$B$74:$B$134,('3 - Il costo opportunità'!$B$9)+1)+(I30)*INDEX('3 - Il costo opportunità'!$C$74:$C$134,('3 - Il costo opportunità'!$B$9)+1))-'3 - Il costo opportunità'!$B$8*MAX(0,(('1 - Il tuo profilo'!$B$22)*INDEX('3 - Il costo opportunità'!$B$74:$B$134,('3 - Il costo opportunità'!$B$9)+1)+(I30)*INDEX('3 - Il costo opportunità'!$C$74:$C$134,('3 - Il costo opportunità'!$B$9)+1))-(('1 - Il tuo profilo'!$B$22)+(I30)*INDEX('3 - Il costo opportunità'!$D$74:$D$134,('3 - Il costo opportunità'!$B$9)+1))))/(1+'1 - Il tuo profilo'!$B$14)^('3 - Il costo opportunità'!$B$9)) -> 190688.54 | L30: =K30*'3 - Il costo opportunità'!$B$10/12 -> 476.72135 | N30: =FV('1 - Il tuo profilo'!$B$13,10,-D30*12) -> 24135.051 | O30: =FV('1 - Il tuo profilo'!$B$13,'3 - Il costo opportunità'!$B$9,-D30*12) -> 100161.13 | P30: =O30*'3 - Il costo opportunità'!$B$10/12 -> 250.40282 | Q30: =FV('1 - Il tuo profilo'!$B$13,'3 - Il costo opportunità'!$B$9,-(I30),-('1 - Il tuo profilo'!$B$22)) -> 231317.02 | R30: =Q30*'3 - Il costo opportunità'!$B$10/12 -> 578.29256
A31: C | B31: Nuova benzina in contanti | C31: ='2 - Le opzioni'!$L$129 -> 339.44037 | D31: =C31-INDEX('3 - Il costo opportunità'!$C$26:$C$44,MATCH('3 - Il costo opportunità'!$B$6,'3 - Il costo opportunità'!$A$26:$A$44,0)) -> 33.485339 | E31: =SIGN(D31*12)*((((0)*INDEX('3 - Il costo opportunità'!$B$74:$B$134,(10)+1)+(ABS(D31*12))*INDEX('3 - Il costo opportunità'!$C$74:$C$134,(10)+1))-'3 - Il costo opportunità'!$B$8*MAX(0,((0)*INDEX('3 - Il costo opportunità'!$B$74:$B$134,(10)+1)+(ABS(D31*12))*INDEX('3 - Il costo opportunità'!$C$74:$C$134,(10)+1))-((0)+(ABS(D31*12))*INDEX('3 - Il costo opportunità'!$D$74:$D$134,(10)+1))))/(1+'1 - Il tuo profilo'!$B$14)^(10)) -> 4416.798 | F31: =SIGN(D31*12)*((((0)*INDEX('3 - Il costo opportunità'!$B$74:$B$134,('3 - Il costo opportunità'!$B$9)+1)+(ABS(D31*12))*INDEX('3 - Il costo opportunità'!$C$74:$C$134,('3 - Il costo opportunità'!$B$9)+1))-'3 - Il costo opportunità'!$B$8*MAX(0,((0)*INDEX('3 - Il costo opportunità'!$B$74:$B$134,('3 - Il costo opportunità'!$B$9)+1)+(ABS(D31*12))*INDEX('3 - Il costo opportunità'!$C$74:$C$134,('3 - Il costo opportunità'!$B$9)+1))-((0)+(ABS(D31*12))*INDEX('3 - Il costo opportunità'!$D$74:$D$134,('3 - Il costo opportunità'!$B$9)+1))))/(1+'1 - Il tuo profilo'!$B$14)^('3 - Il costo opportunità'!$B$9)) -> 16727.246 | G31: =F31*'3 - Il costo opportunità'!$B$10/12 -> 41.818115 | H31: =('1 - Il tuo profilo'!$B$19+'1 - Il tuo profilo'!$B$20+'1 - Il tuo profilo'!$B$21)+C31*12 -> 23822.154 | I31: ='1 - Il tuo profilo'!$B$18-H31 -> 3504.4456 | J31: =I31/'1 - Il tuo profilo'!$B$18 -> 0.12824302 | K31: =(((('1 - Il tuo profilo'!$B$22)*INDEX('3 - Il costo opportunità'!$B$74:$B$134,('3 - Il costo opportunità'!$B$9)+1)+(I31)*INDEX('3 - Il costo opportunità'!$C$74:$C$134,('3 - Il costo opportunità'!$B$9)+1))-'3 - Il costo opportunità'!$B$8*MAX(0,(('1 - Il tuo profilo'!$B$22)*INDEX('3 - Il costo opportunità'!$B$74:$B$134,('3 - Il costo opportunità'!$B$9)+1)+(I31)*INDEX('3 - Il costo opportunità'!$C$74:$C$134,('3 - Il costo opportunità'!$B$9)+1))-(('1 - Il tuo profilo'!$B$22)+(I31)*INDEX('3 - Il costo opportunità'!$D$74:$D$134,('3 - Il costo opportunità'!$B$9)+1))))/(1+'1 - Il tuo profilo'!$B$14)^('3 - Il costo opportunità'!$B$9)) -> 261601.85 | L31: =K31*'3 - Il costo opportunità'!$B$10/12 -> 654.00461 | N31: =FV('1 - Il tuo profilo'!$B$13,10,-D31*12) -> 4606.4626 | O31: =FV('1 - Il tuo profilo'!$B$13,'3 - Il costo opportunità'!$B$9,-D31*12) -> 19116.947 | P31: =O31*'3 - Il costo opportunità'!$B$10/12 -> 47.792367 | Q31: =FV('1 - Il tuo profilo'!$B$13,'3 - Il costo opportunità'!$B$9,-(I31),-('1 - Il tuo profilo'!$B$22)) -> 312361.2 | R31: =Q31*'3 - Il costo opportunità'!$B$10/12 -> 780.90301
A32: D | B32: Usata in contanti (la stessa auto, qualche anno dopo) | C32: ='2 - Le opzioni'!$L$148 -> 305.95503 | D32: =C32-INDEX('3 - Il costo opportunità'!$C$26:$C$44,MATCH('3 - Il costo opportunità'!$B$6,'3 - Il costo opportunità'!$A$26:$A$44,0)) -> 0 | E32: =SIGN(D32*12)*((((0)*INDEX('3 - Il costo opportunità'!$B$74:$B$134,(10)+1)+(ABS(D32*12))*INDEX('3 - Il costo opportunità'!$C$74:$C$134,(10)+1))-'3 - Il costo opportunità'!$B$8*MAX(0,((0)*INDEX('3 - Il costo opportunità'!$B$74:$B$134,(10)+1)+(ABS(D32*12))*INDEX('3 - Il costo opportunità'!$C$74:$C$134,(10)+1))-((0)+(ABS(D32*12))*INDEX('3 - Il costo opportunità'!$D$74:$D$134,(10)+1))))/(1+'1 - Il tuo profilo'!$B$14)^(10)) -> 0 | F32: =SIGN(D32*12)*((((0)*INDEX('3 - Il costo opportunità'!$B$74:$B$134,('3 - Il costo opportunità'!$B$9)+1)+(ABS(D32*12))*INDEX('3 - Il costo opportunità'!$C$74:$C$134,('3 - Il costo opportunità'!$B$9)+1))-'3 - Il costo opportunità'!$B$8*MAX(0,((0)*INDEX('3 - Il costo opportunità'!$B$74:$B$134,('3 - Il costo opportunità'!$B$9)+1)+(ABS(D32*12))*INDEX('3 - Il costo opportunità'!$C$74:$C$134,('3 - Il costo opportunità'!$B$9)+1))-((0)+(ABS(D32*12))*INDEX('3 - Il costo opportunità'!$D$74:$D$134,('3 - Il costo opportunità'!$B$9)+1))))/(1+'1 - Il tuo profilo'!$B$14)^('3 - Il costo opportunità'!$B$9)) -> 0 | G32: =F32*'3 - Il costo opportunità'!$B$10/12 -> 0 | H32: =('1 - Il tuo profilo'!$B$19+'1 - Il tuo profilo'!$B$20+'1 - Il tuo profilo'!$B$21)+C32*12 -> 23420.33 | I32: ='1 - Il tuo profilo'!$B$18-H32 -> 3906.2697 | J32: =I32/'1 - Il tuo profilo'!$B$18 -> 0.14294752 | K32: =(((('1 - Il tuo profilo'!$B$22)*INDEX('3 - Il costo opportunità'!$B$74:$B$134,('3 - Il costo opportunità'!$B$9)+1)+(I32)*INDEX('3 - Il costo opportunità'!$C$74:$C$134,('3 - Il costo opportunità'!$B$9)+1))-'3 - Il costo opportunità'!$B$8*MAX(0,(('1 - Il tuo profilo'!$B$22)*INDEX('3 - Il costo opportunità'!$B$74:$B$134,('3 - Il costo opportunità'!$B$9)+1)+(I32)*INDEX('3 - Il costo opportunità'!$C$74:$C$134,('3 - Il costo opportunità'!$B$9)+1))-(('1 - Il tuo profilo'!$B$22)+(I32)*INDEX('3 - Il costo opportunità'!$D$74:$D$134,('3 - Il costo opportunità'!$B$9)+1))))/(1+'1 - Il tuo profilo'!$B$14)^('3 - Il costo opportunità'!$B$9)) -> 278329.09 | L32: =K32*'3 - Il costo opportunità'!$B$10/12 -> 695.82273 | N32: =FV('1 - Il tuo profilo'!$B$13,10,-D32*12) -> 0 | O32: =FV('1 - Il tuo profilo'!$B$13,'3 - Il costo opportunità'!$B$9,-D32*12) -> 0 | P32: =O32*'3 - Il costo opportunità'!$B$10/12 -> 0 | Q32: =FV('1 - Il tuo profilo'!$B$13,'3 - Il costo opportunità'!$B$9,-(I32),-('1 - Il tuo profilo'!$B$22)) -> 331478.15 | R32: =Q32*'3 - Il costo opportunità'!$B$10/12 -> 828.69538
A33: E | B33: Noleggio a lungo termine, benzina | C33: ='2 - Le opzioni'!$L$338 -> 443.07638 | D33: =C33-INDEX('3 - Il costo opportunità'!$C$26:$C$44,MATCH('3 - Il costo opportunità'!$B$6,'3 - Il costo opportunità'!$A$26:$A$44,0)) -> 137.12135 | E33: =SIGN(D33*12)*((((0)*INDEX('3 - Il costo opportunità'!$B$74:$B$134,(10)+1)+(ABS(D33*12))*INDEX('3 - Il costo opportunità'!$C$74:$C$134,(10)+1))-'3 - Il costo opportunità'!$B$8*MAX(0,((0)*INDEX('3 - Il costo opportunità'!$B$74:$B$134,(10)+1)+(ABS(D33*12))*INDEX('3 - Il costo opportunità'!$C$74:$C$134,(10)+1))-((0)+(ABS(D33*12))*INDEX('3 - Il costo opportunità'!$D$74:$D$134,(10)+1))))/(1+'1 - Il tuo profilo'!$B$14)^(10)) -> 18086.641 | F33: =SIGN(D33*12)*((((0)*INDEX('3 - Il costo opportunità'!$B$74:$B$134,('3 - Il costo opportunità'!$B$9)+1)+(ABS(D33*12))*INDEX('3 - Il costo opportunità'!$C$74:$C$134,('3 - Il costo opportunità'!$B$9)+1))-'3 - Il costo opportunità'!$B$8*MAX(0,((0)*INDEX('3 - Il costo opportunità'!$B$74:$B$134,('3 - Il costo opportunità'!$B$9)+1)+(ABS(D33*12))*INDEX('3 - Il costo opportunità'!$C$74:$C$134,('3 - Il costo opportunità'!$B$9)+1))-((0)+(ABS(D33*12))*INDEX('3 - Il costo opportunità'!$D$74:$D$134,('3 - Il costo opportunità'!$B$9)+1))))/(1+'1 - Il tuo profilo'!$B$14)^('3 - Il costo opportunità'!$B$9)) -> 68497.515 | G33: =F33*'3 - Il costo opportunità'!$B$10/12 -> 171.24379 | H33: =('1 - Il tuo profilo'!$B$19+'1 - Il tuo profilo'!$B$20+'1 - Il tuo profilo'!$B$21)+C33*12 -> 25065.787 | I33: ='1 - Il tuo profilo'!$B$18-H33 -> 2260.8135 | J33: =I33/'1 - Il tuo profilo'!$B$18 -> 0.082733069 | K33: =(((('1 - Il tuo profilo'!$B$22)*INDEX('3 - Il costo opportunità'!$B$74:$B$134,('3 - Il costo opportunità'!$B$9)+1)+(I33)*INDEX('3 - Il costo opportunità'!$C$74:$C$134,('3 - Il costo opportunità'!$B$9)+1))-'3 - Il costo opportunità'!$B$8*MAX(0,(('1 - Il tuo profilo'!$B$22)*INDEX('3 - Il costo opportunità'!$B$74:$B$134,('3 - Il costo opportunità'!$B$9)+1)+(I33)*INDEX('3 - Il costo opportunità'!$C$74:$C$134,('3 - Il costo opportunità'!$B$9)+1))-(('1 - Il tuo profilo'!$B$22)+(I33)*INDEX('3 - Il costo opportunità'!$D$74:$D$134,('3 - Il costo opportunità'!$B$9)+1))))/(1+'1 - Il tuo profilo'!$B$14)^('3 - Il costo opportunità'!$B$9)) -> 209831.58 | L33: =K33*'3 - Il costo opportunità'!$B$10/12 -> 524.57894 | N33: =FV('1 - Il tuo profilo'!$B$13,10,-D33*12) -> 18863.311 | O33: =FV('1 - Il tuo profilo'!$B$13,'3 - Il costo opportunità'!$B$9,-D33*12) -> 78283.261 | P33: =O33*'3 - Il costo opportunità'!$B$10/12 -> 195.70815 | Q33: =FV('1 - Il tuo profilo'!$B$13,'3 - Il costo opportunità'!$B$9,-(I33),-('1 - Il tuo profilo'!$B$22)) -> 253194.89 | R33: =Q33*'3 - Il costo opportunità'!$B$10/12 -> 632.98722
A34: F5 | B34: Tenere l'auto di oggi 5 anni, poi l'usata | C34: ='2 - Le opzioni'!$L$395 -> 323.83508 | D34: =C34-INDEX('3 - Il costo opportunità'!$C$26:$C$44,MATCH('3 - Il costo opportunità'!$B$6,'3 - Il costo opportunità'!$A$26:$A$44,0)) -> 17.880052 | E34: =SIGN(D34*12)*((((0)*INDEX('3 - Il costo opportunità'!$B$74:$B$134,(10)+1)+(ABS(D34*12))*INDEX('3 - Il costo opportunità'!$C$74:$C$134,(10)+1))-'3 - Il costo opportunità'!$B$8*MAX(0,((0)*INDEX('3 - Il costo opportunità'!$B$74:$B$134,(10)+1)+(ABS(D34*12))*INDEX('3 - Il costo opportunità'!$C$74:$C$134,(10)+1))-((0)+(ABS(D34*12))*INDEX('3 - Il costo opportunità'!$D$74:$D$134,(10)+1))))/(1+'1 - Il tuo profilo'!$B$14)^(10)) -> 2358.4226 | F34: =SIGN(D34*12)*((((0)*INDEX('3 - Il costo opportunità'!$B$74:$B$134,('3 - Il costo opportunità'!$B$9)+1)+(ABS(D34*12))*INDEX('3 - Il costo opportunità'!$C$74:$C$134,('3 - Il costo opportunità'!$B$9)+1))-'3 - Il costo opportunità'!$B$8*MAX(0,((0)*INDEX('3 - Il costo opportunità'!$B$74:$B$134,('3 - Il costo opportunità'!$B$9)+1)+(ABS(D34*12))*INDEX('3 - Il costo opportunità'!$C$74:$C$134,('3 - Il costo opportunità'!$B$9)+1))-((0)+(ABS(D34*12))*INDEX('3 - Il costo opportunità'!$D$74:$D$134,('3 - Il costo opportunità'!$B$9)+1))))/(1+'1 - Il tuo profilo'!$B$14)^('3 - Il costo opportunità'!$B$9)) -> 8931.7906 | G34: =F34*'3 - Il costo opportunità'!$B$10/12 -> 22.329477 | H34: =('1 - Il tuo profilo'!$B$19+'1 - Il tuo profilo'!$B$20+'1 - Il tuo profilo'!$B$21)+C34*12 -> 23634.891 | I34: ='1 - Il tuo profilo'!$B$18-H34 -> 3691.709 | J34: =I34/'1 - Il tuo profilo'!$B$18 -> 0.13509581 | K34: =(((('1 - Il tuo profilo'!$B$22)*INDEX('3 - Il costo opportunità'!$B$74:$B$134,('3 - Il costo opportunità'!$B$9)+1)+(I34)*INDEX('3 - Il costo opportunità'!$C$74:$C$134,('3 - Il costo opportunità'!$B$9)+1))-'3 - Il costo opportunità'!$B$8*MAX(0,(('1 - Il tuo profilo'!$B$22)*INDEX('3 - Il costo opportunità'!$B$74:$B$134,('3 - Il costo opportunità'!$B$9)+1)+(I34)*INDEX('3 - Il costo opportunità'!$C$74:$C$134,('3 - Il costo opportunità'!$B$9)+1))-(('1 - Il tuo profilo'!$B$22)+(I34)*INDEX('3 - Il costo opportunità'!$D$74:$D$134,('3 - Il costo opportunità'!$B$9)+1))))/(1+'1 - Il tuo profilo'!$B$14)^('3 - Il costo opportunità'!$B$9)) -> 269397.3 | L34: =K34*'3 - Il costo opportunità'!$B$10/12 -> 673.49325 | N34: =FV('1 - Il tuo profilo'!$B$13,10,-D34*12) -> 2459.6972 | O34: =FV('1 - Il tuo profilo'!$B$13,'3 - Il costo opportunità'!$B$9,-D34*12) -> 10207.811 | P34: =O34*'3 - Il costo opportunità'!$B$10/12 -> 25.519528 | Q34: =FV('1 - Il tuo profilo'!$B$13,'3 - Il costo opportunità'!$B$9,-(I34),-('1 - Il tuo profilo'!$B$22)) -> 321270.34 | R34: =Q34*'3 - Il costo opportunità'!$B$10/12 -> 803.17585
A35: F10 | B35: Tenere l'auto di oggi 10 anni | C35: ='2 - Le opzioni'!$L$376 -> 320.79039 | D35: =C35-INDEX('3 - Il costo opportunità'!$C$26:$C$44,MATCH('3 - Il costo opportunità'!$B$6,'3 - Il costo opportunità'!$A$26:$A$44,0)) -> 14.83536 | E35: =SIGN(D35*12)*((((0)*INDEX('3 - Il costo opportunità'!$B$74:$B$134,(10)+1)+(ABS(D35*12))*INDEX('3 - Il costo opportunità'!$C$74:$C$134,(10)+1))-'3 - Il costo opportunità'!$B$8*MAX(0,((0)*INDEX('3 - Il costo opportunità'!$B$74:$B$134,(10)+1)+(ABS(D35*12))*INDEX('3 - Il costo opportunità'!$C$74:$C$134,(10)+1))-((0)+(ABS(D35*12))*INDEX('3 - Il costo opportunità'!$D$74:$D$134,(10)+1))))/(1+'1 - Il tuo profilo'!$B$14)^(10)) -> 1956.8203 | F35: =SIGN(D35*12)*((((0)*INDEX('3 - Il costo opportunità'!$B$74:$B$134,('3 - Il costo opportunità'!$B$9)+1)+(ABS(D35*12))*INDEX('3 - Il costo opportunità'!$C$74:$C$134,('3 - Il costo opportunità'!$B$9)+1))-'3 - Il costo opportunità'!$B$8*MAX(0,((0)*INDEX('3 - Il costo opportunità'!$B$74:$B$134,('3 - Il costo opportunità'!$B$9)+1)+(ABS(D35*12))*INDEX('3 - Il costo opportunità'!$C$74:$C$134,('3 - Il costo opportunità'!$B$9)+1))-((0)+(ABS(D35*12))*INDEX('3 - Il costo opportunità'!$D$74:$D$134,('3 - Il costo opportunità'!$B$9)+1))))/(1+'1 - Il tuo profilo'!$B$14)^('3 - Il costo opportunità'!$B$9)) -> 7410.847 | G35: =F35*'3 - Il costo opportunità'!$B$10/12 -> 18.527118 | H35: =('1 - Il tuo profilo'!$B$19+'1 - Il tuo profilo'!$B$20+'1 - Il tuo profilo'!$B$21)+C35*12 -> 23598.355 | I35: ='1 - Il tuo profilo'!$B$18-H35 -> 3728.2453 | J35: =I35/'1 - Il tuo profilo'!$B$18 -> 0.13643283 | K35: =(((('1 - Il tuo profilo'!$B$22)*INDEX('3 - Il costo opportunità'!$B$74:$B$134,('3 - Il costo opportunità'!$B$9)+1)+(I35)*INDEX('3 - Il costo opportunità'!$C$74:$C$134,('3 - Il costo opportunità'!$B$9)+1))-'3 - Il costo opportunità'!$B$8*MAX(0,(('1 - Il tuo profilo'!$B$22)*INDEX('3 - Il costo opportunità'!$B$74:$B$134,('3 - Il costo opportunità'!$B$9)+1)+(I35)*INDEX('3 - Il costo opportunità'!$C$74:$C$134,('3 - Il costo opportunità'!$B$9)+1))-(('1 - Il tuo profilo'!$B$22)+(I35)*INDEX('3 - Il costo opportunità'!$D$74:$D$134,('3 - Il costo opportunità'!$B$9)+1))))/(1+'1 - Il tuo profilo'!$B$14)^('3 - Il costo opportunità'!$B$9)) -> 270918.24 | L35: =K35*'3 - Il costo opportunità'!$B$10/12 -> 677.29561 | N35: =FV('1 - Il tuo profilo'!$B$13,10,-D35*12) -> 2040.8494 | O35: =FV('1 - Il tuo profilo'!$B$13,'3 - Il costo opportunità'!$B$9,-D35*12) -> 8469.5813 | P35: =O35*'3 - Il costo opportunità'!$B$10/12 -> 21.173953 | Q35: =FV('1 - Il tuo profilo'!$B$13,'3 - Il costo opportunità'!$B$9,-(I35),-('1 - Il tuo profilo'!$B$22)) -> 323008.57 | R35: =Q35*'3 - Il costo opportunità'!$B$10/12 -> 807.52142
A36: G | B36: Senza auto, città media | C36: ='2 - Le opzioni'!$L$414 -> 171.19237 | D36: =C36-INDEX('3 - Il costo opportunità'!$C$26:$C$44,MATCH('3 - Il costo opportunità'!$B$6,'3 - Il costo opportunità'!$A$26:$A$44,0)) -> -134.76266 | E36: =SIGN(D36*12)*((((0)*INDEX('3 - Il costo opportunità'!$B$74:$B$134,(10)+1)+(ABS(D36*12))*INDEX('3 - Il costo opportunità'!$C$74:$C$134,(10)+1))-'3 - Il costo opportunità'!$B$8*MAX(0,((0)*INDEX('3 - Il costo opportunità'!$B$74:$B$134,(10)+1)+(ABS(D36*12))*INDEX('3 - Il costo opportunità'!$C$74:$C$134,(10)+1))-((0)+(ABS(D36*12))*INDEX('3 - Il costo opportunità'!$D$74:$D$134,(10)+1))))/(1+'1 - Il tuo profilo'!$B$14)^(10)) -> -17775.524 | F36: =SIGN(D36*12)*((((0)*INDEX('3 - Il costo opportunità'!$B$74:$B$134,('3 - Il costo opportunità'!$B$9)+1)+(ABS(D36*12))*INDEX('3 - Il costo opportunità'!$C$74:$C$134,('3 - Il costo opportunità'!$B$9)+1))-'3 - Il costo opportunità'!$B$8*MAX(0,((0)*INDEX('3 - Il costo opportunità'!$B$74:$B$134,('3 - Il costo opportunità'!$B$9)+1)+(ABS(D36*12))*INDEX('3 - Il costo opportunità'!$C$74:$C$134,('3 - Il costo opportunità'!$B$9)+1))-((0)+(ABS(D36*12))*INDEX('3 - Il costo opportunità'!$D$74:$D$134,('3 - Il costo opportunità'!$B$9)+1))))/(1+'1 - Il tuo profilo'!$B$14)^('3 - Il costo opportunità'!$B$9)) -> -67319.256 | G36: =F36*'3 - Il costo opportunità'!$B$10/12 -> -168.29814 | H36: =('1 - Il tuo profilo'!$B$19+'1 - Il tuo profilo'!$B$20+'1 - Il tuo profilo'!$B$21)+C36*12 -> 21803.178 | I36: ='1 - Il tuo profilo'!$B$18-H36 -> 5523.4215 | J36: =I36/'1 - Il tuo profilo'!$B$18 -> 0.20212619 | K36: =(((('1 - Il tuo profilo'!$B$22)*INDEX('3 - Il costo opportunità'!$B$74:$B$134,('3 - Il costo opportunità'!$B$9)+1)+(I36)*INDEX('3 - Il costo opportunità'!$C$74:$C$134,('3 - Il costo opportunità'!$B$9)+1))-'3 - Il costo opportunità'!$B$8*MAX(0,(('1 - Il tuo profilo'!$B$22)*INDEX('3 - Il costo opportunità'!$B$74:$B$134,('3 - Il costo opportunità'!$B$9)+1)+(I36)*INDEX('3 - Il costo opportunità'!$C$74:$C$134,('3 - Il costo opportunità'!$B$9)+1))-(('1 - Il tuo profilo'!$B$22)+(I36)*INDEX('3 - Il costo opportunità'!$D$74:$D$134,('3 - Il costo opportunità'!$B$9)+1))))/(1+'1 - Il tuo profilo'!$B$14)^('3 - Il costo opportunità'!$B$9)) -> 345648.35 | L36: =K36*'3 - Il costo opportunità'!$B$10/12 -> 864.12087 | N36: =FV('1 - Il tuo profilo'!$B$13,10,-D36*12) -> -18538.834 | O36: =FV('1 - Il tuo profilo'!$B$13,'3 - Il costo opportunità'!$B$9,-D36*12) -> -76936.672 | P36: =O36*'3 - Il costo opportunità'!$B$10/12 -> -192.34168 | Q36: =FV('1 - Il tuo profilo'!$B$13,'3 - Il costo opportunità'!$B$9,-(I36),-('1 - Il tuo profilo'!$B$22)) -> 408414.82 | R36: =Q36*'3 - Il costo opportunità'!$B$10/12 -> 1021.0371
A37: C-ibr | B37: Nuova ibrida in contanti | C37: ='2 - Le opzioni'!$L$167 -> 344.01601 | D37: =C37-INDEX('3 - Il costo opportunità'!$C$26:$C$44,MATCH('3 - Il costo opportunità'!$B$6,'3 - Il costo opportunità'!$A$26:$A$44,0)) -> 38.060982 | E37: =SIGN(D37*12)*((((0)*INDEX('3 - Il costo opportunità'!$B$74:$B$134,(10)+1)+(ABS(D37*12))*INDEX('3 - Il costo opportunità'!$C$74:$C$134,(10)+1))-'3 - Il costo opportunità'!$B$8*MAX(0,((0)*INDEX('3 - Il costo opportunità'!$B$74:$B$134,(10)+1)+(ABS(D37*12))*INDEX('3 - Il costo opportunità'!$C$74:$C$134,(10)+1))-((0)+(ABS(D37*12))*INDEX('3 - Il costo opportunità'!$D$74:$D$134,(10)+1))))/(1+'1 - Il tuo profilo'!$B$14)^(10)) -> 5020.3365 | F37: =SIGN(D37*12)*((((0)*INDEX('3 - Il costo opportunità'!$B$74:$B$134,('3 - Il costo opportunità'!$B$9)+1)+(ABS(D37*12))*INDEX('3 - Il costo opportunità'!$C$74:$C$134,('3 - Il costo opportunità'!$B$9)+1))-'3 - Il costo opportunità'!$B$8*MAX(0,((0)*INDEX('3 - Il costo opportunità'!$B$74:$B$134,('3 - Il costo opportunità'!$B$9)+1)+(ABS(D37*12))*INDEX('3 - Il costo opportunità'!$C$74:$C$134,('3 - Il costo opportunità'!$B$9)+1))-((0)+(ABS(D37*12))*INDEX('3 - Il costo opportunità'!$D$74:$D$134,('3 - Il costo opportunità'!$B$9)+1))))/(1+'1 - Il tuo profilo'!$B$14)^('3 - Il costo opportunità'!$B$9)) -> 19012.96 | G37: =F37*'3 - Il costo opportunità'!$B$10/12 -> 47.5324 | H37: =('1 - Il tuo profilo'!$B$19+'1 - Il tuo profilo'!$B$20+'1 - Il tuo profilo'!$B$21)+C37*12 -> 23877.062 | I37: ='1 - Il tuo profilo'!$B$18-H37 -> 3449.5379 | J37: =I37/'1 - Il tuo profilo'!$B$18 -> 0.1262337 | K37: =(((('1 - Il tuo profilo'!$B$22)*INDEX('3 - Il costo opportunità'!$B$74:$B$134,('3 - Il costo opportunità'!$B$9)+1)+(I37)*INDEX('3 - Il costo opportunità'!$C$74:$C$134,('3 - Il costo opportunità'!$B$9)+1))-'3 - Il costo opportunità'!$B$8*MAX(0,(('1 - Il tuo profilo'!$B$22)*INDEX('3 - Il costo opportunità'!$B$74:$B$134,('3 - Il costo opportunità'!$B$9)+1)+(I37)*INDEX('3 - Il costo opportunità'!$C$74:$C$134,('3 - Il costo opportunità'!$B$9)+1))-(('1 - Il tuo profilo'!$B$22)+(I37)*INDEX('3 - Il costo opportunità'!$D$74:$D$134,('3 - Il costo opportunità'!$B$9)+1))))/(1+'1 - Il tuo profilo'!$B$14)^('3 - Il costo opportunità'!$B$9)) -> 259316.13 | L37: =K37*'3 - Il costo opportunità'!$B$10/12 -> 648.29033 | N37: =FV('1 - Il tuo profilo'!$B$13,10,-D37*12) -> 5235.918 | O37: =FV('1 - Il tuo profilo'!$B$13,'3 - Il costo opportunità'!$B$9,-D37*12) -> 21729.204 | P37: =O37*'3 - Il costo opportunità'!$B$10/12 -> 54.323011 | Q37: =FV('1 - Il tuo profilo'!$B$13,'3 - Il costo opportunità'!$B$9,-(I37),-('1 - Il tuo profilo'!$B$22)) -> 309748.95 | R37: =Q37*'3 - Il costo opportunità'!$B$10/12 -> 774.37237
A38: C-el | B38: Nuova elettrica in contanti, ricarica a casa | C38: ='2 - Le opzioni'!$L$186 -> 332.94133 | D38: =C38-INDEX('3 - Il costo opportunità'!$C$26:$C$44,MATCH('3 - Il costo opportunità'!$B$6,'3 - Il costo opportunità'!$A$26:$A$44,0)) -> 26.986305 | E38: =SIGN(D38*12)*((((0)*INDEX('3 - Il costo opportunità'!$B$74:$B$134,(10)+1)+(ABS(D38*12))*INDEX('3 - Il costo opportunità'!$C$74:$C$134,(10)+1))-'3 - Il costo opportunità'!$B$8*MAX(0,((0)*INDEX('3 - Il costo opportunità'!$B$74:$B$134,(10)+1)+(ABS(D38*12))*INDEX('3 - Il costo opportunità'!$C$74:$C$134,(10)+1))-((0)+(ABS(D38*12))*INDEX('3 - Il costo opportunità'!$D$74:$D$134,(10)+1))))/(1+'1 - Il tuo profilo'!$B$14)^(10)) -> 3559.5596 | F38: =SIGN(D38*12)*((((0)*INDEX('3 - Il costo opportunità'!$B$74:$B$134,('3 - Il costo opportunità'!$B$9)+1)+(ABS(D38*12))*INDEX('3 - Il costo opportunità'!$C$74:$C$134,('3 - Il costo opportunità'!$B$9)+1))-'3 - Il costo opportunità'!$B$8*MAX(0,((0)*INDEX('3 - Il costo opportunità'!$B$74:$B$134,('3 - Il costo opportunità'!$B$9)+1)+(ABS(D38*12))*INDEX('3 - Il costo opportunità'!$C$74:$C$134,('3 - Il costo opportunità'!$B$9)+1))-((0)+(ABS(D38*12))*INDEX('3 - Il costo opportunità'!$D$74:$D$134,('3 - Il costo opportunità'!$B$9)+1))))/(1+'1 - Il tuo profilo'!$B$14)^('3 - Il costo opportunità'!$B$9)) -> 13480.722 | G38: =F38*'3 - Il costo opportunità'!$B$10/12 -> 33.701806 | H38: =('1 - Il tuo profilo'!$B$19+'1 - Il tuo profilo'!$B$20+'1 - Il tuo profilo'!$B$21)+C38*12 -> 23744.166 | I38: ='1 - Il tuo profilo'!$B$18-H38 -> 3582.434 | J38: =I38/'1 - Il tuo profilo'!$B$18 -> 0.13109695 | K38: =(((('1 - Il tuo profilo'!$B$22)*INDEX('3 - Il costo opportunità'!$B$74:$B$134,('3 - Il costo opportunità'!$B$9)+1)+(I38)*INDEX('3 - Il costo opportunità'!$C$74:$C$134,('3 - Il costo opportunità'!$B$9)+1))-'3 - Il costo opportunità'!$B$8*MAX(0,(('1 - Il tuo profilo'!$B$22)*INDEX('3 - Il costo opportunità'!$B$74:$B$134,('3 - Il costo opportunità'!$B$9)+1)+(I38)*INDEX('3 - Il costo opportunità'!$C$74:$C$134,('3 - Il costo opportunità'!$B$9)+1))-(('1 - Il tuo profilo'!$B$22)+(I38)*INDEX('3 - Il costo opportunità'!$D$74:$D$134,('3 - Il costo opportunità'!$B$9)+1))))/(1+'1 - Il tuo profilo'!$B$14)^('3 - Il costo opportunità'!$B$9)) -> 264848.37 | L38: =K38*'3 - Il costo opportunità'!$B$10/12 -> 662.12092 | N38: =FV('1 - Il tuo profilo'!$B$13,10,-D38*12) -> 3712.4129 | O38: =FV('1 - Il tuo profilo'!$B$13,'3 - Il costo opportunità'!$B$9,-D38*12) -> 15406.616 | P38: =O38*'3 - Il costo opportunità'!$B$10/12 -> 38.51654 | Q38: =FV('1 - Il tuo profilo'!$B$13,'3 - Il costo opportunità'!$B$9,-(I38),-('1 - Il tuo profilo'!$B$22)) -> 316071.54 | R38: =Q38*'3 - Il costo opportunità'!$B$10/12 -> 790.17884
A39: C-el-pub | B39: Nuova elettrica in contanti, ricarica soprattutto alla colonnina | C39: ='2 - Le opzioni'!$L$205 -> 369.04593 | D39: =C39-INDEX('3 - Il costo opportunità'!$C$26:$C$44,MATCH('3 - Il costo opportunità'!$B$6,'3 - Il costo opportunità'!$A$26:$A$44,0)) -> 63.090905 | E39: =SIGN(D39*12)*((((0)*INDEX('3 - Il costo opportunità'!$B$74:$B$134,(10)+1)+(ABS(D39*12))*INDEX('3 - Il costo opportunità'!$C$74:$C$134,(10)+1))-'3 - Il costo opportunità'!$B$8*MAX(0,((0)*INDEX('3 - Il costo opportunità'!$B$74:$B$134,(10)+1)+(ABS(D39*12))*INDEX('3 - Il costo opportunità'!$C$74:$C$134,(10)+1))-((0)+(ABS(D39*12))*INDEX('3 - Il costo opportunità'!$D$74:$D$134,(10)+1))))/(1+'1 - Il tuo profilo'!$B$14)^(10)) -> 8321.8446 | F39: =SIGN(D39*12)*((((0)*INDEX('3 - Il costo opportunità'!$B$74:$B$134,('3 - Il costo opportunità'!$B$9)+1)+(ABS(D39*12))*INDEX('3 - Il costo opportunità'!$C$74:$C$134,('3 - Il costo opportunità'!$B$9)+1))-'3 - Il costo opportunità'!$B$8*MAX(0,((0)*INDEX('3 - Il costo opportunità'!$B$74:$B$134,('3 - Il costo opportunità'!$B$9)+1)+(ABS(D39*12))*INDEX('3 - Il costo opportunità'!$C$74:$C$134,('3 - Il costo opportunità'!$B$9)+1))-((0)+(ABS(D39*12))*INDEX('3 - Il costo opportunità'!$D$74:$D$134,('3 - Il costo opportunità'!$B$9)+1))))/(1+'1 - Il tuo profilo'!$B$14)^('3 - Il costo opportunità'!$B$9)) -> 31516.392 | G39: =F39*'3 - Il costo opportunità'!$B$10/12 -> 78.790981 | H39: =('1 - Il tuo profilo'!$B$19+'1 - Il tuo profilo'!$B$20+'1 - Il tuo profilo'!$B$21)+C39*12 -> 24177.421 | I39: ='1 - Il tuo profilo'!$B$18-H39 -> 3149.1788 | J39: =I39/'1 - Il tuo profilo'!$B$18 -> 0.11524225 | K39: =(((('1 - Il tuo profilo'!$B$22)*INDEX('3 - Il costo opportunità'!$B$74:$B$134,('3 - Il costo opportunità'!$B$9)+1)+(I39)*INDEX('3 - Il costo opportunità'!$C$74:$C$134,('3 - Il costo opportunità'!$B$9)+1))-'3 - Il costo opportunità'!$B$8*MAX(0,(('1 - Il tuo profilo'!$B$22)*INDEX('3 - Il costo opportunità'!$B$74:$B$134,('3 - Il costo opportunità'!$B$9)+1)+(I39)*INDEX('3 - Il costo opportunità'!$C$74:$C$134,('3 - Il costo opportunità'!$B$9)+1))-(('1 - Il tuo profilo'!$B$22)+(I39)*INDEX('3 - Il costo opportunità'!$D$74:$D$134,('3 - Il costo opportunità'!$B$9)+1))))/(1+'1 - Il tuo profilo'!$B$14)^('3 - Il costo opportunità'!$B$9)) -> 246812.7 | L39: =K39*'3 - Il costo opportunità'!$B$10/12 -> 617.03175 | N39: =FV('1 - Il tuo profilo'!$B$13,10,-D39*12) -> 8679.1982 | O39: =FV('1 - Il tuo profilo'!$B$13,'3 - Il costo opportunità'!$B$9,-D39*12) -> 36018.912 | P39: =O39*'3 - Il costo opportunità'!$B$10/12 -> 90.04728 | Q39: =FV('1 - Il tuo profilo'!$B$13,'3 - Il costo opportunità'!$B$9,-(I39),-('1 - Il tuo profilo'!$B$22)) -> 295459.24 | R39: =Q39*'3 - Il costo opportunità'!$B$10/12 -> 738.6481
A40: A-el | B40: Nuova elettrica a rate, ricarica a casa | C40: ='2 - Le opzioni'!$L$243 -> 359.35863 | D40: =C40-INDEX('3 - Il costo opportunità'!$C$26:$C$44,MATCH('3 - Il costo opportunità'!$B$6,'3 - Il costo opportunità'!$A$26:$A$44,0)) -> 53.403603 | E40: =SIGN(D40*12)*((((0)*INDEX('3 - Il costo opportunità'!$B$74:$B$134,(10)+1)+(ABS(D40*12))*INDEX('3 - Il costo opportunità'!$C$74:$C$134,(10)+1))-'3 - Il costo opportunità'!$B$8*MAX(0,((0)*INDEX('3 - Il costo opportunità'!$B$74:$B$134,(10)+1)+(ABS(D40*12))*INDEX('3 - Il costo opportunità'!$C$74:$C$134,(10)+1))-((0)+(ABS(D40*12))*INDEX('3 - Il costo opportunità'!$D$74:$D$134,(10)+1))))/(1+'1 - Il tuo profilo'!$B$14)^(10)) -> 7044.0658 | F40: =SIGN(D40*12)*((((0)*INDEX('3 - Il costo opportunità'!$B$74:$B$134,('3 - Il costo opportunità'!$B$9)+1)+(ABS(D40*12))*INDEX('3 - Il costo opportunità'!$C$74:$C$134,('3 - Il costo opportunità'!$B$9)+1))-'3 - Il costo opportunità'!$B$8*MAX(0,((0)*INDEX('3 - Il costo opportunità'!$B$74:$B$134,('3 - Il costo opportunità'!$B$9)+1)+(ABS(D40*12))*INDEX('3 - Il costo opportunità'!$C$74:$C$134,('3 - Il costo opportunità'!$B$9)+1))-((0)+(ABS(D40*12))*INDEX('3 - Il costo opportunità'!$D$74:$D$134,('3 - Il costo opportunità'!$B$9)+1))))/(1+'1 - Il tuo profilo'!$B$14)^('3 - Il costo opportunità'!$B$9)) -> 26677.204 | G40: =F40*'3 - Il costo opportunità'!$B$10/12 -> 66.693009 | H40: =('1 - Il tuo profilo'!$B$19+'1 - Il tuo profilo'!$B$20+'1 - Il tuo profilo'!$B$21)+C40*12 -> 24061.174 | I40: ='1 - Il tuo profilo'!$B$18-H40 -> 3265.4264 | J40: =I40/'1 - Il tuo profilo'!$B$18 -> 0.11949626 | K40: =(((('1 - Il tuo profilo'!$B$22)*INDEX('3 - Il costo opportunità'!$B$74:$B$134,('3 - Il costo opportunità'!$B$9)+1)+(I40)*INDEX('3 - Il costo opportunità'!$C$74:$C$134,('3 - Il costo opportunità'!$B$9)+1))-'3 - Il costo opportunità'!$B$8*MAX(0,(('1 - Il tuo profilo'!$B$22)*INDEX('3 - Il costo opportunità'!$B$74:$B$134,('3 - Il costo opportunità'!$B$9)+1)+(I40)*INDEX('3 - Il costo opportunità'!$C$74:$C$134,('3 - Il costo opportunità'!$B$9)+1))-(('1 - Il tuo profilo'!$B$22)+(I40)*INDEX('3 - Il costo opportunità'!$D$74:$D$134,('3 - Il costo opportunità'!$B$9)+1))))/(1+'1 - Il tuo profilo'!$B$14)^('3 - Il costo opportunità'!$B$9)) -> 251651.89 | L40: =K40*'3 - Il costo opportunità'!$B$10/12 -> 629.12972 | N40: =FV('1 - Il tuo profilo'!$B$13,10,-D40*12) -> 7346.5496 | O40: =FV('1 - Il tuo profilo'!$B$13,'3 - Il costo opportunità'!$B$9,-D40*12) -> 30488.384 | P40: =O40*'3 - Il costo opportunità'!$B$10/12 -> 76.220959 | Q40: =FV('1 - Il tuo profilo'!$B$13,'3 - Il costo opportunità'!$B$9,-(I40),-('1 - Il tuo profilo'!$B$22)) -> 300989.77 | R40: =Q40*'3 - Il costo opportunità'!$B$10/12 -> 752.47442
A41: E-el | B41: Noleggio a lungo termine, elettrica | C41: ='2 - Le opzioni'!$L$357 -> 434.20064 | D41: =C41-INDEX('3 - Il costo opportunità'!$C$26:$C$44,MATCH('3 - Il costo opportunità'!$B$6,'3 - Il costo opportunità'!$A$26:$A$44,0)) -> 128.24561 | E41: =SIGN(D41*12)*((((0)*INDEX('3 - Il costo opportunità'!$B$74:$B$134,(10)+1)+(ABS(D41*12))*INDEX('3 - Il costo opportunità'!$C$74:$C$134,(10)+1))-'3 - Il costo opportunità'!$B$8*MAX(0,((0)*INDEX('3 - Il costo opportunità'!$B$74:$B$134,(10)+1)+(ABS(D41*12))*INDEX('3 - Il costo opportunità'!$C$74:$C$134,(10)+1))-((0)+(ABS(D41*12))*INDEX('3 - Il costo opportunità'!$D$74:$D$134,(10)+1))))/(1+'1 - Il tuo profilo'!$B$14)^(10)) -> 16915.91 | F41: =SIGN(D41*12)*((((0)*INDEX('3 - Il costo opportunità'!$B$74:$B$134,('3 - Il costo opportunità'!$B$9)+1)+(ABS(D41*12))*INDEX('3 - Il costo opportunità'!$C$74:$C$134,('3 - Il costo opportunità'!$B$9)+1))-'3 - Il costo opportunità'!$B$8*MAX(0,((0)*INDEX('3 - Il costo opportunità'!$B$74:$B$134,('3 - Il costo opportunità'!$B$9)+1)+(ABS(D41*12))*INDEX('3 - Il costo opportunità'!$C$74:$C$134,('3 - Il costo opportunità'!$B$9)+1))-((0)+(ABS(D41*12))*INDEX('3 - Il costo opportunità'!$D$74:$D$134,('3 - Il costo opportunità'!$B$9)+1))))/(1+'1 - Il tuo profilo'!$B$14)^('3 - Il costo opportunità'!$B$9)) -> 64063.735 | G41: =F41*'3 - Il costo opportunità'!$B$10/12 -> 160.15934 | H41: =('1 - Il tuo profilo'!$B$19+'1 - Il tuo profilo'!$B$20+'1 - Il tuo profilo'!$B$21)+C41*12 -> 24959.278 | I41: ='1 - Il tuo profilo'!$B$18-H41 -> 2367.3223 | J41: =I41/'1 - Il tuo profilo'!$B$18 -> 0.086630694 | K41: =(((('1 - Il tuo profilo'!$B$22)*INDEX('3 - Il costo opportunità'!$B$74:$B$134,('3 - Il costo opportunità'!$B$9)+1)+(I41)*INDEX('3 - Il costo opportunità'!$C$74:$C$134,('3 - Il costo opportunità'!$B$9)+1))-'3 - Il costo opportunità'!$B$8*MAX(0,(('1 - Il tuo profilo'!$B$22)*INDEX('3 - Il costo opportunità'!$B$74:$B$134,('3 - Il costo opportunità'!$B$9)+1)+(I41)*INDEX('3 - Il costo opportunità'!$C$74:$C$134,('3 - Il costo opportunità'!$B$9)+1))-(('1 - Il tuo profilo'!$B$22)+(I41)*INDEX('3 - Il costo opportunità'!$D$74:$D$134,('3 - Il costo opportunità'!$B$9)+1))))/(1+'1 - Il tuo profilo'!$B$14)^('3 - Il costo opportunità'!$B$9)) -> 214265.36 | L41: =K41*'3 - Il costo opportunità'!$B$10/12 -> 535.66339 | N41: =FV('1 - Il tuo profilo'!$B$13,10,-D41*12) -> 17642.306 | O41: =FV('1 - Il tuo profilo'!$B$13,'3 - Il costo opportunità'!$B$9,-D41*12) -> 73216.059 | P41: =O41*'3 - Il costo opportunità'!$B$10/12 -> 183.04015 | Q41: =FV('1 - Il tuo profilo'!$B$13,'3 - Il costo opportunità'!$B$9,-(I41),-('1 - Il tuo profilo'!$B$22)) -> 258262.09 | R41: =Q41*'3 - Il costo opportunità'!$B$10/12 -> 645.65523
