Workbook

Sheet 0 - Indice
A1: Dividendo mensile: rendita o capitale che torna indietro? Il caso di Renata (caso inventato e illustrativo)
A2: Caso inventato e illustrativo, non è consulenza e non è una previsione. Fotografia di ottobre 2026, regole fiscali di oggi. Prima di decidere fai i conti sul tuo caso e parlane con professionisti abilitati.
A4: Indice
A5: 0 - Indice | B5: Questo indice
A6: 1 - Input | B6: Il caso di Renata e le ipotesi (celle gialle): capitale, spesa, distribuzione, quota Q, fisco, scenario
A7: 2 - Distribuzione | B7: Tre percorsi con distribuzione: caso atteso (Q = 0%), Q scelta, limite teorico (Q = 100%)
A8: 3 - Accumulo | B8: La stessa strategia ad accumulo, con sole vendite
A9: 4 - Confronto | B9: Confronto: durate, imposte, minusvalenze, capitale a 10 e 15 anni
A10: 5 - Annualizzatore | B10: Annualizzatore di uno stacco e quota che è capitale che torna indietro
A12: Come usare
A13: 1. Le celle GIALLE sono input — modificale coi tuoi numeri.
A14: 2. Le celle VERDI sono output — si aggiornano automaticamente.
A15: 3. Tutti i numeri di default sono al 2026 da fonti pubbliche.
A16: 4. Niente codice nascosto: l'Excel è solo formule modificabili.
A18: Fonti dati
A19: • Regole fiscali di ottobre 2026: D.L. 66/2014 (26%), D.P.R. 642/1972 (bollo), art. 10-ter L. 77/1983 (proventi dei fondi) (P)
A20: • Rimborso di capitale: Agenzia delle Entrate, risposta 161/2022 e circolare 33/E del 2011, per analogia su un fondo chiuso italiano (P)
A21: • Serie storica dell'indice a opzioni di acquisto coperte, 2002-2026, per gli scenari piatto, crollo e rialzo (P)
A22: • CALCOLI MIEI (E): il caso di Renata, il motore mensile, gli scenari. Gradi: P = fonte primaria, E = stima o calcolo mio
A24: Aggiornamenti: github.com/marcofire-it/marco-fire-simulatori
A25: Note e limiti
... A30: Il motore del calcolo è in fondo ai fogli 2 e 3: non modificare. Nessuna macro, solo formule.

Sheet 1 - Input
A1: Dividendo mensile: rendita o capitale che torna indietro? Il caso di Renata (caso inventato e illustrativo)
A2: Caso inventato e illustrativo, non è consulenza e non è una previsione. Fotografia di ottobre 2026, regole fiscali di oggi. Prima di decidere fai i conti sul tuo caso e parlane con professionisti abilitati.
A4: Input (celle gialle)
A5: Voce | B5: Valore | C5: Nota
A6: Capitale iniziale | B6: 486500 | C6: Capitale investito nel fondo al via.
A7: Spesa netta mensile | B7: 2700 | C7: Netta di imposta, in cassa, indicizzata all'inflazione. Il bollo è a parte.
A8: Distribuzione annua (% del valore) | B8: 0.09 | C8: Versata in dodici rate uguali a distribuzione/12, sul valore di fine mese.
A9: Quota Q: parte della distribuzione qualificata come rimborso di capitale | B9: 0 | C9: Dipende dalla delibera e dal rendiconto del fondo. 0% = tutto provento, tassato per intero. 100% = tutto rimborso: limite teorico, senza fonte per gli ETF esteri. Leggi il rendiconto.
A10: Aliquota sui proventi e sulle plusvalenze | B10: 0.26 | C10: Fotografia di ottobre 2026.
A11: Bollo annuo sul valore | B11: 0.002 | C11: Pagato a dicembre dal portafoglio, non sulla spesa.
A12: Inflazione (indicizzazione della spesa) | B12: 0.02 | C12: Ipotesi di base.
A13: Rendimento reale dell'ipotesi di base | B13: 0.03 | C13: Serve a generare il vettore dei rendimenti base e piatto.
A14: Orizzonte in anni (1-30) | B14: 30 | C14: Per i risultati a fine orizzonte del foglio 4.
A15: Costo fiscale diviso valore al via | B15: 1 | C15: Con una plusvalenza latente (meno di 100%) il percorso ad accumulo perde parte del vantaggio.
A16: Scenario (1-4) | B16: 1 | C16: 1 base, 2 piatto, 3 crollo al primo anno, 4 rialzo forte per tre anni.
A17: Integra con vendite (1 = sì, 0 = solo distribuzioni) | B17: 1 | C17: Con 0 si vede quanto vale la sola distribuzione.
... A20: Interruttore: senza imposte e senza bollo (1 = sì) | B20: 0 | C20: Con 1 aliquota e bollo valgono zero: serve a separare l'effetto del fisco.
A21: Parametri effettivi (formule)
A22: Aliquota effettiva | B22: =IF('1 - Input'!$B$20=1,0,'1 - Input'!$B$10) -> 0.26
A23: Bollo effettivo | B23: =IF('1 - Input'!$B$20=1,0,'1 - Input'!$B$11) -> 0.002
A25: Il vincolo aritmetico del caso
A26: Spesa netta annua | B26: =12*'1 - Input'!$B$7 -> 32400
A27: Prelievo lordo necessario (spesa annua diviso uno meno l'aliquota) | B27: =B26/(1-'1 - Input'!$B$10) -> 43783.784
A28: Il lordo necessario come distribuzione sul capitale | B28: =B27/'1 - Input'!$B$6 -> 0.0899975
A29: Spesa annua diviso capitale | B29: =B26/'1 - Input'!$B$6 -> 0.06659815
A30: Rendimento nominale dell'ipotesi di base | B30: =(1+'1 - Input'!$B$13)*(1+'1 - Input'!$B$12)-1 -> 0.0506
A31: Capitale con un prelievo del 3% (confronto indicativo: il tasso è lordo, la spesa è netta) | B31: =B26/0.03 -> 1080000
A32: Vettore dei rendimenti annui nominali (formule)
A33: Anno | B33: 1 - Base | C33: 2 - Piatto | D33: 3 - Crollo al via | E33: 4 - Rialzo forte
A34: 1 | B34: =(1+'1 - Input'!$B$13)*(1+'1 - Input'!$B$12)-1 -> 0.0506 | C34: ='1 - Input'!$B$12 -> 0.02 | D34: ='1 - Input'!$B$18 -> -0.28654676 | E34: ='1 - Input'!$B$19 -> 0.17386739
A35: 2 | B35: =(1+'1 - Input'!$B$13)*(1+'1 - Input'!$B$12)-1 -> 0.0506 | C35: ='1 - Input'!$B$12 -> 0.02 | D35: =$B$30 -> 0.0506 | E35: ='1 - Input'!$B$19 -> 0.17386739
A36: 3 | B36: =(1+'1 - Input'!$B$13)*(1+'1 - Input'!$B$12)-1 -> 0.0506 | C36: ='1 - Input'!$B$12 -> 0.02 | D36: =$B$30 -> 0.0506 | E36: ='1 - Input'!$B$19 -> 0.17386739
A37: 4 | B37: =(1+'1 - Input'!$B$13)*(1+'1 - Input'!$B$12)-1 -> 0.0506 | C37: ='1 - Input'!$B$12 -> 0.02 | D37: =$B$30 -> 0.0506 | E37: =$B$30 -> 0.0506
A38: 5 | B38: =(1+'1 - Input'!$B$13)*(1+'1 - Input'!$B$12)-1 -> 0.0506 | C38: ='1 - Input'!$B$12 -> 0.02 | D38: =$B$30 -> 0.0506 | E38: =$B$30 -> 0.0506
A39: 6 | B39: =(1+'1 - Input'!$B$13)*(1+'1 - Input'!$B$12)-1 -> 0.0506 | C39: ='1 - Input'!$B$12 -> 0.02 | D39: =$B$30 -> 0.0506 | E39: =$B$30 -> 0.0506
A40: 7 | B40: =(1+'1 - Input'!$B$13)*(1+'1 - Input'!$B$12)-1 -> 0.0506 | C40: ='1 - Input'!$B$12 -> 0.02 | D40: =$B$30 -> 0.0506 | E40: =$B$30 -> 0.0506
A41: 8 | B41: =(1+'1 - Input'!$B$13)*(1+'1 - Input'!$B$12)-1 -> 0.0506 | C41: ='1 - Input'!$B$12 -> 0.02 | D41: =$B$30 -> 0.0506 | E41: =$B$30 -> 0.0506
A42: 9 | B42: =(1+'1 - Input'!$B$13)*(1+'1 - Input'!$B$12)-1 -> 0.0506 | C42: ='1 - Input'!$B$12 -> 0.02 | D42: =$B$30 -> 0.0506 | E42: =$B$30 -> 0.0506
A43: 10 | B43: =(1+'1 - Input'!$B$13)*(1+'1 - Input'!$B$12)-1 -> 0.0506 | C43: ='1 - Input'!$B$12 -> 0.02 | D43: =$B$30 -> 0.0506 | E43: =$B$30 -> 0.0506
A44: 11 | B44: =(1+'1 - Input'!$B$13)*(1+'1 - Input'!$B$12)-1 -> 0.0506 | C44: ='1 - Input'!$B$12 -> 0.02 | D44: =$B$30 -> 0.0506 | E44: =$B$30 -> 0.0506
...

Sheet 2 - Distribuzione
A1: Dividendo mensile: rendita o capitale che torna indietro? Il caso di Renata (caso inventato e illustrativo)
A2: Caso inventato e illustrativo, non è consulenza e non è una previsione. Fotografia di ottobre 2026, regole fiscali di oggi. Prima di decidere fai i conti sul tuo caso e parlane con professionisti abilitati.
A3: Tre percorsi dello stesso motore mensile. La tabella annua è in alto, il motore del calcolo è in fondo (non modificare). Il blocco B è un limite teorico, senza fonte per gli ETF esteri.
A4: A: caso atteso, Q = 0% (tutto provento) | N4: U: Q scelta nel foglio 1 | AA4: B: limite teorico, senza fonte per gli ETF esteri, Q = 100%
A5: Anno | B5: Valore a fine anno (dopo bollo) | C5: Costo fiscale a fine anno | D5: Valore in euro di oggi | E5: Distribuzioni lorde | F5: Distribuzioni nette | G5: Imposte sulle distribuzioni | H5: Imposte sulle vendite | I5: Bollo | J5: Minusvalenze cumulate | K5: Spesa netta media al mese, euro correnti | L5: Spesa netta media al mese, euro di oggi | N5: Anno | O5: Valore a fine anno (dopo bollo) | P5: Costo fiscale a fine anno | Q5: Valore in euro di oggi | R5: Distribuzioni lorde | S5: Distribuzioni nette | T5: Imposte sulle distribuzioni | U5: Imposte sulle vendite | V5: Bollo | W5: Minusvalenze cumulate | X5: Spesa netta media al mese, euro correnti | Y5: Spesa netta media al mese, euro di oggi | AA5: Anno | AB5: Valore a fine anno (dopo bollo) | AC5: Costo fiscale a fine anno | AD5: Valore in euro di oggi | AE5: Distribuzioni lorde | AF5: Distribuzioni nette | AG5: Imposte sulle distribuzioni | AH5: Imposte sulle vendite | AI5: Bollo | AJ5: Minusvalenze cumulate | AK5: Spesa netta media al mese, euro correnti | AL5: Spesa netta media al mese, euro di oggi
A6: 1 | B6: =INDEX('2 - Distribuzione'!$Z$44:$Z$403,12*$A6) -> 465562.82 | C6: =INDEX('2 - Distribuzione'!$AA$44:$AA$403,12*$A6) -> 485036.76 | D6: =B6/(1+'1 - Input'!$B$12)^$A6 -> 456434.13 | E6: =SUMIFS('2 - Distribuzione'!$H$44:$H$403,'2 - Distribuzione'!$B$44:$B$403,$A6) -> 43140.785 | F6: =SUMIFS('2 - Distribuzione'!$L$44:$L$403,'2 - Distribuzione'!$B$44:$B$403,$A6) -> 31924.181 | G6: =SUMIFS('2 - Distribuzione'!$K$44:$K$403,'2 - Distribuzione'!$B$44:$B$403,$A6) -> 11216.604 | H6: =SUMIFS('2 - Distribuzione'!$S$44:$S$403,'2 - Distribuzione'!$B$44:$B$403,$A6) -> 0 | I6: =SUMIFS('2 - Distribuzione'!$Y$44:$Y$403,'2 - Distribuzione'!$B$44:$B$403,$A6) -> 932.99161 | J6: =INDEX('2 - Distribuzione'!$AF$44:$AF$403,12*$A6) -> 15.398999 | K6: =SUMIFS('2 - Distribuzione'!$AB$44:$AB$403,'2 - Distribuzione'!$B$44:$B$403,$A6)/12 -> 2700 | L6: =K6/(1+'1 - Input'!$B$12)^($A6-0.5) -> 2673.3984 | N6: 1 | O6: =INDEX('2 - Distribuzione'!$BJ$44:$BJ$403,12*$N6) -> 465562.82 | P6: =INDEX('2 - Distribuzione'!$BK$44:$BK$403,12*$N6) -> 485036.76 | Q6: =O6/(1+'1 - Input'!$B$12)^$N6 -> 456434.13 | R6: =SUMIFS('2 - Distribuzione'!$AR$44:$AR$403,'2 - Distribuzione'!$AL$44:$AL$403,$N6) -> 43140.785 | S6: =SUMIFS('2 - Distribuzione'!$AV$44:$AV$403,'2 - Distribuzione'!$AL$44:$AL$403,$N6) -> 31924.181 | T6: =SUMIFS('2 - Distribuzione'!$AU$44:$AU$403,'2 - Distribuzione'!$AL$44:$AL$403,$N6) -> 11216.604 | U6: =SUMIFS('2 - Distribuzione'!$BC$44:$BC$403,'2 - Distribuzione'!$AL$44:$AL$403,$N6) -> 0 | V6: =SUMIFS('2 - Distribuzione'!$BI$44:$BI$403,'2 - Distribuzione'!$AL$44:$AL$403,$N6) -> 932.99161 | W6: =INDEX('2 - Distribuzione'!$BP$44:$BP$403,12*$N6) -> 15.398999 | X6: =SUMIFS('2 - Distribuzione'!$BL$44:$BL$403,'2 - Distribuzione'!$AL$44:$AL$403,$N6)/12 -> 2700 | Y6: =X6/(1+'1 - Input'!$B$12)^($N6-0.5) -> 2673.3984 | AA6: 1 | AB6: =INDEX('2 - Distribuzione'!$CT$44:$CT$403,12*$AA6) -> 477016.24 | AC6: =INDEX('2 - Distribuzione'!$CU$44:$CU$403,12*$AA6) -> 453191.8 | AD6: =AB6/(1+'1 - Input'!$B$12)^$AA6 -> 467662.98 | AE6: =SUMIFS('2 - Distribuzione'!$CB$44:$CB$403,'2 - Distribuzione'!$BV$44:$BV$403,$AA6) -> 43615.404 | AF6: =SUMIFS('2 - Distribuzione'!$CF$44:$CF$403,'2 - Distribuzione'!$BV$44:$BV$403,$AA6) -> 43615.404 | AG6: =SUMIFS('2 - Distribuzione'!$CE$44:$CE$403,'2 - Distribuzione'!$BV$44:$BV$403,$AA6) -> 0 | AH6: =SUMIFS('2 - Distribuzione'!$CM$44:$CM$403,'2 - Distribuzione'!$BV$44:$BV$403,$AA6) -> 0 | AI6: =SUMIFS('2 - Distribuzione'!$CS$44:$CS$403,'2 - Distribuzione'!$BV$44:$BV$403,$AA6) -> 955.94437 | AJ6: =INDEX('2 - Distribuzione'!$CZ$44:$CZ$403,12*$AA6) -> 0 | AK6: =SUMIFS('2 - Distribuzione'!$CV$44:$CV$403,'2 - Distribuzione'!$BV$44:$BV$403,$AA6)/12 -> 2700 | AL6: =AK6/(1+'1 - Input'!$B$12)^($AA6-0.5) -> 2673.3984
A7: 2 | B7: =INDEX('2 - Distribuzione'!$Z$44:$Z$403,12*$A7) -> 443463.96 | C7: =INDEX('2 - Distribuzione'!$AA$44:$AA$403,12*$A7) -> 481339.08 | D7: =B7/(1+'1 - Input'!$B$12)^$A7 -> 426243.72 | E7: =SUMIFS('2 - Distribuzione'!$H$44:$H$403,'2 - Distribuzione'!$B$44:$B$403,$A7) -> 41198.954 | F7: =SUMIFS('2 - Distribuzione'!$L$44:$L$403,'2 - Distribuzione'!$B$44:$B$403,$A7) -> 30487.226 | G7: =SUMIFS('2 - Distribuzione'!$K$44:$K$403,'2 - Distribuzione'!$B$44:$B$403,$A7) -> 10711.728 | H7: =SUMIFS('2 - Distribuzione'!$S$44:$S$403,'2 - Distribuzione'!$B$44:$B$403,$A7) -> 0 | I7: =SUMIFS('2 - Distribuzione'!$Y$44:$Y$403,'2 - Distribuzione'!$B$44:$B$403,$A7) -> 888.70534 | J7: =INDEX('2 - Distribuzione'!$AF$44:$AF$403,12*$A7) -> 187.70039 | K7: =SUMIFS('2 - Distribuzione'!$AB$44:$AB$403,'2 - Distribuzione'!$B$44:$B$403,$A7)/12 -> 2754 | L7: =K7/(1+'1 - Input'!$B$12)^($A7-0.5) -> 2673.3984 | N7: 2 | O7: =INDEX('2 - Distribuzione'!$BJ$44:$BJ$403,12*$N7) -> 443463.96 | P7: =INDEX('2 - Distribuzione'!$BK$44:$BK$403,12*$N7) -> 481339.08 | Q7: =O7/(1+'1 - Input'!$B$12)^$N7 -> 426243.72 | R7: =SUMIFS('2 - Distribuzione'!$AR$44:$AR$403,'2 - Distribuzione'!$AL$44:$AL$403,$N7) -> 41198.954 | S7: =SUMIFS('2 - Distribuzione'!$AV$44:$AV$403,'2 - Distribuzione'!$AL$44:$AL$403,$N7) -> 30487.226 | T7: =SUMIFS('2 - Distribuzione'!$AU$44:$AU$403,'2 - Distribuzione'!$AL$44:$AL$403,$N7) -> 10711.728 | U7: =SUMIFS('2 - Distribuzione'!$BC$44:$BC$403,'2 - Distribuzione'!$AL$44:$AL$403,$N7) -> 0 | V7: =SUMIFS('2 - Distribuzione'!$BI$44:$BI$403,'2 - Distribuzione'!$AL$44:$AL$403,$N7) -> 888.70534 | W7: =INDEX('2 - Distribuzione'!$BP$44:$BP$403,12*$N7) -> 187.70039 | X7: =SUMIFS('2 - Distribuzione'!$BL$44:$BL$403,'2 - Distribuzione'!$AL$44:$AL$403,$N7)/12 -> 2754 | Y7: =X7/(1+'1 - Input'!$B$12)^($N7-0.5) -> 2673.3984 | AA7: 2 | AB7: =INDEX('2 - Distribuzione'!$CT$44:$CT$403,12*$AA7) -> 466410.97 | AC7: =INDEX('2 - Distribuzione'!$CU$44:$CU$403,12*$AA7) -> 419303.51 | AD7: =AB7/(1+'1 - Input'!$B$12)^$AA7 -> 448299.66 | AE7: =SUMIFS('2 - Distribuzione'!$CB$44:$CB$403,'2 - Distribuzione'!$BV$44:$BV$403,$AA7) -> 42711.436 | AF7: =SUMIFS('2 - Distribuzione'!$CF$44:$CF$403,'2 - Distribuzione'!$BV$44:$BV$403,$AA7) -> 42711.436 | AG7: =SUMIFS('2 - Distribuzione'!$CE$44:$CE$403,'2 - Distribuzione'!$BV$44:$BV$403,$AA7) -> 0 | AH7: =SUMIFS('2 - Distribuzione'!$CM$44:$CM$403,'2 - Distribuzione'!$BV$44:$BV$403,$AA7) -> 0 | AI7: =SUMIFS('2 - Distribuzione'!$CS$44:$CS$403,'2 - Distribuzione'!$BV$44:$BV$403,$AA7) -> 934.69131 | AJ7: =INDEX('2 - Distribuzione'!$CZ$44:$CZ$403,12*$AA7) -> 0 | AK7: =SUMIFS('2 - Distribuzione'!$CV$44:$CV$403,'2 - Distribuzione'!$BV$44:$BV$403,$AA7)/12 -> 2754 | AL7: =AK7/(1+'1 - Input'!$B$12)^($AA7-0.5) -> 2673.3984
A8: 3 | B8: =INDEX('2 - Distribuzione'!$Z$44:$Z$403,12*$A8) -> 420162.21 | C8: =INDEX('2 - Distribuzione'!$AA$44:$AA$403,12*$A8) -> 475123.16 | D8: =B8/(1+'1 - Input'!$B$12)^$A8 -> 395928.24 | E8: =SUMIFS('2 - Distribuzione'!$H$44:$H$403,'2 - Distribuzione'!$B$44:$B$403,$A8) -> 39150.344 | F8: =SUMIFS('2 - Distribuzione'!$L$44:$L$403,'2 - Distribuzione'!$B$44:$B$403,$A8) -> 28971.254 | G8: =SUMIFS('2 - Distribuzione'!$K$44:$K$403,'2 - Distribuzione'!$B$44:$B$403,$A8) -> 10179.089 | H8: =SUMIFS('2 - Distribuzione'!$S$44:$S$403,'2 - Distribuzione'!$B$44:$B$403,$A8) -> 0 | I8: =SUMIFS('2 - Distribuzione'!$Y$44:$Y$403,'2 - Distribuzione'!$B$44:$B$403,$A8) -> 842.00845 | J8: =INDEX('2 - Distribuzione'!$AF$44:$AF$403,12*$A8) -> 713.76468 | K8: =SUMIFS('2 - Distribuzione'!$AB$44:$AB$403,'2 - Distribuzione'!$B$44:$B$403,$A8)/12 -> 2809.08 | L8: =K8/(1+'1 - Input'!$B$12)^($A8-0.5) -> 2673.3984 | N8: 3 | O8: =INDEX('2 - Distribuzione'!$BJ$44:$BJ$403,12*$N8) -> 420162.21 | P8: =INDEX('2 - Distribuzione'!$BK$44:$BK$403,12*$N8) -> 475123.16 | Q8: =O8/(1+'1 - Input'!$B$12)^$N8 -> 395928.24 | R8: =SUMIFS('2 - Distribuzione'!$AR$44:$AR$403,'2 - Distribuzione'!$AL$44:$AL$403,$N8) -> 39150.344 | S8: =SUMIFS('2 - Distribuzione'!$AV$44:$AV$403,'2 - Distribuzione'!$AL$44:$AL$403,$N8) -> 28971.254 | T8: =SUMIFS('2 - Distribuzione'!$AU$44:$AU$403,'2 - Distribuzione'!$AL$44:$AL$403,$N8) -> 10179.089 | U8: =SUMIFS('2 - Distribuzione'!$BC$44:$BC$403,'2 - Distribuzione'!$AL$44:$AL$403,$N8) -> 0 | V8: =SUMIFS('2 - Distribuzione'!$BI$44:$BI$403,'2 - Distribuzione'!$AL$44:$AL$403,$N8) -> 842.00845 | W8: =INDEX('2 - Distribuzione'!$BP$44:$BP$403,12*$N8) -> 713.76468 | X8: =SUMIFS('2 - Distribuzione'!$BL$44:$BL$403,'2 - Distribuzione'!$AL$44:$AL$403,$N8)/12 -> 2809.08 | Y8: =X8/(1+'1 - Input'!$B$12)^($N8-0.5) -> 2673.3984 | AA8: 3 | AB8: =INDEX('2 - Distribuzione'!$CT$44:$CT$403,12*$AA8) -> 454616.55 | AC8: =INDEX('2 - Distribuzione'!$CU$44:$CU$403,12*$AA8) -> 384823.36 | AD8: =AB8/(1+'1 - Input'!$B$12)^$AA8 -> 428395.32 | AE8: =SUMIFS('2 - Distribuzione'!$CB$44:$CB$403,'2 - Distribuzione'!$BV$44:$BV$403,$AA8) -> 41703.241 | AF8: =SUMIFS('2 - Distribuzione'!$CF$44:$CF$403,'2 - Distribuzione'!$BV$44:$BV$403,$AA8) -> 41703.241 | AG8: =SUMIFS('2 - Distribuzione'!$CE$44:$CE$403,'2 - Distribuzione'!$BV$44:$BV$403,$AA8) -> 0 | AH8: =SUMIFS('2 - Distribuzione'!$CM$44:$CM$403,'2 - Distribuzione'!$BV$44:$BV$403,$AA8) -> 0 | AI8: =SUMIFS('2 - Distribuzione'!$CS$44:$CS$403,'2 - Distribuzione'!$BV$44:$BV$403,$AA8) -> 911.0552 | AJ8: =INDEX('2 - Distribuzione'!$CZ$44:$CZ$403,12*$AA8) -> 0 | AK8: =SUMIFS('2 - Distribuzione'!$CV$44:$CV$403,'2 - Distribuzione'!$BV$44:$BV$403,$AA8)/12 -> 2809.08 | AL8: =AK8/(1+'1 - Input'!$B$12)^($AA8-0.5) -> 2673.3984
A9: 4 | B9: =INDEX('2 - Distribuzione'!$Z$44:$Z$403,12*$A9) -> 395615.07 | C9: =INDEX('2 - Distribuzione'!$AA$44:$AA$403,12*$A9) -> 466077.84 | D9: =B9/(1+'1 - Input'!$B$12)^$A9 -> 365487.18 | E9: =SUMIFS('2 - Distribuzione'!$H$44:$H$403,'2 - Distribuzione'!$B$44:$B$403,$A9) -> 36991.171 | F9: =SUMIFS('2 - Distribuzione'!$L$44:$L$403,'2 - Distribuzione'!$B$44:$B$403,$A9) -> 27373.467 | G9: =SUMIFS('2 - Distribuzione'!$K$44:$K$403,'2 - Distribuzione'!$B$44:$B$403,$A9) -> 9617.7045 | H9: =SUMIFS('2 - Distribuzione'!$S$44:$S$403,'2 - Distribuzione'!$B$44:$B$403,$A9) -> 0 | I9: =SUMIFS('2 - Distribuzione'!$Y$44:$Y$403,'2 - Distribuzione'!$B$44:$B$403,$A9) -> 792.81578 | J9: =INDEX('2 - Distribuzione'!$AF$44:$AF$403,12*$A9) -> 1815.3853 | K9: =SUMIFS('2 - Distribuzione'!$AB$44:$AB$403,'2 - Distribuzione'!$B$44:$B$403,$A9)/12 -> 2865.2616 | L9: =K9/(1+'1 - Input'!$B$12)^($A9-0.5) -> 2673.3984 | N9: 4 | O9: =INDEX('2 - Distribuzione'!$BJ$44:$BJ$403,12*$N9) -> 395615.07 | P9: =INDEX('2 - Distribuzione'!$BK$44:$BK$403,12*$N9) -> 466077.84 | Q9: =O9/(1+'1 - Input'!$B$12)^$N9 -> 365487.18 | R9: =SUMIFS('2 - Distribuzione'!$AR$44:$AR$403,'2 - Distribuzione'!$AL$44:$AL$403,$N9) -> 36991.171 | S9: =SUMIFS('2 - Distribuzione'!$AV$44:$AV$403,'2 - Distribuzione'!$AL$44:$AL$403,$N9) -> 27373.467 | T9: =SUMIFS('2 - Distribuzione'!$AU$44:$AU$403,'2 - Distribuzione'!$AL$44:$AL$403,$N9) -> 9617.7045 | U9: =SUMIFS('2 - Distribuzione'!$BC$44:$BC$403,'2 - Distribuzione'!$AL$44:$AL$403,$N9) -> 0 | V9: =SUMIFS('2 - Distribuzione'!$BI$44:$BI$403,'2 - Distribuzione'!$AL$44:$AL$403,$N9) -> 792.81578 | W9: =INDEX('2 - Distribuzione'!$BP$44:$BP$403,12*$N9) -> 1815.3853 | X9: =SUMIFS('2 - Distribuzione'!$BL$44:$BL$403,'2 - Distribuzione'!$AL$44:$AL$403,$N9)/12 -> 2865.2616 | Y9: =X9/(1+'1 - Input'!$B$12)^($N9-0.5) -> 2673.3984 | AA9: 4 | AB9: =INDEX('2 - Distribuzione'!$CT$44:$CT$403,12*$AA9) -> 441561.81 | AC9: =INDEX('2 - Distribuzione'!$CU$44:$CU$403,12*$AA9) -> 349739.34 | AD9: =AB9/(1+'1 - Input'!$B$12)^$AA9 -> 407934.86 | AE9: =SUMIFS('2 - Distribuzione'!$CB$44:$CB$403,'2 - Distribuzione'!$BV$44:$BV$403,$AA9) -> 40584.557 | AF9: =SUMIFS('2 - Distribuzione'!$CF$44:$CF$403,'2 - Distribuzione'!$BV$44:$BV$403,$AA9) -> 40584.557 | AG9: =SUMIFS('2 - Distribuzione'!$CE$44:$CE$403,'2 - Distribuzione'!$BV$44:$BV$403,$AA9) -> 0 | AH9: =SUMIFS('2 - Distribuzione'!$CM$44:$CM$403,'2 - Distribuzione'!$BV$44:$BV$403,$AA9) -> 0 | AI9: =SUMIFS('2 - Distribuzione'!$CS$44:$CS$403,'2 - Distribuzione'!$BV$44:$BV$403,$AA9) -> 884.89341 | AJ9: =INDEX('2 - Distribuzione'!$CZ$44:$CZ$403,12*$AA9) -> 0 | AK9: =SUMIFS('2 - Distribuzione'!$CV$44:$CV$403,'2 - Distribuzione'!$BV$44:$BV$403,$AA9)/12 -> 2865.2616 | AL9: =AK9/(1+'1 - Input'!$B$12)^($AA9-0.5) -> 2673.3984
A10: 5 | B10: =INDEX('2 - Distribuzione'!$Z$44:$Z$403,12*$A10) -> 369778.76 | C10: =INDEX('2 - Distribuzione'!$AA$44:$AA$403,12*$A10) -> 453862.19 | D10: =B10/(1+'1 - Input'!$B$12)^$A10 -> 334920.01 | E10: =SUMIFS('2 - Distribuzione'!$H$44:$H$403,'2 - Distribuzione'!$B$44:$B$403,$A10) -> 34717.54 | F10: =SUMIFS('2 - Distribuzione'!$L$44:$L$403,'2 - Distribuzione'!$B$44:$B$403,$A10) -> 25690.98 | G10: =SUMIFS('2 - Distribuzione'!$K$44:$K$403,'2 - Distribuzione'!$B$44:$B$403,$A10) -> 9026.5605 | H10: =SUMIFS('2 - Distribuzione'!$S$44:$S$403,'2 - Distribuzione'!$B$44:$B$403,$A10) -> 0 | I10: =SUMIFS('2 - Distribuzione'!$Y$44:$Y$403,'2 - Distribuzione'!$B$44:$B$403,$A10) -> 741.03959 | J10: =INDEX('2 - Distribuzione'!$AF$44:$AF$403,12*$A10) -> 3741.6746 | K10: =SUMIFS('2 - Distribuzione'!$AB$44:$AB$403,'2 - Distribuzione'!$B$44:$B$403,$A10)/12 -> 2922.5668 | L10: =K10/(1+'1 - Input'!$B$12)^($A10-0.5) -> 2673.3984 | N10: 5 | O10: =INDEX('2 - Distribuzione'!$BJ$44:$BJ$403,12*$N10) -> 369778.76 | P10: =INDEX('2 - Distribuzione'!$BK$44:$BK$403,12*$N10) -> 453862.19 | Q10: =O10/(1+'1 - Input'!$B$12)^$N10 -> 334920.01 | R10: =SUMIFS('2 - Distribuzione'!$AR$44:$AR$403,'2 - Distribuzione'!$AL$44:$AL$403,$N10) -> 34717.54 | S10: =SUMIFS('2 - Distribuzione'!$AV$44:$AV$403,'2 - Distribuzione'!$AL$44:$AL$403,$N10) -> 25690.98 | T10: =SUMIFS('2 - Distribuzione'!$AU$44:$AU$403,'2 - Distribuzione'!$AL$44:$AL$403,$N10) -> 9026.5605 | U10: =SUMIFS('2 - Distribuzione'!$BC$44:$BC$403,'2 - Distribuzione'!$AL$44:$AL$403,$N10) -> 0 | V10: =SUMIFS('2 - Distribuzione'!$BI$44:$BI$403,'2 - Distribuzione'!$AL$44:$AL$403,$N10) -> 741.03959 | W10: =INDEX('2 - Distribuzione'!$BP$44:$BP$403,12*$N10) -> 3741.6746 | X10: =SUMIFS('2 - Distribuzione'!$BL$44:$BL$403,'2 - Distribuzione'!$AL$44:$AL$403,$N10)/12 -> 2922.5668 | Y10: =X10/(1+'1 - Input'!$B$12)^($N10-0.5) -> 2673.3984 | AA10: 5 | AB10: =INDEX('2 - Distribuzione'!$CT$44:$CT$403,12*$AA10) -> 427171.88 | AC10: =INDEX('2 - Distribuzione'!$CU$44:$CU$403,12*$AA10) -> 314039.2 | AD10: =AB10/(1+'1 - Input'!$B$12)^$AA10 -> 386902.73 | AE10: =SUMIFS('2 - Distribuzione'!$CB$44:$CB$403,'2 - Distribuzione'!$BV$44:$BV$403,$AA10) -> 39348.793 | AF10: =SUMIFS('2 - Distribuzione'!$CF$44:$CF$403,'2 - Distribuzione'!$BV$44:$BV$403,$AA10) -> 39348.793 | AG10: =SUMIFS('2 - Distribuzione'!$CE$44:$CE$403,'2 - Distribuzione'!$BV$44:$BV$403,$AA10) -> 0 | AH10: =SUMIFS('2 - Distribuzione'!$CM$44:$CM$403,'2 - Distribuzione'!$BV$44:$BV$403,$AA10) -> 0 | AI10: =SUMIFS('2 - Distribuzione'!$CS$44:$CS$403,'2 - Distribuzione'!$BV$44:$BV$403,$AA10) -> 856.05588 | AJ10: =INDEX('2 - Distribuzione'!$CZ$44:$CZ$403,12*$AA10) -> 0 | AK10: =SUMIFS('2 - Distribuzione'!$CV$44:$CV$403,'2 - Distribuzione'!$BV$44:$BV$403,$AA10)/12 -> 2922.5668 | AL10: =AK10/(1+'1 - Input'!$B$12)^($AA10-0.5) -> 2673.3984
A11: 6 | B11: =INDEX('2 - Distribuzione'!$Z$44:$Z$403,12*$A11) -> 342608.14 | C11: =INDEX('2 - Distribuzione'!$AA$44:$AA$403,12*$A11) -> 438102.91 | D11: =B11/(1+'1 - Input'!$B$12)^$A11 -> 304226.22 | E11: =SUMIFS('2 - Distribuzione'!$H$44:$H$403,'2 - Distribuzione'!$B$44:$B$403,$A11) -> 32325.434 | F11: =SUMIFS('2 - Distribuzione'!$L$44:$L$403,'2 - Distribuzione'!$B$44:$B$403,$A11) -> 23920.821 | G11: =SUMIFS('2 - Distribuzione'!$K$44:$K$403,'2 - Distribuzione'!$B$44:$B$403,$A11) -> 8404.613 | H11: =SUMIFS('2 - Distribuzione'!$S$44:$S$403,'2 - Distribuzione'!$B$44:$B$403,$A11) -> 0 | I11: =SUMIFS('2 - Distribuzione'!$Y$44:$Y$403,'2 - Distribuzione'!$B$44:$B$403,$A11) -> 686.58946 | J11: =INDEX('2 - Distribuzione'!$AF$44:$AF$403,12*$A11) -> 6771.5916 | K11: =SUMIFS('2 - Distribuzione'!$AB$44:$AB$403,'2 - Distribuzione'!$B$44:$B$403,$A11)/12 -> 2981.0182 | L11: =K11/(1+'1 - Input'!$B$12)^($A11-0.5) -> 2673.3984 | N11: 6 | O11: =INDEX('2 - Distribuzione'!$BJ$44:$BJ$403,12*$N11) -> 342608.14 | P11: =INDEX('2 - Distribuzione'!$BK$44:$BK$403,12*$N11) -> 438102.91 | Q11: =O11/(1+'1 - Input'!$B$12)^$N11 -> 304226.22 | R11: =SUMIFS('2 - Distribuzione'!$AR$44:$AR$403,'2 - Distribuzione'!$AL$44:$AL$403,$N11) -> 32325.434 | S11: =SUMIFS('2 - Distribuzione'!$AV$44:$AV$403,'2 - Distribuzione'!$AL$44:$AL$403,$N11) -> 23920.821 | T11: =SUMIFS('2 - Distribuzione'!$AU$44:$AU$403,'2 - Distribuzione'!$AL$44:$AL$403,$N11) -> 8404.613 | U11: =SUMIFS('2 - Distribuzione'!$BC$44:$BC$403,'2 - Distribuzione'!$AL$44:$AL$403,$N11) -> 0 | V11: =SUMIFS('2 - Distribuzione'!$BI$44:$BI$403,'2 - Distribuzione'!$AL$44:$AL$403,$N11) -> 686.58946 | W11: =INDEX('2 - Distribuzione'!$BP$44:$BP$403,12*$N11) -> 6771.5916 | X11: =SUMIFS('2 - Distribuzione'!$BL$44:$BL$403,'2 - Distribuzione'!$AL$44:$AL$403,$N11)/12 -> 2981.0182 | Y11: =X11/(1+'1 - Input'!$B$12)^($N11-0.5) -> 2673.3984 | AA11: 6 | AB11: =INDEX('2 - Distribuzione'!$CT$44:$CT$403,12*$AA11) -> 411367.95 | AC11: =INDEX('2 - Distribuzione'!$CU$44:$CU$403,12*$AA11) -> 277710.45 | AD11: =AB11/(1+'1 - Input'!$B$12)^$AA11 -> 365282.97 | AE11: =SUMIFS('2 - Distribuzione'!$CB$44:$CB$403,'2 - Distribuzione'!$BV$44:$BV$403,$AA11) -> 37989.015 | AF11: =SUMIFS('2 - Distribuzione'!$CF$44:$CF$403,'2 - Distribuzione'!$BV$44:$BV$403,$AA11) -> 37989.015 | AG11: =SUMIFS('2 - Distribuzione'!$CE$44:$CE$403,'2 - Distribuzione'!$BV$44:$BV$403,$AA11) -> 0 | AH11: =SUMIFS('2 - Distribuzione'!$CM$44:$CM$403,'2 - Distribuzione'!$BV$44:$BV$403,$AA11) -> 0 | AI11: =SUMIFS('2 - Distribuzione'!$CS$44:$CS$403,'2 - Distribuzione'!$BV$44:$BV$403,$AA11) -> 824.38468 | AJ11: =INDEX('2 - Distribuzione'!$CZ$44:$CZ$403,12*$AA11) -> 0 | AK11: =SUMIFS('2 - Distribuzione'!$CV$44:$CV$403,'2 - Distribuzione'!$BV$44:$BV$403,$AA11)/12 -> 2981.0182 | AL11: =AK11/(1+'1 - Input'!$B$12)^($AA11-0.5) -> 2673.3984
A12: 7 | B12: =INDEX('2 - Distribuzione'!$Z$44:$Z$403,12*$A12) -> 314056.73 | C12: =INDEX('2 - Distribuzione'!$AA$44:$AA$403,12*$A12) -> 418391.63 | D12: =B12/(1+'1 - Input'!$B$12)^$A12 -> 273405.29 | E12: =SUMIFS('2 - Distribuzione'!$H$44:$H$403,'2 - Distribuzione'!$B$44:$B$403,$A12) -> 29810.716 | F12: =SUMIFS('2 - Distribuzione'!$L$44:$L$403,'2 - Distribuzione'!$B$44:$B$403,$A12) -> 22059.93 | G12: =SUMIFS('2 - Distribuzione'!$K$44:$K$403,'2 - Distribuzione'!$B$44:$B$403,$A12) -> 7750.7862 | H12: =SUMIFS('2 - Distribuzione'!$S$44:$S$403,'2 - Distribuzione'!$B$44:$B$403,$A12) -> 0 | I12: =SUMIFS('2 - Distribuzione'!$Y$44:$Y$403,'2 - Distribuzione'!$B$44:$B$403,$A12) -> 629.37221 | J12: =INDEX('2 - Distribuzione'!$AF$44:$AF$403,12*$A12) -> 11216.679 | K12: =SUMIFS('2 - Distribuzione'!$AB$44:$AB$403,'2 - Distribuzione'!$B$44:$B$403,$A12)/12 -> 3040.6385 | L12: =K12/(1+'1 - Input'!$B$12)^($A12-0.5) -> 2673.3984 | N12: 7 | O12: =INDEX('2 - Distribuzione'!$BJ$44:$BJ$403,12*$N12) -> 314056.73 | P12: =INDEX('2 - Distribuzione'!$BK$44:$BK$403,12*$N12) -> 418391.63 | Q12: =O12/(1+'1 - Input'!$B$12)^$N12 -> 273405.29 | R12: =SUMIFS('2 - Distribuzione'!$AR$44:$AR$403,'2 - Distribuzione'!$AL$44:$AL$403,$N12) -> 29810.716 | S12: =SUMIFS('2 - Distribuzione'!$AV$44:$AV$403,'2 - Distribuzione'!$AL$44:$AL$403,$N12) -> 22059.93 | T12: =SUMIFS('2 - Distribuzione'!$AU$44:$AU$403,'2 - Distribuzione'!$AL$44:$AL$403,$N12) -> 7750.7862 | U12: =SUMIFS('2 - Distribuzione'!$BC$44:$BC$403,'2 - Distribuzione'!$AL$44:$AL$403,$N12) -> 0 | V12: =SUMIFS('2 - Distribuzione'!$BI$44:$BI$403,'2 - Distribuzione'!$AL$44:$AL$403,$N12) -> 629.37221 | W12: =INDEX('2 - Distribuzione'!$BP$44:$BP$403,12*$N12) -> 11216.679 | X12: =SUMIFS('2 - Distribuzione'!$BL$44:$BL$403,'2 - Distribuzione'!$AL$44:$AL$403,$N12)/12 -> 3040.6385 | Y12: =X12/(1+'1 - Input'!$B$12)^($N12-0.5) -> 2673.3984 | AA12: 7 | AB12: =INDEX('2 - Distribuzione'!$CT$44:$CT$403,12*$AA12) -> 394047.13 | AC12: =INDEX('2 - Distribuzione'!$CU$44:$CU$403,12*$AA12) -> 240796.91 | AD12: =AB12/(1+'1 - Input'!$B$12)^$AA12 -> 343041.74 | AE12: =SUMIFS('2 - Distribuzione'!$CB$44:$CB$403,'2 - Distribuzione'!$BV$44:$BV$403,$AA12) -> 36497.707 | AF12: =SUMIFS('2 - Distribuzione'!$CF$44:$CF$403,'2 - Distribuzione'!$BV$44:$BV$403,$AA12) -> 36497.707 | AG12: =SUMIFS('2 - Distribuzione'!$CE$44:$CE$403,'2 - Distribuzione'!$BV$44:$BV$403,$AA12) -> 0 | AH12: =SUMIFS('2 - Distribuzione'!$CM$44:$CM$403,'2 - Distribuzione'!$BV$44:$BV$403,$AA12) -> 19.915833 | AI12: =SUMIFS('2 - Distribuzione'!$CS$44:$CS$403,'2 - Distribuzione'!$BV$44:$BV$403,$AA12) -> 789.67361 | AJ12: =INDEX('2 - Distribuzione'!$CZ$44:$CZ$403,12*$AA12) -> 0 | AK12: =SUMIFS('2 - Distribuzione'!$CV$44:$CV$403,'2 - Distribuzione'!$BV$44:$BV$403,$AA12)/12 -> 3040.6385 | AL12: =AK12/(1+'1 - Input'!$B$12)^($AA12-0.5) -> 2673.3984
A13: 8 | B13: =INDEX('2 - Distribuzione'!$Z$44:$Z$403,12*$A13) -> 284076.63 | C13: =INDEX('2 - Distribuzione'!$AA$44:$AA$403,12*$A13) -> 394281.88 | D13: =B13/(1+'1 - Input'!$B$12)^$A13 -> 242456.67 | E13: =SUMIFS('2 - Distribuzione'!$H$44:$H$403,'2 - Distribuzione'!$B$44:$B$403,$A13) -> 27169.121 | F13: =SUMIFS('2 - Distribuzione'!$L$44:$L$403,'2 - Distribuzione'!$B$44:$B$403,$A13) -> 20105.15 | G13: =SUMIFS('2 - Distribuzione'!$K$44:$K$403,'2 - Distribuzione'!$B$44:$B$403,$A13) -> 7063.9715 | H13: =SUMIFS('2 - Distribuzione'!$S$44:$S$403,'2 - Distribuzione'!$B$44:$B$403,$A13) -> 0 | I13: =SUMIFS('2 - Distribuzione'!$Y$44:$Y$403,'2 - Distribuzione'!$B$44:$B$403,$A13) -> 569.29185 | J13: =INDEX('2 - Distribuzione'!$AF$44:$AF$403,12*$A13) -> 17424.027 | K13: =SUMIFS('2 - Distribuzione'!$AB$44:$AB$403,'2 - Distribuzione'!$B$44:$B$403,$A13)/12 -> 3101.4513 | L13: =K13/(1+'1 - Input'!$B$12)^($A13-0.5) -> 2673.3984 | N13: 8 | O13: =INDEX('2 - Distribuzione'!$BJ$44:$BJ$403,12*$N13) -> 284076.63 | P13: =INDEX('2 - Distribuzione'!$BK$44:$BK$403,12*$N13) -> 394281.88 | Q13: =O13/(1+'1 - Input'!$B$12)^$N13 -> 242456.67 | R13: =SUMIFS('2 - Distribuzione'!$AR$44:$AR$403,'2 - Distribuzione'!$AL$44:$AL$403,$N13) -> 27169.121 | S13: =SUMIFS('2 - Distribuzione'!$AV$44:$AV$403,'2 - Distribuzione'!$AL$44:$AL$403,$N13) -> 20105.15 | T13: =SUMIFS('2 - Distribuzione'!$AU$44:$AU$403,'2 - Distribuzione'!$AL$44:$AL$403,$N13) -> 7063.9715 | U13: =SUMIFS('2 - Distribuzione'!$BC$44:$BC$403,'2 - Distribuzione'!$AL$44:$AL$403,$N13) -> 0 | V13: =SUMIFS('2 - Distribuzione'!$BI$44:$BI$403,'2 - Distribuzione'!$AL$44:$AL$403,$N13) -> 569.29185 | W13: =INDEX('2 - Distribuzione'!$BP$44:$BP$403,12*$N13) -> 17424.027 | X13: =SUMIFS('2 - Distribuzione'!$BL$44:$BL$403,'2 - Distribuzione'!$AL$44:$AL$403,$N13)/12 -> 3101.4513 | Y13: =X13/(1+'1 - Input'!$B$12)^($N13-0.5) -> 2673.3984 | AA13: 8 | AB13: =INDEX('2 - Distribuzione'!$CT$44:$CT$403,12*$AA13) -> 374859.67 | AC13: =INDEX('2 - Distribuzione'!$CU$44:$CU$403,12*$AA13) -> 204014.36 | AD13: =AB13/(1+'1 - Input'!$B$12)^$AA13 -> 319939.11 | AE13: =SUMIFS('2 - Distribuzione'!$CB$44:$CB$403,'2 - Distribuzione'!$BV$44:$BV$403,$AA13) -> 34855.527 | AF13: =SUMIFS('2 - Distribuzione'!$CF$44:$CF$403,'2 - Distribuzione'!$BV$44:$BV$403,$AA13) -> 34855.527 | AG13: =SUMIFS('2 - Distribuzione'!$CE$44:$CE$403,'2 - Distribuzione'!$BV$44:$BV$403,$AA13) -> 0 | AH13: =SUMIFS('2 - Distribuzione'!$CM$44:$CM$403,'2 - Distribuzione'!$BV$44:$BV$403,$AA13) -> 296.43827 | AI13: =SUMIFS('2 - Distribuzione'!$CS$44:$CS$403,'2 - Distribuzione'!$BV$44:$BV$403,$AA13) -> 751.22177 | AJ13: =INDEX('2 - Distribuzione'!$CZ$44:$CZ$403,12*$AA13) -> 0 | AK13: =SUMIFS('2 - Distribuzione'!$CV$44:$CV$403,'2 - Distribuzione'!$BV$44:$BV$403,$AA13)/12 -> 3101.4513 | AL13: =AK13/(1+'1 - Input'!$B$12)^($AA13-0.5) -> 2673.3984
A14: 9 | B14: =INDEX('2 - Distribuzione'!$Z$44:$Z$403,12*$A14) -> 252618.49 | C14: =INDEX('2 - Distribuzione'!$AA$44:$AA$403,12*$A14) -> 365285.86 | D14: =B14/(1+'1 - Input'!$B$12)^$A14 -> 211379.85 | E14: =SUMIFS('2 - Distribuzione'!$H$44:$H$403,'2 - Distribuzione'!$B$44:$B$403,$A14) -> 24396.258 | F14: =SUMIFS('2 - Distribuzione'!$L$44:$L$403,'2 - Distribuzione'!$B$44:$B$403,$A14) -> 18053.231 | G14: =SUMIFS('2 - Distribuzione'!$K$44:$K$403,'2 - Distribuzione'!$B$44:$B$403,$A14) -> 6343.027 | H14: =SUMIFS('2 - Distribuzione'!$S$44:$S$403,'2 - Distribuzione'!$B$44:$B$403,$A14) -> 0 | I14: =SUMIFS('2 - Distribuzione'!$Y$44:$Y$403,'2 - Distribuzione'!$B$44:$B$403,$A14) -> 506.24948 | J14: =INDEX('2 - Distribuzione'!$AF$44:$AF$403,12*$A14) -> 25779.479 | K14: =SUMIFS('2 - Distribuzione'!$AB$44:$AB$403,'2 - Distribuzione'!$B$44:$B$403,$A14)/12 -> 3163.4803 | L14: =K14/(1+'1 - Input'!$B$12)^($A14-0.5) -> 2673.3984 | N14: 9 | O14: =INDEX('2 - Distribuzione'!$BJ$44:$BJ$403,12*$N14) -> 252618.49 | P14: =INDEX('2 - Distribuzione'!$BK$44:$BK$403,12*$N14) -> 365285.86 | Q14: =O14/(1+'1 - Input'!$B$12)^$N14 -> 211379.85 | R14: =SUMIFS('2 - Distribuzione'!$AR$44:$AR$403,'2 - Distribuzione'!$AL$44:$AL$403,$N14) -> 24396.258 | S14: =SUMIFS('2 - Distribuzione'!$AV$44:$AV$403,'2 - Distribuzione'!$AL$44:$AL$403,$N14) -> 18053.231 | T14: =SUMIFS('2 - Distribuzione'!$AU$44:$AU$403,'2 - Distribuzione'!$AL$44:$AL$403,$N14) -> 6343.027 | U14: =SUMIFS('2 - Distribuzione'!$BC$44:$BC$403,'2 - Distribuzione'!$AL$44:$AL$403,$N14) -> 0 | V14: =SUMIFS('2 - Distribuzione'!$BI$44:$BI$403,'2 - Distribuzione'!$AL$44:$AL$403,$N14) -> 506.24948 | W14: =INDEX('2 - Distribuzione'!$BP$44:$BP$403,12*$N14) -> 25779.479 | X14: =SUMIFS('2 - Distribuzione'!$BL$44:$BL$403,'2 - Distribuzione'!$AL$44:$AL$403,$N14)/12 -> 3163.4803 | Y14: =X14/(1+'1 - Input'!$B$12)^($N14-0.5) -> 2673.3984 | AA14: 9 | AB14: =INDEX('2 - Distribuzione'!$CT$44:$CT$403,12*$AA14) -> 353540.73 | AC14: =INDEX('2 - Distribuzione'!$CU$44:$CU$403,12*$AA14) -> 167790.9 | AD14: =AB14/(1+'1 - Input'!$B$12)^$AA14 -> 295827.07 | AE14: =SUMIFS('2 - Distribuzione'!$CB$44:$CB$403,'2 - Distribuzione'!$BV$44:$BV$403,$AA14) -> 33033.274 | AF14: =SUMIFS('2 - Distribuzione'!$CF$44:$CF$403,'2 - Distribuzione'!$BV$44:$BV$403,$AA14) -> 33033.274 | AG14: =SUMIFS('2 - Distribuzione'!$CE$44:$CE$403,'2 - Distribuzione'!$BV$44:$BV$403,$AA14) -> 0 | AH14: =SUMIFS('2 - Distribuzione'!$CM$44:$CM$403,'2 - Distribuzione'!$BV$44:$BV$403,$AA14) -> 728.89708 | AI14: =SUMIFS('2 - Distribuzione'!$CS$44:$CS$403,'2 - Distribuzione'!$BV$44:$BV$403,$AA14) -> 708.49847 | AJ14: =INDEX('2 - Distribuzione'!$CZ$44:$CZ$403,12*$AA14) -> 0 | AK14: =SUMIFS('2 - Distribuzione'!$CV$44:$CV$403,'2 - Distribuzione'!$BV$44:$BV$403,$AA14)/12 -> 3163.4803 | AL14: =AK14/(1+'1 - Input'!$B$12)^($AA14-0.5) -> 2673.3984
A15: 10 | B15: =INDEX('2 - Distribuzione'!$Z$44:$Z$403,12*$A15) -> 219631.46 | C15: =INDEX('2 - Distribuzione'!$AA$44:$AA$403,12*$A15) -> 330870.99 | D15: =B15/(1+'1 - Input'!$B$12)^$A15 -> 180174.3 | E15: =SUMIFS('2 - Distribuzione'!$H$44:$H$403,'2 - Distribuzione'!$B$44:$B$403,$A15) -> 21487.6 | F15: =SUMIFS('2 - Distribuzione'!$L$44:$L$403,'2 - Distribuzione'!$B$44:$B$403,$A15) -> 15900.824 | G15: =SUMIFS('2 - Distribuzione'!$K$44:$K$403,'2 - Distribuzione'!$B$44:$B$403,$A15) -> 5586.7759 | H15: =SUMIFS('2 - Distribuzione'!$S$44:$S$403,'2 - Distribuzione'!$B$44:$B$403,$A15) -> 0 | I15: =SUMIFS('2 - Distribuzione'!$Y$44:$Y$403,'2 - Distribuzione'!$B$44:$B$403,$A15) -> 440.14321 | J15: =INDEX('2 - Distribuzione'!$AF$44:$AF$403,12*$A15) -> 36711.099 | K15: =SUMIFS('2 - Distribuzione'!$AB$44:$AB$403,'2 - Distribuzione'!$B$44:$B$403,$A15)/12 -> 3226.7499 | L15: =K15/(1+'1 - Input'!$B$12)^($A15-0.5) -> 2673.3984 | N15: 10 | O15: =INDEX('2 - Distribuzione'!$BJ$44:$BJ$403,12*$N15) -> 219631.46 | P15: =INDEX('2 - Distribuzione'!$BK$44:$BK$403,12*$N15) -> 330870.99 | Q15: =O15/(1+'1 - Input'!$B$12)^$N15 -> 180174.3 | R15: =SUMIFS('2 - Distribuzione'!$AR$44:$AR$403,'2 - Distribuzione'!$AL$44:$AL$403,$N15) -> 21487.6 | S15: =SUMIFS('2 - Distribuzione'!$AV$44:$AV$403,'2 - Distribuzione'!$AL$44:$AL$403,$N15) -> 15900.824 | T15: =SUMIFS('2 - Distribuzione'!$AU$44:$AU$403,'2 - Distribuzione'!$AL$44:$AL$403,$N15) -> 5586.7759 | U15: =SUMIFS('2 - Distribuzione'!$BC$44:$BC$403,'2 - Distribuzione'!$AL$44:$AL$403,$N15) -> 0 | V15: =SUMIFS('2 - Distribuzione'!$BI$44:$BI$403,'2 - Distribuzione'!$AL$44:$AL$403,$N15) -> 440.14321 | W15: =INDEX('2 - Distribuzione'!$BP$44:$BP$403,12*$N15) -> 36711.099 | X15: =SUMIFS('2 - Distribuzione'!$BL$44:$BL$403,'2 - Distribuzione'!$AL$44:$AL$403,$N15)/12 -> 3226.7499 | Y15: =X15/(1+'1 - Input'!$B$12)^($N15-0.5) -> 2673.3984 | AA15: 10 | AB15: =INDEX('2 - Distribuzione'!$CT$44:$CT$403,12*$AA15) -> 329797.96 | AC15: =INDEX('2 - Distribuzione'!$CU$44:$CU$403,12*$AA15) -> 132594.5 | AD15: =AB15/(1+'1 - Input'!$B$12)^$AA15 -> 270549.2 | AE15: =SUMIFS('2 - Distribuzione'!$CB$44:$CB$403,'2 - Distribuzione'!$BV$44:$BV$403,$AA15) -> 31006.455 | AF15: =SUMIFS('2 - Distribuzione'!$CF$44:$CF$403,'2 - Distribuzione'!$BV$44:$BV$403,$AA15) -> 31006.455 | AG15: =SUMIFS('2 - Distribuzione'!$CE$44:$CE$403,'2 - Distribuzione'!$BV$44:$BV$403,$AA15) -> 0 | AH15: =SUMIFS('2 - Distribuzione'!$CM$44:$CM$403,'2 - Distribuzione'!$BV$44:$BV$403,$AA15) -> 1331.7354 | AI15: =SUMIFS('2 - Distribuzione'!$CS$44:$CS$403,'2 - Distribuzione'!$BV$44:$BV$403,$AA15) -> 660.91776 | AJ15: =INDEX('2 - Distribuzione'!$CZ$44:$CZ$403,12*$AA15) -> 0 | AK15: =SUMIFS('2 - Distribuzione'!$CV$44:$CV$403,'2 - Distribuzione'!$BV$44:$BV$403,$AA15)/12 -> 3226.7499 | AL15: =AK15/(1+'1 - Input'!$B$12)^($AA15-0.5) -> 2673.3984
A16: 11 | B16: =INDEX('2 - Distribuzione'!$Z$44:$Z$403,12*$A16) -> 185063.18 | C16: =INDEX('2 - Distribuzione'!$AA$44:$AA$403,12*$A16) -> 290456.14 | D16: =B16/(1+'1 - Input'!$B$12)^$A16 -> 148839.47 | E16: =SUMIFS('2 - Distribuzione'!$H$44:$H$403,'2 - Distribuzione'!$B$44:$B$403,$A16) -> 18438.485 | F16: =SUMIFS('2 - Distribuzione'!$L$44:$L$403,'2 - Distribuzione'!$B$44:$B$403,$A16) -> 13644.479 | G16: =SUMIFS('2 - Distribuzione'!$K$44:$K$403,'2 - Distribuzione'!$B$44:$B$403,$A16) -> 4794.006 | H16: =SUMIFS('2 - Distribuzione'!$S$44:$S$403,'2 - Distribuzione'!$B$44:$B$403,$A16) -> 0 | I16: =SUMIFS('2 - Distribuzione'!$Y$44:$Y$403,'2 - Distribuzione'!$B$44:$B$403,$A16) -> 370.86809 | J16: =INDEX('2 - Distribuzione'!$AF$44:$AF$403,12*$A16) -> 50692.929 | K16: =SUMIFS('2 - Distribuzione'!$AB$44:$AB$403,'2 - Distribuzione'!$B$44:$B$403,$A16)/12 -> 3291.2849 | L16: =K16/(1+'1 - Input'!$B$12)^($A16-0.5) -> 2673.3984 | N16: 11 | O16: =INDEX('2 - Distribuzione'!$BJ$44:$BJ$403,12*$N16) -> 185063.18 | P16: =INDEX('2 - Distribuzione'!$BK$44:$BK$403,12*$N16) -> 290456.14 | Q16: =O16/(1+'1 - Input'!$B$12)^$N16 -> 148839.47 | R16: =SUMIFS('2 - Distribuzione'!$AR$44:$AR$403,'2 - Distribuzione'!$AL$44:$AL$403,$N16) -> 18438.485 | S16: =SUMIFS('2 - Distribuzione'!$AV$44:$AV$403,'2 - Distribuzione'!$AL$44:$AL$403,$N16) -> 13644.479 | T16: =SUMIFS('2 - Distribuzione'!$AU$44:$AU$403,'2 - Distribuzione'!$AL$44:$AL$403,$N16) -> 4794.006 | U16: =SUMIFS('2 - Distribuzione'!$BC$44:$BC$403,'2 - Distribuzione'!$AL$44:$AL$403,$N16) -> 0 | V16: =SUMIFS('2 - Distribuzione'!$BI$44:$BI$403,'2 - Distribuzione'!$AL$44:$AL$403,$N16) -> 370.86809 | W16: =INDEX('2 - Distribuzione'!$BP$44:$BP$403,12*$N16) -> 50692.929 | X16: =SUMIFS('2 - Distribuzione'!$BL$44:$BL$403,'2 - Distribuzione'!$AL$44:$AL$403,$N16)/12 -> 3291.2849 | Y16: =X16/(1+'1 - Input'!$B$12)^($N16-0.5) -> 2673.3984 | AA16: 11 | AB16: =INDEX('2 - Distribuzione'!$CT$44:$CT$403,12*$AA16) -> 303282.34 | AC16: =INDEX('2 - Distribuzione'!$CU$44:$CU$403,12*$AA16) -> 99009.303 | AD16: =AB16/(1+'1 - Input'!$B$12)^$AA16 -> 243918.78 | AE16: =SUMIFS('2 - Distribuzione'!$CB$44:$CB$403,'2 - Distribuzione'!$BV$44:$BV$403,$AA16) -> 28746.364 | AF16: =SUMIFS('2 - Distribuzione'!$CF$44:$CF$403,'2 - Distribuzione'!$BV$44:$BV$403,$AA16) -> 28746.364 | AG16: =SUMIFS('2 - Distribuzione'!$CE$44:$CE$403,'2 - Distribuzione'!$BV$44:$BV$403,$AA16) -> 0 | AH16: =SUMIFS('2 - Distribuzione'!$CM$44:$CM$403,'2 - Distribuzione'!$BV$44:$BV$403,$AA16) -> 2146.2777 | AI16: =SUMIFS('2 - Distribuzione'!$CS$44:$CS$403,'2 - Distribuzione'!$BV$44:$BV$403,$AA16) -> 607.78025 | AJ16: =INDEX('2 - Distribuzione'!$CZ$44:$CZ$403,12*$AA16) -> 0 | AK16: =SUMIFS('2 - Distribuzione'!$CV$44:$CV$403,'2 - Distribuzione'!$BV$44:$BV$403,$AA16)/12 -> 3291.2849 | AL16: =AK16/(1+'1 - Input'!$B$12)^($AA16-0.5) -> 2673.3984
A17: 12 | B17: =INDEX('2 - Distribuzione'!$Z$44:$Z$403,12*$A17) -> 148859.68 | C17: =INDEX('2 - Distribuzione'!$AA$44:$AA$403,12*$A17) -> 243407.56 | D17: =B17/(1+'1 - Input'!$B$12)^$A17 -> 117374.84 | E17: =SUMIFS('2 - Distribuzione'!$H$44:$H$403,'2 - Distribuzione'!$B$44:$B$403,$A17) -> 15244.111 | F17: =SUMIFS('2 - Distribuzione'!$L$44:$L$403,'2 - Distribuzione'!$B$44:$B$403,$A17) -> 11280.642 | G17: =SUMIFS('2 - Distribuzione'!$K$44:$K$403,'2 - Distribuzione'!$B$44:$B$403,$A17) -> 3963.4688 | H17: =SUMIFS('2 - Distribuzione'!$S$44:$S$403,'2 - Distribuzione'!$B$44:$B$403,$A17) -> 0 | I17: =SUMIFS('2 - Distribuzione'!$Y$44:$Y$403,'2 - Distribuzione'!$B$44:$B$403,$A17) -> 298.316 | J17: =INDEX('2 - Distribuzione'!$AF$44:$AF$403,12*$A17) -> 68249.038 | K17: =SUMIFS('2 - Distribuzione'!$AB$44:$AB$403,'2 - Distribuzione'!$B$44:$B$403,$A17)/12 -> 3357.1106 | L17: =K17/(1+'1 - Input'!$B$12)^($A17-0.5) -> 2673.3984 | N17: 12 | O17: =INDEX('2 - Distribuzione'!$BJ$44:$BJ$403,12*$N17) -> 148859.68 | P17: =INDEX('2 - Distribuzione'!$BK$44:$BK$403,12*$N17) -> 243407.56 | Q17: =O17/(1+'1 - Input'!$B$12)^$N17 -> 117374.84 | R17: =SUMIFS('2 - Distribuzione'!$AR$44:$AR$403,'2 - Distribuzione'!$AL$44:$AL$403,$N17) -> 15244.111 | S17: =SUMIFS('2 - Distribuzione'!$AV$44:$AV$403,'2 - Distribuzione'!$AL$44:$AL$403,$N17) -> 11280.642 | T17: =SUMIFS('2 - Distribuzione'!$AU$44:$AU$403,'2 - Distribuzione'!$AL$44:$AL$403,$N17) -> 3963.4688 | U17: =SUMIFS('2 - Distribuzione'!$BC$44:$BC$403,'2 - Distribuzione'!$AL$44:$AL$403,$N17) -> 0 | V17: =SUMIFS('2 - Distribuzione'!$BI$44:$BI$403,'2 - Distribuzione'!$AL$44:$AL$403,$N17) -> 298.316 | W17: =INDEX('2 - Distribuzione'!$BP$44:$BP$403,12*$N17) -> 68249.038 | X17: =SUMIFS('2 - Distribuzione'!$BL$44:$BL$403,'2 - Distribuzione'!$AL$44:$AL$403,$N17)/12 -> 3357.1106 | Y17: =X17/(1+'1 - Input'!$B$12)^($N17-0.5) -> 2673.3984 | AA17: 12 | AB17: =INDEX('2 - Distribuzione'!$CT$44:$CT$403,12*$AA17) -> 273574.2 | AC17: =INDEX('2 - Distribuzione'!$CU$44:$CU$403,12*$AA17) -> 67766.761 | AD17: =AB17/(1+'1 - Input'!$B$12)^$AA17 -> 215711.39 | AE17: =SUMIFS('2 - Distribuzione'!$CB$44:$CB$403,'2 - Distribuzione'!$BV$44:$BV$403,$AA17) -> 26218.616 | AF17: =SUMIFS('2 - Distribuzione'!$CF$44:$CF$403,'2 - Distribuzione'!$BV$44:$BV$403,$AA17) -> 26218.616 | AG17: =SUMIFS('2 - Distribuzione'!$CE$44:$CE$403,'2 - Distribuzione'!$BV$44:$BV$403,$AA17) -> 0 | AH17: =SUMIFS('2 - Distribuzione'!$CM$44:$CM$403,'2 - Distribuzione'!$BV$44:$BV$403,$AA17) -> 3224.9105 | AI17: =SUMIFS('2 - Distribuzione'!$CS$44:$CS$403,'2 - Distribuzione'!$BV$44:$BV$403,$AA17) -> 548.24489 | AJ17: =INDEX('2 - Distribuzione'!$CZ$44:$CZ$403,12*$AA17) -> 0 | AK17: =SUMIFS('2 - Distribuzione'!$CV$44:$CV$403,'2 - Distribuzione'!$BV$44:$BV$403,$AA17)/12 -> 3357.1106 | AL17: =AK17/(1+'1 - Input'!$B$12)^($AA17-0.5) -> 2673.3984
... A35: 30 | B35: =INDEX('2 - Distribuzione'!$Z$44:$Z$403,12*$A35) -> 0 | C35: =INDEX('2 - Distribuzione'!$AA$44:$AA$403,12*$A35) -> 0 | D35: =B35/(1+'1 - Input'!$B$12)^$A35 -> 0 | E35: =SUMIFS('2 - Distribuzione'!$H$44:$H$403,'2 - Distribuzione'!$B$44:$B$403,$A35) -> 0 | F35: =SUMIFS('2 - Distribuzione'!$L$44:$L$403,'2 - Distribuzione'!$B$44:$B$403,$A35) -> 0 | G35: =SUMIFS('2 - Distribuzione'!$K$44:$K$403,'2 - Distribuzione'!$B$44:$B$403,$A35) -> 0 | H35: =SUMIFS('2 - Distribuzione'!$S$44:$S$403,'2 - Distribuzione'!$B$44:$B$403,$A35) -> 0 | I35: =SUMIFS('2 - Distribuzione'!$Y$44:$Y$403,'2 - Distribuzione'!$B$44:$B$403,$A35) -> 0 | J35: =INDEX('2 - Distribuzione'!$AF$44:$AF$403,12*$A35) -> 174289.24 | K35: =SUMIFS('2 - Distribuzione'!$AB$44:$AB$403,'2 - Distribuzione'!$B$44:$B$403,$A35)/12 -> 0 | L35: =K35/(1+'1 - Input'!$B$12)^($A35-0.5) -> 0 | N35: 30 | O35: =INDEX('2 - Distribuzione'!$BJ$44:$BJ$403,12*$N35) -> 0 | P35: =INDEX('2 - Distribuzione'!$BK$44:$BK$403,12*$N35) -> 0 | Q35: =O35/(1+'1 - Input'!$B$12)^$N35 -> 0 | R35: =SUMIFS('2 - Distribuzione'!$AR$44:$AR$403,'2 - Distribuzione'!$AL$44:$AL$403,$N35) -> 0 | S35: =SUMIFS('2 - Distribuzione'!$AV$44:$AV$403,'2 - Distribuzione'!$AL$44:$AL$403,$N35) -> 0 | T35: =SUMIFS('2 - Distribuzione'!$AU$44:$AU$403,'2 - Distribuzione'!$AL$44:$AL$403,$N35) -> 0 | U35: =SUMIFS('2 - Distribuzione'!$BC$44:$BC$403,'2 - Distribuzione'!$AL$44:$AL$403,$N35) -> 0 | V35: =SUMIFS('2 - Distribuzione'!$BI$44:$BI$403,'2 - Distribuzione'!$AL$44:$AL$403,$N35) -> 0 | W35: =INDEX('2 - Distribuzione'!$BP$44:$BP$403,12*$N35) -> 174289.24 | X35: =SUMIFS('2 - Distribuzione'!$BL$44:$BL$403,'2 - Distribuzione'!$AL$44:$AL$403,$N35)/12 -> 0 | Y35: =X35/(1+'1 - Input'!$B$12)^($N35-0.5) -> 0 | AA35: 30 | AB35: =INDEX('2 - Distribuzione'!$CT$44:$CT$403,12*$AA35) -> 0 | AC35: =INDEX('2 - Distribuzione'!$CU$44:$CU$403,12*$AA35) -> 0 | AD35: =AB35/(1+'1 - Input'!$B$12)^$AA35 -> 0 | AE35: =SUMIFS('2 - Distribuzione'!$CB$44:$CB$403,'2 - Distribuzione'!$BV$44:$BV$403,$AA35) -> 0 | AF35: =SUMIFS('2 - Distribuzione'!$CF$44:$CF$403,'2 - Distribuzione'!$BV$44:$BV$403,$AA35) -> 0 | AG35: =SUMIFS('2 - Distribuzione'!$CE$44:$CE$403,'2 - Distribuzione'!$BV$44:$BV$403,$AA35) -> 0 | AH35: =SUMIFS('2 - Distribuzione'!$CM$44:$CM$403,'2 - Distribuzione'!$BV$44:$BV$403,$AA35) -> 0 | AI35: =SUMIFS('2 - Distribuzione'!$CS$44:$CS$403,'2 - Distribuzione'!$BV$44:$BV$403,$AA35) -> 0 | AJ35: =INDEX('2 - Distribuzione'!$CZ$44:$CZ$403,12*$AA35) -> 0 | AK35: =SUMIFS('2 - Distribuzione'!$CV$44:$CV$403,'2 - Distribuzione'!$BV$44:$BV$403,$AA35)/12 -> 0 | AL35: =AK35/(1+'1 - Input'!$B$12)^($AA35-0.5) -> 0
A40: Motore del calcolo, non modificare. A: caso atteso, Q = 0% (tutto provento) | AK40: Motore del calcolo, non modificare. U: Q scelta nel foglio 1 | BU40: Motore del calcolo, non modificare. B: limite teorico, senza fonte per gli ETF esteri, Q = 100%
A41: Quota Q del blocco | B41: =0 -> 0 | AK41: Quota Q del blocco | AL41: ='1 - Input'!$B$9 -> 0 | BU41: Quota Q del blocco | BV41: =1 -> 1
A43: Mese k | B43: Anno | C43: Rendimento mensile | D43: Spesa del mese | E43: Valore prima | F43: Costo prima | G43: Valore con rendimento | H43: Distribuzione lorda | I43: Valore dopo lo stacco | J43: Rimborso di capitale | K43: Imposta sulla distribuzione | L43: Distribuzione netta | M43: Costo dopo rimborso | N43: Avanzo reinvestito | O43: Fabbisogno | P43: Quota di guadagno nel valore | Q43: Vendita necessaria lorda | R43: Vendita effettiva | S43: Imposta sulla vendita | T43: Vendita netta | U43: Spesa non coperta | V43: Minusvalenza realizzata | W43: Valore a fine mese | X43: Costo a fine mese | Y43: Bollo | Z43: Valore dopo bollo | AA43: Costo dopo bollo | AB43: Speso nel mese | AC43: Speso cumulato | AD43: Imposte distribuzione cumulate | AE43: Imposte vendita cumulate | AF43: Minusvalenze cumulate | AG43: Bollo cumulato | AH43: Non coperto cumulato | AI43: Esaurito (1 = sì) | AK43: Mese k | AL43: Anno | AM43: Rendimento mensile | AN43: Spesa del mese | AO43: Valore prima | AP43: Costo prima | AQ43: Valore con rendimento | AR43: Distribuzione lorda | AS43: Valore dopo lo stacco | AT43: Rimborso di capitale | AU43: Imposta sulla distribuzione | AV43: Distribuzione netta | AW43: Costo dopo rimborso | AX43: Avanzo reinvestito | AY43: Fabbisogno | AZ43: Quota di guadagno nel valore | BA43: Vendita necessaria lorda | BB43: Vendita effettiva | BC43: Imposta sulla vendita | BD43: Vendita netta | BE43: Spesa non coperta | BF43: Minusvalenza realizzata | BG43: Valore a fine mese | BH43: Costo a fine mese | BI43: Bollo | BJ43: Valore dopo bollo | BK43: Costo dopo bollo | BL43: Speso nel mese | BM43: Speso cumulato | BN43: Imposte distribuzione cumulate | BO43: Imposte vendita cumulate | BP43: Minusvalenze cumulate | BQ43: Bollo cumulato | BR43: Non coperto cumulato | BS43: Esaurito (1 = sì) | BU43: Mese k | BV43: Anno | BW43: Rendimento mensile | BX43: Spesa del mese | BY43: Valore prima | BZ43: Costo prima | CA43: Valore con rendimento | CB43: Distribuzione lorda | CC43: Valore dopo lo stacco | CD43: Rimborso di capitale | CE43: Imposta sulla distribuzione | CF43: Distribuzione netta | CG43: Costo dopo rimborso | CH43: Avanzo reinvestito | CI43: Fabbisogno | CJ43: Quota di guadagno nel valore | CK43: Vendita necessaria lorda | CL43: Vendita effettiva | CM43: Imposta sulla vendita | CN43: Vendita netta | CO43: Spesa non coperta | CP43: Minusvalenza realizzata | CQ43: Valore a fine mese | CR43: Costo a fine mese | CS43: Bollo | CT43: Valore dopo bollo | CU43: Costo dopo bollo | CV43: Speso nel mese | CW43: Speso cumulato | CX43: Imposte distribuzione cumulate | CY43: Imposte vendita cumulate | CZ43: Minusvalenze cumulate | DA43: Bollo cumulato | DB43: Non coperto cumulato | DC43: Esaurito (1 = sì)
A44: 1 | B44: =ROUNDUP(A44/12,0) -> 1 | C44: =(1+INDEX('1 - Input'!$B$34:$E$63,B44,'1 - Input'!$B$16))^(1/12)-1 -> 0.0041219243 | D44: ='1 - Input'!$B$7*(1+'1 - Input'!$B$12)^(B44-1) -> 2700 | E44: ='1 - Input'!$B$6 -> 486500 | F44: ='1 - Input'!$B$6*'1 - Input'!$B$15 -> 486500 | G44: =E44*(1+C44) -> 488505.32 | H44: =IF(G44>0,'1 - Input'!$B$8/12*G44,0) -> 3663.7899 | I44: =G44-H44 -> 484841.53 | J44: =MIN($B$41*H44,F44) -> 0 | K44: ='1 - Input'!$B$22*(H44-J44) -> 952.58537 | L44: =H44-K44 -> 2711.2045 | M44: =F44-J44 -> 486500 | N44: =IF('1 - Input'!$B$17=1,MAX(0,L44-D44),0) -> 11.204505 | O44: =IF('1 - Input'!$B$17=1,MAX(0,D44-L44),0) -> 0 | P44: =IF(I44>0,MAX(0,1-M44/I44),0) -> 0 | Q44: =IF(AND(O44>0,I44>0),O44/(1-'1 - Input'!$B$22*P44),0) -> 0 | R44: =MIN(Q44,I44) -> 0 | S44: ='1 - Input'!$B$22*P44*R44 -> 0 | T44: =R44-S44 -> 0 | U44: =O44-T44 -> 0 | V44: =IF(I44>0,R44*MAX(0,M44/I44-1),0) -> 0 | W44: =I44-R44+N44 -> 484852.73 | X44: =IF(R44>0,M44*(1-R44/I44),M44)+N44 -> 486511.2 | Y44: =IF(MOD(A44,12)=0,W44*'1 - Input'!$B$23,0) -> 0 | Z44: =W44-Y44 -> 484852.73 | AA44: =IF(MOD(A44,12)=0,X44*(1-'1 - Input'!$B$23),X44) -> 486511.2 | AB44: =IF('1 - Input'!$B$17=1,MIN(L44,D44)+T44,L44) -> 2700 | AC44: =AB44 -> 2700 | AD44: =K44 -> 952.58537 | AE44: =S44 -> 0 | AF44: =V44 -> 0 | AG44: =Y44 -> 0 | AH44: =U44 -> 0 | AI44: =IF(W44<=0.000001,1,0) -> 0 | AK44: 1 | AL44: =ROUNDUP(AK44/12,0) -> 1 | AM44: =(1+INDEX('1 - Input'!$B$34:$E$63,AL44,'1 - Input'!$B$16))^(1/12)-1 -> 0.0041219243 | AN44: ='1 - Input'!$B$7*(1+'1 - Input'!$B$12)^(AL44-1) -> 2700 | AO44: ='1 - Input'!$B$6 -> 486500 | AP44: ='1 - Input'!$B$6*'1 - Input'!$B$15 -> 486500 | AQ44: =AO44*(1+AM44) -> 488505.32 | AR44: =IF(AQ44>0,'1 - Input'!$B$8/12*AQ44,0) -> 3663.7899 | AS44: =AQ44-AR44 -> 484841.53 | AT44: =MIN($AL$41*AR44,AP44) -> 0 | AU44: ='1 - Input'!$B$22*(AR44-AT44) -> 952.58537 | AV44: =AR44-AU44 -> 2711.2045 | AW44: =AP44-AT44 -> 486500 | AX44: =IF('1 - Input'!$B$17=1,MAX(0,AV44-AN44),0) -> 11.204505 | AY44: =IF('1 - Input'!$B$17=1,MAX(0,AN44-AV44),0) -> 0 | AZ44: =IF(AS44>0,MAX(0,1-AW44/AS44),0) -> 0 | BA44: =IF(AND(AY44>0,AS44>0),AY44/(1-'1 - Input'!$B$22*AZ44),0) -> 0 | BB44: =MIN(BA44,AS44) -> 0 | BC44: ='1 - Input'!$B$22*AZ44*BB44 -> 0 | BD44: =BB44-BC44 -> 0 | BE44: =AY44-BD44 -> 0 | BF44: =IF(AS44>0,BB44*MAX(0,AW44/AS44-1),0) -> 0 | BG44: =AS44-BB44+AX44 -> 484852.73 | BH44: =IF(BB44>0,AW44*(1-BB44/AS44),AW44)+AX44 -> 486511.2 | BI44: =IF(MOD(AK44,12)=0,BG44*'1 - Input'!$B$23,0) -> 0 | BJ44: =BG44-BI44 -> 484852.73 | BK44: =IF(MOD(AK44,12)=0,BH44*(1-'1 - Input'!$B$23),BH44) -> 486511.2 | BL44: =IF('1 - Input'!$B$17=1,MIN(AV44,AN44)+BD44,AV44) -> 2700 | BM44: =BL44 -> 2700 | BN44: =AU44 -> 952.58537 | BO44: =BC44 -> 0 | BP44: =BF44 -> 0 | BQ44: =BI44 -> 0 | BR44: =BE44 -> 0 | BS44: =IF(BG44<=0.000001,1,0) -> 0 | BU44: 1 | BV44: =ROUNDUP(BU44/12,0) -> 1 | BW44: =(1+INDEX('1 - Input'!$B$34:$E$63,BV44,'1 - Input'!$B$16))^(1/12)-1 -> 0.0041219243 | BX44: ='1 - Input'!$B$7*(1+'1 - Input'!$B$12)^(BV44-1) -> 2700 | BY44: ='1 - Input'!$B$6 -> 486500 | BZ44: ='1 - Input'!$B$6*'1 - Input'!$B$15 -> 486500 | CA44: =BY44*(1+BW44) -> 488505.32 | CB44: =IF(CA44>0,'1 - Input'!$B$8/12*CA44,0) -> 3663.7899 | CC44: =CA44-CB44 -> 484841.53 | CD44: =MIN($BV$41*CB44,BZ44) -> 3663.7899 | CE44: ='1 - Input'!$B$22*(CB44-CD44) -> 0 | CF44: =CB44-CE44 -> 3663.7899 | CG44: =BZ44-CD44 -> 482836.21 | CH44: =IF('1 - Input'!$B$17=1,MAX(0,CF44-BX44),0) -> 963.78987 | CI44: =IF('1 - Input'!$B$17=1,MAX(0,BX44-CF44),0) -> 0 | CJ44: =IF(CC44>0,MAX(0,1-CG44/CC44),0) -> 0.004136024 | CK44: =IF(AND(CI44>0,CC44>0),CI44/(1-'1 - Input'!$B$22*CJ44),0) -> 0 | CL44: =MIN(CK44,CC44) -> 0 | CM44: ='1 - Input'!$B$22*CJ44*CL44 -> 0 | CN44: =CL44-CM44 -> 0 | CO44: =CI44-CN44 -> 0 | CP44: =IF(CC44>0,CL44*MAX(0,CG44/CC44-1),0) -> 0 | CQ44: =CC44-CL44+CH44 -> 485805.32 | CR44: =IF(CL44>0,CG44*(1-CL44/CC44),CG44)+CH44 -> 483800 | CS44: =IF(MOD(BU44,12)=0,CQ44*'1 - Input'!$B$23,0) -> 0 | CT44: =CQ44-CS44 -> 485805.32 | CU44: =IF(MOD(BU44,12)=0,CR44*(1-'1 - Input'!$B$23),CR44) -> 483800 | CV44: =IF('1 - Input'!$B$17=1,MIN(CF44,BX44)+CN44,CF44) -> 2700 | CW44: =CV44 -> 2700 | CX44: =CE44 -> 0 | CY44: =CM44 -> 0 | CZ44: =CP44 -> 0 | DA44: =CS44 -> 0 | DB44: =CO44 -> 0 | DC44: =IF(CQ44<=0.000001,1,0) -> 0
A45: 2 | B45: =ROUNDUP(A45/12,0) -> 1 | C45: =(1+INDEX('1 - Input'!$B$34:$E$63,B45,'1 - Input'!$B$16))^(1/12)-1 -> 0.0041219243 | D45: ='1 - Input'!$B$7*(1+'1 - Input'!$B$12)^(B45-1) -> 2700 | E45: =Z44 -> 484852.73 | F45: =AA44 -> 486511.2 | G45: =E45*(1+C45) -> 486851.26 | H45: =IF(G45>0,'1 - Input'!$B$8/12*G45,0) -> 3651.3844 | I45: =G45-H45 -> 483199.87 | J45: =MIN($B$41*H45,F45) -> 0 | K45: ='1 - Input'!$B$22*(H45-J45) -> 949.35995 | L45: =H45-K45 -> 2702.0245 | M45: =F45-J45 -> 486511.2 | N45: =IF('1 - Input'!$B$17=1,MAX(0,L45-D45),0) -> 2.0244768 | O45: =IF('1 - Input'!$B$17=1,MAX(0,D45-L45),0) -> 0 | P45: =IF(I45>0,MAX(0,1-M45/I45),0) -> 0 | Q45: =IF(AND(O45>0,I45>0),O45/(1-'1 - Input'!$B$22*P45),0) -> 0 | R45: =MIN(Q45,I45) -> 0 | S45: ='1 - Input'!$B$22*P45*R45 -> 0 | T45: =R45-S45 -> 0 | U45: =O45-T45 -> 0 | V45: =IF(I45>0,R45*MAX(0,M45/I45-1),0) -> 0 | W45: =I45-R45+N45 -> 483201.9 | X45: =IF(R45>0,M45*(1-R45/I45),M45)+N45 -> 486513.23 | Y45: =IF(MOD(A45,12)=0,W45*'1 - Input'!$B$23,0) -> 0 | Z45: =W45-Y45 -> 483201.9 | AA45: =IF(MOD(A45,12)=0,X45*(1-'1 - Input'!$B$23),X45) -> 486513.23 | AB45: =IF('1 - Input'!$B$17=1,MIN(L45,D45)+T45,L45) -> 2700 | AC45: =AC44+AB45 -> 5400 | AD45: =AD44+K45 -> 1901.9453 | AE45: =AE44+S45 -> 0 | AF45: =AF44+V45 -> 0 | AG45: =AG44+Y45 -> 0 | AH45: =AH44+U45 -> 0 | AI45: =IF(W45<=0.000001,1,0) -> 0 | AK45: 2 | AL45: =ROUNDUP(AK45/12,0) -> 1 | AM45: =(1+INDEX('1 - Input'!$B$34:$E$63,AL45,'1 - Input'!$B$16))^(1/12)-1 -> 0.0041219243 | AN45: ='1 - Input'!$B$7*(1+'1 - Input'!$B$12)^(AL45-1) -> 2700 | AO45: =BJ44 -> 484852.73 | AP45: =BK44 -> 486511.2 | AQ45: =AO45*(1+AM45) -> 486851.26 | AR45: =IF(AQ45>0,'1 - Input'!$B$8/12*AQ45,0) -> 3651.3844 | AS45: =AQ45-AR45 -> 483199.87 | AT45: =MIN($AL$41*AR45,AP45) -> 0 | AU45: ='1 - Input'!$B$22*(AR45-AT45) -> 949.35995 | AV45: =AR45-AU45 -> 2702.0245 | AW45: =AP45-AT45 -> 486511.2 | AX45: =IF('1 - Input'!$B$17=1,MAX(0,AV45-AN45),0) -> 2.0244768 | AY45: =IF('1 - Input'!$B$17=1,MAX(0,AN45-AV45),0) -> 0 | AZ45: =IF(AS45>0,MAX(0,1-AW45/AS45),0) -> 0 | BA45: =IF(AND(AY45>0,AS45>0),AY45/(1-'1 - Input'!$B$22*AZ45),0) -> 0 | BB45: =MIN(BA45,AS45) -> 0 | BC45: ='1 - Input'!$B$22*AZ45*BB45 -> 0 | BD45: =BB45-BC45 -> 0 | BE45: =AY45-BD45 -> 0 | BF45: =IF(AS45>0,BB45*MAX(0,AW45/AS45-1),0) -> 0 | BG45: =AS45-BB45+AX45 -> 483201.9 | BH45: =IF(BB45>0,AW45*(1-BB45/AS45),AW45)+AX45 -> 486513.23 | BI45: =IF(MOD(AK45,12)=0,BG45*'1 - Input'!$B$23,0) -> 0 | BJ45: =BG45-BI45 -> 483201.9 | BK45: =IF(MOD(AK45,12)=0,BH45*(1-'1 - Input'!$B$23),BH45) -> 486513.23 | BL45: =IF('1 - Input'!$B$17=1,MIN(AV45,AN45)+BD45,AV45) -> 2700 | BM45: =BM44+BL45 -> 5400 | BN45: =BN44+AU45 -> 1901.9453 | BO45: =BO44+BC45 -> 0 | BP45: =BP44+BF45 -> 0 | BQ45: =BQ44+BI45 -> 0 | BR45: =BR44+BE45 -> 0 | BS45: =IF(BG45<=0.000001,1,0) -> 0 | BU45: 2 | BV45: =ROUNDUP(BU45/12,0) -> 1 | BW45: =(1+INDEX('1 - Input'!$B$34:$E$63,BV45,'1 - Input'!$B$16))^(1/12)-1 -> 0.0041219243 | BX45: ='1 - Input'!$B$7*(1+'1 - Input'!$B$12)^(BV45-1) -> 2700 | BY45: =CT44 -> 485805.32 | BZ45: =CU44 -> 483800 | CA45: =BY45*(1+BW45) -> 487807.77 | CB45: =IF(CA45>0,'1 - Input'!$B$8/12*CA45,0) -> 3658.5583 | CC45: =CA45-CB45 -> 484149.21 | CD45: =MIN($BV$41*CB45,BZ45) -> 3658.5583 | CE45: ='1 - Input'!$B$22*(CB45-CD45) -> 0 | CF45: =CB45-CE45 -> 3658.5583 | CG45: =BZ45-CD45 -> 480141.44 | CH45: =IF('1 - Input'!$B$17=1,MAX(0,CF45-BX45),0) -> 958.55827 | CI45: =IF('1 - Input'!$B$17=1,MAX(0,BX45-CF45),0) -> 0 | CJ45: =IF(CC45>0,MAX(0,1-CG45/CC45),0) -> 0.0082779623 | CK45: =IF(AND(CI45>0,CC45>0),CI45/(1-'1 - Input'!$B$22*CJ45),0) -> 0 | CL45: =MIN(CK45,CC45) -> 0 | CM45: ='1 - Input'!$B$22*CJ45*CL45 -> 0 | CN45: =CL45-CM45 -> 0 | CO45: =CI45-CN45 -> 0 | CP45: =IF(CC45>0,CL45*MAX(0,CG45/CC45-1),0) -> 0 | CQ45: =CC45-CL45+CH45 -> 485107.77 | CR45: =IF(CL45>0,CG45*(1-CL45/CC45),CG45)+CH45 -> 481100 | CS45: =IF(MOD(BU45,12)=0,CQ45*'1 - Input'!$B$23,0) -> 0 | CT45: =CQ45-CS45 -> 485107.77 | CU45: =IF(MOD(BU45,12)=0,CR45*(1-'1 - Input'!$B$23),CR45) -> 481100 | CV45: =IF('1 - Input'!$B$17=1,MIN(CF45,BX45)+CN45,CF45) -> 2700 | CW45: =CW44+CV45 -> 5400 | CX45: =CX44+CE45 -> 0 | CY45: =CY44+CM45 -> 0 | CZ45: =CZ44+CP45 -> 0 | DA45: =DA44+CS45 -> 0 | DB45: =DB44+CO45 -> 0 | DC45: =IF(CQ45<=0.000001,1,0) -> 0
