Workbook

Sheet 0 - Indice
A1: FIRE per forza — NASPI, TFR, ponte e patrimonio dopo un licenziamento
A2: Strumento informativo / divulgativo. NON è consulenza finanziaria. I valori sono indicativi al 2026 e vanno verificati col tuo consulente.
A4: Indice
A5: 1 - INPUT | B5: Il caso, il patrimonio (la latente si CALCOLA), la sequenza dei rendimenti
A6: 2 - NASPI | B6: I 24 assegni: lorda, riduzione, imposte, trattamento, somma differita, CASSA
A7: 3 - TFR | B7: TFR in azienda (separata, salvaguardia, detrazione) e nel fondo (riscatti, RITA)
A8: 4 - PONTE | B8: I due ponti in mesi di spesa e il mese del primo prelievo
A9: 5 - PATRIMONIO | B9: 44 anni di simulazione, la griglia 4x4, il semaforo, la riga-ingrediente
A10: 6 - VOLONTARI | B10: Prosecuzione volontaria: costo, beneficio netto, pareggio, valore attuale
A11: 7 - PARAMETRI 2026 | B11: Tutti i parametri 2026 con la fonte, e le due scadenze
A13: Come usare
A14: 1. Le celle GIALLE sono input — modificale coi tuoi numeri.
A15: 2. Le celle VERDI sono output — si aggiornano automaticamente.
A16: 3. Tutti i numeri di default sono al 2026 da fonti pubbliche.
A17: 4. Niente codice nascosto: l'Excel è solo formule modificabili.
A19: Fonti dati
A20: • D.Lgs. 4 marzo 2015 n. 22 (NASPI): artt. 4, 5 c. 1, 6 c. 1, 9, 10, 12 c. 1
A21: • Messaggio INPS n. 1414 del 9 aprile 2024 (soglie 5.500 / 8.500)
A22: • Circolare INPS n. 96/2020 (trattamento integrativo) e n. 40 del 3 aprile 2026 (CU)
A23: • L. 207/2024, art. 1 cc. 4-9; FAQ Agenzia delle Entrate del 30 aprile 2026
A24: • Art. 2120 c.c.; art. 19 TUIR; art. 1 c. 9 L. 296/2006; D.M. 20 marzo 2008
A25: • D.Lgs. 252/2005: art. 11 cc. 4 e 4-bis, art. 14 c. 2 lett. b) e c), c. 5
... A31: Aggiornamenti: github.com/marcofire-it/marco-fire-simulatori

Sheet 1 - INPUT
A1: 1 — INPUT: il caso, il patrimonio, la sequenza
A2: Strumento informativo / divulgativo. NON è consulenza finanziaria. I valori sono indicativi al 2026 e vanno verificati col tuo consulente.
A4: IL CASO — lavoro, spesa, età
A5: Retribuzione lorda annua | B5: 50000 | D5: Caso Paolo: 50.000 € lordi, che è anche la carriera media. Netto 32.712,18 €.
A6: anzianità presso l'ultimo datore (anni) | B6: 6
A7: Spesa annua netta | B7: 42000 | D7: Variabile di scelta, non un dato. Ancora ISTAT persona sola 35-64 anni: 2.097 €/mese = 25.164 €/anno (Paolo è a 1,67 volte, ma il dato ISTAT include l'affitto figurativo).
A8: Spesa mensile | B8: =B7/12
A9: età oggi | B9: 48
A10: Anno di nascita | B10: 1978
A11: Mese di nascita (1-12) | B11: 9 | D11: Ramo conservativo: nato nella SECONDA metà del 1978. Chi è nato entro l'aprile esce a 68 anni e 8 mesi nel 2046, con un anno di ponte in meno e circa 40.000 € di capitale in meno.
A12: Coorte e requisito proiettato | B12: =IF(B11<=6,"68 anni e 8 mesi nel "&(B10+68),"68 anni e 10 mesi nel "&(B10+69))
A13: Anno di decorrenza della pensione | B13: =IF(B11<=6,B10+68,B10+69)
A14: Anni al pensionamento (ponte) | B14: =B13-(B10+B9)
A15: Coefficiente di trasformazione | B15: =IF(B11<=6,0.05952,0.05988)
A16: età finale del piano | B16: 92
A17: Orizzonte del piano (anni) | B17: =B16-B9 | D17: Il foglio 5 simula esattamente 44 anni. Se cambi età o orizzonte, allunga o accorcia le righe della simulazione.
A19: IL PATRIMONIO — e la latente, che si CALCOLA
A20: Quota da evento non ricorrente | B20: 700000
A21: plusvalenza latente su quella quota | B21: 0
A22: Quota da accumulo | B22: 1050000
A23: plusvalenza latente su quella quota | B23: 0.5
A24: PATRIMONIO TOTALE | B24: =B20+B22
A25: PLUSVALENZA LATENTE INIZIALE (calcolata) | B25: =(B20*B21+B22*B23)/B24 | D25: Non si digita: esce dalla composizione. 700.000 a latente ~0 più 1.050.000 a latente ~50% fanno esattamente il 30%.
A26: La latente è ENDOGENA (foglio 5): la vendita è a costo medio ponderato (art. 26-quinquies D.P.R. 600/1973), quindi la quota di plusvalenza non cresce per effetto del prelievo — cresce solo per effetto del rendimento. A rendimento reale zero resta al 30% per quarantaquattro anni.
A28: LA SEQUENZA DEI RENDIMENTI
A29: Media geometrica reale (target) | B29: 0.03
A30: Ordine dei crolli | B30: costante | D30: costante = nessun crollo · inizio = crolli agli anni 1-2 · meta = anni 22-23 · fine = anni 43-44. Le posizioni sono dichiarate, non implicite: spostarle di un anno vale circa 700 € l'anno di spesa massima.
A31: Primo crollo | B31: -0.35
A32: Secondo crollo | B32: -0.2
A33: Rendimento degli anni normali | B33: =IF(B30="costante",B29,((1+B29)^B17/((1+B31)*(1+B32)))^(1/(B17-2))-1) | D33: Formula dichiarata: ((1+r)^44 / (0,65 x 0,80))^(1/42) - 1. Al 3% reale gli anni normali valgono +4,764%.
A34: Posizione del primo crollo (anno) | B34: =IF(B30="inizio",1,IF(B30="meta",22,IF(B30="fine",43,0)))
A35: Posizione del secondo crollo (anno) | B35: =IF(B34=0,0,B34+1)
A36: ATTENZIONE, è una scelta e non una previsione: due crolli del 35% e del 20% collocati a mano in quarantaquattro anni NON sono una distribuzione di probabilità. Questo foglio non misura la probabilità che il piano fallisca: misura quanto pesa l'ORDINE, a parità di media geometrica.
A38: PARAMETRI FISCALI DEL PORTAFOGLIO
A39: Aliquota sulle plusvalenze | B39: 0.26
A40: Imposta di bollo sul dossier titoli | B40: 0.002 | D40: Calcolata sul patrimonio di FINE anno, non su quello iniziale: nel percorso al 3% reale va da 3.586 € (anno 1) a 5.211 € (anno 44).

Sheet 2 - NASPI
A1: 2 — NASPI: dalla lorda alla cassa vera
A2: Strumento informativo / divulgativo. NON è consulenza finanziaria. I valori sono indicativi al 2026 e vanno verificati col tuo consulente.
A4: PARAMETRI DELL'INDENNITÀ
A5: Retribuzione lorda annua | C5: ='1 - INPUT'!B5
A6: Retribuzione media mensile imponibile | C6: =C5/12
A7: Soglia di riferimento 2026 | C7: 1456.9
A8: Massimale mensile 2026 | C8: 1584.7
A9: NASPI MENSILE LORDA INIZIALE | C9: =MIN(C8,0.75*MIN(C6,C7)+0.25*MAX(0,C6-C7)) | I9: 75% della retribuzione media fino alla soglia, più il 25% dell'eccedenza, con il tetto del massimale.
A10: Riduzione mensile dal sesto mese | C10: 0.03
A11: Durata (mesi) | C11: 24 | I11: Art. 5 c. 1 D.Lgs. 22/2015. Il tetto delle 78 settimane è abrogato dall'art. 43 c. 3 D.Lgs. 148/2015.
A12: Retribuzione oltre la quale si è al massimale | C12: =12*(C7+(C8-0.75*C7)/0.25) | I12: Sopra questa retribuzione l'assegno è identico per tutti: circa 41.100 € lordi l'anno.
A13: Ultimo assegno in % del primo | C13: =(1-C10)^(C11-5)
A15: IL CALCOLO FISCALE, ANNO PER ANNO
A16: Voce | C16: Anno 1 | D16: Anno 2
A17: NASPI lorda dell'anno (imponibile) | C17: =SUM(B33:B44) | D17: =SUM(B45:B56)
A18: IRPEF lorda (scaglioni 2026) | C18: =(MIN(C17,28000)*0.23+MAX(0,MIN(C17,50000)-28000)*0.33+MAX(0,C17-50000)*0.43) | D18: =(MIN(D17,28000)*0.23+MAX(0,MIN(D17,50000)-28000)*0.33+MAX(0,D17-50000)*0.43)
A19: Detrazione art. 13 c. 1 TUIR | C19: =IF(C17<=15000,1955,IF(C17<=28000,1910+1190*(28000-C17)/13000,IF(C17<=50000,1910*(50000-C17)/22000,0))) | D19: =IF(D17<=15000,1955,IF(D17<=28000,1910+1190*(28000-D17)/13000,IF(D17<=50000,1910*(50000-D17)/22000,0)))
A20: IRPEF netta | C20: =MAX(0,C18-C19) | D20: =MAX(0,D18-D19)
A21: Addizionali regionale e comunale (2%) | C21: =0.02*C17 | D21: =0.02*D17
A22: Trattamento integrativo (mensile, in cassa) | C22: =IF(AND(C17<=15000,C18>1955),1200,0) | D22: =IF(AND(D17<=15000,D18>1955),1200,0)
A23: Somma integrativa L. 207/2024 (DIFFERITA) | C23: =IF(C17<=8500,0.071*C17,IF(C17<=15000,0.053*C17,IF(C17<=20000,0.048*C17,0))) | D23: =IF(D17<=8500,0.071*D17,IF(D17<=15000,0.053*D17,IF(D17<=20000,0.048*D17,0)))
A24: NASPI NETTA CONTABILE | C24: =C17-C20-C21+C22+C23 | D24: =D17-D20-D21+D22+D23
A25: NASPI DI CASSA (senza la somma integrativa) | C25: =C24-C23 | D25: =D24-D23
A26: Fattore di cassa (cassa / lorda) | C26: =C25/C17 | D26: =D25/D17
A27: TOTALE 24 MESI — lordo / netto contabile / CASSA | C27: =C17+D17 | D27: =C24+D24 | E27: =C25+D25
A28: DECISIONE D23 — convenzione unica di SOLA CASSA. La somma integrativa non arriva nel cedolino: si recupera in dichiarazione dei redditi l'anno dopo. Quindi resta FUORI dal ponte del foglio 4 e dentro il consiglio operativo: senza dichiarazione questi soldi si perdono. Il totale contabile (30.354 € netti su 30.437 lordi) resta un'altra grandezza, ed è quella che entra nel foglio 5.
A29: Somma integrativa recuperabile SOLO in dichiarazione | C29: =C23+D23
A31: LE VENTIQUATTRO MENSILITÀ
A32: Mese | B32: NASPI lorda | C32: In % del primo assegno | D32: Imposte (pro quota) | E32: Trattamento integrativo | F32: NETTO DI CASSA | G32: Somma integrativa (differita, NON in cassa)
A33: 1 | B33: =$C$9*(1-$C$10)^MAX(0,A33-5) | C33: =B33/$C$9 | D33: =-($C$20+$C$21)*B33/$C$17 | E33: =$C$22*B33/$C$17 | F33: =B33+D33+E33 | G33: =$C$23*B33/$C$17
A34: 2 | B34: =$C$9*(1-$C$10)^MAX(0,A34-5) | C34: =B34/$C$9 | D34: =-($C$20+$C$21)*B34/$C$17 | E34: =$C$22*B34/$C$17 | F34: =B34+D34+E34 | G34: =$C$23*B34/$C$17
A35: 3 | B35: =$C$9*(1-$C$10)^MAX(0,A35-5) | C35: =B35/$C$9 | D35: =-($C$20+$C$21)*B35/$C$17 | E35: =$C$22*B35/$C$17 | F35: =B35+D35+E35 | G35: =$C$23*B35/$C$17
A36: 4 | B36: =$C$9*(1-$C$10)^MAX(0,A36-5) | C36: =B36/$C$9 | D36: =-($C$20+$C$21)*B36/$C$17 | E36: =$C$22*B36/$C$17 | F36: =B36+D36+E36 | G36: =$C$23*B36/$C$17
A37: 5 | B37: =$C$9*(1-$C$10)^MAX(0,A37-5) | C37: =B37/$C$9 | D37: =-($C$20+$C$21)*B37/$C$17 | E37: =$C$22*B37/$C$17 | F37: =B37+D37+E37 | G37: =$C$23*B37/$C$17
A38: 6 | B38: =$C$9*(1-$C$10)^MAX(0,A38-5) | C38: =B38/$C$9 | D38: =-($C$20+$C$21)*B38/$C$17 | E38: =$C$22*B38/$C$17 | F38: =B38+D38+E38 | G38: =$C$23*B38/$C$17
A39: 7 | B39: =$C$9*(1-$C$10)^MAX(0,A39-5) | C39: =B39/$C$9 | D39: =-($C$20+$C$21)*B39/$C$17 | E39: =$C$22*B39/$C$17 | F39: =B39+D39+E39 | G39: =$C$23*B39/$C$17
A40: 8 | B40: =$C$9*(1-$C$10)^MAX(0,A40-5) | C40: =B40/$C$9 | D40: =-($C$20+$C$21)*B40/$C$17 | E40: =$C$22*B40/$C$17 | F40: =B40+D40+E40 | G40: =$C$23*B40/$C$17
A41: 9 | B41: =$C$9*(1-$C$10)^MAX(0,A41-5) | C41: =B41/$C$9 | D41: =-($C$20+$C$21)*B41/$C$17 | E41: =$C$22*B41/$C$17 | F41: =B41+D41+E41 | G41: =$C$23*B41/$C$17
A42: 10 | B42: =$C$9*(1-$C$10)^MAX(0,A42-5) | C42: =B42/$C$9 | D42: =-($C$20+$C$21)*B42/$C$17 | E42: =$C$22*B42/$C$17 | F42: =B42+D42+E42 | G42: =$C$23*B42/$C$17
A43: 11 | B43: =$C$9*(1-$C$10)^MAX(0,A43-5) | C43: =B43/$C$9 | D43: =-($C$20+$C$21)*B43/$C$17 | E43: =$C$22*B43/$C$17 | F43: =B43+D43+E43 | G43: =$C$23*B43/$C$17
...

Sheet 3 - TFR
A1: 3 — TFR: in azienda o nel fondo pensione
A2: Strumento informativo / divulgativo. NON è consulenza finanziaria. I valori sono indicativi al 2026 e vanno verificati col tuo consulente.
A4: A — TFR LASCIATO IN AZIENDA
A5: Retribuzione lorda annua | B5: ='1 - INPUT'!B5
A6: Anni presso il datore | B6: ='1 - INPUT'!B6
A7: Divisore art. 2120 c.c. | B7: 13.5
A8: Contributo al fondo di garanzia (0,50%) | B8: 0.005
A9: Quota annua accantonata | B9: =B5/B7-B8*B5
A10: Rivalutazione annua (1,5% + 75% inflazione) | B10: 0.03
A11: Montante lordo a fine rapporto | B11: =B9*((1+B10)^B6-1)/B10
A12: di cui quote accantonate (imponibile) | B12: =B9*B6
A13: di cui rivalutazioni | B13: =B11-B12
A14: Imposta sostitutiva sulle rivalutazioni (17%) | B14: 0.17
A15: Rivalutazioni nette | B15: =B13*(1-B14)
A16: FONDO DISPONIBILE (montante al netto del 17%) | B16: =B12+B15
A18: LA TASSAZIONE SEPARATA, E LA CLAUSOLA DI SALVAGUARDIA
A19: Reddito di riferimento = (imponibile / anni) x 12 | B19: =B12/B6*12
A20: IRPEF sul reddito di riferimento — aliquote 2026 | B20: =(MIN(B19,28000)*0.23+MAX(0,MIN(B19,50000)-28000)*0.33+MAX(0,B19-50000)*0.43)
A21: aliquota media 2026 | B21: =B20/B19
A22: IRPEF sul reddito di riferimento — scaglioni 2006 | B22: =(MIN(B19,26000)*0.23+MAX(0,MIN(B19,33500)-26000)*0.33+MAX(0,MIN(B19,100000)-33500)*0.39+MAX(0,B19-100000)*0.43)
A23: aliquota media 2006 | B23: =B22/B19 | E23: Scaglioni al 31/12/2006: 23% fino a 26.000, 33% fino a 33.500, 39% fino a 100.000, 43% oltre.
A24: ALIQUOTA APPLICATA (la più favorevole) | B24: =MIN(B21,B23)
A25: La clausola di salvaguardia si applica? | B25: =IF(B23<B21,"SI — vincono gli scaglioni 2006","NO — vincono le aliquote 2026") | E25: Art. 1 c. 9 L. 296/2006. Su Paolo NON si applica: 27,877% contro 26,244%.
A26: Detrazione D.M. 20/03/2008 (redditi fino a 30.000) | B26: =IF(B19<=7500,70,IF(B19<=28000,50+20*(28000-B19)/20500,IF(B19<=30000,50*(30000-B19)/2000,0))) | E26: Art. 2 c. 514 L. 244/2007. Non tocca Paolo, ma smonta la generalizzazione: chi guadagna poco paga meno del 23%.
A27: IMPOSTA SUL TFR | B27: =MAX(0,B12*B24-B26)
A28: TFR NETTO INCASSATO | B28: =B16-B27
A30: SEPARATA CONTRO ORDINARIA — quanto vale davvero il regime
A31: Aliquota contributiva a carico del lavoratore | B31: 0.0919
A32: Reddito imponibile ordinario dell'anno | B32: =B5*(1-B31)
A33: IRPEF ordinaria sul solo reddito | B33: =(MIN(B32,28000)*0.23+MAX(0,MIN(B32,50000)-28000)*0.33+MAX(0,B32-50000)*0.43)
A34: IRPEF ordinaria su reddito + TFR | B34: =(MIN((B32+B12),28000)*0.23+MAX(0,MIN((B32+B12),50000)-28000)*0.33+MAX(0,(B32+B12)-50000)*0.43)
A35: Imposta che il TFR pagherebbe in ordinaria | B35: =B34-B33
A36: RISPARMIO DELLA TASSAZIONE SEPARATA | B36: =B35-B27 | E36: Il regime È di favore, ma meno di quanto si crede: l'aliquota si calcola su un reddito di riferimento che sta già nel secondo o terzo scaglione.
A37: Aliquota media dei 5 anni precedenti (riliquidazione) | B37: 0.25955
A38: Effetto della riliquidazione | B38: =B12*B24-B12*B37 | E38: Sostanzialmente neutra: un centinaio di euro in più o in meno a seconda della convenzione (imposta NETTA 25,955% contro imposta LORDA 26,834%). Il segno non si afferma.
A40: B — TFR CONFERITO AL FONDO PENSIONE
A41: Posizione individuale (esempio numerico neutro) | B41: 60000 | E41: Non è un dato del caso: è un esempio dichiarato. Il solo TFR di sei anni varrebbe circa 22.000 €.
A42: Fattispecie | B42: Quota riscattabile | C42: Aliquota | D42: Importo netto
A43: Inoccupazione fra 12 e 48 mesi (art. 14 c. 2 lett. b) | B43: 0.5 | C43: dal 15% al 9% | D43: =B41*B43*(1-0.15)
A44: Inoccupazione oltre 48 mesi (art. 14 c. 2 lett. c) | B44: 1 | C44: dal 15% al 9% | D44: =B41*B44*(1-0.15)
...

Sheet 4 - PONTE
A1: 4 — IL PONTE: i ventiquattro mesi, a cassa
A2: Strumento informativo / divulgativo. NON è consulenza finanziaria. I valori sono indicativi al 2026 e vanno verificati col tuo consulente.
A4: PARAMETRI
A5: Spesa mensile | C5: ='1 - INPUT'!B8
A6: TFR netto incassato | C6: ='3 - TFR'!B28
A7: Mese di arrivo del TFR | C7: 2 | I7: L'art. 2120 c.c. non fissa il termine: lo fissano i contratti collettivi, tipicamente fra trenta e sessanta giorni.
A8: Il TFR è nel fondo pensione? | C8: NO
A9: Cassa NASPI dei 24 mesi | C9: ='2 - NASPI'!F57
A10: CONVENZIONE (decisione D23): sola cassa incassata nella finestra dei ventiquattro mesi. I rimborsi fiscali — la somma integrativa che si recupera in dichiarazione — restano FUORI. È l'unica convenzione con cui i due ponti e il mese del primo prelievo tornano insieme.
A12: I VENTIQUATTRO MESI
A13: Mese | B13: NASPI di cassa | C13: TFR | D13: Spesa | E13: Saldo del mese | F13: CUMULATO | G13: aux
A14: 1 | B14: ='2 - NASPI'!F33 | C14: =IF(AND($C$8="NO",A14=$C$7),$C$6,0) | D14: =-$C$5 | E14: =B14+C14+D14 | F14: =E14 | G14: =IF(F14>=0,A14,0)
A15: 2 | B15: ='2 - NASPI'!F34 | C15: =IF(AND($C$8="NO",A15=$C$7),$C$6,0) | D15: =-$C$5 | E15: =B15+C15+D15 | F15: =F14+E15 | G15: =IF(F15>=0,A15,0)
A16: 3 | B16: ='2 - NASPI'!F35 | C16: =IF(AND($C$8="NO",A16=$C$7),$C$6,0) | D16: =-$C$5 | E16: =B16+C16+D16 | F16: =F15+E16 | G16: =IF(F16>=0,A16,0)
A17: 4 | B17: ='2 - NASPI'!F36 | C17: =IF(AND($C$8="NO",A17=$C$7),$C$6,0) | D17: =-$C$5 | E17: =B17+C17+D17 | F17: =F16+E17 | G17: =IF(F17>=0,A17,0)
A18: 5 | B18: ='2 - NASPI'!F37 | C18: =IF(AND($C$8="NO",A18=$C$7),$C$6,0) | D18: =-$C$5 | E18: =B18+C18+D18 | F18: =F17+E18 | G18: =IF(F18>=0,A18,0)
A19: 6 | B19: ='2 - NASPI'!F38 | C19: =IF(AND($C$8="NO",A19=$C$7),$C$6,0) | D19: =-$C$5 | E19: =B19+C19+D19 | F19: =F18+E19 | G19: =IF(F19>=0,A19,0)
A20: 7 | B20: ='2 - NASPI'!F39 | C20: =IF(AND($C$8="NO",A20=$C$7),$C$6,0) | D20: =-$C$5 | E20: =B20+C20+D20 | F20: =F19+E20 | G20: =IF(F20>=0,A20,0)
A21: 8 | B21: ='2 - NASPI'!F40 | C21: =IF(AND($C$8="NO",A21=$C$7),$C$6,0) | D21: =-$C$5 | E21: =B21+C21+D21 | F21: =F20+E21 | G21: =IF(F21>=0,A21,0)
A22: 9 | B22: ='2 - NASPI'!F41 | C22: =IF(AND($C$8="NO",A22=$C$7),$C$6,0) | D22: =-$C$5 | E22: =B22+C22+D22 | F22: =F21+E22 | G22: =IF(F22>=0,A22,0)
A23: 10 | B23: ='2 - NASPI'!F42 | C23: =IF(AND($C$8="NO",A23=$C$7),$C$6,0) | D23: =-$C$5 | E23: =B23+C23+D23 | F23: =F22+E23 | G23: =IF(F23>=0,A23,0)
A24: 11 | B24: ='2 - NASPI'!F43 | C24: =IF(AND($C$8="NO",A24=$C$7),$C$6,0) | D24: =-$C$5 | E24: =B24+C24+D24 | F24: =F23+E24 | G24: =IF(F24>=0,A24,0)
A25: 12 | B25: ='2 - NASPI'!F44 | C25: =IF(AND($C$8="NO",A25=$C$7),$C$6,0) | D25: =-$C$5 | E25: =B25+C25+D25 | F25: =F24+E25 | G25: =IF(F25>=0,A25,0)
A26: 13 | B26: ='2 - NASPI'!F45 | C26: =IF(AND($C$8="NO",A26=$C$7),$C$6,0) | D26: =-$C$5 | E26: =B26+C26+D26 | F26: =F25+E26 | G26: =IF(F26>=0,A26,0)
... A37: 24 | B37: ='2 - NASPI'!F56 | C37: =IF(AND($C$8="NO",A37=$C$7),$C$6,0) | D37: =-$C$5 | E37: =B37+C37+D37 | F37: =F36+E37 | G37: =IF(F37>=0,A37,0)
A38: TOT | B38: =SUM(B14:B37) | C38: =SUM(C14:C37) | D38: =SUM(D14:D37) | E38: =SUM(E14:E37)
A40: I RISULTATI
A41: CASSA TOTALE NEI 24 MESI (NASPI + TFR) | C41: =B38+C38
A42: PONTE — NASPI + TFR, in mesi di spesa | C42: =(B38+C38)/C5
A43: PONTE — NASPI sola (TFR nel fondo), in mesi di spesa | C43: =B38/C5
A44: PRIMO PRELIEVO DAL PATRIMONIO (mese) | C44: =1+MAX(G14:G37)
A45: Cumulato a 24 mesi | C45: =F37
A46: Ponte in % dei 24 mesi | C46: =(B38+C38)/C5/24
A47: La cella «primo prelievo» è il mese dal quale il conto non torna più in pari — non il primo mese scoperto. Il primo mese è comunque scoperto finché la liquidazione non arriva. Il risultato è robusto: il TFR può arrivare in un qualunque mese fra il primo e il settimo, il mese del primo prelievo non si muove.
A48: I ventiquattro mesi portano in cassa poco più di tredici mesi di spesa. Se il trattamento di fine rapporto è nel fondo pensione, otto e due. A rosicchiare il ponte non è l'IRPEF — lo Stato si riprende ottantatré euro su trentamilaquattrocento — è la riduzione progressiva dell'assegno e la durata.

Sheet 5 - PATRIMONIO
A1: 5 — PATRIMONIO: quarantaquattro anni, uno per uno
A2: Strumento informativo / divulgativo. NON è consulenza finanziaria. I valori sono indicativi al 2026 e vanno verificati col tuo consulente.
A4: PARAMETRI DELLA SIMULAZIONE
A5: Patrimonio iniziale — override (0 = usa il foglio INPUT) | D5: 0
A6: Spesa annua netta — override (0 = usa il foglio INPUT) | D6: 0 | N6: Sono le due celle su cui lanciare Ricerca obiettivo: vedi le istruzioni in fondo al foglio.
A7: Patrimonio iniziale usato | D7: =IF($D$5>0,$D$5,'1 - INPUT'!B24)
A8: Plusvalenza latente iniziale | D8: ='1 - INPUT'!B25
A9: Base fiscale iniziale | D9: =D7*(1-D8)
A10: Spesa annua netta usata | D10: =IF($D$6>0,$D$6,'1 - INPUT'!B7)
A11: Aliquota sulle plusvalenze | D11: ='1 - INPUT'!B39
A12: Imposta di bollo (sul patrimonio di fine anno) | D12: ='1 - INPUT'!B40
A13: Anni al pensionamento | D13: ='1 - INPUT'!B14
A14: Pensione netta annua (13 mensilità) | D14: 20421.86
A15: NASPI netta contabile, anno 1 | D15: ='2 - NASPI'!C24
A16: NASPI netta contabile, anno 2 | D16: ='2 - NASPI'!D24
A17: TFR netto (0 se è nel fondo pensione) | D17: =IF('4 - PONTE'!C8="SI",0,'3 - TFR'!B28)
A18: Media geometrica reale | D18: ='1 - INPUT'!B29
A19: Ordine dei crolli | D19: ='1 - INPUT'!B30
A20: Rendimento degli anni normali | D20: ='1 - INPUT'!B33
A21: Anno del primo crollo | D21: ='1 - INPUT'!B34
A22: Anno del secondo crollo | D22: ='1 - INPUT'!B35
A23: Primo crollo / secondo crollo | D23: ='1 - INPUT'!B31&" / "&'1 - INPUT'!B32
A24: RIGA-INGREDIENTE (gate G4). Gli anni 1 e 2 di questa simulazione contengono la NASPI netta e il trattamento di fine rapporto: sono i numeri di chi esce ADESSO. Chi è già fermo da tempo non li ha più e deve aggiungere circa cinquantamila euro al capitale necessario. La riga è esplicita nella tabella del capitale, in fondo al foglio.
A26: LA SIMULAZIONE, ANNO PER ANNO
A27: Anno | B27: età | C27: Fabbisogno netto | D27: Patrimonio a inizio anno | E27: Base fiscale a inizio anno | F27: Latente | G27: Vendita lorda | H27: Base consumata | I27: Rendimento | J27: Patrimonio prima del bollo | K27: Imposta di bollo | L27: PATRIMONIO A FINE ANNO
A28: 1 | B28: ='1 - INPUT'!$B$9+A28 | C28: =IF(A28=1,$D$10-$D$15-$D$17,IF(A28=2,$D$10-$D$16,IF(A28<=$D$13,$D$10,$D$10-$D$14))) | D28: =$D$7 | E28: =$D$9 | F28: =IF(D28<=0,0,1-E28/D28) | G28: =IF(D28<=0,0,IF(C28>0,C28/(1-$D$11*F28),C28)) | H28: =IF(C28>0,G28*(1-F28),G28) | I28: =IF(A28=$D$21,'1 - INPUT'!$B$31,IF(A28=$D$22,'1 - INPUT'!$B$32,$D$20)) | J28: =(D28-G28)*(1+I28) | K28: =$D$12*J28 | L28: =J28-K28
A29: 2 | B29: ='1 - INPUT'!$B$9+A29 | C29: =IF(A29=1,$D$10-$D$15-$D$17,IF(A29=2,$D$10-$D$16,IF(A29<=$D$13,$D$10,$D$10-$D$14))) | D29: =L28 | E29: =(E28-H28)*(1-$D$12) | F29: =IF(D29<=0,0,1-E29/D29) | G29: =IF(D29<=0,0,IF(C29>0,C29/(1-$D$11*F29),C29)) | H29: =IF(C29>0,G29*(1-F29),G29) | I29: =IF(A29=$D$21,'1 - INPUT'!$B$31,IF(A29=$D$22,'1 - INPUT'!$B$32,$D$20)) | J29: =(D29-G29)*(1+I29) | K29: =$D$12*J29 | L29: =J29-K29
A30: 3 | B30: ='1 - INPUT'!$B$9+A30 | C30: =IF(A30=1,$D$10-$D$15-$D$17,IF(A30=2,$D$10-$D$16,IF(A30<=$D$13,$D$10,$D$10-$D$14))) | D30: =L29 | E30: =(E29-H29)*(1-$D$12) | F30: =IF(D30<=0,0,1-E30/D30) | G30: =IF(D30<=0,0,IF(C30>0,C30/(1-$D$11*F30),C30)) | H30: =IF(C30>0,G30*(1-F30),G30) | I30: =IF(A30=$D$21,'1 - INPUT'!$B$31,IF(A30=$D$22,'1 - INPUT'!$B$32,$D$20)) | J30: =(D30-G30)*(1+I30) | K30: =$D$12*J30 | L30: =J30-K30
A31: 4 | B31: ='1 - INPUT'!$B$9+A31 | C31: =IF(A31=1,$D$10-$D$15-$D$17,IF(A31=2,$D$10-$D$16,IF(A31<=$D$13,$D$10,$D$10-$D$14))) | D31: =L30 | E31: =(E30-H30)*(1-$D$12) | F31: =IF(D31<=0,0,1-E31/D31) | G31: =IF(D31<=0,0,IF(C31>0,C31/(1-$D$11*F31),C31)) | H31: =IF(C31>0,G31*(1-F31),G31) | I31: =IF(A31=$D$21,'1 - INPUT'!$B$31,IF(A31=$D$22,'1 - INPUT'!$B$32,$D$20)) | J31: =(D31-G31)*(1+I31) | K31: =$D$12*J31 | L31: =J31-K31
A32: 5 | B32: ='1 - INPUT'!$B$9+A32 | C32: =IF(A32=1,$D$10-$D$15-$D$17,IF(A32=2,$D$10-$D$16,IF(A32<=$D$13,$D$10,$D$10-$D$14))) | D32: =L31 | E32: =(E31-H31)*(1-$D$12) | F32: =IF(D32<=0,0,1-E32/D32) | G32: =IF(D32<=0,0,IF(C32>0,C32/(1-$D$11*F32),C32)) | H32: =IF(C32>0,G32*(1-F32),G32) | I32: =IF(A32=$D$21,'1 - INPUT'!$B$31,IF(A32=$D$22,'1 - INPUT'!$B$32,$D$20)) | J32: =(D32-G32)*(1+I32) | K32: =$D$12*J32 | L32: =J32-K32
A33: 6 | B33: ='1 - INPUT'!$B$9+A33 | C33: =IF(A33=1,$D$10-$D$15-$D$17,IF(A33=2,$D$10-$D$16,IF(A33<=$D$13,$D$10,$D$10-$D$14))) | D33: =L32 | E33: =(E32-H32)*(1-$D$12) | F33: =IF(D33<=0,0,1-E33/D33) | G33: =IF(D33<=0,0,IF(C33>0,C33/(1-$D$11*F33),C33)) | H33: =IF(C33>0,G33*(1-F33),G33) | I33: =IF(A33=$D$21,'1 - INPUT'!$B$31,IF(A33=$D$22,'1 - INPUT'!$B$32,$D$20)) | J33: =(D33-G33)*(1+I33) | K33: =$D$12*J33 | L33: =J33-K33
A34: 7 | B34: ='1 - INPUT'!$B$9+A34 | C34: =IF(A34=1,$D$10-$D$15-$D$17,IF(A34=2,$D$10-$D$16,IF(A34<=$D$13,$D$10,$D$10-$D$14))) | D34: =L33 | E34: =(E33-H33)*(1-$D$12) | F34: =IF(D34<=0,0,1-E34/D34) | G34: =IF(D34<=0,0,IF(C34>0,C34/(1-$D$11*F34),C34)) | H34: =IF(C34>0,G34*(1-F34),G34) | I34: =IF(A34=$D$21,'1 - INPUT'!$B$31,IF(A34=$D$22,'1 - INPUT'!$B$32,$D$20)) | J34: =(D34-G34)*(1+I34) | K34: =$D$12*J34 | L34: =J34-K34
A35: 8 | B35: ='1 - INPUT'!$B$9+A35 | C35: =IF(A35=1,$D$10-$D$15-$D$17,IF(A35=2,$D$10-$D$16,IF(A35<=$D$13,$D$10,$D$10-$D$14))) | D35: =L34 | E35: =(E34-H34)*(1-$D$12) | F35: =IF(D35<=0,0,1-E35/D35) | G35: =IF(D35<=0,0,IF(C35>0,C35/(1-$D$11*F35),C35)) | H35: =IF(C35>0,G35*(1-F35),G35) | I35: =IF(A35=$D$21,'1 - INPUT'!$B$31,IF(A35=$D$22,'1 - INPUT'!$B$32,$D$20)) | J35: =(D35-G35)*(1+I35) | K35: =$D$12*J35 | L35: =J35-K35
A36: 9 | B36: ='1 - INPUT'!$B$9+A36 | C36: =IF(A36=1,$D$10-$D$15-$D$17,IF(A36=2,$D$10-$D$16,IF(A36<=$D$13,$D$10,$D$10-$D$14))) | D36: =L35 | E36: =(E35-H35)*(1-$D$12) | F36: =IF(D36<=0,0,1-E36/D36) | G36: =IF(D36<=0,0,IF(C36>0,C36/(1-$D$11*F36),C36)) | H36: =IF(C36>0,G36*(1-F36),G36) | I36: =IF(A36=$D$21,'1 - INPUT'!$B$31,IF(A36=$D$22,'1 - INPUT'!$B$32,$D$20)) | J36: =(D36-G36)*(1+I36) | K36: =$D$12*J36 | L36: =J36-K36
A37: 10 | B37: ='1 - INPUT'!$B$9+A37 | C37: =IF(A37=1,$D$10-$D$15-$D$17,IF(A37=2,$D$10-$D$16,IF(A37<=$D$13,$D$10,$D$10-$D$14))) | D37: =L36 | E37: =(E36-H36)*(1-$D$12) | F37: =IF(D37<=0,0,1-E37/D37) | G37: =IF(D37<=0,0,IF(C37>0,C37/(1-$D$11*F37),C37)) | H37: =IF(C37>0,G37*(1-F37),G37) | I37: =IF(A37=$D$21,'1 - INPUT'!$B$31,IF(A37=$D$22,'1 - INPUT'!$B$32,$D$20)) | J37: =(D37-G37)*(1+I37) | K37: =$D$12*J37 | L37: =J37-K37
A38: 11 | B38: ='1 - INPUT'!$B$9+A38 | C38: =IF(A38=1,$D$10-$D$15-$D$17,IF(A38=2,$D$10-$D$16,IF(A38<=$D$13,$D$10,$D$10-$D$14))) | D38: =L37 | E38: =(E37-H37)*(1-$D$12) | F38: =IF(D38<=0,0,1-E38/D38) | G38: =IF(D38<=0,0,IF(C38>0,C38/(1-$D$11*F38),C38)) | H38: =IF(C38>0,G38*(1-F38),G38) | I38: =IF(A38=$D$21,'1 - INPUT'!$B$31,IF(A38=$D$22,'1 - INPUT'!$B$32,$D$20)) | J38: =(D38-G38)*(1+I38) | K38: =$D$12*J38 | L38: =J38-K38
A39: 12 | B39: ='1 - INPUT'!$B$9+A39 | C39: =IF(A39=1,$D$10-$D$15-$D$17,IF(A39=2,$D$10-$D$16,IF(A39<=$D$13,$D$10,$D$10-$D$14))) | D39: =L38 | E39: =(E38-H38)*(1-$D$12) | F39: =IF(D39<=0,0,1-E39/D39) | G39: =IF(D39<=0,0,IF(C39>0,C39/(1-$D$11*F39),C39)) | H39: =IF(C39>0,G39*(1-F39),G39) | I39: =IF(A39=$D$21,'1 - INPUT'!$B$31,IF(A39=$D$22,'1 - INPUT'!$B$32,$D$20)) | J39: =(D39-G39)*(1+I39) | K39: =$D$12*J39 | L39: =J39-K39
A40: 13 | B40: ='1 - INPUT'!$B$9+A40 | C40: =IF(A40=1,$D$10-$D$15-$D$17,IF(A40=2,$D$10-$D$16,IF(A40<=$D$13,$D$10,$D$10-$D$14))) | D40: =L39 | E40: =(E39-H39)*(1-$D$12) | F40: =IF(D40<=0,0,1-E40/D40) | G40: =IF(D40<=0,0,IF(C40>0,C40/(1-$D$11*F40),C40)) | H40: =IF(C40>0,G40*(1-F40),G40) | I40: =IF(A40=$D$21,'1 - INPUT'!$B$31,IF(A40=$D$22,'1 - INPUT'!$B$32,$D$20)) | J40: =(D40-G40)*(1+I40) | K40: =$D$12*J40 | L40: =J40-K40
... A71: 44 | B71: ='1 - INPUT'!$B$9+A71 | C71: =IF(A71=1,$D$10-$D$15-$D$17,IF(A71=2,$D$10-$D$16,IF(A71<=$D$13,$D$10,$D$10-$D$14))) | D71: =L70 | E71: =(E70-H70)*(1-$D$12) | F71: =IF(D71<=0,0,1-E71/D71) | G71: =IF(D71<=0,0,IF(C71>0,C71/(1-$D$11*F71),C71)) | H71: =IF(C71>0,G71*(1-F71),G71) | I71: =IF(A71=$D$21,'1 - INPUT'!$B$31,IF(A71=$D$22,'1 - INPUT'!$B$32,$D$20)) | J71: =(D71-G71)*(1+I71) | K71: =$D$12*J71 | L71: =J71-K71
A72: PATRIMONIO RESIDUO ALLA FINE DEL PIANO | L72: =L71
...

Sheet 6 - VOLONTARI
A1: 6 — PROSECUZIONE VOLONTARIA: quanto costa, quanto vale
A2: Strumento informativo / divulgativo. NON è consulenza finanziaria. I valori sono indicativi al 2026 e vanno verificati col tuo consulente.
A4: IL COSTO
A5: Retribuzione lorda annua di riferimento | B5: ='1 - INPUT'!B5
A6: Aliquota IVS | B6: 0.33
A7: Prima fascia di retribuzione pensionabile 2026 | B7: 56224
A8: Aliquota aggiuntiva oltre la prima fascia | B8: 0.01
A9: COSTO ANNUO | B9: =B5*B6+MAX(0,B5-B7)*B8 | F9: Con 50.000 € si è sotto la prima fascia: niente aliquota aggiuntiva. La regola resta applicata simmetricamente.
A10: Anni di prosecuzione volontaria | B10: 18.83
A11: Numero di versamenti (per il valore attuale) | B11: 19
A12: Primo versamento utile | B12: ="mese "&('2 - NASPI'!C11+1)&" — durante la NASPI non si versa" | F12: I ventiquattro mesi di indennità sono già coperti da contribuzione figurativa (art. 12 c. 1 D.Lgs. 22/2015): versare lì sarebbe soldi buttati.
A13: REQUISITI (L. 18 febbraio 1983 n. 47, art. 1 cc. 3 e 4, richiamati per gli altri regimi dall'art. 5 cc. 2 e 2-bis del D.Lgs. 184/1997): 260 contributi settimanali qualunque sia l'epoca del versamento, oppure 156 nel quinquennio precedente la domanda. I requisiti si perfezionano con contribuzione effettiva: la figurativa è di regola esclusa, salvo eccezioni tassative (cassa integrazione, TBC, aspettativa sindacale o politica).
A15: IL BENEFICIO LORDO
A16: Rivalutazione reale del montante | B16: 0.006 | F16: Parametro del modello, banda dichiarata 0,0% - 1,2% reale. Non è il rendimento realizzato 2006-2025.
A17: Montante aggiuntivo a fine versamenti | B17: =B9*((1+B16)^B10-1)/B16
A18: Coefficiente di trasformazione | B18: ='1 - INPUT'!B15
A19: PENSIONE LORDA AGGIUNTIVA (annua) | B19: =B17*B18
A20: Incremento lordo di UN anno di versamenti | B20: =B9*(1+B16)^B10*B18
A21: PAREGGIO LORDO (anni) | B21: =B9/B20 | F21: È l'inverso del prodotto fra coefficiente e rivalutazione: non dipende da quanto versi.
A23: IL BENEFICIO NETTO — modello fiscale della pensione
A24: Voce | B24: Pensione base | C24: Base + incremento pieno | D24: Base + un anno
A25: Pensione lorda annua | B25: 26135.85 | C25: =B25+B19 | D25: =B25+B20
A26: IRPEF lorda (scaglioni 2026) | B26: =(MIN(B25,28000)*0.23+MAX(0,MIN(B25,50000)-28000)*0.33+MAX(0,B25-50000)*0.43) | C26: =(MIN(C25,28000)*0.23+MAX(0,MIN(C25,50000)-28000)*0.33+MAX(0,C25-50000)*0.43) | D26: =(MIN(D25,28000)*0.23+MAX(0,MIN(D25,50000)-28000)*0.33+MAX(0,D25-50000)*0.43)
A27: Detrazione art. 13 c. 3 TUIR | B27: =IF(B25<=8500,1955,IF(B25<=28000,700+1255*(28000-B25)/19500,IF(B25<=50000,700*(50000-B25)/22000,0))) | C27: =IF(C25<=8500,1955,IF(C25<=28000,700+1255*(28000-C25)/19500,IF(C25<=50000,700*(50000-C25)/22000,0))) | D27: =IF(D25<=8500,1955,IF(D25<=28000,700+1255*(28000-D25)/19500,IF(D25<=50000,700*(50000-D25)/22000,0)))
A28: IRPEF netta | B28: =MAX(0,B26-B27) | C28: =MAX(0,C26-C27) | D28: =MAX(0,D26-D27)
A29: Addizionali (2%) | B29: =0.02*B25 | C29: =0.02*C25 | D29: =0.02*D25
A30: PENSIONE NETTA | B30: =B25-B28-B29 | C30: =C25-C28-C29 | D30: =D25-D28-D29
A31: INCREMENTO NETTO (differenza finita) | C31: =C30-B30 | D31: =D30-B30
A32: Aliquota marginale effettiva | B32: =1-(D30-B30)/(D25-B25) | F32: Non si digita: esce per differenza finita. 23% di IRPEF, più il 6,436% della detrazione da pensione che si consuma (1.255/19.500), più il 2% di addizionali.
A33: PAREGGIO NETTO (anni) | B33: =B9/(D30-B30) | F33: Vita residua attesa a 69 anni: 18,1 anni (totale), 16,8 (maschi), 19,3 (femmine) — stima 2025, consolidamento dicembre 2026. Il verdetto NON poggia su questo numero.
A35: IL CONFRONTO IN VALORE ATTUALE — ed è qui che si decide
A36: Anni di erogazione della pensione | B36: ='1 - INPUT'!B16-('1 - INPUT'!B9+'1 - INPUT'!B14)
A37: Anni di attesa prima della decorrenza | B37: ='1 - INPUT'!B14
A38: Tasso di sconto reale | B38: 1% | C38: 2% | D38: 3%
A39: Valore attuale del COSTO | B39: =$B$9*(1-(1+0.01)^-$B$11)/0.01*(1+0.01)^-2 | C39: =$B$9*(1-(1+0.02)^-$B$11)/0.02*(1+0.02)^-2 | D39: =$B$9*(1-(1+0.03)^-$B$11)/0.03*(1+0.03)^-2
A40: Valore attuale del BENEFICIO | B40: =($C$30-$B$30)*(1-(1+0.01)^-$B$36)/0.01*(1+0.01)^-$B$37 | C40: =($C$30-$B$30)*(1-(1+0.02)^-$B$36)/0.02*(1+0.02)^-$B$37 | D40: =($C$30-$B$30)*(1-(1+0.03)^-$B$36)/0.03*(1+0.03)^-$B$37
A41: EURO SPESI PER COMPRARNE UNO | B41: =B39/B40 | C41: =C39/C40 | D41: =D39/D40
A42: VERDETTO — non conviene. Al tre per cento reale servono due euro e sei per comprarne uno; all'uno per cento il conto si avvicina al pareggio, un euro e trentasette. Due clausole obbligatorie: si sta scontando una rendita pubblica indicizzata e vitalizia con il tasso di un portafoglio rischioso, e il beneficio è troncato a novantadue anni — chi vive di più continua a incassare, ma i volontari li ha già pagati tutti.
A43: ECCEZIONE, e non è un dettaglio: chi non raggiunge il DIRITTO alla pensione — non ha i venti anni di contributi, o non arriva alla soglia di importo — ha un problema diverso, e lì i volontari sono la cosa più redditizia che esista. Questo foglio parla di chi il diritto ce l'ha già.

Sheet 7 - PARAMETRI 2026
A1: 7 — PARAMETRI 2026, con la fonte di ciascuno
A2: Strumento informativo / divulgativo. NON è consulenza finanziaria. I valori sono indicativi al 2026 e vanno verificati col tuo consulente.
A4: Parametro | B4: Valore | C4: Riferimento normativo / fonte | D4: deperibilità
A5: — NASPI —
A6: Massimale mensile | B6: 1.584,70 € | C6: Art. 4 c. 1 D.Lgs. 22/2015; importo rivalutato per il 2026 | D6: Refresh gennaio 2027
A7: Soglia di riferimento (75% / 25%) | B7: 1.456,90 € | C7: Art. 4 c. 1 D.Lgs. 22/2015 | D7: Refresh gennaio 2027
A8: Retribuzione oltre cui si è al massimale | B8: circa 41.100 € lordi/anno | C8: Derivata dai due parametri qui sopra | D8: Refresh gennaio 2027
A9: Durata massima | B9: 24 mesi | C9: Art. 5 c. 1 D.Lgs. 22/2015; il tetto delle 78 settimane è abrogato dall'art. 43 c. 3 D.Lgs. 148/2015 | D9: Stabile
A10: Riduzione mensile | B10: 3% dal sesto mese | C10: Art. 4 c. 3 D.Lgs. 22/2015 | D10: Stabile
A11: Decorrenza | B11: dall'ottavo giorno; domanda entro 68 giorni | C11: Art. 6 c. 1 D.Lgs. 22/2015 (i 68 giorni); art. 6 c. 2 (l'ottavo giorno) | D11: Stabile
A12: Contribuzione figurativa | B12: 1,4 volte il massimale = 2.218,58 €/mese | C12: Art. 12 c. 1 D.Lgs. 22/2015 | D12: Refresh gennaio 2027
A13: compatibilità con lavoro autonomo | B13: 5.500 €/anno | C13: Art. 10 D.Lgs. 22/2015, che rinvia alle detrazioni dell'art. 13 c. 5 TUIR; soglia tabellata dal messaggio INPS n. 1414 del 9 aprile 2024 | D13: Refresh gennaio 2027
A14: compatibilità con lavoro subordinato | B14: 8.500 €/anno | C14: Art. 9 D.Lgs. 22/2015, che rinvia all'art. 13 TUIR; messaggio INPS n. 1414 del 9 aprile 2024 | D14: Refresh gennaio 2027
A15: Regola della compatibilità | B15: entro soglia: riduzione dell'80% del reddito; oltre soglia: decadenza | C15: Artt. 9 e 10 D.Lgs. 22/2015 | D15: Stabile
A16: Adempimenti | B16: NASPI-COM entro 30 giorni a pena di decadenza; autodichiarazione del reddito entro il 31 marzo dell'anno successivo | C16: Prassi INPS | D16: Stabile
A17: Certificazione unica | B17: — | C17: Circolare INPS n. 40 del 3 aprile 2026 (correzione CU dal 31/3/2026) | D17: Annuale
A18: — IRPEF E BONUS —
A19: Scaglioni IRPEF | B19: 23% fino a 28.000 · 33% fino a 50.000 · 43% oltre | C19: Art. 11 TUIR come modificato dalla Legge di Bilancio 2026 | D19: Refresh gennaio 2027 + rinumerazione TUIR
A20: Addizionali regionale e comunale | B20: 2,0% (ipotesi di lavoro) | C20: Varia per comune e regione: va sostituita con la propria | D20: Da personalizzare
A21: Detrazione da lavoro dipendente | B21: 1.955 fino a 15.000; 1.910 + 1.190 x (28.000 - R)/13.000 fino a 28.000; 1.910 x (50.000 - R)/22.000 fino a 50.000 | C21: Art. 13 c. 1 TUIR | D21: Refresh gennaio 2027 + rinumerazione TUIR
A22: Detrazione da pensione | B22: 1.955 fino a 8.500; 700 + 1.255 x (28.000 - R)/19.500 fino a 28.000; 700 x (50.000 - R)/22.000 fino a 50.000 | C22: Art. 13 c. 3 TUIR | D22: Refresh gennaio 2027 + rinumerazione TUIR
A23: Trattamento integrativo | B23: 1.200 €/anno | C23: D.L. 3/2020, non soppresso dalla L. 207/2024; erogato automaticamente dall'INPS sulla NASPI (circolare INPS n. 96/2020) | D23: Refresh gennaio 2027
A24: Somma integrativa sul cuneo | B24: 7,1% fino a 8.500 · 5,3% fino a 15.000 · 4,8% fino a 20.000 | C24: Art. 1 cc. 4-9 L. 207/2024. applicabilità ai proventi sostitutivi del reddito di lavoro dipendente: FAQ Agenzia delle Entrate del 30 aprile 2026 | D24: Refresh gennaio 2027
A25: Ulteriore detrazione | B25: 1.000 € fra 20.000 e 32.000, decrescente fino a 40.000 | C25: Art. 1 L. 207/2024 | D25: Refresh gennaio 2027
A26: La somma integrativa NON è cassa mensile | B26: si recupera in dichiarazione | C26: Decisione D23 del dossier: convenzione unica di sola cassa nella finestra dei 24 mesi | D26: Stabile
A27: — TFR —
A28: Quota annua | B28: retribuzione / 13,5 meno lo 0,50% | C28: Art. 2120 c.c. | D28: Stabile
A29: Rivalutazione | B29: 1,5% fisso + 75% dell'inflazione | C29: Art. 2120 c.c.; imposta sostitutiva del 17% sulle rivalutazioni | D29: Annuale
A30: Termine di pagamento | B30: fra 30 e 60 giorni, secondo il CCNL | C30: Non fissato dall'art. 2120 c.c.: lo fissano i contratti collettivi | D30: Per contratto
A31: Tassazione separata | B31: aliquota media sul reddito di riferimento | C31: Art. 19 TUIR — reddito di riferimento = (imponibile / anni) x 12 | D31: Rinumerazione TUIR dal 1/1/2027
A32: Clausola di salvaguardia | B32: scaglioni 2006: 23% fino a 26.000, 33% fino a 33.500, 39% fino a 100.000, 43% oltre; si applica se più favorevole | C32: Art. 1 c. 9 L. 296/2006 | D32: RINUMERATA nell'art. 21 c. 11 del D.Lgs. 117/2026 — NON abrogata
A33: Detrazione TFR | B33: 70 € fino a 7.500; decrescente fino a 28.000; 50 € fra 28.000 e 30.000 | C33: D.M. 20 marzo 2008, in attuazione dell'art. 2 c. 514 L. 244/2007 | D33: Stabile
A34: — FONDO PENSIONE —
A35: Riscatto per inoccupazione 12-48 mesi | B35: 50% della posizione, dal 15% al 9% | C35: Art. 14 c. 2 lett. b) D.Lgs. 252/2005 | D35: Stabile
A36: Riscatto per inoccupazione oltre 48 mesi | B36: totale, dal 15% al 9% | C36: Art. 14 c. 2 lett. c) D.Lgs. 252/2005 | D36: Stabile
A37: Divieto quinquennale | B37: il riscatto totale non è esercitabile nel quinquennio precedente la maturazione dei requisiti: si applica l'art. 11 c. 4 | C37: Art. 14 c. 2 lett. c), seconda parte, D.Lgs. 252/2005 | D37: Stabile
A38: Riscatto per cause diverse | B38: totale, 23% | C38: Art. 14 c. 5 D.Lgs. 252/2005 | D38: Stabile
A39: RITA — comma 4 | B39: 5 anni dalla vecchiaia E 20 anni di contributi obbligatori | C39: Art. 11 c. 4 D.Lgs. 252/2005 | D39: Stabile
A40: RITA — comma 4-bis | B40: inoccupazione oltre 24 mesi, 10 anni dalla vecchiaia; NON chiede i 20 anni | C40: Art. 11 c. 4-bis D.Lgs. 252/2005 | D40: Stabile
A41: — PENSIONE E VOLONTARI —
...
