Workbook
Name Cm_m26: '1 - Dati'!$C$30
Name Cm_nasc_a: '1 - Dati'!$C$26
Name Cm_nasc_m: '1 - Dati'!$C$27
Name Cm_netto: '2 - Pensioni'!$C$17
Name Cm_ord_cf: '5 - Motore e tabelle'!$H$358
Name Cm_ord_da: '5 - Motore e tabelle'!$H$353
Name Cm_ord_dm: '5 - Motore e tabelle'!$H$354
Name Cm_ord_em: '5 - Motore e tabelle'!$H$352
Name Cm_primo: '1 - Dati'!$C$29
Name Cm_ral: '1 - Dati'!$C$28
Name Cm_v71_cf: '5 - Motore e tabelle'!$I$358
Name Cm_v71_da: '5 - Motore e tabelle'!$I$353
Name Cm_v71_dm: '5 - Motore e tabelle'!$I$354
Name Cm_v71_em: '5 - Motore e tabelle'!$I$352
Name CT_eta: '5 - Motore e tabelle'!$A$106:$A$120
Name CT_val: '5 - Motore e tabelle'!$B$106:$B$120
Name Dist_tot_1: '2 - Pensioni'!$F$22
Name Dist_tot_2: '2 - Pensioni'!$F$23
Name Dist_tot_3: '2 - Pensioni'!$F$24
Name Dist_tot_4: '2 - Pensioni'!$F$25
Name Ered_2026: '1 - Dati'!$B$51
Name Ered_anno: '1 - Dati'!$B$50
Name Ered_nom: '1 - Dati'!$B$49
Name F_nom: '5 - Motore e tabelle'!$B$21
Name FZ_key: '5 - Motore e tabelle'!$A$310:$A$321
Name FZ_val: '5 - Motore e tabelle'!$E$310:$E$321
Name G_real: '5 - Motore e tabelle'!$B$22
Name imp_R1: '5 - Motore e tabelle'!$B$323
Name imp_R2: '5 - Motore e tabelle'!$B$324
Name K_raw: '5 - Motore e tabelle'!$E$138:$E$306
Name lam_A0: '5 - Motore e tabelle'!$B$24
Name lam_C0: '5 - Motore e tabelle'!$B$23
Name Leva_C: '3 - Numero FIRE'!$B$57
Name Leva_T: '3 - Numero FIRE'!$B$56
Name N_eta: '5 - Motore e tabelle'!$A$125:$A$134
Name Nodi_2013: '5 - Motore e tabelle'!$B$125:$B$134
Name Nodi_2025: '5 - Motore e tabelle'!$C$125:$C$134
Name Num_esito_1: '3 - Numero FIRE'!$B$14
Name Num_esito_2: '3 - Numero FIRE'!$C$14
Name Num_esito_3: '3 - Numero FIRE'!$D$14
Name Num_fine26_1: '3 - Numero FIRE'!$B$16
Name Num_fine26_2: '3 - Numero FIRE'!$C$16
Name Num_fine26_3: '3 - Numero FIRE'!$D$16
Name Num_marg_1: '3 - Numero FIRE'!$B$12
Name Num_marg_2: '3 - Numero FIRE'!$C$12
Name Num_marg_3: '3 - Numero FIRE'!$D$12
Name Num_patr_1: '3 - Numero FIRE'!$B$10
Name Num_patr_2: '3 - Numero FIRE'!$C$10
Name Num_patr_3: '3 - Numero FIRE'!$D$10
Name Num_ric_1: '3 - Numero FIRE'!$B$11
Name Num_ric_2: '3 - Numero FIRE'!$C$11
Name Num_ric_3: '3 - Numero FIRE'!$D$11
Name p_add: '1 - Dati'!$B$10
Name p_anni_eff: '1 - Dati'!$B$20
Name p_anni_min: '1 - Dati'!$B$19
Name p_AS: '1 - Dati'!$B$14
Name p_banda: '1 - Dati'!$B$22
Name p_bollo: '1 - Dati'!$B$8
Name p_cgt: '1 - Dati'!$B$9
Name p_comp: '1 - Dati'!$B$12

Sheet 0 - Indice
A1: FIRE in coppia: un numero o due? Il caso di Tiziano e Camilla (caso inventato e illustrativo)
A2: Strumento informativo / divulgativo. NON è consulenza finanziaria. I valori sono indicativi al 2026 e vanno verificati col tuo consulente.
A4: Indice
A5: 0 - Indice | B5: Questo indice
A6: 1 - Dati | B6: I tuoi dati (celle gialle): ipotesi, persone, spese, patrimonio, scenari, vedovanza
A7: 2 - Pensioni | B7: Stipendio netto e pensione di vecchiaia di ciascuno, regola dei 20 anni
A8: 3 - Numero FIRE | B8: Il numero FIRE: quanto serve, ponte e tratti, anni al traguardo, leve
A9: 4 - Vedovanza | B9: Vedovanza: il piano se uno dei due muore, reversibilità e successione
A10: 5 - Motore e tabelle | B10: Tabelle con fonte e data, motore del calcolo (non modificare)
A12: Come usare
A13: 1. Le celle GIALLE sono input — modificale coi tuoi numeri.
A14: 2. Le celle VERDI sono output — si aggiornano automaticamente.
A15: 3. Tutti i numeri di default sono al 2026 da fonti pubbliche.
A16: 4. Niente codice nascosto: l'Excel è solo formule modificabili.
A18: Fonti dati
A19: • Spesa delle famiglie: Istituto di statistica, indagine sulle spese 2025, tavole per componenti e stato abitativo (P)
A20: • Pensione di vecchiaia: DL 201/2011 art. 24 (testo vigente al 17/10/2026); INPS circ. 28/2026 (requisiti 2027-28); RGS 27 Tab. A1.4 (proiezione dal 2029) (P)
A21: • Coefficienti di trasformazione: decreto direttoriale 20/11/2024 (P); revisione dei coefficienti: RGS 27 Tab. A1.1 e riquadro 6.1 (P, ipotesi E)
A22: • Fisco 2026: TUIR artt. 11-13; L. 207/2024 art. 1 c. 4-9; INPS circ. 6/2026 par. 5 per la prima fascia pensionabile (P)
A23: • Reversibilità: L. 335/1995 tab. F e sentenza della Corte costituzionale 162/2022; trattamento minimo e assegno sociale: INPS circ. 153/2025 e 2026 (P)
A24: • Successioni: codice civile artt. 179, 538, 544, 582, 583; D.Lgs. 346/1990 art. 7 (P)
... A32: Sotto i 20 anni di contributi la pensione di vecchiaia arriva a 71 anni adeguati: un anno di lavoro in più può anticipare la pensione di oltre quattro anni.

Sheet 1 - Dati
A1: 1 - Dati: le celle gialle sono tue, cambiale con i numeri del tuo caso
A2: Strumento informativo / divulgativo. NON è consulenza finanziaria. I valori sono indicativi al 2026 e vanno verificati col tuo consulente.
A3: Il caso di Tiziano e Camilla è inventato e illustrativo. Ogni importo è in euro del 2026 (reali), salvo dove indicato. Le celle verdi si calcolano da sole. Il foglio non ricostruisce la storia dei risparmi: la base di costo dei conti è un dato dichiarato.
A5: Canone: ipotesi e parametri 2026 (caso base)
A6: Rendimento reale annuo | B6: 0.03 | D6: ipotesi
A7: Inflazione annua | B7: 0.02 | D7: ipotesi
A8: Bollo sul patrimonio (annuo) | B8: 0.002 | D8: imposta di bollo sugli strumenti finanziari
A9: Imposta sui guadagni di capitale | B9: 0.26 | D9: aliquota sostitutiva
A10: Addizionali regionali e comunali | B10: 0.02 | D10: convenzione del canale
A11: Rivalutazione reale del montante contributivo | B11: 0.005 | D11: ipotesi; a zero il montante cresce solo con i contributi
A12: Aliquota di computo | B12: 0.33 | D12: dipendenti: 33% della retribuzione
A13: Contributi a carico del dipendente | B13: 0.0919 | D13: INPS 2026
A14: Assegno sociale (€ al mese, per 13 mensilità) | B14: 546.24 | D14: INPS 2026
A15: Trattamento minimo annuo (provvisorio) | B15: 7954.05 | D15: INPS circ. 153/2025: 611,85 € × 13
A16: Ultimo anno del piano (orizzonte) | B16: 2078 | D16: Camilla a 95 anni
A17: Prima fascia pensionabile 2026 (€ l'anno) | B17: 56224 | D17: INPS circ. 6/2026 par. 5
... A21: Scarto della via dei 71 anni (mesi) | B21: 48 | D21: ipotesi dell'analista dal 2029: ordinario + 48 mesi; la legge dice «da adeguare»
A22: Coefficienti di trasformazione (banda) | B22: coefficienti di oggi | D22: «coefficienti di oggi» è il caso più favorevole; le altre due sono proiezioni
A24: Le due persone
B25: Tiziano | C25: Camilla
A26: Anno di nascita | B26: 1978 | C26: 1983
A27: Mese di nascita | B27: 3 | C27: 9
A28: Retribuzione annua lorda (RAL) | B28: 54000 | C28: 29000
A29: Primo anno di contributi | B29: 2004 | C29: 2008
A30: Montante contributivo al 31/12/2026 | B30: 355887.26 | C30: 156401.91 | D30: dall'estratto conto previdenziale; qui valori del caso
A31: Nome | B31: Tiziano | C31: Camilla
A33: Spese della coppia (euro l'anno)
A34: Spese comuni | B34: 39600
A35: Spese individuali di Tiziano | B35: 0
A36: Spese individuali di Camilla | B36: 0
A37: Spesa totale | B37: =p_sp_com+p_sp_T+p_sp_C -> 39600
A38: Quota della spesa se si divide a metà, sul netto di Tiziano | B38: =p_spesa/2/Tz_netto -> 0.56965498
A39: Quota della spesa se si divide a metà, sul netto di Camilla | B39: =p_spesa/2/Cm_netto -> 0.86543773
A40: Quota della spesa in proporzione al netto (uguale per entrambi) | B40: =p_spesa/(Tz_netto+Cm_netto) -> 0.6870649
A42: Patrimonio per intestatario (euro del 2026)
B43: Valore | C43: Base di costo | D43: Quota di guadagno latente
A44: Conto di Tiziano | B44: 400000 | C44: 238297.25 | D44: =1-C44/B44 -> 0.40425687
A45: Conto di Camilla | B45: 180000 | C45: 119854.49 | D45: =1-C45/B45 -> 0.33414172
A46: Conto cointestato | B46: 170000 | C46: 102895.12 | D46: =1-C46/B46 -> 0.39473459
A47: Totale | B47: =Pt_T_val+Pt_C_val+Pt_J_val -> 750000 | C47: =Pt_T_base+Pt_C_base+Pt_J_base -> 461046.86 | D47: =1-Pat_B/Pat_W -> 0.38527085
...

Sheet 2 - Pensioni
A1: 2 - Pensioni: lo stipendio netto e la pensione di vecchiaia di ciascuno
A2: Strumento informativo / divulgativo. NON è consulenza finanziaria. I valori sono indicativi al 2026 e vanno verificati col tuo consulente.
A3: La pensione si calcola con il metodo contributivo: montante × coefficiente di trasformazione all'età di decorrenza. La pensione anticipata contributiva (a 65 anni e 10 mesi per Tiziano, gennaio 2044) è esclusa: richiede un assegno almeno 3,2 volte l'assegno sociale e nel caso base non lo raggiunge.
A5: Netto dello stipendio (fisco 2026, euro l'anno)
B6: Tiziano | C6: Camilla
A7: Retribuzione lorda (RAL) | B7: =Tz_ral -> 54000 | C7: =Cm_ral -> 29000
A8: Contributi del dipendente | B8: =p_contr*Tz_ral -> 4962.6 | C8: =p_contr*Cm_ral -> 2665.1
A9: Contributo aggiuntivo oltre la fascia | B9: =p_ivs_aliq*MAX(0,Tz_ral-p_ivs_soglia) -> 0 | C9: =p_ivs_aliq*MAX(0,Cm_ral-p_ivs_soglia) -> 0
A10: Reddito imponibile | B10: =Tz_ral-B8-B9 -> 49037.4 | C10: =Cm_ral-C8-C9 -> 26334.9
A11: IRPEF lorda | B11: =IF(B10<=sc_L1,sc_A1*B10,IF(B10<=sc_L2,sc_B1+sc_A2*(B10-sc_L1),sc_B2+sc_A3*(B10-sc_L2))) -> 13382.342 | C11: =IF(C10<=sc_L1,sc_A1*C10,IF(C10<=sc_L2,sc_B1+sc_A2*(C10-sc_L1),sc_B2+sc_A3*(C10-sc_L2))) -> 6057.027
A12: Detrazione per lavoro dipendente | B12: =(IF(B10<=15000,1955,IF(B10<=28000,1910+1190*(28000-B10)/13000,IF(B10<=50000,1910*(50000-B10)/22000,0)))+IF(AND(B10>25000,B10<=35000),65,0)) -> 83.571182 | C12: =(IF(C10<=15000,1955,IF(C10<=28000,1910+1190*(28000-C10)/13000,IF(C10<=50000,1910*(50000-C10)/22000,0)))+IF(AND(C10>25000,C10<=35000),65,0)) -> 2127.4207
A13: Ulteriore detrazione (20.000-40.000 €) | B13: =IF(AND(B10>20000,B10<=32000),1000,IF(AND(B10>32000,B10<=40000),1000*(40000-B10)/8000,0)) -> 0 | C13: =IF(AND(C10>20000,C10<=32000),1000,IF(AND(C10>32000,C10<=40000),1000*(40000-C10)/8000,0)) -> 1000
A14: IRPEF netta | B14: =MAX(0,B11-B12-B13) -> 13298.771 | C14: =MAX(0,C11-C12-C13) -> 2929.6063
A15: Addizionali | B15: =p_add*B10 -> 980.748 | C15: =p_add*C10 -> 526.698
A16: Somma non imponibile (reddito fino a 20.000 €) | B16: =IF(B10>20000,0,IF(B10<=8500,0.071*B10,IF(B10<=15000,0.053*B10,0.048*B10))) -> 0 | C16: =IF(C10>20000,0,IF(C10<=8500,0.071*C10,IF(C10<=15000,0.053*C10,0.048*C10))) -> 0
A17: Stipendio netto | B17: =B7-B8-B9-B14-B15+B16 -> 34757.881 | C17: =C7-C8-C9-C14-C15+C16 -> 22878.596
A18: Il netto è quanto entra davvero in cassa: RAL meno contributi, imposte e addizionali, più la somma non imponibile se spetta.
A20: Confronto: come cambia il netto se i due redditi sono distribuiti in modo diverso (stessa RAL totale)
A21: Distribuzione | B21: RAL Tiziano | C21: RAL Camilla | D21: Netto Tiziano | E21: Netto Camilla | F21: Netto della coppia
A22: Caso (54 + 29) | B22: 54000 | C22: 29000 | D22: =B22-p_contr*B22-p_ivs_aliq*MAX(0,B22-p_ivs_soglia)-MAX(0,IF((B22-p_contr*B22-p_ivs_aliq*MAX(0,B22-p_ivs_soglia))<=sc_L1,sc_A1*(B22-p_contr*B22-p_ivs_aliq*MAX(0,B22-p_ivs_soglia)),IF((B22-p_contr*B22-p_ivs_aliq*MAX(0,B22-p_ivs_soglia))<=sc_L2,sc_B1+sc_A2*((B22-p_contr*B22-p_ivs_aliq*MAX(0,B22-p_ivs_soglia))-sc_L1),sc_B2+sc_A3*((B22-p_contr*B22-p_ivs_aliq*MAX(0,B22-p_ivs_soglia))-sc_L2)))-(IF((B22-p_contr*B22-p_ivs_aliq*MAX(0,B22-p_ivs_soglia))<=15000,1955,IF((B22-p_contr*B22-p_ivs_aliq*MAX(0,B22-p_ivs_soglia))<=28000,1910+1190*(28000-(B22-p_contr*B22-p_ivs_aliq*MAX(0,B22-p_ivs_soglia)))/13000,IF((B22-p_contr*B22-p_ivs_aliq*MAX(0,B22-p_ivs_soglia))<=50000,1910*(50000-(B22-p_contr*B22-p_ivs_aliq*MAX(0,B22-p_ivs_soglia)))/22000,0)))+IF(AND((B22-p_contr*B22-p_ivs_aliq*MAX(0,B22-p_ivs_soglia))>25000,(B22-p_contr*B22-p_ivs_aliq*MAX(0,B22-p_ivs_soglia))<=35000),65,0))-IF(AND((B22-p_contr*B22-p_ivs_aliq*MAX(0,B22-p_ivs_soglia))>20000,(B22-p_contr*B22-p_ivs_aliq*MAX(0,B22-p_ivs_soglia))<=32000),1000,IF(AND((B22-p_contr*B22-p_ivs_aliq*MAX(0,B22-p_ivs_soglia))>32000,(B22-p_contr*B22-p_ivs_aliq*MAX(0,B22-p_ivs_soglia))<=40000),1000*(40000-(B22-p_contr*B22-p_ivs_aliq*MAX(0,B22-p_ivs_soglia)))/8000,0)))-p_add*(B22-p_contr*B22-p_ivs_aliq*MAX(0,B22-p_ivs_soglia))+IF((B22-p_contr*B22-p_ivs_aliq*MAX(0,B22-p_ivs_soglia))>20000,0,IF((B22-p_contr*B22-p_ivs_aliq*MAX(0,B22-p_ivs_soglia))<=8500,0.071*(B22-p_contr*B22-p_ivs_aliq*MAX(0,B22-p_ivs_soglia)),IF((B22-p_contr*B22-p_ivs_aliq*MAX(0,B22-p_ivs_soglia))<=15000,0.053*(B22-p_contr*B22-p_ivs_aliq*MAX(0,B22-p_ivs_soglia)),0.048*(B22-p_contr*B22-p_ivs_aliq*MAX(0,B22-p_ivs_soglia))))) -> 34757.881 | E22: =C22-p_contr*C22-p_ivs_aliq*MAX(0,C22-p_ivs_soglia)-MAX(0,IF((C22-p_contr*C22-p_ivs_aliq*MAX(0,C22-p_ivs_soglia))<=sc_L1,sc_A1*(C22-p_contr*C22-p_ivs_aliq*MAX(0,C22-p_ivs_soglia)),IF((C22-p_contr*C22-p_ivs_aliq*MAX(0,C22-p_ivs_soglia))<=sc_L2,sc_B1+sc_A2*((C22-p_contr*C22-p_ivs_aliq*MAX(0,C22-p_ivs_soglia))-sc_L1),sc_B2+sc_A3*((C22-p_contr*C22-p_ivs_aliq*MAX(0,C22-p_ivs_soglia))-sc_L2)))-(IF((C22-p_contr*C22-p_ivs_aliq*MAX(0,C22-p_ivs_soglia))<=15000,1955,IF((C22-p_contr*C22-p_ivs_aliq*MAX(0,C22-p_ivs_soglia))<=28000,1910+1190*(28000-(C22-p_contr*C22-p_ivs_aliq*MAX(0,C22-p_ivs_soglia)))/13000,IF((C22-p_contr*C22-p_ivs_aliq*MAX(0,C22-p_ivs_soglia))<=50000,1910*(50000-(C22-p_contr*C22-p_ivs_aliq*MAX(0,C22-p_ivs_soglia)))/22000,0)))+IF(AND((C22-p_contr*C22-p_ivs_aliq*MAX(0,C22-p_ivs_soglia))>25000,(C22-p_contr*C22-p_ivs_aliq*MAX(0,C22-p_ivs_soglia))<=35000),65,0))-IF(AND((C22-p_contr*C22-p_ivs_aliq*MAX(0,C22-p_ivs_soglia))>20000,(C22-p_contr*C22-p_ivs_aliq*MAX(0,C22-p_ivs_soglia))<=32000),1000,IF(AND((C22-p_contr*C22-p_ivs_aliq*MAX(0,C22-p_ivs_soglia))>32000,(C22-p_contr*C22-p_ivs_aliq*MAX(0,C22-p_ivs_soglia))<=40000),1000*(40000-(C22-p_contr*C22-p_ivs_aliq*MAX(0,C22-p_ivs_soglia)))/8000,0)))-p_add*(C22-p_contr*C22-p_ivs_aliq*MAX(0,C22-p_ivs_soglia))+IF((C22-p_contr*C22-p_ivs_aliq*MAX(0,C22-p_ivs_soglia))>20000,0,IF((C22-p_contr*C22-p_ivs_aliq*MAX(0,C22-p_ivs_soglia))<=8500,0.071*(C22-p_contr*C22-p_ivs_aliq*MAX(0,C22-p_ivs_soglia)),IF((C22-p_contr*C22-p_ivs_aliq*MAX(0,C22-p_ivs_soglia))<=15000,0.053*(C22-p_contr*C22-p_ivs_aliq*MAX(0,C22-p_ivs_soglia)),0.048*(C22-p_contr*C22-p_ivs_aliq*MAX(0,C22-p_ivs_soglia))))) -> 22878.596 | F22: =D22+E22 -> 57636.477
A23: Più sbilanciati (65 + 18) | B23: 65000 | C23: 18000 | D23: =B23-p_contr*B23-p_ivs_aliq*MAX(0,B23-p_ivs_soglia)-MAX(0,IF((B23-p_contr*B23-p_ivs_aliq*MAX(0,B23-p_ivs_soglia))<=sc_L1,sc_A1*(B23-p_contr*B23-p_ivs_aliq*MAX(0,B23-p_ivs_soglia)),IF((B23-p_contr*B23-p_ivs_aliq*MAX(0,B23-p_ivs_soglia))<=sc_L2,sc_B1+sc_A2*((B23-p_contr*B23-p_ivs_aliq*MAX(0,B23-p_ivs_soglia))-sc_L1),sc_B2+sc_A3*((B23-p_contr*B23-p_ivs_aliq*MAX(0,B23-p_ivs_soglia))-sc_L2)))-(IF((B23-p_contr*B23-p_ivs_aliq*MAX(0,B23-p_ivs_soglia))<=15000,1955,IF((B23-p_contr*B23-p_ivs_aliq*MAX(0,B23-p_ivs_soglia))<=28000,1910+1190*(28000-(B23-p_contr*B23-p_ivs_aliq*MAX(0,B23-p_ivs_soglia)))/13000,IF((B23-p_contr*B23-p_ivs_aliq*MAX(0,B23-p_ivs_soglia))<=50000,1910*(50000-(B23-p_contr*B23-p_ivs_aliq*MAX(0,B23-p_ivs_soglia)))/22000,0)))+IF(AND((B23-p_contr*B23-p_ivs_aliq*MAX(0,B23-p_ivs_soglia))>25000,(B23-p_contr*B23-p_ivs_aliq*MAX(0,B23-p_ivs_soglia))<=35000),65,0))-IF(AND((B23-p_contr*B23-p_ivs_aliq*MAX(0,B23-p_ivs_soglia))>20000,(B23-p_contr*B23-p_ivs_aliq*MAX(0,B23-p_ivs_soglia))<=32000),1000,IF(AND((B23-p_contr*B23-p_ivs_aliq*MAX(0,B23-p_ivs_soglia))>32000,(B23-p_contr*B23-p_ivs_aliq*MAX(0,B23-p_ivs_soglia))<=40000),1000*(40000-(B23-p_contr*B23-p_ivs_aliq*MAX(0,B23-p_ivs_soglia)))/8000,0)))-p_add*(B23-p_contr*B23-p_ivs_aliq*MAX(0,B23-p_ivs_soglia))+IF((B23-p_contr*B23-p_ivs_aliq*MAX(0,B23-p_ivs_soglia))>20000,0,IF((B23-p_contr*B23-p_ivs_aliq*MAX(0,B23-p_ivs_soglia))<=8500,0.071*(B23-p_contr*B23-p_ivs_aliq*MAX(0,B23-p_ivs_soglia)),IF((B23-p_contr*B23-p_ivs_aliq*MAX(0,B23-p_ivs_soglia))<=15000,0.053*(B23-p_contr*B23-p_ivs_aliq*MAX(0,B23-p_ivs_soglia)),0.048*(B23-p_contr*B23-p_ivs_aliq*MAX(0,B23-p_ivs_soglia))))) -> 40216.307 | E23: =C23-p_contr*C23-p_ivs_aliq*MAX(0,C23-p_ivs_soglia)-MAX(0,IF((C23-p_contr*C23-p_ivs_aliq*MAX(0,C23-p_ivs_soglia))<=sc_L1,sc_A1*(C23-p_contr*C23-p_ivs_aliq*MAX(0,C23-p_ivs_soglia)),IF((C23-p_contr*C23-p_ivs_aliq*MAX(0,C23-p_ivs_soglia))<=sc_L2,sc_B1+sc_A2*((C23-p_contr*C23-p_ivs_aliq*MAX(0,C23-p_ivs_soglia))-sc_L1),sc_B2+sc_A3*((C23-p_contr*C23-p_ivs_aliq*MAX(0,C23-p_ivs_soglia))-sc_L2)))-(IF((C23-p_contr*C23-p_ivs_aliq*MAX(0,C23-p_ivs_soglia))<=15000,1955,IF((C23-p_contr*C23-p_ivs_aliq*MAX(0,C23-p_ivs_soglia))<=28000,1910+1190*(28000-(C23-p_contr*C23-p_ivs_aliq*MAX(0,C23-p_ivs_soglia)))/13000,IF((C23-p_contr*C23-p_ivs_aliq*MAX(0,C23-p_ivs_soglia))<=50000,1910*(50000-(C23-p_contr*C23-p_ivs_aliq*MAX(0,C23-p_ivs_soglia)))/22000,0)))+IF(AND((C23-p_contr*C23-p_ivs_aliq*MAX(0,C23-p_ivs_soglia))>25000,(C23-p_contr*C23-p_ivs_aliq*MAX(0,C23-p_ivs_soglia))<=35000),65,0))-IF(AND((C23-p_contr*C23-p_ivs_aliq*MAX(0,C23-p_ivs_soglia))>20000,(C23-p_contr*C23-p_ivs_aliq*MAX(0,C23-p_ivs_soglia))<=32000),1000,IF(AND((C23-p_contr*C23-p_ivs_aliq*MAX(0,C23-p_ivs_soglia))>32000,(C23-p_contr*C23-p_ivs_aliq*MAX(0,C23-p_ivs_soglia))<=40000),1000*(40000-(C23-p_contr*C23-p_ivs_aliq*MAX(0,C23-p_ivs_soglia)))/8000,0)))-p_add*(C23-p_contr*C23-p_ivs_aliq*MAX(0,C23-p_ivs_soglia))+IF((C23-p_contr*C23-p_ivs_aliq*MAX(0,C23-p_ivs_soglia))>20000,0,IF((C23-p_contr*C23-p_ivs_aliq*MAX(0,C23-p_ivs_soglia))<=8500,0.071*(C23-p_contr*C23-p_ivs_aliq*MAX(0,C23-p_ivs_soglia)),IF((C23-p_contr*C23-p_ivs_aliq*MAX(0,C23-p_ivs_soglia))<=15000,0.053*(C23-p_contr*C23-p_ivs_aliq*MAX(0,C23-p_ivs_soglia)),0.048*(C23-p_contr*C23-p_ivs_aliq*MAX(0,C23-p_ivs_soglia))))) -> 16020.756 | F23: =D23+E23 -> 56237.063
A24: Uguali (41,5 + 41,5) | B24: 41500 | C24: 41500 | D24: =B24-p_contr*B24-p_ivs_aliq*MAX(0,B24-p_ivs_soglia)-MAX(0,IF((B24-p_contr*B24-p_ivs_aliq*MAX(0,B24-p_ivs_soglia))<=sc_L1,sc_A1*(B24-p_contr*B24-p_ivs_aliq*MAX(0,B24-p_ivs_soglia)),IF((B24-p_contr*B24-p_ivs_aliq*MAX(0,B24-p_ivs_soglia))<=sc_L2,sc_B1+sc_A2*((B24-p_contr*B24-p_ivs_aliq*MAX(0,B24-p_ivs_soglia))-sc_L1),sc_B2+sc_A3*((B24-p_contr*B24-p_ivs_aliq*MAX(0,B24-p_ivs_soglia))-sc_L2)))-(IF((B24-p_contr*B24-p_ivs_aliq*MAX(0,B24-p_ivs_soglia))<=15000,1955,IF((B24-p_contr*B24-p_ivs_aliq*MAX(0,B24-p_ivs_soglia))<=28000,1910+1190*(28000-(B24-p_contr*B24-p_ivs_aliq*MAX(0,B24-p_ivs_soglia)))/13000,IF((B24-p_contr*B24-p_ivs_aliq*MAX(0,B24-p_ivs_soglia))<=50000,1910*(50000-(B24-p_contr*B24-p_ivs_aliq*MAX(0,B24-p_ivs_soglia)))/22000,0)))+IF(AND((B24-p_contr*B24-p_ivs_aliq*MAX(0,B24-p_ivs_soglia))>25000,(B24-p_contr*B24-p_ivs_aliq*MAX(0,B24-p_ivs_soglia))<=35000),65,0))-IF(AND((B24-p_contr*B24-p_ivs_aliq*MAX(0,B24-p_ivs_soglia))>20000,(B24-p_contr*B24-p_ivs_aliq*MAX(0,B24-p_ivs_soglia))<=32000),1000,IF(AND((B24-p_contr*B24-p_ivs_aliq*MAX(0,B24-p_ivs_soglia))>32000,(B24-p_contr*B24-p_ivs_aliq*MAX(0,B24-p_ivs_soglia))<=40000),1000*(40000-(B24-p_contr*B24-p_ivs_aliq*MAX(0,B24-p_ivs_soglia)))/8000,0)))-p_add*(B24-p_contr*B24-p_ivs_aliq*MAX(0,B24-p_ivs_soglia))+IF((B24-p_contr*B24-p_ivs_aliq*MAX(0,B24-p_ivs_soglia))>20000,0,IF((B24-p_contr*B24-p_ivs_aliq*MAX(0,B24-p_ivs_soglia))<=8500,0.071*(B24-p_contr*B24-p_ivs_aliq*MAX(0,B24-p_ivs_soglia)),IF((B24-p_contr*B24-p_ivs_aliq*MAX(0,B24-p_ivs_soglia))<=15000,0.053*(B24-p_contr*B24-p_ivs_aliq*MAX(0,B24-p_ivs_soglia)),0.048*(B24-p_contr*B24-p_ivs_aliq*MAX(0,B24-p_ivs_soglia))))) -> 28654.295 | E24: =C24-p_contr*C24-p_ivs_aliq*MAX(0,C24-p_ivs_soglia)-MAX(0,IF((C24-p_contr*C24-p_ivs_aliq*MAX(0,C24-p_ivs_soglia))<=sc_L1,sc_A1*(C24-p_contr*C24-p_ivs_aliq*MAX(0,C24-p_ivs_soglia)),IF((C24-p_contr*C24-p_ivs_aliq*MAX(0,C24-p_ivs_soglia))<=sc_L2,sc_B1+sc_A2*((C24-p_contr*C24-p_ivs_aliq*MAX(0,C24-p_ivs_soglia))-sc_L1),sc_B2+sc_A3*((C24-p_contr*C24-p_ivs_aliq*MAX(0,C24-p_ivs_soglia))-sc_L2)))-(IF((C24-p_contr*C24-p_ivs_aliq*MAX(0,C24-p_ivs_soglia))<=15000,1955,IF((C24-p_contr*C24-p_ivs_aliq*MAX(0,C24-p_ivs_soglia))<=28000,1910+1190*(28000-(C24-p_contr*C24-p_ivs_aliq*MAX(0,C24-p_ivs_soglia)))/13000,IF((C24-p_contr*C24-p_ivs_aliq*MAX(0,C24-p_ivs_soglia))<=50000,1910*(50000-(C24-p_contr*C24-p_ivs_aliq*MAX(0,C24-p_ivs_soglia)))/22000,0)))+IF(AND((C24-p_contr*C24-p_ivs_aliq*MAX(0,C24-p_ivs_soglia))>25000,(C24-p_contr*C24-p_ivs_aliq*MAX(0,C24-p_ivs_soglia))<=35000),65,0))-IF(AND((C24-p_contr*C24-p_ivs_aliq*MAX(0,C24-p_ivs_soglia))>20000,(C24-p_contr*C24-p_ivs_aliq*MAX(0,C24-p_ivs_soglia))<=32000),1000,IF(AND((C24-p_contr*C24-p_ivs_aliq*MAX(0,C24-p_ivs_soglia))>32000,(C24-p_contr*C24-p_ivs_aliq*MAX(0,C24-p_ivs_soglia))<=40000),1000*(40000-(C24-p_contr*C24-p_ivs_aliq*MAX(0,C24-p_ivs_soglia)))/8000,0)))-p_add*(C24-p_contr*C24-p_ivs_aliq*MAX(0,C24-p_ivs_soglia))+IF((C24-p_contr*C24-p_ivs_aliq*MAX(0,C24-p_ivs_soglia))>20000,0,IF((C24-p_contr*C24-p_ivs_aliq*MAX(0,C24-p_ivs_soglia))<=8500,0.071*(C24-p_contr*C24-p_ivs_aliq*MAX(0,C24-p_ivs_soglia)),IF((C24-p_contr*C24-p_ivs_aliq*MAX(0,C24-p_ivs_soglia))<=15000,0.053*(C24-p_contr*C24-p_ivs_aliq*MAX(0,C24-p_ivs_soglia)),0.048*(C24-p_contr*C24-p_ivs_aliq*MAX(0,C24-p_ivs_soglia))))) -> 28654.295 | F24: =D24+E24 -> 57308.59
A25: Un solo reddito (83 + 0) | B25: 83000 | C25: 0 | D25: =B25-p_contr*B25-p_ivs_aliq*MAX(0,B25-p_ivs_soglia)-MAX(0,IF((B25-p_contr*B25-p_ivs_aliq*MAX(0,B25-p_ivs_soglia))<=sc_L1,sc_A1*(B25-p_contr*B25-p_ivs_aliq*MAX(0,B25-p_ivs_soglia)),IF((B25-p_contr*B25-p_ivs_aliq*MAX(0,B25-p_ivs_soglia))<=sc_L2,sc_B1+sc_A2*((B25-p_contr*B25-p_ivs_aliq*MAX(0,B25-p_ivs_soglia))-sc_L1),sc_B2+sc_A3*((B25-p_contr*B25-p_ivs_aliq*MAX(0,B25-p_ivs_soglia))-sc_L2)))-(IF((B25-p_contr*B25-p_ivs_aliq*MAX(0,B25-p_ivs_soglia))<=15000,1955,IF((B25-p_contr*B25-p_ivs_aliq*MAX(0,B25-p_ivs_soglia))<=28000,1910+1190*(28000-(B25-p_contr*B25-p_ivs_aliq*MAX(0,B25-p_ivs_soglia)))/13000,IF((B25-p_contr*B25-p_ivs_aliq*MAX(0,B25-p_ivs_soglia))<=50000,1910*(50000-(B25-p_contr*B25-p_ivs_aliq*MAX(0,B25-p_ivs_soglia)))/22000,0)))+IF(AND((B25-p_contr*B25-p_ivs_aliq*MAX(0,B25-p_ivs_soglia))>25000,(B25-p_contr*B25-p_ivs_aliq*MAX(0,B25-p_ivs_soglia))<=35000),65,0))-IF(AND((B25-p_contr*B25-p_ivs_aliq*MAX(0,B25-p_ivs_soglia))>20000,(B25-p_contr*B25-p_ivs_aliq*MAX(0,B25-p_ivs_soglia))<=32000),1000,IF(AND((B25-p_contr*B25-p_ivs_aliq*MAX(0,B25-p_ivs_soglia))>32000,(B25-p_contr*B25-p_ivs_aliq*MAX(0,B25-p_ivs_soglia))<=40000),1000*(40000-(B25-p_contr*B25-p_ivs_aliq*MAX(0,B25-p_ivs_soglia)))/8000,0)))-p_add*(B25-p_contr*B25-p_ivs_aliq*MAX(0,B25-p_ivs_soglia))+IF((B25-p_contr*B25-p_ivs_aliq*MAX(0,B25-p_ivs_soglia))>20000,0,IF((B25-p_contr*B25-p_ivs_aliq*MAX(0,B25-p_ivs_soglia))<=8500,0.071*(B25-p_contr*B25-p_ivs_aliq*MAX(0,B25-p_ivs_soglia)),IF((B25-p_contr*B25-p_ivs_aliq*MAX(0,B25-p_ivs_soglia))<=15000,0.053*(B25-p_contr*B25-p_ivs_aliq*MAX(0,B25-p_ivs_soglia)),0.048*(B25-p_contr*B25-p_ivs_aliq*MAX(0,B25-p_ivs_soglia))))) -> 49107.497 | E25: =C25-p_contr*C25-p_ivs_aliq*MAX(0,C25-p_ivs_soglia)-MAX(0,IF((C25-p_contr*C25-p_ivs_aliq*MAX(0,C25-p_ivs_soglia))<=sc_L1,sc_A1*(C25-p_contr*C25-p_ivs_aliq*MAX(0,C25-p_ivs_soglia)),IF((C25-p_contr*C25-p_ivs_aliq*MAX(0,C25-p_ivs_soglia))<=sc_L2,sc_B1+sc_A2*((C25-p_contr*C25-p_ivs_aliq*MAX(0,C25-p_ivs_soglia))-sc_L1),sc_B2+sc_A3*((C25-p_contr*C25-p_ivs_aliq*MAX(0,C25-p_ivs_soglia))-sc_L2)))-(IF((C25-p_contr*C25-p_ivs_aliq*MAX(0,C25-p_ivs_soglia))<=15000,1955,IF((C25-p_contr*C25-p_ivs_aliq*MAX(0,C25-p_ivs_soglia))<=28000,1910+1190*(28000-(C25-p_contr*C25-p_ivs_aliq*MAX(0,C25-p_ivs_soglia)))/13000,IF((C25-p_contr*C25-p_ivs_aliq*MAX(0,C25-p_ivs_soglia))<=50000,1910*(50000-(C25-p_contr*C25-p_ivs_aliq*MAX(0,C25-p_ivs_soglia)))/22000,0)))+IF(AND((C25-p_contr*C25-p_ivs_aliq*MAX(0,C25-p_ivs_soglia))>25000,(C25-p_contr*C25-p_ivs_aliq*MAX(0,C25-p_ivs_soglia))<=35000),65,0))-IF(AND((C25-p_contr*C25-p_ivs_aliq*MAX(0,C25-p_ivs_soglia))>20000,(C25-p_contr*C25-p_ivs_aliq*MAX(0,C25-p_ivs_soglia))<=32000),1000,IF(AND((C25-p_contr*C25-p_ivs_aliq*MAX(0,C25-p_ivs_soglia))>32000,(C25-p_contr*C25-p_ivs_aliq*MAX(0,C25-p_ivs_soglia))<=40000),1000*(40000-(C25-p_contr*C25-p_ivs_aliq*MAX(0,C25-p_ivs_soglia)))/8000,0)))-p_add*(C25-p_contr*C25-p_ivs_aliq*MAX(0,C25-p_ivs_soglia))+IF((C25-p_contr*C25-p_ivs_aliq*MAX(0,C25-p_ivs_soglia))>20000,0,IF((C25-p_contr*C25-p_ivs_aliq*MAX(0,C25-p_ivs_soglia))<=8500,0.071*(C25-p_contr*C25-p_ivs_aliq*MAX(0,C25-p_ivs_soglia)),IF((C25-p_contr*C25-p_ivs_aliq*MAX(0,C25-p_ivs_soglia))<=15000,0.053*(C25-p_contr*C25-p_ivs_aliq*MAX(0,C25-p_ivs_soglia)),0.048*(C25-p_contr*C25-p_ivs_aliq*MAX(0,C25-p_ivs_soglia))))) -> 0 | F25: =D25+E25 -> 49107.497
A26: Lordo identico, netto diverso: l'IRPEF è individuale, quindi conta come il lordo si distribuisce fra i due.
A28: Le due pensioni nei tuoi scenari (ultimo anno lavorato dalle celle gialle del foglio 1)
B29: Oggi: Tiziano | C29: Oggi: Camilla | D29: Comune: Tiziano | E29: Comune: Camilla | F29: Libero: Tiziano | G29: Libero: Camilla
A30: Ultimo anno lavorato | B30: =U_oggi_T -> 2026 | C30: =U_oggi_C -> 2026 | D30: =U_com -> 2029 | E30: =U_com -> 2029 | F30: =U_lib_T -> 2026 | G30: =U_lib_C -> 2033
A31: Anni di contributi | B31: =U_oggi_T-Tz_primo+1 -> 23 | C31: =U_oggi_C-Cm_primo+1 -> 19 | D31: =U_com-Tz_primo+1 -> 26 | E31: =U_com-Cm_primo+1 -> 22 | F31: =U_lib_T-Tz_primo+1 -> 23 | G31: =U_lib_C-Cm_primo+1 -> 26
A32: Regola applicata | B32: =IF(B31<p_anni_min,"via dei 71 anni adeguati","vecchiaia ordinaria") -> vecchiaia ordinaria | C32: =IF(C31<p_anni_min,"via dei 71 anni adeguati","vecchiaia ordinaria") -> via dei 71 anni adeguati | D32: =IF(D31<p_anni_min,"via dei 71 anni adeguati","vecchiaia ordinaria") -> vecchiaia ordinaria | E32: =IF(E31<p_anni_min,"via dei 71 anni adeguati","vecchiaia ordinaria") -> vecchiaia ordinaria | F32: =IF(F31<p_anni_min,"via dei 71 anni adeguati","vecchiaia ordinaria") -> vecchiaia ordinaria | G32: =IF(G31<p_anni_min,"via dei 71 anni adeguati","vecchiaia ordinaria") -> vecchiaia ordinaria
A33: Avviso | B33: =IF(B31<p_anni_eff,"Con meno di "&p_anni_eff&" anni effettivi la pensione di vecchiaia non spetta",IF(B31<p_anni_min,"Sotto i "&p_anni_min&" anni di contributi la pensione di vecchiaia arriva al requisito dei 71 anni adeguati (DL 201/2011 art. 24 c. 7), con almeno "&p_anni_eff&" anni effettivi. Dal 2029 il requisito è una proiezione. Un anno di lavoro in più può anticipare la pensione di oltre quattro anni.","")) | C33: =IF(C31<p_anni_eff,"Con meno di "&p_anni_eff&" anni effettivi la pensione di vecchiaia non spetta",IF(C31<p_anni_min,"Sotto i "&p_anni_min&" anni di contributi la pensione di vecchiaia arriva al requisito dei 71 anni adeguati (DL 201/2011 art. 24 c. 7), con almeno "&p_anni_eff&" anni effettivi. Dal 2029 il requisito è una proiezione. Un anno di lavoro in più può anticipare la pensione di oltre quattro anni.","")) -> Sotto i 20 anni di contributi la pensione di vecchiaia arriva al requisito dei 71 anni adeguati (DL 201/2011 art. 24 c. 7), con almeno 5 anni effettivi. Dal 2029 il requisito è una proiezione. Un anno di lavoro in più può anticipare la pensione di oltre quattro anni. | D33: =IF(D31<p_anni_eff,"Con meno di "&p_anni_eff&" anni effettivi la pensione di vecchiaia non spetta",IF(D31<p_anni_min,"Sotto i "&p_anni_min&" anni di contributi la pensione di vecchiaia arriva al requisito dei 71 anni adeguati (DL 201/2011 art. 24 c. 7), con almeno "&p_anni_eff&" anni effettivi. Dal 2029 il requisito è una proiezione. Un anno di lavoro in più può anticipare la pensione di oltre quattro anni.","")) | E33: =IF(E31<p_anni_eff,"Con meno di "&p_anni_eff&" anni effettivi la pensione di vecchiaia non spetta",IF(E31<p_anni_min,"Sotto i "&p_anni_min&" anni di contributi la pensione di vecchiaia arriva al requisito dei 71 anni adeguati (DL 201/2011 art. 24 c. 7), con almeno "&p_anni_eff&" anni effettivi. Dal 2029 il requisito è una proiezione. Un anno di lavoro in più può anticipare la pensione di oltre quattro anni.","")) | F33: =IF(F31<p_anni_eff,"Con meno di "&p_anni_eff&" anni effettivi la pensione di vecchiaia non spetta",IF(F31<p_anni_min,"Sotto i "&p_anni_min&" anni di contributi la pensione di vecchiaia arriva al requisito dei 71 anni adeguati (DL 201/2011 art. 24 c. 7), con almeno "&p_anni_eff&" anni effettivi. Dal 2029 il requisito è una proiezione. Un anno di lavoro in più può anticipare la pensione di oltre quattro anni.","")) | G33: =IF(G31<p_anni_eff,"Con meno di "&p_anni_eff&" anni effettivi la pensione di vecchiaia non spetta",IF(G31<p_anni_min,"Sotto i "&p_anni_min&" anni di contributi la pensione di vecchiaia arriva al requisito dei 71 anni adeguati (DL 201/2011 art. 24 c. 7), con almeno "&p_anni_eff&" anni effettivi. Dal 2029 il requisito è una proiezione. Un anno di lavoro in più può anticipare la pensione di oltre quattro anni.",""))
A34: Decorrenza (mese/anno) | B34: =TEXT(INDEX(PT_dm,U_oggi_T-2025),"00")&"/"&INDEX(PT_da,U_oggi_T-2025) -> 12/2046 | C34: =TEXT(INDEX(PC_dm,U_oggi_C-2025),"00")&"/"&INDEX(PC_da,U_oggi_C-2025) -> 05/2057 | D34: =TEXT(INDEX(PT_dm,U_com-2025),"00")&"/"&INDEX(PT_da,U_com-2025) -> 12/2046 | E34: =TEXT(INDEX(PC_dm,U_com-2025),"00")&"/"&INDEX(PC_da,U_com-2025) -> 12/2052 | F34: =TEXT(INDEX(PT_dm,U_lib_T-2025),"00")&"/"&INDEX(PT_da,U_lib_T-2025) -> 12/2046 | G34: =TEXT(INDEX(PC_dm,U_lib_C-2025),"00")&"/"&INDEX(PC_da,U_lib_C-2025) -> 12/2052
A35: Età alla decorrenza | B35: =INT(INDEX(PT_em,U_oggi_T-2025)/12)&" anni e "&MOD(INDEX(PT_em,U_oggi_T-2025),12)&" mesi" -> 68 anni e 9 mesi | C35: =INT(INDEX(PC_em,U_oggi_C-2025)/12)&" anni e "&MOD(INDEX(PC_em,U_oggi_C-2025),12)&" mesi" -> 73 anni e 8 mesi | D35: =INT(INDEX(PT_em,U_com-2025)/12)&" anni e "&MOD(INDEX(PT_em,U_com-2025),12)&" mesi" -> 68 anni e 9 mesi | E35: =INT(INDEX(PC_em,U_com-2025)/12)&" anni e "&MOD(INDEX(PC_em,U_com-2025),12)&" mesi" -> 69 anni e 3 mesi | F35: =INT(INDEX(PT_em,U_lib_T-2025)/12)&" anni e "&MOD(INDEX(PT_em,U_lib_T-2025),12)&" mesi" -> 68 anni e 9 mesi | G35: =INT(INDEX(PC_em,U_lib_C-2025)/12)&" anni e "&MOD(INDEX(PC_em,U_lib_C-2025),12)&" mesi" -> 69 anni e 3 mesi
A36: Pensione lorda | B36: =INDEX(PT_lorda,U_oggi_T-2025) -> 23475.13 | C36: =INDEX(PC_lorda,U_oggi_C-2025) -> 11884.227 | D36: =INDEX(PT_lorda,U_com-2025) -> 26966.501 | E36: =INDEX(PC_lorda,U_com-2025) -> 12798.692 | F36: =INDEX(PT_lorda,U_lib_T-2025) -> 23475.13 | G36: =INDEX(PC_lorda,U_lib_C-2025) -> 15377.773
A37: Pensione netta | B37: =INDEX(PT_netta,U_oggi_T-2025) -> 18597.564 | C37: =INDEX(PC_netta,U_oggi_C-2025) -> 10650.365 | D37: =INDEX(PT_netta,U_com-2025) -> 21041.391 | E37: =INDEX(PC_netta,U_com-2025) -> 11277.359 | F37: =INDEX(PT_netta,U_lib_T-2025) -> 18597.564 | G37: =INDEX(PC_netta,U_lib_C-2025) -> 13045.683
A38: Rapporto con il netto dello stipendio | B38: =B37/Tz_netto -> 0.53506034 | C38: =C37/Cm_netto -> 0.46551656 | D38: =D37/Tz_netto -> 0.60537035 | E38: =E37/Cm_netto -> 0.49292183 | F38: =F37/Tz_netto -> 0.53506034 | G38: =G37/Cm_netto -> 0.57021347
A39: Almeno l'assegno sociale annuo? | B39: =IF(B36>=p_AS*13,"sì","no") -> sì | C39: =IF(C36>=p_AS*13,"sì","no") -> sì | D39: =IF(D36>=p_AS*13,"sì","no") -> sì | E39: =IF(E36>=p_AS*13,"sì","no") -> sì | F39: =IF(F36>=p_AS*13,"sì","no") -> sì | G39: =IF(G36>=p_AS*13,"sì","no") -> sì
A41: Soglia dei 20 anni: con il primo contributo nel 2008, Camilla arriva a 20 anni se l'ultimo anno lavorato è il 2027 o dopo. Il salto fra 2026 e 2027 sposta la decorrenza di oltre quattro anni.
A46: Pensione di vecchiaia di Tiziano per ultimo anno lavorato (euro del 2026)
A47: Ultimo anno lavorato | B47: Anni di contributi | C47: Via 71 anni (1 = sì) | D47: Regola | E47: Anno decorrenza | F47: Mese decorrenza | G47: Età (mesi) | H47: Coefficiente | I47: Montante all'ultimo anno | J47: Pensione lorda | K47: Imposta netta | L47: Pensione netta | M47: Età alla decorrenza | N47: Rapporto con il netto
A48: 2026 | B48: =A48-Tz_primo+1 -> 23 | C48: =IF(B48<p_anni_min,1,0) -> 0 | D48: =IF(C48=1,"via dei 71 anni adeguati","vecchiaia ordinaria") -> vecchiaia ordinaria | E48: =IF(C48=1,Tz_v71_da,Tz_ord_da) -> 2046 | F48: =IF(C48=1,Tz_v71_dm,Tz_ord_dm) -> 12 | G48: =IF(C48=1,Tz_v71_em,Tz_ord_em) -> 825 | H48: =IF(C48=1,Tz_v71_cf,Tz_ord_cf) -> 0.0597 | I48: =Tz_m26*(1+p_g)^MAX(0,A48-2026)+p_comp*Tz_ral*IF(p_g=0,MAX(0,A48-2026),((1+p_g)^MAX(0,A48-2026)-1)/p_g) -> 355887.26 | J48: =I48*(1+p_g)^MAX(0,E48-A48)*H48 -> 23475.13 | K48: =MAX(0,IF(J48<=sc_L1,sc_A1*J48,IF(J48<=sc_L2,sc_B1+sc_A2*(J48-sc_L1),sc_B2+sc_A3*(J48-sc_L2)))-(IF(J48<=8500,1955,IF(J48<=28000,700+1255*(28000-J48)/19500,IF(J48<=50000,700*(50000-J48)/22000,0)))+IF(AND(J48>25000,J48<=29000),50,0))) -> 4408.0639 | L48: =J48-K48-IF(K48>0,p_add*J48,0) -> 18597.564 | M48: =INT(G48/12)&" anni e "&MOD(G48,12)&" mesi" -> 68 anni e 9 mesi | N48: =L48/Tz_netto -> 0.53506034
...

Sheet 3 - Numero FIRE
A1: 3 - Il numero FIRE della coppia: quanto serve, e da quando
A2: Strumento informativo / divulgativo. NON è consulenza finanziaria. I valori sono indicativi al 2026 e vanno verificati col tuo consulente.
A3: Il numero è il capitale che, con le pensioni di entrambi, copre la spesa fino al 2078 (euro del 2026, rendimento reale e imposte dichiarati nel foglio 1). I tre scenari sono separati: «se smettete oggi», «scenario comune» (stesso ultimo anno per entrambi) e «scenario libero» (anni diversi).
A5: A - Numero FIRE per scenario
B6: Se smettete oggi | C6: Scenario comune | D6: Scenario libero
A7: Ultimo anno lavorato di Tiziano | B7: ='5 - Motore e tabelle'!$B$362 -> 2026 | C7: ='5 - Motore e tabelle'!$C$362 -> 2029 | D7: ='5 - Motore e tabelle'!$D$362 -> 2026
A8: Ultimo anno lavorato di Camilla | B8: ='5 - Motore e tabelle'!$B$363 -> 2026 | C8: ='5 - Motore e tabelle'!$C$363 -> 2029 | D8: ='5 - Motore e tabelle'!$D$363 -> 2033
A9: Primo dei due che smette | B9: ='5 - Motore e tabelle'!$B$365 -> 2026 | C9: ='5 - Motore e tabelle'!$C$365 -> 2029 | D9: ='5 - Motore e tabelle'!$D$365 -> 2026
A10: Patrimonio (euro reali, a inizio anno dopo m) | B10: ='5 - Motore e tabelle'!$B$371 -> 750000 | C10: ='5 - Motore e tabelle'!$C$371 -> 871827.59 | D10: ='5 - Motore e tabelle'!$D$371 -> 750000
A11: Capitale richiesto (numero FIRE) | B11: ='5 - Motore e tabelle'!$B$379 -> 962186.06 | C11: ='5 - Motore e tabelle'!$C$379 -> 819183.17 | D11: ='5 - Motore e tabelle'!$D$379 -> 737544.01
A12: Margine (patrimonio meno richiesto) | B12: ='5 - Motore e tabelle'!$B$380 -> -212186.06 | C12: ='5 - Motore e tabelle'!$C$380 -> 52644.416 | D12: ='5 - Motore e tabelle'!$D$380 -> 12455.991
A13: In parole | B13: =IF('5 - Motore e tabelle'!$B$380<0,"mancano "&FIXED(-'5 - Motore e tabelle'!$B$380,0)&" €","margine di "&FIXED('5 - Motore e tabelle'!$B$380,0)&" €") -> mancano 212.186 € | C13: =IF('5 - Motore e tabelle'!$C$380<0,"mancano "&FIXED(-'5 - Motore e tabelle'!$C$380,0)&" €","margine di "&FIXED('5 - Motore e tabelle'!$C$380,0)&" €") -> margine di 52.644 € | D13: =IF('5 - Motore e tabelle'!$D$380<0,"mancano "&FIXED(-'5 - Motore e tabelle'!$D$380,0)&" €","margine di "&FIXED('5 - Motore e tabelle'!$D$380,0)&" €") -> margine di 12.456 €
A14: Si può smettere? | B14: =IF('5 - Motore e tabelle'!$B$380>=0,"Sì","No") -> No | C14: =IF('5 - Motore e tabelle'!$C$380>=0,"Sì","No") -> Sì | D14: =IF('5 - Motore e tabelle'!$D$380>=0,"Sì","No") -> Sì
A15: Avviso | B15: =IF('5 - Motore e tabelle'!$B$381>0,"surplus dopo m scartato: il numero è prudente","") | C15: =IF('5 - Motore e tabelle'!$C$381>0,"surplus dopo m scartato: il numero è prudente","") | D15: =IF('5 - Motore e tabelle'!$D$381>0,"surplus dopo m scartato: il numero è prudente","")
A16: Capitale richiesto a fine 2026 | B16: =IF('5 - Motore e tabelle'!$B$365=2026,'5 - Motore e tabelle'!$B$379,"non definito: parte dell'accumulo è futura") -> 962186.06 | C16: =IF('5 - Motore e tabelle'!$C$365=2026,'5 - Motore e tabelle'!$C$379,"non definito: parte dell'accumulo è futura") -> non definito: parte dell'accumulo è futura | D16: =IF('5 - Motore e tabelle'!$D$365=2026,'5 - Motore e tabelle'!$D$379,"non definito: parte dell'accumulo è futura") -> 737544.01
A18: B - Ponte e tratti (convenzione: l'anno in cui parte una pensione appartiene al tratto precedente)
B19: Se smettete oggi | C19: Scenario comune | D19: Scenario libero
A20: Ponte: dal primo anno senza stipendio alla prima pensione | B20: =SUMIFS('5 - Motore e tabelle'!$B$387:$B$438,'5 - Motore e tabelle'!$A$387:$A$438,">="&('5 - Motore e tabelle'!$B$365+1),'5 - Motore e tabelle'!$A$387:$A$438,"<="&'5 - Motore e tabelle'!$B$382) -> 725683.05 | C20: =SUMIFS('5 - Motore e tabelle'!$C$387:$C$438,'5 - Motore e tabelle'!$A$387:$A$438,">="&('5 - Motore e tabelle'!$C$365+1),'5 - Motore e tabelle'!$A$387:$A$438,"<="&'5 - Motore e tabelle'!$C$382) -> 643870.85 | D20: =SUMIFS('5 - Motore e tabelle'!$D$387:$D$438,'5 - Motore e tabelle'!$A$387:$A$438,">="&('5 - Motore e tabelle'!$D$365+1),'5 - Motore e tabelle'!$A$387:$A$438,"<="&'5 - Motore e tabelle'!$D$382) -> 557843.74
A21: Una sola pensione | B21: =SUMIFS('5 - Motore e tabelle'!$B$387:$B$438,'5 - Motore e tabelle'!$A$387:$A$438,">"&'5 - Motore e tabelle'!$B$382,'5 - Motore e tabelle'!$A$387:$A$438,"<="&'5 - Motore e tabelle'!$B$383) -> 143399.84 | C21: =SUMIFS('5 - Motore e tabelle'!$C$387:$C$438,'5 - Motore e tabelle'!$A$387:$A$438,">"&'5 - Motore e tabelle'!$C$382,'5 - Motore e tabelle'!$A$387:$A$438,"<="&'5 - Motore e tabelle'!$C$383) -> 80973.978 | D21: =SUMIFS('5 - Motore e tabelle'!$D$387:$D$438,'5 - Motore e tabelle'!$A$387:$A$438,">"&'5 - Motore e tabelle'!$D$382,'5 - Motore e tabelle'!$A$387:$A$438,"<="&'5 - Motore e tabelle'!$D$383) -> 84622.943
A22: Due pensioni | B22: =SUMIFS('5 - Motore e tabelle'!$B$387:$B$438,'5 - Motore e tabelle'!$A$387:$A$438,">"&'5 - Motore e tabelle'!$B$383) -> 93103.174 | C22: =SUMIFS('5 - Motore e tabelle'!$C$387:$C$438,'5 - Motore e tabelle'!$A$387:$A$438,">"&'5 - Motore e tabelle'!$C$383) -> 94338.347 | D22: =SUMIFS('5 - Motore e tabelle'!$D$387:$D$438,'5 - Motore e tabelle'!$A$387:$A$438,">"&'5 - Motore e tabelle'!$D$383) -> 95077.332
A23: Totale | B23: =SUM(B20:B22) -> 962186.06 | C23: =SUM(C20:C22) -> 819183.17 | D23: =SUM(D20:D22) -> 737544.01
A24: Anni di ponte | B24: =MAX(0,'5 - Motore e tabelle'!$B$382-'5 - Motore e tabelle'!$B$365) -> 20 | C24: =MAX(0,'5 - Motore e tabelle'!$C$382-'5 - Motore e tabelle'!$C$365) -> 17 | D24: =MAX(0,'5 - Motore e tabelle'!$D$382-'5 - Motore e tabelle'!$D$365) -> 20
A25: Anni con una pensione | B25: ='5 - Motore e tabelle'!$B$383-'5 - Motore e tabelle'!$B$382 -> 11 | C25: ='5 - Motore e tabelle'!$C$383-'5 - Motore e tabelle'!$C$382 -> 6 | D25: ='5 - Motore e tabelle'!$D$383-'5 - Motore e tabelle'!$D$382 -> 6
A26: Anni con due pensioni | B26: =p_orizz-'5 - Motore e tabelle'!$B$383 -> 21 | C26: =p_orizz-'5 - Motore e tabelle'!$C$383 -> 26 | D26: =p_orizz-'5 - Motore e tabelle'!$D$383 -> 26
A27: Quota del ponte sul totale | B27: =B20/B23 -> 0.75420241 | C27: =C20/C23 -> 0.7859913 | D27: =D20/D23 -> 0.75635315
A28: Con l'altra convenzione (l'anno di decorrenza nel tratto successivo) i tratti cambiano, il totale no: nello scenario «se smettete oggi» sarebbe 697.682 + 163.590 + 100.915 €.
A30: C - Anni al traguardo: stesso ultimo anno lavorato per entrambi
A31: Ultimo anno lavorato di entrambi | B31: Patrimonio (reale) | C31: Capitale richiesto | D31: Margine | E31: Si può smettere?
A32: 2026 | B32: ='5 - Motore e tabelle'!$G$371 -> 750000 | C32: ='5 - Motore e tabelle'!$G$379 -> 962186.06 | D32: ='5 - Motore e tabelle'!$G$380 -> -212186.06 | E32: =IF(D32>=0,"Sì","No") -> No
A33: 2027 | B33: ='5 - Motore e tabelle'!$H$371 -> 789495.42 | C33: ='5 - Motore e tabelle'!$H$379 -> 903646.89 | D33: ='5 - Motore e tabelle'!$H$380 -> -114151.47 | E33: =IF(D33>=0,"Sì","No") -> No
A34: 2028 | B34: ='5 - Motore e tabelle'!$I$371 -> 830094.33 | C34: ='5 - Motore e tabelle'!$I$379 -> 861894.87 | D34: ='5 - Motore e tabelle'!$I$380 -> -31800.535 | E34: =IF(D34>=0,"Sì","No") -> No
A35: 2029 | B35: ='5 - Motore e tabelle'!$J$371 -> 871827.59 | C35: ='5 - Motore e tabelle'!$J$379 -> 819183.17 | D35: ='5 - Motore e tabelle'!$J$380 -> 52644.416 | E35: =IF(D35>=0,"Sì","No") -> Sì
A36: 2030 | B36: ='5 - Motore e tabelle'!$K$371 -> 914726.86 | C36: ='5 - Motore e tabelle'!$K$379 -> 774787.64 | D36: ='5 - Motore e tabelle'!$K$380 -> 139939.22 | E36: =IF(D36>=0,"Sì","No") -> Sì
A37: 2031 | B37: ='5 - Motore e tabelle'!$L$371 -> 958824.75 | C37: ='5 - Motore e tabelle'!$L$379 -> 730721.4 | D37: ='5 - Motore e tabelle'!$L$380 -> 228103.35 | E37: =IF(D37>=0,"Sì","No") -> Sì
A38: 2032 | B38: ='5 - Motore e tabelle'!$M$371 -> 1004154.7 | C38: ='5 - Motore e tabelle'!$M$379 -> 683912.26 | D38: ='5 - Motore e tabelle'!$M$380 -> 320242.47 | E38: =IF(D38>=0,"Sì","No") -> Sì
A39: 2033 | B39: ='5 - Motore e tabelle'!$N$371 -> 1050751.2 | C39: ='5 - Motore e tabelle'!$N$379 -> 635207.97 | D39: ='5 - Motore e tabelle'!$N$380 -> 415543.26 | E39: =IF(D39>=0,"Sì","No") -> Sì
A40: 2034 | B40: ='5 - Motore e tabelle'!$O$371 -> 1098649.6 | C40: ='5 - Motore e tabelle'!$O$379 -> 584559.39 | D40: ='5 - Motore e tabelle'!$O$380 -> 514090.24 | E40: =IF(D40>=0,"Sì","No") -> Sì
A41: 2035 | B41: ='5 - Motore e tabelle'!$P$371 -> 1147886.3 | C41: ='5 - Motore e tabelle'!$P$379 -> 531915.2 | D41: ='5 - Motore e tabelle'!$P$380 -> 615971.12 | E41: =IF(D41>=0,"Sì","No") -> Sì
A42: 2036 | B42: ='5 - Motore e tabelle'!$Q$371 -> 1198498.7 | C42: ='5 - Motore e tabelle'!$Q$379 -> 488515.05 | D42: ='5 - Motore e tabelle'!$Q$380 -> 709983.63 | E42: =IF(D42>=0,"Sì","No") -> Sì
A43: 2037 | B43: ='5 - Motore e tabelle'!$R$371 -> 1250525.1 | C43: ='5 - Motore e tabelle'!$R$379 -> 449977.04 | D43: ='5 - Motore e tabelle'!$R$380 -> 800548.11 | E43: =IF(D43>=0,"Sì","No") -> Sì
...

Sheet 4 - Vedovanza
A1: 4 - Vedovanza: che cosa succede al piano se uno dei due muore
A2: Strumento informativo / divulgativo. NON è consulenza finanziaria. I valori sono indicativi al 2026 e vanno verificati col tuo consulente.
A3: Il piano è quello dello scenario comune (foglio 1). Scegli chi muore, quando, il regime e il testamento. Reversibilità dall'anno dopo la morte, a rata piena (semplificazione). La quota ereditata conserva la base di costo del defunto (ipotesi prudente); quote costanti nel tempo. Limiti: calcolo deterministico, una famiglia d'origine per volta, il 4% di successione oltre 1.000.000 € non è modellato, non è consulenza.
A5: Ingressi (dal foglio 1) e quote ereditarie
A6: Chi muore | B6: =V_chi -> T | D6: ESITI
A7: Anno della morte | B7: =V_anno -> 2035 | D7: Anno di esaurimento del patrimonio (0 = non si esaurisce) | E7: =IF(COUNT(AA44:AA95)=0,0,MIN(AA44:AA95)) -> 0
A8: Ultimo anno lavorato (scenario comune) | B8: =U_com -> 2029 | D8: Patrimonio finale in euro reali (−1 = esaurito) | E8: =IF(Ved_esaur>0,-1,INDEX(AF44:AF95,p_orizz-2026)) -> 1151564.7
A9: Chi resta | B9: =IF(V_chi="T","Camilla",IF(V_chi="C","Tiziano","nessuno")) -> Camilla | D9: In parole | E9: =IF(Ved_esaur>0,"si esaurisce nel "&Ved_esaur,"resta "&FIXED(Ved_finale,0)&" € (reali) al "&p_orizz) -> resta 1.151.565 € (reali) al 2078
A10: Quota del defunto sul valore del patrimonio | B10: =IF(V_chi="nessuno",0,IF(V_regime=1,(IF(V_chi="T",Ered_2026,0)+(Pat_W-Ered_2026)/2)/Pat_W,(IF(V_chi="T",Pt_T_val,Pt_C_val)+Pt_J_val/2)/Pat_W)) -> 0.72448434 | D10: Reversibilità piena nel primo anno dopo la morte | E10: =IFERROR(INDEX(J44:J95,V_anno+1-2026),0) -> 10785.432
A11: Quota del defunto sulla base di costo | B11: =IF(V_chi="nessuno",0,IF(V_regime=1,(IF(V_chi="T",Ered_nom,0)+(Pat_B-Ered_nom)/2)/Pat_B,(IF(V_chi="T",Pt_T_base,Pt_C_base)+Pt_J_base/2)/Pat_B)) -> 0.71689769 | D11: Reversibilità dopo la riduzione per reddito, primo anno | E11: =IFERROR(INDEX(M44:M95,V_anno+1-2026),0) -> 10785.432
A12: Quota dell'eredità che va al superstite | B12: =INDEX(FZ_val,MATCH(V_regime&"|"&V_test&"|"&V_fam,FZ_key,0)) -> 1 | D12: Avviso | E12: =IF(AND(V_regime=1,Ved_q>0,Pat_W*Ved_q>1000000),"la quota ereditata supera 1.000.000 €: l'imposta del 4% non è modellata",IF(V_regime=2,"conviventi: nessuna reversibilità e imposta dell'8% senza franchigia",""))
A13: Imposta di successione | B13: =IF(V_regime=1,imp_R1,imp_R2) -> 0
A14: Fattore sul valore del patrimonio (q) | B14: =(1-$B$10)+$B$10*$B$12*(1-$B$13) -> 1
A15: Fattore sulla base di costo | B15: =(1-$B$11)+$B$11*$B$12*(1-$B$13) -> 1
A16: Aliquota di reversibilità applicata | B16: =IF(V_regime=1,V_aliq,0) -> 0.6
A17: Montante di Tiziano alla morte | B17: =(Tz_m26*(1+p_g)^MAX(0,MIN(V_anno,U_com)-2026)+p_comp*Tz_ral*IF(p_g=0,MAX(0,MIN(V_anno,U_com)-2026),((1+p_g)^MAX(0,MIN(V_anno,U_com)-2026)-1)/p_g))*(1+p_g)^MAX(0,V_anno-MIN(V_anno,U_com)) -> 427586.11
A18: Reversibilità indiretta di Tiziano (aliquota × montante × coefficiente dell'età) | B18: =V_aliq*$B$17*IF(MAX(V_anno-Tz_nasc_a,57)>=71,INDEX(CT_val,15),INDEX(CT_val,MAX(V_anno-Tz_nasc_a,57)-56)) -> 10785.432
A19: Pensione lorda di Tiziano (scenario comune) | B19: =INDEX(PT_lorda,U_com-2025) -> 26966.501
A20: Pensione netta di Tiziano (scenario comune) | B20: =INDEX(PT_netta,U_com-2025) -> 21041.391
A21: Anno di decorrenza di Tiziano | B21: =INDEX(PT_da,U_com-2025) -> 2046
A22: Mese di decorrenza di Tiziano | B22: =INDEX(PT_dm,U_com-2025) -> 12
A23: Montante di Camilla alla morte | B23: =(Cm_m26*(1+p_g)^MAX(0,MIN(V_anno,U_com)-2026)+p_comp*Cm_ral*IF(p_g=0,MAX(0,MIN(V_anno,U_com)-2026),((1+p_g)^MAX(0,MIN(V_anno,U_com)-2026)-1)/p_g))*(1+p_g)^MAX(0,V_anno-MIN(V_anno,U_com)) -> 193312.71
A24: Reversibilità indiretta di Camilla (aliquota × montante × coefficiente dell'età) | B24: =V_aliq*$B$23*IF(MAX(V_anno-Cm_nasc_a,57)>=71,INDEX(CT_val,15),INDEX(CT_val,MAX(V_anno-Cm_nasc_a,57)-56)) -> 4876.1197
A25: Pensione lorda di Camilla (scenario comune) | B25: =INDEX(PC_lorda,U_com-2025) -> 12798.692
A26: Pensione netta di Camilla (scenario comune) | B26: =INDEX(PC_netta,U_com-2025) -> 11277.359
A27: Anno di decorrenza di Camilla | B27: =INDEX(PC_da,U_com-2025) -> 2052
A28: Mese di decorrenza di Camilla | B28: =INDEX(PC_dm,U_com-2025) -> 12
A29: Base della reversibilità (pensione propria del defunto se già in pagamento, altrimenti indiretta) | B29: =IF(V_chi="T",IF(V_anno>=$B$21,$B$19,$B$17*IF(MAX(V_anno-Tz_nasc_a,57)>=71,INDEX(CT_val,15),INDEX(CT_val,MAX(V_anno-Tz_nasc_a,57)-56))),IF(V_anno>=$B$27,$B$25,$B$23*IF(MAX(V_anno-Cm_nasc_a,57)>=71,INDEX(CT_val,15),INDEX(CT_val,MAX(V_anno-Cm_nasc_a,57)-56)))) -> 17975.72
A30: Anno di nascita di chi resta | B30: =IF(V_chi="T",Cm_nasc_a,Tz_nasc_a) -> 1983
A31: RAL di chi resta | B31: =IF(V_chi="T",Cm_ral,Tz_ral) -> 29000
A42: Piano anno per anno (euro nominali; l'ultima colonna è il patrimonio in euro reali)
A43: Anno | B43: Dopo la morte (1 = sì) | C43: Stipendio Tiziano | D43: Pensione Tiziano | E43: Stipendio Camilla | F43: Pensione Camilla | G43: Pensione lorda di chi resta | H43: Reddito da lavoro di chi resta | I43: Reddito lordo di chi resta | J43: Reversibilità piena | K43: Moltiplicatore | L43: Riduzione | M43: Reversibilità dopo la riduzione | N43: Pensione + reversibilità (lordo) | O43: Imposta sulla pensione | P43: Netto da pensione | Q43: Netto della reversibilità (con lavoro) | R43: Entrate nette | S43: Spesa | T43: Fabbisogno (reale) | U43: Indice prezzi | V43: Fabbisogno nominale | W43: Patrimonio a inizio anno | X43: Base di costo a inizio anno | Y43: Quota di guadagno latente | Z43: Vendita lorda | AA43: Anno di esaurimento | AB43: Patrimonio dopo il prelievo | AC43: Base dopo il prelievo | AD43: Patrimonio a fine anno | AE43: Base a fine anno | AF43: Patrimonio a fine anno (euro reali)
A44: 2027 | B44: =IF(AND(V_chi<>"nessuno",A44>V_anno),1,0) -> 0 | C44: =Tz_netto*(A44<=$B$8) -> 34757.881 | D44: =$B$20*IF(A44>$B$21,1,IF(A44=$B$21,(13-$B$22)/12,0)) -> 0 | E44: =Cm_netto*(A44<=$B$8) -> 22878.596 | F44: =$B$26*IF(A44>$B$27,1,IF(A44=$B$27,(13-$B$28)/12,0)) -> 0 | G44: =IF(B44=1,IF(V_chi="T",$B$25*IF(A44>$B$27,1,IF(A44=$B$27,(13-$B$28)/12,0)),$B$19*IF(A44>$B$21,1,IF(A44=$B$21,(13-$B$22)/12,0))),0) -> 0 | H44: =IF(B44=1,$B$31*(1-p_contr)*(A44<=$B$8),0) -> 0 | I44: =G44+H44 -> 0 | J44: =IF(B44=1,$B$16*$B$29,0) -> 0 | K44: =IF(V_figli=1,1,IF(I44>tf_S5,tf_M5,IF(I44>tf_S4,tf_M4,IF(I44>tf_S3,tf_M3,1)))) -> 1 | L44: =MIN(J44*(1-K44),I44) -> 0 | M44: =J44-L44 -> 0 | N44: =G44+M44 -> 0 | O44: =MAX(0,IF(N44<=sc_L1,sc_A1*N44,IF(N44<=sc_L2,sc_B1+sc_A2*(N44-sc_L1),sc_B2+sc_A3*(N44-sc_L2)))-(IF(N44<=8500,1955,IF(N44<=28000,700+1255*(28000-N44)/19500,IF(N44<=50000,700*(50000-N44)/22000,0)))+IF(AND(N44>25000,N44<=29000),50,0))) -> 0 | P44: =IF(N44>0,N44-O44-IF(O44>0,p_add*N44,0),0) -> 0 | Q44: =IF(B44=1,MAX(M44-(IF((I44+M44)<=sc_L1,sc_A1*(I44+M44),IF((I44+M44)<=sc_L2,sc_B1+sc_A2*((I44+M44)-sc_L1),sc_B2+sc_A3*((I44+M44)-sc_L2)))-IF(I44<=sc_L1,sc_A1*I44,IF(I44<=sc_L2,sc_B1+sc_A2*(I44-sc_L1),sc_B2+sc_A3*(I44-sc_L2))))-p_add*M44,0),0) -> 0 | R44: =IF(B44=1,IF(A44>$B$8,P44,IF(V_chi="T",E44,C44)+IF(V_chi="T",F44,D44)+Q44),C44+D44+E44+F44) -> 57636.477 | S44: =IF(B44=1,p_spesa/IF(A44-$B$30>=65,V_den65,V_den64),p_spesa) -> 39600 | T44: =S44-R44 -> -18036.477 | U44: =1 -> 1 | V44: =T44*U44 -> -18036.477 | W44: =Pat_W*IF(AND(V_chi<>"nessuno",A44=V_anno+1),Ved_q,1) -> 750000 | X44: =Pat_B*IF(AND(V_chi<>"nessuno",A44=V_anno+1),Ved_qb,1) -> 461046.86 | Y44: =IF(W44>0,MAX(0,1-X44/W44),0) -> 0.38527085 | Z44: =IF(V44>0,V44/(1-p_cgt*Y44),0) -> 0 | AA44: =IF(""<>"","",IF(AND(V44>0,Z44>W44,A44<=p_orizz),A44,"")) | AB44: =IF(V44>0,W44-Z44,W44-V44) -> 768036.48 | AC44: =IF(V44>0,IF(W44>0,X44-X44*Z44/W44,X44),X44-V44) -> 479083.34 | AD44: =AB44*(1+p_rend)*(1+p_infl)*(1-p_bollo) -> 805285.32 | AE44: =AC44 -> 479083.34 | AF44: =AD44/(U44*(1+p_infl)) -> 789495.42
A45: 2028 | B45: =IF(AND(V_chi<>"nessuno",A45>V_anno),1,0) -> 0 | C45: =Tz_netto*(A45<=$B$8) -> 34757.881 | D45: =$B$20*IF(A45>$B$21,1,IF(A45=$B$21,(13-$B$22)/12,0)) -> 0 | E45: =Cm_netto*(A45<=$B$8) -> 22878.596 | F45: =$B$26*IF(A45>$B$27,1,IF(A45=$B$27,(13-$B$28)/12,0)) -> 0 | G45: =IF(B45=1,IF(V_chi="T",$B$25*IF(A45>$B$27,1,IF(A45=$B$27,(13-$B$28)/12,0)),$B$19*IF(A45>$B$21,1,IF(A45=$B$21,(13-$B$22)/12,0))),0) -> 0 | H45: =IF(B45=1,$B$31*(1-p_contr)*(A45<=$B$8),0) -> 0 | I45: =G45+H45 -> 0 | J45: =IF(B45=1,$B$16*$B$29,0) -> 0 | K45: =IF(V_figli=1,1,IF(I45>tf_S5,tf_M5,IF(I45>tf_S4,tf_M4,IF(I45>tf_S3,tf_M3,1)))) -> 1 | L45: =MIN(J45*(1-K45),I45) -> 0 | M45: =J45-L45 -> 0 | N45: =G45+M45 -> 0 | O45: =MAX(0,IF(N45<=sc_L1,sc_A1*N45,IF(N45<=sc_L2,sc_B1+sc_A2*(N45-sc_L1),sc_B2+sc_A3*(N45-sc_L2)))-(IF(N45<=8500,1955,IF(N45<=28000,700+1255*(28000-N45)/19500,IF(N45<=50000,700*(50000-N45)/22000,0)))+IF(AND(N45>25000,N45<=29000),50,0))) -> 0 | P45: =IF(N45>0,N45-O45-IF(O45>0,p_add*N45,0),0) -> 0 | Q45: =IF(B45=1,MAX(M45-(IF((I45+M45)<=sc_L1,sc_A1*(I45+M45),IF((I45+M45)<=sc_L2,sc_B1+sc_A2*((I45+M45)-sc_L1),sc_B2+sc_A3*((I45+M45)-sc_L2)))-IF(I45<=sc_L1,sc_A1*I45,IF(I45<=sc_L2,sc_B1+sc_A2*(I45-sc_L1),sc_B2+sc_A3*(I45-sc_L2))))-p_add*M45,0),0) -> 0 | R45: =IF(B45=1,IF(A45>$B$8,P45,IF(V_chi="T",E45,C45)+IF(V_chi="T",F45,D45)+Q45),C45+D45+E45+F45) -> 57636.477 | S45: =IF(B45=1,p_spesa/IF(A45-$B$30>=65,V_den65,V_den64),p_spesa) -> 39600 | T45: =S45-R45 -> -18036.477 | U45: =U44*(1+p_infl) -> 1.02 | V45: =T45*U45 -> -18397.206 | W45: =AD44*IF(AND(V_chi<>"nessuno",A45=V_anno+1),Ved_q,1) -> 805285.32 | X45: =AE44*IF(AND(V_chi<>"nessuno",A45=V_anno+1),Ved_qb,1) -> 479083.34 | Y45: =IF(W45>0,MAX(0,1-X45/W45),0) -> 0.40507628 | Z45: =IF(V45>0,V45/(1-p_cgt*Y45),0) -> 0 | AA45: =IF(AA44<>"",AA44,IF(AND(V45>0,Z45>W45,A45<=p_orizz),A45,"")) | AB45: =IF(V45>0,W45-Z45,W45-V45) -> 823682.53 | AC45: =IF(V45>0,IF(W45>0,X45-X45*Z45/W45,X45),X45-V45) -> 497480.54 | AD45: =AB45*(1+p_rend)*(1+p_infl)*(1-p_bollo) -> 863630.15 | AE45: =AC45 -> 497480.54 | AF45: =AD45/(U45*(1+p_infl)) -> 830094.33
A46: 2029 | B46: =IF(AND(V_chi<>"nessuno",A46>V_anno),1,0) -> 0 | C46: =Tz_netto*(A46<=$B$8) -> 34757.881 | D46: =$B$20*IF(A46>$B$21,1,IF(A46=$B$21,(13-$B$22)/12,0)) -> 0 | E46: =Cm_netto*(A46<=$B$8) -> 22878.596 | F46: =$B$26*IF(A46>$B$27,1,IF(A46=$B$27,(13-$B$28)/12,0)) -> 0 | G46: =IF(B46=1,IF(V_chi="T",$B$25*IF(A46>$B$27,1,IF(A46=$B$27,(13-$B$28)/12,0)),$B$19*IF(A46>$B$21,1,IF(A46=$B$21,(13-$B$22)/12,0))),0) -> 0 | H46: =IF(B46=1,$B$31*(1-p_contr)*(A46<=$B$8),0) -> 0 | I46: =G46+H46 -> 0 | J46: =IF(B46=1,$B$16*$B$29,0) -> 0 | K46: =IF(V_figli=1,1,IF(I46>tf_S5,tf_M5,IF(I46>tf_S4,tf_M4,IF(I46>tf_S3,tf_M3,1)))) -> 1 | L46: =MIN(J46*(1-K46),I46) -> 0 | M46: =J46-L46 -> 0 | N46: =G46+M46 -> 0 | O46: =MAX(0,IF(N46<=sc_L1,sc_A1*N46,IF(N46<=sc_L2,sc_B1+sc_A2*(N46-sc_L1),sc_B2+sc_A3*(N46-sc_L2)))-(IF(N46<=8500,1955,IF(N46<=28000,700+1255*(28000-N46)/19500,IF(N46<=50000,700*(50000-N46)/22000,0)))+IF(AND(N46>25000,N46<=29000),50,0))) -> 0 | P46: =IF(N46>0,N46-O46-IF(O46>0,p_add*N46,0),0) -> 0 | Q46: =IF(B46=1,MAX(M46-(IF((I46+M46)<=sc_L1,sc_A1*(I46+M46),IF((I46+M46)<=sc_L2,sc_B1+sc_A2*((I46+M46)-sc_L1),sc_B2+sc_A3*((I46+M46)-sc_L2)))-IF(I46<=sc_L1,sc_A1*I46,IF(I46<=sc_L2,sc_B1+sc_A2*(I46-sc_L1),sc_B2+sc_A3*(I46-sc_L2))))-p_add*M46,0),0) -> 0 | R46: =IF(B46=1,IF(A46>$B$8,P46,IF(V_chi="T",E46,C46)+IF(V_chi="T",F46,D46)+Q46),C46+D46+E46+F46) -> 57636.477 | S46: =IF(B46=1,p_spesa/IF(A46-$B$30>=65,V_den65,V_den64),p_spesa) -> 39600 | T46: =S46-R46 -> -18036.477 | U46: =U45*(1+p_infl) -> 1.0404 | V46: =T46*U46 -> -18765.151 | W46: =AD45*IF(AND(V_chi<>"nessuno",A46=V_anno+1),Ved_q,1) -> 863630.15 | X46: =AE45*IF(AND(V_chi<>"nessuno",A46=V_anno+1),Ved_qb,1) -> 497480.54 | Y46: =IF(W46>0,MAX(0,1-X46/W46),0) -> 0.42396575 | Z46: =IF(V46>0,V46/(1-p_cgt*Y46),0) -> 0 | AA46: =IF(AA45<>"",AA45,IF(AND(V46>0,Z46>W46,A46<=p_orizz),A46,"")) | AB46: =IF(V46>0,W46-Z46,W46-V46) -> 882395.3 | AC46: =IF(V46>0,IF(W46>0,X46-X46*Z46/W46,X46),X46-V46) -> 516245.69 | AD46: =AB46*(1+p_rend)*(1+p_infl)*(1-p_bollo) -> 925190.41 | AE46: =AC46 -> 516245.69 | AF46: =AD46/(U46*(1+p_infl)) -> 871827.59
A47: 2030 | B47: =IF(AND(V_chi<>"nessuno",A47>V_anno),1,0) -> 0 | C47: =Tz_netto*(A47<=$B$8) -> 0 | D47: =$B$20*IF(A47>$B$21,1,IF(A47=$B$21,(13-$B$22)/12,0)) -> 0 | E47: =Cm_netto*(A47<=$B$8) -> 0 | F47: =$B$26*IF(A47>$B$27,1,IF(A47=$B$27,(13-$B$28)/12,0)) -> 0 | G47: =IF(B47=1,IF(V_chi="T",$B$25*IF(A47>$B$27,1,IF(A47=$B$27,(13-$B$28)/12,0)),$B$19*IF(A47>$B$21,1,IF(A47=$B$21,(13-$B$22)/12,0))),0) -> 0 | H47: =IF(B47=1,$B$31*(1-p_contr)*(A47<=$B$8),0) -> 0 | I47: =G47+H47 -> 0 | J47: =IF(B47=1,$B$16*$B$29,0) -> 0 | K47: =IF(V_figli=1,1,IF(I47>tf_S5,tf_M5,IF(I47>tf_S4,tf_M4,IF(I47>tf_S3,tf_M3,1)))) -> 1 | L47: =MIN(J47*(1-K47),I47) -> 0 | M47: =J47-L47 -> 0 | N47: =G47+M47 -> 0 | O47: =MAX(0,IF(N47<=sc_L1,sc_A1*N47,IF(N47<=sc_L2,sc_B1+sc_A2*(N47-sc_L1),sc_B2+sc_A3*(N47-sc_L2)))-(IF(N47<=8500,1955,IF(N47<=28000,700+1255*(28000-N47)/19500,IF(N47<=50000,700*(50000-N47)/22000,0)))+IF(AND(N47>25000,N47<=29000),50,0))) -> 0 | P47: =IF(N47>0,N47-O47-IF(O47>0,p_add*N47,0),0) -> 0 | Q47: =IF(B47=1,MAX(M47-(IF((I47+M47)<=sc_L1,sc_A1*(I47+M47),IF((I47+M47)<=sc_L2,sc_B1+sc_A2*((I47+M47)-sc_L1),sc_B2+sc_A3*((I47+M47)-sc_L2)))-IF(I47<=sc_L1,sc_A1*I47,IF(I47<=sc_L2,sc_B1+sc_A2*(I47-sc_L1),sc_B2+sc_A3*(I47-sc_L2))))-p_add*M47,0),0) -> 0 | R47: =IF(B47=1,IF(A47>$B$8,P47,IF(V_chi="T",E47,C47)+IF(V_chi="T",F47,D47)+Q47),C47+D47+E47+F47) -> 0 | S47: =IF(B47=1,p_spesa/IF(A47-$B$30>=65,V_den65,V_den64),p_spesa) -> 39600 | T47: =S47-R47 -> 39600 | U47: =U46*(1+p_infl) -> 1.061208 | V47: =T47*U47 -> 42023.837 | W47: =AD46*IF(AND(V_chi<>"nessuno",A47=V_anno+1),Ved_q,1) -> 925190.41 | X47: =AE46*IF(AND(V_chi<>"nessuno",A47=V_anno+1),Ved_qb,1) -> 516245.69 | Y47: =IF(W47>0,MAX(0,1-X47/W47),0) -> 0.44201141 | Z47: =IF(V47>0,V47/(1-p_cgt*Y47),0) -> 47480.428 | AA47: =IF(AA46<>"",AA46,IF(AND(V47>0,Z47>W47,A47<=p_orizz),A47,"")) | AB47: =IF(V47>0,W47-Z47,W47-V47) -> 877709.98 | AC47: =IF(V47>0,IF(W47>0,X47-X47*Z47/W47,X47),X47-V47) -> 489752.16 | AD47: =AB47*(1+p_rend)*(1+p_infl)*(1-p_bollo) -> 920277.86 | AE47: =AC47 -> 489752.16 | AF47: =AD47/(U47*(1+p_infl)) -> 850194.49
A48: 2031 | B48: =IF(AND(V_chi<>"nessuno",A48>V_anno),1,0) -> 0 | C48: =Tz_netto*(A48<=$B$8) -> 0 | D48: =$B$20*IF(A48>$B$21,1,IF(A48=$B$21,(13-$B$22)/12,0)) -> 0 | E48: =Cm_netto*(A48<=$B$8) -> 0 | F48: =$B$26*IF(A48>$B$27,1,IF(A48=$B$27,(13-$B$28)/12,0)) -> 0 | G48: =IF(B48=1,IF(V_chi="T",$B$25*IF(A48>$B$27,1,IF(A48=$B$27,(13-$B$28)/12,0)),$B$19*IF(A48>$B$21,1,IF(A48=$B$21,(13-$B$22)/12,0))),0) -> 0 | H48: =IF(B48=1,$B$31*(1-p_contr)*(A48<=$B$8),0) -> 0 | I48: =G48+H48 -> 0 | J48: =IF(B48=1,$B$16*$B$29,0) -> 0 | K48: =IF(V_figli=1,1,IF(I48>tf_S5,tf_M5,IF(I48>tf_S4,tf_M4,IF(I48>tf_S3,tf_M3,1)))) -> 1 | L48: =MIN(J48*(1-K48),I48) -> 0 | M48: =J48-L48 -> 0 | N48: =G48+M48 -> 0 | O48: =MAX(0,IF(N48<=sc_L1,sc_A1*N48,IF(N48<=sc_L2,sc_B1+sc_A2*(N48-sc_L1),sc_B2+sc_A3*(N48-sc_L2)))-(IF(N48<=8500,1955,IF(N48<=28000,700+1255*(28000-N48)/19500,IF(N48<=50000,700*(50000-N48)/22000,0)))+IF(AND(N48>25000,N48<=29000),50,0))) -> 0 | P48: =IF(N48>0,N48-O48-IF(O48>0,p_add*N48,0),0) -> 0 | Q48: =IF(B48=1,MAX(M48-(IF((I48+M48)<=sc_L1,sc_A1*(I48+M48),IF((I48+M48)<=sc_L2,sc_B1+sc_A2*((I48+M48)-sc_L1),sc_B2+sc_A3*((I48+M48)-sc_L2)))-IF(I48<=sc_L1,sc_A1*I48,IF(I48<=sc_L2,sc_B1+sc_A2*(I48-sc_L1),sc_B2+sc_A3*(I48-sc_L2))))-p_add*M48,0),0) -> 0 | R48: =IF(B48=1,IF(A48>$B$8,P48,IF(V_chi="T",E48,C48)+IF(V_chi="T",F48,D48)+Q48),C48+D48+E48+F48) -> 0 | S48: =IF(B48=1,p_spesa/IF(A48-$B$30>=65,V_den65,V_den64),p_spesa) -> 39600 | T48: =S48-R48 -> 39600 | U48: =U47*(1+p_infl) -> 1.0824322 | V48: =T48*U48 -> 42864.314 | W48: =AD47*IF(AND(V_chi<>"nessuno",A48=V_anno+1),Ved_q,1) -> 920277.86 | X48: =AE47*IF(AND(V_chi<>"nessuno",A48=V_anno+1),Ved_qb,1) -> 489752.16 | Y48: =IF(W48>0,MAX(0,1-X48/W48),0) -> 0.46782143 | Z48: =IF(V48>0,V48/(1-p_cgt*Y48),0) -> 48800.036 | AA48: =IF(AA47<>"",AA47,IF(AND(V48>0,Z48>W48,A48<=p_orizz),A48,"")) | AB48: =IF(V48>0,W48-Z48,W48-V48) -> 871477.82 | AC48: =IF(V48>0,IF(W48>0,X48-X48*Z48/W48,X48),X48-V48) -> 463781.82 | AD48: =AB48*(1+p_rend)*(1+p_infl)*(1-p_bollo) -> 913743.45 | AE48: =AC48 -> 463781.82 | AF48: =AD48/(U48*(1+p_infl)) -> 827605.6
A49: 2032 | B49: =IF(AND(V_chi<>"nessuno",A49>V_anno),1,0) -> 0 | C49: =Tz_netto*(A49<=$B$8) -> 0 | D49: =$B$20*IF(A49>$B$21,1,IF(A49=$B$21,(13-$B$22)/12,0)) -> 0 | E49: =Cm_netto*(A49<=$B$8) -> 0 | F49: =$B$26*IF(A49>$B$27,1,IF(A49=$B$27,(13-$B$28)/12,0)) -> 0 | G49: =IF(B49=1,IF(V_chi="T",$B$25*IF(A49>$B$27,1,IF(A49=$B$27,(13-$B$28)/12,0)),$B$19*IF(A49>$B$21,1,IF(A49=$B$21,(13-$B$22)/12,0))),0) -> 0 | H49: =IF(B49=1,$B$31*(1-p_contr)*(A49<=$B$8),0) -> 0 | I49: =G49+H49 -> 0 | J49: =IF(B49=1,$B$16*$B$29,0) -> 0 | K49: =IF(V_figli=1,1,IF(I49>tf_S5,tf_M5,IF(I49>tf_S4,tf_M4,IF(I49>tf_S3,tf_M3,1)))) -> 1 | L49: =MIN(J49*(1-K49),I49) -> 0 | M49: =J49-L49 -> 0 | N49: =G49+M49 -> 0 | O49: =MAX(0,IF(N49<=sc_L1,sc_A1*N49,IF(N49<=sc_L2,sc_B1+sc_A2*(N49-sc_L1),sc_B2+sc_A3*(N49-sc_L2)))-(IF(N49<=8500,1955,IF(N49<=28000,700+1255*(28000-N49)/19500,IF(N49<=50000,700*(50000-N49)/22000,0)))+IF(AND(N49>25000,N49<=29000),50,0))) -> 0 | P49: =IF(N49>0,N49-O49-IF(O49>0,p_add*N49,0),0) -> 0 | Q49: =IF(B49=1,MAX(M49-(IF((I49+M49)<=sc_L1,sc_A1*(I49+M49),IF((I49+M49)<=sc_L2,sc_B1+sc_A2*((I49+M49)-sc_L1),sc_B2+sc_A3*((I49+M49)-sc_L2)))-IF(I49<=sc_L1,sc_A1*I49,IF(I49<=sc_L2,sc_B1+sc_A2*(I49-sc_L1),sc_B2+sc_A3*(I49-sc_L2))))-p_add*M49,0),0) -> 0 | R49: =IF(B49=1,IF(A49>$B$8,P49,IF(V_chi="T",E49,C49)+IF(V_chi="T",F49,D49)+Q49),C49+D49+E49+F49) -> 0 | S49: =IF(B49=1,p_spesa/IF(A49-$B$30>=65,V_den65,V_den64),p_spesa) -> 39600 | T49: =S49-R49 -> 39600 | U49: =U48*(1+p_infl) -> 1.1040808 | V49: =T49*U49 -> 43721.6 | W49: =AD48*IF(AND(V_chi<>"nessuno",A49=V_anno+1),Ved_q,1) -> 913743.45 | X49: =AE48*IF(AND(V_chi<>"nessuno",A49=V_anno+1),Ved_qb,1) -> 463781.82 | Y49: =IF(W49>0,MAX(0,1-X49/W49),0) -> 0.4924376 | Z49: =IF(V49>0,V49/(1-p_cgt*Y49),0) -> 50141.391 | AA49: =IF(AA48<>"",AA48,IF(AND(V49>0,Z49>W49,A49<=p_orizz),A49,"")) | AB49: =IF(V49>0,W49-Z49,W49-V49) -> 863602.06 | AC49: =IF(V49>0,IF(W49>0,X49-X49*Z49/W49,X49),X49-V49) -> 438331.94 | AD49: =AB49*(1+p_rend)*(1+p_infl)*(1-p_bollo) -> 905485.73 | AE49: =AC49 -> 438331.94 | AF49: =AD49/(U49*(1+p_infl)) -> 804045.41
