Workbook

Sheet 0-Indice
A1: Inflazione dello stile di vita — il simulatore del caso (2026)
A2: Strumento informativo / divulgativo. NON è consulenza finanziaria. I valori sono indicativi al 2026 e vanno verificati col tuo consulente.
A4: Indice
A5: P-Parametri | B5: Aliquote, detrazioni, soglie: le costanti normative, tutte in un posto solo
A6: 1-Input | B6: La scheda-caso e il vincolo aritmetico da cui esce il capitale
A7: 2-Busta-paga | B7: Il motore fiscale 2026, da RAL 15.000 a 62.000, e le due marginali
A8: 3-Aumento | B8: I due eventi: la promozione ordinaria e il rinnovo con la sostitutiva del 5%
A9: 4-Rapporto-RAL | B9: Il fattore del comma 7 IN FUNZIONE DELLA RAL, e quanto è stretta la finestra
A10: 5-Moltiplicatore | B10: Quanto capitale serve per un euro al mese, per sempre
A11: 6-Anni-al-FIRE | B11: La formula degli anni al traguardo e la controprova anno per anno
A12: 7-Scenari | B12: I quattro destini, la banda del rendimento e il doppio effetto
A13: 8-Soglia-q | B13: La soglia q*: la dimostrazione che non dipende da quanto è grande l'aumento
A14: 9-Traduttore | B14: Traduce una spesa mensile in obiettivo, anni e ore di lavoro
A15: 10-Regola-ora | B15: Quanto vale un'ora, e quanto puoi spendere per ricomprartela
A16: 11-Cruscotto | B16: Gli otto numeri e il semaforo — il foglio della demo
... A18: 13-Verifica | B18: Il confronto fra il motore e i numeri del video, con lo scarto
A20: Come usare
A21: 1. Le celle GIALLE sono input — modificale coi tuoi numeri.
A22: 2. Le celle VERDI sono output — si aggiornano automaticamente.
A23: 3. Tutti i numeri di default sono al 2026 da fonti pubbliche.
A24: 4. Niente codice nascosto: l'Excel è solo formule modificabili.
A26: Fonti dati
A27: • IRPEF 2026 23/33/43% — art. 11 TUIR, L. 199/2025 art. 1 c. 3
A28: • Detrazione da lavoro dipendente — art. 13 c. 1 TUIR
A29: • Ulteriore detrazione — L. 207/2024 art. 1 c. 6 (in vigore per tutto il 2026)
A30: • Imposta sostitutiva 5% sugli incrementi retributivi — L. 199/2025 art. 1 c. 7
A31: • Circolari Agenzia delle Entrate n. 2/E del 24/2/2026 e n. 3/E del 24/6/2026
A32: • Contributi 9,19% — art. 1 c. 769 L. 296/2006
... A40: QUESTA PARTE SCADE: l'imposta sostitutiva del 5% (fogli 3 e 4) vale SOLO sugli incrementi retributivi EROGATI NEL 2026. Il contenuto durevole del foglio è l'aliquota marginale effettiva e la soglia q*, che non dipendono da nessuna norma a termine. Refresh obbligatorio a gennaio 2027.

Sheet P-Parametri
A1: P — Parametri normativi 2026 (celle gialle: si toccano solo se cambia la legge)
A2: Strumento informativo / divulgativo. NON è consulenza finanziaria. I valori sono indicativi al 2026 e vanno verificati col tuo consulente.
A3: FOTOGRAFIA DEL 2026. Il D.Lgs. 117/2026 (testo unico delle imposte sui redditi) è entrato in vigore il 4/7/2026 ma i suoi effetti DECORRONO dal 1° gennaio 2027 (art. 377), e l'art. 376 c. 2 dispone la continuità dei rinvii: è ricodificazione, non soppressione. Per tutto il 2026 valgono le norme di questo foglio. Chi verificherà su Normattiva nel 2027 leggerà di default la versione già abrogata: bisogna scendere di una versione e leggere quella vigente nell'anno del video.
A5: IRPEF — art. 11 TUIR come modificato dalla L. 199/2025 art. 1 c. 3
A6: Primo scaglione: limite / aliquota | B6: 28000 | C6: 0.23
A7: Secondo scaglione: limite / aliquota | B7: 50000 | C7: 0.33
A8: Terzo scaglione: aliquota | C8: 0.43
A9: IRPEF cumulata a fine primo scaglione (derivata) | B9: ='P-Parametri'!$B$6*'P-Parametri'!$C$6 -> 6440
A10: IRPEF cumulata a fine secondo scaglione (derivata) | B10: ='P-Parametri'!$B$9+'P-Parametri'!$C$7*('P-Parametri'!$B$7-'P-Parametri'!$B$6) -> 13700
A11: Detrazioni e contributi
A12: Detrazione lavoro dipendente — importo pieno / soglia (art. 13 c. 1 TUIR) | B12: 1955 | C12: 15000
A13: Fascia 15.000-28.000: base / incremento / ampiezza | B13: 1910 | C13: 1190 | D13: 13000
A14: Fascia 28.000-50.000: base / ampiezza | B14: 1910 | C14: 22000
A15: Ulteriore detrazione L. 207/2024 art. 1 c. 6 — importo / da / piena fino a / azzerata a | B15: 1000 | C15: 8500 | D15: 32000 | E15: 40000
A16: Trattamento integrativo D.L. 3/2020 — importo / soglia / scarto di capienza | B16: 1200 | C16: 15000 | D16: 75
A17: Somma sul cuneo L. 207/2024 art. 1 c. 4 — tre aliquote | B17: 0.071 | C17: 0.053 | D17: 0.048
A18: Somma sul cuneo — tre soglie di reddito complessivo | B18: 8500 | C18: 15000 | D18: 20000
A19: Contributi a carico del lavoratore (art. 1 c. 769 L. 296/2006) | B19: 0.0919
A20: Addizionali regionale + comunale — IPOTESI DI CANALE, non una norma | B20: 0.02
A21: I passi «somma sul cuneo» e «trattamento integrativo» NON mordono mai sul caso (reddito complessivo 32.691,60 €): sono nel motore per completezza e perché il foglio 2 copre RAL da 15.000 a 62.000.
A22: Imposta sostitutiva sugli incrementi retributivi — L. 199/2025 art. 1 c. 7
A23: Aliquota sostitutiva di IRPEF e addizionali | B23: 0.05
A24: Tetto: reddito di lavoro dipendente 2025 | B24: 33000
A25: Anno di erogazione agevolato (la norma vale SOLO su questo) | B25: 2026
A26: QUESTA PARTE SCADE. Il comma 7 si applica agli incrementi EROGATI nel 2026. Dal 2027 l'incremento rientra in tassazione ordinaria e ogni numero dei blocchi «CCNL» e «rapporto» smette di valere. Circolari AdE 2/E del 24/2/2026 e 3/E del 24/6/2026. Il limite dei 33.000 € si verifica sommando TUTTI i redditi di lavoro dipendente percepiti nel 2025, anche da più rapporti (circ. 2/E, verbatim). È un'opzione, non un obbligo: con rinuncia scritta si sceglie la tassazione ordinaria.
A27: Canone numerico del canale
A28: Rendimento REALE su 60/40 (DMS Yearbook) — banda bassa / base / alta | B28: 0.02 | C28: 0.03 | D28: 0.04
A29: Tasso di prelievo — regola del 4% / prudente / Anarkulova 2025 | B29: 0.04 | C29: 0.03 | D29: 0.0231
A30: Inflazione dichiarata (il modello è in euro reali: non entra nei conti) | B30: 0.02
A31: Il 5% e il 7% reale dei blog americani NON sono in elenco: sono vietati dal canone del canale. Anarkulova, Cederburg, O'Doherty, Sias (2025), J. Pension Econ. Fin. 24(3):464-500 danno un prelievo sicuro del 2,31%.
A32: Riferimenti del caso
A33: Spesa media mensile ISTAT 2024, persona sola (€/mese) | B33: 1932
A34: Settimane lavorate all'anno / settimane dell'anno | B34: 43 | C34: 52
A35: QUARTO ERRORE DI FAMIGLIA. L'aggregato ISTAT «spesa media mensile per consumi» INCLUDE gli affitti figurativi dei proprietari, che sono una componente NON monetaria. Confrontarlo con un flusso di cassa è omogeneo solo se si dichiara lo stato abitativo: vedi la cella B15 del foglio 1-Input.
A36: Fiscalità finanziaria — canone di canale, dichiarata NON attiva qui
A37: Imposta sulla plusvalenza realizzata | B37: 0.26
A38: Imposta di bollo sul dossier titoli | B38: 0.002
A39: LIMITE DICHIARATO. Questo modello è in accumulo e usa il traguardo come moltiplicatore della spesa (FIRE number = m × spesa): non simula i prelievi, quindi capital gain e bollo NON entrano in nessun conto di questi fogli. Sono qui perché sono il canone del canale e perché chi riusa il foglio deve sapere che mancano — non perché siano applicati. Il rendimento è già REALE e al lordo di queste due imposte.
A40: REFRESH GENNAIO 2027 — OBBLIGATORIO. Scaglioni, detrazioni, ulteriore detrazione, trattamento integrativo e somma sul cuneo sono riscritti ogni anno dalla legge di bilancio, e l'imposta sostitutiva del comma 7 vale SOLO sul 2026.

Sheet 1-Input
A1: 1 — Input del caso (le celle GIALLE sono le uniche che si toccano)
A2: Strumento informativo / divulgativo. NON è consulenza finanziaria. I valori sono indicativi al 2026 e vanno verificati col tuo consulente.
A3: Caso ILLUSTRATIVO e COMPOSITO. Non è una persona reale e il video non promette il FIRE: promette una differenza fra due modi di usare lo stesso aumento.
A4: La scheda-caso
A5: Età | B5: 32
A6: RAL (retribuzione annua lorda) | B6: 36000
A7: Spesa annua | B7: 21000
A8: Capitale già investito | B8: 26000
A9: Aumento LORDO ricevuto (promozione, canale ordinario) | B9: 7000
A10: Quota dell'aumento assorbita in spesa q (0% / 50% / 76,17% / 100%) | B10: 1
A11: Rendimento REALE annuo r (2% / 3% / 4% — il 5% è vietato) | B11: 0.03
A12: Tasso di prelievo w (4% / 3% / 2,31%) | B12: 0.04
A13: Ore lavorate all'anno (ipotesi dichiarata: 40 h × 43 settimane) | B13: 1720
A14: Settimane su cui si conta un'ora restituita (43 = lavorative) | B14: 43
A15: Stato abitativo (affitto / proprietà) — variabile OBBLIGATORIA | B15: affitto
A16: Settore (privato / pubblico) — il comma 7 vale solo sul privato | B16: privato
A17: Anno di erogazione dell'aumento | B17: 2026
A19: Che cosa ne esce — tutto formula, niente digitato
A21: Contributi a carico del lavoratore | B21: ='P-Parametri'!$B$19*'1-Input'!$B$6 -> 3308.4
A22: Reddito complessivo (= reddito di lavoro dipendente) | B22: ='1-Input'!$B$6-'1-Input'!$B$21 -> 32691.6
A23: Netto annuo | B23: =('1-Input'!$B$6*(1-'P-Parametri'!$B$19))-(MAX(0,(IF(('1-Input'!$B$6*(1-'P-Parametri'!$B$19))<='P-Parametri'!$B$6,'P-Parametri'!$C$6*('1-Input'!$B$6*(1-'P-Parametri'!$B$19)),IF(('1-Input'!$B$6*(1-'P-Parametri'!$B$19))<='P-Parametri'!$B$7,'P-Parametri'!$B$9+'P-Parametri'!$C$7*(('1-Input'!$B$6*(1-'P-Parametri'!$B$19))-'P-Parametri'!$B$6),'P-Parametri'!$B$10+'P-Parametri'!$C$8*(('1-Input'!$B$6*(1-'P-Parametri'!$B$19))-'P-Parametri'!$B$7))))-(IF(('1-Input'!$B$6*(1-'P-Parametri'!$B$19))<='P-Parametri'!$C$12,'P-Parametri'!$B$12,IF(('1-Input'!$B$6*(1-'P-Parametri'!$B$19))<='P-Parametri'!$B$6,'P-Parametri'!$B$13+'P-Parametri'!$C$13*('P-Parametri'!$B$6-('1-Input'!$B$6*(1-'P-Parametri'!$B$19)))/'P-Parametri'!$D$13,IF(('1-Input'!$B$6*(1-'P-Parametri'!$B$19))<='P-Parametri'!$B$7,'P-Parametri'!$B$14*('P-Parametri'!$B$7-('1-Input'!$B$6*(1-'P-Parametri'!$B$19)))/'P-Parametri'!$C$14,0))))-(IF(('1-Input'!$B$6*(1-'P-Parametri'!$B$19))<='P-Parametri'!$C$15,0,IF(('1-Input'!$B$6*(1-'P-Parametri'!$B$19))<='P-Parametri'!$D$15,'P-Parametri'!$B$15,IF(('1-Input'!$B$6*(1-'P-Parametri'!$B$19))<'P-Parametri'!$E$15,'P-Parametri'!$B$15*('P-Parametri'!$E$15-('1-Input'!$B$6*(1-'P-Parametri'!$B$19)))/('P-Parametri'!$E$15-'P-Parametri'!$D$15),0))))))-(IF(MAX(0,(IF(('1-Input'!$B$6*(1-'P-Parametri'!$B$19))<='P-Parametri'!$B$6,'P-Parametri'!$C$6*('1-Input'!$B$6*(1-'P-Parametri'!$B$19)),IF(('1-Input'!$B$6*(1-'P-Parametri'!$B$19))<='P-Parametri'!$B$7,'P-Parametri'!$B$9+'P-Parametri'!$C$7*(('1-Input'!$B$6*(1-'P-Parametri'!$B$19))-'P-Parametri'!$B$6),'P-Parametri'!$B$10+'P-Parametri'!$C$8*(('1-Input'!$B$6*(1-'P-Parametri'!$B$19))-'P-Parametri'!$B$7))))-(IF(('1-Input'!$B$6*(1-'P-Parametri'!$B$19))<='P-Parametri'!$C$12,'P-Parametri'!$B$12,IF(('1-Input'!$B$6*(1-'P-Parametri'!$B$19))<='P-Parametri'!$B$6,'P-Parametri'!$B$13+'P-Parametri'!$C$13*('P-Parametri'!$B$6-('1-Input'!$B$6*(1-'P-Parametri'!$B$19)))/'P-Parametri'!$D$13,IF(('1-Input'!$B$6*(1-'P-Parametri'!$B$19))<='P-Parametri'!$B$7,'P-Parametri'!$B$14*('P-Parametri'!$B$7-('1-Input'!$B$6*(1-'P-Parametri'!$B$19)))/'P-Parametri'!$C$14,0))))-(IF(('1-Input'!$B$6*(1-'P-Parametri'!$B$19))<='P-Parametri'!$C$15,0,IF(('1-Input'!$B$6*(1-'P-Parametri'!$B$19))<='P-Parametri'!$D$15,'P-Parametri'!$B$15,IF(('1-Input'!$B$6*(1-'P-Parametri'!$B$19))<'P-Parametri'!$E$15,'P-Parametri'!$B$15*('P-Parametri'!$E$15-('1-Input'!$B$6*(1-'P-Parametri'!$B$19)))/('P-Parametri'!$E$15-'P-Parametri'!$D$15),0)))))>0,'P-Parametri'!$B$20*('1-Input'!$B$6*(1-'P-Parametri'!$B$19)),0))+(IF(AND(('1-Input'!$B$6*(1-'P-Parametri'!$B$19))<='P-Parametri'!$C$16,(IF(('1-Input'!$B$6*(1-'P-Parametri'!$B$19))<='P-Parametri'!$B$6,'P-Parametri'!$C$6*('1-Input'!$B$6*(1-'P-Parametri'!$B$19)),IF(('1-Input'!$B$6*(1-'P-Parametri'!$B$19))<='P-Parametri'!$B$7,'P-Parametri'!$B$9+'P-Parametri'!$C$7*(('1-Input'!$B$6*(1-'P-Parametri'!$B$19))-'P-Parametri'!$B$6),'P-Parametri'!$B$10+'P-Parametri'!$C$8*(('1-Input'!$B$6*(1-'P-Parametri'!$B$19))-'P-Parametri'!$B$7))))>(IF(('1-Input'!$B$6*(1-'P-Parametri'!$B$19))<='P-Parametri'!$C$12,'P-Parametri'!$B$12,IF(('1-Input'!$B$6*(1-'P-Parametri'!$B$19))<='P-Parametri'!$B$6,'P-Parametri'!$B$13+'P-Parametri'!$C$13*('P-Parametri'!$B$6-('1-Input'!$B$6*(1-'P-Parametri'!$B$19)))/'P-Parametri'!$D$13,IF(('1-Input'!$B$6*(1-'P-Parametri'!$B$19))<='P-Parametri'!$B$7,'P-Parametri'!$B$14*('P-Parametri'!$B$7-('1-Input'!$B$6*(1-'P-Parametri'!$B$19)))/'P-Parametri'!$C$14,0))))-'P-Parametri'!$D$16),'P-Parametri'!$B$16,0))+(IF(('1-Input'!$B$6*(1-'P-Parametri'!$B$19))>'P-Parametri'!$D$18,0,IF(('1-Input'!$B$6*(1-'P-Parametri'!$B$19))<='P-Parametri'!$B$18,'P-Parametri'!$B$17*('1-Input'!$B$6*(1-'P-Parametri'!$B$19)),IF(('1-Input'!$B$6*(1-'P-Parametri'!$B$19))<='P-Parametri'!$C$18,'P-Parametri'!$C$17*('1-Input'!$B$6*(1-'P-Parametri'!$B$19)),'P-Parametri'!$D$17*('1-Input'!$B$6*(1-'P-Parametri'!$B$19)))))) -> 26465.774
A24: Netto mensile — su 12 / su 13 | B24: ='1-Input'!$B$23/12 -> 2205.4812 | C24: ='1-Input'!$B$23/13 -> 2035.8288
A25: Risparmio annuo | B25: ='1-Input'!$B$23-'1-Input'!$B$7 -> 5465.7738
A26: Tasso di risparmio (sul netto) | B26: ='1-Input'!$B$25/'1-Input'!$B$23 -> 0.20652235
A27: Moltiplicatore del traguardo m = 1/w | B27: =1/'1-Input'!$B$12 -> 25
A28: FIRE number = m × spesa | B28: ='1-Input'!$B$27*'1-Input'!$B$7 -> 525000
A29: Reddito di lavoro dipendente 2025 (test del comma 7) | B29: ='1-Input'!$B$22 -> 32691.6
A30: Margine sotto il tetto dei 33.000 € | B30: ='P-Parametri'!$B$24-'1-Input'!$B$29 -> 308.4
A31: Anni al traguardo, caso base | B31: =LN(('1-Input'!$B$28+'1-Input'!$B$25/'1-Input'!$B$11)/('1-Input'!$B$8+'1-Input'!$B$25/'1-Input'!$B$11))/LN(1+'1-Input'!$B$11) -> 41.369738
A32: Netto in % della RAL | B32: ='1-Input'!$B$23/'1-Input'!$B$6 -> 0.73516038
A33: Ammissibile al comma 7? | B33: =IF(AND('1-Input'!$B$16="privato",'1-Input'!$B$29<='P-Parametri'!$B$24,'1-Input'!$B$17='P-Parametri'!$B$25),"SI — settore privato, sotto i 33.000, anno 2026","NO — verifica settore, tetto reddituale o anno di erogazione") -> SI — settore privato, sotto i 33.000, anno 2026
A34: Età al traguardo, caso base | B34: ='1-Input'!$B$5+'1-Input'!$B$31 -> 73.369738
A36: Il vincolo aritmetico: da dove viene il capitale (terzo errore di famiglia)
A37: Anno | B37: Età | C37: RAL | D37: Netto | E37: Spesa | F37: Risparmio | G37: Tasso di risparmio | H37: Montante al 1/1/2026
A38: =2019 -> 2019 | B38: =25 -> 25 | C38: 26000 | D38: =(C38*(1-'P-Parametri'!$B$19))-(MAX(0,(IF((C38*(1-'P-Parametri'!$B$19))<='P-Parametri'!$B$6,'P-Parametri'!$C$6*(C38*(1-'P-Parametri'!$B$19)),IF((C38*(1-'P-Parametri'!$B$19))<='P-Parametri'!$B$7,'P-Parametri'!$B$9+'P-Parametri'!$C$7*((C38*(1-'P-Parametri'!$B$19))-'P-Parametri'!$B$6),'P-Parametri'!$B$10+'P-Parametri'!$C$8*((C38*(1-'P-Parametri'!$B$19))-'P-Parametri'!$B$7))))-(IF((C38*(1-'P-Parametri'!$B$19))<='P-Parametri'!$C$12,'P-Parametri'!$B$12,IF((C38*(1-'P-Parametri'!$B$19))<='P-Parametri'!$B$6,'P-Parametri'!$B$13+'P-Parametri'!$C$13*('P-Parametri'!$B$6-(C38*(1-'P-Parametri'!$B$19)))/'P-Parametri'!$D$13,IF((C38*(1-'P-Parametri'!$B$19))<='P-Parametri'!$B$7,'P-Parametri'!$B$14*('P-Parametri'!$B$7-(C38*(1-'P-Parametri'!$B$19)))/'P-Parametri'!$C$14,0))))-(IF((C38*(1-'P-Parametri'!$B$19))<='P-Parametri'!$C$15,0,IF((C38*(1-'P-Parametri'!$B$19))<='P-Parametri'!$D$15,'P-Parametri'!$B$15,IF((C38*(1-'P-Parametri'!$B$19))<'P-Parametri'!$E$15,'P-Parametri'!$B$15*('P-Parametri'!$E$15-(C38*(1-'P-Parametri'!$B$19)))/('P-Parametri'!$E$15-'P-Parametri'!$D$15),0))))))-(IF(MAX(0,(IF((C38*(1-'P-Parametri'!$B$19))<='P-Parametri'!$B$6,'P-Parametri'!$C$6*(C38*(1-'P-Parametri'!$B$19)),IF((C38*(1-'P-Parametri'!$B$19))<='P-Parametri'!$B$7,'P-Parametri'!$B$9+'P-Parametri'!$C$7*((C38*(1-'P-Parametri'!$B$19))-'P-Parametri'!$B$6),'P-Parametri'!$B$10+'P-Parametri'!$C$8*((C38*(1-'P-Parametri'!$B$19))-'P-Parametri'!$B$7))))-(IF((C38*(1-'P-Parametri'!$B$19))<='P-Parametri'!$C$12,'P-Parametri'!$B$12,IF((C38*(1-'P-Parametri'!$B$19))<='P-Parametri'!$B$6,'P-Parametri'!$B$13+'P-Parametri'!$C$13*('P-Parametri'!$B$6-(C38*(1-'P-Parametri'!$B$19)))/'P-Parametri'!$D$13,IF((C38*(1-'P-Parametri'!$B$19))<='P-Parametri'!$B$7,'P-Parametri'!$B$14*('P-Parametri'!$B$7-(C38*(1-'P-Parametri'!$B$19)))/'P-Parametri'!$C$14,0))))-(IF((C38*(1-'P-Parametri'!$B$19))<='P-Parametri'!$C$15,0,IF((C38*(1-'P-Parametri'!$B$19))<='P-Parametri'!$D$15,'P-Parametri'!$B$15,IF((C38*(1-'P-Parametri'!$B$19))<'P-Parametri'!$E$15,'P-Parametri'!$B$15*('P-Parametri'!$E$15-(C38*(1-'P-Parametri'!$B$19)))/('P-Parametri'!$E$15-'P-Parametri'!$D$15),0)))))>0,'P-Parametri'!$B$20*(C38*(1-'P-Parametri'!$B$19)),0))+(IF(AND((C38*(1-'P-Parametri'!$B$19))<='P-Parametri'!$C$16,(IF((C38*(1-'P-Parametri'!$B$19))<='P-Parametri'!$B$6,'P-Parametri'!$C$6*(C38*(1-'P-Parametri'!$B$19)),IF((C38*(1-'P-Parametri'!$B$19))<='P-Parametri'!$B$7,'P-Parametri'!$B$9+'P-Parametri'!$C$7*((C38*(1-'P-Parametri'!$B$19))-'P-Parametri'!$B$6),'P-Parametri'!$B$10+'P-Parametri'!$C$8*((C38*(1-'P-Parametri'!$B$19))-'P-Parametri'!$B$7))))>(IF((C38*(1-'P-Parametri'!$B$19))<='P-Parametri'!$C$12,'P-Parametri'!$B$12,IF((C38*(1-'P-Parametri'!$B$19))<='P-Parametri'!$B$6,'P-Parametri'!$B$13+'P-Parametri'!$C$13*('P-Parametri'!$B$6-(C38*(1-'P-Parametri'!$B$19)))/'P-Parametri'!$D$13,IF((C38*(1-'P-Parametri'!$B$19))<='P-Parametri'!$B$7,'P-Parametri'!$B$14*('P-Parametri'!$B$7-(C38*(1-'P-Parametri'!$B$19)))/'P-Parametri'!$C$14,0))))-'P-Parametri'!$D$16),'P-Parametri'!$B$16,0))+(IF((C38*(1-'P-Parametri'!$B$19))>'P-Parametri'!$D$18,0,IF((C38*(1-'P-Parametri'!$B$19))<='P-Parametri'!$B$18,'P-Parametri'!$B$17*(C38*(1-'P-Parametri'!$B$19)),IF((C38*(1-'P-Parametri'!$B$19))<='P-Parametri'!$C$18,'P-Parametri'!$C$17*(C38*(1-'P-Parametri'!$B$19)),'P-Parametri'!$D$17*(C38*(1-'P-Parametri'!$B$19)))))) -> 21019.749 | E38: 19500 | F38: =D38-E38 -> 1519.7489 | G38: =F38/D38 -> 0.072301003 | H38: =F38*(1+'1-Input'!$B$11)^(2025-A38) -> 1814.6597
A39: =2020 -> 2020 | B39: =26 -> 26 | C39: 27500 | D39: =(C39*(1-'P-Parametri'!$B$19))-(MAX(0,(IF((C39*(1-'P-Parametri'!$B$19))<='P-Parametri'!$B$6,'P-Parametri'!$C$6*(C39*(1-'P-Parametri'!$B$19)),IF((C39*(1-'P-Parametri'!$B$19))<='P-Parametri'!$B$7,'P-Parametri'!$B$9+'P-Parametri'!$C$7*((C39*(1-'P-Parametri'!$B$19))-'P-Parametri'!$B$6),'P-Parametri'!$B$10+'P-Parametri'!$C$8*((C39*(1-'P-Parametri'!$B$19))-'P-Parametri'!$B$7))))-(IF((C39*(1-'P-Parametri'!$B$19))<='P-Parametri'!$C$12,'P-Parametri'!$B$12,IF((C39*(1-'P-Parametri'!$B$19))<='P-Parametri'!$B$6,'P-Parametri'!$B$13+'P-Parametri'!$C$13*('P-Parametri'!$B$6-(C39*(1-'P-Parametri'!$B$19)))/'P-Parametri'!$D$13,IF((C39*(1-'P-Parametri'!$B$19))<='P-Parametri'!$B$7,'P-Parametri'!$B$14*('P-Parametri'!$B$7-(C39*(1-'P-Parametri'!$B$19)))/'P-Parametri'!$C$14,0))))-(IF((C39*(1-'P-Parametri'!$B$19))<='P-Parametri'!$C$15,0,IF((C39*(1-'P-Parametri'!$B$19))<='P-Parametri'!$D$15,'P-Parametri'!$B$15,IF((C39*(1-'P-Parametri'!$B$19))<'P-Parametri'!$E$15,'P-Parametri'!$B$15*('P-Parametri'!$E$15-(C39*(1-'P-Parametri'!$B$19)))/('P-Parametri'!$E$15-'P-Parametri'!$D$15),0))))))-(IF(MAX(0,(IF((C39*(1-'P-Parametri'!$B$19))<='P-Parametri'!$B$6,'P-Parametri'!$C$6*(C39*(1-'P-Parametri'!$B$19)),IF((C39*(1-'P-Parametri'!$B$19))<='P-Parametri'!$B$7,'P-Parametri'!$B$9+'P-Parametri'!$C$7*((C39*(1-'P-Parametri'!$B$19))-'P-Parametri'!$B$6),'P-Parametri'!$B$10+'P-Parametri'!$C$8*((C39*(1-'P-Parametri'!$B$19))-'P-Parametri'!$B$7))))-(IF((C39*(1-'P-Parametri'!$B$19))<='P-Parametri'!$C$12,'P-Parametri'!$B$12,IF((C39*(1-'P-Parametri'!$B$19))<='P-Parametri'!$B$6,'P-Parametri'!$B$13+'P-Parametri'!$C$13*('P-Parametri'!$B$6-(C39*(1-'P-Parametri'!$B$19)))/'P-Parametri'!$D$13,IF((C39*(1-'P-Parametri'!$B$19))<='P-Parametri'!$B$7,'P-Parametri'!$B$14*('P-Parametri'!$B$7-(C39*(1-'P-Parametri'!$B$19)))/'P-Parametri'!$C$14,0))))-(IF((C39*(1-'P-Parametri'!$B$19))<='P-Parametri'!$C$15,0,IF((C39*(1-'P-Parametri'!$B$19))<='P-Parametri'!$D$15,'P-Parametri'!$B$15,IF((C39*(1-'P-Parametri'!$B$19))<'P-Parametri'!$E$15,'P-Parametri'!$B$15*('P-Parametri'!$E$15-(C39*(1-'P-Parametri'!$B$19)))/('P-Parametri'!$E$15-'P-Parametri'!$D$15),0)))))>0,'P-Parametri'!$B$20*(C39*(1-'P-Parametri'!$B$19)),0))+(IF(AND((C39*(1-'P-Parametri'!$B$19))<='P-Parametri'!$C$16,(IF((C39*(1-'P-Parametri'!$B$19))<='P-Parametri'!$B$6,'P-Parametri'!$C$6*(C39*(1-'P-Parametri'!$B$19)),IF((C39*(1-'P-Parametri'!$B$19))<='P-Parametri'!$B$7,'P-Parametri'!$B$9+'P-Parametri'!$C$7*((C39*(1-'P-Parametri'!$B$19))-'P-Parametri'!$B$6),'P-Parametri'!$B$10+'P-Parametri'!$C$8*((C39*(1-'P-Parametri'!$B$19))-'P-Parametri'!$B$7))))>(IF((C39*(1-'P-Parametri'!$B$19))<='P-Parametri'!$C$12,'P-Parametri'!$B$12,IF((C39*(1-'P-Parametri'!$B$19))<='P-Parametri'!$B$6,'P-Parametri'!$B$13+'P-Parametri'!$C$13*('P-Parametri'!$B$6-(C39*(1-'P-Parametri'!$B$19)))/'P-Parametri'!$D$13,IF((C39*(1-'P-Parametri'!$B$19))<='P-Parametri'!$B$7,'P-Parametri'!$B$14*('P-Parametri'!$B$7-(C39*(1-'P-Parametri'!$B$19)))/'P-Parametri'!$C$14,0))))-'P-Parametri'!$D$16),'P-Parametri'!$B$16,0))+(IF((C39*(1-'P-Parametri'!$B$19))>'P-Parametri'!$D$18,0,IF((C39*(1-'P-Parametri'!$B$19))<='P-Parametri'!$B$18,'P-Parametri'!$B$17*(C39*(1-'P-Parametri'!$B$19)),IF((C39*(1-'P-Parametri'!$B$19))<='P-Parametri'!$C$18,'P-Parametri'!$C$17*(C39*(1-'P-Parametri'!$B$19)),'P-Parametri'!$D$17*(C39*(1-'P-Parametri'!$B$19)))))) -> 21916.672 | E39: 19750 | F39: =D39-E39 -> 2166.6723 | G39: =F39/D39 -> 0.098859548 | H39: =F39*(1+'1-Input'!$B$11)^(2025-A39) -> 2511.767
A40: =2021 -> 2021 | B40: =27 -> 27 | C40: 29000 | D40: =(C40*(1-'P-Parametri'!$B$19))-(MAX(0,(IF((C40*(1-'P-Parametri'!$B$19))<='P-Parametri'!$B$6,'P-Parametri'!$C$6*(C40*(1-'P-Parametri'!$B$19)),IF((C40*(1-'P-Parametri'!$B$19))<='P-Parametri'!$B$7,'P-Parametri'!$B$9+'P-Parametri'!$C$7*((C40*(1-'P-Parametri'!$B$19))-'P-Parametri'!$B$6),'P-Parametri'!$B$10+'P-Parametri'!$C$8*((C40*(1-'P-Parametri'!$B$19))-'P-Parametri'!$B$7))))-(IF((C40*(1-'P-Parametri'!$B$19))<='P-Parametri'!$C$12,'P-Parametri'!$B$12,IF((C40*(1-'P-Parametri'!$B$19))<='P-Parametri'!$B$6,'P-Parametri'!$B$13+'P-Parametri'!$C$13*('P-Parametri'!$B$6-(C40*(1-'P-Parametri'!$B$19)))/'P-Parametri'!$D$13,IF((C40*(1-'P-Parametri'!$B$19))<='P-Parametri'!$B$7,'P-Parametri'!$B$14*('P-Parametri'!$B$7-(C40*(1-'P-Parametri'!$B$19)))/'P-Parametri'!$C$14,0))))-(IF((C40*(1-'P-Parametri'!$B$19))<='P-Parametri'!$C$15,0,IF((C40*(1-'P-Parametri'!$B$19))<='P-Parametri'!$D$15,'P-Parametri'!$B$15,IF((C40*(1-'P-Parametri'!$B$19))<'P-Parametri'!$E$15,'P-Parametri'!$B$15*('P-Parametri'!$E$15-(C40*(1-'P-Parametri'!$B$19)))/('P-Parametri'!$E$15-'P-Parametri'!$D$15),0))))))-(IF(MAX(0,(IF((C40*(1-'P-Parametri'!$B$19))<='P-Parametri'!$B$6,'P-Parametri'!$C$6*(C40*(1-'P-Parametri'!$B$19)),IF((C40*(1-'P-Parametri'!$B$19))<='P-Parametri'!$B$7,'P-Parametri'!$B$9+'P-Parametri'!$C$7*((C40*(1-'P-Parametri'!$B$19))-'P-Parametri'!$B$6),'P-Parametri'!$B$10+'P-Parametri'!$C$8*((C40*(1-'P-Parametri'!$B$19))-'P-Parametri'!$B$7))))-(IF((C40*(1-'P-Parametri'!$B$19))<='P-Parametri'!$C$12,'P-Parametri'!$B$12,IF((C40*(1-'P-Parametri'!$B$19))<='P-Parametri'!$B$6,'P-Parametri'!$B$13+'P-Parametri'!$C$13*('P-Parametri'!$B$6-(C40*(1-'P-Parametri'!$B$19)))/'P-Parametri'!$D$13,IF((C40*(1-'P-Parametri'!$B$19))<='P-Parametri'!$B$7,'P-Parametri'!$B$14*('P-Parametri'!$B$7-(C40*(1-'P-Parametri'!$B$19)))/'P-Parametri'!$C$14,0))))-(IF((C40*(1-'P-Parametri'!$B$19))<='P-Parametri'!$C$15,0,IF((C40*(1-'P-Parametri'!$B$19))<='P-Parametri'!$D$15,'P-Parametri'!$B$15,IF((C40*(1-'P-Parametri'!$B$19))<'P-Parametri'!$E$15,'P-Parametri'!$B$15*('P-Parametri'!$E$15-(C40*(1-'P-Parametri'!$B$19)))/('P-Parametri'!$E$15-'P-Parametri'!$D$15),0)))))>0,'P-Parametri'!$B$20*(C40*(1-'P-Parametri'!$B$19)),0))+(IF(AND((C40*(1-'P-Parametri'!$B$19))<='P-Parametri'!$C$16,(IF((C40*(1-'P-Parametri'!$B$19))<='P-Parametri'!$B$6,'P-Parametri'!$C$6*(C40*(1-'P-Parametri'!$B$19)),IF((C40*(1-'P-Parametri'!$B$19))<='P-Parametri'!$B$7,'P-Parametri'!$B$9+'P-Parametri'!$C$7*((C40*(1-'P-Parametri'!$B$19))-'P-Parametri'!$B$6),'P-Parametri'!$B$10+'P-Parametri'!$C$8*((C40*(1-'P-Parametri'!$B$19))-'P-Parametri'!$B$7))))>(IF((C40*(1-'P-Parametri'!$B$19))<='P-Parametri'!$C$12,'P-Parametri'!$B$12,IF((C40*(1-'P-Parametri'!$B$19))<='P-Parametri'!$B$6,'P-Parametri'!$B$13+'P-Parametri'!$C$13*('P-Parametri'!$B$6-(C40*(1-'P-Parametri'!$B$19)))/'P-Parametri'!$D$13,IF((C40*(1-'P-Parametri'!$B$19))<='P-Parametri'!$B$7,'P-Parametri'!$B$14*('P-Parametri'!$B$7-(C40*(1-'P-Parametri'!$B$19)))/'P-Parametri'!$C$14,0))))-'P-Parametri'!$D$16),'P-Parametri'!$B$16,0))+(IF((C40*(1-'P-Parametri'!$B$19))>'P-Parametri'!$D$18,0,IF((C40*(1-'P-Parametri'!$B$19))<='P-Parametri'!$B$18,'P-Parametri'!$B$17*(C40*(1-'P-Parametri'!$B$19)),IF((C40*(1-'P-Parametri'!$B$19))<='P-Parametri'!$C$18,'P-Parametri'!$C$17*(C40*(1-'P-Parametri'!$B$19)),'P-Parametri'!$D$17*(C40*(1-'P-Parametri'!$B$19)))))) -> 22813.596 | E40: 20000 | F40: =D40-E40 -> 2813.5957 | G40: =F40/D40 -> 0.12332978 | H40: =F40*(1+'1-Input'!$B$11)^(2025-A40) -> 3166.7267
A41: =2022 -> 2022 | B41: =28 -> 28 | C41: 30500 | D41: =(C41*(1-'P-Parametri'!$B$19))-(MAX(0,(IF((C41*(1-'P-Parametri'!$B$19))<='P-Parametri'!$B$6,'P-Parametri'!$C$6*(C41*(1-'P-Parametri'!$B$19)),IF((C41*(1-'P-Parametri'!$B$19))<='P-Parametri'!$B$7,'P-Parametri'!$B$9+'P-Parametri'!$C$7*((C41*(1-'P-Parametri'!$B$19))-'P-Parametri'!$B$6),'P-Parametri'!$B$10+'P-Parametri'!$C$8*((C41*(1-'P-Parametri'!$B$19))-'P-Parametri'!$B$7))))-(IF((C41*(1-'P-Parametri'!$B$19))<='P-Parametri'!$C$12,'P-Parametri'!$B$12,IF((C41*(1-'P-Parametri'!$B$19))<='P-Parametri'!$B$6,'P-Parametri'!$B$13+'P-Parametri'!$C$13*('P-Parametri'!$B$6-(C41*(1-'P-Parametri'!$B$19)))/'P-Parametri'!$D$13,IF((C41*(1-'P-Parametri'!$B$19))<='P-Parametri'!$B$7,'P-Parametri'!$B$14*('P-Parametri'!$B$7-(C41*(1-'P-Parametri'!$B$19)))/'P-Parametri'!$C$14,0))))-(IF((C41*(1-'P-Parametri'!$B$19))<='P-Parametri'!$C$15,0,IF((C41*(1-'P-Parametri'!$B$19))<='P-Parametri'!$D$15,'P-Parametri'!$B$15,IF((C41*(1-'P-Parametri'!$B$19))<'P-Parametri'!$E$15,'P-Parametri'!$B$15*('P-Parametri'!$E$15-(C41*(1-'P-Parametri'!$B$19)))/('P-Parametri'!$E$15-'P-Parametri'!$D$15),0))))))-(IF(MAX(0,(IF((C41*(1-'P-Parametri'!$B$19))<='P-Parametri'!$B$6,'P-Parametri'!$C$6*(C41*(1-'P-Parametri'!$B$19)),IF((C41*(1-'P-Parametri'!$B$19))<='P-Parametri'!$B$7,'P-Parametri'!$B$9+'P-Parametri'!$C$7*((C41*(1-'P-Parametri'!$B$19))-'P-Parametri'!$B$6),'P-Parametri'!$B$10+'P-Parametri'!$C$8*((C41*(1-'P-Parametri'!$B$19))-'P-Parametri'!$B$7))))-(IF((C41*(1-'P-Parametri'!$B$19))<='P-Parametri'!$C$12,'P-Parametri'!$B$12,IF((C41*(1-'P-Parametri'!$B$19))<='P-Parametri'!$B$6,'P-Parametri'!$B$13+'P-Parametri'!$C$13*('P-Parametri'!$B$6-(C41*(1-'P-Parametri'!$B$19)))/'P-Parametri'!$D$13,IF((C41*(1-'P-Parametri'!$B$19))<='P-Parametri'!$B$7,'P-Parametri'!$B$14*('P-Parametri'!$B$7-(C41*(1-'P-Parametri'!$B$19)))/'P-Parametri'!$C$14,0))))-(IF((C41*(1-'P-Parametri'!$B$19))<='P-Parametri'!$C$15,0,IF((C41*(1-'P-Parametri'!$B$19))<='P-Parametri'!$D$15,'P-Parametri'!$B$15,IF((C41*(1-'P-Parametri'!$B$19))<'P-Parametri'!$E$15,'P-Parametri'!$B$15*('P-Parametri'!$E$15-(C41*(1-'P-Parametri'!$B$19)))/('P-Parametri'!$E$15-'P-Parametri'!$D$15),0)))))>0,'P-Parametri'!$B$20*(C41*(1-'P-Parametri'!$B$19)),0))+(IF(AND((C41*(1-'P-Parametri'!$B$19))<='P-Parametri'!$C$16,(IF((C41*(1-'P-Parametri'!$B$19))<='P-Parametri'!$B$6,'P-Parametri'!$C$6*(C41*(1-'P-Parametri'!$B$19)),IF((C41*(1-'P-Parametri'!$B$19))<='P-Parametri'!$B$7,'P-Parametri'!$B$9+'P-Parametri'!$C$7*((C41*(1-'P-Parametri'!$B$19))-'P-Parametri'!$B$6),'P-Parametri'!$B$10+'P-Parametri'!$C$8*((C41*(1-'P-Parametri'!$B$19))-'P-Parametri'!$B$7))))>(IF((C41*(1-'P-Parametri'!$B$19))<='P-Parametri'!$C$12,'P-Parametri'!$B$12,IF((C41*(1-'P-Parametri'!$B$19))<='P-Parametri'!$B$6,'P-Parametri'!$B$13+'P-Parametri'!$C$13*('P-Parametri'!$B$6-(C41*(1-'P-Parametri'!$B$19)))/'P-Parametri'!$D$13,IF((C41*(1-'P-Parametri'!$B$19))<='P-Parametri'!$B$7,'P-Parametri'!$B$14*('P-Parametri'!$B$7-(C41*(1-'P-Parametri'!$B$19)))/'P-Parametri'!$C$14,0))))-'P-Parametri'!$D$16),'P-Parametri'!$B$16,0))+(IF((C41*(1-'P-Parametri'!$B$19))>'P-Parametri'!$D$18,0,IF((C41*(1-'P-Parametri'!$B$19))<='P-Parametri'!$B$18,'P-Parametri'!$B$17*(C41*(1-'P-Parametri'!$B$19)),IF((C41*(1-'P-Parametri'!$B$19))<='P-Parametri'!$C$18,'P-Parametri'!$C$17*(C41*(1-'P-Parametri'!$B$19)),'P-Parametri'!$D$17*(C41*(1-'P-Parametri'!$B$19)))))) -> 23710.519 | E41: 20250 | F41: =D41-E41 -> 3460.5191 | G41: =F41/D41 -> 0.14594868 | H41: =F41*(1+'1-Input'!$B$11)^(2025-A41) -> 3781.4026
A42: =2023 -> 2023 | B42: =29 -> 29 | C42: 32000 | D42: =(C42*(1-'P-Parametri'!$B$19))-(MAX(0,(IF((C42*(1-'P-Parametri'!$B$19))<='P-Parametri'!$B$6,'P-Parametri'!$C$6*(C42*(1-'P-Parametri'!$B$19)),IF((C42*(1-'P-Parametri'!$B$19))<='P-Parametri'!$B$7,'P-Parametri'!$B$9+'P-Parametri'!$C$7*((C42*(1-'P-Parametri'!$B$19))-'P-Parametri'!$B$6),'P-Parametri'!$B$10+'P-Parametri'!$C$8*((C42*(1-'P-Parametri'!$B$19))-'P-Parametri'!$B$7))))-(IF((C42*(1-'P-Parametri'!$B$19))<='P-Parametri'!$C$12,'P-Parametri'!$B$12,IF((C42*(1-'P-Parametri'!$B$19))<='P-Parametri'!$B$6,'P-Parametri'!$B$13+'P-Parametri'!$C$13*('P-Parametri'!$B$6-(C42*(1-'P-Parametri'!$B$19)))/'P-Parametri'!$D$13,IF((C42*(1-'P-Parametri'!$B$19))<='P-Parametri'!$B$7,'P-Parametri'!$B$14*('P-Parametri'!$B$7-(C42*(1-'P-Parametri'!$B$19)))/'P-Parametri'!$C$14,0))))-(IF((C42*(1-'P-Parametri'!$B$19))<='P-Parametri'!$C$15,0,IF((C42*(1-'P-Parametri'!$B$19))<='P-Parametri'!$D$15,'P-Parametri'!$B$15,IF((C42*(1-'P-Parametri'!$B$19))<'P-Parametri'!$E$15,'P-Parametri'!$B$15*('P-Parametri'!$E$15-(C42*(1-'P-Parametri'!$B$19)))/('P-Parametri'!$E$15-'P-Parametri'!$D$15),0))))))-(IF(MAX(0,(IF((C42*(1-'P-Parametri'!$B$19))<='P-Parametri'!$B$6,'P-Parametri'!$C$6*(C42*(1-'P-Parametri'!$B$19)),IF((C42*(1-'P-Parametri'!$B$19))<='P-Parametri'!$B$7,'P-Parametri'!$B$9+'P-Parametri'!$C$7*((C42*(1-'P-Parametri'!$B$19))-'P-Parametri'!$B$6),'P-Parametri'!$B$10+'P-Parametri'!$C$8*((C42*(1-'P-Parametri'!$B$19))-'P-Parametri'!$B$7))))-(IF((C42*(1-'P-Parametri'!$B$19))<='P-Parametri'!$C$12,'P-Parametri'!$B$12,IF((C42*(1-'P-Parametri'!$B$19))<='P-Parametri'!$B$6,'P-Parametri'!$B$13+'P-Parametri'!$C$13*('P-Parametri'!$B$6-(C42*(1-'P-Parametri'!$B$19)))/'P-Parametri'!$D$13,IF((C42*(1-'P-Parametri'!$B$19))<='P-Parametri'!$B$7,'P-Parametri'!$B$14*('P-Parametri'!$B$7-(C42*(1-'P-Parametri'!$B$19)))/'P-Parametri'!$C$14,0))))-(IF((C42*(1-'P-Parametri'!$B$19))<='P-Parametri'!$C$15,0,IF((C42*(1-'P-Parametri'!$B$19))<='P-Parametri'!$D$15,'P-Parametri'!$B$15,IF((C42*(1-'P-Parametri'!$B$19))<'P-Parametri'!$E$15,'P-Parametri'!$B$15*('P-Parametri'!$E$15-(C42*(1-'P-Parametri'!$B$19)))/('P-Parametri'!$E$15-'P-Parametri'!$D$15),0)))))>0,'P-Parametri'!$B$20*(C42*(1-'P-Parametri'!$B$19)),0))+(IF(AND((C42*(1-'P-Parametri'!$B$19))<='P-Parametri'!$C$16,(IF((C42*(1-'P-Parametri'!$B$19))<='P-Parametri'!$B$6,'P-Parametri'!$C$6*(C42*(1-'P-Parametri'!$B$19)),IF((C42*(1-'P-Parametri'!$B$19))<='P-Parametri'!$B$7,'P-Parametri'!$B$9+'P-Parametri'!$C$7*((C42*(1-'P-Parametri'!$B$19))-'P-Parametri'!$B$6),'P-Parametri'!$B$10+'P-Parametri'!$C$8*((C42*(1-'P-Parametri'!$B$19))-'P-Parametri'!$B$7))))>(IF((C42*(1-'P-Parametri'!$B$19))<='P-Parametri'!$C$12,'P-Parametri'!$B$12,IF((C42*(1-'P-Parametri'!$B$19))<='P-Parametri'!$B$6,'P-Parametri'!$B$13+'P-Parametri'!$C$13*('P-Parametri'!$B$6-(C42*(1-'P-Parametri'!$B$19)))/'P-Parametri'!$D$13,IF((C42*(1-'P-Parametri'!$B$19))<='P-Parametri'!$B$7,'P-Parametri'!$B$14*('P-Parametri'!$B$7-(C42*(1-'P-Parametri'!$B$19)))/'P-Parametri'!$C$14,0))))-'P-Parametri'!$D$16),'P-Parametri'!$B$16,0))+(IF((C42*(1-'P-Parametri'!$B$19))>'P-Parametri'!$D$18,0,IF((C42*(1-'P-Parametri'!$B$19))<='P-Parametri'!$B$18,'P-Parametri'!$B$17*(C42*(1-'P-Parametri'!$B$19)),IF((C42*(1-'P-Parametri'!$B$19))<='P-Parametri'!$C$18,'P-Parametri'!$C$17*(C42*(1-'P-Parametri'!$B$19)),'P-Parametri'!$D$17*(C42*(1-'P-Parametri'!$B$19)))))) -> 24506.522 | E42: 20500 | F42: =D42-E42 -> 4006.5222 | G42: =F42/D42 -> 0.163488 | H42: =F42*(1+'1-Input'!$B$11)^(2025-A42) -> 4250.5194
A43: =2024 -> 2024 | B43: =30 -> 30 | C43: 34000 | D43: =(C43*(1-'P-Parametri'!$B$19))-(MAX(0,(IF((C43*(1-'P-Parametri'!$B$19))<='P-Parametri'!$B$6,'P-Parametri'!$C$6*(C43*(1-'P-Parametri'!$B$19)),IF((C43*(1-'P-Parametri'!$B$19))<='P-Parametri'!$B$7,'P-Parametri'!$B$9+'P-Parametri'!$C$7*((C43*(1-'P-Parametri'!$B$19))-'P-Parametri'!$B$6),'P-Parametri'!$B$10+'P-Parametri'!$C$8*((C43*(1-'P-Parametri'!$B$19))-'P-Parametri'!$B$7))))-(IF((C43*(1-'P-Parametri'!$B$19))<='P-Parametri'!$C$12,'P-Parametri'!$B$12,IF((C43*(1-'P-Parametri'!$B$19))<='P-Parametri'!$B$6,'P-Parametri'!$B$13+'P-Parametri'!$C$13*('P-Parametri'!$B$6-(C43*(1-'P-Parametri'!$B$19)))/'P-Parametri'!$D$13,IF((C43*(1-'P-Parametri'!$B$19))<='P-Parametri'!$B$7,'P-Parametri'!$B$14*('P-Parametri'!$B$7-(C43*(1-'P-Parametri'!$B$19)))/'P-Parametri'!$C$14,0))))-(IF((C43*(1-'P-Parametri'!$B$19))<='P-Parametri'!$C$15,0,IF((C43*(1-'P-Parametri'!$B$19))<='P-Parametri'!$D$15,'P-Parametri'!$B$15,IF((C43*(1-'P-Parametri'!$B$19))<'P-Parametri'!$E$15,'P-Parametri'!$B$15*('P-Parametri'!$E$15-(C43*(1-'P-Parametri'!$B$19)))/('P-Parametri'!$E$15-'P-Parametri'!$D$15),0))))))-(IF(MAX(0,(IF((C43*(1-'P-Parametri'!$B$19))<='P-Parametri'!$B$6,'P-Parametri'!$C$6*(C43*(1-'P-Parametri'!$B$19)),IF((C43*(1-'P-Parametri'!$B$19))<='P-Parametri'!$B$7,'P-Parametri'!$B$9+'P-Parametri'!$C$7*((C43*(1-'P-Parametri'!$B$19))-'P-Parametri'!$B$6),'P-Parametri'!$B$10+'P-Parametri'!$C$8*((C43*(1-'P-Parametri'!$B$19))-'P-Parametri'!$B$7))))-(IF((C43*(1-'P-Parametri'!$B$19))<='P-Parametri'!$C$12,'P-Parametri'!$B$12,IF((C43*(1-'P-Parametri'!$B$19))<='P-Parametri'!$B$6,'P-Parametri'!$B$13+'P-Parametri'!$C$13*('P-Parametri'!$B$6-(C43*(1-'P-Parametri'!$B$19)))/'P-Parametri'!$D$13,IF((C43*(1-'P-Parametri'!$B$19))<='P-Parametri'!$B$7,'P-Parametri'!$B$14*('P-Parametri'!$B$7-(C43*(1-'P-Parametri'!$B$19)))/'P-Parametri'!$C$14,0))))-(IF((C43*(1-'P-Parametri'!$B$19))<='P-Parametri'!$C$15,0,IF((C43*(1-'P-Parametri'!$B$19))<='P-Parametri'!$D$15,'P-Parametri'!$B$15,IF((C43*(1-'P-Parametri'!$B$19))<'P-Parametri'!$E$15,'P-Parametri'!$B$15*('P-Parametri'!$E$15-(C43*(1-'P-Parametri'!$B$19)))/('P-Parametri'!$E$15-'P-Parametri'!$D$15),0)))))>0,'P-Parametri'!$B$20*(C43*(1-'P-Parametri'!$B$19)),0))+(IF(AND((C43*(1-'P-Parametri'!$B$19))<='P-Parametri'!$C$16,(IF((C43*(1-'P-Parametri'!$B$19))<='P-Parametri'!$B$6,'P-Parametri'!$C$6*(C43*(1-'P-Parametri'!$B$19)),IF((C43*(1-'P-Parametri'!$B$19))<='P-Parametri'!$B$7,'P-Parametri'!$B$9+'P-Parametri'!$C$7*((C43*(1-'P-Parametri'!$B$19))-'P-Parametri'!$B$6),'P-Parametri'!$B$10+'P-Parametri'!$C$8*((C43*(1-'P-Parametri'!$B$19))-'P-Parametri'!$B$7))))>(IF((C43*(1-'P-Parametri'!$B$19))<='P-Parametri'!$C$12,'P-Parametri'!$B$12,IF((C43*(1-'P-Parametri'!$B$19))<='P-Parametri'!$B$6,'P-Parametri'!$B$13+'P-Parametri'!$C$13*('P-Parametri'!$B$6-(C43*(1-'P-Parametri'!$B$19)))/'P-Parametri'!$D$13,IF((C43*(1-'P-Parametri'!$B$19))<='P-Parametri'!$B$7,'P-Parametri'!$B$14*('P-Parametri'!$B$7-(C43*(1-'P-Parametri'!$B$19)))/'P-Parametri'!$C$14,0))))-'P-Parametri'!$D$16),'P-Parametri'!$B$16,0))+(IF((C43*(1-'P-Parametri'!$B$19))>'P-Parametri'!$D$18,0,IF((C43*(1-'P-Parametri'!$B$19))<='P-Parametri'!$B$18,'P-Parametri'!$B$17*(C43*(1-'P-Parametri'!$B$19)),IF((C43*(1-'P-Parametri'!$B$19))<='P-Parametri'!$C$18,'P-Parametri'!$C$17*(C43*(1-'P-Parametri'!$B$19)),'P-Parametri'!$D$17*(C43*(1-'P-Parametri'!$B$19)))))) -> 25529.373 | E43: 20750 | F43: =D43-E43 -> 4779.373 | G43: =F43/D43 -> 0.18721075 | H43: =F43*(1+'1-Input'!$B$11)^(2025-A43) -> 4922.7542
...

Sheet 2-Busta-paga
A1: 2 — Busta paga 2026: il motore fiscale, riga per riga
A2: Strumento informativo / divulgativo. NON è consulenza finanziaria. I valori sono indicativi al 2026 e vanno verificati col tuo consulente.
A3: Dipendente privato, nessun carico familiare, anno intero. Otto passi, ognuno in una colonna: contributi 9,19% → reddito complessivo → IRPEF lorda a scaglioni → detrazione da lavoro (art. 13 c. 1 TUIR) → ulteriore detrazione (L. 207/2024 c. 6) → somma sul cuneo (c. 4) → trattamento integrativo (D.L. 3/2020) → addizionali. Zero costanti nelle celle: tutto viene da P-Parametri.
A4: DUE MARGINALI, E NON SONO LA STESSA COSA. La colonna «marginale su +1.000 €» è la differenza fra due righe del motore completo: è quello che sente in busta chi prende mille euro in più. La colonna «marginale di banda» è la derivata analitica dentro la fascia. Coincidono ovunque tranne dove un incremento di mille euro ATTRAVERSA una soglia: lì l'osservata è una media pesata delle due fasce. Esempio: a RAL 55.000 la banda dà 48,86% ma la marginale su +1.000 € è 49,98%, perché l'incremento entra nel terzo scaglione. Il numero che va a video per il confronto con il 60,21% è 49,98%.
A7: RAL | B7: Contributi | C7: Reddito compl. | D7: IRPEF lorda | E7: Detr. lavoro | F7: Ulteriore detr. | G7: Somma cuneo | H7: Tratt. integr. | I7: IRPEF netta | J7: Addizionali | K7: NETTO | L7: Netto / RAL | M7: Marg. su +1.000 € | N7: Marg. di banda | O7: Scarto
A8: =15000 -> 15000 | B8: ='P-Parametri'!$B$19*$A8 -> 1378.5 | C8: =$A8-B8 -> 13621.5 | D8: =IF($C8<='P-Parametri'!$B$6,'P-Parametri'!$C$6*$C8,IF($C8<='P-Parametri'!$B$7,'P-Parametri'!$B$9+'P-Parametri'!$C$7*($C8-'P-Parametri'!$B$6),'P-Parametri'!$B$10+'P-Parametri'!$C$8*($C8-'P-Parametri'!$B$7))) -> 3132.945 | E8: =IF($C8<='P-Parametri'!$C$12,'P-Parametri'!$B$12,IF($C8<='P-Parametri'!$B$6,'P-Parametri'!$B$13+'P-Parametri'!$C$13*('P-Parametri'!$B$6-$C8)/'P-Parametri'!$D$13,IF($C8<='P-Parametri'!$B$7,'P-Parametri'!$B$14*('P-Parametri'!$B$7-$C8)/'P-Parametri'!$C$14,0))) -> 1955 | F8: =IF($C8<='P-Parametri'!$C$15,0,IF($C8<='P-Parametri'!$D$15,'P-Parametri'!$B$15,IF($C8<'P-Parametri'!$E$15,'P-Parametri'!$B$15*('P-Parametri'!$E$15-$C8)/('P-Parametri'!$E$15-'P-Parametri'!$D$15),0))) -> 1000 | G8: =IF($C8>'P-Parametri'!$D$18,0,IF($C8<='P-Parametri'!$B$18,'P-Parametri'!$B$17*$C8,IF($C8<='P-Parametri'!$C$18,'P-Parametri'!$C$17*$C8,'P-Parametri'!$D$17*$C8))) -> 721.9395 | H8: =IF(AND($C8<='P-Parametri'!$C$16,D8>E8-'P-Parametri'!$D$16),'P-Parametri'!$B$16,0) -> 1200 | I8: =MAX(0,D8-E8-F8) -> 177.945 | J8: =IF(I8>0,'P-Parametri'!$B$20*$C8,0) -> 272.43 | K8: =$C8-I8-J8+H8+G8 -> 15093.065 | L8: =K8/$A8 -> 1.0062043 | M8: =1-(K10-K8)/1000 -> 0.2707957 | N8: ='P-Parametri'!$B$19+(1-'P-Parametri'!$B$19)*((IF(($A8*(1-'P-Parametri'!$B$19))<='P-Parametri'!$B$6,'P-Parametri'!$C$6,IF(($A8*(1-'P-Parametri'!$B$19))<='P-Parametri'!$B$7,'P-Parametri'!$C$7,'P-Parametri'!$C$8)))+(IF(($A8*(1-'P-Parametri'!$B$19))<='P-Parametri'!$C$12,0,IF(($A8*(1-'P-Parametri'!$B$19))<='P-Parametri'!$B$6,'P-Parametri'!$C$13/'P-Parametri'!$D$13,IF(($A8*(1-'P-Parametri'!$B$19))<='P-Parametri'!$B$7,'P-Parametri'!$B$14/'P-Parametri'!$C$14,0))))+(IF(AND(($A8*(1-'P-Parametri'!$B$19))>'P-Parametri'!$D$15,($A8*(1-'P-Parametri'!$B$19))<'P-Parametri'!$E$15),'P-Parametri'!$B$15/('P-Parametri'!$E$15-'P-Parametri'!$D$15),0))+'P-Parametri'!$B$20) -> 0.318925 | O8: =M8-N8 -> -0.0481293
A9: =15500 -> 15500 | B9: ='P-Parametri'!$B$19*$A9 -> 1424.45 | C9: =$A9-B9 -> 14075.55 | D9: =IF($C9<='P-Parametri'!$B$6,'P-Parametri'!$C$6*$C9,IF($C9<='P-Parametri'!$B$7,'P-Parametri'!$B$9+'P-Parametri'!$C$7*($C9-'P-Parametri'!$B$6),'P-Parametri'!$B$10+'P-Parametri'!$C$8*($C9-'P-Parametri'!$B$7))) -> 3237.3765 | E9: =IF($C9<='P-Parametri'!$C$12,'P-Parametri'!$B$12,IF($C9<='P-Parametri'!$B$6,'P-Parametri'!$B$13+'P-Parametri'!$C$13*('P-Parametri'!$B$6-$C9)/'P-Parametri'!$D$13,IF($C9<='P-Parametri'!$B$7,'P-Parametri'!$B$14*('P-Parametri'!$B$7-$C9)/'P-Parametri'!$C$14,0))) -> 1955 | F9: =IF($C9<='P-Parametri'!$C$15,0,IF($C9<='P-Parametri'!$D$15,'P-Parametri'!$B$15,IF($C9<'P-Parametri'!$E$15,'P-Parametri'!$B$15*('P-Parametri'!$E$15-$C9)/('P-Parametri'!$E$15-'P-Parametri'!$D$15),0))) -> 1000 | G9: =IF($C9>'P-Parametri'!$D$18,0,IF($C9<='P-Parametri'!$B$18,'P-Parametri'!$B$17*$C9,IF($C9<='P-Parametri'!$C$18,'P-Parametri'!$C$17*$C9,'P-Parametri'!$D$17*$C9))) -> 746.00415 | H9: =IF(AND($C9<='P-Parametri'!$C$16,D9>E9-'P-Parametri'!$D$16),'P-Parametri'!$B$16,0) -> 1200 | I9: =MAX(0,D9-E9-F9) -> 282.3765 | J9: =IF(I9>0,'P-Parametri'!$B$20*$C9,0) -> 281.511 | K9: =$C9-I9-J9+H9+G9 -> 15457.667 | L9: =K9/$A9 -> 0.99726882 | M9: =1-(K11-K9)/1000 -> 0.2707957 | N9: ='P-Parametri'!$B$19+(1-'P-Parametri'!$B$19)*((IF(($A9*(1-'P-Parametri'!$B$19))<='P-Parametri'!$B$6,'P-Parametri'!$C$6,IF(($A9*(1-'P-Parametri'!$B$19))<='P-Parametri'!$B$7,'P-Parametri'!$C$7,'P-Parametri'!$C$8)))+(IF(($A9*(1-'P-Parametri'!$B$19))<='P-Parametri'!$C$12,0,IF(($A9*(1-'P-Parametri'!$B$19))<='P-Parametri'!$B$6,'P-Parametri'!$C$13/'P-Parametri'!$D$13,IF(($A9*(1-'P-Parametri'!$B$19))<='P-Parametri'!$B$7,'P-Parametri'!$B$14/'P-Parametri'!$C$14,0))))+(IF(AND(($A9*(1-'P-Parametri'!$B$19))>'P-Parametri'!$D$15,($A9*(1-'P-Parametri'!$B$19))<'P-Parametri'!$E$15),'P-Parametri'!$B$15/('P-Parametri'!$E$15-'P-Parametri'!$D$15),0))+'P-Parametri'!$B$20) -> 0.318925 | O9: =M9-N9 -> -0.0481293
A10: =16000 -> 16000 | B10: ='P-Parametri'!$B$19*$A10 -> 1470.4 | C10: =$A10-B10 -> 14529.6 | D10: =IF($C10<='P-Parametri'!$B$6,'P-Parametri'!$C$6*$C10,IF($C10<='P-Parametri'!$B$7,'P-Parametri'!$B$9+'P-Parametri'!$C$7*($C10-'P-Parametri'!$B$6),'P-Parametri'!$B$10+'P-Parametri'!$C$8*($C10-'P-Parametri'!$B$7))) -> 3341.808 | E10: =IF($C10<='P-Parametri'!$C$12,'P-Parametri'!$B$12,IF($C10<='P-Parametri'!$B$6,'P-Parametri'!$B$13+'P-Parametri'!$C$13*('P-Parametri'!$B$6-$C10)/'P-Parametri'!$D$13,IF($C10<='P-Parametri'!$B$7,'P-Parametri'!$B$14*('P-Parametri'!$B$7-$C10)/'P-Parametri'!$C$14,0))) -> 1955 | F10: =IF($C10<='P-Parametri'!$C$15,0,IF($C10<='P-Parametri'!$D$15,'P-Parametri'!$B$15,IF($C10<'P-Parametri'!$E$15,'P-Parametri'!$B$15*('P-Parametri'!$E$15-$C10)/('P-Parametri'!$E$15-'P-Parametri'!$D$15),0))) -> 1000 | G10: =IF($C10>'P-Parametri'!$D$18,0,IF($C10<='P-Parametri'!$B$18,'P-Parametri'!$B$17*$C10,IF($C10<='P-Parametri'!$C$18,'P-Parametri'!$C$17*$C10,'P-Parametri'!$D$17*$C10))) -> 770.0688 | H10: =IF(AND($C10<='P-Parametri'!$C$16,D10>E10-'P-Parametri'!$D$16),'P-Parametri'!$B$16,0) -> 1200 | I10: =MAX(0,D10-E10-F10) -> 386.808 | J10: =IF(I10>0,'P-Parametri'!$B$20*$C10,0) -> 290.592 | K10: =$C10-I10-J10+H10+G10 -> 15822.269 | L10: =K10/$A10 -> 0.9888918 | M10: =1-(K12-K10)/1000 -> 0.6435592 | N10: ='P-Parametri'!$B$19+(1-'P-Parametri'!$B$19)*((IF(($A10*(1-'P-Parametri'!$B$19))<='P-Parametri'!$B$6,'P-Parametri'!$C$6,IF(($A10*(1-'P-Parametri'!$B$19))<='P-Parametri'!$B$7,'P-Parametri'!$C$7,'P-Parametri'!$C$8)))+(IF(($A10*(1-'P-Parametri'!$B$19))<='P-Parametri'!$C$12,0,IF(($A10*(1-'P-Parametri'!$B$19))<='P-Parametri'!$B$6,'P-Parametri'!$C$13/'P-Parametri'!$D$13,IF(($A10*(1-'P-Parametri'!$B$19))<='P-Parametri'!$B$7,'P-Parametri'!$B$14/'P-Parametri'!$C$14,0))))+(IF(AND(($A10*(1-'P-Parametri'!$B$19))>'P-Parametri'!$D$15,($A10*(1-'P-Parametri'!$B$19))<'P-Parametri'!$E$15),'P-Parametri'!$B$15/('P-Parametri'!$E$15-'P-Parametri'!$D$15),0))+'P-Parametri'!$B$20) -> 0.318925 | O10: =M10-N10 -> 0.3246342
A11: =16500 -> 16500 | B11: ='P-Parametri'!$B$19*$A11 -> 1516.35 | C11: =$A11-B11 -> 14983.65 | D11: =IF($C11<='P-Parametri'!$B$6,'P-Parametri'!$C$6*$C11,IF($C11<='P-Parametri'!$B$7,'P-Parametri'!$B$9+'P-Parametri'!$C$7*($C11-'P-Parametri'!$B$6),'P-Parametri'!$B$10+'P-Parametri'!$C$8*($C11-'P-Parametri'!$B$7))) -> 3446.2395 | E11: =IF($C11<='P-Parametri'!$C$12,'P-Parametri'!$B$12,IF($C11<='P-Parametri'!$B$6,'P-Parametri'!$B$13+'P-Parametri'!$C$13*('P-Parametri'!$B$6-$C11)/'P-Parametri'!$D$13,IF($C11<='P-Parametri'!$B$7,'P-Parametri'!$B$14*('P-Parametri'!$B$7-$C11)/'P-Parametri'!$C$14,0))) -> 1955 | F11: =IF($C11<='P-Parametri'!$C$15,0,IF($C11<='P-Parametri'!$D$15,'P-Parametri'!$B$15,IF($C11<'P-Parametri'!$E$15,'P-Parametri'!$B$15*('P-Parametri'!$E$15-$C11)/('P-Parametri'!$E$15-'P-Parametri'!$D$15),0))) -> 1000 | G11: =IF($C11>'P-Parametri'!$D$18,0,IF($C11<='P-Parametri'!$B$18,'P-Parametri'!$B$17*$C11,IF($C11<='P-Parametri'!$C$18,'P-Parametri'!$C$17*$C11,'P-Parametri'!$D$17*$C11))) -> 794.13345 | H11: =IF(AND($C11<='P-Parametri'!$C$16,D11>E11-'P-Parametri'!$D$16),'P-Parametri'!$B$16,0) -> 1200 | I11: =MAX(0,D11-E11-F11) -> 491.2395 | J11: =IF(I11>0,'P-Parametri'!$B$20*$C11,0) -> 299.673 | K11: =$C11-I11-J11+H11+G11 -> 16186.871 | L11: =K11/$A11 -> 0.98102248 | M11: =1-(K13-K11)/1000 -> 0.53231695 | N11: ='P-Parametri'!$B$19+(1-'P-Parametri'!$B$19)*((IF(($A11*(1-'P-Parametri'!$B$19))<='P-Parametri'!$B$6,'P-Parametri'!$C$6,IF(($A11*(1-'P-Parametri'!$B$19))<='P-Parametri'!$B$7,'P-Parametri'!$C$7,'P-Parametri'!$C$8)))+(IF(($A11*(1-'P-Parametri'!$B$19))<='P-Parametri'!$C$12,0,IF(($A11*(1-'P-Parametri'!$B$19))<='P-Parametri'!$B$6,'P-Parametri'!$C$13/'P-Parametri'!$D$13,IF(($A11*(1-'P-Parametri'!$B$19))<='P-Parametri'!$B$7,'P-Parametri'!$B$14/'P-Parametri'!$C$14,0))))+(IF(AND(($A11*(1-'P-Parametri'!$B$19))>'P-Parametri'!$D$15,($A11*(1-'P-Parametri'!$B$19))<'P-Parametri'!$E$15),'P-Parametri'!$B$15/('P-Parametri'!$E$15-'P-Parametri'!$D$15),0))+'P-Parametri'!$B$20) -> 0.318925 | O11: =M11-N11 -> 0.21339195
A12: =17000 -> 17000 | B12: ='P-Parametri'!$B$19*$A12 -> 1562.3 | C12: =$A12-B12 -> 15437.7 | D12: =IF($C12<='P-Parametri'!$B$6,'P-Parametri'!$C$6*$C12,IF($C12<='P-Parametri'!$B$7,'P-Parametri'!$B$9+'P-Parametri'!$C$7*($C12-'P-Parametri'!$B$6),'P-Parametri'!$B$10+'P-Parametri'!$C$8*($C12-'P-Parametri'!$B$7))) -> 3550.671 | E12: =IF($C12<='P-Parametri'!$C$12,'P-Parametri'!$B$12,IF($C12<='P-Parametri'!$B$6,'P-Parametri'!$B$13+'P-Parametri'!$C$13*('P-Parametri'!$B$6-$C12)/'P-Parametri'!$D$13,IF($C12<='P-Parametri'!$B$7,'P-Parametri'!$B$14*('P-Parametri'!$B$7-$C12)/'P-Parametri'!$C$14,0))) -> 3059.9336 | F12: =IF($C12<='P-Parametri'!$C$15,0,IF($C12<='P-Parametri'!$D$15,'P-Parametri'!$B$15,IF($C12<'P-Parametri'!$E$15,'P-Parametri'!$B$15*('P-Parametri'!$E$15-$C12)/('P-Parametri'!$E$15-'P-Parametri'!$D$15),0))) -> 1000 | G12: =IF($C12>'P-Parametri'!$D$18,0,IF($C12<='P-Parametri'!$B$18,'P-Parametri'!$B$17*$C12,IF($C12<='P-Parametri'!$C$18,'P-Parametri'!$C$17*$C12,'P-Parametri'!$D$17*$C12))) -> 741.0096 | H12: =IF(AND($C12<='P-Parametri'!$C$16,D12>E12-'P-Parametri'!$D$16),'P-Parametri'!$B$16,0) -> 0 | I12: =MAX(0,D12-E12-F12) -> 0 | J12: =IF(I12>0,'P-Parametri'!$B$20*$C12,0) -> 0 | K12: =$C12-I12-J12+H12+G12 -> 16178.71 | L12: =K12/$A12 -> 0.9516888 | M12: =1-(K14-K12)/1000 -> 0.0483112 | N12: ='P-Parametri'!$B$19+(1-'P-Parametri'!$B$19)*((IF(($A12*(1-'P-Parametri'!$B$19))<='P-Parametri'!$B$6,'P-Parametri'!$C$6,IF(($A12*(1-'P-Parametri'!$B$19))<='P-Parametri'!$B$7,'P-Parametri'!$C$7,'P-Parametri'!$C$8)))+(IF(($A12*(1-'P-Parametri'!$B$19))<='P-Parametri'!$C$12,0,IF(($A12*(1-'P-Parametri'!$B$19))<='P-Parametri'!$B$6,'P-Parametri'!$C$13/'P-Parametri'!$D$13,IF(($A12*(1-'P-Parametri'!$B$19))<='P-Parametri'!$B$7,'P-Parametri'!$B$14/'P-Parametri'!$C$14,0))))+(IF(AND(($A12*(1-'P-Parametri'!$B$19))>'P-Parametri'!$D$15,($A12*(1-'P-Parametri'!$B$19))<'P-Parametri'!$E$15),'P-Parametri'!$B$15/('P-Parametri'!$E$15-'P-Parametri'!$D$15),0))+'P-Parametri'!$B$20) -> 0.40205108 | O12: =M12-N12 -> -0.35373988
A13: =17500 -> 17500 | B13: ='P-Parametri'!$B$19*$A13 -> 1608.25 | C13: =$A13-B13 -> 15891.75 | D13: =IF($C13<='P-Parametri'!$B$6,'P-Parametri'!$C$6*$C13,IF($C13<='P-Parametri'!$B$7,'P-Parametri'!$B$9+'P-Parametri'!$C$7*($C13-'P-Parametri'!$B$6),'P-Parametri'!$B$10+'P-Parametri'!$C$8*($C13-'P-Parametri'!$B$7))) -> 3655.1025 | E13: =IF($C13<='P-Parametri'!$C$12,'P-Parametri'!$B$12,IF($C13<='P-Parametri'!$B$6,'P-Parametri'!$B$13+'P-Parametri'!$C$13*('P-Parametri'!$B$6-$C13)/'P-Parametri'!$D$13,IF($C13<='P-Parametri'!$B$7,'P-Parametri'!$B$14*('P-Parametri'!$B$7-$C13)/'P-Parametri'!$C$14,0))) -> 3018.3706 | F13: =IF($C13<='P-Parametri'!$C$15,0,IF($C13<='P-Parametri'!$D$15,'P-Parametri'!$B$15,IF($C13<'P-Parametri'!$E$15,'P-Parametri'!$B$15*('P-Parametri'!$E$15-$C13)/('P-Parametri'!$E$15-'P-Parametri'!$D$15),0))) -> 1000 | G13: =IF($C13>'P-Parametri'!$D$18,0,IF($C13<='P-Parametri'!$B$18,'P-Parametri'!$B$17*$C13,IF($C13<='P-Parametri'!$C$18,'P-Parametri'!$C$17*$C13,'P-Parametri'!$D$17*$C13))) -> 762.804 | H13: =IF(AND($C13<='P-Parametri'!$C$16,D13>E13-'P-Parametri'!$D$16),'P-Parametri'!$B$16,0) -> 0 | I13: =MAX(0,D13-E13-F13) -> 0 | J13: =IF(I13>0,'P-Parametri'!$B$20*$C13,0) -> 0 | K13: =$C13-I13-J13+H13+G13 -> 16654.554 | L13: =K13/$A13 -> 0.9516888 | M13: =1-(K15-K13)/1000 -> 0.0483112 | N13: ='P-Parametri'!$B$19+(1-'P-Parametri'!$B$19)*((IF(($A13*(1-'P-Parametri'!$B$19))<='P-Parametri'!$B$6,'P-Parametri'!$C$6,IF(($A13*(1-'P-Parametri'!$B$19))<='P-Parametri'!$B$7,'P-Parametri'!$C$7,'P-Parametri'!$C$8)))+(IF(($A13*(1-'P-Parametri'!$B$19))<='P-Parametri'!$C$12,0,IF(($A13*(1-'P-Parametri'!$B$19))<='P-Parametri'!$B$6,'P-Parametri'!$C$13/'P-Parametri'!$D$13,IF(($A13*(1-'P-Parametri'!$B$19))<='P-Parametri'!$B$7,'P-Parametri'!$B$14/'P-Parametri'!$C$14,0))))+(IF(AND(($A13*(1-'P-Parametri'!$B$19))>'P-Parametri'!$D$15,($A13*(1-'P-Parametri'!$B$19))<'P-Parametri'!$E$15),'P-Parametri'!$B$15/('P-Parametri'!$E$15-'P-Parametri'!$D$15),0))+'P-Parametri'!$B$20) -> 0.40205108 | O13: =M13-N13 -> -0.35373988
A14: =18000 -> 18000 | B14: ='P-Parametri'!$B$19*$A14 -> 1654.2 | C14: =$A14-B14 -> 16345.8 | D14: =IF($C14<='P-Parametri'!$B$6,'P-Parametri'!$C$6*$C14,IF($C14<='P-Parametri'!$B$7,'P-Parametri'!$B$9+'P-Parametri'!$C$7*($C14-'P-Parametri'!$B$6),'P-Parametri'!$B$10+'P-Parametri'!$C$8*($C14-'P-Parametri'!$B$7))) -> 3759.534 | E14: =IF($C14<='P-Parametri'!$C$12,'P-Parametri'!$B$12,IF($C14<='P-Parametri'!$B$6,'P-Parametri'!$B$13+'P-Parametri'!$C$13*('P-Parametri'!$B$6-$C14)/'P-Parametri'!$D$13,IF($C14<='P-Parametri'!$B$7,'P-Parametri'!$B$14*('P-Parametri'!$B$7-$C14)/'P-Parametri'!$C$14,0))) -> 2976.8075 | F14: =IF($C14<='P-Parametri'!$C$15,0,IF($C14<='P-Parametri'!$D$15,'P-Parametri'!$B$15,IF($C14<'P-Parametri'!$E$15,'P-Parametri'!$B$15*('P-Parametri'!$E$15-$C14)/('P-Parametri'!$E$15-'P-Parametri'!$D$15),0))) -> 1000 | G14: =IF($C14>'P-Parametri'!$D$18,0,IF($C14<='P-Parametri'!$B$18,'P-Parametri'!$B$17*$C14,IF($C14<='P-Parametri'!$C$18,'P-Parametri'!$C$17*$C14,'P-Parametri'!$D$17*$C14))) -> 784.5984 | H14: =IF(AND($C14<='P-Parametri'!$C$16,D14>E14-'P-Parametri'!$D$16),'P-Parametri'!$B$16,0) -> 0 | I14: =MAX(0,D14-E14-F14) -> 0 | J14: =IF(I14>0,'P-Parametri'!$B$20*$C14,0) -> 0 | K14: =$C14-I14-J14+H14+G14 -> 17130.398 | L14: =K14/$A14 -> 0.9516888 | M14: =1-(K16-K14)/1000 -> 0.46810474 | N14: ='P-Parametri'!$B$19+(1-'P-Parametri'!$B$19)*((IF(($A14*(1-'P-Parametri'!$B$19))<='P-Parametri'!$B$6,'P-Parametri'!$C$6,IF(($A14*(1-'P-Parametri'!$B$19))<='P-Parametri'!$B$7,'P-Parametri'!$C$7,'P-Parametri'!$C$8)))+(IF(($A14*(1-'P-Parametri'!$B$19))<='P-Parametri'!$C$12,0,IF(($A14*(1-'P-Parametri'!$B$19))<='P-Parametri'!$B$6,'P-Parametri'!$C$13/'P-Parametri'!$D$13,IF(($A14*(1-'P-Parametri'!$B$19))<='P-Parametri'!$B$7,'P-Parametri'!$B$14/'P-Parametri'!$C$14,0))))+(IF(AND(($A14*(1-'P-Parametri'!$B$19))>'P-Parametri'!$D$15,($A14*(1-'P-Parametri'!$B$19))<'P-Parametri'!$E$15),'P-Parametri'!$B$15/('P-Parametri'!$E$15-'P-Parametri'!$D$15),0))+'P-Parametri'!$B$20) -> 0.40205108 | O14: =M14-N14 -> 0.066053662
A15: =18500 -> 18500 | B15: ='P-Parametri'!$B$19*$A15 -> 1700.15 | C15: =$A15-B15 -> 16799.85 | D15: =IF($C15<='P-Parametri'!$B$6,'P-Parametri'!$C$6*$C15,IF($C15<='P-Parametri'!$B$7,'P-Parametri'!$B$9+'P-Parametri'!$C$7*($C15-'P-Parametri'!$B$6),'P-Parametri'!$B$10+'P-Parametri'!$C$8*($C15-'P-Parametri'!$B$7))) -> 3863.9655 | E15: =IF($C15<='P-Parametri'!$C$12,'P-Parametri'!$B$12,IF($C15<='P-Parametri'!$B$6,'P-Parametri'!$B$13+'P-Parametri'!$C$13*('P-Parametri'!$B$6-$C15)/'P-Parametri'!$D$13,IF($C15<='P-Parametri'!$B$7,'P-Parametri'!$B$14*('P-Parametri'!$B$7-$C15)/'P-Parametri'!$C$14,0))) -> 2935.2445 | F15: =IF($C15<='P-Parametri'!$C$15,0,IF($C15<='P-Parametri'!$D$15,'P-Parametri'!$B$15,IF($C15<'P-Parametri'!$E$15,'P-Parametri'!$B$15*('P-Parametri'!$E$15-$C15)/('P-Parametri'!$E$15-'P-Parametri'!$D$15),0))) -> 1000 | G15: =IF($C15>'P-Parametri'!$D$18,0,IF($C15<='P-Parametri'!$B$18,'P-Parametri'!$B$17*$C15,IF($C15<='P-Parametri'!$C$18,'P-Parametri'!$C$17*$C15,'P-Parametri'!$D$17*$C15))) -> 806.3928 | H15: =IF(AND($C15<='P-Parametri'!$C$16,D15>E15-'P-Parametri'!$D$16),'P-Parametri'!$B$16,0) -> 0 | I15: =MAX(0,D15-E15-F15) -> 0 | J15: =IF(I15>0,'P-Parametri'!$B$20*$C15,0) -> 0 | K15: =$C15-I15-J15+H15+G15 -> 17606.243 | L15: =K15/$A15 -> 0.9516888 | M15: =1-(K17-K15)/1000 -> 0.62318028 | N15: ='P-Parametri'!$B$19+(1-'P-Parametri'!$B$19)*((IF(($A15*(1-'P-Parametri'!$B$19))<='P-Parametri'!$B$6,'P-Parametri'!$C$6,IF(($A15*(1-'P-Parametri'!$B$19))<='P-Parametri'!$B$7,'P-Parametri'!$C$7,'P-Parametri'!$C$8)))+(IF(($A15*(1-'P-Parametri'!$B$19))<='P-Parametri'!$C$12,0,IF(($A15*(1-'P-Parametri'!$B$19))<='P-Parametri'!$B$6,'P-Parametri'!$C$13/'P-Parametri'!$D$13,IF(($A15*(1-'P-Parametri'!$B$19))<='P-Parametri'!$B$7,'P-Parametri'!$B$14/'P-Parametri'!$C$14,0))))+(IF(AND(($A15*(1-'P-Parametri'!$B$19))>'P-Parametri'!$D$15,($A15*(1-'P-Parametri'!$B$19))<'P-Parametri'!$E$15),'P-Parametri'!$B$15/('P-Parametri'!$E$15-'P-Parametri'!$D$15),0))+'P-Parametri'!$B$20) -> 0.40205108 | O15: =M15-N15 -> 0.2211292
A16: =19000 -> 19000 | B16: ='P-Parametri'!$B$19*$A16 -> 1746.1 | C16: =$A16-B16 -> 17253.9 | D16: =IF($C16<='P-Parametri'!$B$6,'P-Parametri'!$C$6*$C16,IF($C16<='P-Parametri'!$B$7,'P-Parametri'!$B$9+'P-Parametri'!$C$7*($C16-'P-Parametri'!$B$6),'P-Parametri'!$B$10+'P-Parametri'!$C$8*($C16-'P-Parametri'!$B$7))) -> 3968.397 | E16: =IF($C16<='P-Parametri'!$C$12,'P-Parametri'!$B$12,IF($C16<='P-Parametri'!$B$6,'P-Parametri'!$B$13+'P-Parametri'!$C$13*('P-Parametri'!$B$6-$C16)/'P-Parametri'!$D$13,IF($C16<='P-Parametri'!$B$7,'P-Parametri'!$B$14*('P-Parametri'!$B$7-$C16)/'P-Parametri'!$C$14,0))) -> 2893.6815 | F16: =IF($C16<='P-Parametri'!$C$15,0,IF($C16<='P-Parametri'!$D$15,'P-Parametri'!$B$15,IF($C16<'P-Parametri'!$E$15,'P-Parametri'!$B$15*('P-Parametri'!$E$15-$C16)/('P-Parametri'!$E$15-'P-Parametri'!$D$15),0))) -> 1000 | G16: =IF($C16>'P-Parametri'!$D$18,0,IF($C16<='P-Parametri'!$B$18,'P-Parametri'!$B$17*$C16,IF($C16<='P-Parametri'!$C$18,'P-Parametri'!$C$17*$C16,'P-Parametri'!$D$17*$C16))) -> 828.1872 | H16: =IF(AND($C16<='P-Parametri'!$C$16,D16>E16-'P-Parametri'!$D$16),'P-Parametri'!$B$16,0) -> 0 | I16: =MAX(0,D16-E16-F16) -> 74.715538 | J16: =IF(I16>0,'P-Parametri'!$B$20*$C16,0) -> 345.078 | K16: =$C16-I16-J16+H16+G16 -> 17662.294 | L16: =K16/$A16 -> 0.9295944 | M16: =1-(K18-K16)/1000 -> 0.35846228 | N16: ='P-Parametri'!$B$19+(1-'P-Parametri'!$B$19)*((IF(($A16*(1-'P-Parametri'!$B$19))<='P-Parametri'!$B$6,'P-Parametri'!$C$6,IF(($A16*(1-'P-Parametri'!$B$19))<='P-Parametri'!$B$7,'P-Parametri'!$C$7,'P-Parametri'!$C$8)))+(IF(($A16*(1-'P-Parametri'!$B$19))<='P-Parametri'!$C$12,0,IF(($A16*(1-'P-Parametri'!$B$19))<='P-Parametri'!$B$6,'P-Parametri'!$C$13/'P-Parametri'!$D$13,IF(($A16*(1-'P-Parametri'!$B$19))<='P-Parametri'!$B$7,'P-Parametri'!$B$14/'P-Parametri'!$C$14,0))))+(IF(AND(($A16*(1-'P-Parametri'!$B$19))>'P-Parametri'!$D$15,($A16*(1-'P-Parametri'!$B$19))<'P-Parametri'!$E$15),'P-Parametri'!$B$15/('P-Parametri'!$E$15-'P-Parametri'!$D$15),0))+'P-Parametri'!$B$20) -> 0.40205108 | O16: =M16-N16 -> -0.0435888
A17: =19500 -> 19500 | B17: ='P-Parametri'!$B$19*$A17 -> 1792.05 | C17: =$A17-B17 -> 17707.95 | D17: =IF($C17<='P-Parametri'!$B$6,'P-Parametri'!$C$6*$C17,IF($C17<='P-Parametri'!$B$7,'P-Parametri'!$B$9+'P-Parametri'!$C$7*($C17-'P-Parametri'!$B$6),'P-Parametri'!$B$10+'P-Parametri'!$C$8*($C17-'P-Parametri'!$B$7))) -> 4072.8285 | E17: =IF($C17<='P-Parametri'!$C$12,'P-Parametri'!$B$12,IF($C17<='P-Parametri'!$B$6,'P-Parametri'!$B$13+'P-Parametri'!$C$13*('P-Parametri'!$B$6-$C17)/'P-Parametri'!$D$13,IF($C17<='P-Parametri'!$B$7,'P-Parametri'!$B$14*('P-Parametri'!$B$7-$C17)/'P-Parametri'!$C$14,0))) -> 2852.1184 | F17: =IF($C17<='P-Parametri'!$C$15,0,IF($C17<='P-Parametri'!$D$15,'P-Parametri'!$B$15,IF($C17<'P-Parametri'!$E$15,'P-Parametri'!$B$15*('P-Parametri'!$E$15-$C17)/('P-Parametri'!$E$15-'P-Parametri'!$D$15),0))) -> 1000 | G17: =IF($C17>'P-Parametri'!$D$18,0,IF($C17<='P-Parametri'!$B$18,'P-Parametri'!$B$17*$C17,IF($C17<='P-Parametri'!$C$18,'P-Parametri'!$C$17*$C17,'P-Parametri'!$D$17*$C17))) -> 849.9816 | H17: =IF(AND($C17<='P-Parametri'!$C$16,D17>E17-'P-Parametri'!$D$16),'P-Parametri'!$B$16,0) -> 0 | I17: =MAX(0,D17-E17-F17) -> 220.71008 | J17: =IF(I17>0,'P-Parametri'!$B$20*$C17,0) -> 354.159 | K17: =$C17-I17-J17+H17+G17 -> 17983.063 | L17: =K17/$A17 -> 0.92220833 | M17: =1-(K19-K17)/1000 -> 0.35846228 | N17: ='P-Parametri'!$B$19+(1-'P-Parametri'!$B$19)*((IF(($A17*(1-'P-Parametri'!$B$19))<='P-Parametri'!$B$6,'P-Parametri'!$C$6,IF(($A17*(1-'P-Parametri'!$B$19))<='P-Parametri'!$B$7,'P-Parametri'!$C$7,'P-Parametri'!$C$8)))+(IF(($A17*(1-'P-Parametri'!$B$19))<='P-Parametri'!$C$12,0,IF(($A17*(1-'P-Parametri'!$B$19))<='P-Parametri'!$B$6,'P-Parametri'!$C$13/'P-Parametri'!$D$13,IF(($A17*(1-'P-Parametri'!$B$19))<='P-Parametri'!$B$7,'P-Parametri'!$B$14/'P-Parametri'!$C$14,0))))+(IF(AND(($A17*(1-'P-Parametri'!$B$19))>'P-Parametri'!$D$15,($A17*(1-'P-Parametri'!$B$19))<'P-Parametri'!$E$15),'P-Parametri'!$B$15/('P-Parametri'!$E$15-'P-Parametri'!$D$15),0))+'P-Parametri'!$B$20) -> 0.40205108 | O17: =M17-N17 -> -0.0435888
A18: =20000 -> 20000 | B18: ='P-Parametri'!$B$19*$A18 -> 1838 | C18: =$A18-B18 -> 18162 | D18: =IF($C18<='P-Parametri'!$B$6,'P-Parametri'!$C$6*$C18,IF($C18<='P-Parametri'!$B$7,'P-Parametri'!$B$9+'P-Parametri'!$C$7*($C18-'P-Parametri'!$B$6),'P-Parametri'!$B$10+'P-Parametri'!$C$8*($C18-'P-Parametri'!$B$7))) -> 4177.26 | E18: =IF($C18<='P-Parametri'!$C$12,'P-Parametri'!$B$12,IF($C18<='P-Parametri'!$B$6,'P-Parametri'!$B$13+'P-Parametri'!$C$13*('P-Parametri'!$B$6-$C18)/'P-Parametri'!$D$13,IF($C18<='P-Parametri'!$B$7,'P-Parametri'!$B$14*('P-Parametri'!$B$7-$C18)/'P-Parametri'!$C$14,0))) -> 2810.5554 | F18: =IF($C18<='P-Parametri'!$C$15,0,IF($C18<='P-Parametri'!$D$15,'P-Parametri'!$B$15,IF($C18<'P-Parametri'!$E$15,'P-Parametri'!$B$15*('P-Parametri'!$E$15-$C18)/('P-Parametri'!$E$15-'P-Parametri'!$D$15),0))) -> 1000 | G18: =IF($C18>'P-Parametri'!$D$18,0,IF($C18<='P-Parametri'!$B$18,'P-Parametri'!$B$17*$C18,IF($C18<='P-Parametri'!$C$18,'P-Parametri'!$C$17*$C18,'P-Parametri'!$D$17*$C18))) -> 871.776 | H18: =IF(AND($C18<='P-Parametri'!$C$16,D18>E18-'P-Parametri'!$D$16),'P-Parametri'!$B$16,0) -> 0 | I18: =MAX(0,D18-E18-F18) -> 366.70462 | J18: =IF(I18>0,'P-Parametri'!$B$20*$C18,0) -> 363.24 | K18: =$C18-I18-J18+H18+G18 -> 18303.831 | L18: =K18/$A18 -> 0.91519157 | M18: =1-(K20-K18)/1000 -> 0.35846228 | N18: ='P-Parametri'!$B$19+(1-'P-Parametri'!$B$19)*((IF(($A18*(1-'P-Parametri'!$B$19))<='P-Parametri'!$B$6,'P-Parametri'!$C$6,IF(($A18*(1-'P-Parametri'!$B$19))<='P-Parametri'!$B$7,'P-Parametri'!$C$7,'P-Parametri'!$C$8)))+(IF(($A18*(1-'P-Parametri'!$B$19))<='P-Parametri'!$C$12,0,IF(($A18*(1-'P-Parametri'!$B$19))<='P-Parametri'!$B$6,'P-Parametri'!$C$13/'P-Parametri'!$D$13,IF(($A18*(1-'P-Parametri'!$B$19))<='P-Parametri'!$B$7,'P-Parametri'!$B$14/'P-Parametri'!$C$14,0))))+(IF(AND(($A18*(1-'P-Parametri'!$B$19))>'P-Parametri'!$D$15,($A18*(1-'P-Parametri'!$B$19))<'P-Parametri'!$E$15),'P-Parametri'!$B$15/('P-Parametri'!$E$15-'P-Parametri'!$D$15),0))+'P-Parametri'!$B$20) -> 0.40205108 | O18: =M18-N18 -> -0.0435888
