Workbook

Sheet 0 - Indice
A1: Marco FIRE — Non autosufficienza 2026
A2: Strumento informativo / divulgativo. NON è consulenza finanziaria. I valori sono indicativi al 2026 e vanno verificati col tuo consulente.
A4: Indice
A5: 1 - IL TUO CASO | B5: Esborso netto annuo e capitale extra necessario oggi
A6: 2 - COSTI | B6: Ore, badante convivente e RSA: da dove nasce ogni numero
A7: 3 - COPERTURE | B7: Indennita', quota sanitaria, detrazioni, deduzioni, ISEE
A8: 4 - CAPITALE EXTRA | B8: Il conto anno per anno, in valore di oggi
A9: 5 - MATRICE | B9: Durata per configurazione, e polizza vs auto-assicurazione
A11: Come usare
A12: 1. Le celle GIALLE sono input — modificale coi tuoi numeri.
A13: 2. Le celle VERDI sono output — si aggiornano automaticamente.
A14: 3. Tutti i numeri di default sono al 2026 da fonti pubbliche.
A15: 4. Niente codice nascosto: l'Excel è solo formule modificabili.
A17: Fonti dati
A18: • INPS — messaggio n. 628 del 23 febbraio 2026, che rettifica le tabelle M.1, M.2 e M.3 dell'allegato 2 alla circolare INPS n. 153 del 19 dicembre 2025: indennita' di accompagnamento 2026 pari a 551,53 euro al mese per 12 mensilita' (6.618,36 euro l'anno), senza limiti di reddito
A19: • DPCM 12 gennaio 2017 «Definizione e aggiornamento dei livelli essenziali di assistenza» (Gazzetta Ufficiale n. 65 del 18 marzo 2017, S.O. n. 15), art. 30: i trattamenti di lungoassistenza agli anziani non autosufficienti sono a carico del Servizio sanitario nazionale per una quota pari al 50% della tariffa giornaliera; i trattamenti estensivi (max 60 giorni) e quelli a elevato impegno sanitario (art. 29 c.3) sono interamente a carico del SSN
A20: • Altroconsumo — inchiesta sulle RSA pubblicata il 28 aprile 2026 su 594 famiglie: retta media 2.031 euro al mese piu' 108 euro di extra; Nord 2.306, Sud e Isole 1.630; attesa media di 115 giorni
A21: • FNP CISL Lombardia — «Non autosufficienza e RSA, Rapporto Lombardia» n. 1/2026 (dati al 31 dicembre 2025): retta media a carico della famiglia 76,02 euro al giorno, pari a 2.312 euro al mese e 27.747 euro l'anno; ATS Milano 92,52 euro al giorno; posti solventi 91,40 euro al giorno; 121.830 domande in lista d'attesa
A22: • ISTAT — «Le strutture residenziali socio-assistenziali e socio-sanitarie al 1° gennaio 2024», pubblicato il 13 gennaio 2026: 12.987 presidi, 425.780 posti letto, quasi 239.000 ospiti anziani non autosufficienti; posti letto per mille anziani residenti da 32 nel Nord-est a 6 nel Sud. L'ISTAT non rileva le rette
A23: • Cergas SDA Bocconi — Rapporto OASI 2025 cap. 5 e 8° Rapporto dell'Osservatorio Long Term Care (6 maggio 2026): 4.027.488 over 65 non autosufficienti; le RSA coprono l'8% del bisogno, l'assistenza domiciliare integrata il 31% ma con 14 ore all'anno per caso; eta' media di ingresso in RSA 83,8 anni e degenza media 340 giorni; spesa pubblica per la long term care 1,61% del PIL nel 2024, componente over 65 all'1,18% contro l'1,43% del 2020
... A32: Aggiornamenti: github.com/marcofire-it/marco-fire-simulatori

Sheet 1 - IL TUO CASO
A1: Il rischio non autosufficienza dentro il tuo piano
A2: Strumento informativo / divulgativo. NON è consulenza finanziaria. I valori sono indicativi al 2026 e vanno verificati col tuo consulente.
A4: INPUT — cambia solo le celle gialle
A5: La tua eta' oggi | B5: 60
A6: Capitale finanziario che hai oggi (€) | B6: 400000
A7: Rendimento REALE netto atteso del portafoglio (%) | B7: 0.015
A8: Eta' ipotizzata di ingresso in non autosufficienza | B8: 84
A9: Anni di assistenza ipotizzati | B9: 5
A10: Configurazione: 1 = a ore 2 = badante convivente 3 = RSA | B10: 3
A11: Area: 1 = Nord 2 = Centro 3 = Sud e Isole | B11: 1
A12: Crescita REALE annua del costo dell'assistenza (%) | B12: 0.01
A13: Aliquota marginale IRPEF di chi paga (%) | B13: 0.33
A14: Reddito complessivo di chi paga (€) | B14: 35000
A15: Le celle 10 e 11 accettano solo 1, 2 o 3. L'eta' di ingresso di default e' 84 anni: l'eta' media di ingresso in RSA rilevata dall'Osservatorio Long Term Care della Bocconi e' 83,8 anni.
A17: OUTPUT — il conto di un anno di assistenza
A18: Costo mensile della configurazione scelta | B18: =INDEX('2 - COSTI'!$B$6:$D$8,$B$10,$B$11)
A19: Costo annuo | B19: =B18*12
A20: Coperture pubbliche e fiscali (foglio 3) | B20: ='3 - COPERTURE'!$B$34
A21: ESBORSO NETTO ANNUO DELLA FAMIGLIA | B21: =MAX(0,B19-B20)
A22: Quota della spesa coperta dal pubblico e dal fisco | B22: =IFERROR(B20/B19,0)
A23: Esborso netto mensile | B23: =B21/12
A25: OUTPUT — quanto capitale in piu' serve OGGI
A26: Anni che mancano all'ingresso in non autosufficienza | B26: =MAX(0,B8-B5)
A27: CAPITALE EXTRA NECESSARIO OGGI (valore attuale) | B27: ='4 - CAPITALE EXTRA'!$B$10
A28: In percentuale sul capitale che hai oggi | B28: =IFERROR(B27/B6,0)
A29: Capitale che resta disponibile per il resto del piano | B29: =B6-B27
A30: Accantonamento mensile equivalente da qui all'ingresso | B30: =IF(B26<=0,B27,IFERROR(B27*(1+B7)^B26*((1+B7)^(1/12)-1)/((1+B7)^B26-1),0))
A32: Come leggere il risultato. Il capitale extra non e' una spesa che farai di sicuro: e' il prezzo dell'assicurazione che ti fai da solo. Non tutti entrano in non autosufficienza e non tutti per lo stesso numero di anni. Questo foglio ti dice quanto costa mettere al riparo il piano dallo scenario che lo farebbe saltare, e lascia a te la decisione su quanto di quello scenario coprire.
A33: Tutto e' in termini REALI, cioe' a valore di oggi: in B7 metti un rendimento gia' al netto di tasse e inflazione, e in B12 solo la crescita del costo dell'assistenza in ECCESSO rispetto all'inflazione. Cosi' non conti l'inflazione due volte, che e' l'errore piu' frequente in questo tipo di simulazioni.

Sheet 2 - COSTI
A1: Quanto costa l'assistenza nel 2026
A2: Strumento informativo / divulgativo. NON è consulenza finanziaria. I valori sono indicativi al 2026 e vanno verificati col tuo consulente.
A4: Riepilogo: costo mensile a carico della famiglia (€/mese)
A5: Configurazione | B5: Nord | C5: Centro | D5: Sud e Isole
A6: 1 — Assistenza a ore (non convivente) | B6: =$B$17 | C6: =$B$17 | D6: =$B$17
A7: 2 — Badante convivente (costo pieno del datore) | B7: =$B$34 | C7: =$B$34 | D7: =$B$34
A8: 3 — RSA, retta a carico dell'utente | B8: =B45 | C8: =C45 | D8: =D45
A9: Le prime due righe non cambiano con l'area perche' i minimi del contratto nazionale del lavoro domestico sono uguali in tutta Italia: quello che cambia, al Nord, sono i superminimi di mercato. La terza riga cambia molto, e la differenza fra Nord e Sud e' il dato piu' solido di tutta questa tabella.
A11: A — Assistenza a ore: da cosa nasce il costo orario
A12: Ore di assistenza alla settimana | B12: 24
A13: Minimo contrattuale C super non convivente (€/ora) | B13: 8.3
A14: Costo orario PIENO (paga + 13ª + ferie + TFR + contributi) | B14: 11.67
A15: Ore all'anno | B15: =B12*52
A16: Costo annuo | B16: =B15*B14
A17: COSTO MENSILE | B17: =B16/12
A18: Il minimo orario del contratto e' 8,30 euro per il livello C super (assistenza a persona non autosufficiente, senza formazione): il costo pieno per la famiglia arriva pero' vicino a 11,70 euro l'ora una volta aggiunti tredicesima, ferie, trattamento di fine rapporto e contributi. Sul mercato, cooperative e agenzie chiedono di piu'. Con 24 ore alla settimana si copre poco piu' di mezza giornata: e' il livello che copre il bisogno solo se in casa c'e' gia' qualcuno.
A20: B — Badante convivente: il costo pieno del datore di lavoro
A21: Minimo mensile C super convivente, tabelle 2026 (€) | B21: 1193.84
A22: Indennita' di vitto e alloggio (6,66 €/giorno x 30) | B22: 199.8
A23: Ore settimanali (massimo contrattuale del convivente: 54) | B23: 54
A24: Contributo INPS orario a carico del datore (€) | B24: 0.93
A25: Assistenza contrattuale oraria a carico del datore (€) | B25: 0.04
A26: Retribuzione globale di fatto mensile | B26: =B21+B22
A27: Dodici mensilita' | B27: =B26*12
A28: Tredicesima (art. 39: una mensilita' piena) | B28: =B26
A29: Retribuzione annua totale | B29: =B27+B28
A30: Trattamento di fine rapporto (art. 41: annuo diviso 13,5) | B30: =B29/13.5
A31: Contributi INPS a carico del datore (ore x 52 x quota) | B31: =B23*52*B24
A32: Assistenza contrattuale a carico del datore | B32: =B23*52*B25
A33: COSTO ANNUO PIENO DEL DATORE DI LAVORO | B33: =B29+B30+B31+B32
A34: COSTO MENSILE EQUIVALENTE | B34: =B33/12
A35: Attenzione a due errori opposti. Il primo e' fermarsi al minimo contrattuale: tredicesima, trattamento di fine rapporto, contributi e vitto e alloggio aggiungono circa un quarto. Il secondo e' contare le ferie come costo aggiuntivo: per il convivente mensilizzato sono gia' dentro le dodici mensilita'. Restano fuori da questo conto le sostituzioni nei giorni di riposo, che il contratto regola con una tabella dedicata: se assumi un sostituto, aggiungi la sua spesa.
A37: C — RSA: la retta che paga davvero la famiglia
A38: Voce | B38: Nord | C38: Centro | D38: Sud e Isole
A39: Retta media mensile a carico della famiglia (€) | B39: 2306 | C39: 2031 | D39: 1630
A40: Spese extra medie al mese (€) | B40: 108 | C40: 108 | D40: 108
A41: Riferimento: tariffa giornaliera piena della struttura (€) | B41: 129.72
A42: Quota a carico del Servizio sanitario nazionale (%) | B42: 0.5
A43: Quota giornaliera a carico dell'utente | B43: =B41*(1-B42)
A44: Equivalente mensile della quota utente (365/12 giorni) | B44: =B43*365/12
...

Sheet 3 - COPERTURE
A1: Cosa copre davvero il pubblico (e cosa il fisco)
A2: Strumento informativo / divulgativo. NON è consulenza finanziaria. I valori sono indicativi al 2026 e vanno verificati col tuo consulente.
A4: 1 — Indennita' di accompagnamento
A5: Importo mensile 2026 (€) | B5: 551.53
A6: Mensilita' (non e' prevista la tredicesima) | B6: 12
A7: Ne hai diritto? 1 = si', 0 = no | B7: 1
A8: TOTALE ANNUO | B8: =B5*B6*B7
A9: Spetta a chi e' riconosciuto invalido civile totale con necessita' di assistenza continua. Non ha limiti di reddito, non e' tassata e non dipende dall'eta', ma non prevede la tredicesima. L'importo 2026 e' quello fissato dall'INPS con il messaggio n. 628 del 23 febbraio 2026, che ha rettificato le tabelle allegate alla circolare n. 153 del 19 dicembre 2025.
A11: 2 — Quota sanitaria in RSA accreditata
A12: Si applica? (1 solo se hai scelto la RSA) | B12: =IF('1 - IL TUO CASO'!$B$10=3,1,0)
A13: Quota a carico del Servizio sanitario nazionale (%) | B13: ='2 - COSTI'!$B$42
A14: Nel foglio 2 la retta della RSA e' gia' inserita come importo a carico della famiglia: la quota sanitaria e' quindi gia' scontata a monte e qui non viene sottratta una seconda volta, altrimenti la conteresti due volte. Questa riga serve a ricordare quanto vale la copertura pubblica e che in una struttura non accreditata semplicemente non c'e'.
A16: 3 — Agevolazioni fiscali
A17: Spesa annua per addetti all'assistenza personale (€) | B17: =IF('1 - IL TUO CASO'!$B$10=3,0,'1 - IL TUO CASO'!$B$19)
A18: Tetto di spesa detraibile (€) | B18: 2100
A19: Aliquota della detrazione (%) | B19: 0.19
A20: Limite di reddito complessivo oltre il quale si azzera (€) | B20: 40000
A21: DETRAZIONE 19% ADDETTI ALL'ASSISTENZA | B21: =IF('1 - IL TUO CASO'!$B$14>B20,0,MIN(B17,B18)*B19)
A22: Contributi previdenziali versati per la badante (€) | B22: =IF('1 - IL TUO CASO'!$B$10=2,'2 - COSTI'!$B$31,0)
A23: Tetto deducibile dei contributi (€) | B23: 1549.37
A24: RISPARMIO DALLA DEDUZIONE DEI CONTRIBUTI | B24: =MIN(B22,B23)*'1 - IL TUO CASO'!$B$13
A25: Spese di assistenza specifica deducibili al 100% (€) | B25: 0
A26: RISPARMIO DALLA DEDUZIONE INTEGRALE | B26: =B25*'1 - IL TUO CASO'!$B$13
A27: Tre cose che quasi tutti sbagliano. Primo: la detrazione del 19% sugli addetti all'assistenza vale su un massimo di 2.100 euro di spesa, quindi al piu' 399 euro di imposta risparmiata, e sopra 40.000 euro di reddito complessivo non si riduce, si azzera. Secondo: quel tetto e' per contribuente, non per persona assistita. Terzo: della retta di una struttura si deduce solo la parte medica e di assistenza specifica, e solo se l'istituto la indica distintamente nella documentazione; non esiste una percentuale forfetaria valida in tutta Italia. La deduzione dei contributi previdenziali di colf e badanti arriva a 1.549,37 euro, riguarda solo la quota a carico del datore e vale l'aliquota marginale.
A29: 4 — Prestazione universale (per pochissimi)
A30: Hai TUTTI i requisiti? 1 = si', 0 = no | B30: 0
A31: Quota integrativa mensile (€) | B31: 850
A32: Quota integrativa annua | B32: =B30*B31*12
A33: E' la misura sperimentale prevista dal decreto legislativo 29 del 2024 per il biennio 2025-2026: servono almeno ottant'anni, un bisogno assistenziale gravissimo, l'indennita' di accompagnamento e un indicatore della situazione economica equivalente sociosanitario non superiore a 6.000 euro. Chi apre questo foglio per pianificare un patrimonio quasi certamente non ne avra' diritto: lascia zero. La quota integrativa e' inoltre vincolata a pagare lavoro di cura regolare o servizi qualificati, non e' denaro libero.
A34: TOTALE COPERTURE ANNUE | B34: =B8+B21+B24+B26+B32
A36: 5 — Promemoria ISEE (non entra nel calcolo)
A37: Se chiedi al Comune l'integrazione della retta, l'indicatore che conta e' quello socio-sanitario per le prestazioni residenziali a ciclo continuativo, regolato dall'articolo 6 comma 3 del decreto del Presidente del Consiglio 159 del 2013. Tre regole rendono quel calcolo piu' severo di quello ordinario: la retta pagata non si porta in detrazione dall'indicatore; per ogni figlio fuori dal nucleo si aggiunge una componente calcolata sulla sua situazione economica; le donazioni fatte dopo la domanda, e quelle dei tre anni precedenti verso chi e' tenuto agli alimenti, restano nel patrimonio di chi le ha fatte.
A38: Due aggiornamenti da tenere distinti. Il primo vale anche qui: dal marzo 2025, per effetto del decreto del Presidente del Consiglio 13 del 2025, titoli di Stato, buoni fruttiferi postali e libretti postali sono esclusi dal patrimonio mobiliare fino a 50.000 euro per nucleo. Il secondo NON vale qui: la franchigia piu' alta sulla prima casa introdotta dalla legge di bilancio 2026 riguarda, secondo il messaggio INPS 102 del 12 gennaio 2026, soltanto cinque prestazioni (assegno di inclusione, supporto formazione e lavoro, assegno unico, bonus asilo nido, bonus nuovi nati) e non le prestazioni socio-sanitarie residenziali.

Sheet 4 - CAPITALE EXTRA
A1: Quanto capitale in piu' serve, in valore di oggi
A2: Strumento informativo / divulgativo. NON è consulenza finanziaria. I valori sono indicativi al 2026 e vanno verificati col tuo consulente.
A4: Parametri richiamati dal foglio 1
A5: Esborso netto annuo ai prezzi di oggi (€) | B5: ='1 - IL TUO CASO'!$B$21
A6: Anni che mancano all'ingresso | B6: ='1 - IL TUO CASO'!$B$26
A7: Anni di assistenza | B7: ='1 - IL TUO CASO'!$B$9
A8: Rendimento reale netto (%) | B8: ='1 - IL TUO CASO'!$B$7
A9: Crescita reale del costo dell'assistenza (%) | B9: ='1 - IL TUO CASO'!$B$12
A10: CAPITALE EXTRA NECESSARIO OGGI | B10: =SUM(E14:E38)
A12: Il conto anno per anno, per esteso
A13: Anno di assistenza | B13: Eta' | C13: Costo netto di quell'anno | D13: Anni da oggi | E13: Valore attuale
A14: 1 | B14: =IF(A14>$B$7,"",'1 - IL TUO CASO'!$B$8+A14-1) | C14: =IF(A14>$B$7,0,$B$5*(1+$B$9)^($B$6+A14-1)) | D14: =IF(A14>$B$7,"",$B$6+A14-1) | E14: =IF(A14>$B$7,0,C14/(1+$B$8)^($B$6+A14-1))
A15: 2 | B15: =IF(A15>$B$7,"",'1 - IL TUO CASO'!$B$8+A15-1) | C15: =IF(A15>$B$7,0,$B$5*(1+$B$9)^($B$6+A15-1)) | D15: =IF(A15>$B$7,"",$B$6+A15-1) | E15: =IF(A15>$B$7,0,C15/(1+$B$8)^($B$6+A15-1))
A16: 3 | B16: =IF(A16>$B$7,"",'1 - IL TUO CASO'!$B$8+A16-1) | C16: =IF(A16>$B$7,0,$B$5*(1+$B$9)^($B$6+A16-1)) | D16: =IF(A16>$B$7,"",$B$6+A16-1) | E16: =IF(A16>$B$7,0,C16/(1+$B$8)^($B$6+A16-1))
A17: 4 | B17: =IF(A17>$B$7,"",'1 - IL TUO CASO'!$B$8+A17-1) | C17: =IF(A17>$B$7,0,$B$5*(1+$B$9)^($B$6+A17-1)) | D17: =IF(A17>$B$7,"",$B$6+A17-1) | E17: =IF(A17>$B$7,0,C17/(1+$B$8)^($B$6+A17-1))
A18: 5 | B18: =IF(A18>$B$7,"",'1 - IL TUO CASO'!$B$8+A18-1) | C18: =IF(A18>$B$7,0,$B$5*(1+$B$9)^($B$6+A18-1)) | D18: =IF(A18>$B$7,"",$B$6+A18-1) | E18: =IF(A18>$B$7,0,C18/(1+$B$8)^($B$6+A18-1))
A19: 6 | B19: =IF(A19>$B$7,"",'1 - IL TUO CASO'!$B$8+A19-1) | C19: =IF(A19>$B$7,0,$B$5*(1+$B$9)^($B$6+A19-1)) | D19: =IF(A19>$B$7,"",$B$6+A19-1) | E19: =IF(A19>$B$7,0,C19/(1+$B$8)^($B$6+A19-1))
A20: 7 | B20: =IF(A20>$B$7,"",'1 - IL TUO CASO'!$B$8+A20-1) | C20: =IF(A20>$B$7,0,$B$5*(1+$B$9)^($B$6+A20-1)) | D20: =IF(A20>$B$7,"",$B$6+A20-1) | E20: =IF(A20>$B$7,0,C20/(1+$B$8)^($B$6+A20-1))
A21: 8 | B21: =IF(A21>$B$7,"",'1 - IL TUO CASO'!$B$8+A21-1) | C21: =IF(A21>$B$7,0,$B$5*(1+$B$9)^($B$6+A21-1)) | D21: =IF(A21>$B$7,"",$B$6+A21-1) | E21: =IF(A21>$B$7,0,C21/(1+$B$8)^($B$6+A21-1))
A22: 9 | B22: =IF(A22>$B$7,"",'1 - IL TUO CASO'!$B$8+A22-1) | C22: =IF(A22>$B$7,0,$B$5*(1+$B$9)^($B$6+A22-1)) | D22: =IF(A22>$B$7,"",$B$6+A22-1) | E22: =IF(A22>$B$7,0,C22/(1+$B$8)^($B$6+A22-1))
A23: 10 | B23: =IF(A23>$B$7,"",'1 - IL TUO CASO'!$B$8+A23-1) | C23: =IF(A23>$B$7,0,$B$5*(1+$B$9)^($B$6+A23-1)) | D23: =IF(A23>$B$7,"",$B$6+A23-1) | E23: =IF(A23>$B$7,0,C23/(1+$B$8)^($B$6+A23-1))
A24: 11 | B24: =IF(A24>$B$7,"",'1 - IL TUO CASO'!$B$8+A24-1) | C24: =IF(A24>$B$7,0,$B$5*(1+$B$9)^($B$6+A24-1)) | D24: =IF(A24>$B$7,"",$B$6+A24-1) | E24: =IF(A24>$B$7,0,C24/(1+$B$8)^($B$6+A24-1))
A25: 12 | B25: =IF(A25>$B$7,"",'1 - IL TUO CASO'!$B$8+A25-1) | C25: =IF(A25>$B$7,0,$B$5*(1+$B$9)^($B$6+A25-1)) | D25: =IF(A25>$B$7,"",$B$6+A25-1) | E25: =IF(A25>$B$7,0,C25/(1+$B$8)^($B$6+A25-1))
... A38: 25 | B38: =IF(A38>$B$7,"",'1 - IL TUO CASO'!$B$8+A38-1) | C38: =IF(A38>$B$7,0,$B$5*(1+$B$9)^($B$6+A38-1)) | D38: =IF(A38>$B$7,"",$B$6+A38-1) | E38: =IF(A38>$B$7,0,C38/(1+$B$8)^($B$6+A38-1))
A40: Il metodo e' quello di qualsiasi obiettivo futuro: si prende il costo di ogni singolo anno di assistenza, lo si riporta al valore di oggi scontandolo al rendimento reale del portafoglio, e si sommano i pezzi. Il risultato e' il capitale che devi avere OGGI, in aggiunta a tutto il resto, perche' quegli anni non facciano saltare il piano.
A41: Nota importante: se la crescita reale del costo dell'assistenza supera il rendimento reale del portafoglio, il capitale necessario cresce piu' che proporzionalmente con gli anni. E' il motivo per cui il vero rischio non e' l'importo medio, ma la DURATA. Prova a portare gli anni di assistenza da tre a otto e guarda cosa succede alla cella B10.

Sheet 5 - MATRICE
A1: Capitale extra necessario oggi: durata per configurazione
A2: Strumento informativo / divulgativo. NON è consulenza finanziaria. I valori sono indicativi al 2026 e vanno verificati col tuo consulente.
A4: Matrice — € di capitale extra necessario OGGI
A5: Anni di assistenza | B5: Assistenza a ore | C5: Badante convivente | D5: RSA
A6: 3 anni | B6: =B$18*$B$11 | C6: =C$18*$B$11 | D6: =D$18*$B$11
A7: 5 anni | B7: =B$18*$B$12 | C7: =C$18*$B$12 | D7: =D$18*$B$12
A8: 8 anni | B8: =B$18*$B$13 | C8: =C$18*$B$13 | D8: =D$18*$B$13
A9: La matrice usa l'area geografica scelta nel foglio 1 e sottrae la sola indennita' di accompagnamento, che e' l'unica copertura certa e uguale per tutti. Le agevolazioni fiscali dipendono dal reddito di chi paga e restano nel foglio 3. Il salto fra la colonna della badante e quella della RSA e' il numero che conta davvero.
A10: Motore del calcolo (celle di appoggio)
A11: Fattore di attualizzazione — 3 anni | B11: =IF($B$15=1,3/(1+$B$14)^$B$16,$B$15^$B$16*(1-$B$15^3)/(1-$B$15))
A12: Fattore di attualizzazione — 5 anni | B12: =IF($B$15=1,5/(1+$B$14)^$B$16,$B$15^$B$16*(1-$B$15^5)/(1-$B$15))
A13: Fattore di attualizzazione — 8 anni | B13: =IF($B$15=1,8/(1+$B$14)^$B$16,$B$15^$B$16*(1-$B$15^8)/(1-$B$15))
A14: Rendimento reale netto | B14: ='1 - IL TUO CASO'!$B$7
A15: Rapporto (1+crescita costi)/(1+rendimento) | B15: =(1+'1 - IL TUO CASO'!$B$12)/(1+'1 - IL TUO CASO'!$B$7)
A16: Anni che mancano all'ingresso | B16: ='1 - IL TUO CASO'!$B$26
A17: Costo annuo lordo della configurazione | B17: =INDEX('2 - COSTI'!$B$6:$D$8,1,'1 - IL TUO CASO'!$B$11)*12 | C17: =INDEX('2 - COSTI'!$B$6:$D$8,2,'1 - IL TUO CASO'!$B$11)*12 | D17: =INDEX('2 - COSTI'!$B$6:$D$8,3,'1 - IL TUO CASO'!$B$11)*12
A18: Costo annuo netto dell'indennita' di accompagnamento | B18: =MAX(0,B17-'3 - COPERTURE'!$B$8) | C18: =MAX(0,C17-'3 - COPERTURE'!$B$8) | D18: =MAX(0,D17-'3 - COPERTURE'!$B$8)
A20: Auto-assicurarsi o assicurarsi: il confronto onesto
A21: Strada | B21: Cosa costa | C21: Il punto scomodo
A22: Capitale dedicato (auto-assicurazione) | B22: Il capitale extra calcolato qui sopra, tenuto in strumenti prudenti e liquidabili | C22: Se la non autosufficienza non arriva, quel capitale resta agli eredi: non e' denaro perso, ma e' denaro non goduto
A23: Polizza per il rischio di non autosufficienza | B23: Un premio annuo per tutta la vita, tanto piu' basso quanto prima si sottoscrive | C23: Premio rivedibile e definizione di non autosufficienza spesso restrittiva: prima del prezzo si legge quando la compagnia paga
A24: Immobile come riserva da liquidare | B24: Nessun esborso oggi | C24: Va venduto proprio nel momento peggiore, con tempi lunghi e spesso quando chi dovrebbe firmare non e' piu' in grado di farlo
A26: Il trattamento fiscale del premio
A27: Premio annuo ipotizzato (€) | B27: 900
A28: Tetto detraibile dei premi non autosufficienza (€) | B28: 1291.14
A29: Detrazione del 19% | B29: =MIN(B27,B28)*0.19
A30: Premio annuo al netto della detrazione | B30: =B27-B29
A31: Premi netti versati fino all'eta' di ingresso | B31: =B30*'1 - IL TUO CASO'!$B$26
A33: I premi delle polizze che coprono il rischio di non autosufficienza nel compiere gli atti della vita quotidiana danno diritto a una detrazione del 19% su un massimo di 1.291,14 euro l'anno, al netto degli eventuali premi per morte e invalidita' permanente compresi nello stesso contratto. Il premio della riga 27 e' un'ipotesi da sostituire con un preventivo vero: questo foglio non indica ne' consiglia alcun prodotto o compagnia, serve solo a confrontare due ordini di grandezza. In Italia il mercato e' minuscolo: la Banca d'Italia, all'assemblea dell'ANIA del 2 luglio 2025, ha ricordato che i premi long term care valgono poco piu' di 350 milioni di euro su 150 miliardi di raccolta complessiva.
