Workbook

Sheet 0 - Indice
A1: La pensione si allontana — il simulatore (ottobre 2026)
A2: Strumento informativo / divulgativo. NON è consulenza finanziaria. I valori sono indicativi al 2026 e vanno verificati col tuo consulente.
A4: Indice
A5: 1 - Il tuo traguardo | B5: La tua data di nascita: prima rata di vecchiaia, mesi oltre i 67, ponte, RITA, anticipata
A6: 2 - Il costo del ponte | B6: Quanto capitale serve per arrivare alla prima rata e quanto costa un mese in più
A7: 3 - Le tre forze | B7: Il caso di Irene: storia di risparmio, messaggio in due passi, età / inflazione / stipendi, stop minimo nei mondi
A8: 4 - Le leve | B8: Spesa, TFR, part-time, fondo pensione, riscatto, volontari, soglia: mesi di anticipo; rendimento di pareggio
A9: 5 - La manovra | B9: Le proposte al 29/09/2026, la tua manovra, la soglia dell'anticipata, le previsioni da verificare
A11: Come usare
A12: 1. Le celle GIALLE sono input — modificale coi tuoi numeri.
A13: 2. Le celle VERDI sono output — si aggiornano automaticamente.
A14: 3. Tutti i numeri di default sono al 2026 da fonti pubbliche.
A15: 4. Niente codice nascosto: l'Excel è solo formule modificabili.
A16: 5. Le celle BIANCHE sono dati ufficiali (tabelle RGS, coefficienti, righe INPS, FOI, PIL ISTAT): non modificarle; la fonte è nella colonna accanto.
A17: Fonti dati
A18: • RGS, Rapporto n. 27 (22/09/2026): Tab. A1.4 p. 211 e A1.5 p. 212 (requisiti; dal 2029 proiezioni), Tab. A1.1 p. 197 (coefficienti), Riquadro 5.1 p. 159, Riquadro 6.1 pp. 184-185, §1.2 (PIL reale 0,5%)
A19: • RGS, Rapporto n. 26 (agosto 2025), base ISTAT 2023: la curva di un anno fa
A20: • Decreto direttoriale 20/11/2024: coefficienti di trasformazione 2025-2026
A21: • INPS, messaggio n. 707 del 27/02/2026: coefficienti di rivalutazione del montante; circolare n. 28/2026 (requisiti 2027-2028); circolare n. 153/2025 (assegno sociale 2026: 546,24 €)
A22: • ISTAT, Pil e indebitamento AP 2022-2024 (03/03/2025); Conti economici nazionali (22/09/2026); indice FOI; inflazione acquisita 2026
... A35: Campo del simulatore: nati fra il 1960 e il 2000, stop fra 40 e 65 anni (foglio 1, riga 8). Fuori campo le celle mostrano un messaggio, non un numero.

Sheet 1 - Il tuo traguardo
A1: Il tuo traguardo: quando arriva la prima rata di vecchiaia
A2: Strumento informativo / divulgativo. NON è consulenza finanziaria. I valori sono indicativi al 2026 e vanno verificati col tuo consulente.
A4: I tuoi dati
A5: Data di nascita | B5: 30756 | C5: Esempio del video: Irene, nata il 15/03/1984
A6: Età a cui vuoi smettere di lavorare: anni | B6: 50
A7: … più mesi | B7: 0
A8: Data di nascita ed età di stop valgono anche nei fogli 2-5 (il caso di Irene). Campo del simulatore: nati fra il 1960 e il 2000; stop fisso fra 40 e 65 anni e 11 mesi, da gennaio 2027 a dicembre 2066 (il caso accumula fino a dicembre 2067). Gli stop minimi si cercano fra 40 e 65 anni: fuori da lì le celle scrivono «già ora» (se regge già da gennaio 2027), «prima dei 40 anni» o «dopo i 65 anni (fuori scala)». Fuori campo compare un messaggio, mai un numero.
A10: La tua prima rata di vecchiaia (curva RGS 27: dal 2029 è una proiezione, non una norma)
A11: Età in cui maturi il requisito | B11: =IFERROR(INT(($B$48-$B$46)/12)&" anni"&IF(MOD(($B$48-$B$46),12)>0," e "&MOD(($B$48-$B$46),12)&IF(MOD(($B$48-$B$46),12)=1," mese"," mesi"),""),"fuori dal campo del simulatore (foglio 1, riga 8)") -> 69 anni e 3 mesi
A12: Mese in cui lo maturi | B12: =IFERROR(CHOOSE(MOD($B$48,12)+1,"gennaio","febbraio","marzo","aprile","maggio","giugno","luglio","agosto","settembre","ottobre","novembre","dicembre")&" "&INT($B$48/12),"fuori dal campo del simulatore (foglio 1, riga 8)") -> giugno 2053
A13: Prima rata (il 1° del mese dopo) | B13: =IFERROR("1° "&CHOOSE(MOD($B$49,12)+1,"gennaio","febbraio","marzo","aprile","maggio","giugno","luglio","agosto","settembre","ottobre","novembre","dicembre")&" "&INT($B$49/12),"fuori dal campo del simulatore (foglio 1, riga 8)") -> 1° luglio 2053
A14: Mesi oltre i 67 anni | B14: =IFERROR($B$48-$B$46-804,"fuori dal campo del simulatore (foglio 1, riga 8)") -> 27
A15: Stop dal lavoro | B15: =IFERROR(INT(($B$47-$B$46)/12)&" anni"&IF(MOD(($B$47-$B$46),12)>0," e "&MOD(($B$47-$B$46),12)&IF(MOD(($B$47-$B$46),12)=1," mese"," mesi"),"")&", "&CHOOSE(MOD($B$47,12)+1,"gennaio","febbraio","marzo","aprile","maggio","giugno","luglio","agosto","settembre","ottobre","novembre","dicembre")&" "&INT($B$47/12),"fuori dal campo del simulatore (foglio 1, riga 8)") -> 50 anni, marzo 2034
A16: Mesi di ponte (dallo stop alla prima rata) | B16: =IFERROR($B$49-$B$47,"fuori dal campo del simulatore (foglio 1, riga 8)") -> 232
A17: Anni di ponte | B17: =IFERROR(INT(($B$49-$B$47)/12)&" anni"&IF(MOD(($B$49-$B$47),12)>0," e "&MOD(($B$49-$B$47),12)&IF(MOD(($B$49-$B$47),12)=1," mese"," mesi"),""),"fuori dal campo del simulatore (foglio 1, riga 8)") -> 19 anni e 4 mesi
A18: La RITA del fondo pensione si apre a | B18: =IFERROR(INT(($B$48-$B$46-120)/12)&" anni"&IF(MOD(($B$48-$B$46-120),12)>0," e "&MOD(($B$48-$B$46-120),12)&IF(MOD(($B$48-$B$46-120),12)=1," mese"," mesi"),""),"fuori dal campo del simulatore (foglio 1, riga 8)") -> 59 anni e 3 mesi | C18: RITA: fino a 10 anni prima dell'età di vecchiaia, dopo 24 mesi senza lavoro (D.Lgs. 252/2005 art. 11 c. 4-bis): si sposta con il traguardo
A20: Pensione anticipata contributiva (64 anni + adeguamenti, 20 anni di contributi; soglia di importo: foglio 5)
A21: Età in cui maturi il requisito | B21: =IFERROR(INT(($B$50-$B$46)/12)&" anni"&IF(MOD(($B$50-$B$46),12)>0," e "&MOD(($B$50-$B$46),12)&IF(MOD(($B$50-$B$46),12)=1," mese"," mesi"),""),"fuori dal campo del simulatore (foglio 1, riga 8)") -> 66 anni
A22: Mese in cui lo maturi | B22: =IFERROR(CHOOSE(MOD($B$50,12)+1,"gennaio","febbraio","marzo","aprile","maggio","giugno","luglio","agosto","settembre","ottobre","novembre","dicembre")&" "&INT($B$50/12),"fuori dal campo del simulatore (foglio 1, riga 8)") -> marzo 2050
A23: Decorrenza (dopo la finestra di 3 mesi) | B23: =IFERROR("1° "&CHOOSE(MOD($B$51,12)+1,"gennaio","febbraio","marzo","aprile","maggio","giugno","luglio","agosto","settembre","ottobre","novembre","dicembre")&" "&INT($B$51/12),"fuori dal campo del simulatore (foglio 1, riga 8)") -> 1° luglio 2050
A24: Età alla decorrenza | B24: =IFERROR(INT(($B$51-$B$46-1)/12)&" anni"&IF(MOD(($B$51-$B$46-1),12)>0," e "&MOD(($B$51-$B$46-1),12)&IF(MOD(($B$51-$B$46-1),12)=1," mese"," mesi"),""),"fuori dal campo del simulatore (foglio 1, riga 8)") -> 66 anni e 3 mesi
A26: La stessa data con la curva di un anno fa (RGS 26, agosto 2025, base ISTAT 2023)
A27: Età della prima rata con la curva RGS 26 | B27: =IFERROR(INT(($B$52-$B$46)/12)&" anni"&IF(MOD(($B$52-$B$46),12)>0," e "&MOD(($B$52-$B$46),12)&IF(MOD(($B$52-$B$46),12)=1," mese"," mesi"),""),"fuori dal campo del simulatore (foglio 1, riga 8)") -> 69 anni e 2 mesi
A28: Prima rata con la curva RGS 26 | B28: =IFERROR("1° "&CHOOSE(MOD($B$53,12)+1,"gennaio","febbraio","marzo","aprile","maggio","giugno","luglio","agosto","settembre","ottobre","novembre","dicembre")&" "&INT($B$53/12),"fuori dal campo del simulatore (foglio 1, riga 8)") -> 1° giugno 2053
A29: Spostamento in un anno (mesi) | B29: =IFERROR($B$49-$B$53,"fuori dal campo del simulatore (foglio 1, riga 8)") -> 1
A31: Le generazioni: prima rata di vecchiaia (proiezione RGS 27), nati a gennaio e a dicembre
A32: Anno di nascita | B32: Nati a gennaio: età | C32: Nati a gennaio: prima rata | D32: Nati a dicembre: età | E32: Nati a dicembre: prima rata | F32: Mesi oltre i 67 (gennaio / dicembre) | G32: RITA da (nati a gennaio)
A33: 1966 | B33: =IFERROR(INT(($C$56-$B$56)/12)&" anni"&IF(MOD(($C$56-$B$56),12)>0," e "&MOD(($C$56-$B$56),12)&IF(MOD(($C$56-$B$56),12)=1," mese"," mesi"),""),"fuori dal campo del simulatore (foglio 1, riga 8)") -> 67 anni e 9 mesi | C33: =IFERROR("1° "&CHOOSE(MOD(($C$56+1),12)+1,"gennaio","febbraio","marzo","aprile","maggio","giugno","luglio","agosto","settembre","ottobre","novembre","dicembre")&" "&INT(($C$56+1)/12),"fuori dal campo del simulatore (foglio 1, riga 8)") -> 1° novembre 2033 | D33: =IFERROR(INT(($E$56-$D$56)/12)&" anni"&IF(MOD(($E$56-$D$56),12)>0," e "&MOD(($E$56-$D$56),12)&IF(MOD(($E$56-$D$56),12)=1," mese"," mesi"),""),"fuori dal campo del simulatore (foglio 1, riga 8)") -> 67 anni e 9 mesi | E33: =IFERROR("1° "&CHOOSE(MOD(($E$56+1),12)+1,"gennaio","febbraio","marzo","aprile","maggio","giugno","luglio","agosto","settembre","ottobre","novembre","dicembre")&" "&INT(($E$56+1)/12),"fuori dal campo del simulatore (foglio 1, riga 8)") -> 1° ottobre 2034 | F33: =IFERROR("+"&($C$56-$B$56-804)&" / +"&($E$56-$D$56-804),"fuori dal campo del simulatore (foglio 1, riga 8)") -> +9 / +9 | G33: =IFERROR(INT(($C$56-$B$56-120)/12)&" anni"&IF(MOD(($C$56-$B$56-120),12)>0," e "&MOD(($C$56-$B$56-120),12)&IF(MOD(($C$56-$B$56-120),12)=1," mese"," mesi"),""),"fuori dal campo del simulatore (foglio 1, riga 8)") -> 57 anni e 9 mesi
A34: 1970 | B34: =IFERROR(INT(($C$57-$B$57)/12)&" anni"&IF(MOD(($C$57-$B$57),12)>0," e "&MOD(($C$57-$B$57),12)&IF(MOD(($C$57-$B$57),12)=1," mese"," mesi"),""),"fuori dal campo del simulatore (foglio 1, riga 8)") -> 68 anni | C34: =IFERROR("1° "&CHOOSE(MOD(($C$57+1),12)+1,"gennaio","febbraio","marzo","aprile","maggio","giugno","luglio","agosto","settembre","ottobre","novembre","dicembre")&" "&INT(($C$57+1)/12),"fuori dal campo del simulatore (foglio 1, riga 8)") -> 1° febbraio 2038 | D34: =IFERROR(INT(($E$57-$D$57)/12)&" anni"&IF(MOD(($E$57-$D$57),12)>0," e "&MOD(($E$57-$D$57),12)&IF(MOD(($E$57-$D$57),12)=1," mese"," mesi"),""),"fuori dal campo del simulatore (foglio 1, riga 8)") -> 68 anni | E34: =IFERROR("1° "&CHOOSE(MOD(($E$57+1),12)+1,"gennaio","febbraio","marzo","aprile","maggio","giugno","luglio","agosto","settembre","ottobre","novembre","dicembre")&" "&INT(($E$57+1)/12),"fuori dal campo del simulatore (foglio 1, riga 8)") -> 1° gennaio 2039 | F34: =IFERROR("+"&($C$57-$B$57-804)&" / +"&($E$57-$D$57-804),"fuori dal campo del simulatore (foglio 1, riga 8)") -> +12 / +12 | G34: =IFERROR(INT(($C$57-$B$57-120)/12)&" anni"&IF(MOD(($C$57-$B$57-120),12)>0," e "&MOD(($C$57-$B$57-120),12)&IF(MOD(($C$57-$B$57-120),12)=1," mese"," mesi"),""),"fuori dal campo del simulatore (foglio 1, riga 8)") -> 58 anni
A35: 1975 | B35: =IFERROR(INT(($C$58-$B$58)/12)&" anni"&IF(MOD(($C$58-$B$58),12)>0," e "&MOD(($C$58-$B$58),12)&IF(MOD(($C$58-$B$58),12)=1," mese"," mesi"),""),"fuori dal campo del simulatore (foglio 1, riga 8)") -> 68 anni e 6 mesi | C35: =IFERROR("1° "&CHOOSE(MOD(($C$58+1),12)+1,"gennaio","febbraio","marzo","aprile","maggio","giugno","luglio","agosto","settembre","ottobre","novembre","dicembre")&" "&INT(($C$58+1)/12),"fuori dal campo del simulatore (foglio 1, riga 8)") -> 1° agosto 2043 | D35: =IFERROR(INT(($E$58-$D$58)/12)&" anni"&IF(MOD(($E$58-$D$58),12)>0," e "&MOD(($E$58-$D$58),12)&IF(MOD(($E$58-$D$58),12)=1," mese"," mesi"),""),"fuori dal campo del simulatore (foglio 1, riga 8)") -> 68 anni e 6 mesi | E35: =IFERROR("1° "&CHOOSE(MOD(($E$58+1),12)+1,"gennaio","febbraio","marzo","aprile","maggio","giugno","luglio","agosto","settembre","ottobre","novembre","dicembre")&" "&INT(($E$58+1)/12),"fuori dal campo del simulatore (foglio 1, riga 8)") -> 1° luglio 2044 | F35: =IFERROR("+"&($C$58-$B$58-804)&" / +"&($E$58-$D$58-804),"fuori dal campo del simulatore (foglio 1, riga 8)") -> +18 / +18 | G35: =IFERROR(INT(($C$58-$B$58-120)/12)&" anni"&IF(MOD(($C$58-$B$58-120),12)>0," e "&MOD(($C$58-$B$58-120),12)&IF(MOD(($C$58-$B$58-120),12)=1," mese"," mesi"),""),"fuori dal campo del simulatore (foglio 1, riga 8)") -> 58 anni e 6 mesi
A36: 1980 | B36: =IFERROR(INT(($C$59-$B$59)/12)&" anni"&IF(MOD(($C$59-$B$59),12)>0," e "&MOD(($C$59-$B$59),12)&IF(MOD(($C$59-$B$59),12)=1," mese"," mesi"),""),"fuori dal campo del simulatore (foglio 1, riga 8)") -> 68 anni e 10 mesi | C36: =IFERROR("1° "&CHOOSE(MOD(($C$59+1),12)+1,"gennaio","febbraio","marzo","aprile","maggio","giugno","luglio","agosto","settembre","ottobre","novembre","dicembre")&" "&INT(($C$59+1)/12),"fuori dal campo del simulatore (foglio 1, riga 8)") -> 1° dicembre 2048 | D36: =IFERROR(INT(($E$59-$D$59)/12)&" anni"&IF(MOD(($E$59-$D$59),12)>0," e "&MOD(($E$59-$D$59),12)&IF(MOD(($E$59-$D$59),12)=1," mese"," mesi"),""),"fuori dal campo del simulatore (foglio 1, riga 8)") -> 69 anni | E36: =IFERROR("1° "&CHOOSE(MOD(($E$59+1),12)+1,"gennaio","febbraio","marzo","aprile","maggio","giugno","luglio","agosto","settembre","ottobre","novembre","dicembre")&" "&INT(($E$59+1)/12),"fuori dal campo del simulatore (foglio 1, riga 8)") -> 1° gennaio 2050 | F36: =IFERROR("+"&($C$59-$B$59-804)&" / +"&($E$59-$D$59-804),"fuori dal campo del simulatore (foglio 1, riga 8)") -> +22 / +24 | G36: =IFERROR(INT(($C$59-$B$59-120)/12)&" anni"&IF(MOD(($C$59-$B$59-120),12)>0," e "&MOD(($C$59-$B$59-120),12)&IF(MOD(($C$59-$B$59-120),12)=1," mese"," mesi"),""),"fuori dal campo del simulatore (foglio 1, riga 8)") -> 58 anni e 10 mesi
A37: 1984 | B37: =IFERROR(INT(($C$60-$B$60)/12)&" anni"&IF(MOD(($C$60-$B$60),12)>0," e "&MOD(($C$60-$B$60),12)&IF(MOD(($C$60-$B$60),12)=1," mese"," mesi"),""),"fuori dal campo del simulatore (foglio 1, riga 8)") -> 69 anni e 3 mesi | C37: =IFERROR("1° "&CHOOSE(MOD(($C$60+1),12)+1,"gennaio","febbraio","marzo","aprile","maggio","giugno","luglio","agosto","settembre","ottobre","novembre","dicembre")&" "&INT(($C$60+1)/12),"fuori dal campo del simulatore (foglio 1, riga 8)") -> 1° maggio 2053 | D37: =IFERROR(INT(($E$60-$D$60)/12)&" anni"&IF(MOD(($E$60-$D$60),12)>0," e "&MOD(($E$60-$D$60),12)&IF(MOD(($E$60-$D$60),12)=1," mese"," mesi"),""),"fuori dal campo del simulatore (foglio 1, riga 8)") -> 69 anni e 3 mesi | E37: =IFERROR("1° "&CHOOSE(MOD(($E$60+1),12)+1,"gennaio","febbraio","marzo","aprile","maggio","giugno","luglio","agosto","settembre","ottobre","novembre","dicembre")&" "&INT(($E$60+1)/12),"fuori dal campo del simulatore (foglio 1, riga 8)") -> 1° aprile 2054 | F37: =IFERROR("+"&($C$60-$B$60-804)&" / +"&($E$60-$D$60-804),"fuori dal campo del simulatore (foglio 1, riga 8)") -> +27 / +27 | G37: =IFERROR(INT(($C$60-$B$60-120)/12)&" anni"&IF(MOD(($C$60-$B$60-120),12)>0," e "&MOD(($C$60-$B$60-120),12)&IF(MOD(($C$60-$B$60-120),12)=1," mese"," mesi"),""),"fuori dal campo del simulatore (foglio 1, riga 8)") -> 59 anni e 3 mesi
A38: 1990 | B38: =IFERROR(INT(($C$61-$B$61)/12)&" anni"&IF(MOD(($C$61-$B$61),12)>0," e "&MOD(($C$61-$B$61),12)&IF(MOD(($C$61-$B$61),12)=1," mese"," mesi"),""),"fuori dal campo del simulatore (foglio 1, riga 8)") -> 69 anni e 9 mesi | C38: =IFERROR("1° "&CHOOSE(MOD(($C$61+1),12)+1,"gennaio","febbraio","marzo","aprile","maggio","giugno","luglio","agosto","settembre","ottobre","novembre","dicembre")&" "&INT(($C$61+1)/12),"fuori dal campo del simulatore (foglio 1, riga 8)") -> 1° novembre 2059 | D38: =IFERROR(INT(($E$61-$D$61)/12)&" anni"&IF(MOD(($E$61-$D$61),12)>0," e "&MOD(($E$61-$D$61),12)&IF(MOD(($E$61-$D$61),12)=1," mese"," mesi"),""),"fuori dal campo del simulatore (foglio 1, riga 8)") -> 69 anni e 9 mesi | E38: =IFERROR("1° "&CHOOSE(MOD(($E$61+1),12)+1,"gennaio","febbraio","marzo","aprile","maggio","giugno","luglio","agosto","settembre","ottobre","novembre","dicembre")&" "&INT(($E$61+1)/12),"fuori dal campo del simulatore (foglio 1, riga 8)") -> 1° ottobre 2060 | F38: =IFERROR("+"&($C$61-$B$61-804)&" / +"&($E$61-$D$61-804),"fuori dal campo del simulatore (foglio 1, riga 8)") -> +33 / +33 | G38: =IFERROR(INT(($C$61-$B$61-120)/12)&" anni"&IF(MOD(($C$61-$B$61-120),12)>0," e "&MOD(($C$61-$B$61-120),12)&IF(MOD(($C$61-$B$61-120),12)=1," mese"," mesi"),""),"fuori dal campo del simulatore (foglio 1, riga 8)") -> 59 anni e 9 mesi
A39: 2000 | B39: =IFERROR(INT(($C$62-$B$62)/12)&" anni"&IF(MOD(($C$62-$B$62),12)>0," e "&MOD(($C$62-$B$62),12)&IF(MOD(($C$62-$B$62),12)=1," mese"," mesi"),""),"fuori dal campo del simulatore (foglio 1, riga 8)") -> 70 anni e 3 mesi | C39: =IFERROR("1° "&CHOOSE(MOD(($C$62+1),12)+1,"gennaio","febbraio","marzo","aprile","maggio","giugno","luglio","agosto","settembre","ottobre","novembre","dicembre")&" "&INT(($C$62+1)/12),"fuori dal campo del simulatore (foglio 1, riga 8)") -> 1° maggio 2070 | D39: =IFERROR(INT(($E$62-$D$62)/12)&" anni"&IF(MOD(($E$62-$D$62),12)>0," e "&MOD(($E$62-$D$62),12)&IF(MOD(($E$62-$D$62),12)=1," mese"," mesi"),""),"fuori dal campo del simulatore (foglio 1, riga 8)") -> 70 anni e 4 mesi | E39: =IFERROR("1° "&CHOOSE(MOD(($E$62+1),12)+1,"gennaio","febbraio","marzo","aprile","maggio","giugno","luglio","agosto","settembre","ottobre","novembre","dicembre")&" "&INT(($E$62+1)/12),"fuori dal campo del simulatore (foglio 1, riga 8)") -> 1° maggio 2071 | F39: =IFERROR("+"&($C$62-$B$62-804)&" / +"&($E$62-$D$62-804),"fuori dal campo del simulatore (foglio 1, riga 8)") -> +39 / +40 | G39: =IFERROR(INT(($C$62-$B$62-120)/12)&" anni"&IF(MOD(($C$62-$B$62-120),12)>0," e "&MOD(($C$62-$B$62-120),12)&IF(MOD(($C$62-$B$62-120),12)=1," mese"," mesi"),""),"fuori dal campo del simulatore (foglio 1, riga 8)") -> 60 anni e 3 mesi
A40: Dopo il 2028 le età sono proiezioni della Ragioneria (scenario demografico ISTAT mediano, base 2024), non norme: la data vera si fissa con i decreti biennali sulla speranza di vita. Nato/a il 15 del mese: la prima rata parte il 1° del mese dopo la maturazione.
A44: Motore del calcolo — non modificare
A45: Indici di mese = anno × 12 + mese − 1. Maturazione = primo mese in cui l'età raggiunge il requisito dell'anno solare (MATCH sulla colonna «ultimo mese di nascita che matura nell'anno»).
A46: Mese di nascita (indice) | B46: =YEAR($B$5)*12+MONTH($B$5)-1 -> 23810
A47: Mese di stop (indice) | B47: =$B$46+12*$B$6+$B$7 -> 24410
A48: Maturazione vecchiaia RGS 27 (indice) | B48: =MAX(12*(2011+(IFERROR(MATCH($B$46-0.5,$F$65:$F$137,1),0)+1)),$B$46+INDEX($B$65:$B$137,(IFERROR(MATCH($B$46-0.5,$F$65:$F$137,1),0)+1))) -> 24641
...

Sheet 2 - Il costo del ponte
A1: Il costo del ponte: quanto capitale serve per arrivare alla prima rata
A2: Strumento informativo / divulgativo. NON è consulenza finanziaria. I valori sono indicativi al 2026 e vanno verificati col tuo consulente.
A4: Ipotesi (rendimento, inflazione, imposte e bollo valgono anche nei fogli 3-5)
A5: Spesa annua nel ponte (euro di oggi) | B5: 24000 | C5: Tabella generale del video: 24.000 €. Il caso di Irene (22.000 €) sta nel foglio 3.
A6: Rendimento reale del portafoglio | B6: 0.03 | C6: Canone del canale (portafoglio 60/40).
A7: Inflazione dopo il 2026 | B7: 0.02 | C7: Obiettivo BCE, canone del canale.
A8: Plusvalenza latente allo stop (quota del patrimonio) | B8: 0.2 | C8: Ipotesi generale delle tabelle; per Irene il foglio 3 la calcola dalla sua storia.
A9: Imposta sulle plusvalenze | B9: 0.26 | C9: Pagata solo sulla quota di guadagno di ciò che vendi (base di costo tracciata).
A10: Imposta di bollo annua | B10: 0.002 | C10: Sul valore del dossier.
A12: Risultati (data di nascita ed età di stop dal foglio 1)
A13: Stop dal lavoro | B13: =IFERROR(INT(('1 - Il tuo traguardo'!$B$47-'1 - Il tuo traguardo'!$B$46)/12)&" anni"&IF(MOD(('1 - Il tuo traguardo'!$B$47-'1 - Il tuo traguardo'!$B$46),12)>0," e "&MOD(('1 - Il tuo traguardo'!$B$47-'1 - Il tuo traguardo'!$B$46),12)&IF(MOD(('1 - Il tuo traguardo'!$B$47-'1 - Il tuo traguardo'!$B$46),12)=1," mese"," mesi"),"")&", "&CHOOSE(MOD('1 - Il tuo traguardo'!$B$47,12)+1,"gennaio","febbraio","marzo","aprile","maggio","giugno","luglio","agosto","settembre","ottobre","novembre","dicembre")&" "&INT('1 - Il tuo traguardo'!$B$47/12),"fuori dal campo del simulatore (foglio 1, riga 8)") -> 50 anni, marzo 2034
A14: Prima rata di vecchiaia (foglio 1) | B14: =IFERROR("1° "&CHOOSE(MOD('1 - Il tuo traguardo'!$B$49,12)+1,"gennaio","febbraio","marzo","aprile","maggio","giugno","luglio","agosto","settembre","ottobre","novembre","dicembre")&" "&INT('1 - Il tuo traguardo'!$B$49/12),"fuori dal campo del simulatore (foglio 1, riga 8)") -> 1° luglio 2053
A15: Mesi di ponte | B15: =IFERROR($B$37,"fuori dal campo del simulatore (foglio 1, riga 8)") -> 232
A16: Capitale del ponte allo stop (euro di oggi) | B16: =IFERROR($X$41,"fuori dal campo del simulatore (foglio 1, riga 8)") -> 412708.86
A17: Capitale con un mese di requisito in più | B17: =IFERROR($X$86,"fuori dal campo del simulatore (foglio 1, riga 8)") -> 414145.7
A18: Un mese in più di requisito costa | B18: =IFERROR($X$86-$X$41,"fuori dal campo del simulatore (foglio 1, riga 8)") -> 1436.8424
A19: … in mesi di spesa | B19: =IFERROR(($X$86-$X$41)/('2 - Il costo del ponte'!$B$5/12),"fuori dal campo del simulatore (foglio 1, riga 8)") -> 0.71842122
A20: Moltiplicatore implicito: capitale / valore attuale della spesa al rendimento reale | B20: =IFERROR($X$41/$D$41,"fuori dal campo del simulatore (foglio 1, riga 8)") -> 1.1507396
A21: Moltiplicatore fiscale medio del canale (per confronto) | B21: 1.173 | C21: Fonte: posso_smettere_01/02 (canale): costo medio di imposte e bollo sul capitale
A22: Il ponte si paga col portafoglio (prelievo a inizio anno, 26% sulla quota di plusvalenza, bollo). Tabella del video: nati nel 1984, stop a 50 anni, 24.000 € di spesa, latente 20%.
A26: Motore del calcolo — non modificare
A27: Capitale necessario = il più piccolo capitale per cui il minimo del percorso (saldo dopo ogni prelievo e saldo finale, in euro dello stop) non scende sotto zero; trovato con la secante (2 inneschi + 4 correzioni).
A29: Rendimento reale (foglio 2) | B29: ='2 - Il costo del ponte'!$B$6 -> 0.03
A30: Inflazione dopo il 2026 (foglio 2) | B30: ='2 - Il costo del ponte'!$B$7 -> 0.02
A31: Imposta sulle plusvalenze (foglio 2) | B31: ='2 - Il costo del ponte'!$B$9 -> 0.26
A32: 1 − bollo (foglio 2) | B32: =1-'2 - Il costo del ponte'!$B$10 -> 0.998
A33: Crescita reale annua del portafoglio (1 + r), prima del bollo | B33: =1+$B$29 -> 1.03
A34: Inflazione: la base di costo nominale perde (1 + inflazione) ogni anno in euro reali | B34: =1+$B$30 -> 1.02
A36: Ricerca 1 — capitale del ponte | B36: Capitale necessario: | C36: =$X$41 -> 412708.86
A37: Mesi di ponte (foglio 1) | B37: ='1 - Il tuo traguardo'!$B$49-'1 - Il tuo traguardo'!$B$47 -> 232
A38: Spesa annua | B38: ='2 - Il costo del ponte'!$B$5 -> 24000
A39: Plusvalenza latente allo stop | B39: ='2 - Il costo del ponte'!$B$8 -> 0.2
A40: Numero di prelievi annui | B40: =ROUNDUP($B$37/12,0) -> 20
A41: Capitale provato (secante: 2 inneschi + 4 correzioni) | D41: =IF(SUMPRODUCT($C$44:$C$79,1/$B$33^$B$44:$B$79)<=0,1000,SUMPRODUCT($C$44:$C$79,1/$B$33^$B$44:$B$79)) -> 358646.6 | H41: =1.15*$D$41 -> 412443.59 | L41: =IF($H$42=$D$42,$H$41,$H$41-$H$42*($H$41-$D$41)/($H$42-$D$42)) -> 412705.67 | P41: =IF($L$42=$H$42,$L$41,$L$41-$L$42*($L$41-$H$41)/($L$42-$H$42)) -> 412708.86 | T41: =IF($P$42=$L$42,$P$41,$P$41-$P$42*($P$41-$L$41)/($P$42-$L$42)) -> 412708.86 | X41: =IF($T$42=$P$42,$T$41,$T$41-$T$42*($T$41-$P$41)/($T$42-$P$42)) -> 412708.86
A42: Minimo del percorso con quel capitale (euro dello stop) | D42: =MIN($F$44:$F$79) -> -78448.803 | H42: =MIN($J$44:$J$79) -> -380.31471 | L42: =MIN($N$44:$N$79) -> -4.5781937 | P42: =MIN($R$44:$R$79) -> -2.1955771e-11 | T42: =MIN($V$44:$V$79) -> -2.1955771e-11
B43: k (anni dallo stop) | C43: Fabbisogno (euro dello stop) | D43: Prova 1: Patrimonio prima del prelievo | E43: Prova 1: Prelievo lordo | F43: Prova 1: Patrimonio dopo il prelievo | G43: Prova 1: Base di costo (all'anno dopo) | H43: Prova 2: Patrimonio prima del prelievo | I43: Prova 2: Prelievo lordo | J43: Prova 2: Patrimonio dopo il prelievo | K43: Prova 2: Base di costo (all'anno dopo) | L43: Prova 3: Patrimonio prima del prelievo | M43: Prova 3: Prelievo lordo | N43: Prova 3: Patrimonio dopo il prelievo | O43: Prova 3: Base di costo (all'anno dopo) | P43: Prova 4: Patrimonio prima del prelievo | Q43: Prova 4: Prelievo lordo | R43: Prova 4: Patrimonio dopo il prelievo | S43: Prova 4: Base di costo (all'anno dopo) | T43: Prova 5: Patrimonio prima del prelievo | U43: Prova 5: Prelievo lordo | V43: Prova 5: Patrimonio dopo il prelievo | W43: Prova 5: Base di costo (all'anno dopo) | X43: Capitale necessario
B44: 0 | C44: =$B$38*MIN(12,MAX(0,$B$37-12*$B44))/12 -> 24000 | D44: =$D$41 -> 358646.6 | E44: =IF(AND(C44>0,D44>0),C44/(1-$B$31*MAX(0,1-$D$41*(1-$B$39)/D44)),0) -> 25316.456 | F44: =IF(E44>0,IF(E44<=D44,D44-E44,C44*(D44/E44-1)),D44-C44) -> 333330.15 | G44: =IF(E44>0,IF(E44<=D44,$D$41*(1-$B$39)*(1-E44/D44),0),IF(AND(C44<0,F44>0),$D$41*(1-$B$39)-C44,$D$41*(1-$B$39)))/$B$34 -> 261435.41 | H44: =$H$41 -> 412443.59 | I44: =IF(AND(C44>0,H44>0),C44/(1-$B$31*MAX(0,1-$H$41*(1-$B$39)/H44)),0) -> 25316.456 | J44: =IF(I44>0,IF(I44<=H44,H44-I44,C44*(H44/I44-1)),H44-C44) -> 387127.14 | K44: =IF(I44>0,IF(I44<=H44,$H$41*(1-$B$39)*(1-I44/H44),0),IF(AND(C44<0,J44>0),$H$41*(1-$B$39)-C44,$H$41*(1-$B$39)))/$B$34 -> 303629.13 | L44: =$L$41 -> 412705.67 | M44: =IF(AND(C44>0,L44>0),C44/(1-$B$31*MAX(0,1-$L$41*(1-$B$39)/L44)),0) -> 25316.456 | N44: =IF(M44>0,IF(M44<=L44,L44-M44,C44*(L44/M44-1)),L44-C44) -> 387389.21 | O44: =IF(M44>0,IF(M44<=L44,$L$41*(1-$B$39)*(1-M44/L44),0),IF(AND(C44<0,N44>0),$L$41*(1-$B$39)-C44,$L$41*(1-$B$39)))/$B$34 -> 303834.68 | P44: =$P$41 -> 412708.86 | Q44: =IF(AND(C44>0,P44>0),C44/(1-$B$31*MAX(0,1-$P$41*(1-$B$39)/P44)),0) -> 25316.456 | R44: =IF(Q44>0,IF(Q44<=P44,P44-Q44,C44*(P44/Q44-1)),P44-C44) -> 387392.4 | S44: =IF(Q44>0,IF(Q44<=P44,$P$41*(1-$B$39)*(1-Q44/P44),0),IF(AND(C44<0,R44>0),$P$41*(1-$B$39)-C44,$P$41*(1-$B$39)))/$B$34 -> 303837.18 | T44: =$T$41 -> 412708.86 | U44: =IF(AND(C44>0,T44>0),C44/(1-$B$31*MAX(0,1-$T$41*(1-$B$39)/T44)),0) -> 25316.456 | V44: =IF(U44>0,IF(U44<=T44,T44-U44,C44*(T44/U44-1)),T44-C44) -> 387392.4 | W44: =IF(U44>0,IF(U44<=T44,$T$41*(1-$B$39)*(1-U44/T44),0),IF(AND(C44<0,V44>0),$T$41*(1-$B$39)-C44,$T$41*(1-$B$39)))/$B$34 -> 303837.18
B45: 1 | C45: =$B$38*MIN(12,MAX(0,$B$37-12*$B45))/12 -> 24000 | D45: =IF($B45>$B$40,F44,F44*$B$33*IF(F44>0,$B$32,1)) -> 342643.39 | E45: =IF(AND(C45>0,D45>0),C45/(1-$B$31*MAX(0,1-G44/D45)),0) -> 25576.024 | F45: =IF(E45>0,IF(E45<=D45,D45-E45,C45*(D45/E45-1)),D45-C45) -> 317067.37 | G45: =IF(E45>0,IF(E45<=D45,G44*(1-E45/D45),0),IF(AND(C45<0,F45>0),G44-C45,G44))/$B$34 -> 237177.47 | H45: =IF($B45>$B$40,J44,J44*$B$33*IF(J44>0,$B$32,1)) -> 397943.47 | I45: =IF(AND(C45>0,H45>0),C45/(1-$B$31*MAX(0,1-K44/H45)),0) -> 25576.024 | J45: =IF(I45>0,IF(I45<=H45,H45-I45,C45*(H45/I45-1)),H45-C45) -> 372367.45 | K45: =IF(I45>0,IF(I45<=H45,K44*(1-I45/H45),0),IF(AND(C45<0,J45>0),K44-C45,K44))/$B$34 -> 278543.86 | L45: =IF($B45>$B$40,N44,N44*$B$33*IF(N44>0,$B$32,1)) -> 398212.87 | M45: =IF(AND(C45>0,L45>0),C45/(1-$B$31*MAX(0,1-O44/L45)),0) -> 25576.024 | N45: =IF(M45>0,IF(M45<=L45,L45-M45,C45*(L45/M45-1)),L45-C45) -> 372636.84 | O45: =IF(M45>0,IF(M45<=L45,O44*(1-M45/L45),0),IF(AND(C45<0,N45>0),O44-C45,O44))/$B$34 -> 278745.37 | P45: =IF($B45>$B$40,R44,R44*$B$33*IF(R44>0,$B$32,1)) -> 398216.15 | Q45: =IF(AND(C45>0,P45>0),C45/(1-$B$31*MAX(0,1-S44/P45)),0) -> 25576.024 | R45: =IF(Q45>0,IF(Q45<=P45,P45-Q45,C45*(P45/Q45-1)),P45-C45) -> 372640.12 | S45: =IF(Q45>0,IF(Q45<=P45,S44*(1-Q45/P45),0),IF(AND(C45<0,R45>0),S44-C45,S44))/$B$34 -> 278747.83 | T45: =IF($B45>$B$40,V44,V44*$B$33*IF(V44>0,$B$32,1)) -> 398216.15 | U45: =IF(AND(C45>0,T45>0),C45/(1-$B$31*MAX(0,1-W44/T45)),0) -> 25576.024 | V45: =IF(U45>0,IF(U45<=T45,T45-U45,C45*(T45/U45-1)),T45-C45) -> 372640.12 | W45: =IF(U45>0,IF(U45<=T45,W44*(1-U45/T45),0),IF(AND(C45<0,V45>0),W44-C45,W44))/$B$34 -> 278747.83
B46: 2 | C46: =$B$38*MIN(12,MAX(0,$B$37-12*$B46))/12 -> 24000 | D46: =IF($B46>$B$40,F45,F45*$B$33*IF(F45>0,$B$32,1)) -> 325926.23 | E46: =IF(AND(C46>0,D46>0),C46/(1-$B$31*MAX(0,1-G45/D46)),0) -> 25828.593 | F46: =IF(E46>0,IF(E46<=D46,D46-E46,C46*(D46/E46-1)),D46-C46) -> 300097.64 | G46: =IF(E46>0,IF(E46<=D46,G45*(1-E46/D46),0),IF(AND(C46<0,F46>0),G45-C46,G45))/$B$34 -> 214099.92 | H46: =IF($B46>$B$40,J45,J45*$B$33*IF(J45>0,$B$32,1)) -> 382771.39 | I46: =IF(AND(C46>0,H46>0),C46/(1-$B$31*MAX(0,1-K45/H46)),0) -> 25828.593 | J46: =IF(I46>0,IF(I46<=H46,H46-I46,C46*(H46/I46-1)),H46-C46) -> 356942.8 | K46: =IF(I46>0,IF(I46<=H46,K45*(1-I46/H46),0),IF(AND(C46<0,J46>0),K45-C46,K45))/$B$34 -> 254655.21 | L46: =IF($B46>$B$40,N45,N45*$B$33*IF(N45>0,$B$32,1)) -> 383048.32 | M46: =IF(AND(C46>0,L46>0),C46/(1-$B$31*MAX(0,1-O45/L46)),0) -> 25828.593 | N46: =IF(M46>0,IF(M46<=L46,L46-M46,C46*(L46/M46-1)),L46-C46) -> 357219.72 | O46: =IF(M46>0,IF(M46<=L46,O45*(1-M46/L46),0),IF(AND(C46<0,N46>0),O45-C46,O45))/$B$34 -> 254852.78 | P46: =IF($B46>$B$40,R45,R45*$B$33*IF(R45>0,$B$32,1)) -> 383051.69 | Q46: =IF(AND(C46>0,P46>0),C46/(1-$B$31*MAX(0,1-S45/P46)),0) -> 25828.593 | R46: =IF(Q46>0,IF(Q46<=P46,P46-Q46,C46*(P46/Q46-1)),P46-C46) -> 357223.1 | S46: =IF(Q46>0,IF(Q46<=P46,S45*(1-Q46/P46),0),IF(AND(C46<0,R46>0),S45-C46,S45))/$B$34 -> 254855.18 | T46: =IF($B46>$B$40,V45,V45*$B$33*IF(V45>0,$B$32,1)) -> 383051.69 | U46: =IF(AND(C46>0,T46>0),C46/(1-$B$31*MAX(0,1-W45/T46)),0) -> 25828.593 | V46: =IF(U46>0,IF(U46<=T46,T46-U46,C46*(T46/U46-1)),T46-C46) -> 357223.1 | W46: =IF(U46>0,IF(U46<=T46,W45*(1-U46/T46),0),IF(AND(C46<0,V46>0),W45-C46,W45))/$B$34 -> 254855.18
B47: 3 | C47: =$B$38*MIN(12,MAX(0,$B$37-12*$B47))/12 -> 24000 | D47: =IF($B47>$B$40,F46,F46*$B$33*IF(F46>0,$B$32,1)) -> 308482.36 | E47: =IF(AND(C47>0,D47>0),C47/(1-$B$31*MAX(0,1-G46/D47)),0) -> 26074.172 | F47: =IF(E47>0,IF(E47<=D47,D47-E47,C47*(D47/E47-1)),D47-C47) -> 282408.19 | G47: =IF(E47>0,IF(E47<=D47,G46*(1-E47/D47),0),IF(AND(C47<0,F47>0),G46-C47,G46))/$B$34 -> 192160.13 | H47: =IF($B47>$B$40,J46,J46*$B$33*IF(J46>0,$B$32,1)) -> 366915.78 | I47: =IF(AND(C47>0,H47>0),C47/(1-$B$31*MAX(0,1-K46/H47)),0) -> 26074.172 | J47: =IF(I47>0,IF(I47<=H47,H47-I47,C47*(H47/I47-1)),H47-C47) -> 340841.61 | K47: =IF(I47>0,IF(I47<=H47,K46*(1-I47/H47),0),IF(AND(C47<0,J47>0),K46-C47,K46))/$B$34 -> 231920.22 | L47: =IF($B47>$B$40,N46,N46*$B$33*IF(N46>0,$B$32,1)) -> 367200.44 | M47: =IF(AND(C47>0,L47>0),C47/(1-$B$31*MAX(0,1-O46/L47)),0) -> 26074.172 | N47: =IF(M47>0,IF(M47<=L47,L47-M47,C47*(L47/M47-1)),L47-C47) -> 341126.27 | O47: =IF(M47>0,IF(M47<=L47,O46*(1-M47/L47),0),IF(AND(C47<0,N47>0),O46-C47,O46))/$B$34 -> 232113.91 | P47: =IF($B47>$B$40,R46,R46*$B$33*IF(R46>0,$B$32,1)) -> 367203.91 | Q47: =IF(AND(C47>0,P47>0),C47/(1-$B$31*MAX(0,1-S46/P47)),0) -> 26074.172 | R47: =IF(Q47>0,IF(Q47<=P47,P47-Q47,C47*(P47/Q47-1)),P47-C47) -> 341129.74 | S47: =IF(Q47>0,IF(Q47<=P47,S46*(1-Q47/P47),0),IF(AND(C47<0,R47>0),S46-C47,S46))/$B$34 -> 232116.27 | T47: =IF($B47>$B$40,V46,V46*$B$33*IF(V46>0,$B$32,1)) -> 367203.91 | U47: =IF(AND(C47>0,T47>0),C47/(1-$B$31*MAX(0,1-W46/T47)),0) -> 26074.172 | V47: =IF(U47>0,IF(U47<=T47,T47-U47,C47*(T47/U47-1)),T47-C47) -> 341129.74 | W47: =IF(U47>0,IF(U47<=T47,W46*(1-U47/T47),0),IF(AND(C47<0,V47>0),W46-C47,W46))/$B$34 -> 232116.27
...

Sheet 3 - Le tre forze
A1: Le tre forze: età, inflazione e stipendi sul caso di Irene
A2: Strumento informativo / divulgativo. NON è consulenza finanziaria. I valori sono indicativi al 2026 e vanno verificati col tuo consulente.
A4: Il caso (celle gialle modificabili)
A5: RAL nel primo anno di lavoro | B5: 27000 | C5: Irene: 27.000 € nel 2009, cresciuta del 4,05% l'anno
A6: RAL 2026 | B6: 53000 | C6: Dal 2027 costante in termini reali
A7: Anno del primo contributo (dal 2009 in poi) | B7: 2009 | C7: Contributiva pura: primo contributo dopo il 1995
A8: Spesa annua in cassa, da occupata e da FIRE (euro di oggi) | B8: 22000 | C8: Affitto compreso: 650 €/mese
A9: Età fino a cui deve durare il piano | B9: 92 | C9: Convenzione del canale
A10: Aliquota contributiva IVS | B10: 0.33 | C10: Dipendenti del settore privato
A11: Inflazione 2026 (acquisita ad agosto) | B11: 0.029 | C11: ISTAT, prezzi al consumo agosto 2026 (inflazione acquisita)
A12: Shock di inflazione: 2027 | B12: 0.03 | C12: Prova di stress, non previsione: rendimenti nominali invariati
A13: Shock di inflazione: 2028 | B13: 0.03
A14: Stipendi reali: variazione 2027 | B14: -0.006 | C14: Contratti sotto i prezzi, senza recupero
A15: Stipendi reali: variazione 2028 | B15: -0.006
A16: Punto della banda per il dettaglio | B16: centrale | C16: «a regole di oggi», «centrale» (revisione a circa 0,2 l'anno), «se la revisione accelera»
A17: Nascita e stop fisso dal foglio 1; rendimento, inflazione, imposte e bollo dal foglio 2. Gli stop di questo foglio non contano il TFR, che resta un cuscinetto: lo aggiunge la leva del foglio 4.
A19: La storia di risparmio 2009-2026: patrimonio e base di costo derivati dalla stessa storia
A20: Netto 2026 (regole 2026) | B20: =IFERROR(Q180,"fuori dal campo del simulatore (foglio 1, riga 8)") -> 34246.456 | C20: Versamenti mensili = quota × netto dell'anno; 3% reale + inflazione FOI, bollo 0,20%
A21: Risparmio 2026 | B21: =IFERROR(Q180-$B$8,"fuori dal campo del simulatore (foglio 1, riga 8)") -> 12246.456
A22: Quota di risparmio sul netto (la stessa ogni anno) | B22: =IFERROR(1-$B$8/Q180,"fuori dal campo del simulatore (foglio 1, riga 8)") -> 0.35759776
A23: Patrimonio al 31/12/2026 | B23: =IFERROR(S180,"fuori dal campo del simulatore (foglio 1, riga 8)") -> 254467.88
A24: Versato (base di costo) | B24: =IFERROR(T180,"fuori dal campo del simulatore (foglio 1, riga 8)") -> 166895.72
A25: Crescita | B25: =IFERROR($B$23-$B$24,"fuori dal campo del simulatore (foglio 1, riga 8)") -> 87572.167
A26: Plusvalenza latente | B26: =IFERROR(1-$B$24/$B$23,"fuori dal campo del simulatore (foglio 1, riga 8)") -> 0.34413839
A28: Allo stop fisso del foglio 1
A29: Stop fisso | B29: =IFERROR(INT(($B$130-$B$129)/12)&" anni"&IF(MOD(($B$130-$B$129),12)>0," e "&MOD(($B$130-$B$129),12)&IF(MOD(($B$130-$B$129),12)=1," mese"," mesi"),"")&", "&CHOOSE(MOD($B$130,12)+1,"gennaio","febbraio","marzo","aprile","maggio","giugno","luglio","agosto","settembre","ottobre","novembre","dicembre")&" "&INT($B$130/12),"fuori dal campo del simulatore (foglio 1, riga 8)") -> 50 anni, marzo 2034
A30: Patrimonio allo stop (euro di oggi) | B30: =IFERROR(IF(NOT($B$137),"stop fisso fuori campo (foglio 1, riga 8)",$B$1340),"fuori dal campo del simulatore (foglio 1, riga 8)") -> 406949.98
A31: … con lo shock di inflazione | B31: =IFERROR(IF(NOT($B$137),"stop fisso fuori campo (foglio 1, riga 8)",$B$822),"fuori dal campo del simulatore (foglio 1, riga 8)") -> 400687.23
A32: Mesi di ponte con i 67 anni di ieri | B32: =IFERROR(IF(NOT($B$137),"stop fisso fuori campo (foglio 1, riga 8)",$B$2006),"fuori dal campo del simulatore (foglio 1, riga 8)") -> 205
A33: Mesi di ponte con la curva RGS 27 | B33: =IFERROR(IF(NOT($B$137),"stop fisso fuori campo (foglio 1, riga 8)",$B$2054),"fuori dal campo del simulatore (foglio 1, riga 8)") -> 232
A34: Un mese di lavoro vale (margine a stop + 12 mesi meno margine allo stop, diviso 12) | B34: =IFERROR(IF(NOT($B$137),"stop fisso fuori campo (foglio 1, riga 8)",($E$1927-$E$1335)/12),"fuori dal campo del simulatore (foglio 1, riga 8)") -> 4029.2228
A35: Risparmio annuo con gli stipendi fermi (2028) | B35: =IFERROR(12*AB182,"fuori dal campo del simulatore (foglio 1, riga 8)") -> 11922.165
A36: Rivalutazione del montante stimata per il 2026 (riga 2025) | B36: =IFERROR(J179-1,"fuori dal campo del simulatore (foglio 1, riga 8)") -> 0.062636827 | C36: Stima: riga ufficiale 2024 e PIL 2025 ISTAT; contro l'inflazione acquisita del 2,9%
A38: Il messaggio in due passi (stop fisso; mesi di lavoro = euro / valore di un mese di lavoro)
A39: Voce | B39: A regole di oggi | C39: Centrale | D39: Se la revisione accelera
A40: Ponte in più (euro) | B40: =IFERROR(IF(NOT($B$137),"stop fisso fuori campo (foglio 1, riga 8)",($X$2057-$X$2009)),"fuori dal campo del simulatore (foglio 1, riga 8)") -> 37833.541 | C40: =IFERROR(IF(NOT($B$137),"stop fisso fuori campo (foglio 1, riga 8)",($X$2057-$X$2009)),"fuori dal campo del simulatore (foglio 1, riga 8)") -> 37833.541 | D40: =IFERROR(IF(NOT($B$137),"stop fisso fuori campo (foglio 1, riga 8)",($X$2057-$X$2009)),"fuori dal campo del simulatore (foglio 1, riga 8)") -> 37833.541
A41: Ponte in più (mesi di lavoro) | B41: =IFERROR(IF(NOT($B$137),"stop fisso fuori campo (foglio 1, riga 8)",($X$2057-$X$2009)/$B$34),"fuori dal campo del simulatore (foglio 1, riga 8)") -> 9.3897863 | C41: =IFERROR(IF(NOT($B$137),"stop fisso fuori campo (foglio 1, riga 8)",($X$2057-$X$2009)/$B$34),"fuori dal campo del simulatore (foglio 1, riga 8)") -> 9.3897863 | D41: =IFERROR(IF(NOT($B$137),"stop fisso fuori campo (foglio 1, riga 8)",($X$2057-$X$2009)/$B$34),"fuori dal campo del simulatore (foglio 1, riga 8)") -> 9.3897863
A42: In media, un mese di ponte costa | B42: =IFERROR(IF(NOT($B$137),"stop fisso fuori campo (foglio 1, riga 8)",($X$2057-$X$2009)/($B$134-$B$135)),"fuori dal campo del simulatore (foglio 1, riga 8)") -> 1401.2422 | C42: =IFERROR(IF(NOT($B$137),"stop fisso fuori campo (foglio 1, riga 8)",($X$2057-$X$2009)/($B$134-$B$135)),"fuori dal campo del simulatore (foglio 1, riga 8)") -> 1401.2422 | D42: =IFERROR(IF(NOT($B$137),"stop fisso fuori campo (foglio 1, riga 8)",($X$2057-$X$2009)/($B$134-$B$135)),"fuori dal campo del simulatore (foglio 1, riga 8)") -> 1401.2422
A43: La pensione più alta restituisce (euro) | B43: =IFERROR(IF(NOT($B$137),"stop fisso fuori campo (foglio 1, riga 8)",($X$759-$X$2009)-($X$1055-$X$2057)),"fuori dal campo del simulatore (foglio 1, riga 8)") -> 24982.394 | C43: =IFERROR(IF(NOT($B$137),"stop fisso fuori campo (foglio 1, riga 8)",($X$759-$X$2009)-($X$1351-$X$2057)),"fuori dal campo del simulatore (foglio 1, riga 8)") -> 8801.2504 | D43: =IFERROR(IF(NOT($B$137),"stop fisso fuori campo (foglio 1, riga 8)",($X$759-$X$2009)-($X$1647-$X$2057)),"fuori dal campo del simulatore (foglio 1, riga 8)") -> -2612.3712
A44: La pensione più alta restituisce (mesi di lavoro) | B44: =IFERROR(IF(NOT($B$137),"stop fisso fuori campo (foglio 1, riga 8)",(($X$759-$X$2009)-($X$1055-$X$2057))/$B$34),"fuori dal campo del simulatore (foglio 1, riga 8)") -> 6.2003011 | C44: =IFERROR(IF(NOT($B$137),"stop fisso fuori campo (foglio 1, riga 8)",(($X$759-$X$2009)-($X$1351-$X$2057))/$B$34),"fuori dal campo del simulatore (foglio 1, riga 8)") -> 2.1843544 | D44: =IFERROR(IF(NOT($B$137),"stop fisso fuori campo (foglio 1, riga 8)",(($X$759-$X$2009)-($X$1647-$X$2057))/$B$34),"fuori dal campo del simulatore (foglio 1, riga 8)") -> -0.6483561
...

Sheet 4 - Le leve
A1: Le leve di Irene: che cosa sposta davvero lo stop
A2: Strumento informativo / divulgativo. NON è consulenza finanziaria. I valori sono indicativi al 2026 e vanno verificati col tuo consulente.
A4: Le leve (celle gialle modificabili)
A5: Spesa: taglio percentuale | B5: 0.1 | C5: Da 22.000 a 19.800 €
A6: Part-time nel ponte: anni | B6: 3 | C6: Nei primi anni dopo lo stop
A7: Part-time: RAL annua | B7: 14000 | C7: Con i contributi al 33%
A8: TFR in azienda incassato allo stop (Sì / No) | B8: Sì | C8: Art. 2120 c.c.: si liquida alla cessazione del rapporto
A9: Aliquota media sul TFR (vuoto = stimata dal foglio) | C9: Tassazione separata, approssimata con l'IRPEF sul reddito di riferimento
A10: Fondo pensione: versamento annuo | B10: 5300 | C10: Limite di deducibilità 2026 (L. 199/2025 art. 1 c. 201, fonti secondarie concordi)
A11: Fondo pensione: aliquota marginale IRPEF | B11: 0.33
A12: Fondo pensione: tassazione della prestazione | B12: 0.15 | C12: Solo l'arbitraggio fiscale, niente altro
A13: Riscatto della laurea agevolato: anni | B13: 5
A14: Riscatto: costo per anno (agevolato 2026) | B14: 6206.64 | C14: INPS, riscatto agevolato 2026: minimale × 33%
A15: Riscatto: aliquota di deduzione | B15: 0.33
A16: Contributi volontari: anni dopo lo stop | B16: 3
A17: Contributi volontari: aliquota sulla RAL 2026 | B17: 0.33
A18: Lavorare fino alla soglia dell'anticipata: quale soglia | B18: proiezione RGS | C18: «proiezione RGS» (componente legata al PIL) o «pavimento» (3,2 volte l'assegno sociale)
A20: Risultati: stop minimo e mesi di anticipo (centrale; gli stop non contano il TFR, salvo la sua leva)
A21: Leva | B21: Stop minimo | C21: Mese | D21: Mesi di anticipo (+ = prima, − = dopo)
A22: Nessuna leva (centrale, dal foglio 3) | B22: =IFERROR(IF('3 - Le tre forze'!$E$2327=0,INT(('3 - Le tre forze'!$C$2327-$B$76)/12)&" anni"&IF(MOD(('3 - Le tre forze'!$C$2327-$B$76),12)>0," e "&MOD(('3 - Le tre forze'!$C$2327-$B$76),12)&IF(MOD(('3 - Le tre forze'!$C$2327-$B$76),12)=1," mese"," mesi"),""),'3 - Le tre forze'!$G$2327),"fuori dal campo del simulatore (foglio 1, riga 8)") -> 50 anni e 4 mesi | C22: =IFERROR(IF('3 - Le tre forze'!$E$2327<>0,"n.d. (fuori scala)",CHOOSE(MOD('3 - Le tre forze'!$C$2327,12)+1,"gennaio","febbraio","marzo","aprile","maggio","giugno","luglio","agosto","settembre","ottobre","novembre","dicembre")&" "&INT('3 - Le tre forze'!$C$2327/12)),"fuori dal campo del simulatore (foglio 1, riga 8)") -> luglio 2034 | D22: =IFERROR(0,"fuori dal campo del simulatore (foglio 1, riga 8)") -> 0
A23: =IFERROR("Spesa −"&ROUND($B$5*100,0)&"% da occupata e da FIRE","fuori dal campo del simulatore (foglio 1, riga 8)") -> Spesa −10% da occupata e da FIRE | B23: =IFERROR(IF($E$101=0,INT(($C$101-$B$76)/12)&" anni"&IF(MOD(($C$101-$B$76),12)>0," e "&MOD(($C$101-$B$76),12)&IF(MOD(($C$101-$B$76),12)=1," mese"," mesi"),""),$G$101),"fuori dal campo del simulatore (foglio 1, riga 8)") -> 48 anni e 6 mesi | C23: =IFERROR(IF($E$101<>0,"n.d. (fuori scala)",CHOOSE(MOD($C$101,12)+1,"gennaio","febbraio","marzo","aprile","maggio","giugno","luglio","agosto","settembre","ottobre","novembre","dicembre")&" "&INT($C$101/12)),"fuori dal campo del simulatore (foglio 1, riga 8)") -> settembre 2032 | D23: =IFERROR(IF(OR('3 - Le tre forze'!$E$2327<>0,$E$101<>0),"non calcolabile: stop fuori scala",'3 - Le tre forze'!$C$2327-$C$101),"fuori dal campo del simulatore (foglio 1, riga 8)") -> 22
A24: =IFERROR("Spesa −"&ROUND($B$5*100,0)&"% solo da FIRE","fuori dal campo del simulatore (foglio 1, riga 8)") -> Spesa −10% solo da FIRE | B24: =IFERROR(IF($E$180=0,INT(($C$180-$B$76)/12)&" anni"&IF(MOD(($C$180-$B$76),12)>0," e "&MOD(($C$180-$B$76),12)&IF(MOD(($C$180-$B$76),12)=1," mese"," mesi"),""),$G$180),"fuori dal campo del simulatore (foglio 1, riga 8)") -> 48 anni e 10 mesi | C24: =IFERROR(IF($E$180<>0,"n.d. (fuori scala)",CHOOSE(MOD($C$180,12)+1,"gennaio","febbraio","marzo","aprile","maggio","giugno","luglio","agosto","settembre","ottobre","novembre","dicembre")&" "&INT($C$180/12)),"fuori dal campo del simulatore (foglio 1, riga 8)") -> gennaio 2033 | D24: =IFERROR(IF(OR('3 - Le tre forze'!$E$2327<>0,$E$180<>0),"non calcolabile: stop fuori scala",'3 - Le tre forze'!$C$2327-$C$180),"fuori dal campo del simulatore (foglio 1, riga 8)") -> 18
A25: TFR in azienda incassato allo stop | B25: =IFERROR(IF($E$259=0,INT(($C$259-$B$76)/12)&" anni"&IF(MOD(($C$259-$B$76),12)>0," e "&MOD(($C$259-$B$76),12)&IF(MOD(($C$259-$B$76),12)=1," mese"," mesi"),""),$G$259),"fuori dal campo del simulatore (foglio 1, riga 8)") -> 48 anni e 11 mesi | C25: =IFERROR(IF($E$259<>0,"n.d. (fuori scala)",CHOOSE(MOD($C$259,12)+1,"gennaio","febbraio","marzo","aprile","maggio","giugno","luglio","agosto","settembre","ottobre","novembre","dicembre")&" "&INT($C$259/12)),"fuori dal campo del simulatore (foglio 1, riga 8)") -> febbraio 2033 | D25: =IFERROR(IF(OR('3 - Le tre forze'!$E$2327<>0,$E$259<>0),"non calcolabile: stop fuori scala",'3 - Le tre forze'!$C$2327-$C$259),"fuori dal campo del simulatore (foglio 1, riga 8)") -> 17
A26: Part-time nei primi anni del ponte | B26: =IFERROR(IF($E$343=0,INT(($C$343-$B$76)/12)&" anni"&IF(MOD(($C$343-$B$76),12)>0," e "&MOD(($C$343-$B$76),12)&IF(MOD(($C$343-$B$76),12)=1," mese"," mesi"),""),$G$343),"fuori dal campo del simulatore (foglio 1, riga 8)") -> 49 anni e 4 mesi | C26: =IFERROR(IF($E$343<>0,"n.d. (fuori scala)",CHOOSE(MOD($C$343,12)+1,"gennaio","febbraio","marzo","aprile","maggio","giugno","luglio","agosto","settembre","ottobre","novembre","dicembre")&" "&INT($C$343/12)),"fuori dal campo del simulatore (foglio 1, riga 8)") -> luglio 2033 | D26: =IFERROR(IF(OR('3 - Le tre forze'!$E$2327<>0,$E$343<>0),"non calcolabile: stop fuori scala",'3 - Le tre forze'!$C$2327-$C$343),"fuori dal campo del simulatore (foglio 1, riga 8)") -> 12
A27: Fondo pensione (solo il vantaggio fiscale) | B27: =IFERROR(IF($E$422=0,INT(($C$422-$B$76)/12)&" anni"&IF(MOD(($C$422-$B$76),12)>0," e "&MOD(($C$422-$B$76),12)&IF(MOD(($C$422-$B$76),12)=1," mese"," mesi"),""),$G$422),"fuori dal campo del simulatore (foglio 1, riga 8)") -> 50 anni e 2 mesi | C27: =IFERROR(IF($E$422<>0,"n.d. (fuori scala)",CHOOSE(MOD($C$422,12)+1,"gennaio","febbraio","marzo","aprile","maggio","giugno","luglio","agosto","settembre","ottobre","novembre","dicembre")&" "&INT($C$422/12)),"fuori dal campo del simulatore (foglio 1, riga 8)") -> maggio 2034 | D27: =IFERROR(IF(OR('3 - Le tre forze'!$E$2327<>0,$E$422<>0),"non calcolabile: stop fuori scala",'3 - Le tre forze'!$C$2327-$C$422),"fuori dal campo del simulatore (foglio 1, riga 8)") -> 2
A28: Riscatto della laurea agevolato | B28: =IFERROR(IF($E$501=0,INT(($C$501-$B$76)/12)&" anni"&IF(MOD(($C$501-$B$76),12)>0," e "&MOD(($C$501-$B$76),12)&IF(MOD(($C$501-$B$76),12)=1," mese"," mesi"),""),$G$501),"fuori dal campo del simulatore (foglio 1, riga 8)") -> 50 anni e 6 mesi | C28: =IFERROR(IF($E$501<>0,"n.d. (fuori scala)",CHOOSE(MOD($C$501,12)+1,"gennaio","febbraio","marzo","aprile","maggio","giugno","luglio","agosto","settembre","ottobre","novembre","dicembre")&" "&INT($C$501/12)),"fuori dal campo del simulatore (foglio 1, riga 8)") -> settembre 2034 | D28: =IFERROR(IF(OR('3 - Le tre forze'!$E$2327<>0,$E$501<>0),"non calcolabile: stop fuori scala",'3 - Le tre forze'!$C$2327-$C$501),"fuori dal campo del simulatore (foglio 1, riga 8)") -> -2
A29: Contributi volontari dopo lo stop | B29: =IFERROR(IF($E$580=0,INT(($C$580-$B$76)/12)&" anni"&IF(MOD(($C$580-$B$76),12)>0," e "&MOD(($C$580-$B$76),12)&IF(MOD(($C$580-$B$76),12)=1," mese"," mesi"),""),$G$580),"fuori dal campo del simulatore (foglio 1, riga 8)") -> 51 anni e 3 mesi | C29: =IFERROR(IF($E$580<>0,"n.d. (fuori scala)",CHOOSE(MOD($C$580,12)+1,"gennaio","febbraio","marzo","aprile","maggio","giugno","luglio","agosto","settembre","ottobre","novembre","dicembre")&" "&INT($C$580/12)),"fuori dal campo del simulatore (foglio 1, riga 8)") -> giugno 2035 | D29: =IFERROR(IF(OR('3 - Le tre forze'!$E$2327<>0,$E$580<>0),"non calcolabile: stop fuori scala",'3 - Le tre forze'!$C$2327-$C$580),"fuori dal campo del simulatore (foglio 1, riga 8)") -> -11
A30: Lavorare fino alla soglia dell'anticipata e uscire con l'anticipata | B30: =IFERROR(IF($E$659=0,INT(($C$659-$B$76)/12)&" anni"&IF(MOD(($C$659-$B$76),12)>0," e "&MOD(($C$659-$B$76),12)&IF(MOD(($C$659-$B$76),12)=1," mese"," mesi"),""),$G$659),"fuori dal campo del simulatore (foglio 1, riga 8)") -> 51 anni e 10 mesi | C30: =IFERROR(IF($E$659<>0,"n.d. (fuori scala)",CHOOSE(MOD($C$659,12)+1,"gennaio","febbraio","marzo","aprile","maggio","giugno","luglio","agosto","settembre","ottobre","novembre","dicembre")&" "&INT($C$659/12)),"fuori dal campo del simulatore (foglio 1, riga 8)") -> gennaio 2036 | D30: =IFERROR(IF(OR('3 - Le tre forze'!$E$2327<>0,$E$659<>0),"non calcolabile: stop fuori scala",'3 - Le tre forze'!$C$2327-$C$659),"fuori dal campo del simulatore (foglio 1, riga 8)") -> -18
A32: Con il TFR: TFR netto allo stop (euro di oggi) | B32: =IFERROR(IF($E$259<>0,"n.d. (fuori scala)",$B$748),"fuori dal campo del simulatore (foglio 1, riga 8)") -> 60743.011 | C32: Gli stop del video non contano il TFR: con il TFR lo stop centrale è quello della riga 25
A33: Con il TFR: aliquota media stimata | B33: =IFERROR(IF($E$259<>0,"n.d. (fuori scala)",$B$746),"fuori dal campo del simulatore (foglio 1, riga 8)") -> 0.27131374
A35: Classifica delle leve (mesi di anticipo, dal più grande)
A36: Posizione | B36: Leva | C36: Mesi di anticipo
A37: 1 | B37: =IFERROR(INDEX($A$23:$A$30,MATCH(LARGE($B$1146:$B$1153,1),$B$1146:$B$1153,0)),"fuori dal campo del simulatore (foglio 1, riga 8)") -> Spesa −10% da occupata e da FIRE | C37: =IFERROR(INDEX($D$23:$D$30,MATCH(LARGE($B$1146:$B$1153,1),$B$1146:$B$1153,0)),"fuori dal campo del simulatore (foglio 1, riga 8)") -> 22
A38: 2 | B38: =IFERROR(INDEX($A$23:$A$30,MATCH(LARGE($B$1146:$B$1153,2),$B$1146:$B$1153,0)),"fuori dal campo del simulatore (foglio 1, riga 8)") -> Spesa −10% solo da FIRE | C38: =IFERROR(INDEX($D$23:$D$30,MATCH(LARGE($B$1146:$B$1153,2),$B$1146:$B$1153,0)),"fuori dal campo del simulatore (foglio 1, riga 8)") -> 18
A39: 3 | B39: =IFERROR(INDEX($A$23:$A$30,MATCH(LARGE($B$1146:$B$1153,3),$B$1146:$B$1153,0)),"fuori dal campo del simulatore (foglio 1, riga 8)") -> TFR in azienda incassato allo stop | C39: =IFERROR(INDEX($D$23:$D$30,MATCH(LARGE($B$1146:$B$1153,3),$B$1146:$B$1153,0)),"fuori dal campo del simulatore (foglio 1, riga 8)") -> 17
A40: 4 | B40: =IFERROR(INDEX($A$23:$A$30,MATCH(LARGE($B$1146:$B$1153,4),$B$1146:$B$1153,0)),"fuori dal campo del simulatore (foglio 1, riga 8)") -> Part-time nei primi anni del ponte | C40: =IFERROR(INDEX($D$23:$D$30,MATCH(LARGE($B$1146:$B$1153,4),$B$1146:$B$1153,0)),"fuori dal campo del simulatore (foglio 1, riga 8)") -> 12
A41: 5 | B41: =IFERROR(INDEX($A$23:$A$30,MATCH(LARGE($B$1146:$B$1153,5),$B$1146:$B$1153,0)),"fuori dal campo del simulatore (foglio 1, riga 8)") -> Fondo pensione (solo il vantaggio fiscale) | C41: =IFERROR(INDEX($D$23:$D$30,MATCH(LARGE($B$1146:$B$1153,5),$B$1146:$B$1153,0)),"fuori dal campo del simulatore (foglio 1, riga 8)") -> 2
A42: 6 | B42: =IFERROR(INDEX($A$23:$A$30,MATCH(LARGE($B$1146:$B$1153,6),$B$1146:$B$1153,0)),"fuori dal campo del simulatore (foglio 1, riga 8)") -> Riscatto della laurea agevolato | C42: =IFERROR(INDEX($D$23:$D$30,MATCH(LARGE($B$1146:$B$1153,6),$B$1146:$B$1153,0)),"fuori dal campo del simulatore (foglio 1, riga 8)") -> -2
A43: 7 | B43: =IFERROR(INDEX($A$23:$A$30,MATCH(LARGE($B$1146:$B$1153,7),$B$1146:$B$1153,0)),"fuori dal campo del simulatore (foglio 1, riga 8)") -> Contributi volontari dopo lo stop | C43: =IFERROR(INDEX($D$23:$D$30,MATCH(LARGE($B$1146:$B$1153,7),$B$1146:$B$1153,0)),"fuori dal campo del simulatore (foglio 1, riga 8)") -> -11
A44: 8 | B44: =IFERROR(INDEX($A$23:$A$30,MATCH(LARGE($B$1146:$B$1153,8),$B$1146:$B$1153,0)),"fuori dal campo del simulatore (foglio 1, riga 8)") -> Lavorare fino alla soglia dell'anticipata e uscire con l'anticipata | C44: =IFERROR(INDEX($D$23:$D$30,MATCH(LARGE($B$1146:$B$1153,8),$B$1146:$B$1153,0)),"fuori dal campo del simulatore (foglio 1, riga 8)") -> -18
...

Sheet 5 - La manovra
A1: La manovra 2027 e la soglia dell'anticipata: che cosa cambia per Irene
A2: Strumento informativo / divulgativo. NON è consulenza finanziaria. I valori sono indicativi al 2026 e vanno verificati col tuo consulente.
A4: Stato delle proposte al 29/09/2026 (fonti secondarie datate; il Documento programmatico di finanza pubblica è atteso entro il 02/10: da riscrivere il giorno prima della narrazione)
A5: Proposta | B5: Chi, quando (fonte) | C5: Stato | D5: Effetto su Irene (mesi di anticipo) | E5: Perché
A6: Sterilizzare il mese di aumento del 2027 | B6: Lega; circa 1,1 miliardi (Il Messaggero 07/09); forse selettiva (BusinessOnline 20/09, fiducia bassa) | C6: proposta | D6: =IFERROR($B$79-$B$183,"fuori dal campo del simulatore (foglio 1, riga 8)") -> 0 | E6: La prima rata non cambia: il mese del 2027 non tocca chi matura nel 2053
A7: Quota 64 per il sistema misto, con ricalcolo contributivo | B7: Durigon 09-10/09 (Il Giornale, QuiFinanza); Salvini a Pontida 20/09 (ANSA); Durigon 26/09: «puntiamo a quota 64» (ANSA) | C7: ipotesi, nessun testo (aPensione 02/09) | D7: =IFERROR(IF($B$83>=1996,0,"non calcolato: sistema misto"),"fuori dal campo del simulatore (foglio 1, riga 8)") -> 0 | E7: Riguarda il sistema misto: Irene è nel contributivo puro
A8: TFR in rendita per raggiungere la soglia | B8: Schema di quota 64 (QuiFinanza 09/09; Virgilio 07/09; CGIL, Il Fatto Quotidiano 07/09); «il meccanismo non è definito» (aPensione 02/09) | C8: ipotesi | D8: =IFERROR($B$46,"fuori dal campo del simulatore (foglio 1, riga 8)") -> 0 | E8: Il TFR in azienda si liquida alla cessazione del rapporto (art. 2120 c.c.): Irene lo incassa sedici anni prima della soglia
A9: Soglia ridotta o annullata per chi è senza lavoro | B9: Durigon 17/09 (ANSA) | C9: ipotesi | D9: =IFERROR(IF(OR('3 - Le tre forze'!$E$2327<>0,$E$273<>0),"non calcolabile: stop fuori scala",$B$89-$C$273),"fuori dal campo del simulatore (foglio 1, riga 8)") -> 5 | E9: Se valesse per i contributivi puri: anticipata a 66 anni e 3 mesi
A10: Quota 41 flessibile | B10: Lega (Il Messaggero 07/09) | C10: nessun testo | D10: =IFERROR(IF('3 - Le tre forze'!$E$2327<>0,"non calcolabile: stop fuori scala",IF(($B$89-12*$B$83)/12<41,0,"non calcolato: 41 anni di contributi raggiunti")),"fuori dal campo del simulatore (foglio 1, riga 8)") -> 0 | E10: Servono 41 anni di contributi: Irene ne avrà circa 25
A11: Pensioni minime a 700-800 € | B11: Tajani (Il Messaggero 07/09) | C11: proposta | D11: =IFERROR(IF($B$83>=1996,0,"non calcolato: sistema misto"),"fuori dal campo del simulatore (foglio 1, riga 8)") -> 0 | E11: Niente integrazione al minimo nel contributivo puro (L. 335/1995 art. 1 c. 16)
A12: Blocco strutturale dell'età a 67 anni | B12: nessuno | C12: — | D12: =IFERROR(IF(OR('3 - Le tre forze'!$E$2327<>0,'3 - Le tre forze'!$E$2175<>0),"non calcolabile: stop fuori scala",$B$89-$B$90),"fuori dal campo del simulatore (foglio 1, riga 8)") -> 4 | E12: La revisione dei coefficienti continuerebbe (foglio 3, mondo «67 anni, revisione centrale»)
A13: Anche se passasse tutto, al massimo (mesi di anticipo) | D13: =IFERROR(IF(SUMPRODUCT(--ISTEXT($D$6:$D$12))>0,"non calcolabile: una riga non ha un numero",MAX($D$6:$D$12)),"fuori dal campo del simulatore (foglio 1, riga 8)") -> 5
A14: Calendario: Documento programmatico di finanza pubblica atteso entro il 02/10, Documento programmatico di bilancio entro il 15/10, DDL alle Camere entro il 20/10 (L. 196/2009 art. 7), legge entro il 31/12. Già legge: 67 anni e 1 mese nel 2027, 67 anni e 3 mesi nel 2028 (L. 199/2025 c. 185; INPS circ. 28/2026).
A16: La tua manovra (celle gialle)
A17: Requisito di vecchiaia nel 2027 | B17: 67 anni e 1 mese
A18: Età di vecchiaia bloccata a 67 anni dall'anno (vuoto = nessun blocco)
A19: Soglia dell'anticipata contributiva | B19: proiezione RGS | C19: «proiezione RGS»: la più alta fra componente legata al PIL e pavimento; «pavimento»: 3,2 volte l'assegno sociale; «nessuna soglia»: la proposta per chi è senza lavoro
A20: Il TFR vale per raggiungere la soglia (Sì / No) | B20: No
A21: Il tuo TFR è ancora da liquidare quando chiedi la pensione (Sì / No) | B21: No | C21: Chi lascia il lavoro incassa il TFR alla cessazione: per Irene è «No». Con «Sì» e «Sì» il foglio converte in rendita, alla decorrenza dell'anticipata, il capitale che manca alla soglia: quei soldi escono dal portafoglio e non finanziano più il ponte (effetto teorico: il TFR a Irene non serve)
A22: Prima rata di vecchiaia con la tua manovra | B22: =IFERROR("1° "&CHOOSE(MOD($B$181,12)+1,"gennaio","febbraio","marzo","aprile","maggio","giugno","luglio","agosto","settembre","ottobre","novembre","dicembre")&" "&INT($B$181/12)&", a "&INT(($B$180-$B$76)/12)&" anni"&IF(MOD(($B$180-$B$76),12)>0," e "&MOD(($B$180-$B$76),12)&IF(MOD(($B$180-$B$76),12)=1," mese"," mesi"),""),"fuori dal campo del simulatore (foglio 1, riga 8)") -> 1° luglio 2053, a 69 anni e 3 mesi
A23: Stop minimo con la tua manovra | B23: =IFERROR(IF($E$188=0,INT(($C$188-$B$76)/12)&" anni"&IF(MOD(($C$188-$B$76),12)>0," e "&MOD(($C$188-$B$76),12)&IF(MOD(($C$188-$B$76),12)=1," mese"," mesi"),"")&", "&CHOOSE(MOD($C$188,12)+1,"gennaio","febbraio","marzo","aprile","maggio","giugno","luglio","agosto","settembre","ottobre","novembre","dicembre")&" "&INT($C$188/12),$G$188),"fuori dal campo del simulatore (foglio 1, riga 8)") -> 50 anni e 4 mesi, luglio 2034
A24: Canale di uscita | B24: =IFERROR(IF($E$188<>0,"n.d. (fuori scala)",IF($B$440,IF(AND($B$103,$B$439<$B$102),"anticipata contributiva, con capitale proprio convertito (teorico)","anticipata contributiva"),"vecchiaia")),"fuori dal campo del simulatore (foglio 1, riga 8)") -> vecchiaia
A25: Differenza sulle regole di oggi (mesi di anticipo) | B25: =IFERROR(IF(OR('3 - Le tre forze'!$E$2327<>0,$E$188<>0),"non calcolabile: stop fuori scala",$B$89-$C$188),"fuori dal campo del simulatore (foglio 1, riga 8)") -> 0
A27: La soglia dell'anticipata nel 2050 (euro di oggi): pavimento e proiezione RGS
A28: Anticipata di Irene: decorrenza | B28: =IFERROR("1° "&CHOOSE(MOD($B$80,12)+1,"gennaio","febbraio","marzo","aprile","maggio","giugno","luglio","agosto","settembre","ottobre","novembre","dicembre")&" "&INT($B$80/12)&", a "&INT(($B$80-$B$76-1)/12)&" anni"&IF(MOD(($B$80-$B$76-1),12)>0," e "&MOD(($B$80-$B$76-1),12)&IF(MOD(($B$80-$B$76-1),12)=1," mese"," mesi"),""),"fuori dal campo del simulatore (foglio 1, riga 8)") -> 1° luglio 2050, a 66 anni e 3 mesi
A29: Assegno sociale 2026 (€/mese; in euro di oggi resta uguale) | B29: =IFERROR($B$84,"fuori dal campo del simulatore (foglio 1, riga 8)") -> 546.24 | C29: INPS, circolare n. 153/2025 (assegno sociale 2026: 546,24 €), dato del motore del foglio 3
A30: Pavimento: 3,2 volte l'assegno sociale (€/mese) | B30: =IFERROR($B$93,"fuori dal campo del simulatore (foglio 1, riga 8)") -> 1747.968 | C30: Art. 24 c. 11 D.L. 201/2011: dal 2030 3,2 volte l'assegno sociale (lo stesso numero di pensione_64_soglia)
A31: Componente legata al PIL: proiezione RGS (€/mese) | B31: =IFERROR($B$92,"fuori dal campo del simulatore (foglio 1, riga 8)") -> 1919.7375 | C31: RGS 27, Tab. A1.5 nota (****): 1.638,72 € nel 2026 rivalutati con la media quinquennale del PIL nominale; è una proiezione, non la norma
A32: Soglia se morde la proiezione RGS (la più alta delle due) | B32: =IFERROR(MAX($B$30,$B$31),"fuori dal campo del simulatore (foglio 1, riga 8)") -> 1919.7375
A33: Pensione anticipata di Irene allo stop minimo centrale (€/mese lordi) | B33: =IFERROR(IF('3 - Le tre forze'!$E$2327<>0,"non calcolabile: stop fuori scala",$B$97),"fuori dal campo del simulatore (foglio 1, riga 8)") -> 1813.4259
A34: … in % della proiezione RGS | B34: =IFERROR(IF('3 - Le tre forze'!$E$2327<>0,"non calcolabile: stop fuori scala",$B$33/$B$32),"fuori dal campo del simulatore (foglio 1, riga 8)") -> 0.9446218
A35: … in % del pavimento | B35: =IFERROR(IF('3 - Le tre forze'!$E$2327<>0,"non calcolabile: stop fuori scala",$B$33/$B$30),"fuori dal campo del simulatore (foglio 1, riga 8)") -> 1.037448
A36: La soglia scelta nel foglio 4 si raggiunge lavorando fino a | B36: =IFERROR('4 - Le leve'!$B$52,"fuori dal campo del simulatore (foglio 1, riga 8)") -> 51 anni e 10 mesi
A37: Controllo a uno stop a scelta: anni | B37: 51
A38: … più mesi | B38: 0
A39: Pensione anticipata a quello stop (€/mese lordi) | B39: =IFERROR($B$101,"fuori dal campo del simulatore (foglio 1, riga 8)") -> 1862.54
A40: … in % della proiezione RGS | B40: =IFERROR($B$39/$B$32,"fuori dal campo del simulatore (foglio 1, riga 8)") -> 0.97020556
A41: … in % del pavimento | B41: =IFERROR($B$39/$B$30,"fuori dal campo del simulatore (foglio 1, riga 8)") -> 1.0655458
A43: Il TFR per la soglia
A44: Allo stop minimo centrale mancano (€/mese lordi, proiezione RGS) | B44: =IFERROR(IF('3 - Le tre forze'!$E$2327<>0,"non calcolabile: stop fuori scala",MAX(0,$B$32-$B$33)),"fuori dal campo del simulatore (foglio 1, riga 8)") -> 106.31161
...
