Workbook

Sheet 0 - Indice
A1: Polizza vita in banca contro ETF — il simulatore (ottobre 2026)
A2: Strumento informativo / divulgativo. NON è consulenza finanziaria. I valori sono indicativi al 2026 e vanno verificati col tuo consulente.
A4: Indice
A5: 1 - Il tuo confronto | B5: I tuoi numeri: capitale finale di polizza ed ETF prima e dopo le imposte, euro persi, anno per anno
A6: 2 - Uscire prima | B6: Uscire prima: riscatto con la penale anno per anno contro l'ETF; costi di uscita di tre prodotti reali (anonimi)
A7: 3 - Le medie IVASS | B7: I dati ufficiali IVASS e il confronto con i costi medi di ramo I, multiramo e unit linked, al 5% e al 3%
A8: 4 - Quando la polizza ha senso | B8: Successione (con il calcolo) e impignorabilità (con i limiti): quando la polizza può servire
A9: 5 - Come leggere il KID | B9: Dove trovare nel documento con le informazioni chiave (KID) i numeri da inserire
A11: Come usare
A12: 1. Le celle GIALLE sono input — modificale coi tuoi numeri.
A13: 2. Le celle VERDI sono output — si aggiornano automaticamente.
A14: 3. Tutti i numeri di default sono al 2026 da fonti pubbliche.
A15: 4. Niente codice nascosto: l'Excel è solo formule modificabili.
A16: 5. Le celle BIANCHE sono dati ufficiali (IVASS, KID, norme): non modificarle; la fonte è nella colonna accanto.
A17: Fonti dati
A18: • IVASS, Bollettino statistico n. 4/2025 (novembre 2025), cap. 9: KID al 15/09/2025, 529 prodotti: costo totale annuo medio (RIY) ramo I 1,7%, multiramo 2,5%, unit linked 2,9%; canale bancario e postale 72,1% della raccolta 2024; tassi di riscatto
A19: • IVASS, Relazione annuale sull'attività 2025 (18/06/2026): gestioni separate 2025 3,0% lordo, 1,9% agli assicurati, 35,6% trattenuto; BTP decennale 3,6%
A20: • Agenzia delle Entrate, Circolare n. 19/E del 27/06/2014: imposta 26%, quota titoli di Stato al 12,5%
A21: • Agenzia delle Entrate, Risoluzione n. 76/E del 16/09/2016: capitale caso morte, rendimento comunque tassato
A22: • Agenzia delle Entrate, Circolare n. 7/E del 04/06/2025: bollo 0,20% su ramo III e V versato ogni anno dal 2025 (L. 207/2024, art. 1 c. 87)
... A35: Il file si ricalcola da solo: niente macro, solo formule. Se un input è fuori campo, le celle mostrano un messaggio, non un numero.

Sheet 1 - Il tuo confronto
A1: Il tuo confronto: polizza d'investimento contro ETF, stesso mercato
A2: Strumento informativo / divulgativo. NON è consulenza finanziaria. I valori sono indicativi al 2026 e vanno verificati col tuo consulente.
A4: I tuoi numeri (celle gialle)
A5: Capitale iniziale (premio unico) | B5: 50000 | C5: Caso del video: 50.000 €
A6: Versamento aggiuntivo ogni anno (a fine anno) | B6: 0 | C6: 0 = solo premio unico, come nel video
A7: Anni di durata | B7: 20 | C7: Da 1 a 40 anni interi
A8: Rendimento lordo annuo, prima dei costi (uguale per tutti) | B8: 0.05 | C8: Ipotesi didattica: stesso mercato per polizza ed ETF. Prova anche il 3%
A9: Costo annuo della polizza (incidenza annuale dei costi, dal KID) | B9: 0.029 | C9: Default: media IVASS unit linked 2,9% (ramo I 1,7%, multiramo 2,5%). Misurata sul periodo raccomandato, qui usata per tutti gli anni: approssimazione
A10: Costo annuo dell'ETF, tutto compreso | B10: 0.002 | C10: Costo annuo del fondo 0,14-0,20% per un azionario globale; 0,20% include per prudenza commissioni e spread
A11: Imposta sul guadagno | B11: 0.26 | C11: Agenzia Entrate, Circ. 19/E/2014: si paga all'uscita, sul guadagno
A12: Imposta sulla parte in titoli di Stato | B12: 0.125 | C12: Circ. 19/E/2014: quota titoli di Stato al 12,5%
A13: Quota in titoli di Stato della polizza | B13: 0 | C13: Incerto: dipende dagli attivi della gestione (ramo I spesso alta). 0% = come nel video
A14: Quota in titoli di Stato dell'ETF | B14: 0 | C14: Azionario: 0%. Un ETF di titoli di Stato: vicino al 100%
A15: Imposta di bollo annua | B15: 0.002 | C15: Agenzia Entrate, Circ. 7/E/2025: 0,20% l'anno su unit linked e dossier titoli
A16: Conta il bollo nel calcolo? | B16: no | C16: «no» = come nel video: lo pagano sia la unit linked sia l'ETF, quindi pesa su entrambi
A17: La polizza paga il bollo? | B17: sì | C17: Ramo III e multiramo sì; ramo I no (dedotto dal testo della norma, non scritto in modo esplicito)
A19: Penale di riscatto se esci alla fine dell'anno (dal tuo contratto)
A20: Fine dell'anno | B20: Anno 1 | C20: Anno 2 | D20: Anno 3 | E20: Anno 4 | F20: Anno 5 | G20: Anno 6 | H20: Anno 7 | I20: Anno 8 | J20: Anno 9 | K20: Anno 10
A21: Penale sul valore di riscatto | B21: 0.02 | C21: 0.015 | D21: 0 | E21: 0 | F21: 0 | G21: 0 | H21: 0 | I21: 0 | J21: 0 | K21: 0
A22: Default: penali del Prodotto A (KID del 22/11/2025): 2,00% dopo 1 anno, 1,50% dopo 2, zero dal terzo. Il KID non dice se «1 anno» vuol dire fine del primo o del secondo anno: qui fine del primo. Dall'anno 11 la penale è zero. La penale non tocca il capitale finale a scadenza.
A24: Risultati
A25: Voce | B25: ETF | C25: Polizza | D25: Differenza (polizza − ETF)
A26: Totale versato | B26: =IFERROR(IF($B$83,INDEX($B$92:$B$132,$B$7+1),"controlla le celle gialle del foglio 1"),"controlla le celle gialle del foglio 1") -> 50000 | C26: =IFERROR(B26,"controlla le celle gialle del foglio 1") -> 50000
A27: Capitale finale prima delle imposte | B27: =IFERROR(IF($B$83,INDEX($C$92:$C$132,$B$7+1),"controlla le celle gialle del foglio 1"),"controlla le celle gialle del foglio 1") -> 127701.4 | C27: =IFERROR(IF($B$83,INDEX($D$92:$D$132,$B$7+1),"controlla le celle gialle del foglio 1"),"controlla le celle gialle del foglio 1") -> 75767.829 | D27: =IFERROR(C27-B27,"controlla le celle gialle del foglio 1") -> -51933.57
A28: Imposta sul guadagno, all'uscita | B28: =IFERROR(MAX(0,B27-B26)*$B$84,"controlla le celle gialle del foglio 1") -> 20202.364 | C28: =IFERROR(MAX(0,C27-C26)*$B$85,"controlla le celle gialle del foglio 1") -> 6699.6357 | D28: =IFERROR(C28-B28,"controlla le celle gialle del foglio 1") -> -13502.728
A29: Capitale finale dopo le imposte | B29: =IFERROR(B27-B28,"controlla le celle gialle del foglio 1") -> 107499.04 | C29: =IFERROR(C27-C28,"controlla le celle gialle del foglio 1") -> 69068.194 | D29: =IFERROR(C29-B29,"controlla le celle gialle del foglio 1") -> -38430.842
A30: Guadagno netto | B30: =IFERROR(B29-B26,"controlla le celle gialle del foglio 1") -> 57499.036 | C30: =IFERROR(C29-C26,"controlla le celle gialle del foglio 1") -> 19068.194 | D30: =IFERROR(C30-B30,"controlla le celle gialle del foglio 1") -> -38430.842
A31: Euro persi con la polizza, prima delle imposte | B31: =IFERROR(B27-C27,"controlla le celle gialle del foglio 1") -> 51933.57
A32: Euro persi con la polizza, dopo le imposte | B32: =IFERROR(B29-C29,"controlla le celle gialle del foglio 1") -> 38430.842
A33: L'ETF finisce a … volte la polizza (prima delle imposte) | B33: =IFERROR(B27/C27,"controlla le celle gialle del foglio 1") -> 1.6854304
A34: Costo come riduzione del rendimento: capitale × (1 + rendimento − costo)^anni. Imposta sul guadagno pagata una volta sola all'uscita, per polizza ed ETF ad accumulazione. Nessun riscatto anticipato a scadenza: per l'uscita prima vedi il foglio 2.
A36: Anno per anno
A37: Anno | B37: Versato | C37: ETF prima delle imposte | D37: Polizza prima delle imposte | E37: Differenza | F37: ETF netto se vendi | G37: Polizza netta se riscatti (con penale) | H37: Differenza netta
A38: =IFERROR(IF(OR(NOT($B$83),0>$B$7),"",0),"controlla le celle gialle del foglio 1") -> 0 | B38: =IFERROR(IF($A38="","",$B$92),"controlla le celle gialle del foglio 1") -> 50000 | C38: =IFERROR(IF($A38="","",$C$92),"controlla le celle gialle del foglio 1") -> 50000 | D38: =IFERROR(IF($A38="","",$D$92),"controlla le celle gialle del foglio 1") -> 50000 | E38: =IFERROR(IF($A38="","",D38-C38),"controlla le celle gialle del foglio 1") -> 0 | F38: =IFERROR(IF($A38="","",$H$92),"controlla le celle gialle del foglio 1") -> 50000 | G38: =IFERROR(IF($A38="","",$J$92),"controlla le celle gialle del foglio 1") -> 50000 | H38: =IFERROR(IF($A38="","",G38-F38),"controlla le celle gialle del foglio 1") -> 0
A39: =IFERROR(IF(OR(NOT($B$83),1>$B$7),"",1),"controlla le celle gialle del foglio 1") -> 1 | B39: =IFERROR(IF($A39="","",$B$93),"controlla le celle gialle del foglio 1") -> 50000 | C39: =IFERROR(IF($A39="","",$C$93),"controlla le celle gialle del foglio 1") -> 52400 | D39: =IFERROR(IF($A39="","",$D$93),"controlla le celle gialle del foglio 1") -> 51050 | E39: =IFERROR(IF($A39="","",D39-C39),"controlla le celle gialle del foglio 1") -> -1350 | F39: =IFERROR(IF($A39="","",$H$93),"controlla le celle gialle del foglio 1") -> 51776 | G39: =IFERROR(IF($A39="","",$J$93),"controlla le celle gialle del foglio 1") -> 50021.46 | H39: =IFERROR(IF($A39="","",G39-F39),"controlla le celle gialle del foglio 1") -> -1754.54
A40: =IFERROR(IF(OR(NOT($B$83),2>$B$7),"",2),"controlla le celle gialle del foglio 1") -> 2 | B40: =IFERROR(IF($A40="","",$B$94),"controlla le celle gialle del foglio 1") -> 50000 | C40: =IFERROR(IF($A40="","",$C$94),"controlla le celle gialle del foglio 1") -> 54915.2 | D40: =IFERROR(IF($A40="","",$D$94),"controlla le celle gialle del foglio 1") -> 52122.05 | E40: =IFERROR(IF($A40="","",D40-C40),"controlla le celle gialle del foglio 1") -> -2793.15 | F40: =IFERROR(IF($A40="","",$H$94),"controlla le celle gialle del foglio 1") -> 53637.248 | G40: =IFERROR(IF($A40="","",$J$94),"controlla le celle gialle del foglio 1") -> 50991.762 | H40: =IFERROR(IF($A40="","",G40-F40),"controlla le celle gialle del foglio 1") -> -2645.4858
A41: =IFERROR(IF(OR(NOT($B$83),3>$B$7),"",3),"controlla le celle gialle del foglio 1") -> 3 | B41: =IFERROR(IF($A41="","",$B$95),"controlla le celle gialle del foglio 1") -> 50000 | C41: =IFERROR(IF($A41="","",$C$95),"controlla le celle gialle del foglio 1") -> 57551.13 | D41: =IFERROR(IF($A41="","",$D$95),"controlla le celle gialle del foglio 1") -> 53216.613 | E41: =IFERROR(IF($A41="","",D41-C41),"controlla le celle gialle del foglio 1") -> -4334.5165 | F41: =IFERROR(IF($A41="","",$H$95),"controlla le celle gialle del foglio 1") -> 55587.836 | G41: =IFERROR(IF($A41="","",$J$95),"controlla le celle gialle del foglio 1") -> 52380.294 | H41: =IFERROR(IF($A41="","",G41-F41),"controlla le celle gialle del foglio 1") -> -3207.5422
A42: =IFERROR(IF(OR(NOT($B$83),4>$B$7),"",4),"controlla le celle gialle del foglio 1") -> 4 | B42: =IFERROR(IF($A42="","",$B$96),"controlla le celle gialle del foglio 1") -> 50000 | C42: =IFERROR(IF($A42="","",$C$96),"controlla le celle gialle del foglio 1") -> 60313.584 | D42: =IFERROR(IF($A42="","",$D$96),"controlla le celle gialle del foglio 1") -> 54334.162 | E42: =IFERROR(IF($A42="","",D42-C42),"controlla le celle gialle del foglio 1") -> -5979.4219 | F42: =IFERROR(IF($A42="","",$H$96),"controlla le celle gialle del foglio 1") -> 57632.052 | G42: =IFERROR(IF($A42="","",$J$96),"controlla le celle gialle del foglio 1") -> 53207.28 | H42: =IFERROR(IF($A42="","",G42-F42),"controlla le celle gialle del foglio 1") -> -4424.7722
A43: =IFERROR(IF(OR(NOT($B$83),5>$B$7),"",5),"controlla le celle gialle del foglio 1") -> 5 | B43: =IFERROR(IF($A43="","",$B$97),"controlla le celle gialle del foglio 1") -> 50000 | C43: =IFERROR(IF($A43="","",$C$97),"controlla le celle gialle del foglio 1") -> 63208.636 | D43: =IFERROR(IF($A43="","",$D$97),"controlla le celle gialle del foglio 1") -> 55475.179 | E43: =IFERROR(IF($A43="","",D43-C43),"controlla le celle gialle del foglio 1") -> -7733.4565 | F43: =IFERROR(IF($A43="","",$H$97),"controlla le celle gialle del foglio 1") -> 59774.391 | G43: =IFERROR(IF($A43="","",$J$97),"controlla le celle gialle del foglio 1") -> 54051.633 | H43: =IFERROR(IF($A43="","",G43-F43),"controlla le celle gialle del foglio 1") -> -5722.7578
A44: =IFERROR(IF(OR(NOT($B$83),6>$B$7),"",6),"controlla le celle gialle del foglio 1") -> 6 | B44: =IFERROR(IF($A44="","",$B$98),"controlla le celle gialle del foglio 1") -> 50000 | C44: =IFERROR(IF($A44="","",$C$98),"controlla le celle gialle del foglio 1") -> 66242.65 | D44: =IFERROR(IF($A44="","",$D$98),"controlla le celle gialle del foglio 1") -> 56640.158 | E44: =IFERROR(IF($A44="","",D44-C44),"controlla le celle gialle del foglio 1") -> -9602.4923 | F44: =IFERROR(IF($A44="","",$H$98),"controlla le celle gialle del foglio 1") -> 62019.561 | G44: =IFERROR(IF($A44="","",$J$98),"controlla le celle gialle del foglio 1") -> 54913.717 | H44: =IFERROR(IF($A44="","",G44-F44),"controlla le celle gialle del foglio 1") -> -7105.8443
...

Sheet 2 - Uscire prima
A1: Uscire prima: quanto costa il riscatto nei primi anni
A2: Strumento informativo / divulgativo. NON è consulenza finanziaria. I valori sono indicativi al 2026 e vanno verificati col tuo consulente.
A4: Costi di uscita dai KID di tre prodotti venduti allo sportello (esempio del KID: 10.000 €)
A5: Prodotto | B5: Costo totale se esci dopo 1 anno | C5: Costo annuo sul periodo raccomandato | D5: Periodo raccomandato (anni) | E5: Penali di riscatto | F5: Fonte
A6: Prodotto A (unit linked / multiramo) | B6: 0.06 | C6: 0.04 | D6: 8 | E6: 2,00% dopo 1 anno; 1,50% dopo 2; zero dal 3° | F6: KID del 22/11/2025: dipende dall'opzione, 2,7%-6,0% a 1 anno e 0,6%-4,0% l'anno sul periodo raccomandato (qui il valore massimo)
A7: Prodotto B (multiramo) | B7: 0.035 | C7: 0.019 | D7: 10 | E7: nessuna al periodo raccomandato; anno per anno non pubblicate nel KID | F7: KID del 18/12/2025: 346 € dopo 1 anno, 2.006 € in 10 anni su 10.000 €
A8: Prodotto C (ramo I, gestione separata) | B8: 0.052 | C8: 0.016 | D8: 8 | E8: anno per anno non pubblicate nel KID; costi concentrati nei primi anni | F8: KID del 14/04/2025: 509 € dopo 1 anno, 1.324 € sul periodo raccomandato su 10.000 €
A9: Il vostro prodotto (dal vostro KID) | B9: 0.035 | C9: 0.019 | D9: 10 | E9: Tabella «Andamento dei costi nel tempo» del KID. Le penali anno per anno vanno nel foglio 1, riga 21
A11: Il costo del primo anno sul vostro capitale (foglio 1)
A12: Prodotto | B12: Costo se esci dopo 1 anno | C12: Con l'ETF, lo stesso anno | D12: Differenza
A13: =IFERROR(A6,"controlla le celle gialle del foglio 1") -> Prodotto A (unit linked / multiramo) | B13: =IFERROR('1 - Il tuo confronto'!$B$5*B6,"controlla le celle gialle del foglio 1") -> 3000 | C13: =IFERROR('1 - Il tuo confronto'!$B$5*'1 - Il tuo confronto'!$B$10,"controlla le celle gialle del foglio 1") -> 100 | D13: =IFERROR(B13-C13,"controlla le celle gialle del foglio 1") -> 2900
A14: =IFERROR(A7,"controlla le celle gialle del foglio 1") -> Prodotto B (multiramo) | B14: =IFERROR('1 - Il tuo confronto'!$B$5*B7,"controlla le celle gialle del foglio 1") -> 1750 | C14: =IFERROR('1 - Il tuo confronto'!$B$5*'1 - Il tuo confronto'!$B$10,"controlla le celle gialle del foglio 1") -> 100 | D14: =IFERROR(B14-C14,"controlla le celle gialle del foglio 1") -> 1650
A15: =IFERROR(A8,"controlla le celle gialle del foglio 1") -> Prodotto C (ramo I, gestione separata) | B15: =IFERROR('1 - Il tuo confronto'!$B$5*B8,"controlla le celle gialle del foglio 1") -> 2600 | C15: =IFERROR('1 - Il tuo confronto'!$B$5*'1 - Il tuo confronto'!$B$10,"controlla le celle gialle del foglio 1") -> 100 | D15: =IFERROR(B15-C15,"controlla le celle gialle del foglio 1") -> 2500
A16: =IFERROR(A9,"controlla le celle gialle del foglio 1") -> Il vostro prodotto (dal vostro KID) | B16: =IFERROR('1 - Il tuo confronto'!$B$5*B9,"controlla le celle gialle del foglio 1") -> 1750 | C16: =IFERROR('1 - Il tuo confronto'!$B$5*'1 - Il tuo confronto'!$B$10,"controlla le celle gialle del foglio 1") -> 100 | D16: =IFERROR(B16-C16,"controlla le celle gialle del foglio 1") -> 1650
A17: Costo totale del primo anno come nel KID (ingresso, uscita e costi correnti), applicato al capitale del foglio 1. Per il Prodotto A è il massimo fra le opzioni.
A19: Riscatto anno per anno contro l'ETF (numeri e penali del foglio 1)
A20: Fine dell'anno | B20: Penale | C20: Penale in euro | D20: Polizza prima della penale | E20: Riscatto dopo la penale | F20: Polizza netta dopo le imposte | G20: ETF netto se vendi | H20: Distanza netta (polizza − ETF)
A21: =IFERROR(IF(A38="","",A38),"controlla le celle gialle del foglio 1") -> 1 | B21: =IFERROR(IF($A21="","",B38),"controlla le celle gialle del foglio 1") -> 0.02 | C21: =IFERROR(IF($A21="","",C38*B38),"controlla le celle gialle del foglio 1") -> 1021 | D21: =IFERROR(IF($A21="","",C38),"controlla le celle gialle del foglio 1") -> 51050 | E21: =IFERROR(IF($A21="","",D38),"controlla le celle gialle del foglio 1") -> 50029 | F21: =IFERROR(IF($A21="","",E38),"controlla le celle gialle del foglio 1") -> 50021.46 | G21: =IFERROR(IF($A21="","",F38),"controlla le celle gialle del foglio 1") -> 51776 | H21: =IFERROR(IF($A21="","",F21-G21),"controlla le celle gialle del foglio 1") -> -1754.54
A22: =IFERROR(IF(A39="","",A39),"controlla le celle gialle del foglio 1") -> 2 | B22: =IFERROR(IF($A22="","",B39),"controlla le celle gialle del foglio 1") -> 0.015 | C22: =IFERROR(IF($A22="","",C39*B39),"controlla le celle gialle del foglio 1") -> 781.83075 | D22: =IFERROR(IF($A22="","",C39),"controlla le celle gialle del foglio 1") -> 52122.05 | E22: =IFERROR(IF($A22="","",D39),"controlla le celle gialle del foglio 1") -> 51340.219 | F22: =IFERROR(IF($A22="","",E39),"controlla le celle gialle del foglio 1") -> 50991.762 | G22: =IFERROR(IF($A22="","",F39),"controlla le celle gialle del foglio 1") -> 53637.248 | H22: =IFERROR(IF($A22="","",F22-G22),"controlla le celle gialle del foglio 1") -> -2645.4858
A23: =IFERROR(IF(A40="","",A40),"controlla le celle gialle del foglio 1") -> 3 | B23: =IFERROR(IF($A23="","",B40),"controlla le celle gialle del foglio 1") -> 0 | C23: =IFERROR(IF($A23="","",C40*B40),"controlla le celle gialle del foglio 1") -> 0 | D23: =IFERROR(IF($A23="","",C40),"controlla le celle gialle del foglio 1") -> 53216.613 | E23: =IFERROR(IF($A23="","",D40),"controlla le celle gialle del foglio 1") -> 53216.613 | F23: =IFERROR(IF($A23="","",E40),"controlla le celle gialle del foglio 1") -> 52380.294 | G23: =IFERROR(IF($A23="","",F40),"controlla le celle gialle del foglio 1") -> 55587.836 | H23: =IFERROR(IF($A23="","",F23-G23),"controlla le celle gialle del foglio 1") -> -3207.5422
A24: =IFERROR(IF(A41="","",A41),"controlla le celle gialle del foglio 1") -> 4 | B24: =IFERROR(IF($A24="","",B41),"controlla le celle gialle del foglio 1") -> 0 | C24: =IFERROR(IF($A24="","",C41*B41),"controlla le celle gialle del foglio 1") -> 0 | D24: =IFERROR(IF($A24="","",C41),"controlla le celle gialle del foglio 1") -> 54334.162 | E24: =IFERROR(IF($A24="","",D41),"controlla le celle gialle del foglio 1") -> 54334.162 | F24: =IFERROR(IF($A24="","",E41),"controlla le celle gialle del foglio 1") -> 53207.28 | G24: =IFERROR(IF($A24="","",F41),"controlla le celle gialle del foglio 1") -> 57632.052 | H24: =IFERROR(IF($A24="","",F24-G24),"controlla le celle gialle del foglio 1") -> -4424.7722
A25: =IFERROR(IF(A42="","",A42),"controlla le celle gialle del foglio 1") -> 5 | B25: =IFERROR(IF($A25="","",B42),"controlla le celle gialle del foglio 1") -> 0 | C25: =IFERROR(IF($A25="","",C42*B42),"controlla le celle gialle del foglio 1") -> 0 | D25: =IFERROR(IF($A25="","",C42),"controlla le celle gialle del foglio 1") -> 55475.179 | E25: =IFERROR(IF($A25="","",D42),"controlla le celle gialle del foglio 1") -> 55475.179 | F25: =IFERROR(IF($A25="","",E42),"controlla le celle gialle del foglio 1") -> 54051.633 | G25: =IFERROR(IF($A25="","",F42),"controlla le celle gialle del foglio 1") -> 59774.391 | H25: =IFERROR(IF($A25="","",F25-G25),"controlla le celle gialle del foglio 1") -> -5722.7578
A26: =IFERROR(IF(A43="","",A43),"controlla le celle gialle del foglio 1") -> 6 | B26: =IFERROR(IF($A26="","",B43),"controlla le celle gialle del foglio 1") -> 0 | C26: =IFERROR(IF($A26="","",C43*B43),"controlla le celle gialle del foglio 1") -> 0 | D26: =IFERROR(IF($A26="","",C43),"controlla le celle gialle del foglio 1") -> 56640.158 | E26: =IFERROR(IF($A26="","",D43),"controlla le celle gialle del foglio 1") -> 56640.158 | F26: =IFERROR(IF($A26="","",E43),"controlla le celle gialle del foglio 1") -> 54913.717 | G26: =IFERROR(IF($A26="","",F43),"controlla le celle gialle del foglio 1") -> 62019.561 | H26: =IFERROR(IF($A26="","",F26-G26),"controlla le celle gialle del foglio 1") -> -7105.8443
A27: =IFERROR(IF(A44="","",A44),"controlla le celle gialle del foglio 1") -> 7 | B27: =IFERROR(IF($A27="","",B44),"controlla le celle gialle del foglio 1") -> 0 | C27: =IFERROR(IF($A27="","",C44*B44),"controlla le celle gialle del foglio 1") -> 0 | D27: =IFERROR(IF($A27="","",C44),"controlla le celle gialle del foglio 1") -> 57829.601 | E27: =IFERROR(IF($A27="","",D44),"controlla le celle gialle del foglio 1") -> 57829.601 | F27: =IFERROR(IF($A27="","",E44),"controlla le celle gialle del foglio 1") -> 55793.905 | G27: =IFERROR(IF($A27="","",F44),"controlla le celle gialle del foglio 1") -> 64372.5 | H27: =IFERROR(IF($A27="","",F27-G27),"controlla le celle gialle del foglio 1") -> -8578.5952
A28: =IFERROR(IF(A45="","",A45),"controlla le celle gialle del foglio 1") -> 8 | B28: =IFERROR(IF($A28="","",B45),"controlla le celle gialle del foglio 1") -> 0 | C28: =IFERROR(IF($A28="","",C45*B45),"controlla le celle gialle del foglio 1") -> 0 | D28: =IFERROR(IF($A28="","",C45),"controlla le celle gialle del foglio 1") -> 59044.023 | E28: =IFERROR(IF($A28="","",D45),"controlla le celle gialle del foglio 1") -> 59044.023 | F28: =IFERROR(IF($A28="","",E45),"controlla le celle gialle del foglio 1") -> 56692.577 | G28: =IFERROR(IF($A28="","",F45),"controlla le celle gialle del foglio 1") -> 66838.38 | H28: =IFERROR(IF($A28="","",F28-G28),"controlla le celle gialle del foglio 1") -> -10145.803
A29: =IFERROR(IF(A46="","",A46),"controlla le celle gialle del foglio 1") -> 9 | B29: =IFERROR(IF($A29="","",B46),"controlla le celle gialle del foglio 1") -> 0 | C29: =IFERROR(IF($A29="","",C46*B46),"controlla le celle gialle del foglio 1") -> 0 | D29: =IFERROR(IF($A29="","",C46),"controlla le celle gialle del foglio 1") -> 60283.948 | E29: =IFERROR(IF($A29="","",D46),"controlla le celle gialle del foglio 1") -> 60283.948 | F29: =IFERROR(IF($A29="","",E46),"controlla le celle gialle del foglio 1") -> 57610.121 | G29: =IFERROR(IF($A29="","",F46),"controlla le celle gialle del foglio 1") -> 69422.622 | H29: =IFERROR(IF($A29="","",F29-G29),"controlla le celle gialle del foglio 1") -> -11812.501
A30: =IFERROR(IF(A47="","",A47),"controlla le celle gialle del foglio 1") -> 10 | B30: =IFERROR(IF($A30="","",B47),"controlla le celle gialle del foglio 1") -> 0 | C30: =IFERROR(IF($A30="","",C47*B47),"controlla le celle gialle del foglio 1") -> 0 | D30: =IFERROR(IF($A30="","",C47),"controlla le celle gialle del foglio 1") -> 61549.91 | E30: =IFERROR(IF($A30="","",D47),"controlla le celle gialle del foglio 1") -> 61549.91 | F30: =IFERROR(IF($A30="","",E47),"controlla le celle gialle del foglio 1") -> 58546.934 | G30: =IFERROR(IF($A30="","",F47),"controlla le celle gialle del foglio 1") -> 72130.908 | H30: =IFERROR(IF($A30="","",F30-G30),"controlla le celle gialle del foglio 1") -> -13583.975
A31: Imposta al riscatto: 26% (o l'aliquota del foglio 1) sul guadagno, calcolato dopo la penale. Righe vuote oltre la durata del foglio 1. Anche senza penale, nei primi anni i costi d'ingresso pesano di più (colonna B della tabella in alto).
A35: Motore del calcolo — non modificare
A36: Calcoli intermedi usati dalle celle verdi qui sopra: si possono leggere, non vanno modificati.
A37: Anno | B37: Penale | C37: Polizza | D37: Riscatto | E37: Polizza netta | F37: ETF netto
A38: =IF(OR(NOT('1 - Il tuo confronto'!$B$83),1>'1 - Il tuo confronto'!$B$7),"",1) -> 1 | B38: ='1 - Il tuo confronto'!$E$93 -> 0.02 | C38: ='1 - Il tuo confronto'!$D$93 -> 51050 | D38: ='1 - Il tuo confronto'!$F$93 -> 50029 | E38: ='1 - Il tuo confronto'!$J$93 -> 50021.46 | F38: ='1 - Il tuo confronto'!$H$93 -> 51776
A39: =IF(OR(NOT('1 - Il tuo confronto'!$B$83),2>'1 - Il tuo confronto'!$B$7),"",2) -> 2 | B39: ='1 - Il tuo confronto'!$E$94 -> 0.015 | C39: ='1 - Il tuo confronto'!$D$94 -> 52122.05 | D39: ='1 - Il tuo confronto'!$F$94 -> 51340.219 | E39: ='1 - Il tuo confronto'!$J$94 -> 50991.762 | F39: ='1 - Il tuo confronto'!$H$94 -> 53637.248
A40: =IF(OR(NOT('1 - Il tuo confronto'!$B$83),3>'1 - Il tuo confronto'!$B$7),"",3) -> 3 | B40: ='1 - Il tuo confronto'!$E$95 -> 0 | C40: ='1 - Il tuo confronto'!$D$95 -> 53216.613 | D40: ='1 - Il tuo confronto'!$F$95 -> 53216.613 | E40: ='1 - Il tuo confronto'!$J$95 -> 52380.294 | F40: ='1 - Il tuo confronto'!$H$95 -> 55587.836
A41: =IF(OR(NOT('1 - Il tuo confronto'!$B$83),4>'1 - Il tuo confronto'!$B$7),"",4) -> 4 | B41: ='1 - Il tuo confronto'!$E$96 -> 0 | C41: ='1 - Il tuo confronto'!$D$96 -> 54334.162 | D41: ='1 - Il tuo confronto'!$F$96 -> 54334.162 | E41: ='1 - Il tuo confronto'!$J$96 -> 53207.28 | F41: ='1 - Il tuo confronto'!$H$96 -> 57632.052
A42: =IF(OR(NOT('1 - Il tuo confronto'!$B$83),5>'1 - Il tuo confronto'!$B$7),"",5) -> 5 | B42: ='1 - Il tuo confronto'!$E$97 -> 0 | C42: ='1 - Il tuo confronto'!$D$97 -> 55475.179 | D42: ='1 - Il tuo confronto'!$F$97 -> 55475.179 | E42: ='1 - Il tuo confronto'!$J$97 -> 54051.633 | F42: ='1 - Il tuo confronto'!$H$97 -> 59774.391
A43: =IF(OR(NOT('1 - Il tuo confronto'!$B$83),6>'1 - Il tuo confronto'!$B$7),"",6) -> 6 | B43: ='1 - Il tuo confronto'!$E$98 -> 0 | C43: ='1 - Il tuo confronto'!$D$98 -> 56640.158 | D43: ='1 - Il tuo confronto'!$F$98 -> 56640.158 | E43: ='1 - Il tuo confronto'!$J$98 -> 54913.717 | F43: ='1 - Il tuo confronto'!$H$98 -> 62019.561
A44: =IF(OR(NOT('1 - Il tuo confronto'!$B$83),7>'1 - Il tuo confronto'!$B$7),"",7) -> 7 | B44: ='1 - Il tuo confronto'!$E$99 -> 0 | C44: ='1 - Il tuo confronto'!$D$99 -> 57829.601 | D44: ='1 - Il tuo confronto'!$F$99 -> 57829.601 | E44: ='1 - Il tuo confronto'!$J$99 -> 55793.905 | F44: ='1 - Il tuo confronto'!$H$99 -> 64372.5
A45: =IF(OR(NOT('1 - Il tuo confronto'!$B$83),8>'1 - Il tuo confronto'!$B$7),"",8) -> 8 | B45: ='1 - Il tuo confronto'!$E$100 -> 0 | C45: ='1 - Il tuo confronto'!$D$100 -> 59044.023 | D45: ='1 - Il tuo confronto'!$F$100 -> 59044.023 | E45: ='1 - Il tuo confronto'!$J$100 -> 56692.577 | F45: ='1 - Il tuo confronto'!$H$100 -> 66838.38
A46: =IF(OR(NOT('1 - Il tuo confronto'!$B$83),9>'1 - Il tuo confronto'!$B$7),"",9) -> 9 | B46: ='1 - Il tuo confronto'!$E$101 -> 0 | C46: ='1 - Il tuo confronto'!$D$101 -> 60283.948 | D46: ='1 - Il tuo confronto'!$F$101 -> 60283.948 | E46: ='1 - Il tuo confronto'!$J$101 -> 57610.121 | F46: ='1 - Il tuo confronto'!$H$101 -> 69422.622
...

Sheet 3 - Le medie IVASS
A1: Le medie IVASS: quanto costano le polizze d'investimento
A2: Strumento informativo / divulgativo. NON è consulenza finanziaria. I valori sono indicativi al 2026 e vanno verificati col tuo consulente.
A4: Dati ufficiali IVASS (celle bianche: non modificare)
A5: Voce | B5: Ramo I (rivalutabili) | C5: Multiramo | D5: Unit linked | E5: Fonte
A6: Costo totale annuo medio (RIY, scenario moderato, sul periodo raccomandato) | B6: 0.017 | C6: 0.025 | D6: 0.029 | E6: IVASS, Bollettino statistico n. 4/2025 (novembre 2025), cap. 9: KID al 15/09/2025, 529 prodotti
A7: Periodo di detenzione raccomandato medio (anni) | B7: 7.9 | C7: 7.7 | D7: 9.2 | E7: IVASS, Bollettino statistico n. 4/2025 (novembre 2025), cap. 9: KID al 15/09/2025, 529 prodotti
A8: Rendimento netto atteso medio (scenario moderato del KID) | B8: 0.016 | C8: 0.027 | D8: 0.03 | E8: IVASS, Bollettino statistico n. 4/2025 (novembre 2025), cap. 9: KID al 15/09/2025, 529 prodotti
A9: Tasso di riscatto 2024 (ramo I e ramo III) | B9: 0.095 | C9: n.d. | D9: 0.121 | E9: IVASS, Bollettino statistico n. 4/2025 (novembre 2025), cap. 9: KID al 15/09/2025, 529 prodotti (la colonna unit linked è il ramo III)
A11: Altri dati ufficiali
A12: Voce | B12: Valore | C12: Fonte
A13: Raccolta vita 2024 passata da sportelli bancari e postali | B13: 0.721 | C13: IVASS, Bollettino statistico n. 4/2025 (novembre 2025), cap. 9: KID al 15/09/2025, 529 prodotti
A14: Unit linked e multiramo: costo medio più alto nel canale bancario | B14: sì | C14: IVASS, Bollettino statistico n. 4/2025 (novembre 2025), cap. 9: KID al 15/09/2025, 529 prodotti
A15: Fondi esterni contro fondi interni: costo in più (punti) | B15: 0.008 | C15: IVASS, Bollettino statistico n. 4/2025 (novembre 2025), cap. 9: KID al 15/09/2025, 529 prodotti, fig. 25
A16: Gestioni separate 2025: rendimento medio lordo | B16: 0.03 | C16: IVASS, Relazione annuale sull'attività 2025 (18/06/2026)
A17: Gestioni separate 2025: rendimento passato agli assicurati | B17: 0.019 | C17: IVASS, Relazione annuale sull'attività 2025 (18/06/2026)
A18: Gestioni separate 2025: quota trattenuta sul rendimento | B18: 0.356 | C18: IVASS, Relazione annuale sull'attività 2025 (18/06/2026)
A19: BTP decennale 2025, rendimento medio | B19: 0.036 | C19: IVASS, Relazione annuale sull'attività 2025 (18/06/2026)
A20: Inflazione 2025 | B20: 0.014 | C20: IVASS, Relazione annuale sull'attività 2025 (18/06/2026)
A21: Confronto con i costi medi (capitale, versamenti, anni e imposta del foglio 1)
A22: Secondo rendimento lordo (scenario prudente) | B22: 0.03 | C22: Vicino al lordo 2025 delle gestioni separate. Il primo rendimento è quello del foglio 1
A23: Costo annuo di un portafoglio ETF 60/40 | B23: 0.0012 | C23: 60% azionario globale a 0,14% + 40% obbligazionario globale a 0,10%
A25: Strumento | B25: Costo annuo | C25: Capitale finale al rendimento del foglio 1 | D25: Distanza dall'ETF | E25: Capitale finale al secondo rendimento | F25: Distanza dall'ETF (secondo) | G25: Netto dopo l'imposta (foglio 1) | H25: Distanza netta
A26: ETF, costo del foglio 1 | B26: =IFERROR('1 - Il tuo confronto'!$B$10,"controlla le celle gialle del foglio 1") -> 0.002 | C26: =IFERROR(IF('1 - Il tuo confronto'!$B$83,C39,"controlla le celle gialle del foglio 1"),"controlla le celle gialle del foglio 1") -> 127701.4 | D26: =IFERROR(C26-$C$26,"controlla le celle gialle del foglio 1") -> 0 | E26: =IFERROR(IF('1 - Il tuo confronto'!$B$83,D39,"controlla le celle gialle del foglio 1"),"controlla le celle gialle del foglio 1") -> 86862.495 | F26: =IFERROR(E26-$E$26,"controlla le celle gialle del foglio 1") -> 0 | G26: =IFERROR(IF('1 - Il tuo confronto'!$B$83,E39,"controlla le celle gialle del foglio 1"),"controlla le celle gialle del foglio 1") -> 107499.04 | H26: =IFERROR(G26-$G$26,"controlla le celle gialle del foglio 1") -> 0
A27: Portafoglio ETF 60/40 | B27: =IFERROR($B$23,"controlla le celle gialle del foglio 1") -> 0.0012 | C27: =IFERROR(IF('1 - Il tuo confronto'!$B$83,C40,"controlla le celle gialle del foglio 1"),"controlla le celle gialle del foglio 1") -> 129665.24 | D27: =IFERROR(C27-$C$26,"controlla le celle gialle del foglio 1") -> 1963.8433 | E27: =IFERROR(IF('1 - Il tuo confronto'!$B$83,D40,"controlla le celle gialle del foglio 1"),"controlla le celle gialle del foglio 1") -> 88224.482 | F27: =IFERROR(E27-$E$26,"controlla le celle gialle del foglio 1") -> 1361.9872 | G27: =IFERROR(IF('1 - Il tuo confronto'!$B$83,E40,"controlla le celle gialle del foglio 1"),"controlla le celle gialle del foglio 1") -> 108952.28 | H27: =IFERROR(G27-$G$26,"controlla le celle gialle del foglio 1") -> 1453.244
A28: Ramo I, media IVASS | B28: =IFERROR($B$6,"controlla le celle gialle del foglio 1") -> 0.017 | C28: =IFERROR(IF('1 - Il tuo confronto'!$B$83,C41,"controlla le celle gialle del foglio 1"),"controlla le celle gialle del foglio 1") -> 95714.213 | D28: =IFERROR(C28-$C$26,"controlla le celle gialle del foglio 1") -> -31987.186 | E28: =IFERROR(IF('1 - Il tuo confronto'!$B$83,D41,"controlla le celle gialle del foglio 1"),"controlla le celle gialle del foglio 1") -> 64737.945 | F28: =IFERROR(E28-$E$26,"controlla le celle gialle del foglio 1") -> -22124.549 | G28: =IFERROR(IF('1 - Il tuo confronto'!$B$83,E41,"controlla le celle gialle del foglio 1"),"controlla le celle gialle del foglio 1") -> 83828.518 | H28: =IFERROR(G28-$G$26,"controlla le celle gialle del foglio 1") -> -23670.518
A29: Prodotto B (KID, periodo raccomandato) | B29: =IFERROR('2 - Uscire prima'!$C$7,"controlla le celle gialle del foglio 1") -> 0.019 | C29: =IFERROR(IF('1 - Il tuo confronto'!$B$83,C42,"controlla le celle gialle del foglio 1"),"controlla le celle gialle del foglio 1") -> 92075.336 | D29: =IFERROR(C29-$C$26,"controlla le celle gialle del foglio 1") -> -35626.064 | E29: =IFERROR(IF('1 - Il tuo confronto'!$B$83,D42,"controlla le celle gialle del foglio 1"),"controlla le celle gialle del foglio 1") -> 62229.042 | F29: =IFERROR(E29-$E$26,"controlla le celle gialle del foglio 1") -> -24633.452 | G29: =IFERROR(IF('1 - Il tuo confronto'!$B$83,E42,"controlla le celle gialle del foglio 1"),"controlla le celle gialle del foglio 1") -> 81135.748 | H29: =IFERROR(G29-$G$26,"controlla le celle gialle del foglio 1") -> -26363.287
A30: Multiramo, media IVASS | B30: =IFERROR($C$6,"controlla le celle gialle del foglio 1") -> 0.025 | C30: =IFERROR(IF('1 - Il tuo confronto'!$B$83,C43,"controlla le celle gialle del foglio 1"),"controlla le celle gialle del foglio 1") -> 81930.822 | D30: =IFERROR(C30-$C$26,"controlla le celle gialle del foglio 1") -> -45770.578 | E30: =IFERROR(IF('1 - Il tuo confronto'!$B$83,D43,"controlla le celle gialle del foglio 1"),"controlla le celle gialle del foglio 1") -> 55244.779 | F30: =IFERROR(E30-$E$26,"controlla le celle gialle del foglio 1") -> -31617.716 | G30: =IFERROR(IF('1 - Il tuo confronto'!$B$83,E43,"controlla le celle gialle del foglio 1"),"controlla le celle gialle del foglio 1") -> 73628.808 | H30: =IFERROR(G30-$G$26,"controlla le celle gialle del foglio 1") -> -33870.227
A31: Unit linked, media IVASS | B31: =IFERROR($D$6,"controlla le celle gialle del foglio 1") -> 0.029 | C31: =IFERROR(IF('1 - Il tuo confronto'!$B$83,C44,"controlla le celle gialle del foglio 1"),"controlla le celle gialle del foglio 1") -> 75767.829 | D31: =IFERROR(C31-$C$26,"controlla le celle gialle del foglio 1") -> -51933.57 | E31: =IFERROR(IF('1 - Il tuo confronto'!$B$83,D44,"controlla le celle gialle del foglio 1"),"controlla le celle gialle del foglio 1") -> 51009.557 | F31: =IFERROR(E31-$E$26,"controlla le celle gialle del foglio 1") -> -35852.937 | G31: =IFERROR(IF('1 - Il tuo confronto'!$B$83,E44,"controlla le celle gialle del foglio 1"),"controlla le celle gialle del foglio 1") -> 69068.194 | H31: =IFERROR(G31-$G$26,"controlla le celle gialle del foglio 1") -> -38430.842
A32: Imposta sul guadagno con l'aliquota del foglio 1 (26%), senza quota titoli di Stato e senza bollo, come nel video. Per il ramo I la distanza vera è un po' più piccola: parte dei rendimenti è tassata al 12,5% e il bollo non si paga (provalo nel foglio 1, celle B13 e B17). Stesso rendimento lordo per strumenti di rischio diverso: ipotesi didattica.
A36: Motore del calcolo — non modificare
A37: Calcoli intermedi usati dalle celle verdi qui sopra: si possono leggere, non vanno modificati.
A38: Strumento | B38: Fattore al rendimento 1 | C38: Capitale 1 | D38: Capitale 2 | E38: Netto 1 | F38: Fattore al rendimento 2 | G38: Versato
A39: =A26 -> ETF, costo del foglio 1 | B39: =1+'1 - Il tuo confronto'!$B$8-B26 -> 1.048 | C39: =IF(ABS(B39-1)<0.000000000001,'1 - Il tuo confronto'!$B$5+'1 - Il tuo confronto'!$B$6*'1 - Il tuo confronto'!$B$7,'1 - Il tuo confronto'!$B$5*B39^'1 - Il tuo confronto'!$B$7+'1 - Il tuo confronto'!$B$6*(B39^'1 - Il tuo confronto'!$B$7-1)/(B39-1)) -> 127701.4 | D39: =IF(ABS(F39-1)<0.000000000001,'1 - Il tuo confronto'!$B$5+'1 - Il tuo confronto'!$B$6*'1 - Il tuo confronto'!$B$7,'1 - Il tuo confronto'!$B$5*F39^'1 - Il tuo confronto'!$B$7+'1 - Il tuo confronto'!$B$6*(F39^'1 - Il tuo confronto'!$B$7-1)/(F39-1)) -> 86862.495 | E39: =C39-MAX(0,C39-G39)*'1 - Il tuo confronto'!$B$11 -> 107499.04 | F39: =1+$B$22-B26 -> 1.028 | G39: ='1 - Il tuo confronto'!$B$5+'1 - Il tuo confronto'!$B$6*'1 - Il tuo confronto'!$B$7 -> 50000
A40: =A27 -> Portafoglio ETF 60/40 | B40: =1+'1 - Il tuo confronto'!$B$8-B27 -> 1.0488 | C40: =IF(ABS(B40-1)<0.000000000001,'1 - Il tuo confronto'!$B$5+'1 - Il tuo confronto'!$B$6*'1 - Il tuo confronto'!$B$7,'1 - Il tuo confronto'!$B$5*B40^'1 - Il tuo confronto'!$B$7+'1 - Il tuo confronto'!$B$6*(B40^'1 - Il tuo confronto'!$B$7-1)/(B40-1)) -> 129665.24 | D40: =IF(ABS(F40-1)<0.000000000001,'1 - Il tuo confronto'!$B$5+'1 - Il tuo confronto'!$B$6*'1 - Il tuo confronto'!$B$7,'1 - Il tuo confronto'!$B$5*F40^'1 - Il tuo confronto'!$B$7+'1 - Il tuo confronto'!$B$6*(F40^'1 - Il tuo confronto'!$B$7-1)/(F40-1)) -> 88224.482 | E40: =C40-MAX(0,C40-G40)*'1 - Il tuo confronto'!$B$11 -> 108952.28 | F40: =1+$B$22-B27 -> 1.0288 | G40: ='1 - Il tuo confronto'!$B$5+'1 - Il tuo confronto'!$B$6*'1 - Il tuo confronto'!$B$7 -> 50000
A41: =A28 -> Ramo I, media IVASS | B41: =1+'1 - Il tuo confronto'!$B$8-B28 -> 1.033 | C41: =IF(ABS(B41-1)<0.000000000001,'1 - Il tuo confronto'!$B$5+'1 - Il tuo confronto'!$B$6*'1 - Il tuo confronto'!$B$7,'1 - Il tuo confronto'!$B$5*B41^'1 - Il tuo confronto'!$B$7+'1 - Il tuo confronto'!$B$6*(B41^'1 - Il tuo confronto'!$B$7-1)/(B41-1)) -> 95714.213 | D41: =IF(ABS(F41-1)<0.000000000001,'1 - Il tuo confronto'!$B$5+'1 - Il tuo confronto'!$B$6*'1 - Il tuo confronto'!$B$7,'1 - Il tuo confronto'!$B$5*F41^'1 - Il tuo confronto'!$B$7+'1 - Il tuo confronto'!$B$6*(F41^'1 - Il tuo confronto'!$B$7-1)/(F41-1)) -> 64737.945 | E41: =C41-MAX(0,C41-G41)*'1 - Il tuo confronto'!$B$11 -> 83828.518 | F41: =1+$B$22-B28 -> 1.013 | G41: ='1 - Il tuo confronto'!$B$5+'1 - Il tuo confronto'!$B$6*'1 - Il tuo confronto'!$B$7 -> 50000
A42: =A29 -> Prodotto B (KID, periodo raccomandato) | B42: =1+'1 - Il tuo confronto'!$B$8-B29 -> 1.031 | C42: =IF(ABS(B42-1)<0.000000000001,'1 - Il tuo confronto'!$B$5+'1 - Il tuo confronto'!$B$6*'1 - Il tuo confronto'!$B$7,'1 - Il tuo confronto'!$B$5*B42^'1 - Il tuo confronto'!$B$7+'1 - Il tuo confronto'!$B$6*(B42^'1 - Il tuo confronto'!$B$7-1)/(B42-1)) -> 92075.336 | D42: =IF(ABS(F42-1)<0.000000000001,'1 - Il tuo confronto'!$B$5+'1 - Il tuo confronto'!$B$6*'1 - Il tuo confronto'!$B$7,'1 - Il tuo confronto'!$B$5*F42^'1 - Il tuo confronto'!$B$7+'1 - Il tuo confronto'!$B$6*(F42^'1 - Il tuo confronto'!$B$7-1)/(F42-1)) -> 62229.042 | E42: =C42-MAX(0,C42-G42)*'1 - Il tuo confronto'!$B$11 -> 81135.748 | F42: =1+$B$22-B29 -> 1.011 | G42: ='1 - Il tuo confronto'!$B$5+'1 - Il tuo confronto'!$B$6*'1 - Il tuo confronto'!$B$7 -> 50000
A43: =A30 -> Multiramo, media IVASS | B43: =1+'1 - Il tuo confronto'!$B$8-B30 -> 1.025 | C43: =IF(ABS(B43-1)<0.000000000001,'1 - Il tuo confronto'!$B$5+'1 - Il tuo confronto'!$B$6*'1 - Il tuo confronto'!$B$7,'1 - Il tuo confronto'!$B$5*B43^'1 - Il tuo confronto'!$B$7+'1 - Il tuo confronto'!$B$6*(B43^'1 - Il tuo confronto'!$B$7-1)/(B43-1)) -> 81930.822 | D43: =IF(ABS(F43-1)<0.000000000001,'1 - Il tuo confronto'!$B$5+'1 - Il tuo confronto'!$B$6*'1 - Il tuo confronto'!$B$7,'1 - Il tuo confronto'!$B$5*F43^'1 - Il tuo confronto'!$B$7+'1 - Il tuo confronto'!$B$6*(F43^'1 - Il tuo confronto'!$B$7-1)/(F43-1)) -> 55244.779 | E43: =C43-MAX(0,C43-G43)*'1 - Il tuo confronto'!$B$11 -> 73628.808 | F43: =1+$B$22-B30 -> 1.005 | G43: ='1 - Il tuo confronto'!$B$5+'1 - Il tuo confronto'!$B$6*'1 - Il tuo confronto'!$B$7 -> 50000
A44: =A31 -> Unit linked, media IVASS | B44: =1+'1 - Il tuo confronto'!$B$8-B31 -> 1.021 | C44: =IF(ABS(B44-1)<0.000000000001,'1 - Il tuo confronto'!$B$5+'1 - Il tuo confronto'!$B$6*'1 - Il tuo confronto'!$B$7,'1 - Il tuo confronto'!$B$5*B44^'1 - Il tuo confronto'!$B$7+'1 - Il tuo confronto'!$B$6*(B44^'1 - Il tuo confronto'!$B$7-1)/(B44-1)) -> 75767.829 | D44: =IF(ABS(F44-1)<0.000000000001,'1 - Il tuo confronto'!$B$5+'1 - Il tuo confronto'!$B$6*'1 - Il tuo confronto'!$B$7,'1 - Il tuo confronto'!$B$5*F44^'1 - Il tuo confronto'!$B$7+'1 - Il tuo confronto'!$B$6*(F44^'1 - Il tuo confronto'!$B$7-1)/(F44-1)) -> 51009.557 | E44: =C44-MAX(0,C44-G44)*'1 - Il tuo confronto'!$B$11 -> 69068.194 | F44: =1+$B$22-B31 -> 1.001 | G44: ='1 - Il tuo confronto'!$B$5+'1 - Il tuo confronto'!$B$6*'1 - Il tuo confronto'!$B$7 -> 50000

Sheet 4 - Quando la polizza ha senso
A1: Quando la polizza ha senso: successione e impignorabilità
A2: Strumento informativo / divulgativo. NON è consulenza finanziaria. I valori sono indicativi al 2026 e vanno verificati col tuo consulente.
A4: Successione: la stessa somma in polizza o nell'eredità (celle gialle)
A5: Patrimonio ereditario senza la polizza | B5: 1200000 | C5: Tutto ciò che entra nell'eredità (esclusi titoli di Stato e polizze)
A6: Somma pagata dalla polizza al beneficiario | B6: 300000 | C6: Il capitale che la compagnia paga alla morte
A7: Chi riceve (un solo erede che è anche il beneficiario) | B7: coniuge o figli | C7: Con più eredi la franchigia vale per ciascuno: rifai il conto per ogni erede
A8: Erede con disabilità grave (L. 104/1992)? | B8: no | C8: Sì = franchigia di 1.500.000 €
A10: Aliquote e franchigie (celle bianche)
A11: Chi riceve | B11: Aliquota | C11: Franchigia | D11: Fonte
A12: coniuge o figli | B12: 0.04 | C12: 1000000 | D12: art. 7 D.Lgs. 346/1990 come sostituito dal D.Lgs. 139/2024 (già DL 262/2006, art. 2 c. 48-49). Verificate le aliquote col vostro notaio o consulente.
A13: fratelli o sorelle | B13: 0.06 | C13: 100000 | D13: art. 7 D.Lgs. 346/1990 come sostituito dal D.Lgs. 139/2024 (già DL 262/2006, art. 2 c. 48-49). Verificate le aliquote col vostro notaio o consulente.
A14: altri parenti fino al 4° grado o affini | B14: 0.06 | C14: 0 | D14: art. 7 D.Lgs. 346/1990 come sostituito dal D.Lgs. 139/2024 (già DL 262/2006, art. 2 c. 48-49). Verificate le aliquote col vostro notaio o consulente.
A15: altri | B15: 0.08 | C15: 0 | D15: art. 7 D.Lgs. 346/1990 come sostituito dal D.Lgs. 139/2024 (già DL 262/2006, art. 2 c. 48-49). Verificate le aliquote col vostro notaio o consulente.
A16: Franchigia per disabilità grave | C16: 1500000 | D16: art. 7 D.Lgs. 346/1990 come sostituito dal D.Lgs. 139/2024 (già DL 262/2006, art. 2 c. 49-bis). Verificate col vostro notaio o consulente.
A18: Risultato
A19: Imposta di successione se la somma entra nell'eredità | B19: =IFERROR(IF($B$54,MAX(0,B5+B6-$B$52)*$B$53,"controlla le celle gialle del foglio 4"),"controlla le celle gialle") -> 20000
A20: Imposta di successione con la polizza (somma esclusa dall'attivo) | B20: =IFERROR(IF($B$54,MAX(0,B5-$B$52)*$B$53,"controlla le celle gialle del foglio 4"),"controlla le celle gialle") -> 8000
A21: Risparmio sull'imposta di successione | B21: =IFERROR(B19-B20,"controlla le celle gialle") -> 12000
A22: Stesso risparmio con titoli di Stato (anche loro esclusi dall'attivo) | B22: =IFERROR(B21,"controlla le celle gialle") -> 12000
A23: Quanto avresti in più con l'ETF sulla stessa somma (anni, rendimento e costi del foglio 1) | B23: =IFERROR(IF('1 - Il tuo confronto'!$B$83,B6*(('1 - Il tuo confronto'!$B$88/'1 - Il tuo confronto'!$B$89)^'1 - Il tuo confronto'!$B$7-1),"controlla le celle gialle del foglio 1"),"controlla le celle gialle") -> 205629.11
A24: Saldo: risparmio sulla successione − costo in più della polizza | B24: =IFERROR(B21-B23,"controlla le celle gialle") -> -193629.11
A25: Verdetto | B25: =IFERROR(IF(B24>0,"il risparmio sulla successione supera il costo in più","il costo in più della polizza supera il risparmio sulla successione"),"controlla le celle gialle") -> il costo in più della polizza supera il risparmio sulla successione
A26: Norma: art. 12 c. 1 lett. c) D.Lgs. 346/1990 fino al 31/12/2026, poi art. 97 D.Lgs. 123/2025 con lo stesso testo (art. 205 D.Lgs. 123/2025, come modificato dal DL 200/2025 conv. L. 26/2026). Il beneficiario ha un diritto proprio (art. 1920 c.c.). Restano collazione e riduzione per lesione di legittima (art. 1923 c. 2 c.c.). Il rendimento della polizza resta tassato anche alla morte (Agenzia Entrate, Ris. 76/E/2016). Costo in più calcolato prima delle imposte sul guadagno, come se la somma fosse rimasta investita per gli anni del foglio 1.
A28: Impignorabilità: cosa protegge e cosa no
A29: La regola | B29: Art. 1923 c.c.: le somme dovute dalla compagnia non possono essere pignorate né sequestrate.
A30: Limite 1 | B30: Restano le azioni revocatorie sui premi pagati: chi versa in polizza per sfuggire ai creditori può vedersi revocare i versamenti.
A31: Limite 2 | B31: Restano collazione, imputazione e riduzione delle donazioni: la polizza non scavalca la quota dei legittimari.
A32: Limite 3 | B32: Per le unit linked puramente finanziarie la tutela non è automatica: la Cassazione (n. 3785 del 12/02/2024) chiede una vera funzione previdenziale, cioè un rischio legato alla vita (per esempio un capitale minimo garantito).
A33: In pratica | B33: Più la polizza assomiglia a un fondo d'investimento, più la protezione è debole. Non è uno scudo da comprare dopo che i debiti sono arrivati.
A35: Altri casi in cui una polizza può avere senso
A36: Garanzia del capitale | B36: Ramo I per chi non vuole oscillazioni: costo medio 1,7% (canale bancario 1,4%). Confronto onesto: titoli di Stato diretti, al 12,5%, esclusi dalla successione, senza costi annui.
A37: Beneficiari fuori famiglia | B37: Destinare una somma a chi ha franchigie basse o nessuna (vedi la tabella sopra).
A38: Coperture di puro rischio | B38: Temporanea caso morte e non autosufficienza: sono un'altra cosa, utili, e non sono prodotti d'investimento.
A50: Motore del calcolo — non modificare
A51: Calcoli intermedi usati dalle celle verdi qui sopra: si possono leggere, non vanno modificati.
A52: Franchigia applicata | B52: =IF(B8="sì",$C$16,INDEX($C$12:$C$15,MATCH(B7,$A$12:$A$15,0))) -> 1000000
A53: Aliquota applicata | B53: =INDEX($B$12:$B$15,MATCH(B7,$A$12:$A$15,0)) -> 0.04
A54: Input validi | B54: =IFERROR(AND(ISNUMBER(B5),B5>=0,ISNUMBER(B6),B6>=0,ISNUMBER($B$52),ISNUMBER($B$53)),FALSE) -> TRUE

Sheet 5 - Come leggere il KID
A1: Come leggere il KID: dove trovare i numeri da inserire
A2: Strumento informativo / divulgativo. NON è consulenza finanziaria. I valori sono indicativi al 2026 e vanno verificati col tuo consulente.
A4: Le parti del documento con le informazioni chiave (KID) che servono
A5: Dove, nel KID | B5: Cosa leggere | C5: Esempio: Prodotto B (KID, su 10.000 €) | D5: Dove va nel simulatore
A6: Cos'è questo prodotto? | B6: Il tipo: ramo I (gestione separata, spesso con garanzia), ramo III (unit linked), multiramo. E il periodo di detenzione raccomandato. | C6: Multiramo; periodo raccomandato 10 anni | D6: Foglio 1, B17 (il ramo I non paga il bollo); foglio 2, riga 9
A7: Quali sono i rischi e qual è il potenziale rendimento? | B7: Gli scenari: il «moderato» è una stima, non una promessa. Guarda il rendimento prima e dopo i costi. | C7: 4,0% l'anno prima dei costi, 2,1% dopo | D7: Foglio 1, B8: usa lo stesso lordo per polizza ed ETF
A8: Quali sono i costi? — Andamento dei costi nel tempo | B8: Costi totali in euro e incidenza annuale se esci dopo 1 anno e alla fine del periodo raccomandato. | C8: 346 € e 3,5% dopo 1 anno; 2.006 € e 1,9% l'anno a 10 anni | D8: Foglio 1, B9 (incidenza annuale sul periodo raccomandato); foglio 2, B9
A9: Quali sono i costi? — Composizione dei costi | B9: Ingresso, uscita, gestione, transazione, performance. Se ingresso e uscita pesano molto, uscire presto costa caro. | C9: Ingresso 0,2%; uscita nessuna a 10 anni; gestione 1,7% l'anno | D9: Serve a capire se il costo è concentrato all'inizio
A10: Per quanto tempo devo detenerlo e posso ritirare il capitale prematuramente? | B10: Da quando si può riscattare e con quali penali. Spesso la tabella anno per anno è nel documento aggiuntivo (DIP aggiuntivo). | C10: Nessuna commissione di uscita al periodo raccomandato | D10: Foglio 1, riga 21 (penale anno per anno)
A11: Documento aggiuntivo (DIP aggiuntivo) | B11: Imposte, garanzie (sul premio investito, cioè al netto dei costi, non sul premio versato), penali di riscatto. | C11: Garanzia sulla parte in gestione separata | D11: Foglio 1, B13 (quota in titoli di Stato) e riga 21
A13: Il vostro KID in tre numeri (celle gialle)
A14: Costi totali se esci dopo 1 anno (in euro, dalla tabella del KID) | B14: 346
A15: Importo dell'esempio del KID | B15: 10000 | C15: Di solito 10.000 €
A16: Incidenza annuale dei costi alla fine del periodo raccomandato | B16: 0.019 | C16: Default: Prodotto B, 1,9% l'anno
A18: Cosa vuol dire sul vostro capitale (capitale, anni e rendimento del foglio 1)
A19: Costo se esci dopo 1 anno, in percentuale | B19: =IFERROR(B14/B15,"controlla le celle gialle del foglio 1") -> 0.0346
A20: Lo stesso costo sul vostro capitale | B20: =IFERROR(B19*'1 - Il tuo confronto'!$B$5,"controlla le celle gialle del foglio 1") -> 1730
A21: Capitale finale con questo costo annuo, prima delle imposte | B21: =IFERROR(IF('1 - Il tuo confronto'!$B$83,$B$33,"controlla le celle gialle del foglio 1"),"controlla le celle gialle del foglio 1") -> 92075.336
A22: Capitale finale con l'ETF (foglio 1) | B22: =IFERROR(IF('1 - Il tuo confronto'!$B$83,$B$34,"controlla le celle gialle del foglio 1"),"controlla le celle gialle del foglio 1") -> 127701.4
A23: Euro persi contro l'ETF, prima delle imposte | B23: =IFERROR(B22-B21,"controlla le celle gialle del foglio 1") -> 35626.064
A24: Per il confronto completo (imposte, bollo, anno per anno) copia l'incidenza annuale nella cella B9 del foglio 1. Senza bollo, come i default del foglio 1.
A30: Motore del calcolo — non modificare
A31: Calcoli intermedi usati dalle celle verdi qui sopra: si possono leggere, non vanno modificati.
A32: Fattore annuo con il vostro costo | B32: =1+'1 - Il tuo confronto'!$B$8-B16 -> 1.031
A33: Capitale finale con il vostro costo | B33: =IF(ABS($B$32-1)<0.000000000001,'1 - Il tuo confronto'!$B$5+'1 - Il tuo confronto'!$B$6*'1 - Il tuo confronto'!$B$7,'1 - Il tuo confronto'!$B$5*$B$32^'1 - Il tuo confronto'!$B$7+'1 - Il tuo confronto'!$B$6*($B$32^'1 - Il tuo confronto'!$B$7-1)/($B$32-1)) -> 92075.336
A34: Capitale finale ETF, senza bollo | B34: =IF(ABS((1+'1 - Il tuo confronto'!$B$8-'1 - Il tuo confronto'!$B$10)-1)<0.000000000001,'1 - Il tuo confronto'!$B$5+'1 - Il tuo confronto'!$B$6*'1 - Il tuo confronto'!$B$7,'1 - Il tuo confronto'!$B$5*(1+'1 - Il tuo confronto'!$B$8-'1 - Il tuo confronto'!$B$10)^'1 - Il tuo confronto'!$B$7+'1 - Il tuo confronto'!$B$6*((1+'1 - Il tuo confronto'!$B$8-'1 - Il tuo confronto'!$B$10)^'1 - Il tuo confronto'!$B$7-1)/((1+'1 - Il tuo confronto'!$B$8-'1 - Il tuo confronto'!$B$10)-1)) -> 127701.4
