Workbook

Sheet 0 - Indice
A1: Marco FIRE — Posso smettere? Il simulatore a sei numeri
A2: Strumento informativo / divulgativo. NON è consulenza finanziaria. I valori sono indicativi al 2026 e vanno verificati col tuo consulente.
A4: Indice
A5: 1 - I TUOI 6 NUMERI | B5: Sei numeri, un verdetto: il ponte fino alla pensione regge o no
A6: 2 - ANNO PER ANNO | B6: Il decumulo anno per anno, con imposta sulla plusvalenza e bollo
A7: 3 - MATRICE | B7: A che età finisce il capitale, per spesa e per rendimento
A8: 4 - SEQUENZA | B8: Stesso rendimento medio, ordine diverso: quanto cambia il risultato
A10: Come usare
A11: 1. Le celle GIALLE sono input — modificale coi tuoi numeri.
A12: 2. Le celle VERDI sono output — si aggiornano automaticamente.
A13: 3. Tutti i numeri di default sono al 2026 da fonti pubbliche.
A14: 4. Niente codice nascosto: l'Excel è solo formule modificabili.
A16: Fonti dati
A17: • D.L. 66/2014 art. 3 e TUIR — imposta sostitutiva 26% sui redditi di natura finanziaria; 12,5% su titoli di Stato italiani ed emittenti white list
A18: • D.P.R. 642/1972, Tariffa allegata art. 13 c. 2-ter — imposta di bollo sui prodotti finanziari: 0,2% annuo del valore di mercato
A19: • Bengen W. (1994), Determining Withdrawal Rates Using Historical Data — SAFEMAX 4,15% su orizzonte di 30 anni
A20: • Cooley P., Hubbard C., Walz D. (1998), Trinity Study — tassi di prelievo sostenibili e probabilità di successo per orizzonte e allocazione
A21: • Morningstar (2025), The State of Retirement Income — tasso di prelievo iniziale sicuro 3,9% nello scenario base
A22: • Rendimenti reali di lungo periodo di azionario e obbligazionario: ipotesi dichiarate, non previsioni. Cambia la cella gialla e guarda quanto conta
A24: Aggiornamenti: github.com/marcofire-it/marco-fire-simulatori

Sheet 1 - I TUOI 6 NUMERI
A1: Posso smettere? Il tuo caso in sei numeri
A2: Strumento informativo / divulgativo. NON è consulenza finanziaria. I valori sono indicativi al 2026 e vanno verificati col tuo consulente.
A4: I TUOI 6 NUMERI — cambia solo le celle gialle
A5: 1. Quanti anni hai oggi | B5: 45
A6: 2. Capitale investito oggi (€) | B6: 400000
A7: 3. Quanto spendi davvero in un anno, netto (€) | B7: 24000
A8: 4. Rendimento REALE atteso del portafoglio (%) | B8: 0.03
A9: 5. Plusvalenza latente sul portafoglio oggi (%) | B9: 0.2
A10: 6. A che età arriva la pensione pubblica | B10: 67 | D10: Oggi la vecchiaia è a 67 anni, 67 e 1 mese nel 2027, 67 e 3 mesi dal 2028. Ma per chi ci arriva intorno al 2050 la Ragioneria dello Stato proietta 69 anni: se hai meno di 50 anni, prova a scrivere 69 qui.
A11: Il numero 3 è quello che decide tutto, ed è anche l'unico che nessuno conosce davvero: prendi l'estratto conto degli ultimi dodici mesi e somma, non stimare a memoria. Il numero 5 è la plusvalenza NON ancora realizzata: se hai investito 320.000 € e oggi il portafoglio ne vale 400.000, la plusvalenza latente è 80.000 su 400.000, cioè il 20%.
A13: IPOTESI TECNICHE — puoi cambiarle, ma sappi cosa fai
A14: Inflazione media attesa (%) | B14: 0.02
A15: Aliquota sulle plusvalenze (%) | B15: 0.26
A16: Imposta di bollo annua sul dossier (%) | B16: 0.002
A17: Base fiscale iniziale (quanto hai versato) | B17: =B6*(1-B9)
A18: Rendimento NOMINALE corrispondente | B18: =(1+B8)*(1+B14)-1
A20: IL VERDETTO
A21: Anni interi in cui il capitale regge | B21: =COUNTIF('2 - ANNO PER ANNO'!J7:J52,">0")
A22: Età a cui il capitale finisce | B22: =B5+B21
A23: Anni da coprire fino alla pensione | B23: =MAX(0,B10-B5)
A24: VERDETTO SUL PONTE | B24: =IF(B21>=B23,"SI - il ponte fino alla pensione regge","NO - il capitale finisce prima della pensione")
A25: Anni che ti mancano (0 = ce la fai) | B25: =MAX(0,B23-B21)
A26: Capitale in euro di oggi il giorno della pensione | B26: =IFERROR(MAX(0,INDEX('2 - ANNO PER ANNO'!L7:L52,MATCH(B10-1,'2 - ANNO PER ANNO'!A7:A52,0))),0)
A28: IL PRIMO ANNO, VOCE PER VOCE
A29: Spesa netta che vuoi avere in mano | B29: =B7
A30: Prelievo LORDO necessario | B30: ='2 - ANNO PER ANNO'!G7
A31: Di cui imposta sulla plusvalenza | B31: ='2 - ANNO PER ANNO'!H7
A32: Imposta di bollo sul dossier | B32: ='2 - ANNO PER ANNO'!I7
A33: USCITA TOTALE dal portafoglio nel primo anno | B33: ='2 - ANNO PER ANNO'!G7+'2 - ANNO PER ANNO'!I7
A34: Tasso di prelievo effettivo sul capitale | B34: =IFERROR(B33/B6,0)
A35: Confronto: tasso di prelievo «sicuro» Morningstar 2025 | B35: =0.039
A37: Quanto capitale servirebbe per coprire tutto il ponte
A38: Valori calcolati con questo stesso modello, partendo da 45 anni con rendimento reale 3% e plusvalenza latente 20%. Sono il capitale MINIMO che, con quella spesa, arriva esattamente alla pensione: sotto quella cifra il ponte non regge. La seconda colonna usa i 67 anni di oggi, la terza i 69 anni proiettati dalla Ragioneria dello Stato per chi va in pensione intorno al 2050. Verificali: scrivi la cifra nella cella gialla del capitale, metti 67 o 69 nell'età della pensione, e guarda il verdetto qui sopra.
A39: Spesa annua netta | B39: Per arrivare a 67 (22 anni) | C39: Per arrivare a 69 (24 anni)
A40: 18.000 € | B40: 344000 | C40: 368000
A41: 24.000 € | B41: 459000 | C41: 491000
A42: 30.000 € | B42: 573000 | C42: 613000
A43: 36.000 € | B43: 688000 | C43: 736000
A45: Attenzione al confronto con la «regola del 4%»: quella regola nasce su orizzonti di 30 anni, su mercati americani e SENZA la fiscalità italiana. Qui il tasso di prelievo che vedi sopra è già comprensivo di imposta sulla plusvalenza e di bollo, ed è quindi più alto di quello che scriveresti guardando solo la spesa.

Sheet 2 - ANNO PER ANNO
A1: Il ponte, anno per anno
A2: Strumento informativo / divulgativo. NON è consulenza finanziaria. I valori sono indicativi al 2026 e vanno verificati col tuo consulente.
A3: Tutti i valori sono NOMINALI (euro correnti dell'anno) tranne l'ultima colonna, che riporta il capitale in euro di oggi. La colonna «quota plusvalenza» è la parte di ogni vendita che risulta guadagno: cresce nel tempo perché la base fiscale si consuma, e per questo l'imposta pesa sempre di più. Riga in cui il capitale finale diventa negativo = anno in cui il capitale si esaurisce.
A6: Età | B6: Anno | C6: Capitale inizio | D6: Spesa netta | E6: Base fiscale | F6: Quota plus. | G6: Prelievo lordo | H6: Imposta | I6: Bollo | J6: Capitale fine | L6: Capitale in € di oggi
A7: ='1 - I TUOI 6 NUMERI'!$B$5+0 | B7: =2026+0 | C7: ='1 - I TUOI 6 NUMERI'!$B$6 | D7: ='1 - I TUOI 6 NUMERI'!$B$7*(1+'1 - I TUOI 6 NUMERI'!$B$14)^0 | E7: ='1 - I TUOI 6 NUMERI'!$B$17 | F7: =IF(C7<=0,0,MEDIAN(0,(C7-E7)/C7,1)) | G7: =IF(C7<=0,0,D7/(1-'1 - I TUOI 6 NUMERI'!$B$15*F7)) | H7: ='1 - I TUOI 6 NUMERI'!$B$15*G7*F7 | I7: =IF(C7<=0,0,'1 - I TUOI 6 NUMERI'!$B$16*C7) | J7: =IF(C7<=0,0,(C7-G7-I7)*(1+'1 - I TUOI 6 NUMERI'!$B$18)) | L7: =J7/(1+'1 - I TUOI 6 NUMERI'!$B$14)^1
A8: ='1 - I TUOI 6 NUMERI'!$B$5+1 | B8: =2026+1 | C8: =J7 | D8: ='1 - I TUOI 6 NUMERI'!$B$7*(1+'1 - I TUOI 6 NUMERI'!$B$14)^1 | E8: =MAX(0,E7-G7*(1-F7)) | F8: =IF(C8<=0,0,MEDIAN(0,(C8-E8)/C8,1)) | G8: =IF(C8<=0,0,D8/(1-'1 - I TUOI 6 NUMERI'!$B$15*F8)) | H8: ='1 - I TUOI 6 NUMERI'!$B$15*G8*F8 | I8: =IF(C8<=0,0,'1 - I TUOI 6 NUMERI'!$B$16*C8) | J8: =IF(C8<=0,0,(C8-G8-I8)*(1+'1 - I TUOI 6 NUMERI'!$B$18)) | L8: =J8/(1+'1 - I TUOI 6 NUMERI'!$B$14)^2
A9: ='1 - I TUOI 6 NUMERI'!$B$5+2 | B9: =2026+2 | C9: =J8 | D9: ='1 - I TUOI 6 NUMERI'!$B$7*(1+'1 - I TUOI 6 NUMERI'!$B$14)^2 | E9: =MAX(0,E8-G8*(1-F8)) | F9: =IF(C9<=0,0,MEDIAN(0,(C9-E9)/C9,1)) | G9: =IF(C9<=0,0,D9/(1-'1 - I TUOI 6 NUMERI'!$B$15*F9)) | H9: ='1 - I TUOI 6 NUMERI'!$B$15*G9*F9 | I9: =IF(C9<=0,0,'1 - I TUOI 6 NUMERI'!$B$16*C9) | J9: =IF(C9<=0,0,(C9-G9-I9)*(1+'1 - I TUOI 6 NUMERI'!$B$18)) | L9: =J9/(1+'1 - I TUOI 6 NUMERI'!$B$14)^3
A10: ='1 - I TUOI 6 NUMERI'!$B$5+3 | B10: =2026+3 | C10: =J9 | D10: ='1 - I TUOI 6 NUMERI'!$B$7*(1+'1 - I TUOI 6 NUMERI'!$B$14)^3 | E10: =MAX(0,E9-G9*(1-F9)) | F10: =IF(C10<=0,0,MEDIAN(0,(C10-E10)/C10,1)) | G10: =IF(C10<=0,0,D10/(1-'1 - I TUOI 6 NUMERI'!$B$15*F10)) | H10: ='1 - I TUOI 6 NUMERI'!$B$15*G10*F10 | I10: =IF(C10<=0,0,'1 - I TUOI 6 NUMERI'!$B$16*C10) | J10: =IF(C10<=0,0,(C10-G10-I10)*(1+'1 - I TUOI 6 NUMERI'!$B$18)) | L10: =J10/(1+'1 - I TUOI 6 NUMERI'!$B$14)^4
A11: ='1 - I TUOI 6 NUMERI'!$B$5+4 | B11: =2026+4 | C11: =J10 | D11: ='1 - I TUOI 6 NUMERI'!$B$7*(1+'1 - I TUOI 6 NUMERI'!$B$14)^4 | E11: =MAX(0,E10-G10*(1-F10)) | F11: =IF(C11<=0,0,MEDIAN(0,(C11-E11)/C11,1)) | G11: =IF(C11<=0,0,D11/(1-'1 - I TUOI 6 NUMERI'!$B$15*F11)) | H11: ='1 - I TUOI 6 NUMERI'!$B$15*G11*F11 | I11: =IF(C11<=0,0,'1 - I TUOI 6 NUMERI'!$B$16*C11) | J11: =IF(C11<=0,0,(C11-G11-I11)*(1+'1 - I TUOI 6 NUMERI'!$B$18)) | L11: =J11/(1+'1 - I TUOI 6 NUMERI'!$B$14)^5
A12: ='1 - I TUOI 6 NUMERI'!$B$5+5 | B12: =2026+5 | C12: =J11 | D12: ='1 - I TUOI 6 NUMERI'!$B$7*(1+'1 - I TUOI 6 NUMERI'!$B$14)^5 | E12: =MAX(0,E11-G11*(1-F11)) | F12: =IF(C12<=0,0,MEDIAN(0,(C12-E12)/C12,1)) | G12: =IF(C12<=0,0,D12/(1-'1 - I TUOI 6 NUMERI'!$B$15*F12)) | H12: ='1 - I TUOI 6 NUMERI'!$B$15*G12*F12 | I12: =IF(C12<=0,0,'1 - I TUOI 6 NUMERI'!$B$16*C12) | J12: =IF(C12<=0,0,(C12-G12-I12)*(1+'1 - I TUOI 6 NUMERI'!$B$18)) | L12: =J12/(1+'1 - I TUOI 6 NUMERI'!$B$14)^6
A13: ='1 - I TUOI 6 NUMERI'!$B$5+6 | B13: =2026+6 | C13: =J12 | D13: ='1 - I TUOI 6 NUMERI'!$B$7*(1+'1 - I TUOI 6 NUMERI'!$B$14)^6 | E13: =MAX(0,E12-G12*(1-F12)) | F13: =IF(C13<=0,0,MEDIAN(0,(C13-E13)/C13,1)) | G13: =IF(C13<=0,0,D13/(1-'1 - I TUOI 6 NUMERI'!$B$15*F13)) | H13: ='1 - I TUOI 6 NUMERI'!$B$15*G13*F13 | I13: =IF(C13<=0,0,'1 - I TUOI 6 NUMERI'!$B$16*C13) | J13: =IF(C13<=0,0,(C13-G13-I13)*(1+'1 - I TUOI 6 NUMERI'!$B$18)) | L13: =J13/(1+'1 - I TUOI 6 NUMERI'!$B$14)^7
A14: ='1 - I TUOI 6 NUMERI'!$B$5+7 | B14: =2026+7 | C14: =J13 | D14: ='1 - I TUOI 6 NUMERI'!$B$7*(1+'1 - I TUOI 6 NUMERI'!$B$14)^7 | E14: =MAX(0,E13-G13*(1-F13)) | F14: =IF(C14<=0,0,MEDIAN(0,(C14-E14)/C14,1)) | G14: =IF(C14<=0,0,D14/(1-'1 - I TUOI 6 NUMERI'!$B$15*F14)) | H14: ='1 - I TUOI 6 NUMERI'!$B$15*G14*F14 | I14: =IF(C14<=0,0,'1 - I TUOI 6 NUMERI'!$B$16*C14) | J14: =IF(C14<=0,0,(C14-G14-I14)*(1+'1 - I TUOI 6 NUMERI'!$B$18)) | L14: =J14/(1+'1 - I TUOI 6 NUMERI'!$B$14)^8
A15: ='1 - I TUOI 6 NUMERI'!$B$5+8 | B15: =2026+8 | C15: =J14 | D15: ='1 - I TUOI 6 NUMERI'!$B$7*(1+'1 - I TUOI 6 NUMERI'!$B$14)^8 | E15: =MAX(0,E14-G14*(1-F14)) | F15: =IF(C15<=0,0,MEDIAN(0,(C15-E15)/C15,1)) | G15: =IF(C15<=0,0,D15/(1-'1 - I TUOI 6 NUMERI'!$B$15*F15)) | H15: ='1 - I TUOI 6 NUMERI'!$B$15*G15*F15 | I15: =IF(C15<=0,0,'1 - I TUOI 6 NUMERI'!$B$16*C15) | J15: =IF(C15<=0,0,(C15-G15-I15)*(1+'1 - I TUOI 6 NUMERI'!$B$18)) | L15: =J15/(1+'1 - I TUOI 6 NUMERI'!$B$14)^9
A16: ='1 - I TUOI 6 NUMERI'!$B$5+9 | B16: =2026+9 | C16: =J15 | D16: ='1 - I TUOI 6 NUMERI'!$B$7*(1+'1 - I TUOI 6 NUMERI'!$B$14)^9 | E16: =MAX(0,E15-G15*(1-F15)) | F16: =IF(C16<=0,0,MEDIAN(0,(C16-E16)/C16,1)) | G16: =IF(C16<=0,0,D16/(1-'1 - I TUOI 6 NUMERI'!$B$15*F16)) | H16: ='1 - I TUOI 6 NUMERI'!$B$15*G16*F16 | I16: =IF(C16<=0,0,'1 - I TUOI 6 NUMERI'!$B$16*C16) | J16: =IF(C16<=0,0,(C16-G16-I16)*(1+'1 - I TUOI 6 NUMERI'!$B$18)) | L16: =J16/(1+'1 - I TUOI 6 NUMERI'!$B$14)^10
A17: ='1 - I TUOI 6 NUMERI'!$B$5+10 | B17: =2026+10 | C17: =J16 | D17: ='1 - I TUOI 6 NUMERI'!$B$7*(1+'1 - I TUOI 6 NUMERI'!$B$14)^10 | E17: =MAX(0,E16-G16*(1-F16)) | F17: =IF(C17<=0,0,MEDIAN(0,(C17-E17)/C17,1)) | G17: =IF(C17<=0,0,D17/(1-'1 - I TUOI 6 NUMERI'!$B$15*F17)) | H17: ='1 - I TUOI 6 NUMERI'!$B$15*G17*F17 | I17: =IF(C17<=0,0,'1 - I TUOI 6 NUMERI'!$B$16*C17) | J17: =IF(C17<=0,0,(C17-G17-I17)*(1+'1 - I TUOI 6 NUMERI'!$B$18)) | L17: =J17/(1+'1 - I TUOI 6 NUMERI'!$B$14)^11
A18: ='1 - I TUOI 6 NUMERI'!$B$5+11 | B18: =2026+11 | C18: =J17 | D18: ='1 - I TUOI 6 NUMERI'!$B$7*(1+'1 - I TUOI 6 NUMERI'!$B$14)^11 | E18: =MAX(0,E17-G17*(1-F17)) | F18: =IF(C18<=0,0,MEDIAN(0,(C18-E18)/C18,1)) | G18: =IF(C18<=0,0,D18/(1-'1 - I TUOI 6 NUMERI'!$B$15*F18)) | H18: ='1 - I TUOI 6 NUMERI'!$B$15*G18*F18 | I18: =IF(C18<=0,0,'1 - I TUOI 6 NUMERI'!$B$16*C18) | J18: =IF(C18<=0,0,(C18-G18-I18)*(1+'1 - I TUOI 6 NUMERI'!$B$18)) | L18: =J18/(1+'1 - I TUOI 6 NUMERI'!$B$14)^12
A19: ='1 - I TUOI 6 NUMERI'!$B$5+12 | B19: =2026+12 | C19: =J18 | D19: ='1 - I TUOI 6 NUMERI'!$B$7*(1+'1 - I TUOI 6 NUMERI'!$B$14)^12 | E19: =MAX(0,E18-G18*(1-F18)) | F19: =IF(C19<=0,0,MEDIAN(0,(C19-E19)/C19,1)) | G19: =IF(C19<=0,0,D19/(1-'1 - I TUOI 6 NUMERI'!$B$15*F19)) | H19: ='1 - I TUOI 6 NUMERI'!$B$15*G19*F19 | I19: =IF(C19<=0,0,'1 - I TUOI 6 NUMERI'!$B$16*C19) | J19: =IF(C19<=0,0,(C19-G19-I19)*(1+'1 - I TUOI 6 NUMERI'!$B$18)) | L19: =J19/(1+'1 - I TUOI 6 NUMERI'!$B$14)^13
A20: ='1 - I TUOI 6 NUMERI'!$B$5+13 | B20: =2026+13 | C20: =J19 | D20: ='1 - I TUOI 6 NUMERI'!$B$7*(1+'1 - I TUOI 6 NUMERI'!$B$14)^13 | E20: =MAX(0,E19-G19*(1-F19)) | F20: =IF(C20<=0,0,MEDIAN(0,(C20-E20)/C20,1)) | G20: =IF(C20<=0,0,D20/(1-'1 - I TUOI 6 NUMERI'!$B$15*F20)) | H20: ='1 - I TUOI 6 NUMERI'!$B$15*G20*F20 | I20: =IF(C20<=0,0,'1 - I TUOI 6 NUMERI'!$B$16*C20) | J20: =IF(C20<=0,0,(C20-G20-I20)*(1+'1 - I TUOI 6 NUMERI'!$B$18)) | L20: =J20/(1+'1 - I TUOI 6 NUMERI'!$B$14)^14
A21: ='1 - I TUOI 6 NUMERI'!$B$5+14 | B21: =2026+14 | C21: =J20 | D21: ='1 - I TUOI 6 NUMERI'!$B$7*(1+'1 - I TUOI 6 NUMERI'!$B$14)^14 | E21: =MAX(0,E20-G20*(1-F20)) | F21: =IF(C21<=0,0,MEDIAN(0,(C21-E21)/C21,1)) | G21: =IF(C21<=0,0,D21/(1-'1 - I TUOI 6 NUMERI'!$B$15*F21)) | H21: ='1 - I TUOI 6 NUMERI'!$B$15*G21*F21 | I21: =IF(C21<=0,0,'1 - I TUOI 6 NUMERI'!$B$16*C21) | J21: =IF(C21<=0,0,(C21-G21-I21)*(1+'1 - I TUOI 6 NUMERI'!$B$18)) | L21: =J21/(1+'1 - I TUOI 6 NUMERI'!$B$14)^15
A22: ='1 - I TUOI 6 NUMERI'!$B$5+15 | B22: =2026+15 | C22: =J21 | D22: ='1 - I TUOI 6 NUMERI'!$B$7*(1+'1 - I TUOI 6 NUMERI'!$B$14)^15 | E22: =MAX(0,E21-G21*(1-F21)) | F22: =IF(C22<=0,0,MEDIAN(0,(C22-E22)/C22,1)) | G22: =IF(C22<=0,0,D22/(1-'1 - I TUOI 6 NUMERI'!$B$15*F22)) | H22: ='1 - I TUOI 6 NUMERI'!$B$15*G22*F22 | I22: =IF(C22<=0,0,'1 - I TUOI 6 NUMERI'!$B$16*C22) | J22: =IF(C22<=0,0,(C22-G22-I22)*(1+'1 - I TUOI 6 NUMERI'!$B$18)) | L22: =J22/(1+'1 - I TUOI 6 NUMERI'!$B$14)^16
A23: ='1 - I TUOI 6 NUMERI'!$B$5+16 | B23: =2026+16 | C23: =J22 | D23: ='1 - I TUOI 6 NUMERI'!$B$7*(1+'1 - I TUOI 6 NUMERI'!$B$14)^16 | E23: =MAX(0,E22-G22*(1-F22)) | F23: =IF(C23<=0,0,MEDIAN(0,(C23-E23)/C23,1)) | G23: =IF(C23<=0,0,D23/(1-'1 - I TUOI 6 NUMERI'!$B$15*F23)) | H23: ='1 - I TUOI 6 NUMERI'!$B$15*G23*F23 | I23: =IF(C23<=0,0,'1 - I TUOI 6 NUMERI'!$B$16*C23) | J23: =IF(C23<=0,0,(C23-G23-I23)*(1+'1 - I TUOI 6 NUMERI'!$B$18)) | L23: =J23/(1+'1 - I TUOI 6 NUMERI'!$B$14)^17
A24: ='1 - I TUOI 6 NUMERI'!$B$5+17 | B24: =2026+17 | C24: =J23 | D24: ='1 - I TUOI 6 NUMERI'!$B$7*(1+'1 - I TUOI 6 NUMERI'!$B$14)^17 | E24: =MAX(0,E23-G23*(1-F23)) | F24: =IF(C24<=0,0,MEDIAN(0,(C24-E24)/C24,1)) | G24: =IF(C24<=0,0,D24/(1-'1 - I TUOI 6 NUMERI'!$B$15*F24)) | H24: ='1 - I TUOI 6 NUMERI'!$B$15*G24*F24 | I24: =IF(C24<=0,0,'1 - I TUOI 6 NUMERI'!$B$16*C24) | J24: =IF(C24<=0,0,(C24-G24-I24)*(1+'1 - I TUOI 6 NUMERI'!$B$18)) | L24: =J24/(1+'1 - I TUOI 6 NUMERI'!$B$14)^18
A25: ='1 - I TUOI 6 NUMERI'!$B$5+18 | B25: =2026+18 | C25: =J24 | D25: ='1 - I TUOI 6 NUMERI'!$B$7*(1+'1 - I TUOI 6 NUMERI'!$B$14)^18 | E25: =MAX(0,E24-G24*(1-F24)) | F25: =IF(C25<=0,0,MEDIAN(0,(C25-E25)/C25,1)) | G25: =IF(C25<=0,0,D25/(1-'1 - I TUOI 6 NUMERI'!$B$15*F25)) | H25: ='1 - I TUOI 6 NUMERI'!$B$15*G25*F25 | I25: =IF(C25<=0,0,'1 - I TUOI 6 NUMERI'!$B$16*C25) | J25: =IF(C25<=0,0,(C25-G25-I25)*(1+'1 - I TUOI 6 NUMERI'!$B$18)) | L25: =J25/(1+'1 - I TUOI 6 NUMERI'!$B$14)^19
A26: ='1 - I TUOI 6 NUMERI'!$B$5+19 | B26: =2026+19 | C26: =J25 | D26: ='1 - I TUOI 6 NUMERI'!$B$7*(1+'1 - I TUOI 6 NUMERI'!$B$14)^19 | E26: =MAX(0,E25-G25*(1-F25)) | F26: =IF(C26<=0,0,MEDIAN(0,(C26-E26)/C26,1)) | G26: =IF(C26<=0,0,D26/(1-'1 - I TUOI 6 NUMERI'!$B$15*F26)) | H26: ='1 - I TUOI 6 NUMERI'!$B$15*G26*F26 | I26: =IF(C26<=0,0,'1 - I TUOI 6 NUMERI'!$B$16*C26) | J26: =IF(C26<=0,0,(C26-G26-I26)*(1+'1 - I TUOI 6 NUMERI'!$B$18)) | L26: =J26/(1+'1 - I TUOI 6 NUMERI'!$B$14)^20
A27: ='1 - I TUOI 6 NUMERI'!$B$5+20 | B27: =2026+20 | C27: =J26 | D27: ='1 - I TUOI 6 NUMERI'!$B$7*(1+'1 - I TUOI 6 NUMERI'!$B$14)^20 | E27: =MAX(0,E26-G26*(1-F26)) | F27: =IF(C27<=0,0,MEDIAN(0,(C27-E27)/C27,1)) | G27: =IF(C27<=0,0,D27/(1-'1 - I TUOI 6 NUMERI'!$B$15*F27)) | H27: ='1 - I TUOI 6 NUMERI'!$B$15*G27*F27 | I27: =IF(C27<=0,0,'1 - I TUOI 6 NUMERI'!$B$16*C27) | J27: =IF(C27<=0,0,(C27-G27-I27)*(1+'1 - I TUOI 6 NUMERI'!$B$18)) | L27: =J27/(1+'1 - I TUOI 6 NUMERI'!$B$14)^21
A28: ='1 - I TUOI 6 NUMERI'!$B$5+21 | B28: =2026+21 | C28: =J27 | D28: ='1 - I TUOI 6 NUMERI'!$B$7*(1+'1 - I TUOI 6 NUMERI'!$B$14)^21 | E28: =MAX(0,E27-G27*(1-F27)) | F28: =IF(C28<=0,0,MEDIAN(0,(C28-E28)/C28,1)) | G28: =IF(C28<=0,0,D28/(1-'1 - I TUOI 6 NUMERI'!$B$15*F28)) | H28: ='1 - I TUOI 6 NUMERI'!$B$15*G28*F28 | I28: =IF(C28<=0,0,'1 - I TUOI 6 NUMERI'!$B$16*C28) | J28: =IF(C28<=0,0,(C28-G28-I28)*(1+'1 - I TUOI 6 NUMERI'!$B$18)) | L28: =J28/(1+'1 - I TUOI 6 NUMERI'!$B$14)^22
A29: ='1 - I TUOI 6 NUMERI'!$B$5+22 | B29: =2026+22 | C29: =J28 | D29: ='1 - I TUOI 6 NUMERI'!$B$7*(1+'1 - I TUOI 6 NUMERI'!$B$14)^22 | E29: =MAX(0,E28-G28*(1-F28)) | F29: =IF(C29<=0,0,MEDIAN(0,(C29-E29)/C29,1)) | G29: =IF(C29<=0,0,D29/(1-'1 - I TUOI 6 NUMERI'!$B$15*F29)) | H29: ='1 - I TUOI 6 NUMERI'!$B$15*G29*F29 | I29: =IF(C29<=0,0,'1 - I TUOI 6 NUMERI'!$B$16*C29) | J29: =IF(C29<=0,0,(C29-G29-I29)*(1+'1 - I TUOI 6 NUMERI'!$B$18)) | L29: =J29/(1+'1 - I TUOI 6 NUMERI'!$B$14)^23
A30: ='1 - I TUOI 6 NUMERI'!$B$5+23 | B30: =2026+23 | C30: =J29 | D30: ='1 - I TUOI 6 NUMERI'!$B$7*(1+'1 - I TUOI 6 NUMERI'!$B$14)^23 | E30: =MAX(0,E29-G29*(1-F29)) | F30: =IF(C30<=0,0,MEDIAN(0,(C30-E30)/C30,1)) | G30: =IF(C30<=0,0,D30/(1-'1 - I TUOI 6 NUMERI'!$B$15*F30)) | H30: ='1 - I TUOI 6 NUMERI'!$B$15*G30*F30 | I30: =IF(C30<=0,0,'1 - I TUOI 6 NUMERI'!$B$16*C30) | J30: =IF(C30<=0,0,(C30-G30-I30)*(1+'1 - I TUOI 6 NUMERI'!$B$18)) | L30: =J30/(1+'1 - I TUOI 6 NUMERI'!$B$14)^24
A31: ='1 - I TUOI 6 NUMERI'!$B$5+24 | B31: =2026+24 | C31: =J30 | D31: ='1 - I TUOI 6 NUMERI'!$B$7*(1+'1 - I TUOI 6 NUMERI'!$B$14)^24 | E31: =MAX(0,E30-G30*(1-F30)) | F31: =IF(C31<=0,0,MEDIAN(0,(C31-E31)/C31,1)) | G31: =IF(C31<=0,0,D31/(1-'1 - I TUOI 6 NUMERI'!$B$15*F31)) | H31: ='1 - I TUOI 6 NUMERI'!$B$15*G31*F31 | I31: =IF(C31<=0,0,'1 - I TUOI 6 NUMERI'!$B$16*C31) | J31: =IF(C31<=0,0,(C31-G31-I31)*(1+'1 - I TUOI 6 NUMERI'!$B$18)) | L31: =J31/(1+'1 - I TUOI 6 NUMERI'!$B$14)^25
A32: ='1 - I TUOI 6 NUMERI'!$B$5+25 | B32: =2026+25 | C32: =J31 | D32: ='1 - I TUOI 6 NUMERI'!$B$7*(1+'1 - I TUOI 6 NUMERI'!$B$14)^25 | E32: =MAX(0,E31-G31*(1-F31)) | F32: =IF(C32<=0,0,MEDIAN(0,(C32-E32)/C32,1)) | G32: =IF(C32<=0,0,D32/(1-'1 - I TUOI 6 NUMERI'!$B$15*F32)) | H32: ='1 - I TUOI 6 NUMERI'!$B$15*G32*F32 | I32: =IF(C32<=0,0,'1 - I TUOI 6 NUMERI'!$B$16*C32) | J32: =IF(C32<=0,0,(C32-G32-I32)*(1+'1 - I TUOI 6 NUMERI'!$B$18)) | L32: =J32/(1+'1 - I TUOI 6 NUMERI'!$B$14)^26
A33: ='1 - I TUOI 6 NUMERI'!$B$5+26 | B33: =2026+26 | C33: =J32 | D33: ='1 - I TUOI 6 NUMERI'!$B$7*(1+'1 - I TUOI 6 NUMERI'!$B$14)^26 | E33: =MAX(0,E32-G32*(1-F32)) | F33: =IF(C33<=0,0,MEDIAN(0,(C33-E33)/C33,1)) | G33: =IF(C33<=0,0,D33/(1-'1 - I TUOI 6 NUMERI'!$B$15*F33)) | H33: ='1 - I TUOI 6 NUMERI'!$B$15*G33*F33 | I33: =IF(C33<=0,0,'1 - I TUOI 6 NUMERI'!$B$16*C33) | J33: =IF(C33<=0,0,(C33-G33-I33)*(1+'1 - I TUOI 6 NUMERI'!$B$18)) | L33: =J33/(1+'1 - I TUOI 6 NUMERI'!$B$14)^27
A34: ='1 - I TUOI 6 NUMERI'!$B$5+27 | B34: =2026+27 | C34: =J33 | D34: ='1 - I TUOI 6 NUMERI'!$B$7*(1+'1 - I TUOI 6 NUMERI'!$B$14)^27 | E34: =MAX(0,E33-G33*(1-F33)) | F34: =IF(C34<=0,0,MEDIAN(0,(C34-E34)/C34,1)) | G34: =IF(C34<=0,0,D34/(1-'1 - I TUOI 6 NUMERI'!$B$15*F34)) | H34: ='1 - I TUOI 6 NUMERI'!$B$15*G34*F34 | I34: =IF(C34<=0,0,'1 - I TUOI 6 NUMERI'!$B$16*C34) | J34: =IF(C34<=0,0,(C34-G34-I34)*(1+'1 - I TUOI 6 NUMERI'!$B$18)) | L34: =J34/(1+'1 - I TUOI 6 NUMERI'!$B$14)^28
A35: ='1 - I TUOI 6 NUMERI'!$B$5+28 | B35: =2026+28 | C35: =J34 | D35: ='1 - I TUOI 6 NUMERI'!$B$7*(1+'1 - I TUOI 6 NUMERI'!$B$14)^28 | E35: =MAX(0,E34-G34*(1-F34)) | F35: =IF(C35<=0,0,MEDIAN(0,(C35-E35)/C35,1)) | G35: =IF(C35<=0,0,D35/(1-'1 - I TUOI 6 NUMERI'!$B$15*F35)) | H35: ='1 - I TUOI 6 NUMERI'!$B$15*G35*F35 | I35: =IF(C35<=0,0,'1 - I TUOI 6 NUMERI'!$B$16*C35) | J35: =IF(C35<=0,0,(C35-G35-I35)*(1+'1 - I TUOI 6 NUMERI'!$B$18)) | L35: =J35/(1+'1 - I TUOI 6 NUMERI'!$B$14)^29
A36: ='1 - I TUOI 6 NUMERI'!$B$5+29 | B36: =2026+29 | C36: =J35 | D36: ='1 - I TUOI 6 NUMERI'!$B$7*(1+'1 - I TUOI 6 NUMERI'!$B$14)^29 | E36: =MAX(0,E35-G35*(1-F35)) | F36: =IF(C36<=0,0,MEDIAN(0,(C36-E36)/C36,1)) | G36: =IF(C36<=0,0,D36/(1-'1 - I TUOI 6 NUMERI'!$B$15*F36)) | H36: ='1 - I TUOI 6 NUMERI'!$B$15*G36*F36 | I36: =IF(C36<=0,0,'1 - I TUOI 6 NUMERI'!$B$16*C36) | J36: =IF(C36<=0,0,(C36-G36-I36)*(1+'1 - I TUOI 6 NUMERI'!$B$18)) | L36: =J36/(1+'1 - I TUOI 6 NUMERI'!$B$14)^30
A37: ='1 - I TUOI 6 NUMERI'!$B$5+30 | B37: =2026+30 | C37: =J36 | D37: ='1 - I TUOI 6 NUMERI'!$B$7*(1+'1 - I TUOI 6 NUMERI'!$B$14)^30 | E37: =MAX(0,E36-G36*(1-F36)) | F37: =IF(C37<=0,0,MEDIAN(0,(C37-E37)/C37,1)) | G37: =IF(C37<=0,0,D37/(1-'1 - I TUOI 6 NUMERI'!$B$15*F37)) | H37: ='1 - I TUOI 6 NUMERI'!$B$15*G37*F37 | I37: =IF(C37<=0,0,'1 - I TUOI 6 NUMERI'!$B$16*C37) | J37: =IF(C37<=0,0,(C37-G37-I37)*(1+'1 - I TUOI 6 NUMERI'!$B$18)) | L37: =J37/(1+'1 - I TUOI 6 NUMERI'!$B$14)^31
A38: ='1 - I TUOI 6 NUMERI'!$B$5+31 | B38: =2026+31 | C38: =J37 | D38: ='1 - I TUOI 6 NUMERI'!$B$7*(1+'1 - I TUOI 6 NUMERI'!$B$14)^31 | E38: =MAX(0,E37-G37*(1-F37)) | F38: =IF(C38<=0,0,MEDIAN(0,(C38-E38)/C38,1)) | G38: =IF(C38<=0,0,D38/(1-'1 - I TUOI 6 NUMERI'!$B$15*F38)) | H38: ='1 - I TUOI 6 NUMERI'!$B$15*G38*F38 | I38: =IF(C38<=0,0,'1 - I TUOI 6 NUMERI'!$B$16*C38) | J38: =IF(C38<=0,0,(C38-G38-I38)*(1+'1 - I TUOI 6 NUMERI'!$B$18)) | L38: =J38/(1+'1 - I TUOI 6 NUMERI'!$B$14)^32
A39: ='1 - I TUOI 6 NUMERI'!$B$5+32 | B39: =2026+32 | C39: =J38 | D39: ='1 - I TUOI 6 NUMERI'!$B$7*(1+'1 - I TUOI 6 NUMERI'!$B$14)^32 | E39: =MAX(0,E38-G38*(1-F38)) | F39: =IF(C39<=0,0,MEDIAN(0,(C39-E39)/C39,1)) | G39: =IF(C39<=0,0,D39/(1-'1 - I TUOI 6 NUMERI'!$B$15*F39)) | H39: ='1 - I TUOI 6 NUMERI'!$B$15*G39*F39 | I39: =IF(C39<=0,0,'1 - I TUOI 6 NUMERI'!$B$16*C39) | J39: =IF(C39<=0,0,(C39-G39-I39)*(1+'1 - I TUOI 6 NUMERI'!$B$18)) | L39: =J39/(1+'1 - I TUOI 6 NUMERI'!$B$14)^33
A40: ='1 - I TUOI 6 NUMERI'!$B$5+33 | B40: =2026+33 | C40: =J39 | D40: ='1 - I TUOI 6 NUMERI'!$B$7*(1+'1 - I TUOI 6 NUMERI'!$B$14)^33 | E40: =MAX(0,E39-G39*(1-F39)) | F40: =IF(C40<=0,0,MEDIAN(0,(C40-E40)/C40,1)) | G40: =IF(C40<=0,0,D40/(1-'1 - I TUOI 6 NUMERI'!$B$15*F40)) | H40: ='1 - I TUOI 6 NUMERI'!$B$15*G40*F40 | I40: =IF(C40<=0,0,'1 - I TUOI 6 NUMERI'!$B$16*C40) | J40: =IF(C40<=0,0,(C40-G40-I40)*(1+'1 - I TUOI 6 NUMERI'!$B$18)) | L40: =J40/(1+'1 - I TUOI 6 NUMERI'!$B$14)^34
A41: ='1 - I TUOI 6 NUMERI'!$B$5+34 | B41: =2026+34 | C41: =J40 | D41: ='1 - I TUOI 6 NUMERI'!$B$7*(1+'1 - I TUOI 6 NUMERI'!$B$14)^34 | E41: =MAX(0,E40-G40*(1-F40)) | F41: =IF(C41<=0,0,MEDIAN(0,(C41-E41)/C41,1)) | G41: =IF(C41<=0,0,D41/(1-'1 - I TUOI 6 NUMERI'!$B$15*F41)) | H41: ='1 - I TUOI 6 NUMERI'!$B$15*G41*F41 | I41: =IF(C41<=0,0,'1 - I TUOI 6 NUMERI'!$B$16*C41) | J41: =IF(C41<=0,0,(C41-G41-I41)*(1+'1 - I TUOI 6 NUMERI'!$B$18)) | L41: =J41/(1+'1 - I TUOI 6 NUMERI'!$B$14)^35
A42: ='1 - I TUOI 6 NUMERI'!$B$5+35 | B42: =2026+35 | C42: =J41 | D42: ='1 - I TUOI 6 NUMERI'!$B$7*(1+'1 - I TUOI 6 NUMERI'!$B$14)^35 | E42: =MAX(0,E41-G41*(1-F41)) | F42: =IF(C42<=0,0,MEDIAN(0,(C42-E42)/C42,1)) | G42: =IF(C42<=0,0,D42/(1-'1 - I TUOI 6 NUMERI'!$B$15*F42)) | H42: ='1 - I TUOI 6 NUMERI'!$B$15*G42*F42 | I42: =IF(C42<=0,0,'1 - I TUOI 6 NUMERI'!$B$16*C42) | J42: =IF(C42<=0,0,(C42-G42-I42)*(1+'1 - I TUOI 6 NUMERI'!$B$18)) | L42: =J42/(1+'1 - I TUOI 6 NUMERI'!$B$14)^36
...

Sheet 3 - MATRICE
A1: A che età finisce il capitale
A2: Strumento informativo / divulgativo. NON è consulenza finanziaria. I valori sono indicativi al 2026 e vanno verificati col tuo consulente.
A4: Righe: quanto spendi in un anno. Colonne: quanto rende il portafoglio in termini REALI, cioè già al netto dell'inflazione. Ogni cella è l'età a cui il capitale arriva a zero, calcolata con lo stesso motore del foglio 2 e con il TUO capitale e la TUA plusvalenza latente. La riga che conta è quella della tua spesa vera.
A6: Spesa annua netta | B6: Reale 1% | C6: Reale 3% | D6: Reale 5%
A7: 18.000 € | B7: ='1 - I TUOI 6 NUMERI'!$B$5+COUNTIF(G22:G67,">0") | C7: ='1 - I TUOI 6 NUMERI'!$B$5+COUNTIF(I22:I67,">0") | D7: ='1 - I TUOI 6 NUMERI'!$B$5+COUNTIF(K22:K67,">0")
A8: 24.000 € | B8: ='1 - I TUOI 6 NUMERI'!$B$5+COUNTIF(M22:M67,">0") | C8: ='1 - I TUOI 6 NUMERI'!$B$5+COUNTIF(O22:O67,">0") | D8: ='1 - I TUOI 6 NUMERI'!$B$5+COUNTIF(Q22:Q67,">0")
A9: 30.000 € | B9: ='1 - I TUOI 6 NUMERI'!$B$5+COUNTIF(S22:S67,">0") | C9: ='1 - I TUOI 6 NUMERI'!$B$5+COUNTIF(U22:U67,">0") | D9: ='1 - I TUOI 6 NUMERI'!$B$5+COUNTIF(W22:W67,">0")
A10: 36.000 € | B10: ='1 - I TUOI 6 NUMERI'!$B$5+COUNTIF(Y22:Y67,">0") | C10: ='1 - I TUOI 6 NUMERI'!$B$5+COUNTIF(AA22:AA67,">0") | D10: ='1 - I TUOI 6 NUMERI'!$B$5+COUNTIF(AC22:AC67,">0")
A12: Età della pensione pubblica | B12: ='1 - I TUOI 6 NUMERI'!$B$10
A13: Confronta ogni cella con questo numero: se l'età nella cella è più bassa, quel piano non arriva alla pensione. Nota che il rendimento non è una tua scelta: è la variabile su cui non hai nessun controllo, e sposta il risultato di anni.
F19: MOTORE DI CALCOLO — non modificare
F20: t | G20: 18k @ 1% | I20: 18k @ 3% | K20: 18k @ 5% | M20: 24k @ 1% | O20: 24k @ 3% | Q20: 24k @ 5% | S20: 30k @ 1% | U20: 30k @ 3% | W20: 30k @ 5% | Y20: 36k @ 1% | AA20: 36k @ 3% | AC20: 36k @ 5%
G21: cap. fine | H21: base | I21: cap. fine | J21: base | K21: cap. fine | L21: base | M21: cap. fine | N21: base | O21: cap. fine | P21: base | Q21: cap. fine | R21: base | S21: cap. fine | T21: base | U21: cap. fine | V21: base | W21: cap. fine | X21: base | Y21: cap. fine | Z21: base | AA21: cap. fine | AB21: base | AC21: cap. fine | AD21: base
F22: 0 | G22: =IF('1 - I TUOI 6 NUMERI'!$B$6<=0,0,('1 - I TUOI 6 NUMERI'!$B$6-(IF('1 - I TUOI 6 NUMERI'!$B$6<=0,0,(18000*(1+'1 - I TUOI 6 NUMERI'!$B$14)^0)/(1-'1 - I TUOI 6 NUMERI'!$B$15*(IF('1 - I TUOI 6 NUMERI'!$B$6<=0,0,MEDIAN(0,('1 - I TUOI 6 NUMERI'!$B$6-'1 - I TUOI 6 NUMERI'!$B$17)/'1 - I TUOI 6 NUMERI'!$B$6,1))))))-(IF('1 - I TUOI 6 NUMERI'!$B$6<=0,0,'1 - I TUOI 6 NUMERI'!$B$16*'1 - I TUOI 6 NUMERI'!$B$6)))*(1+((1+0.01)*(1+'1 - I TUOI 6 NUMERI'!$B$14)-1))) | H22: =MAX(0,'1 - I TUOI 6 NUMERI'!$B$17-(IF('1 - I TUOI 6 NUMERI'!$B$6<=0,0,(18000*(1+'1 - I TUOI 6 NUMERI'!$B$14)^0)/(1-'1 - I TUOI 6 NUMERI'!$B$15*(IF('1 - I TUOI 6 NUMERI'!$B$6<=0,0,MEDIAN(0,('1 - I TUOI 6 NUMERI'!$B$6-'1 - I TUOI 6 NUMERI'!$B$17)/'1 - I TUOI 6 NUMERI'!$B$6,1))))))*(1-(IF('1 - I TUOI 6 NUMERI'!$B$6<=0,0,MEDIAN(0,('1 - I TUOI 6 NUMERI'!$B$6-'1 - I TUOI 6 NUMERI'!$B$17)/'1 - I TUOI 6 NUMERI'!$B$6,1))))) | I22: =IF('1 - I TUOI 6 NUMERI'!$B$6<=0,0,('1 - I TUOI 6 NUMERI'!$B$6-(IF('1 - I TUOI 6 NUMERI'!$B$6<=0,0,(18000*(1+'1 - I TUOI 6 NUMERI'!$B$14)^0)/(1-'1 - I TUOI 6 NUMERI'!$B$15*(IF('1 - I TUOI 6 NUMERI'!$B$6<=0,0,MEDIAN(0,('1 - I TUOI 6 NUMERI'!$B$6-'1 - I TUOI 6 NUMERI'!$B$17)/'1 - I TUOI 6 NUMERI'!$B$6,1))))))-(IF('1 - I TUOI 6 NUMERI'!$B$6<=0,0,'1 - I TUOI 6 NUMERI'!$B$16*'1 - I TUOI 6 NUMERI'!$B$6)))*(1+((1+0.03)*(1+'1 - I TUOI 6 NUMERI'!$B$14)-1))) | J22: =MAX(0,'1 - I TUOI 6 NUMERI'!$B$17-(IF('1 - I TUOI 6 NUMERI'!$B$6<=0,0,(18000*(1+'1 - I TUOI 6 NUMERI'!$B$14)^0)/(1-'1 - I TUOI 6 NUMERI'!$B$15*(IF('1 - I TUOI 6 NUMERI'!$B$6<=0,0,MEDIAN(0,('1 - I TUOI 6 NUMERI'!$B$6-'1 - I TUOI 6 NUMERI'!$B$17)/'1 - I TUOI 6 NUMERI'!$B$6,1))))))*(1-(IF('1 - I TUOI 6 NUMERI'!$B$6<=0,0,MEDIAN(0,('1 - I TUOI 6 NUMERI'!$B$6-'1 - I TUOI 6 NUMERI'!$B$17)/'1 - I TUOI 6 NUMERI'!$B$6,1))))) | K22: =IF('1 - I TUOI 6 NUMERI'!$B$6<=0,0,('1 - I TUOI 6 NUMERI'!$B$6-(IF('1 - I TUOI 6 NUMERI'!$B$6<=0,0,(18000*(1+'1 - I TUOI 6 NUMERI'!$B$14)^0)/(1-'1 - I TUOI 6 NUMERI'!$B$15*(IF('1 - I TUOI 6 NUMERI'!$B$6<=0,0,MEDIAN(0,('1 - I TUOI 6 NUMERI'!$B$6-'1 - I TUOI 6 NUMERI'!$B$17)/'1 - I TUOI 6 NUMERI'!$B$6,1))))))-(IF('1 - I TUOI 6 NUMERI'!$B$6<=0,0,'1 - I TUOI 6 NUMERI'!$B$16*'1 - I TUOI 6 NUMERI'!$B$6)))*(1+((1+0.05)*(1+'1 - I TUOI 6 NUMERI'!$B$14)-1))) | L22: =MAX(0,'1 - I TUOI 6 NUMERI'!$B$17-(IF('1 - I TUOI 6 NUMERI'!$B$6<=0,0,(18000*(1+'1 - I TUOI 6 NUMERI'!$B$14)^0)/(1-'1 - I TUOI 6 NUMERI'!$B$15*(IF('1 - I TUOI 6 NUMERI'!$B$6<=0,0,MEDIAN(0,('1 - I TUOI 6 NUMERI'!$B$6-'1 - I TUOI 6 NUMERI'!$B$17)/'1 - I TUOI 6 NUMERI'!$B$6,1))))))*(1-(IF('1 - I TUOI 6 NUMERI'!$B$6<=0,0,MEDIAN(0,('1 - I TUOI 6 NUMERI'!$B$6-'1 - I TUOI 6 NUMERI'!$B$17)/'1 - I TUOI 6 NUMERI'!$B$6,1))))) | M22: =IF('1 - I TUOI 6 NUMERI'!$B$6<=0,0,('1 - I TUOI 6 NUMERI'!$B$6-(IF('1 - I TUOI 6 NUMERI'!$B$6<=0,0,(24000*(1+'1 - I TUOI 6 NUMERI'!$B$14)^0)/(1-'1 - I TUOI 6 NUMERI'!$B$15*(IF('1 - I TUOI 6 NUMERI'!$B$6<=0,0,MEDIAN(0,('1 - I TUOI 6 NUMERI'!$B$6-'1 - I TUOI 6 NUMERI'!$B$17)/'1 - I TUOI 6 NUMERI'!$B$6,1))))))-(IF('1 - I TUOI 6 NUMERI'!$B$6<=0,0,'1 - I TUOI 6 NUMERI'!$B$16*'1 - I TUOI 6 NUMERI'!$B$6)))*(1+((1+0.01)*(1+'1 - I TUOI 6 NUMERI'!$B$14)-1))) | N22: =MAX(0,'1 - I TUOI 6 NUMERI'!$B$17-(IF('1 - I TUOI 6 NUMERI'!$B$6<=0,0,(24000*(1+'1 - I TUOI 6 NUMERI'!$B$14)^0)/(1-'1 - I TUOI 6 NUMERI'!$B$15*(IF('1 - I TUOI 6 NUMERI'!$B$6<=0,0,MEDIAN(0,('1 - I TUOI 6 NUMERI'!$B$6-'1 - I TUOI 6 NUMERI'!$B$17)/'1 - I TUOI 6 NUMERI'!$B$6,1))))))*(1-(IF('1 - I TUOI 6 NUMERI'!$B$6<=0,0,MEDIAN(0,('1 - I TUOI 6 NUMERI'!$B$6-'1 - I TUOI 6 NUMERI'!$B$17)/'1 - I TUOI 6 NUMERI'!$B$6,1))))) | O22: =IF('1 - I TUOI 6 NUMERI'!$B$6<=0,0,('1 - I TUOI 6 NUMERI'!$B$6-(IF('1 - I TUOI 6 NUMERI'!$B$6<=0,0,(24000*(1+'1 - I TUOI 6 NUMERI'!$B$14)^0)/(1-'1 - I TUOI 6 NUMERI'!$B$15*(IF('1 - I TUOI 6 NUMERI'!$B$6<=0,0,MEDIAN(0,('1 - I TUOI 6 NUMERI'!$B$6-'1 - I TUOI 6 NUMERI'!$B$17)/'1 - I TUOI 6 NUMERI'!$B$6,1))))))-(IF('1 - I TUOI 6 NUMERI'!$B$6<=0,0,'1 - I TUOI 6 NUMERI'!$B$16*'1 - I TUOI 6 NUMERI'!$B$6)))*(1+((1+0.03)*(1+'1 - I TUOI 6 NUMERI'!$B$14)-1))) | P22: =MAX(0,'1 - I TUOI 6 NUMERI'!$B$17-(IF('1 - I TUOI 6 NUMERI'!$B$6<=0,0,(24000*(1+'1 - I TUOI 6 NUMERI'!$B$14)^0)/(1-'1 - I TUOI 6 NUMERI'!$B$15*(IF('1 - I TUOI 6 NUMERI'!$B$6<=0,0,MEDIAN(0,('1 - I TUOI 6 NUMERI'!$B$6-'1 - I TUOI 6 NUMERI'!$B$17)/'1 - I TUOI 6 NUMERI'!$B$6,1))))))*(1-(IF('1 - I TUOI 6 NUMERI'!$B$6<=0,0,MEDIAN(0,('1 - I TUOI 6 NUMERI'!$B$6-'1 - I TUOI 6 NUMERI'!$B$17)/'1 - I TUOI 6 NUMERI'!$B$6,1))))) | Q22: =IF('1 - I TUOI 6 NUMERI'!$B$6<=0,0,('1 - I TUOI 6 NUMERI'!$B$6-(IF('1 - I TUOI 6 NUMERI'!$B$6<=0,0,(24000*(1+'1 - I TUOI 6 NUMERI'!$B$14)^0)/(1-'1 - I TUOI 6 NUMERI'!$B$15*(IF('1 - I TUOI 6 NUMERI'!$B$6<=0,0,MEDIAN(0,('1 - I TUOI 6 NUMERI'!$B$6-'1 - I TUOI 6 NUMERI'!$B$17)/'1 - I TUOI 6 NUMERI'!$B$6,1))))))-(IF('1 - I TUOI 6 NUMERI'!$B$6<=0,0,'1 - I TUOI 6 NUMERI'!$B$16*'1 - I TUOI 6 NUMERI'!$B$6)))*(1+((1+0.05)*(1+'1 - I TUOI 6 NUMERI'!$B$14)-1))) | R22: =MAX(0,'1 - I TUOI 6 NUMERI'!$B$17-(IF('1 - I TUOI 6 NUMERI'!$B$6<=0,0,(24000*(1+'1 - I TUOI 6 NUMERI'!$B$14)^0)/(1-'1 - I TUOI 6 NUMERI'!$B$15*(IF('1 - I TUOI 6 NUMERI'!$B$6<=0,0,MEDIAN(0,('1 - I TUOI 6 NUMERI'!$B$6-'1 - I TUOI 6 NUMERI'!$B$17)/'1 - I TUOI 6 NUMERI'!$B$6,1))))))*(1-(IF('1 - I TUOI 6 NUMERI'!$B$6<=0,0,MEDIAN(0,('1 - I TUOI 6 NUMERI'!$B$6-'1 - I TUOI 6 NUMERI'!$B$17)/'1 - I TUOI 6 NUMERI'!$B$6,1))))) | S22: =IF('1 - I TUOI 6 NUMERI'!$B$6<=0,0,('1 - I TUOI 6 NUMERI'!$B$6-(IF('1 - I TUOI 6 NUMERI'!$B$6<=0,0,(30000*(1+'1 - I TUOI 6 NUMERI'!$B$14)^0)/(1-'1 - I TUOI 6 NUMERI'!$B$15*(IF('1 - I TUOI 6 NUMERI'!$B$6<=0,0,MEDIAN(0,('1 - I TUOI 6 NUMERI'!$B$6-'1 - I TUOI 6 NUMERI'!$B$17)/'1 - I TUOI 6 NUMERI'!$B$6,1))))))-(IF('1 - I TUOI 6 NUMERI'!$B$6<=0,0,'1 - I TUOI 6 NUMERI'!$B$16*'1 - I TUOI 6 NUMERI'!$B$6)))*(1+((1+0.01)*(1+'1 - I TUOI 6 NUMERI'!$B$14)-1))) | T22: =MAX(0,'1 - I TUOI 6 NUMERI'!$B$17-(IF('1 - I TUOI 6 NUMERI'!$B$6<=0,0,(30000*(1+'1 - I TUOI 6 NUMERI'!$B$14)^0)/(1-'1 - I TUOI 6 NUMERI'!$B$15*(IF('1 - I TUOI 6 NUMERI'!$B$6<=0,0,MEDIAN(0,('1 - I TUOI 6 NUMERI'!$B$6-'1 - I TUOI 6 NUMERI'!$B$17)/'1 - I TUOI 6 NUMERI'!$B$6,1))))))*(1-(IF('1 - I TUOI 6 NUMERI'!$B$6<=0,0,MEDIAN(0,('1 - I TUOI 6 NUMERI'!$B$6-'1 - I TUOI 6 NUMERI'!$B$17)/'1 - I TUOI 6 NUMERI'!$B$6,1))))) | U22: =IF('1 - I TUOI 6 NUMERI'!$B$6<=0,0,('1 - I TUOI 6 NUMERI'!$B$6-(IF('1 - I TUOI 6 NUMERI'!$B$6<=0,0,(30000*(1+'1 - I TUOI 6 NUMERI'!$B$14)^0)/(1-'1 - I TUOI 6 NUMERI'!$B$15*(IF('1 - I TUOI 6 NUMERI'!$B$6<=0,0,MEDIAN(0,('1 - I TUOI 6 NUMERI'!$B$6-'1 - I TUOI 6 NUMERI'!$B$17)/'1 - I TUOI 6 NUMERI'!$B$6,1))))))-(IF('1 - I TUOI 6 NUMERI'!$B$6<=0,0,'1 - I TUOI 6 NUMERI'!$B$16*'1 - I TUOI 6 NUMERI'!$B$6)))*(1+((1+0.03)*(1+'1 - I TUOI 6 NUMERI'!$B$14)-1))) | V22: =MAX(0,'1 - I TUOI 6 NUMERI'!$B$17-(IF('1 - I TUOI 6 NUMERI'!$B$6<=0,0,(30000*(1+'1 - I TUOI 6 NUMERI'!$B$14)^0)/(1-'1 - I TUOI 6 NUMERI'!$B$15*(IF('1 - I TUOI 6 NUMERI'!$B$6<=0,0,MEDIAN(0,('1 - I TUOI 6 NUMERI'!$B$6-'1 - I TUOI 6 NUMERI'!$B$17)/'1 - I TUOI 6 NUMERI'!$B$6,1))))))*(1-(IF('1 - I TUOI 6 NUMERI'!$B$6<=0,0,MEDIAN(0,('1 - I TUOI 6 NUMERI'!$B$6-'1 - I TUOI 6 NUMERI'!$B$17)/'1 - I TUOI 6 NUMERI'!$B$6,1))))) | W22: =IF('1 - I TUOI 6 NUMERI'!$B$6<=0,0,('1 - I TUOI 6 NUMERI'!$B$6-(IF('1 - I TUOI 6 NUMERI'!$B$6<=0,0,(30000*(1+'1 - I TUOI 6 NUMERI'!$B$14)^0)/(1-'1 - I TUOI 6 NUMERI'!$B$15*(IF('1 - I TUOI 6 NUMERI'!$B$6<=0,0,MEDIAN(0,('1 - I TUOI 6 NUMERI'!$B$6-'1 - I TUOI 6 NUMERI'!$B$17)/'1 - I TUOI 6 NUMERI'!$B$6,1))))))-(IF('1 - I TUOI 6 NUMERI'!$B$6<=0,0,'1 - I TUOI 6 NUMERI'!$B$16*'1 - I TUOI 6 NUMERI'!$B$6)))*(1+((1+0.05)*(1+'1 - I TUOI 6 NUMERI'!$B$14)-1))) | X22: =MAX(0,'1 - I TUOI 6 NUMERI'!$B$17-(IF('1 - I TUOI 6 NUMERI'!$B$6<=0,0,(30000*(1+'1 - I TUOI 6 NUMERI'!$B$14)^0)/(1-'1 - I TUOI 6 NUMERI'!$B$15*(IF('1 - I TUOI 6 NUMERI'!$B$6<=0,0,MEDIAN(0,('1 - I TUOI 6 NUMERI'!$B$6-'1 - I TUOI 6 NUMERI'!$B$17)/'1 - I TUOI 6 NUMERI'!$B$6,1))))))*(1-(IF('1 - I TUOI 6 NUMERI'!$B$6<=0,0,MEDIAN(0,('1 - I TUOI 6 NUMERI'!$B$6-'1 - I TUOI 6 NUMERI'!$B$17)/'1 - I TUOI 6 NUMERI'!$B$6,1))))) | Y22: =IF('1 - I TUOI 6 NUMERI'!$B$6<=0,0,('1 - I TUOI 6 NUMERI'!$B$6-(IF('1 - I TUOI 6 NUMERI'!$B$6<=0,0,(36000*(1+'1 - I TUOI 6 NUMERI'!$B$14)^0)/(1-'1 - I TUOI 6 NUMERI'!$B$15*(IF('1 - I TUOI 6 NUMERI'!$B$6<=0,0,MEDIAN(0,('1 - I TUOI 6 NUMERI'!$B$6-'1 - I TUOI 6 NUMERI'!$B$17)/'1 - I TUOI 6 NUMERI'!$B$6,1))))))-(IF('1 - I TUOI 6 NUMERI'!$B$6<=0,0,'1 - I TUOI 6 NUMERI'!$B$16*'1 - I TUOI 6 NUMERI'!$B$6)))*(1+((1+0.01)*(1+'1 - I TUOI 6 NUMERI'!$B$14)-1))) | Z22: =MAX(0,'1 - I TUOI 6 NUMERI'!$B$17-(IF('1 - I TUOI 6 NUMERI'!$B$6<=0,0,(36000*(1+'1 - I TUOI 6 NUMERI'!$B$14)^0)/(1-'1 - I TUOI 6 NUMERI'!$B$15*(IF('1 - I TUOI 6 NUMERI'!$B$6<=0,0,MEDIAN(0,('1 - I TUOI 6 NUMERI'!$B$6-'1 - I TUOI 6 NUMERI'!$B$17)/'1 - I TUOI 6 NUMERI'!$B$6,1))))))*(1-(IF('1 - I TUOI 6 NUMERI'!$B$6<=0,0,MEDIAN(0,('1 - I TUOI 6 NUMERI'!$B$6-'1 - I TUOI 6 NUMERI'!$B$17)/'1 - I TUOI 6 NUMERI'!$B$6,1))))) | AA22: =IF('1 - I TUOI 6 NUMERI'!$B$6<=0,0,('1 - I TUOI 6 NUMERI'!$B$6-(IF('1 - I TUOI 6 NUMERI'!$B$6<=0,0,(36000*(1+'1 - I TUOI 6 NUMERI'!$B$14)^0)/(1-'1 - I TUOI 6 NUMERI'!$B$15*(IF('1 - I TUOI 6 NUMERI'!$B$6<=0,0,MEDIAN(0,('1 - I TUOI 6 NUMERI'!$B$6-'1 - I TUOI 6 NUMERI'!$B$17)/'1 - I TUOI 6 NUMERI'!$B$6,1))))))-(IF('1 - I TUOI 6 NUMERI'!$B$6<=0,0,'1 - I TUOI 6 NUMERI'!$B$16*'1 - I TUOI 6 NUMERI'!$B$6)))*(1+((1+0.03)*(1+'1 - I TUOI 6 NUMERI'!$B$14)-1))) | AB22: =MAX(0,'1 - I TUOI 6 NUMERI'!$B$17-(IF('1 - I TUOI 6 NUMERI'!$B$6<=0,0,(36000*(1+'1 - I TUOI 6 NUMERI'!$B$14)^0)/(1-'1 - I TUOI 6 NUMERI'!$B$15*(IF('1 - I TUOI 6 NUMERI'!$B$6<=0,0,MEDIAN(0,('1 - I TUOI 6 NUMERI'!$B$6-'1 - I TUOI 6 NUMERI'!$B$17)/'1 - I TUOI 6 NUMERI'!$B$6,1))))))*(1-(IF('1 - I TUOI 6 NUMERI'!$B$6<=0,0,MEDIAN(0,('1 - I TUOI 6 NUMERI'!$B$6-'1 - I TUOI 6 NUMERI'!$B$17)/'1 - I TUOI 6 NUMERI'!$B$6,1))))) | AC22: =IF('1 - I TUOI 6 NUMERI'!$B$6<=0,0,('1 - I TUOI 6 NUMERI'!$B$6-(IF('1 - I TUOI 6 NUMERI'!$B$6<=0,0,(36000*(1+'1 - I TUOI 6 NUMERI'!$B$14)^0)/(1-'1 - I TUOI 6 NUMERI'!$B$15*(IF('1 - I TUOI 6 NUMERI'!$B$6<=0,0,MEDIAN(0,('1 - I TUOI 6 NUMERI'!$B$6-'1 - I TUOI 6 NUMERI'!$B$17)/'1 - I TUOI 6 NUMERI'!$B$6,1))))))-(IF('1 - I TUOI 6 NUMERI'!$B$6<=0,0,'1 - I TUOI 6 NUMERI'!$B$16*'1 - I TUOI 6 NUMERI'!$B$6)))*(1+((1+0.05)*(1+'1 - I TUOI 6 NUMERI'!$B$14)-1))) | AD22: =MAX(0,'1 - I TUOI 6 NUMERI'!$B$17-(IF('1 - I TUOI 6 NUMERI'!$B$6<=0,0,(36000*(1+'1 - I TUOI 6 NUMERI'!$B$14)^0)/(1-'1 - I TUOI 6 NUMERI'!$B$15*(IF('1 - I TUOI 6 NUMERI'!$B$6<=0,0,MEDIAN(0,('1 - I TUOI 6 NUMERI'!$B$6-'1 - I TUOI 6 NUMERI'!$B$17)/'1 - I TUOI 6 NUMERI'!$B$6,1))))))*(1-(IF('1 - I TUOI 6 NUMERI'!$B$6<=0,0,MEDIAN(0,('1 - I TUOI 6 NUMERI'!$B$6-'1 - I TUOI 6 NUMERI'!$B$17)/'1 - I TUOI 6 NUMERI'!$B$6,1)))))
F23: 1 | G23: =IF(G22<=0,0,(G22-(IF(G22<=0,0,(18000*(1+'1 - I TUOI 6 NUMERI'!$B$14)^1)/(1-'1 - I TUOI 6 NUMERI'!$B$15*(IF(G22<=0,0,MEDIAN(0,(G22-H22)/G22,1))))))-(IF(G22<=0,0,'1 - I TUOI 6 NUMERI'!$B$16*G22)))*(1+((1+0.01)*(1+'1 - I TUOI 6 NUMERI'!$B$14)-1))) | H23: =MAX(0,H22-(IF(G22<=0,0,(18000*(1+'1 - I TUOI 6 NUMERI'!$B$14)^1)/(1-'1 - I TUOI 6 NUMERI'!$B$15*(IF(G22<=0,0,MEDIAN(0,(G22-H22)/G22,1))))))*(1-(IF(G22<=0,0,MEDIAN(0,(G22-H22)/G22,1))))) | I23: =IF(I22<=0,0,(I22-(IF(I22<=0,0,(18000*(1+'1 - I TUOI 6 NUMERI'!$B$14)^1)/(1-'1 - I TUOI 6 NUMERI'!$B$15*(IF(I22<=0,0,MEDIAN(0,(I22-J22)/I22,1))))))-(IF(I22<=0,0,'1 - I TUOI 6 NUMERI'!$B$16*I22)))*(1+((1+0.03)*(1+'1 - I TUOI 6 NUMERI'!$B$14)-1))) | J23: =MAX(0,J22-(IF(I22<=0,0,(18000*(1+'1 - I TUOI 6 NUMERI'!$B$14)^1)/(1-'1 - I TUOI 6 NUMERI'!$B$15*(IF(I22<=0,0,MEDIAN(0,(I22-J22)/I22,1))))))*(1-(IF(I22<=0,0,MEDIAN(0,(I22-J22)/I22,1))))) | K23: =IF(K22<=0,0,(K22-(IF(K22<=0,0,(18000*(1+'1 - I TUOI 6 NUMERI'!$B$14)^1)/(1-'1 - I TUOI 6 NUMERI'!$B$15*(IF(K22<=0,0,MEDIAN(0,(K22-L22)/K22,1))))))-(IF(K22<=0,0,'1 - I TUOI 6 NUMERI'!$B$16*K22)))*(1+((1+0.05)*(1+'1 - I TUOI 6 NUMERI'!$B$14)-1))) | L23: =MAX(0,L22-(IF(K22<=0,0,(18000*(1+'1 - I TUOI 6 NUMERI'!$B$14)^1)/(1-'1 - I TUOI 6 NUMERI'!$B$15*(IF(K22<=0,0,MEDIAN(0,(K22-L22)/K22,1))))))*(1-(IF(K22<=0,0,MEDIAN(0,(K22-L22)/K22,1))))) | M23: =IF(M22<=0,0,(M22-(IF(M22<=0,0,(24000*(1+'1 - I TUOI 6 NUMERI'!$B$14)^1)/(1-'1 - I TUOI 6 NUMERI'!$B$15*(IF(M22<=0,0,MEDIAN(0,(M22-N22)/M22,1))))))-(IF(M22<=0,0,'1 - I TUOI 6 NUMERI'!$B$16*M22)))*(1+((1+0.01)*(1+'1 - I TUOI 6 NUMERI'!$B$14)-1))) | N23: =MAX(0,N22-(IF(M22<=0,0,(24000*(1+'1 - I TUOI 6 NUMERI'!$B$14)^1)/(1-'1 - I TUOI 6 NUMERI'!$B$15*(IF(M22<=0,0,MEDIAN(0,(M22-N22)/M22,1))))))*(1-(IF(M22<=0,0,MEDIAN(0,(M22-N22)/M22,1))))) | O23: =IF(O22<=0,0,(O22-(IF(O22<=0,0,(24000*(1+'1 - I TUOI 6 NUMERI'!$B$14)^1)/(1-'1 - I TUOI 6 NUMERI'!$B$15*(IF(O22<=0,0,MEDIAN(0,(O22-P22)/O22,1))))))-(IF(O22<=0,0,'1 - I TUOI 6 NUMERI'!$B$16*O22)))*(1+((1+0.03)*(1+'1 - I TUOI 6 NUMERI'!$B$14)-1))) | P23: =MAX(0,P22-(IF(O22<=0,0,(24000*(1+'1 - I TUOI 6 NUMERI'!$B$14)^1)/(1-'1 - I TUOI 6 NUMERI'!$B$15*(IF(O22<=0,0,MEDIAN(0,(O22-P22)/O22,1))))))*(1-(IF(O22<=0,0,MEDIAN(0,(O22-P22)/O22,1))))) | Q23: =IF(Q22<=0,0,(Q22-(IF(Q22<=0,0,(24000*(1+'1 - I TUOI 6 NUMERI'!$B$14)^1)/(1-'1 - I TUOI 6 NUMERI'!$B$15*(IF(Q22<=0,0,MEDIAN(0,(Q22-R22)/Q22,1))))))-(IF(Q22<=0,0,'1 - I TUOI 6 NUMERI'!$B$16*Q22)))*(1+((1+0.05)*(1+'1 - I TUOI 6 NUMERI'!$B$14)-1))) | R23: =MAX(0,R22-(IF(Q22<=0,0,(24000*(1+'1 - I TUOI 6 NUMERI'!$B$14)^1)/(1-'1 - I TUOI 6 NUMERI'!$B$15*(IF(Q22<=0,0,MEDIAN(0,(Q22-R22)/Q22,1))))))*(1-(IF(Q22<=0,0,MEDIAN(0,(Q22-R22)/Q22,1))))) | S23: =IF(S22<=0,0,(S22-(IF(S22<=0,0,(30000*(1+'1 - I TUOI 6 NUMERI'!$B$14)^1)/(1-'1 - I TUOI 6 NUMERI'!$B$15*(IF(S22<=0,0,MEDIAN(0,(S22-T22)/S22,1))))))-(IF(S22<=0,0,'1 - I TUOI 6 NUMERI'!$B$16*S22)))*(1+((1+0.01)*(1+'1 - I TUOI 6 NUMERI'!$B$14)-1))) | T23: =MAX(0,T22-(IF(S22<=0,0,(30000*(1+'1 - I TUOI 6 NUMERI'!$B$14)^1)/(1-'1 - I TUOI 6 NUMERI'!$B$15*(IF(S22<=0,0,MEDIAN(0,(S22-T22)/S22,1))))))*(1-(IF(S22<=0,0,MEDIAN(0,(S22-T22)/S22,1))))) | U23: =IF(U22<=0,0,(U22-(IF(U22<=0,0,(30000*(1+'1 - I TUOI 6 NUMERI'!$B$14)^1)/(1-'1 - I TUOI 6 NUMERI'!$B$15*(IF(U22<=0,0,MEDIAN(0,(U22-V22)/U22,1))))))-(IF(U22<=0,0,'1 - I TUOI 6 NUMERI'!$B$16*U22)))*(1+((1+0.03)*(1+'1 - I TUOI 6 NUMERI'!$B$14)-1))) | V23: =MAX(0,V22-(IF(U22<=0,0,(30000*(1+'1 - I TUOI 6 NUMERI'!$B$14)^1)/(1-'1 - I TUOI 6 NUMERI'!$B$15*(IF(U22<=0,0,MEDIAN(0,(U22-V22)/U22,1))))))*(1-(IF(U22<=0,0,MEDIAN(0,(U22-V22)/U22,1))))) | W23: =IF(W22<=0,0,(W22-(IF(W22<=0,0,(30000*(1+'1 - I TUOI 6 NUMERI'!$B$14)^1)/(1-'1 - I TUOI 6 NUMERI'!$B$15*(IF(W22<=0,0,MEDIAN(0,(W22-X22)/W22,1))))))-(IF(W22<=0,0,'1 - I TUOI 6 NUMERI'!$B$16*W22)))*(1+((1+0.05)*(1+'1 - I TUOI 6 NUMERI'!$B$14)-1))) | X23: =MAX(0,X22-(IF(W22<=0,0,(30000*(1+'1 - I TUOI 6 NUMERI'!$B$14)^1)/(1-'1 - I TUOI 6 NUMERI'!$B$15*(IF(W22<=0,0,MEDIAN(0,(W22-X22)/W22,1))))))*(1-(IF(W22<=0,0,MEDIAN(0,(W22-X22)/W22,1))))) | Y23: =IF(Y22<=0,0,(Y22-(IF(Y22<=0,0,(36000*(1+'1 - I TUOI 6 NUMERI'!$B$14)^1)/(1-'1 - I TUOI 6 NUMERI'!$B$15*(IF(Y22<=0,0,MEDIAN(0,(Y22-Z22)/Y22,1))))))-(IF(Y22<=0,0,'1 - I TUOI 6 NUMERI'!$B$16*Y22)))*(1+((1+0.01)*(1+'1 - I TUOI 6 NUMERI'!$B$14)-1))) | Z23: =MAX(0,Z22-(IF(Y22<=0,0,(36000*(1+'1 - I TUOI 6 NUMERI'!$B$14)^1)/(1-'1 - I TUOI 6 NUMERI'!$B$15*(IF(Y22<=0,0,MEDIAN(0,(Y22-Z22)/Y22,1))))))*(1-(IF(Y22<=0,0,MEDIAN(0,(Y22-Z22)/Y22,1))))) | AA23: =IF(AA22<=0,0,(AA22-(IF(AA22<=0,0,(36000*(1+'1 - I TUOI 6 NUMERI'!$B$14)^1)/(1-'1 - I TUOI 6 NUMERI'!$B$15*(IF(AA22<=0,0,MEDIAN(0,(AA22-AB22)/AA22,1))))))-(IF(AA22<=0,0,'1 - I TUOI 6 NUMERI'!$B$16*AA22)))*(1+((1+0.03)*(1+'1 - I TUOI 6 NUMERI'!$B$14)-1))) | AB23: =MAX(0,AB22-(IF(AA22<=0,0,(36000*(1+'1 - I TUOI 6 NUMERI'!$B$14)^1)/(1-'1 - I TUOI 6 NUMERI'!$B$15*(IF(AA22<=0,0,MEDIAN(0,(AA22-AB22)/AA22,1))))))*(1-(IF(AA22<=0,0,MEDIAN(0,(AA22-AB22)/AA22,1))))) | AC23: =IF(AC22<=0,0,(AC22-(IF(AC22<=0,0,(36000*(1+'1 - I TUOI 6 NUMERI'!$B$14)^1)/(1-'1 - I TUOI 6 NUMERI'!$B$15*(IF(AC22<=0,0,MEDIAN(0,(AC22-AD22)/AC22,1))))))-(IF(AC22<=0,0,'1 - I TUOI 6 NUMERI'!$B$16*AC22)))*(1+((1+0.05)*(1+'1 - I TUOI 6 NUMERI'!$B$14)-1))) | AD23: =MAX(0,AD22-(IF(AC22<=0,0,(36000*(1+'1 - I TUOI 6 NUMERI'!$B$14)^1)/(1-'1 - I TUOI 6 NUMERI'!$B$15*(IF(AC22<=0,0,MEDIAN(0,(AC22-AD22)/AC22,1))))))*(1-(IF(AC22<=0,0,MEDIAN(0,(AC22-AD22)/AC22,1)))))
F24: 2 | G24: =IF(G23<=0,0,(G23-(IF(G23<=0,0,(18000*(1+'1 - I TUOI 6 NUMERI'!$B$14)^2)/(1-'1 - I TUOI 6 NUMERI'!$B$15*(IF(G23<=0,0,MEDIAN(0,(G23-H23)/G23,1))))))-(IF(G23<=0,0,'1 - I TUOI 6 NUMERI'!$B$16*G23)))*(1+((1+0.01)*(1+'1 - I TUOI 6 NUMERI'!$B$14)-1))) | H24: =MAX(0,H23-(IF(G23<=0,0,(18000*(1+'1 - I TUOI 6 NUMERI'!$B$14)^2)/(1-'1 - I TUOI 6 NUMERI'!$B$15*(IF(G23<=0,0,MEDIAN(0,(G23-H23)/G23,1))))))*(1-(IF(G23<=0,0,MEDIAN(0,(G23-H23)/G23,1))))) | I24: =IF(I23<=0,0,(I23-(IF(I23<=0,0,(18000*(1+'1 - I TUOI 6 NUMERI'!$B$14)^2)/(1-'1 - I TUOI 6 NUMERI'!$B$15*(IF(I23<=0,0,MEDIAN(0,(I23-J23)/I23,1))))))-(IF(I23<=0,0,'1 - I TUOI 6 NUMERI'!$B$16*I23)))*(1+((1+0.03)*(1+'1 - I TUOI 6 NUMERI'!$B$14)-1))) | J24: =MAX(0,J23-(IF(I23<=0,0,(18000*(1+'1 - I TUOI 6 NUMERI'!$B$14)^2)/(1-'1 - I TUOI 6 NUMERI'!$B$15*(IF(I23<=0,0,MEDIAN(0,(I23-J23)/I23,1))))))*(1-(IF(I23<=0,0,MEDIAN(0,(I23-J23)/I23,1))))) | K24: =IF(K23<=0,0,(K23-(IF(K23<=0,0,(18000*(1+'1 - I TUOI 6 NUMERI'!$B$14)^2)/(1-'1 - I TUOI 6 NUMERI'!$B$15*(IF(K23<=0,0,MEDIAN(0,(K23-L23)/K23,1))))))-(IF(K23<=0,0,'1 - I TUOI 6 NUMERI'!$B$16*K23)))*(1+((1+0.05)*(1+'1 - I TUOI 6 NUMERI'!$B$14)-1))) | L24: =MAX(0,L23-(IF(K23<=0,0,(18000*(1+'1 - I TUOI 6 NUMERI'!$B$14)^2)/(1-'1 - I TUOI 6 NUMERI'!$B$15*(IF(K23<=0,0,MEDIAN(0,(K23-L23)/K23,1))))))*(1-(IF(K23<=0,0,MEDIAN(0,(K23-L23)/K23,1))))) | M24: =IF(M23<=0,0,(M23-(IF(M23<=0,0,(24000*(1+'1 - I TUOI 6 NUMERI'!$B$14)^2)/(1-'1 - I TUOI 6 NUMERI'!$B$15*(IF(M23<=0,0,MEDIAN(0,(M23-N23)/M23,1))))))-(IF(M23<=0,0,'1 - I TUOI 6 NUMERI'!$B$16*M23)))*(1+((1+0.01)*(1+'1 - I TUOI 6 NUMERI'!$B$14)-1))) | N24: =MAX(0,N23-(IF(M23<=0,0,(24000*(1+'1 - I TUOI 6 NUMERI'!$B$14)^2)/(1-'1 - I TUOI 6 NUMERI'!$B$15*(IF(M23<=0,0,MEDIAN(0,(M23-N23)/M23,1))))))*(1-(IF(M23<=0,0,MEDIAN(0,(M23-N23)/M23,1))))) | O24: =IF(O23<=0,0,(O23-(IF(O23<=0,0,(24000*(1+'1 - I TUOI 6 NUMERI'!$B$14)^2)/(1-'1 - I TUOI 6 NUMERI'!$B$15*(IF(O23<=0,0,MEDIAN(0,(O23-P23)/O23,1))))))-(IF(O23<=0,0,'1 - I TUOI 6 NUMERI'!$B$16*O23)))*(1+((1+0.03)*(1+'1 - I TUOI 6 NUMERI'!$B$14)-1))) | P24: =MAX(0,P23-(IF(O23<=0,0,(24000*(1+'1 - I TUOI 6 NUMERI'!$B$14)^2)/(1-'1 - I TUOI 6 NUMERI'!$B$15*(IF(O23<=0,0,MEDIAN(0,(O23-P23)/O23,1))))))*(1-(IF(O23<=0,0,MEDIAN(0,(O23-P23)/O23,1))))) | Q24: =IF(Q23<=0,0,(Q23-(IF(Q23<=0,0,(24000*(1+'1 - I TUOI 6 NUMERI'!$B$14)^2)/(1-'1 - I TUOI 6 NUMERI'!$B$15*(IF(Q23<=0,0,MEDIAN(0,(Q23-R23)/Q23,1))))))-(IF(Q23<=0,0,'1 - I TUOI 6 NUMERI'!$B$16*Q23)))*(1+((1+0.05)*(1+'1 - I TUOI 6 NUMERI'!$B$14)-1))) | R24: =MAX(0,R23-(IF(Q23<=0,0,(24000*(1+'1 - I TUOI 6 NUMERI'!$B$14)^2)/(1-'1 - I TUOI 6 NUMERI'!$B$15*(IF(Q23<=0,0,MEDIAN(0,(Q23-R23)/Q23,1))))))*(1-(IF(Q23<=0,0,MEDIAN(0,(Q23-R23)/Q23,1))))) | S24: =IF(S23<=0,0,(S23-(IF(S23<=0,0,(30000*(1+'1 - I TUOI 6 NUMERI'!$B$14)^2)/(1-'1 - I TUOI 6 NUMERI'!$B$15*(IF(S23<=0,0,MEDIAN(0,(S23-T23)/S23,1))))))-(IF(S23<=0,0,'1 - I TUOI 6 NUMERI'!$B$16*S23)))*(1+((1+0.01)*(1+'1 - I TUOI 6 NUMERI'!$B$14)-1))) | T24: =MAX(0,T23-(IF(S23<=0,0,(30000*(1+'1 - I TUOI 6 NUMERI'!$B$14)^2)/(1-'1 - I TUOI 6 NUMERI'!$B$15*(IF(S23<=0,0,MEDIAN(0,(S23-T23)/S23,1))))))*(1-(IF(S23<=0,0,MEDIAN(0,(S23-T23)/S23,1))))) | U24: =IF(U23<=0,0,(U23-(IF(U23<=0,0,(30000*(1+'1 - I TUOI 6 NUMERI'!$B$14)^2)/(1-'1 - I TUOI 6 NUMERI'!$B$15*(IF(U23<=0,0,MEDIAN(0,(U23-V23)/U23,1))))))-(IF(U23<=0,0,'1 - I TUOI 6 NUMERI'!$B$16*U23)))*(1+((1+0.03)*(1+'1 - I TUOI 6 NUMERI'!$B$14)-1))) | V24: =MAX(0,V23-(IF(U23<=0,0,(30000*(1+'1 - I TUOI 6 NUMERI'!$B$14)^2)/(1-'1 - I TUOI 6 NUMERI'!$B$15*(IF(U23<=0,0,MEDIAN(0,(U23-V23)/U23,1))))))*(1-(IF(U23<=0,0,MEDIAN(0,(U23-V23)/U23,1))))) | W24: =IF(W23<=0,0,(W23-(IF(W23<=0,0,(30000*(1+'1 - I TUOI 6 NUMERI'!$B$14)^2)/(1-'1 - I TUOI 6 NUMERI'!$B$15*(IF(W23<=0,0,MEDIAN(0,(W23-X23)/W23,1))))))-(IF(W23<=0,0,'1 - I TUOI 6 NUMERI'!$B$16*W23)))*(1+((1+0.05)*(1+'1 - I TUOI 6 NUMERI'!$B$14)-1))) | X24: =MAX(0,X23-(IF(W23<=0,0,(30000*(1+'1 - I TUOI 6 NUMERI'!$B$14)^2)/(1-'1 - I TUOI 6 NUMERI'!$B$15*(IF(W23<=0,0,MEDIAN(0,(W23-X23)/W23,1))))))*(1-(IF(W23<=0,0,MEDIAN(0,(W23-X23)/W23,1))))) | Y24: =IF(Y23<=0,0,(Y23-(IF(Y23<=0,0,(36000*(1+'1 - I TUOI 6 NUMERI'!$B$14)^2)/(1-'1 - I TUOI 6 NUMERI'!$B$15*(IF(Y23<=0,0,MEDIAN(0,(Y23-Z23)/Y23,1))))))-(IF(Y23<=0,0,'1 - I TUOI 6 NUMERI'!$B$16*Y23)))*(1+((1+0.01)*(1+'1 - I TUOI 6 NUMERI'!$B$14)-1))) | Z24: =MAX(0,Z23-(IF(Y23<=0,0,(36000*(1+'1 - I TUOI 6 NUMERI'!$B$14)^2)/(1-'1 - I TUOI 6 NUMERI'!$B$15*(IF(Y23<=0,0,MEDIAN(0,(Y23-Z23)/Y23,1))))))*(1-(IF(Y23<=0,0,MEDIAN(0,(Y23-Z23)/Y23,1))))) | AA24: =IF(AA23<=0,0,(AA23-(IF(AA23<=0,0,(36000*(1+'1 - I TUOI 6 NUMERI'!$B$14)^2)/(1-'1 - I TUOI 6 NUMERI'!$B$15*(IF(AA23<=0,0,MEDIAN(0,(AA23-AB23)/AA23,1))))))-(IF(AA23<=0,0,'1 - I TUOI 6 NUMERI'!$B$16*AA23)))*(1+((1+0.03)*(1+'1 - I TUOI 6 NUMERI'!$B$14)-1))) | AB24: =MAX(0,AB23-(IF(AA23<=0,0,(36000*(1+'1 - I TUOI 6 NUMERI'!$B$14)^2)/(1-'1 - I TUOI 6 NUMERI'!$B$15*(IF(AA23<=0,0,MEDIAN(0,(AA23-AB23)/AA23,1))))))*(1-(IF(AA23<=0,0,MEDIAN(0,(AA23-AB23)/AA23,1))))) | AC24: =IF(AC23<=0,0,(AC23-(IF(AC23<=0,0,(36000*(1+'1 - I TUOI 6 NUMERI'!$B$14)^2)/(1-'1 - I TUOI 6 NUMERI'!$B$15*(IF(AC23<=0,0,MEDIAN(0,(AC23-AD23)/AC23,1))))))-(IF(AC23<=0,0,'1 - I TUOI 6 NUMERI'!$B$16*AC23)))*(1+((1+0.05)*(1+'1 - I TUOI 6 NUMERI'!$B$14)-1))) | AD24: =MAX(0,AD23-(IF(AC23<=0,0,(36000*(1+'1 - I TUOI 6 NUMERI'!$B$14)^2)/(1-'1 - I TUOI 6 NUMERI'!$B$15*(IF(AC23<=0,0,MEDIAN(0,(AC23-AD23)/AC23,1))))))*(1-(IF(AC23<=0,0,MEDIAN(0,(AC23-AD23)/AC23,1)))))
F25: 3 | G25: =IF(G24<=0,0,(G24-(IF(G24<=0,0,(18000*(1+'1 - I TUOI 6 NUMERI'!$B$14)^3)/(1-'1 - I TUOI 6 NUMERI'!$B$15*(IF(G24<=0,0,MEDIAN(0,(G24-H24)/G24,1))))))-(IF(G24<=0,0,'1 - I TUOI 6 NUMERI'!$B$16*G24)))*(1+((1+0.01)*(1+'1 - I TUOI 6 NUMERI'!$B$14)-1))) | H25: =MAX(0,H24-(IF(G24<=0,0,(18000*(1+'1 - I TUOI 6 NUMERI'!$B$14)^3)/(1-'1 - I TUOI 6 NUMERI'!$B$15*(IF(G24<=0,0,MEDIAN(0,(G24-H24)/G24,1))))))*(1-(IF(G24<=0,0,MEDIAN(0,(G24-H24)/G24,1))))) | I25: =IF(I24<=0,0,(I24-(IF(I24<=0,0,(18000*(1+'1 - I TUOI 6 NUMERI'!$B$14)^3)/(1-'1 - I TUOI 6 NUMERI'!$B$15*(IF(I24<=0,0,MEDIAN(0,(I24-J24)/I24,1))))))-(IF(I24<=0,0,'1 - I TUOI 6 NUMERI'!$B$16*I24)))*(1+((1+0.03)*(1+'1 - I TUOI 6 NUMERI'!$B$14)-1))) | J25: =MAX(0,J24-(IF(I24<=0,0,(18000*(1+'1 - I TUOI 6 NUMERI'!$B$14)^3)/(1-'1 - I TUOI 6 NUMERI'!$B$15*(IF(I24<=0,0,MEDIAN(0,(I24-J24)/I24,1))))))*(1-(IF(I24<=0,0,MEDIAN(0,(I24-J24)/I24,1))))) | K25: =IF(K24<=0,0,(K24-(IF(K24<=0,0,(18000*(1+'1 - I TUOI 6 NUMERI'!$B$14)^3)/(1-'1 - I TUOI 6 NUMERI'!$B$15*(IF(K24<=0,0,MEDIAN(0,(K24-L24)/K24,1))))))-(IF(K24<=0,0,'1 - I TUOI 6 NUMERI'!$B$16*K24)))*(1+((1+0.05)*(1+'1 - I TUOI 6 NUMERI'!$B$14)-1))) | L25: =MAX(0,L24-(IF(K24<=0,0,(18000*(1+'1 - I TUOI 6 NUMERI'!$B$14)^3)/(1-'1 - I TUOI 6 NUMERI'!$B$15*(IF(K24<=0,0,MEDIAN(0,(K24-L24)/K24,1))))))*(1-(IF(K24<=0,0,MEDIAN(0,(K24-L24)/K24,1))))) | M25: =IF(M24<=0,0,(M24-(IF(M24<=0,0,(24000*(1+'1 - I TUOI 6 NUMERI'!$B$14)^3)/(1-'1 - I TUOI 6 NUMERI'!$B$15*(IF(M24<=0,0,MEDIAN(0,(M24-N24)/M24,1))))))-(IF(M24<=0,0,'1 - I TUOI 6 NUMERI'!$B$16*M24)))*(1+((1+0.01)*(1+'1 - I TUOI 6 NUMERI'!$B$14)-1))) | N25: =MAX(0,N24-(IF(M24<=0,0,(24000*(1+'1 - I TUOI 6 NUMERI'!$B$14)^3)/(1-'1 - I TUOI 6 NUMERI'!$B$15*(IF(M24<=0,0,MEDIAN(0,(M24-N24)/M24,1))))))*(1-(IF(M24<=0,0,MEDIAN(0,(M24-N24)/M24,1))))) | O25: =IF(O24<=0,0,(O24-(IF(O24<=0,0,(24000*(1+'1 - I TUOI 6 NUMERI'!$B$14)^3)/(1-'1 - I TUOI 6 NUMERI'!$B$15*(IF(O24<=0,0,MEDIAN(0,(O24-P24)/O24,1))))))-(IF(O24<=0,0,'1 - I TUOI 6 NUMERI'!$B$16*O24)))*(1+((1+0.03)*(1+'1 - I TUOI 6 NUMERI'!$B$14)-1))) | P25: =MAX(0,P24-(IF(O24<=0,0,(24000*(1+'1 - I TUOI 6 NUMERI'!$B$14)^3)/(1-'1 - I TUOI 6 NUMERI'!$B$15*(IF(O24<=0,0,MEDIAN(0,(O24-P24)/O24,1))))))*(1-(IF(O24<=0,0,MEDIAN(0,(O24-P24)/O24,1))))) | Q25: =IF(Q24<=0,0,(Q24-(IF(Q24<=0,0,(24000*(1+'1 - I TUOI 6 NUMERI'!$B$14)^3)/(1-'1 - I TUOI 6 NUMERI'!$B$15*(IF(Q24<=0,0,MEDIAN(0,(Q24-R24)/Q24,1))))))-(IF(Q24<=0,0,'1 - I TUOI 6 NUMERI'!$B$16*Q24)))*(1+((1+0.05)*(1+'1 - I TUOI 6 NUMERI'!$B$14)-1))) | R25: =MAX(0,R24-(IF(Q24<=0,0,(24000*(1+'1 - I TUOI 6 NUMERI'!$B$14)^3)/(1-'1 - I TUOI 6 NUMERI'!$B$15*(IF(Q24<=0,0,MEDIAN(0,(Q24-R24)/Q24,1))))))*(1-(IF(Q24<=0,0,MEDIAN(0,(Q24-R24)/Q24,1))))) | S25: =IF(S24<=0,0,(S24-(IF(S24<=0,0,(30000*(1+'1 - I TUOI 6 NUMERI'!$B$14)^3)/(1-'1 - I TUOI 6 NUMERI'!$B$15*(IF(S24<=0,0,MEDIAN(0,(S24-T24)/S24,1))))))-(IF(S24<=0,0,'1 - I TUOI 6 NUMERI'!$B$16*S24)))*(1+((1+0.01)*(1+'1 - I TUOI 6 NUMERI'!$B$14)-1))) | T25: =MAX(0,T24-(IF(S24<=0,0,(30000*(1+'1 - I TUOI 6 NUMERI'!$B$14)^3)/(1-'1 - I TUOI 6 NUMERI'!$B$15*(IF(S24<=0,0,MEDIAN(0,(S24-T24)/S24,1))))))*(1-(IF(S24<=0,0,MEDIAN(0,(S24-T24)/S24,1))))) | U25: =IF(U24<=0,0,(U24-(IF(U24<=0,0,(30000*(1+'1 - I TUOI 6 NUMERI'!$B$14)^3)/(1-'1 - I TUOI 6 NUMERI'!$B$15*(IF(U24<=0,0,MEDIAN(0,(U24-V24)/U24,1))))))-(IF(U24<=0,0,'1 - I TUOI 6 NUMERI'!$B$16*U24)))*(1+((1+0.03)*(1+'1 - I TUOI 6 NUMERI'!$B$14)-1))) | V25: =MAX(0,V24-(IF(U24<=0,0,(30000*(1+'1 - I TUOI 6 NUMERI'!$B$14)^3)/(1-'1 - I TUOI 6 NUMERI'!$B$15*(IF(U24<=0,0,MEDIAN(0,(U24-V24)/U24,1))))))*(1-(IF(U24<=0,0,MEDIAN(0,(U24-V24)/U24,1))))) | W25: =IF(W24<=0,0,(W24-(IF(W24<=0,0,(30000*(1+'1 - I TUOI 6 NUMERI'!$B$14)^3)/(1-'1 - I TUOI 6 NUMERI'!$B$15*(IF(W24<=0,0,MEDIAN(0,(W24-X24)/W24,1))))))-(IF(W24<=0,0,'1 - I TUOI 6 NUMERI'!$B$16*W24)))*(1+((1+0.05)*(1+'1 - I TUOI 6 NUMERI'!$B$14)-1))) | X25: =MAX(0,X24-(IF(W24<=0,0,(30000*(1+'1 - I TUOI 6 NUMERI'!$B$14)^3)/(1-'1 - I TUOI 6 NUMERI'!$B$15*(IF(W24<=0,0,MEDIAN(0,(W24-X24)/W24,1))))))*(1-(IF(W24<=0,0,MEDIAN(0,(W24-X24)/W24,1))))) | Y25: =IF(Y24<=0,0,(Y24-(IF(Y24<=0,0,(36000*(1+'1 - I TUOI 6 NUMERI'!$B$14)^3)/(1-'1 - I TUOI 6 NUMERI'!$B$15*(IF(Y24<=0,0,MEDIAN(0,(Y24-Z24)/Y24,1))))))-(IF(Y24<=0,0,'1 - I TUOI 6 NUMERI'!$B$16*Y24)))*(1+((1+0.01)*(1+'1 - I TUOI 6 NUMERI'!$B$14)-1))) | Z25: =MAX(0,Z24-(IF(Y24<=0,0,(36000*(1+'1 - I TUOI 6 NUMERI'!$B$14)^3)/(1-'1 - I TUOI 6 NUMERI'!$B$15*(IF(Y24<=0,0,MEDIAN(0,(Y24-Z24)/Y24,1))))))*(1-(IF(Y24<=0,0,MEDIAN(0,(Y24-Z24)/Y24,1))))) | AA25: =IF(AA24<=0,0,(AA24-(IF(AA24<=0,0,(36000*(1+'1 - I TUOI 6 NUMERI'!$B$14)^3)/(1-'1 - I TUOI 6 NUMERI'!$B$15*(IF(AA24<=0,0,MEDIAN(0,(AA24-AB24)/AA24,1))))))-(IF(AA24<=0,0,'1 - I TUOI 6 NUMERI'!$B$16*AA24)))*(1+((1+0.03)*(1+'1 - I TUOI 6 NUMERI'!$B$14)-1))) | AB25: =MAX(0,AB24-(IF(AA24<=0,0,(36000*(1+'1 - I TUOI 6 NUMERI'!$B$14)^3)/(1-'1 - I TUOI 6 NUMERI'!$B$15*(IF(AA24<=0,0,MEDIAN(0,(AA24-AB24)/AA24,1))))))*(1-(IF(AA24<=0,0,MEDIAN(0,(AA24-AB24)/AA24,1))))) | AC25: =IF(AC24<=0,0,(AC24-(IF(AC24<=0,0,(36000*(1+'1 - I TUOI 6 NUMERI'!$B$14)^3)/(1-'1 - I TUOI 6 NUMERI'!$B$15*(IF(AC24<=0,0,MEDIAN(0,(AC24-AD24)/AC24,1))))))-(IF(AC24<=0,0,'1 - I TUOI 6 NUMERI'!$B$16*AC24)))*(1+((1+0.05)*(1+'1 - I TUOI 6 NUMERI'!$B$14)-1))) | AD25: =MAX(0,AD24-(IF(AC24<=0,0,(36000*(1+'1 - I TUOI 6 NUMERI'!$B$14)^3)/(1-'1 - I TUOI 6 NUMERI'!$B$15*(IF(AC24<=0,0,MEDIAN(0,(AC24-AD24)/AC24,1))))))*(1-(IF(AC24<=0,0,MEDIAN(0,(AC24-AD24)/AC24,1)))))
F26: 4 | G26: =IF(G25<=0,0,(G25-(IF(G25<=0,0,(18000*(1+'1 - I TUOI 6 NUMERI'!$B$14)^4)/(1-'1 - I TUOI 6 NUMERI'!$B$15*(IF(G25<=0,0,MEDIAN(0,(G25-H25)/G25,1))))))-(IF(G25<=0,0,'1 - I TUOI 6 NUMERI'!$B$16*G25)))*(1+((1+0.01)*(1+'1 - I TUOI 6 NUMERI'!$B$14)-1))) | H26: =MAX(0,H25-(IF(G25<=0,0,(18000*(1+'1 - I TUOI 6 NUMERI'!$B$14)^4)/(1-'1 - I TUOI 6 NUMERI'!$B$15*(IF(G25<=0,0,MEDIAN(0,(G25-H25)/G25,1))))))*(1-(IF(G25<=0,0,MEDIAN(0,(G25-H25)/G25,1))))) | I26: =IF(I25<=0,0,(I25-(IF(I25<=0,0,(18000*(1+'1 - I TUOI 6 NUMERI'!$B$14)^4)/(1-'1 - I TUOI 6 NUMERI'!$B$15*(IF(I25<=0,0,MEDIAN(0,(I25-J25)/I25,1))))))-(IF(I25<=0,0,'1 - I TUOI 6 NUMERI'!$B$16*I25)))*(1+((1+0.03)*(1+'1 - I TUOI 6 NUMERI'!$B$14)-1))) | J26: =MAX(0,J25-(IF(I25<=0,0,(18000*(1+'1 - I TUOI 6 NUMERI'!$B$14)^4)/(1-'1 - I TUOI 6 NUMERI'!$B$15*(IF(I25<=0,0,MEDIAN(0,(I25-J25)/I25,1))))))*(1-(IF(I25<=0,0,MEDIAN(0,(I25-J25)/I25,1))))) | K26: =IF(K25<=0,0,(K25-(IF(K25<=0,0,(18000*(1+'1 - I TUOI 6 NUMERI'!$B$14)^4)/(1-'1 - I TUOI 6 NUMERI'!$B$15*(IF(K25<=0,0,MEDIAN(0,(K25-L25)/K25,1))))))-(IF(K25<=0,0,'1 - I TUOI 6 NUMERI'!$B$16*K25)))*(1+((1+0.05)*(1+'1 - I TUOI 6 NUMERI'!$B$14)-1))) | L26: =MAX(0,L25-(IF(K25<=0,0,(18000*(1+'1 - I TUOI 6 NUMERI'!$B$14)^4)/(1-'1 - I TUOI 6 NUMERI'!$B$15*(IF(K25<=0,0,MEDIAN(0,(K25-L25)/K25,1))))))*(1-(IF(K25<=0,0,MEDIAN(0,(K25-L25)/K25,1))))) | M26: =IF(M25<=0,0,(M25-(IF(M25<=0,0,(24000*(1+'1 - I TUOI 6 NUMERI'!$B$14)^4)/(1-'1 - I TUOI 6 NUMERI'!$B$15*(IF(M25<=0,0,MEDIAN(0,(M25-N25)/M25,1))))))-(IF(M25<=0,0,'1 - I TUOI 6 NUMERI'!$B$16*M25)))*(1+((1+0.01)*(1+'1 - I TUOI 6 NUMERI'!$B$14)-1))) | N26: =MAX(0,N25-(IF(M25<=0,0,(24000*(1+'1 - I TUOI 6 NUMERI'!$B$14)^4)/(1-'1 - I TUOI 6 NUMERI'!$B$15*(IF(M25<=0,0,MEDIAN(0,(M25-N25)/M25,1))))))*(1-(IF(M25<=0,0,MEDIAN(0,(M25-N25)/M25,1))))) | O26: =IF(O25<=0,0,(O25-(IF(O25<=0,0,(24000*(1+'1 - I TUOI 6 NUMERI'!$B$14)^4)/(1-'1 - I TUOI 6 NUMERI'!$B$15*(IF(O25<=0,0,MEDIAN(0,(O25-P25)/O25,1))))))-(IF(O25<=0,0,'1 - I TUOI 6 NUMERI'!$B$16*O25)))*(1+((1+0.03)*(1+'1 - I TUOI 6 NUMERI'!$B$14)-1))) | P26: =MAX(0,P25-(IF(O25<=0,0,(24000*(1+'1 - I TUOI 6 NUMERI'!$B$14)^4)/(1-'1 - I TUOI 6 NUMERI'!$B$15*(IF(O25<=0,0,MEDIAN(0,(O25-P25)/O25,1))))))*(1-(IF(O25<=0,0,MEDIAN(0,(O25-P25)/O25,1))))) | Q26: =IF(Q25<=0,0,(Q25-(IF(Q25<=0,0,(24000*(1+'1 - I TUOI 6 NUMERI'!$B$14)^4)/(1-'1 - I TUOI 6 NUMERI'!$B$15*(IF(Q25<=0,0,MEDIAN(0,(Q25-R25)/Q25,1))))))-(IF(Q25<=0,0,'1 - I TUOI 6 NUMERI'!$B$16*Q25)))*(1+((1+0.05)*(1+'1 - I TUOI 6 NUMERI'!$B$14)-1))) | R26: =MAX(0,R25-(IF(Q25<=0,0,(24000*(1+'1 - I TUOI 6 NUMERI'!$B$14)^4)/(1-'1 - I TUOI 6 NUMERI'!$B$15*(IF(Q25<=0,0,MEDIAN(0,(Q25-R25)/Q25,1))))))*(1-(IF(Q25<=0,0,MEDIAN(0,(Q25-R25)/Q25,1))))) | S26: =IF(S25<=0,0,(S25-(IF(S25<=0,0,(30000*(1+'1 - I TUOI 6 NUMERI'!$B$14)^4)/(1-'1 - I TUOI 6 NUMERI'!$B$15*(IF(S25<=0,0,MEDIAN(0,(S25-T25)/S25,1))))))-(IF(S25<=0,0,'1 - I TUOI 6 NUMERI'!$B$16*S25)))*(1+((1+0.01)*(1+'1 - I TUOI 6 NUMERI'!$B$14)-1))) | T26: =MAX(0,T25-(IF(S25<=0,0,(30000*(1+'1 - I TUOI 6 NUMERI'!$B$14)^4)/(1-'1 - I TUOI 6 NUMERI'!$B$15*(IF(S25<=0,0,MEDIAN(0,(S25-T25)/S25,1))))))*(1-(IF(S25<=0,0,MEDIAN(0,(S25-T25)/S25,1))))) | U26: =IF(U25<=0,0,(U25-(IF(U25<=0,0,(30000*(1+'1 - I TUOI 6 NUMERI'!$B$14)^4)/(1-'1 - I TUOI 6 NUMERI'!$B$15*(IF(U25<=0,0,MEDIAN(0,(U25-V25)/U25,1))))))-(IF(U25<=0,0,'1 - I TUOI 6 NUMERI'!$B$16*U25)))*(1+((1+0.03)*(1+'1 - I TUOI 6 NUMERI'!$B$14)-1))) | V26: =MAX(0,V25-(IF(U25<=0,0,(30000*(1+'1 - I TUOI 6 NUMERI'!$B$14)^4)/(1-'1 - I TUOI 6 NUMERI'!$B$15*(IF(U25<=0,0,MEDIAN(0,(U25-V25)/U25,1))))))*(1-(IF(U25<=0,0,MEDIAN(0,(U25-V25)/U25,1))))) | W26: =IF(W25<=0,0,(W25-(IF(W25<=0,0,(30000*(1+'1 - I TUOI 6 NUMERI'!$B$14)^4)/(1-'1 - I TUOI 6 NUMERI'!$B$15*(IF(W25<=0,0,MEDIAN(0,(W25-X25)/W25,1))))))-(IF(W25<=0,0,'1 - I TUOI 6 NUMERI'!$B$16*W25)))*(1+((1+0.05)*(1+'1 - I TUOI 6 NUMERI'!$B$14)-1))) | X26: =MAX(0,X25-(IF(W25<=0,0,(30000*(1+'1 - I TUOI 6 NUMERI'!$B$14)^4)/(1-'1 - I TUOI 6 NUMERI'!$B$15*(IF(W25<=0,0,MEDIAN(0,(W25-X25)/W25,1))))))*(1-(IF(W25<=0,0,MEDIAN(0,(W25-X25)/W25,1))))) | Y26: =IF(Y25<=0,0,(Y25-(IF(Y25<=0,0,(36000*(1+'1 - I TUOI 6 NUMERI'!$B$14)^4)/(1-'1 - I TUOI 6 NUMERI'!$B$15*(IF(Y25<=0,0,MEDIAN(0,(Y25-Z25)/Y25,1))))))-(IF(Y25<=0,0,'1 - I TUOI 6 NUMERI'!$B$16*Y25)))*(1+((1+0.01)*(1+'1 - I TUOI 6 NUMERI'!$B$14)-1))) | Z26: =MAX(0,Z25-(IF(Y25<=0,0,(36000*(1+'1 - I TUOI 6 NUMERI'!$B$14)^4)/(1-'1 - I TUOI 6 NUMERI'!$B$15*(IF(Y25<=0,0,MEDIAN(0,(Y25-Z25)/Y25,1))))))*(1-(IF(Y25<=0,0,MEDIAN(0,(Y25-Z25)/Y25,1))))) | AA26: =IF(AA25<=0,0,(AA25-(IF(AA25<=0,0,(36000*(1+'1 - I TUOI 6 NUMERI'!$B$14)^4)/(1-'1 - I TUOI 6 NUMERI'!$B$15*(IF(AA25<=0,0,MEDIAN(0,(AA25-AB25)/AA25,1))))))-(IF(AA25<=0,0,'1 - I TUOI 6 NUMERI'!$B$16*AA25)))*(1+((1+0.03)*(1+'1 - I TUOI 6 NUMERI'!$B$14)-1))) | AB26: =MAX(0,AB25-(IF(AA25<=0,0,(36000*(1+'1 - I TUOI 6 NUMERI'!$B$14)^4)/(1-'1 - I TUOI 6 NUMERI'!$B$15*(IF(AA25<=0,0,MEDIAN(0,(AA25-AB25)/AA25,1))))))*(1-(IF(AA25<=0,0,MEDIAN(0,(AA25-AB25)/AA25,1))))) | AC26: =IF(AC25<=0,0,(AC25-(IF(AC25<=0,0,(36000*(1+'1 - I TUOI 6 NUMERI'!$B$14)^4)/(1-'1 - I TUOI 6 NUMERI'!$B$15*(IF(AC25<=0,0,MEDIAN(0,(AC25-AD25)/AC25,1))))))-(IF(AC25<=0,0,'1 - I TUOI 6 NUMERI'!$B$16*AC25)))*(1+((1+0.05)*(1+'1 - I TUOI 6 NUMERI'!$B$14)-1))) | AD26: =MAX(0,AD25-(IF(AC25<=0,0,(36000*(1+'1 - I TUOI 6 NUMERI'!$B$14)^4)/(1-'1 - I TUOI 6 NUMERI'!$B$15*(IF(AC25<=0,0,MEDIAN(0,(AC25-AD25)/AC25,1))))))*(1-(IF(AC25<=0,0,MEDIAN(0,(AC25-AD25)/AC25,1)))))
