Workbook

Sheet 0 - Indice
A1: Radiografia del fondo World: quanta tecnologia hai davvero dentro
A2: Strumento didattico, non consulenza; dati storici, non previsioni.
A4: Indice
A5: 1 - Radiografia | B5: Pesi di sei blocchi → USA, primi 10 titoli, tecnologia, comunicazione, euro su 1.000 € e sul tuo importo
A6: 2 - Stress test | B6: Che cosa succede se il blocco tecnologia + comunicazione dimezza: quattro scenari di trascinamento
A7: 3 - Precedente 2000-02 | B7: Calo massimo del tuo mix a fine mese, 320 mesi in euro, e i dati giornalieri del video
A8: 4 - CAPE | B8: Rendimento reale a 10 anni per fascia del rapporto prezzo-utili di Shiller (relazione storica)
A9: 5 - Fonti e limiti | B9: Fonte e data di ogni parametro, limiti dichiarati
A11: Come usare
A12: 1. Le celle GIALLE sono input — modificale coi tuoi numeri.
A13: 2. Le celle VERDI sono output — si aggiornano automaticamente.
A14: 3. Tutti i numeri di default sono al 2026 da fonti pubbliche.
A15: 4. Niente codice nascosto: l'Excel è solo formule modificabili.
A17: Fonti dati
A18: • Pesi per paese, settore e primi 10 titoli: schede degli indici MSCI World, USA, World ex USA, World Equal Weight, Emergenti, 30/09/2026
A19: • Rapporto prezzo-utili di Shiller (CAPE) dell'S&P 500: dati di R. Shiller, verifica del 16/10/2026; settembre 2026 = 40,58
A20: • Rendimenti mensili 2000-02 → 2026-09 in euro, rendimento totale: serie MSCI; obbligazioni = proxy Bund 10 anni (curva Svensson, Bundesbank)
A21: • Nasdaq cento e Composite: serie Nasdaq a prezzo, convertite in euro col cambio implicito delle serie MSCI
A22: • Calcoli miei: dossier del video e questo foglio. Dati storici, non previsioni. Data dei dati: 30/09/2026
A24: Aggiornamenti: github.com/marcofire-it/marco-fire-simulatori
A30: Limiti: il calo del foglio 3 è a fine mese, quindi minore di quello giornaliero del video; il raccordo dei dividendi prima di dicembre 2000 è una stima; il World a pesi uguali prima del 2008 è una simulazione; le obbligazioni sono un proxy a duration costante, non un fondo. Vedi il foglio 5.

Sheet 1 - Radiografia
A1: Radiografia: quanta tecnologia c'è nel tuo portafoglio
A2: Strumento didattico, non consulenza; dati storici, non previsioni.
A4: Il tuo portafoglio (celle gialle = input)
A5: Peso: World | B5: 1
A6: Peso: USA | B6: 0
A7: Peso: World escluso USA | B7: 0
A8: Peso: World a pesi uguali (Equal Weight) | B8: 0
A9: Peso: Mercati emergenti | B9: 0
A10: Peso: Obbligazioni (proxy Bund 10 anni) | B10: 0
A11: Somma dei pesi | B11: =SUM(B5:B10) -> 1
A12: Controllo | B12: =IF(ABS(B11-1)<0.00001,"OK: somma 100%","ATTENZIONE: la somma deve fare 100%") -> OK: somma 100%
A13: Quota del Consumo discrezionale contata come «intelligenza artificiale» (k) | B13: 0.5
A14: Importo del portafoglio (€) | B14: 117000
A16: Parametri dei sei blocchi (dati di fonte, azzurri): peso % di ciascuna voce dentro il blocco
A17: Blocco | B17: USA | C17: Lista dei 10 del World (calcolo) | D17: Tecnologia | E17: Comunicazione | F17: Consumo discrezionale | G17: Fonte | H17: Data factsheet
A18: World | B18: 0.7294 | C18: 0.2785 | D18: 0.3178 | E18: 0.0831 | F18: 0.0836 | G18: MSCI, scheda dell'indice | H18: 46295
A19: USA | B19: 1 | C19: 0.3819 | D19: 0.395 | E19: 0.1007 | F19: 0.087 | G19: MSCI, scheda dell'indice | H19: 46295
A20: World escluso USA | B20: 0 | C20: 0 | D20: 0.1096 | E20: 0.0355 | F20: 0.0744 | G20: MSCI, scheda dell'indice | H20: 46295
A21: World a pesi uguali (Equal Weight) | B21: 0.4061 | C21: 0.008 | D21: 0.1138 | E21: 0.0466 | F21: 0.0906 | G21: MSCI, scheda dell'indice | H21: 46295
A22: Mercati emergenti | B22: 0 | C22: 0 | D22: 0.4378 | E22: 0.0586 | F22: 0.0739 | G22: MSCI, scheda dell'indice | H22: 46295
A23: Obbligazioni (proxy Bund 10 anni) | B23: 0 | C23: 0 | D23: 0 | E23: 0 | F23: 0 | G23: nessuna azione: zero per definizione
A24: La «lista dei 10» è la lista fissa dei dieci titoli di testa del World al 30/09/2026: nell'indice USA gli stessi nomi pesano 38,19%; nel World a pesi uguali 0,80% (calcolo: 10 titoli × 1/1.249); fuori dagli Stati Uniti e nei Mercati emergenti zero. È una quota di mix, non il peso dei primi 10 del tuo portafoglio.
A26: Primi 10 titoli di ciascun indice (dato di factsheet 30/09/2026, quello del video; un solo valore per indice)
A27: Indice | B27: Primi 10 dell'indice | C27: Fonte | D27: Data factsheet
A28: World | B28: 0.2785 | C28: MSCI, scheda dell'indice | D28: 46295
A29: USA | B29: 0.3819 | C29: MSCI, scheda dell'indice | D29: 46295
A30: World escluso USA | B30: 0.1271 | C30: MSCI, scheda dell'indice | D30: 46295
A31: World a pesi uguali (Equal Weight) | B31: 0.0118 | C31: MSCI, scheda dell'indice | D31: 46295
A32: Mercati emergenti | B32: 0.3903 | C32: MSCI, scheda dell'indice | D32: 46295
A33: Nel World i primi 10 sono nove società, perché una compare con due classi di azioni. Questi valori sono solo di lettura: il calcolo del tuo portafoglio usa la lista dei 10 qui sopra.
A35: Il risultato per il tuo portafoglio (celle verdi = formule)
A36: Esposizione agli Stati Uniti | B36: =SUMPRODUCT($B$5:$B$10,B18:B23) -> 0.7294
A37: Quota della lista dei 10 titoli di testa del World nel tuo mix | B37: =SUMPRODUCT($B$5:$B$10,C18:C23) -> 0.2785
A38: Tecnologia | B38: =SUMPRODUCT($B$5:$B$10,D18:D23) -> 0.3178
A39: Comunicazione | B39: =SUMPRODUCT($B$5:$B$10,E18:E23) -> 0.0831
A40: Consumo discrezionale | B40: =SUMPRODUCT($B$5:$B$10,F18:F23) -> 0.0836
A41: Tecnologia + Comunicazione | B41: =B38+B39 -> 0.4009
A42: Tecnologia + Comunicazione + k × Consumo discrezionale | B42: =B41+B13*B40 -> 0.4427
A43: Euro in Tecnologia + Comunicazione, su 1.000 € investiti | B43: =1000*B41 -> 400.9
A44: Euro in Tecnologia + Comunicazione, sul tuo importo | B44: =B14*B41 -> 46905.3
...

Sheet 2 - Stress test
A1: Stress test: che cosa succede se il blocco dimezza
A2: Strumento didattico, non consulenza; dati storici, non previsioni.
A4: Ipotesi (celle gialle = input)
A5: Shock sul blocco (da −90% a 0%) | B5: -0.5
A6: Blocco che subisce lo shock | B6: Tecnologia + Comunicazione
A7: Trascinamento personalizzato φ (da 0 a 1) | B7: 0.5
A8: Rendimento delle obbligazioni nello scenario (da −20% a +20%) | B8: 0
A9: Importo del portafoglio (dal foglio 1) | B9: ='1 - Radiografia'!B14 -> 117000
A11: Esposizione del tuo portafoglio (dal foglio 1)
A12: b = esposizione del blocco scelto | B12: =IF(B6="Tecnologia",'1 - Radiografia'!B38,IF(B6="Tecnologia + Comunicazione",'1 - Radiografia'!B41,'1 - Radiografia'!B42)) -> 0.4009
A13: Peso delle obbligazioni | B13: ='1 - Radiografia'!B10 -> 0
A14: E = quota azionaria (1 − peso delle obbligazioni) | B14: =1-B13 -> 1
A16: Perdita = shock × [ b + (E − b) × φ ] + peso obbligazioni × rendimento obbligazioni
A17: Scenario | B17: φ | C17: Etichetta | D17: Perdita % | E17: Perdita in € | F17: Valore dopo lo shock
A18: Passo didattico | B18: 0 | C18: tech isolato (passo didattico) | D18: =$B$5*($B$12+($B$14-$B$12)*B18)+$B$13*$B$8 -> -0.20045 | E18: =D18*$B$9 -> -23452.65 | F18: =$B$9+E18 -> 93547.35
A19: Giorni normali | B19: 0.21 | C19: correlazione dei giorni normali, non dei crolli (beta giornaliero 2023-26) | D19: =$B$5*($B$12+($B$14-$B$12)*B19)+$B$13*$B$8 -> -0.2633555 | E19: =D19*$B$9 -> -30812.594 | F19: =$B$9+E19 -> 86187.406
A20: Come nel 2000-02 | B20: 0.45 | C20: come nel 2000-02 (intervallo ricostruito 0,35-0,52) | D20: =$B$5*($B$12+($B$14-$B$12)*B20)+$B$13*$B$8 -> -0.3352475 | E20: =D20*$B$9 -> -39223.958 | F20: =$B$9+E20 -> 77776.042
A21: Crisi generale | B21: 0.8 | C21: crisi generale (2007-09 e 2020 intorno a 1,1; 2022: 0,62) | D21: =$B$5*($B$12+($B$14-$B$12)*B21)+$B$13*$B$8 -> -0.44009 | E21: =D21*$B$9 -> -51490.53 | F21: =$B$9+E21 -> 65509.47
A22: Il tuo φ | B22: =B7 -> 0.5 | C22: trascinamento personalizzato (cella B7) | D22: =$B$5*($B$12+($B$14-$B$12)*B22)+$B$13*$B$8 -> -0.350225 | E22: =D22*$B$9 -> -40976.325 | F22: =$B$9+E22 -> 76023.675
A24: Scenario «che cosa succede se», non una previsione. φ è il trascinamento del resto delle azioni per unità di shock del blocco: 0,45 è la stima per lo scoppio del 2000-02 (intervallo 0,35-0,52, pesi storici ricostruiti, ±5 punti); 0,8 è una convenzione fra 2022 (0,62) e 2007-09 e 2020 (intorno a 1,1). Le obbligazioni a zero sono prudenti nel 2000-02, non nel 2022.

Sheet 3 - Precedente 2000-02
A1: Il precedente 2000-02: il calo massimo del tuo mix
A2: Strumento didattico, non consulenza; dati storici, non previsioni.
A4: Parametri
A5: Costo annuo c (da 0% a 3%), sottratto come c/12 al mese | B5: 0.004
A6: Peso: World (dal foglio 1) | B6: ='1 - Radiografia'!B5 -> 1
A7: Peso: USA (dal foglio 1) | B7: ='1 - Radiografia'!B6 -> 0
A8: Peso: World escluso USA (dal foglio 1) | B8: ='1 - Radiografia'!B7 -> 0
A9: Peso: World a pesi uguali (Equal Weight) (dal foglio 1) | B9: ='1 - Radiografia'!B8 -> 0
A10: Peso: Mercati emergenti (dal foglio 1) | B10: ='1 - Radiografia'!B9 -> 0
A11: Peso: Obbligazioni (proxy Bund 10 anni) (dal foglio 1) | B11: ='1 - Radiografia'!B10 -> 0
A13: Il tuo portafoglio: calo massimo a fine mese (minore del giornaliero del video)
A14: Voce | B14: Fino a dic 2003 | C14: Fino a dic 2010 | D14: Fino a set 2026
A15: Calo massimo a fine mese | B15: =MIN(L$42:L$362) -> -0.54663552 | C15: =MIN(M$42:M$362) -> -0.57418577 | D15: =MIN(K$42:K$362) -> -0.57418577
A16: Indice al picco | B16: =INDEX(J$42:J$362,MATCH(B15,L$42:L$362,0)) -> 1.1409645 | C16: =INDEX(J$42:J$362,MATCH(C15,M$42:M$362,0)) -> 1.1409645 | D16: =INDEX(J$42:J$362,MATCH(D15,K$42:K$362,0)) -> 1.1409645
A17: Mese del picco | B17: =INDEX(A$42:A$362,MATCH(B16,I$42:I$362,0)) -> 36769 | C17: =INDEX(A$42:A$362,MATCH(C16,I$42:I$362,0)) -> 36769 | D17: =INDEX(A$42:A$362,MATCH(D16,I$42:I$362,0)) -> 36769
A18: Mese del minimo | B18: =INDEX(A$42:A$362,MATCH(B15,L$42:L$362,0)) -> 37711 | C18: =INDEX(A$42:A$362,MATCH(C15,M$42:M$362,0)) -> 39872 | D18: =INDEX(A$42:A$362,MATCH(D15,K$42:K$362,0)) -> 39872
A19: Mesi dal picco al minimo | B19: =(YEAR(B18)-YEAR(B17))*12+MONTH(B18)-MONTH(B17) -> 31 | C19: =(YEAR(C18)-YEAR(C17))*12+MONTH(C18)-MONTH(C17) -> 102 | D19: =(YEAR(D18)-YEAR(D17))*12+MONTH(D18)-MONTH(D17) -> 102
A20: Mese di ritorno al picco | B20: =IF(COUNT(N$42:N$362)=0,"oltre set 2026",MIN(N$42:N$362)) -> 41820 | C20: =IF(COUNT(O$42:O$362)=0,"oltre set 2026",MIN(O$42:O$362)) -> 41820 | D20: =IF(COUNT(P$42:P$362)=0,"oltre set 2026",MIN(P$42:P$362)) -> 41820
A21: Moltiplicatore feb 2000 → set 2026 (con il costo c) | B21: =I362 -> 4.5662034
A22: Calo massimo a fine mese: usa solo i dati dell'ultimo giorno di ogni mese, quindi è minore del calo giornaliero del video. Mix costante: ribilanciato ogni mese. Rendimento del portafoglio = somma pesata dei rendimenti − c/12.
A24: Dati del video, giornalieri (EUR, rendimento totale, lordi di costi): dati di fonte, non cambiano
A25: Indice | B25: Calo massimo | C25: Picco | D25: Minimo | E25: Ritorno al picco | F25: Anni dal picco al ritorno
A26: Nasdaq cento (a prezzo) | B26: -0.8312 | C26: 36612 | D26: 37538 | E26: 42773 | F26: 16.9
A27: Nasdaq Composite (a prezzo) | B27: -0.7843 | C27: 36595 | D27: 37538 | E27: 42719 | F27: 16.8
A28: World | B28: -0.5743 | C28: 36776 | D28: 37692 | E28: 41654 | F28: 13.4
A29: World a pesi uguali (simulazione prima del 2008) | B29: -0.4718 | C29: 36777 | D29: 37692 | E29: 38548 | F29: 4.8
A30: 60% World, 40% obbligazioni | B30: -0.3313 | C30: 36776 | D30: 37692 | E30: 38721 | F30: 5.3
A31: 80% World, 20% obbligazioni | B31: -0.4645 | C31: 36776 | D31: 37692 | E31: 41094 | F31: 11.8
A32: 40% World, 60% obbligazioni | B32: -0.1717 | C32: 36773 | D32: 37460 | E32: 38334 | F32: 4.3
A34: Nasdaq in euro = prezzo, col cambio implicito delle serie MSCI (nessun rendimento totale pubblico). Obbligazioni = proxy Bund a duration costante, non un fondo. Raccordo dei dividendi prima di dicembre 2000 = stima (±1 punto sul World). World a pesi uguali: indice lanciato nel 2008, prima è una simulazione.
A36: Motore del calcolo, non modificare: rendimenti mensili in euro (azzurri) e calcolo del tuo mix
A37: 320 righe, da fine febbraio 2000 a fine settembre 2026. Indice = 1 a fine gennaio 2000. Drawdown = indice / massimo precedente − 1.
A38: Pesi del mix (dalle celle B6:B11) | B38: =$B$6 -> 1 | C38: =$B$7 -> 0 | D38: =$B$8 -> 0 | E38: =$B$9 -> 0 | F38: =$B$10 -> 0 | G38: =$B$11 -> 0
A41: Fine mese | B41: World | C41: USA | D41: World escluso USA | E41: World a pesi uguali | F41: Emergenti | G41: Obbligazioni (proxy) | H41: Rendimento del mix | I41: Indice | J41: Massimo precedente | K41: Calo dal massimo | L41: Calo (fino a dic 2003) | M41: Calo (fino a dic 2010) | N41: Ritorno 2003 | O41: Ritorno 2010 | P41: Ritorno 2026
A42: 36556 | I42: 1 | J42: =MAX(I$42:I42) -> 1 | K42: =I42/J42-1 -> 0 | L42: =IF(A42<=DATE(2003,12,31),K42,"") -> 0 | M42: =IF(A42<=DATE(2010,12,31),K42,"") -> 0
A43: 36585 | B43: 0.019061 | C43: -0.008102 | D43: 0.045413 | E43: -0.00162 | F43: 0.031096 | G43: 0.012963 | H43: =SUMPRODUCT($B$38:$G$38,B43:G43)-$B$5/12 -> 0.018727667 | I43: =I42*(1+H43) -> 1.0187277 | J43: =MAX(I$42:I43) -> 1.0187277 | K43: =I43/J43-1 -> 0 | L43: =IF(A43<=DATE(2003,12,31),K43,"") -> 0 | M43: =IF(A43<=DATE(2010,12,31),K43,"") -> 0 | N43: =IF(AND(A43>$B$18,I43>=$B$16),A43,"") | O43: =IF(AND(A43>$C$18,I43>=$C$16),A43,"") | P43: =IF(AND(A43>$D$18,I43>=$D$16),A43,"")
A44: 36616 | B44: 0.0759 | C44: 0.106536 | D44: 0.047914 | E44: 0.07972 | F44: 0.011326 | G44: 0.026584 | H44: =SUMPRODUCT($B$38:$G$38,B44:G44)-$B$5/12 -> 0.075566667 | I44: =I43*(1+H44) -> 1.0957095 | J44: =MAX(I$42:I44) -> 1.0957095 | K44: =I44/J44-1 -> 0 | L44: =IF(A44<=DATE(2003,12,31),K44,"") -> 0 | M44: =IF(A44<=DATE(2010,12,31),K44,"") -> 0 | N44: =IF(AND(A44>$B$18,I44>=$B$16),A44,"") | O44: =IF(AND(A44>$C$18,I44>=$C$16),A44,"") | P44: =IF(AND(A44>$D$18,I44>=$D$16),A44,"")
A45: 36646 | B45: 0.005791 | C45: 0.016005 | D45: -0.00406 | E45: 0.026681 | F45: -0.049359 | G45: -0.007562 | H45: =SUMPRODUCT($B$38:$G$38,B45:G45)-$B$5/12 -> 0.0054576667 | I45: =I44*(1+H45) -> 1.1016895 | J45: =MAX(I$42:I45) -> 1.1016895 | K45: =I45/J45-1 -> 0 | L45: =IF(A45<=DATE(2003,12,31),K45,"") -> 0 | M45: =IF(A45<=DATE(2010,12,31),K45,"") -> 0 | N45: =IF(AND(A45>$B$18,I45>=$B$16),A45,"") | O45: =IF(AND(A45>$C$18,I45>=$C$16),A45,"") | P45: =IF(AND(A45>$D$18,I45>=$D$16),A45,"")
A46: 36677 | B46: -0.042056 | C46: -0.043401 | D46: -0.040726 | E46: -0.013192 | F46: -0.058368 | G46: 0.012857 | H46: =SUMPRODUCT($B$38:$G$38,B46:G46)-$B$5/12 -> -0.042389333 | I46: =I45*(1+H46) -> 1.0549897 | J46: =MAX(I$42:I46) -> 1.1016895 | K46: =I46/J46-1 -> -0.042389333 | L46: =IF(A46<=DATE(2003,12,31),K46,"") -> -0.042389333 | M46: =IF(A46<=DATE(2010,12,31),K46,"") -> -0.042389333 | N46: =IF(AND(A46>$B$18,I46>=$B$16),A46,"") | O46: =IF(AND(A46>$C$18,I46>=$C$16),A46,"") | P46: =IF(AND(A46>$D$18,I46>=$D$16),A46,"")
A47: 36707 | B47: 0.000216 | C47: -0.009349 | D47: 0.009674 | E47: 0.014615 | F47: 0.000235 | G47: 0.006739 | H47: =SUMPRODUCT($B$38:$G$38,B47:G47)-$B$5/12 -> -0.00011733333 | I47: =I46*(1+H47) -> 1.0548659 | J47: =MAX(I$42:I47) -> 1.1016895 | K47: =I47/J47-1 -> -0.042501693 | L47: =IF(A47<=DATE(2003,12,31),K47,"") -> -0.042501693 | M47: =IF(A47<=DATE(2010,12,31),K47,"") -> -0.042501693 | N47: =IF(AND(A47>$B$18,I47>=$B$16),A47,"") | O47: =IF(AND(A47>$C$18,I47>=$C$16),A47,"") | P47: =IF(AND(A47>$D$18,I47>=$D$16),A47,"")
...

Sheet 4 - CAPE
A1: Il rapporto prezzo-utili di Shiller (CAPE) e il rendimento dei dieci anni dopo
A2: Strumento didattico, non consulenza; dati storici, non previsioni.
A4: Il valore da guardare (cella gialla = input)
A5: CAPE di riferimento (da 5 a 60); set 2026 = 40,58 | B5: 40.58
A7: Rendimento reale annuo a 10 anni, per fascia del CAPE (S&P 500, 1881-2016: 1.630 mesi con risultato noto)
A8: Fascia | B8: Fino a (incluso) | C8: Mesi | D8: Peggiore | E8: Mediana | F8: Migliore
A9: fino a 10 | B9: 10 | C9: 229 | D9: 0.018 | E9: 0.11 | F9: 0.2
A10: da 10 a 15 | B10: 15 | C10: 461 | D10: -0.042 | E10: 0.078 | F10: 0.176
A11: da 15 a 20 | B11: 20 | C11: 514 | D11: -0.046 | E11: 0.062 | F11: 0.161
A12: da 20 a 25 | B12: 25 | C12: 260 | D12: -0.04 | E12: 0.049 | F12: 0.142
A13: da 25 a 30 | B13: 30 | C13: 109 | D13: -0.012 | E13: 0.056 | F13: 0.118
A14: oltre 30 | B14: — | C14: campione insufficiente (2 episodi con risultato noto: 1929 e 1997-2002)
A16: La fascia del tuo CAPE
A17: Numero della fascia (1-6) | B17: =IF(B5>30,6,COUNTIF($B$9:$B$13,"<"&B5)+1) -> 6
A18: Fascia | B18: =IF(B17=6,"oltre 30",INDEX($A$9:$A$13,B17)) -> oltre 30
A19: Mesi nel campione | B19: =IF(B17=6,"n/d",INDEX($C$9:$C$13,B17)) -> n/d
A20: Peggiore | B20: =IF(B17=6,"n/d",INDEX($D$9:$D$13,B17)) -> n/d
A21: Mediana | B21: =IF(B17=6,"nessuna mediana: campione insufficiente (2 episodi con risultato noto: 1929 e 1997-2002)",INDEX($E$9:$E$13,B17)) -> nessuna mediana: campione insufficiente (2 episodi con risultato noto: 1929 e 1997-2002)
A22: Migliore | B22: =IF(B17=6,"n/d",INDEX($F$9:$F$13,B17)) -> n/d
A24: Quanto spiega il CAPE (dati di fonte, azzurri)
A25: Episodi indipendenti sopra 30, con risultato a 10 anni noto | B25: 2
A26: R² sui mesi sovrapposti (non è un campione indipendente) | B26: 0.256
A27: R² su 120 sottocampioni non sovrapposti: minimo | B27: 0.04
A28: R² su 120 sottocampioni non sovrapposti: mediana | B28: 0.16
A29: R² su 120 sottocampioni non sovrapposti: massimo | B29: 0.61
A30: CAPE di settembre 2026 | B30: 40.58
A31: CAPE massimo (dicembre 1999) | B31: 44.2
A32: CAPE medio della serie | B32: 17.78
A33: Giugno 1997: CAPE 31,26 → rendimento reale annuo a 10 anni (fino al 2007) | B33: 0.0449
A34: Giugno 1997 → dicembre 1999: rendimento reale annuo | B34: 0.209
A35: Luglio 2017: CAPE 30,00 → rendimento reale annuo fino a settembre 2026 | B35: 0.111
A36: Relazione storica, non previsione. CAPE dell'S&P 500, non del World; utili del 2026 in parte stimati; set 2026. Sopra 30 gli episodi con risultato noto sono due (1929 e 1997-2002): due non fanno una statistica. Percentile del CAPE di set 2026: intorno al 99° (98,91% sui 1.748 mesi 1881-gennaio → agosto 2026).

Sheet 5 - Fonti e limiti
A1: Fonti e limiti
A2: Strumento didattico, non consulenza; dati storici, non previsioni.
A4: Ogni parametro con la sua fonte
A5: Parametro | B5: Fonte | C5: Data
A6: Pesi per paese, settore, primi 10 titoli (sei blocchi) | B6: MSCI, schede degli indici World, USA, World ex USA, World Equal Weight, Emergenti | C6: 30/09/2026
A7: CAPE, medie e fasce | B7: R. Shiller, dati mensili dell'S&P 500, calcoli miei | C7: 16/10/2026
A8: Rendimenti mensili in euro 2000-2026 | B8: Serie MSCI di rendimento totale; prima di dicembre 2000 raccordo dei dividendi stimato | C8: 16/10/2026
A9: Obbligazioni | B9: Proxy: Bund a 10 anni, curva Svensson della Bundesbank, duration costante | C9: 16/10/2026
A10: Nasdaq cento e Composite | B10: Serie Nasdaq a prezzo, cambio implicito delle serie MSCI | C10: ottobre 2026
A11: Costo annuo c | B11: Parametro ipotetico (default 0,40% = 0,20% di gestione + 0,20% di bollo): non è il costo di un prodotto | C11: —
A12: Trascinamento φ | B12: Stima mia sul 2000-02 (0,35-0,52), 2007-09, 2020, 2022 | C12: ottobre 2026
A14: Limiti dichiarati
A15: 1. Il calo del foglio 3 è a fine mese: è minore di quello giornaliero mostrato nel video (il World passa da −54,18% a fine mese a −57,43% in giornata).
A16: 2. Raccordo dei dividendi prima di dicembre 2000: stima, con incertezza intorno a un punto sul calo del World. Il World a pesi uguali non ha raccordo.
A17: 3. World a pesi uguali: indice lanciato nel 2008; prima è una simulazione fatta a posteriori.
A18: 4. Obbligazioni: proxy a duration costante, non un fondo.
A19: 5. Peso degli Stati Uniti e della tecnologia nel World del 2000: ricostruzione dai prezzi, nessuna fonte primaria, errore fino a cinque punti.
A20: 6. CAPE: S&P 500; l'unico dato dell'analisi che non riguarda il World. Sopra 30 il campione è insufficiente.
A21: 7. I pesi dei settori cambiano con la classificazione: nel 2018 il settore delle comunicazioni è stato ridefinito, e il suo peso è salito senza movimenti di prezzo.
A22: 8. Tutto è storico: nessuna previsione, nessun invito a comprare o vendere.
