Workbook
Name Aliq: '1 - Parametri'!$B$30
Name Aliq_eff: '1 - Parametri'!$B$39
Name Alt_pens1: '4 - Fisco e pensione'!$C$13
Name Alt_pens2: '4 - Fisco e pensione'!$C$14
Name Alt_pens3: '4 - Fisco e pensione'!$C$15
Name Anni: '1 - Parametri'!$B$44
Name Anni_ipotesi: '1 - Parametri'!$B$48
Name Anni_osservati: '1 - Parametri'!$B$47
Name Anno_inizio: '1 - Parametri'!$B$15
Name Anno_pens: '1 - Parametri'!$B$35
Name Bollo: '1 - Parametri'!$B$31
Name Bollo_anno1: '4 - Fisco e pensione'!$B$20
Name Bollo_eff: '1 - Parametri'!$B$40
Name Cap_con_pens: '4 - Fisco e pensione'!$B$7
Name Cap_diff: '4 - Fisco e pensione'!$B$8
Name Cap_senza_pens: '4 - Fisco e pensione'!$B$6
Name Durata_testo: '1 - Parametri'!$B$45
Name Eta_fine: '1 - Parametri'!$B$11
Name Eta_inizio: '1 - Parametri'!$B$10
Name Eta_rif_VPW: '1 - Parametri'!$B$19
Name GK_banda: '1 - Parametri'!$B$22
Name GK_taglio: '1 - Parametri'!$B$23
Name GK_ultimi: '1 - Parametri'!$B$24
Name GK_variante: '1 - Parametri'!$B$21
Name Imposta_anno1: '4 - Fisco e pensione'!$B$19
Name Infl_c: '1 - Parametri'!$B$17
Name Lat_anno_pens: '4 - Fisco e pensione'!$B$33
Name Lat_anno1: '4 - Fisco e pensione'!$B$32
Name Lat_ponte2: '1 - Parametri'!$B$37
Name Lat_ultimo: '4 - Fisco e pensione'!$B$34
Name Latente_eff: '1 - Parametri'!$B$41
Name Latente0: '1 - Parametri'!$B$29
Name Mese_pens: '1 - Parametri'!$B$34
Name Mesi_ultimo: '1 - Parametri'!$B$12
Name Modalita: '1 - Parametri'!$B$6
Name Patrimonio: '1 - Parametri'!$B$7
Name Pav_pct: '1 - Parametri'!$B$27
Name Pens_eta_testo: '1 - Parametri'!$B$46
Name Pens_mesi_req: '1 - Parametri'!$B$36
Name Pensione: '1 - Parametri'!$B$33
Name Ponte_L: '4 - Fisco e pensione'!$C$41
Name Ponte_M: '4 - Fisco e pensione'!$C$42
Name Ponte_N: '4 - Fisco e pensione'!$C$43
Name r_VPW: '1 - Parametri'!$B$20
Name Rend_c: '1 - Parametri'!$B$16
Name Serie: '1 - Parametri'!$B$14
Name Spesa_netta: '1 - Parametri'!$B$9
Name Spesa0: '1 - Parametri'!$B$42
Name Tasso: '1 - Parametri'!$B$8
Name Tasso_con_bollo: '4 - Fisco e pensione'!$B$23
Name Tasso_lordo_eq: '4 - Fisco e pensione'!$B$22
Name Tasso0: '1 - Parametri'!$B$43
Name Uscita_anno1: '4 - Fisco e pensione'!$B$21
Name Venduto_anno1: '4 - Fisco e pensione'!$B$18
Name VG_pav: '1 - Parametri'!$B$26
Name VG_tetto: '1 - Parametri'!$B$25

Sheet 0 - Indice
A1: Regole di prelievo: quanto posso spendere quest'anno? (caso inventato e illustrativo)
A2: Strumento informativo / divulgativo. NON è consulenza finanziaria. I valori sono indicativi al 2026 e vanno verificati col tuo consulente.
A4: Indice
A5: 0 - Indice | B5: Questo indice
A6: 1 - Parametri | B6: I tuoi dati (celle gialle) e la sintesi per regola
A7: 2 - Sequenza storica | B7: Le sei regole su una sequenza storica, anno per anno
A8: 3 - Rendimento costante | B8: Le stesse sei regole con rendimento costante
A9: 4 - Fisco e pensione | B9: Fisco, plusvalenza latente, pensione e ponte
A10: 5 - Dati | B10: Serie annuali e tabella di controllo della percentuale variabile
A12: Come usare
A13: 1. Le celle GIALLE sono input — modificale coi tuoi numeri.
A14: 2. Le celle VERDI sono output — si aggiornano automaticamente.
A15: 3. Tutti i numeri di default sono al 2026 da fonti pubbliche.
A16: 4. Niente codice nascosto: l'Excel è solo formule modificabili.
A18: Fonti dati
A19: • Primo studio sul quattro per cento: Bengen, Journal of Financial Planning, ottobre 1994
A20: • Regola dei guardrail: Guyton e Klinger, Journal of Financial Planning, marzo 2006 (qui senza il tetto del 6% all'inflazione)
A21: • Regole con pavimento e con tetto e pavimento: Morningstar, State of Retirement Income 2025 (3/12/2025)
A22: • Tabella della percentuale variabile: wiki Bogleheads, «Variable percentage withdrawal»
A23: • Serie USA dal 1871: Shiller. Serie in euro: indice azionario mondiale (rendimento netto), titolo di Stato tedesco a 10 anni, inflazione armonizzata italiana (HICP)
A24: • Pensione: Ragioneria generale dello Stato, Le tendenze di medio-lungo periodo, rapporto n. 27 (22/09/2026)
... A34: Il motore del calcolo è in fondo ai fogli 2, 3 e 4: non modificare. Nessuna macro, solo formule.

Sheet 1 - Parametri
A1: 1 - Parametri: le celle gialle sono i tuoi dati
A2: Strumento informativo / divulgativo. NON è consulenza finanziaria. I valori sono indicativi al 2026 e vanno verificati col tuo consulente.
A3: Il caso di default è Corrado, inventato e illustrativo: 51 anni, 1.056.000 € in un portafoglio 60/40, casa senza mutuo, 38.000 € netti l'anno fino a 93 anni. Importi in euro di oggi (reali). Il foglio 2 usa una sequenza storica, il foglio 3 un rendimento costante.
A5: Modalità e caso
A6: Modalità (lordo / tassato) | B6: tassato | C6: Lordo = backtest di distribuzione: la regola decide il venduto, nessuna imposta. Tassato = caso Corrado: la regola decide la spesa netta, in cassa.
A7: Patrimonio iniziale (€) | B7: 1056000 | C7: Valore di mercato a inizio piano, in euro di oggi.
A8: Tasso di prelievo iniziale (solo modalità lordo) | B8: 0.04 | C8: Spesa iniziale lorda = patrimonio × tasso: 42.240 € con i default.
A9: Spesa netta annua (solo modalità tassato) (€) | B9: 38000 | C9: Quanto vuoi avere in cassa ogni anno, in euro di oggi.
A10: Età a inizio piano (anni) | B10: 51 | C10: Età all'inizio del primo anno di prelievi.
A11: Età a fine piano (anni) | B11: 93 | C11: La durata del piano è età finale meno età iniziale (massimo 59 anni).
A12: Mesi dell'ultimo anno del piano | B12: 2 | C12: Con 93 anni al 15/03/2068 l'ultimo anno ha 2 mesi. Con 12 il piano è di 42 anni pieni (usato nei vettori di prova).
A13: Sequenza dei rendimenti
A14: Serie storica (EUR / USA) | B14: EUR | C14: EUR: partenze 2000-2025. USA: partenze 1871-2025. Oltre l'ultimo dato la sequenza prosegue al rendimento costante.
A15: Anno di partenza della sequenza (gennaio) | B15: 2000 | C15: Prova 2007 o 2010 per vedere un altro inizio; un anno senza dati dà il rendimento costante per tutto il piano.
A16: Rendimento reale costante | B16: 0.03 | C16: Ipotesi al canone: usata nel foglio 3 e dopo l'ultimo dato storico.
A17: Inflazione costante | B17: 0.02 | C17: Ipotesi al canone.
A18: Parametri delle regole
A19: Percentuale variabile: età di esaurimento | B19: 100 | C19: L'età a cui la percentuale variabile porta il capitale a zero.
A20: Percentuale variabile: rendimento reale ipotizzato | B20: 0.03 | C20: Default 3% (canone). Alternativa 3,76% (tabella del 60/40 di una comunità di investitori americani).
A21: Guardrail: variante (1 = 2006, 2 = 2004, 3 = senza congelamento) | B21: 1 | C21: 1 = proposta del 2006 (non indicizza dopo un anno negativo solo se il tasso supererebbe l'iniziale). Qui senza il tetto del 6% all'inflazione degli autori.
A22: Guardrail: banda sul tasso iniziale | B22: 0.2 | C22: Se il tasso corrente esce da ±20% del tasso iniziale scatta la correzione.
A23: Guardrail: taglio o aumento | B23: 0.1 | C23: Correzione della spesa quando si esce dalla banda.
A24: Guardrail: anni finali senza taglio | B24: 15 | C24: Negli ultimi anni del piano il taglio è spento.
A25: Tetto e pavimento: massimo aumento annuo | B25: 0.05 | C25: La spesa non cresce più del 5% l'anno.
A26: Tetto e pavimento: massimo calo annuo | B26: -0.025 | C26: La spesa non cala più del 2,5% l'anno.
A27: Percentuale con pavimento: quota della spesa iniziale | B27: 0.9 | C27: Pavimento al 90% della spesa iniziale.
A28: Fisco
A29: Plusvalenza latente iniziale | B29: 0.43435582 | C29: 1 − base di costo / valore: 1 − 597.580 / 1.056.460 = 43,4% (valore pieno: con 0,434 le uscite divergono di più di 1 €).
A30: Aliquota sulla plusvalenza | B30: 0.26 | C30: Norma di oggi (nuovo testo unico fiscale, effetti dal 1/1/2027).
A31: Bollo annuo sul valore | B31: 0.002 | C31: 0,20% del valore a fine anno.
A32: Pensione (proiezione RGS n. 27, revisione centrale)
A33: Pensione netta annua (€) | B33: 30711.544 | C33: Proiezione della Ragioneria generale dello Stato, rapporto n. 27, in euro di oggi (valore pieno: 30.712 € mostrati). Alternative: 31.829 · 29.951 · 29.349 (ipotesi di scuola).
A34: Mese della prima rata nell'anno di pensione | B34: 10 | C34: Ottobre 2043: tre rate nel primo anno.
A35: Anno del piano in cui parte la pensione | B35: 17 | C35: Anno 17 del piano. Se superiore a 60 la pensione non entra nel calcolo.
A36: Requisito della pensione (mesi di età compiuti) | B36: 822 | C36: 822 mesi: vedi la lettura in anni e mesi qui sotto.
A37: Seconda ipotesi di plusvalenza latente per il ponte | B37: 0.6 | C37: Usata nel foglio 4.
A38: Derivati (formule)
A39: Aliquota effettiva | B39: =IF(Modalita="tassato",Aliq,0) -> 0.26 | C39: Zero in modalità lordo.
A40: Bollo effettivo | B40: =IF(Modalita="tassato",Bollo,0) -> 0.002 | C40: Zero in modalità lordo.
A41: Plusvalenza latente effettiva | B41: =IF(Modalita="tassato",Latente0,0) -> 0.43435582 | C41: Zero in modalità lordo.
...

Sheet 2 - Sequenza storica
A1: 2 - Sequenza storica: spesa pagata e capitale, anno per anno (euro di oggi)
A2: Strumento informativo / divulgativo. NON è consulenza finanziaria. I valori sono indicativi al 2026 e vanno verificati col tuo consulente.
A3: Risultati: spesa pagata (euro in cassa se «tassato», venduto lordo se «lordo») e capitale a inizio anno
A4: ="Sequenza: "&Serie&" dal "&Anno_inizio&" · anni osservati: "&Anni_osservati&" · anni di ipotesi al canone: "&Anni_ipotesi&" · modalità: "&Modalita -> Sequenza: EUR dal 2000 · anni osservati: 26 · anni di ipotesi al canone: 16 · modalità: tassato
A5: t | B5: Età | C5: Anno | D5: Spesa pagata: Fisso indicizzato | E5: Spesa pagata: Percentuale costante | F5: Spesa pagata: Percentuale con pavimento | G5: Spesa pagata: Percentuale variabile | H5: Spesa pagata: Guardrail (senza tetto all'inflazione) | I5: Spesa pagata: Tetto e pavimento (+5% / −2,5%) | J5: Capitale inizio anno: Fisso indicizzato | K5: Capitale inizio anno: Percentuale costante | L5: Capitale inizio anno: Percentuale con pavimento | M5: Capitale inizio anno: Percentuale variabile | N5: Capitale inizio anno: Guardrail (senza tetto all'inflazione) | O5: Capitale inizio anno: Tetto e pavimento (+5% / −2,5%) | P5: Dato storico o ipotesi
A6: =A71 -> 1 | B6: =IF($A6>Anni,"",B71) -> 51 | C6: =IF($A6>Anni,"",C71) -> 2000 | D6: =IF($A6>Anni,"",M71) -> 38000 | E6: =IF($A6>Anni,"",R71) -> 38000 | F6: =IF($A6>Anni,"",W71) -> 38000 | G6: =IF($A6>Anni,"",AC71) -> 35662.76 | H6: =IF($A6>Anni,"",AJ71) -> 38000 | I6: =IF($A6>Anni,"",AO71) -> 38000 | J6: =IF($A6>Anni,"",N71) -> 1056000 | K6: =IF($A6>Anni,"",S71) -> 1056000 | L6: =IF($A6>Anni,"",X71) -> 1056000 | M6: =IF($A6>Anni,"",AD71) -> 1056000 | N6: =IF($A6>Anni,"",AK71) -> 1056000 | O6: =IF($A6>Anni,"",AP71) -> 1056000 | P6: =IF($A6>Anni,"",IF(D71=1,"osservato","ipotesi")) -> osservato
A7: =A72 -> 2 | B7: =IF($A7>Anni,"",B72) -> 52 | C7: =IF($A7>Anni,"",C72) -> 2001 | D7: =IF($A7>Anni,"",M72) -> 38000 | E7: =IF($A7>Anni,"",R72) -> 36810.118 | F7: =IF($A7>Anni,"",W72) -> 36810.118 | G7: =IF($A7>Anni,"",AC72) -> 34957.976 | H7: =IF($A7>Anni,"",AJ72) -> 38000 | I7: =IF($A7>Anni,"",AO72) -> 37050 | J7: =IF($A7>Anni,"",N72) -> 1029708.4 | K7: =IF($A7>Anni,"",S72) -> 1029708.4 | L7: =IF($A7>Anni,"",X72) -> 1029708.4 | M7: =IF($A7>Anni,"",AD72) -> 1032386.2 | N7: =IF($A7>Anni,"",AK72) -> 1029708.4 | O7: =IF($A7>Anni,"",AP72) -> 1029708.4 | P7: =IF($A7>Anni,"",IF(D72=1,"osservato","ipotesi")) -> osservato
A8: =A73 -> 3 | B8: =IF($A8>Anni,"",B73) -> 53 | C8: =IF($A8>Anni,"",C73) -> 2002 | D8: =IF($A8>Anni,"",M73) -> 38000 | E8: =IF($A8>Anni,"",R73) -> 32361.467 | F8: =IF($A8>Anni,"",W73) -> 34200 | G8: =IF($A8>Anni,"",AC73) -> 31099.612 | H8: =IF($A8>Anni,"",AJ73) -> 37157.757 | I8: =IF($A8>Anni,"",AO73) -> 36123.75 | J8: =IF($A8>Anni,"",N73) -> 892443.2 | K8: =IF($A8>Anni,"",S73) -> 893664.6 | L8: =IF($A8>Anni,"",X73) -> 893664.6 | M8: =IF($A8>Anni,"",AD73) -> 897988.1 | N8: =IF($A8>Anni,"",AK73) -> 892443.2 | O8: =IF($A8>Anni,"",AP73) -> 893418.36 | P8: =IF($A8>Anni,"",IF(D73=1,"osservato","ipotesi")) -> osservato
A9: =A74 -> 4 | B9: =IF($A9>Anni,"",B74) -> 54 | C9: =IF($A9>Anni,"",C74) -> 2003 | D9: =IF($A9>Anni,"",M74) -> 38000 | E9: =IF($A9>Anni,"",R74) -> 26006.674 | F9: =IF($A9>Anni,"",W74) -> 34200 | G9: =IF($A9>Anni,"",AC74) -> 25290.609 | H9: =IF($A9>Anni,"",AJ74) -> 32509.505 | I9: =IF($A9>Anni,"",AO74) -> 35220.656 | J9: =IF($A9>Anni,"",N74) -> 688278.51 | K9: =IF($A9>Anni,"",S74) -> 694383.14 | L9: =IF($A9>Anni,"",X74) -> 692715.16 | M9: =IF($A9>Anni,"",AD74) -> 699029.37 | N9: =IF($A9>Anni,"",AK74) -> 689042.62 | O9: =IF($A9>Anni,"",AP74) -> 690770.46 | P9: =IF($A9>Anni,"",IF(D74=1,"osservato","ipotesi")) -> osservato
A10: =A75 -> 5 | B10: =IF($A10>Anni,"",B75) -> 55 | C10: =IF($A10>Anni,"",C75) -> 2004 | D10: =IF($A10>Anni,"",M75) -> 38000 | E10: =IF($A10>Anni,"",R75) -> 26959.76 | F10: =IF($A10>Anni,"",W75) -> 34200 | G10: =IF($A10>Anni,"",AC75) -> 26530.058 | H10: =IF($A10>Anni,"",AJ75) -> 29258.554 | I10: =IF($A10>Anni,"",AO75) -> 34340.14 | J10: =IF($A10>Anni,"",N75) -> 715476.36 | K10: =IF($A10>Anni,"",S75) -> 736588.25 | L10: =IF($A10>Anni,"",X75) -> 724932.29 | M10: =IF($A10>Anni,"",AD75) -> 742582.78 | N10: =IF($A10>Anni,"",AK75) -> 722896.24 | O10: =IF($A10>Anni,"",AP75) -> 721559.89 | P10: =IF($A10>Anni,"",IF(D75=1,"osservato","ipotesi")) -> osservato
A11: =A76 -> 6 | B11: =IF($A11>Anni,"",B76) -> 56 | C11: =IF($A11>Anni,"",C76) -> 2005 | D11: =IF($A11>Anni,"",M76) -> 38000 | E11: =IF($A11>Anni,"",R76) -> 26924.161 | F11: =IF($A11>Anni,"",W76) -> 34200 | G11: =IF($A11>Anni,"",AC76) -> 26810.942 | H11: =IF($A11>Anni,"",AJ76) -> 29258.554 | I11: =IF($A11>Anni,"",AO76) -> 33481.636 | J11: =IF($A11>Anni,"",N76) -> 709816.36 | K11: =IF($A11>Anni,"",S76) -> 744970.09 | L11: =IF($A11>Anni,"",X76) -> 724223.96 | M11: =IF($A11>Anni,"",AD76) -> 751791.21 | N11: =IF($A11>Anni,"",AK76) -> 727850.99 | O11: =IF($A11>Anni,"",AP76) -> 720505.25 | P11: =IF($A11>Anni,"",IF(D76=1,"osservato","ipotesi")) -> osservato
A12: =A77 -> 7 | B12: =IF($A12>Anni,"",B77) -> 57 | C12: =IF($A12>Anni,"",C77) -> 2006 | D12: =IF($A12>Anni,"",M77) -> 38000 | E12: =IF($A12>Anni,"",R77) -> 28803.531 | F12: =IF($A12>Anni,"",W77) -> 34200 | G12: =IF($A12>Anni,"",AC77) -> 29024.405 | H12: =IF($A12>Anni,"",AJ77) -> 29258.554 | I12: =IF($A12>Anni,"",AO77) -> 32644.595 | J12: =IF($A12>Anni,"",N77) -> 762479.54 | K12: =IF($A12>Anni,"",S77) -> 816863.52 | L12: =IF($A12>Anni,"",X77) -> 783820.1 | M12: =IF($A12>Anni,"",AD77) -> 824804.39 | N12: =IF($A12>Anni,"",AK77) -> 794304.14 | O12: =IF($A12>Anni,"",AP77) -> 780491.61 | P12: =IF($A12>Anni,"",IF(D77=1,"osservato","ipotesi")) -> osservato
A13: =A78 -> 8 | B13: =IF($A13>Anni,"",B78) -> 58 | C13: =IF($A13>Anni,"",C78) -> 2007 | D13: =IF($A13>Anni,"",M78) -> 38000 | E13: =IF($A13>Anni,"",R78) -> 28184.307 | F13: =IF($A13>Anni,"",W78) -> 34200 | G13: =IF($A13>Anni,"",AC78) -> 28739.066 | H13: =IF($A13>Anni,"",AJ78) -> 29258.554 | I13: =IF($A13>Anni,"",AO78) -> 31828.481 | J13: =IF($A13>Anni,"",N78) -> 737887.98 | K13: =IF($A13>Anni,"",S78) -> 804580.64 | L13: =IF($A13>Anni,"",X78) -> 764284.42 | M13: =IF($A13>Anni,"",AD78) -> 812471.94 | N13: =IF($A13>Anni,"",AK78) -> 780883.57 | O13: =IF($A13>Anni,"",AP78) -> 762704.39 | P13: =IF($A13>Anni,"",IF(D78=1,"osservato","ipotesi")) -> osservato
A14: =A79 -> 9 | B14: =IF($A14>Anni,"",B79) -> 59 | C14: =IF($A14>Anni,"",C79) -> 2008 | D14: =IF($A14>Anni,"",M79) -> 38000 | E14: =IF($A14>Anni,"",R79) -> 24895.373 | F14: =IF($A14>Anni,"",W79) -> 34200 | G14: =IF($A14>Anni,"",AC79) -> 25688.08 | H14: =IF($A14>Anni,"",AJ79) -> 28363.898 | I14: =IF($A14>Anni,"",AO79) -> 31032.769 | J14: =IF($A14>Anni,"",N79) -> 633176.44 | K14: =IF($A14>Anni,"",S79) -> 704406.88 | L14: =IF($A14>Anni,"",X79) -> 661279.1 | M14: =IF($A14>Anni,"",AD79) -> 711021.56 | N14: =IF($A14>Anni,"",AK79) -> 681647.81 | O14: =IF($A14>Anni,"",AP79) -> 662343.36 | P14: =IF($A14>Anni,"",IF(D79=1,"osservato","ipotesi")) -> osservato
A15: =A80 -> 10 | B15: =IF($A15>Anni,"",B80) -> 60 | C15: =IF($A15>Anni,"",C80) -> 2009 | D15: =IF($A15>Anni,"",M80) -> 38000 | E15: =IF($A15>Anni,"",R80) -> 20288.788 | F15: =IF($A15>Anni,"",W80) -> 34200 | G15: =IF($A15>Anni,"",AC80) -> 21184.431 | H15: =IF($A15>Anni,"",AJ80) -> 25185.24 | I15: =IF($A15>Anni,"",AO80) -> 30256.949 | J15: =IF($A15>Anni,"",N80) -> 486442.45 | K15: =IF($A15>Anni,"",S80) -> 557624.98 | L15: =IF($A15>Anni,"",X80) -> 513228.58 | M15: =IF($A15>Anni,"",AD80) -> 562331.98 | N15: =IF($A15>Anni,"",AK80) -> 535561.74 | O15: =IF($A15>Anni,"",AP80) -> 517106.21 | P15: =IF($A15>Anni,"",IF(D80=1,"osservato","ipotesi")) -> osservato
A16: =A81 -> 11 | B16: =IF($A16>Anni,"",B81) -> 61 | C16: =IF($A16>Anni,"",C81) -> 2010 | D16: =IF($A16>Anni,"",M81) -> 38000 | E16: =IF($A16>Anni,"",R81) -> 21967.594 | F16: =IF($A16>Anni,"",W81) -> 34200 | G16: =IF($A16>Anni,"",AC81) -> 23210.843 | H16: =IF($A16>Anni,"",AJ81) -> 22666.716 | I16: =IF($A16>Anni,"",AO81) -> 29500.526 | J16: =IF($A16>Anni,"",N81) -> 514498.22 | K16: =IF($A16>Anni,"",S81) -> 619847.53 | L16: =IF($A16>Anni,"",X81) -> 550440.83 | M16: =IF($A16>Anni,"",AD81) -> 624144.05 | N16: =IF($A16>Anni,"",AK81) -> 587960.45 | O16: =IF($A16>Anni,"",AP81) -> 560026.8 | P16: =IF($A16>Anni,"",IF(D81=1,"osservato","ipotesi")) -> osservato
A17: =A82 -> 12 | B17: =IF($A17>Anni,"",B82) -> 62 | C17: =IF($A17>Anni,"",C82) -> 2011 | D17: =IF($A17>Anni,"",M82) -> 38000 | E17: =IF($A17>Anni,"",R82) -> 23079.086 | F17: =IF($A17>Anni,"",W82) -> 34200 | G17: =IF($A17>Anni,"",AC82) -> 24675.998 | H17: =IF($A17>Anni,"",AJ82) -> 22666.716 | I17: =IF($A17>Anni,"",AO82) -> 28763.012 | J17: =IF($A17>Anni,"",N82) -> 525493.43 | K17: =IF($A17>Anni,"",S82) -> 663505.08 | L17: =IF($A17>Anni,"",X82) -> 570447.12 | M17: =IF($A17>Anni,"",AD82) -> 666710.98 | N17: =IF($A17>Anni,"",AK82) -> 627036.11 | O17: =IF($A17>Anni,"",AP82) -> 587143.61 | P17: =IF($A17>Anni,"",IF(D82=1,"osservato","ipotesi")) -> osservato
... A47: =A112 -> 42 | B47: =IF($A47>Anni,"",B112) -> 92 | C47: =IF($A47>Anni,"",C112) -> 2041 | D47: =IF($A47>Anni,"",M112) -> 0 | E47: =IF($A47>Anni,"",R112) -> 19562.99 | F47: =IF($A47>Anni,"",W112) -> 0 | G47: =IF($A47>Anni,"",AC112) -> 29848.501 | H47: =IF($A47>Anni,"",AJ112) -> 20481.744 | I47: =IF($A47>Anni,"",AO112) -> 15193.992 | J47: =IF($A47>Anni,"",N112) -> 0 | K47: =IF($A47>Anni,"",S112) -> 634790.62 | L47: =IF($A47>Anni,"",X112) -> 0 | M47: =IF($A47>Anni,"",AD112) -> 284077.02 | N47: =IF($A47>Anni,"",AK112) -> 675902.15 | O47: =IF($A47>Anni,"",AP112) -> 493022.97 | P47: =IF($A47>Anni,"",IF(D112=1,"osservato","ipotesi")) -> ipotesi
A48: =A113 -> 43 | B48: =IF($A48>Anni,"",B113) | C48: =IF($A48>Anni,"",C113) | D48: =IF($A48>Anni,"",M113) | E48: =IF($A48>Anni,"",R113) | F48: =IF($A48>Anni,"",W113) | G48: =IF($A48>Anni,"",AC113) | H48: =IF($A48>Anni,"",AJ113) | I48: =IF($A48>Anni,"",AO113) | J48: =IF($A48>Anni,"",N113) | K48: =IF($A48>Anni,"",S113) | L48: =IF($A48>Anni,"",X113) | M48: =IF($A48>Anni,"",AD113) | N48: =IF($A48>Anni,"",AK113) | O48: =IF($A48>Anni,"",AP113) | P48: =IF($A48>Anni,"",IF(D113=1,"osservato","ipotesi")) | R48: Il grafico mostra i primi 42 anni (righe 6-47); la tabella a sinistra mostra l'intero piano.
A49: =A114 -> 44 | B49: =IF($A49>Anni,"",B114) | C49: =IF($A49>Anni,"",C114) | D49: =IF($A49>Anni,"",M114) | E49: =IF($A49>Anni,"",R114) | F49: =IF($A49>Anni,"",W114) | G49: =IF($A49>Anni,"",AC114) | H49: =IF($A49>Anni,"",AJ114) | I49: =IF($A49>Anni,"",AO114) | J49: =IF($A49>Anni,"",N114) | K49: =IF($A49>Anni,"",S114) | L49: =IF($A49>Anni,"",X114) | M49: =IF($A49>Anni,"",AD114) | N49: =IF($A49>Anni,"",AK114) | O49: =IF($A49>Anni,"",AP114) | P49: =IF($A49>Anni,"",IF(D114=1,"osservato","ipotesi"))
A50: =A115 -> 45 | B50: =IF($A50>Anni,"",B115) | C50: =IF($A50>Anni,"",C115) | D50: =IF($A50>Anni,"",M115) | E50: =IF($A50>Anni,"",R115) | F50: =IF($A50>Anni,"",W115) | G50: =IF($A50>Anni,"",AC115) | H50: =IF($A50>Anni,"",AJ115) | I50: =IF($A50>Anni,"",AO115) | J50: =IF($A50>Anni,"",N115) | K50: =IF($A50>Anni,"",S115) | L50: =IF($A50>Anni,"",X115) | M50: =IF($A50>Anni,"",AD115) | N50: =IF($A50>Anni,"",AK115) | O50: =IF($A50>Anni,"",AP115) | P50: =IF($A50>Anni,"",IF(D115=1,"osservato","ipotesi"))
A51: =A116 -> 46 | B51: =IF($A51>Anni,"",B116) | C51: =IF($A51>Anni,"",C116) | D51: =IF($A51>Anni,"",M116) | E51: =IF($A51>Anni,"",R116) | F51: =IF($A51>Anni,"",W116) | G51: =IF($A51>Anni,"",AC116) | H51: =IF($A51>Anni,"",AJ116) | I51: =IF($A51>Anni,"",AO116) | J51: =IF($A51>Anni,"",N116) | K51: =IF($A51>Anni,"",S116) | L51: =IF($A51>Anni,"",X116) | M51: =IF($A51>Anni,"",AD116) | N51: =IF($A51>Anni,"",AK116) | O51: =IF($A51>Anni,"",AP116) | P51: =IF($A51>Anni,"",IF(D116=1,"osservato","ipotesi"))
A52: =A117 -> 47 | B52: =IF($A52>Anni,"",B117) | C52: =IF($A52>Anni,"",C117) | D52: =IF($A52>Anni,"",M117) | E52: =IF($A52>Anni,"",R117) | F52: =IF($A52>Anni,"",W117) | G52: =IF($A52>Anni,"",AC117) | H52: =IF($A52>Anni,"",AJ117) | I52: =IF($A52>Anni,"",AO117) | J52: =IF($A52>Anni,"",N117) | K52: =IF($A52>Anni,"",S117) | L52: =IF($A52>Anni,"",X117) | M52: =IF($A52>Anni,"",AD117) | N52: =IF($A52>Anni,"",AK117) | O52: =IF($A52>Anni,"",AP117) | P52: =IF($A52>Anni,"",IF(D117=1,"osservato","ipotesi"))
A53: =A118 -> 48 | B53: =IF($A53>Anni,"",B118) | C53: =IF($A53>Anni,"",C118) | D53: =IF($A53>Anni,"",M118) | E53: =IF($A53>Anni,"",R118) | F53: =IF($A53>Anni,"",W118) | G53: =IF($A53>Anni,"",AC118) | H53: =IF($A53>Anni,"",AJ118) | I53: =IF($A53>Anni,"",AO118) | J53: =IF($A53>Anni,"",N118) | K53: =IF($A53>Anni,"",S118) | L53: =IF($A53>Anni,"",X118) | M53: =IF($A53>Anni,"",AD118) | N53: =IF($A53>Anni,"",AK118) | O53: =IF($A53>Anni,"",AP118) | P53: =IF($A53>Anni,"",IF(D118=1,"osservato","ipotesi"))
A54: =A119 -> 49 | B54: =IF($A54>Anni,"",B119) | C54: =IF($A54>Anni,"",C119) | D54: =IF($A54>Anni,"",M119) | E54: =IF($A54>Anni,"",R119) | F54: =IF($A54>Anni,"",W119) | G54: =IF($A54>Anni,"",AC119) | H54: =IF($A54>Anni,"",AJ119) | I54: =IF($A54>Anni,"",AO119) | J54: =IF($A54>Anni,"",N119) | K54: =IF($A54>Anni,"",S119) | L54: =IF($A54>Anni,"",X119) | M54: =IF($A54>Anni,"",AD119) | N54: =IF($A54>Anni,"",AK119) | O54: =IF($A54>Anni,"",AP119) | P54: =IF($A54>Anni,"",IF(D119=1,"osservato","ipotesi"))
A55: =A120 -> 50 | B55: =IF($A55>Anni,"",B120) | C55: =IF($A55>Anni,"",C120) | D55: =IF($A55>Anni,"",M120) | E55: =IF($A55>Anni,"",R120) | F55: =IF($A55>Anni,"",W120) | G55: =IF($A55>Anni,"",AC120) | H55: =IF($A55>Anni,"",AJ120) | I55: =IF($A55>Anni,"",AO120) | J55: =IF($A55>Anni,"",N120) | K55: =IF($A55>Anni,"",S120) | L55: =IF($A55>Anni,"",X120) | M55: =IF($A55>Anni,"",AD120) | N55: =IF($A55>Anni,"",AK120) | O55: =IF($A55>Anni,"",AP120) | P55: =IF($A55>Anni,"",IF(D120=1,"osservato","ipotesi"))
A56: =A121 -> 51 | B56: =IF($A56>Anni,"",B121) | C56: =IF($A56>Anni,"",C121) | D56: =IF($A56>Anni,"",M121) | E56: =IF($A56>Anni,"",R121) | F56: =IF($A56>Anni,"",W121) | G56: =IF($A56>Anni,"",AC121) | H56: =IF($A56>Anni,"",AJ121) | I56: =IF($A56>Anni,"",AO121) | J56: =IF($A56>Anni,"",N121) | K56: =IF($A56>Anni,"",S121) | L56: =IF($A56>Anni,"",X121) | M56: =IF($A56>Anni,"",AD121) | N56: =IF($A56>Anni,"",AK121) | O56: =IF($A56>Anni,"",AP121) | P56: =IF($A56>Anni,"",IF(D121=1,"osservato","ipotesi"))
A57: =A122 -> 52 | B57: =IF($A57>Anni,"",B122) | C57: =IF($A57>Anni,"",C122) | D57: =IF($A57>Anni,"",M122) | E57: =IF($A57>Anni,"",R122) | F57: =IF($A57>Anni,"",W122) | G57: =IF($A57>Anni,"",AC122) | H57: =IF($A57>Anni,"",AJ122) | I57: =IF($A57>Anni,"",AO122) | J57: =IF($A57>Anni,"",N122) | K57: =IF($A57>Anni,"",S122) | L57: =IF($A57>Anni,"",X122) | M57: =IF($A57>Anni,"",AD122) | N57: =IF($A57>Anni,"",AK122) | O57: =IF($A57>Anni,"",AP122) | P57: =IF($A57>Anni,"",IF(D122=1,"osservato","ipotesi"))
A58: =A123 -> 53 | B58: =IF($A58>Anni,"",B123) | C58: =IF($A58>Anni,"",C123) | D58: =IF($A58>Anni,"",M123) | E58: =IF($A58>Anni,"",R123) | F58: =IF($A58>Anni,"",W123) | G58: =IF($A58>Anni,"",AC123) | H58: =IF($A58>Anni,"",AJ123) | I58: =IF($A58>Anni,"",AO123) | J58: =IF($A58>Anni,"",N123) | K58: =IF($A58>Anni,"",S123) | L58: =IF($A58>Anni,"",X123) | M58: =IF($A58>Anni,"",AD123) | N58: =IF($A58>Anni,"",AK123) | O58: =IF($A58>Anni,"",AP123) | P58: =IF($A58>Anni,"",IF(D123=1,"osservato","ipotesi"))
A59: =A124 -> 54 | B59: =IF($A59>Anni,"",B124) | C59: =IF($A59>Anni,"",C124) | D59: =IF($A59>Anni,"",M124) | E59: =IF($A59>Anni,"",R124) | F59: =IF($A59>Anni,"",W124) | G59: =IF($A59>Anni,"",AC124) | H59: =IF($A59>Anni,"",AJ124) | I59: =IF($A59>Anni,"",AO124) | J59: =IF($A59>Anni,"",N124) | K59: =IF($A59>Anni,"",S124) | L59: =IF($A59>Anni,"",X124) | M59: =IF($A59>Anni,"",AD124) | N59: =IF($A59>Anni,"",AK124) | O59: =IF($A59>Anni,"",AP124) | P59: =IF($A59>Anni,"",IF(D124=1,"osservato","ipotesi"))
A60: =A125 -> 55 | B60: =IF($A60>Anni,"",B125) | C60: =IF($A60>Anni,"",C125) | D60: =IF($A60>Anni,"",M125) | E60: =IF($A60>Anni,"",R125) | F60: =IF($A60>Anni,"",W125) | G60: =IF($A60>Anni,"",AC125) | H60: =IF($A60>Anni,"",AJ125) | I60: =IF($A60>Anni,"",AO125) | J60: =IF($A60>Anni,"",N125) | K60: =IF($A60>Anni,"",S125) | L60: =IF($A60>Anni,"",X125) | M60: =IF($A60>Anni,"",AD125) | N60: =IF($A60>Anni,"",AK125) | O60: =IF($A60>Anni,"",AP125) | P60: =IF($A60>Anni,"",IF(D125=1,"osservato","ipotesi"))
... A65: =A130 -> 60 | B65: =IF($A65>Anni,"",B130) | C65: =IF($A65>Anni,"",C130) | D65: =IF($A65>Anni,"",M130) | E65: =IF($A65>Anni,"",R130) | F65: =IF($A65>Anni,"",W130) | G65: =IF($A65>Anni,"",AC130) | H65: =IF($A65>Anni,"",AJ130) | I65: =IF($A65>Anni,"",AO130) | J65: =IF($A65>Anni,"",N130) | K65: =IF($A65>Anni,"",S130) | L65: =IF($A65>Anni,"",X130) | M65: =IF($A65>Anni,"",AD130) | N65: =IF($A65>Anni,"",AK130) | O65: =IF($A65>Anni,"",AP130) | P65: =IF($A65>Anni,"",IF(D130=1,"osservato","ipotesi"))
A68: Motore del calcolo, non modificare
A69: Anno e rendimenti | J69: Fisso indicizzato | O69: Percentuale costante | T69: Percentuale con pavimento | Y69: Percentuale variabile | AE69: Guardrail (senza tetto all'inflazione) | AL69: Tetto e pavimento | AQ69: Cambio % annuo della spesa pagata
A70: t | B70: Età | C70: Anno | D70: Dato storico (1/0) | E70: Rendimento nominale 60/40 | F70: Inflazione | G70: Fattore nominale dopo bollo (g) | H70: Base di costo / valore (k) | I70: Quota netta del venduto (q) | J70: Fisso: pianificata | K70: Fisso: venduto | L70: Fisso: esaurimento | M70: Fisso: pagata | N70: Fisso: capitale (W) | O70: Perc. costante: pianificata | P70: Perc. costante: venduto | Q70: Perc. costante: esaurimento | R70: Perc. costante: pagata | S70: Perc. costante: capitale (W) | T70: Perc. con pav.: pianificata | U70: Perc. con pav.: venduto | V70: Perc. con pav.: esaurimento | W70: Perc. con pav.: pagata | X70: Perc. con pav.: capitale (W) | Y70: Perc. variabile: percentuale | Z70: Perc. variabile: pianificata | AA70: Perc. variabile: venduto | AB70: Perc. variabile: esaurimento | AC70: Perc. variabile: pagata | AD70: Perc. variabile: capitale (W) | AE70: Guardrail: prima della regola | AF70: Guardrail: tasso corrente | AG70: Guardrail: pianificata | AH70: Guardrail: venduto | AI70: Guardrail: esaurimento | AJ70: Guardrail: pagata | AK70: Guardrail: capitale (W) | AL70: Tetto e pav.: pianificata | AM70: Tetto e pav.: venduto | AN70: Tetto e pav.: esaurimento | AO70: Tetto e pav.: pagata | AP70: Tetto e pav.: capitale (W) | AQ70: Cambio % fisso | AR70: Cambio % perc. costante | AS70: Cambio % perc. con pav. | AT70: Cambio % perc. variabile | AU70: Cambio % guardrail | AV70: Cambio % tetto e pav.
A71: 1 | B71: =Eta_inizio+A71-1 -> 51 | C71: =Anno_inizio+A71-1 -> 2000 | D71: =IF(COUNTIFS('5 - Dati'!$A$6:$A$186,Serie,'5 - Dati'!$B$6:$B$186,C71)>0,1,0) -> 1 | E71: =IF(D71=1,SUMIFS('5 - Dati'!$F$6:$F$186,'5 - Dati'!$A$6:$A$186,Serie,'5 - Dati'!$B$6:$B$186,C71),(1+Rend_c)*(1+Infl_c)-1) -> 0.04340975 | F71: =IF(D71=1,SUMIFS('5 - Dati'!$E$6:$E$186,'5 - Dati'!$A$6:$A$186,Serie,'5 - Dati'!$B$6:$B$186,C71),Infl_c) -> 0.02459017 | G71: =(1+E71)*(1-Bollo_eff) -> 1.0413229 | H71: =1-Latente_eff -> 0.56564418 | I71: =1-Aliq_eff*MAX(0,1-H71) -> 0.88706749 | J71: =Spesa0 -> 38000 | K71: =J71/I71 -> 42837.778 | L71: =IF(K71>N71+0.000000001,1,0) -> 0 | M71: =MIN(K71,N71)*I71 -> 38000 | N71: =Patrimonio -> 1056000 | O71: =Tasso0*S71*I71 -> 38000 | P71: =O71/I71 -> 42837.778 | Q71: =IF(P71>S71+0.000000001,1,0) -> 0 | R71: =MIN(P71,S71)*I71 -> 38000 | S71: =Patrimonio -> 1056000 | T71: =MAX(Tasso0*X71*I71,Pav_pct*Spesa0) -> 38000 | U71: =T71/I71 -> 42837.778 | V71: =IF(U71>X71+0.000000001,1,0) -> 0 | W71: =MIN(U71,X71)*I71 -> 38000 | X71: =Patrimonio -> 1056000 | Y71: =IF(Eta_rif_VPW-B71<=1,1,IF(r_VPW=0,1/(Eta_rif_VPW-B71),r_VPW/(1-(1+r_VPW)^(-(Eta_rif_VPW-B71)))/(1+r_VPW))) -> 0.038071008 | Z71: =Y71*AD71*I71 -> 35662.76 | AA71: =Z71/I71 -> 40202.985 | AB71: =IF(AA71>AD71+0.000000001,1,0) -> 0 | AC71: =MIN(AA71,AD71)*I71 -> 35662.76 | AD71: =Patrimonio -> 1056000 | AE71: =Spesa0 -> 38000 | AF71: =IF(AK71*I71<=0,9.9,AE71/(AK71*I71)) -> 0.040566078 | AG71: =IF(AND(AF71>Tasso0*(1+GK_banda),A71<=Anni-GK_ultimi),AE71*(1-GK_taglio),IF(AF71<Tasso0*(1-GK_banda),AE71*(1+GK_taglio),AE71)) -> 38000 | AH71: =AG71/I71 -> 42837.778 | AI71: =IF(AH71>AK71+0.000000001,1,0) -> 0 | AJ71: =MIN(AH71,AK71)*I71 -> 38000 | AK71: =Patrimonio -> 1056000 | AL71: =Spesa0 -> 38000 | AM71: =AL71/I71 -> 42837.778 | AN71: =IF(AM71>AP71+0.000000001,1,0) -> 0 | AO71: =MIN(AM71,AP71)*I71 -> 38000 | AP71: =Patrimonio -> 1056000
A72: =A71+1 -> 2 | B72: =Eta_inizio+A72-1 -> 52 | C72: =Anno_inizio+A72-1 -> 2001 | D72: =IF(COUNTIFS('5 - Dati'!$A$6:$A$186,Serie,'5 - Dati'!$B$6:$B$186,C72)>0,1,0) -> 1 | E72: =IF(D72=1,SUMIFS('5 - Dati'!$F$6:$F$186,'5 - Dati'!$A$6:$A$186,Serie,'5 - Dati'!$B$6:$B$186,C72),(1+Rend_c)*(1+Infl_c)-1) -> -0.073065986 | F72: =IF(D72=1,SUMIFS('5 - Dati'!$E$6:$E$186,'5 - Dati'!$A$6:$A$186,Serie,'5 - Dati'!$B$6:$B$186,C72),Infl_c) -> 0.02266669 | G72: =(1+E72)*(1-Bollo_eff) -> 0.92508015 | H72: =H71/G71 -> 0.54319766 | I72: =1-Aliq_eff*MAX(0,1-H72) -> 0.88123139 | J72: =Spesa0 -> 38000 | K72: =J72/I72 -> 43121.478 | L72: =IF(K72>N72+0.000000001,1,0) -> 0 | M72: =MIN(K72,N72)*I72 -> 38000 | N72: =(N71-MIN(K71,N71))*G71/(1+F71) -> 1029708.4 | O72: =Tasso0*S72*I72 -> 36810.118 | P72: =O72/I72 -> 41771.229 | Q72: =IF(P72>S72+0.000000001,1,0) -> 0 | R72: =MIN(P72,S72)*I72 -> 36810.118 | S72: =(S71-MIN(P71,S71))*G71/(1+F71) -> 1029708.4 | T72: =MAX(Tasso0*X72*I72,Pav_pct*Spesa0) -> 36810.118 | U72: =T72/I72 -> 41771.229 | V72: =IF(U72>X72+0.000000001,1,0) -> 0 | W72: =MIN(U72,X72)*I72 -> 36810.118 | X72: =(X71-MIN(U71,X71))*G71/(1+F71) -> 1029708.4 | Y72: =IF(Eta_rif_VPW-B72<=1,1,IF(r_VPW=0,1/(Eta_rif_VPW-B72),r_VPW/(1-(1+r_VPW)^(-(Eta_rif_VPW-B72)))/(1+r_VPW))) -> 0.038425023 | Z72: =Y72*AD72*I72 -> 34957.976 | AA72: =Z72/I72 -> 39669.463 | AB72: =IF(AA72>AD72+0.000000001,1,0) -> 0 | AC72: =MIN(AA72,AD72)*I72 -> 34957.976 | AD72: =(AD71-MIN(AA71,AD71))*G71/(1+F71) -> 1032386.2 | AE72: =IF(OR(E71>=0,GK_variante=3),AG71,IF(GK_variante=2,AG71/(1+F71),IF(AK72*I72<=0,AG71/(1+F71),IF(AG71/(AK72*I72)>Tasso0,AG71/(1+F71),AG71)))) -> 38000 | AF72: =IF(AK72*I72<=0,9.9,AE72/(AK72*I72)) -> 0.04187737 | AG72: =IF(AND(AF72>Tasso0*(1+GK_banda),A72<=Anni-GK_ultimi),AE72*(1-GK_taglio),IF(AF72<Tasso0*(1-GK_banda),AE72*(1+GK_taglio),AE72)) -> 38000 | AH72: =AG72/I72 -> 43121.478 | AI72: =IF(AH72>AK72+0.000000001,1,0) -> 0 | AJ72: =MIN(AH72,AK72)*I72 -> 38000 | AK72: =(AK71-MIN(AH71,AK71))*G71/(1+F71) -> 1029708.4 | AL72: =MIN(MAX(Tasso0*AP72*I72,AL71*(1+VG_pav)),AL71*(1+VG_tetto)) -> 37050 | AM72: =AL72/I72 -> 42043.441 | AN72: =IF(AM72>AP72+0.000000001,1,0) -> 0 | AO72: =MIN(AM72,AP72)*I72 -> 37050 | AP72: =(AP71-MIN(AM71,AP71))*G71/(1+F71) -> 1029708.4 | AQ72: =IF(AND(A72<=Anni,M71>0),M72/M71-1,"") -> 0 | AR72: =IF(AND(A72<=Anni,R71>0),R72/R71-1,"") -> -0.031312681 | AS72: =IF(AND(A72<=Anni,W71>0),W72/W71-1,"") -> -0.031312681 | AT72: =IF(AND(A72<=Anni,AC71>0),AC72/AC71-1,"") -> -0.019762483 | AU72: =IF(AND(A72<=Anni,AJ71>0),AJ72/AJ71-1,"") -> 0 | AV72: =IF(AND(A72<=Anni,AO71>0),AO72/AO71-1,"") -> -0.025
A73: =A72+1 -> 3 | B73: =Eta_inizio+A73-1 -> 53 | C73: =Anno_inizio+A73-1 -> 2002 | D73: =IF(COUNTIFS('5 - Dati'!$A$6:$A$186,Serie,'5 - Dati'!$B$6:$B$186,C73)>0,1,0) -> 1 | E73: =IF(D73=1,SUMIFS('5 - Dati'!$F$6:$F$186,'5 - Dati'!$A$6:$A$186,Serie,'5 - Dati'!$B$6:$B$186,C73),(1+Rend_c)*(1+Infl_c)-1) -> -0.16524189 | F73: =IF(D73=1,SUMIFS('5 - Dati'!$E$6:$E$186,'5 - Dati'!$A$6:$A$186,Serie,'5 - Dati'!$B$6:$B$186,C73),Infl_c) -> 0.02868319 | G73: =(1+E73)*(1-Bollo_eff) -> 0.83308859 | H73: =H72/G72 -> 0.58718983 | I73: =1-Aliq_eff*MAX(0,1-H73) -> 0.89266936 | J73: =Spesa0 -> 38000 | K73: =J73/I73 -> 42568.953 | L73: =IF(K73>N73+0.000000001,1,0) -> 0 | M73: =MIN(K73,N73)*I73 -> 38000 | N73: =(N72-MIN(K72,N72))*G72/(1+F72) -> 892443.2 | O73: =Tasso0*S73*I73 -> 32361.467 | P73: =O73/I73 -> 36252.467 | Q73: =IF(P73>S73+0.000000001,1,0) -> 0 | R73: =MIN(P73,S73)*I73 -> 32361.467 | S73: =(S72-MIN(P72,S72))*G72/(1+F72) -> 893664.6 | T73: =MAX(Tasso0*X73*I73,Pav_pct*Spesa0) -> 34200 | U73: =T73/I73 -> 38312.058 | V73: =IF(U73>X73+0.000000001,1,0) -> 0 | W73: =MIN(U73,X73)*I73 -> 34200 | X73: =(X72-MIN(U72,X72))*G72/(1+F72) -> 893664.6 | Y73: =IF(Eta_rif_VPW-B73<=1,1,IF(r_VPW=0,1/(Eta_rif_VPW-B73),r_VPW/(1-(1+r_VPW)^(-(Eta_rif_VPW-B73)))/(1+r_VPW))) -> 0.038796608 | Z73: =Y73*AD73*I73 -> 31099.612 | AA73: =Z73/I73 -> 34838.893 | AB73: =IF(AA73>AD73+0.000000001,1,0) -> 0 | AC73: =MIN(AA73,AD73)*I73 -> 31099.612 | AD73: =(AD72-MIN(AA72,AD72))*G72/(1+F72) -> 897988.1 | AE73: =IF(OR(E72>=0,GK_variante=3),AG72,IF(GK_variante=2,AG72/(1+F72),IF(AK73*I73<=0,AG72/(1+F72),IF(AG72/(AK73*I73)>Tasso0,AG72/(1+F72),AG72)))) -> 37157.757 | AF73: =IF(AK73*I73<=0,9.9,AE73/(AK73*I73)) -> 0.046642119 | AG73: =IF(AND(AF73>Tasso0*(1+GK_banda),A73<=Anni-GK_ultimi),AE73*(1-GK_taglio),IF(AF73<Tasso0*(1-GK_banda),AE73*(1+GK_taglio),AE73)) -> 37157.757 | AH73: =AG73/I73 -> 41625.442 | AI73: =IF(AH73>AK73+0.000000001,1,0) -> 0 | AJ73: =MIN(AH73,AK73)*I73 -> 37157.757 | AK73: =(AK72-MIN(AH72,AK72))*G72/(1+F72) -> 892443.2 | AL73: =MIN(MAX(Tasso0*AP73*I73,AL72*(1+VG_pav)),AL72*(1+VG_tetto)) -> 36123.75 | AM73: =AL73/I73 -> 40467.111 | AN73: =IF(AM73>AP73+0.000000001,1,0) -> 0 | AO73: =MIN(AM73,AP73)*I73 -> 36123.75 | AP73: =(AP72-MIN(AM72,AP72))*G72/(1+F72) -> 893418.36 | AQ73: =IF(AND(A73<=Anni,M72>0),M73/M72-1,"") -> 0 | AR73: =IF(AND(A73<=Anni,R72>0),R73/R72-1,"") -> -0.12085404 | AS73: =IF(AND(A73<=Anni,W72>0),W73/W72-1,"") -> -0.070907627 | AT73: =IF(AND(A73<=Anni,AC72>0),AC73/AC72-1,"") -> -0.11037149 | AU73: =IF(AND(A73<=Anni,AJ72>0),AJ73/AJ72-1,"") -> -0.022164299 | AV73: =IF(AND(A73<=Anni,AO72>0),AO73/AO72-1,"") -> -0.025
A74: =A73+1 -> 4 | B74: =Eta_inizio+A74-1 -> 54 | C74: =Anno_inizio+A74-1 -> 2003 | D74: =IF(COUNTIFS('5 - Dati'!$A$6:$A$186,Serie,'5 - Dati'!$B$6:$B$186,C74)>0,1,0) -> 1 | E74: =IF(D74=1,SUMIFS('5 - Dati'!$F$6:$F$186,'5 - Dati'!$A$6:$A$186,Serie,'5 - Dati'!$B$6:$B$186,C74),(1+Rend_c)*(1+Infl_c)-1) -> 0.13171752 | F74: =IF(D74=1,SUMIFS('5 - Dati'!$E$6:$E$186,'5 - Dati'!$A$6:$A$186,Serie,'5 - Dati'!$B$6:$B$186,C74),Infl_c) -> 0.02154625 | G74: =(1+E74)*(1-Bollo_eff) -> 1.1294541 | H74: =H73/G73 -> 0.7048348 | I74: =1-Aliq_eff*MAX(0,1-H74) -> 0.92325705 | J74: =Spesa0 -> 38000 | K74: =J74/I74 -> 41158.635 | L74: =IF(K74>N74+0.000000001,1,0) -> 0 | M74: =MIN(K74,N74)*I74 -> 38000 | N74: =(N73-MIN(K73,N73))*G73/(1+F73) -> 688278.51 | O74: =Tasso0*S74*I74 -> 26006.674 | P74: =O74/I74 -> 28168.4 | Q74: =IF(P74>S74+0.000000001,1,0) -> 0 | R74: =MIN(P74,S74)*I74 -> 26006.674 | S74: =(S73-MIN(P73,S73))*G73/(1+F73) -> 694383.14 | T74: =MAX(Tasso0*X74*I74,Pav_pct*Spesa0) -> 34200 | U74: =T74/I74 -> 37042.772 | V74: =IF(U74>X74+0.000000001,1,0) -> 0 | W74: =MIN(U74,X74)*I74 -> 34200 | X74: =(X73-MIN(U73,X73))*G73/(1+F73) -> 692715.16 | Y74: =IF(Eta_rif_VPW-B74<=1,1,IF(r_VPW=0,1/(Eta_rif_VPW-B74),r_VPW/(1-(1+r_VPW)^(-(Eta_rif_VPW-B74)))/(1+r_VPW))) -> 0.03918693 | Z74: =Y74*AD74*I74 -> 25290.609 | AA74: =Z74/I74 -> 27392.815 | AB74: =IF(AA74>AD74+0.000000001,1,0) -> 0 | AC74: =MIN(AA74,AD74)*I74 -> 25290.609 | AD74: =(AD73-MIN(AA73,AD73))*G73/(1+F73) -> 699029.37 | AE74: =IF(OR(E73>=0,GK_variante=3),AG73,IF(GK_variante=2,AG73/(1+F73),IF(AK74*I74<=0,AG73/(1+F73),IF(AG73/(AK74*I74)>Tasso0,AG73/(1+F73),AG73)))) -> 36121.672 | AF74: =IF(AK74*I74<=0,9.9,AE74/(AK74*I74)) -> 0.056780488 | AG74: =IF(AND(AF74>Tasso0*(1+GK_banda),A74<=Anni-GK_ultimi),AE74*(1-GK_taglio),IF(AF74<Tasso0*(1-GK_banda),AE74*(1+GK_taglio),AE74)) -> 32509.505 | AH74: =AG74/I74 -> 35211.759 | AI74: =IF(AH74>AK74+0.000000001,1,0) -> 0 | AJ74: =MIN(AH74,AK74)*I74 -> 32509.505 | AK74: =(AK73-MIN(AH73,AK73))*G73/(1+F73) -> 689042.62 | AL74: =MIN(MAX(Tasso0*AP74*I74,AL73*(1+VG_pav)),AL73*(1+VG_tetto)) -> 35220.656 | AM74: =AL74/I74 -> 38148.267 | AN74: =IF(AM74>AP74+0.000000001,1,0) -> 0 | AO74: =MIN(AM74,AP74)*I74 -> 35220.656 | AP74: =(AP73-MIN(AM73,AP73))*G73/(1+F73) -> 690770.46 | AQ74: =IF(AND(A74<=Anni,M73>0),M74/M73-1,"") -> 0 | AR74: =IF(AND(A74<=Anni,R73>0),R74/R73-1,"") -> -0.19636911 | AS74: =IF(AND(A74<=Anni,W73>0),W74/W73-1,"") -> 0 | AT74: =IF(AND(A74<=Anni,AC73>0),AC74/AC73-1,"") -> -0.18678698 | AU74: =IF(AND(A74<=Anni,AJ73>0),AJ74/AJ73-1,"") -> -0.12509506 | AV74: =IF(AND(A74<=Anni,AO73>0),AO74/AO73-1,"") -> -0.025
A75: =A74+1 -> 5 | B75: =Eta_inizio+A75-1 -> 55 | C75: =Anno_inizio+A75-1 -> 2004 | D75: =IF(COUNTIFS('5 - Dati'!$A$6:$A$186,Serie,'5 - Dati'!$B$6:$B$186,C75)>0,1,0) -> 1 | E75: =IF(D75=1,SUMIFS('5 - Dati'!$F$6:$F$186,'5 - Dati'!$A$6:$A$186,Serie,'5 - Dati'!$B$6:$B$186,C75),(1+Rend_c)*(1+Infl_c)-1) -> 0.077222002 | F75: =IF(D75=1,SUMIFS('5 - Dati'!$E$6:$E$186,'5 - Dati'!$A$6:$A$186,Serie,'5 - Dati'!$B$6:$B$186,C75),Infl_c) -> 0.01985112 | G75: =(1+E75)*(1-Bollo_eff) -> 1.0750676 | H75: =H74/G74 -> 0.6240491 | I75: =1-Aliq_eff*MAX(0,1-H75) -> 0.90225277 | J75: =Spesa0 -> 38000 | K75: =J75/I75 -> 42116.801 | L75: =IF(K75>N75+0.000000001,1,0) -> 0 | M75: =MIN(K75,N75)*I75 -> 38000 | N75: =(N74-MIN(K74,N74))*G74/(1+F74) -> 715476.36 | O75: =Tasso0*S75*I75 -> 26959.76 | P75: =O75/I75 -> 29880.496 | Q75: =IF(P75>S75+0.000000001,1,0) -> 0 | R75: =MIN(P75,S75)*I75 -> 26959.76 | S75: =(S74-MIN(P74,S74))*G74/(1+F74) -> 736588.25 | T75: =MAX(Tasso0*X75*I75,Pav_pct*Spesa0) -> 34200 | U75: =T75/I75 -> 37905.121 | V75: =IF(U75>X75+0.000000001,1,0) -> 0 | W75: =MIN(U75,X75)*I75 -> 34200 | X75: =(X74-MIN(U74,X74))*G74/(1+F74) -> 724932.29 | Y75: =IF(Eta_rif_VPW-B75<=1,1,IF(r_VPW=0,1/(Eta_rif_VPW-B75),r_VPW/(1-(1+r_VPW)^(-(Eta_rif_VPW-B75)))/(1+r_VPW))) -> 0.039597258 | Z75: =Y75*AD75*I75 -> 26530.058 | AA75: =Z75/I75 -> 29404.242 | AB75: =IF(AA75>AD75+0.000000001,1,0) -> 0 | AC75: =MIN(AA75,AD75)*I75 -> 26530.058 | AD75: =(AD74-MIN(AA74,AD74))*G74/(1+F74) -> 742582.78 | AE75: =IF(OR(E74>=0,GK_variante=3),AG74,IF(GK_variante=2,AG74/(1+F74),IF(AK75*I75<=0,AG74/(1+F74),IF(AG74/(AK75*I75)>Tasso0,AG74/(1+F74),AG74)))) -> 32509.505 | AF75: =IF(AK75*I75<=0,9.9,AE75/(AK75*I75)) -> 0.049843229 | AG75: =IF(AND(AF75>Tasso0*(1+GK_banda),A75<=Anni-GK_ultimi),AE75*(1-GK_taglio),IF(AF75<Tasso0*(1-GK_banda),AE75*(1+GK_taglio),AE75)) -> 29258.554 | AH75: =AG75/I75 -> 32428.334 | AI75: =IF(AH75>AK75+0.000000001,1,0) -> 0 | AJ75: =MIN(AH75,AK75)*I75 -> 29258.554 | AK75: =(AK74-MIN(AH74,AK74))*G74/(1+F74) -> 722896.24 | AL75: =MIN(MAX(Tasso0*AP75*I75,AL74*(1+VG_pav)),AL74*(1+VG_tetto)) -> 34340.14 | AM75: =AL75/I75 -> 38060.443 | AN75: =IF(AM75>AP75+0.000000001,1,0) -> 0 | AO75: =MIN(AM75,AP75)*I75 -> 34340.14 | AP75: =(AP74-MIN(AM74,AP74))*G74/(1+F74) -> 721559.89 | AQ75: =IF(AND(A75<=Anni,M74>0),M75/M74-1,"") -> 0 | AR75: =IF(AND(A75<=Anni,R74>0),R75/R74-1,"") -> 0.036647742 | AS75: =IF(AND(A75<=Anni,W74>0),W75/W74-1,"") -> 0 | AT75: =IF(AND(A75<=Anni,AC74>0),AC75/AC74-1,"") -> 0.049008269 | AU75: =IF(AND(A75<=Anni,AJ74>0),AJ75/AJ74-1,"") -> -0.1 | AV75: =IF(AND(A75<=Anni,AO74>0),AO75/AO74-1,"") -> -0.025
...

Sheet 3 - Rendimento costante
A1: 3 - Rendimento costante: spesa pagata e capitale, anno per anno (euro di oggi)
A2: Strumento informativo / divulgativo. NON è consulenza finanziaria. I valori sono indicativi al 2026 e vanno verificati col tuo consulente.
A3: Risultati: spesa pagata (euro in cassa se «tassato», venduto lordo se «lordo») e capitale a inizio anno
A4: ="Rendimento reale costante "&TEXT(Rend_c,"0.00%")&" e inflazione "&TEXT(Infl_c,"0.00%")&" · nessun dato storico · modalità: "&Modalita -> Rendimento reale costante 003% e inflazione 002% · nessun dato storico · modalità: tassato
A5: t | B5: Età | C5: Anno | D5: Spesa pagata: Fisso indicizzato | E5: Spesa pagata: Percentuale costante | F5: Spesa pagata: Percentuale con pavimento | G5: Spesa pagata: Percentuale variabile | H5: Spesa pagata: Guardrail (senza tetto all'inflazione) | I5: Spesa pagata: Tetto e pavimento (+5% / −2,5%) | J5: Capitale inizio anno: Fisso indicizzato | K5: Capitale inizio anno: Percentuale costante | L5: Capitale inizio anno: Percentuale con pavimento | M5: Capitale inizio anno: Percentuale variabile | N5: Capitale inizio anno: Guardrail (senza tetto all'inflazione) | O5: Capitale inizio anno: Tetto e pavimento (+5% / −2,5%) | P5: Dato storico o ipotesi
A6: =A71 -> 1 | B6: =IF($A6>Anni,"",B71) -> 51 | C6: =IF($A6>Anni,"",C71) -> 2000 | D6: =IF($A6>Anni,"",M71) -> 38000 | E6: =IF($A6>Anni,"",R71) -> 38000 | F6: =IF($A6>Anni,"",W71) -> 38000 | G6: =IF($A6>Anni,"",AC71) -> 35662.76 | H6: =IF($A6>Anni,"",AJ71) -> 38000 | I6: =IF($A6>Anni,"",AO71) -> 38000 | J6: =IF($A6>Anni,"",N71) -> 1056000 | K6: =IF($A6>Anni,"",S71) -> 1056000 | L6: =IF($A6>Anni,"",X71) -> 1056000 | M6: =IF($A6>Anni,"",AD71) -> 1056000 | N6: =IF($A6>Anni,"",AK71) -> 1056000 | O6: =IF($A6>Anni,"",AP71) -> 1056000 | P6: =IF($A6>Anni,"",IF(D71=1,"osservato","ipotesi")) -> ipotesi
A7: =A72 -> 2 | B7: =IF($A7>Anni,"",B72) -> 52 | C7: =IF($A7>Anni,"",C72) -> 2001 | D7: =IF($A7>Anni,"",M72) -> 38000 | E7: =IF($A7>Anni,"",R72) -> 37189.737 | F7: =IF($A7>Anni,"",W72) -> 37189.737 | G7: =IF($A7>Anni,"",AC72) -> 35318.494 | H7: =IF($A7>Anni,"",AJ72) -> 38000 | I7: =IF($A7>Anni,"",AO72) -> 37189.737 | J7: =IF($A7>Anni,"",N72) -> 1041470 | K7: =IF($A7>Anni,"",S72) -> 1041470 | L7: =IF($A7>Anni,"",X72) -> 1041470 | M7: =IF($A7>Anni,"",AD72) -> 1044178.4 | N7: =IF($A7>Anni,"",AK72) -> 1041470 | O7: =IF($A7>Anni,"",AP72) -> 1041470 | P7: =IF($A7>Anni,"",IF(D72=1,"osservato","ipotesi")) -> ipotesi
A8: =A73 -> 3 | B8: =IF($A8>Anni,"",B73) -> 53 | C8: =IF($A8>Anni,"",C73) -> 2002 | D8: =IF($A8>Anni,"",M73) -> 38000 | E8: =IF($A8>Anni,"",R73) -> 36407.689 | F8: =IF($A8>Anni,"",W73) -> 36407.689 | G8: =IF($A8>Anni,"",AC73) -> 34988.062 | H8: =IF($A8>Anni,"",AJ73) -> 38000 | I8: =IF($A8>Anni,"",AO73) -> 36407.689 | J8: =IF($A8>Anni,"",N73) -> 1026193.7 | K8: =IF($A8>Anni,"",S73) -> 1027139.9 | L8: =IF($A8>Anni,"",X73) -> 1027139.9 | M8: =IF($A8>Anni,"",AD73) -> 1032109.1 | N8: =IF($A8>Anni,"",AK73) -> 1026193.7 | O8: =IF($A8>Anni,"",AP73) -> 1027139.9 | P8: =IF($A8>Anni,"",IF(D73=1,"osservato","ipotesi")) -> ipotesi
A9: =A74 -> 4 | B9: =IF($A9>Anni,"",B74) -> 54 | C9: =IF($A9>Anni,"",C74) -> 2003 | D9: =IF($A9>Anni,"",M74) -> 38000 | E9: =IF($A9>Anni,"",R74) -> 35652.454 | F9: =IF($A9>Anni,"",W74) -> 35652.454 | G9: =IF($A9>Anni,"",AC74) -> 34670.803 | H9: =IF($A9>Anni,"",AJ74) -> 38000 | I9: =IF($A9>Anni,"",AO74) -> 35652.454 | J9: =IF($A9>Anni,"",N74) -> 1010161.1 | K9: =IF($A9>Anni,"",S74) -> 1013007 | L9: =IF($A9>Anni,"",X74) -> 1013007 | M9: =IF($A9>Anni,"",AD74) -> 1019785.1 | N9: =IF($A9>Anni,"",AK74) -> 1010161.1 | O9: =IF($A9>Anni,"",AP74) -> 1013007 | P9: =IF($A9>Anni,"",IF(D74=1,"osservato","ipotesi")) -> ipotesi
A10: =A75 -> 5 | B10: =IF($A10>Anni,"",B75) -> 55 | C10: =IF($A10>Anni,"",C75) -> 2004 | D10: =IF($A10>Anni,"",M75) -> 38000 | E10: =IF($A10>Anni,"",R75) -> 34922.709 | F10: =IF($A10>Anni,"",W75) -> 34922.709 | G10: =IF($A10>Anni,"",AC75) -> 34366.089 | H10: =IF($A10>Anni,"",AJ75) -> 38000 | I10: =IF($A10>Anni,"",AO75) -> 34922.709 | J10: =IF($A10>Anni,"",N75) -> 993361.67 | K10: =IF($A10>Anni,"",S75) -> 999068.49 | L10: =IF($A10>Anni,"",X75) -> 999068.49 | M10: =IF($A10>Anni,"",AD75) -> 1007199.1 | N10: =IF($A10>Anni,"",AK75) -> 993361.67 | O10: =IF($A10>Anni,"",AP75) -> 999068.49 | P10: =IF($A10>Anni,"",IF(D75=1,"osservato","ipotesi")) -> ipotesi
A11: =A76 -> 6 | B11: =IF($A11>Anni,"",B76) -> 56 | C11: =IF($A11>Anni,"",C76) -> 2005 | D11: =IF($A11>Anni,"",M76) -> 38000 | E11: =IF($A11>Anni,"",R76) -> 34217.207 | F11: =IF($A11>Anni,"",W76) -> 34217.207 | G11: =IF($A11>Anni,"",AC76) -> 34073.32 | H11: =IF($A11>Anni,"",AJ76) -> 38000 | I11: =IF($A11>Anni,"",AO76) -> 34217.207 | J11: =IF($A11>Anni,"",N76) -> 975784.52 | K11: =IF($A11>Anni,"",S76) -> 985321.81 | L11: =IF($A11>Anni,"",X76) -> 985321.81 | M11: =IF($A11>Anni,"",AD76) -> 994343.65 | N11: =IF($A11>Anni,"",AK76) -> 975784.52 | O11: =IF($A11>Anni,"",AP76) -> 985321.81 | P11: =IF($A11>Anni,"",IF(D76=1,"osservato","ipotesi")) -> ipotesi
A12: =A77 -> 7 | B12: =IF($A12>Anni,"",B77) -> 57 | C12: =IF($A12>Anni,"",C77) -> 2006 | D12: =IF($A12>Anni,"",M77) -> 38000 | E12: =IF($A12>Anni,"",R77) -> 33534.772 | F12: =IF($A12>Anni,"",W77) -> 34200 | G12: =IF($A12>Anni,"",AC77) -> 33791.927 | H12: =IF($A12>Anni,"",AJ77) -> 38000 | I12: =IF($A12>Anni,"",AO77) -> 33534.772 | J12: =IF($A12>Anni,"",N77) -> 957418.21 | K12: =IF($A12>Anni,"",S77) -> 971764.28 | L12: =IF($A12>Anni,"",X77) -> 971764.28 | M12: =IF($A12>Anni,"",AD77) -> 981210.97 | N12: =IF($A12>Anni,"",AK77) -> 957418.21 | O12: =IF($A12>Anni,"",AP77) -> 971764.28 | P12: =IF($A12>Anni,"",IF(D77=1,"osservato","ipotesi")) -> ipotesi
A13: =A78 -> 8 | B13: =IF($A13>Anni,"",B78) -> 58 | C13: =IF($A13>Anni,"",C78) -> 2007 | D13: =IF($A13>Anni,"",M78) -> 38000 | E13: =IF($A13>Anni,"",R78) -> 32874.293 | F13: =IF($A13>Anni,"",W78) -> 34200 | G13: =IF($A13>Anni,"",AC78) -> 33521.367 | H13: =IF($A13>Anni,"",AJ78) -> 38000 | I13: =IF($A13>Anni,"",AO78) -> 32874.293 | J13: =IF($A13>Anni,"",N78) -> 938250.79 | K13: =IF($A13>Anni,"",S78) -> 958393.3 | L13: =IF($A13>Anni,"",X78) -> 957589.46 | M13: =IF($A13>Anni,"",AD78) -> 967793.19 | N13: =IF($A13>Anni,"",AK78) -> 938250.79 | O13: =IF($A13>Anni,"",AP78) -> 958393.3 | P13: =IF($A13>Anni,"",IF(D78=1,"osservato","ipotesi")) -> ipotesi
A14: =A79 -> 9 | B14: =IF($A14>Anni,"",B79) -> 59 | C14: =IF($A14>Anni,"",C79) -> 2008 | D14: =IF($A14>Anni,"",M79) -> 38000 | E14: =IF($A14>Anni,"",R79) -> 32234.722 | F14: =IF($A14>Anni,"",W79) -> 34200 | G14: =IF($A14>Anni,"",AC79) -> 33261.125 | H14: =IF($A14>Anni,"",AJ79) -> 34200 | I14: =IF($A14>Anni,"",AO79) -> 32234.722 | J14: =IF($A14>Anni,"",N79) -> 918269.8 | K14: =IF($A14>Anni,"",S79) -> 945206.29 | L14: =IF($A14>Anni,"",X79) -> 942768.37 | M14: =IF($A14>Anni,"",AD79) -> 954082.18 | N14: =IF($A14>Anni,"",AK79) -> 918269.8 | O14: =IF($A14>Anni,"",AP79) -> 945206.29 | P14: =IF($A14>Anni,"",IF(D79=1,"osservato","ipotesi")) -> ipotesi
A15: =A80 -> 10 | B15: =IF($A15>Anni,"",B80) -> 60 | C15: =IF($A15>Anni,"",C80) -> 2009 | D15: =IF($A15>Anni,"",M80) -> 38000 | E15: =IF($A15>Anni,"",R80) -> 31615.068 | F15: =IF($A15>Anni,"",W80) -> 34200 | G15: =IF($A15>Anni,"",AC80) -> 33010.708 | H15: =IF($A15>Anni,"",AJ80) -> 34200 | I15: =IF($A15>Anni,"",AO80) -> 31615.068 | J15: =IF($A15>Anni,"",N80) -> 897462.21 | K15: =IF($A15>Anni,"",S80) -> 932200.73 | L15: =IF($A15>Anni,"",X80) -> 927291.67 | M15: =IF($A15>Anni,"",AD80) -> 940069.59 | N15: =IF($A15>Anni,"",AK80) -> 902108.62 | O15: =IF($A15>Anni,"",AP80) -> 932200.73 | P15: =IF($A15>Anni,"",IF(D80=1,"osservato","ipotesi")) -> ipotesi
A16: =A81 -> 11 | B16: =IF($A16>Anni,"",B81) -> 61 | C16: =IF($A16>Anni,"",C81) -> 2010 | D16: =IF($A16>Anni,"",M81) -> 38000 | E16: =IF($A16>Anni,"",R81) -> 31014.399 | F16: =IF($A16>Anni,"",W81) -> 34200 | G16: =IF($A16>Anni,"",AC81) -> 32769.648 | H16: =IF($A16>Anni,"",AJ81) -> 34200 | I16: =IF($A16>Anni,"",AO81) -> 31014.399 | J16: =IF($A16>Anni,"",N81) -> 875814.41 | K16: =IF($A16>Anni,"",S81) -> 919374.12 | L16: =IF($A16>Anni,"",X81) -> 911149.6 | M16: =IF($A16>Anni,"",AD81) -> 925746.83 | N16: =IF($A16>Anni,"",AK81) -> 885262.93 | O16: =IF($A16>Anni,"",AP81) -> 919374.12 | P16: =IF($A16>Anni,"",IF(D81=1,"osservato","ipotesi")) -> ipotesi
A17: =A82 -> 12 | B17: =IF($A17>Anni,"",B82) -> 62 | C17: =IF($A17>Anni,"",C82) -> 2011 | D17: =IF($A17>Anni,"",M82) -> 38000 | E17: =IF($A17>Anni,"",R82) -> 30431.831 | F17: =IF($A17>Anni,"",W82) -> 34200 | G17: =IF($A17>Anni,"",AC82) -> 32537.501 | H17: =IF($A17>Anni,"",AJ82) -> 34200 | I17: =IF($A17>Anni,"",AO82) -> 30431.831 | J17: =IF($A17>Anni,"",N82) -> 853312.21 | K17: =IF($A17>Anni,"",S82) -> 906724 | L17: =IF($A17>Anni,"",X82) -> 894331.9 | M17: =IF($A17>Anni,"",AD82) -> 911105.06 | N17: =IF($A17>Anni,"",AK82) -> 867721.96 | O17: =IF($A17>Anni,"",AP82) -> 906724 | P17: =IF($A17>Anni,"",IF(D82=1,"osservato","ipotesi")) -> ipotesi
... A47: =A112 -> 42 | B47: =IF($A47>Anni,"",B112) -> 92 | C47: =IF($A47>Anni,"",C112) -> 2041 | D47: =IF($A47>Anni,"",M112) -> 0 | E47: =IF($A47>Anni,"",R112) -> 18474.109 | F47: =IF($A47>Anni,"",W112) -> 797.03326 | G47: =IF($A47>Anni,"",AC112) -> 28187.125 | H47: =IF($A47>Anni,"",AJ112) -> 22438.62 | I47: =IF($A47>Anni,"",AO112) -> 18474.109 | J47: =IF($A47>Anni,"",N112) -> 0 | K47: =IF($A47>Anni,"",S112) -> 598356.73 | L47: =IF($A47>Anni,"",X112) -> 1047.2157 | M47: =IF($A47>Anni,"",AD112) -> 267772.38 | N47: =IF($A47>Anni,"",AK112) -> 427955.64 | O47: =IF($A47>Anni,"",AP112) -> 598356.73 | P47: =IF($A47>Anni,"",IF(D112=1,"osservato","ipotesi")) -> ipotesi
A48: =A113 -> 43 | B48: =IF($A48>Anni,"",B113) | C48: =IF($A48>Anni,"",C113) | D48: =IF($A48>Anni,"",M113) | E48: =IF($A48>Anni,"",R113) | F48: =IF($A48>Anni,"",W113) | G48: =IF($A48>Anni,"",AC113) | H48: =IF($A48>Anni,"",AJ113) | I48: =IF($A48>Anni,"",AO113) | J48: =IF($A48>Anni,"",N113) | K48: =IF($A48>Anni,"",S113) | L48: =IF($A48>Anni,"",X113) | M48: =IF($A48>Anni,"",AD113) | N48: =IF($A48>Anni,"",AK113) | O48: =IF($A48>Anni,"",AP113) | P48: =IF($A48>Anni,"",IF(D113=1,"osservato","ipotesi")) | R48: Il grafico mostra i primi 42 anni (righe 6-47); la tabella a sinistra mostra l'intero piano.
A49: =A114 -> 44 | B49: =IF($A49>Anni,"",B114) | C49: =IF($A49>Anni,"",C114) | D49: =IF($A49>Anni,"",M114) | E49: =IF($A49>Anni,"",R114) | F49: =IF($A49>Anni,"",W114) | G49: =IF($A49>Anni,"",AC114) | H49: =IF($A49>Anni,"",AJ114) | I49: =IF($A49>Anni,"",AO114) | J49: =IF($A49>Anni,"",N114) | K49: =IF($A49>Anni,"",S114) | L49: =IF($A49>Anni,"",X114) | M49: =IF($A49>Anni,"",AD114) | N49: =IF($A49>Anni,"",AK114) | O49: =IF($A49>Anni,"",AP114) | P49: =IF($A49>Anni,"",IF(D114=1,"osservato","ipotesi"))
A50: =A115 -> 45 | B50: =IF($A50>Anni,"",B115) | C50: =IF($A50>Anni,"",C115) | D50: =IF($A50>Anni,"",M115) | E50: =IF($A50>Anni,"",R115) | F50: =IF($A50>Anni,"",W115) | G50: =IF($A50>Anni,"",AC115) | H50: =IF($A50>Anni,"",AJ115) | I50: =IF($A50>Anni,"",AO115) | J50: =IF($A50>Anni,"",N115) | K50: =IF($A50>Anni,"",S115) | L50: =IF($A50>Anni,"",X115) | M50: =IF($A50>Anni,"",AD115) | N50: =IF($A50>Anni,"",AK115) | O50: =IF($A50>Anni,"",AP115) | P50: =IF($A50>Anni,"",IF(D115=1,"osservato","ipotesi"))
A51: =A116 -> 46 | B51: =IF($A51>Anni,"",B116) | C51: =IF($A51>Anni,"",C116) | D51: =IF($A51>Anni,"",M116) | E51: =IF($A51>Anni,"",R116) | F51: =IF($A51>Anni,"",W116) | G51: =IF($A51>Anni,"",AC116) | H51: =IF($A51>Anni,"",AJ116) | I51: =IF($A51>Anni,"",AO116) | J51: =IF($A51>Anni,"",N116) | K51: =IF($A51>Anni,"",S116) | L51: =IF($A51>Anni,"",X116) | M51: =IF($A51>Anni,"",AD116) | N51: =IF($A51>Anni,"",AK116) | O51: =IF($A51>Anni,"",AP116) | P51: =IF($A51>Anni,"",IF(D116=1,"osservato","ipotesi"))
A52: =A117 -> 47 | B52: =IF($A52>Anni,"",B117) | C52: =IF($A52>Anni,"",C117) | D52: =IF($A52>Anni,"",M117) | E52: =IF($A52>Anni,"",R117) | F52: =IF($A52>Anni,"",W117) | G52: =IF($A52>Anni,"",AC117) | H52: =IF($A52>Anni,"",AJ117) | I52: =IF($A52>Anni,"",AO117) | J52: =IF($A52>Anni,"",N117) | K52: =IF($A52>Anni,"",S117) | L52: =IF($A52>Anni,"",X117) | M52: =IF($A52>Anni,"",AD117) | N52: =IF($A52>Anni,"",AK117) | O52: =IF($A52>Anni,"",AP117) | P52: =IF($A52>Anni,"",IF(D117=1,"osservato","ipotesi"))
A53: =A118 -> 48 | B53: =IF($A53>Anni,"",B118) | C53: =IF($A53>Anni,"",C118) | D53: =IF($A53>Anni,"",M118) | E53: =IF($A53>Anni,"",R118) | F53: =IF($A53>Anni,"",W118) | G53: =IF($A53>Anni,"",AC118) | H53: =IF($A53>Anni,"",AJ118) | I53: =IF($A53>Anni,"",AO118) | J53: =IF($A53>Anni,"",N118) | K53: =IF($A53>Anni,"",S118) | L53: =IF($A53>Anni,"",X118) | M53: =IF($A53>Anni,"",AD118) | N53: =IF($A53>Anni,"",AK118) | O53: =IF($A53>Anni,"",AP118) | P53: =IF($A53>Anni,"",IF(D118=1,"osservato","ipotesi"))
A54: =A119 -> 49 | B54: =IF($A54>Anni,"",B119) | C54: =IF($A54>Anni,"",C119) | D54: =IF($A54>Anni,"",M119) | E54: =IF($A54>Anni,"",R119) | F54: =IF($A54>Anni,"",W119) | G54: =IF($A54>Anni,"",AC119) | H54: =IF($A54>Anni,"",AJ119) | I54: =IF($A54>Anni,"",AO119) | J54: =IF($A54>Anni,"",N119) | K54: =IF($A54>Anni,"",S119) | L54: =IF($A54>Anni,"",X119) | M54: =IF($A54>Anni,"",AD119) | N54: =IF($A54>Anni,"",AK119) | O54: =IF($A54>Anni,"",AP119) | P54: =IF($A54>Anni,"",IF(D119=1,"osservato","ipotesi"))
A55: =A120 -> 50 | B55: =IF($A55>Anni,"",B120) | C55: =IF($A55>Anni,"",C120) | D55: =IF($A55>Anni,"",M120) | E55: =IF($A55>Anni,"",R120) | F55: =IF($A55>Anni,"",W120) | G55: =IF($A55>Anni,"",AC120) | H55: =IF($A55>Anni,"",AJ120) | I55: =IF($A55>Anni,"",AO120) | J55: =IF($A55>Anni,"",N120) | K55: =IF($A55>Anni,"",S120) | L55: =IF($A55>Anni,"",X120) | M55: =IF($A55>Anni,"",AD120) | N55: =IF($A55>Anni,"",AK120) | O55: =IF($A55>Anni,"",AP120) | P55: =IF($A55>Anni,"",IF(D120=1,"osservato","ipotesi"))
A56: =A121 -> 51 | B56: =IF($A56>Anni,"",B121) | C56: =IF($A56>Anni,"",C121) | D56: =IF($A56>Anni,"",M121) | E56: =IF($A56>Anni,"",R121) | F56: =IF($A56>Anni,"",W121) | G56: =IF($A56>Anni,"",AC121) | H56: =IF($A56>Anni,"",AJ121) | I56: =IF($A56>Anni,"",AO121) | J56: =IF($A56>Anni,"",N121) | K56: =IF($A56>Anni,"",S121) | L56: =IF($A56>Anni,"",X121) | M56: =IF($A56>Anni,"",AD121) | N56: =IF($A56>Anni,"",AK121) | O56: =IF($A56>Anni,"",AP121) | P56: =IF($A56>Anni,"",IF(D121=1,"osservato","ipotesi"))
A57: =A122 -> 52 | B57: =IF($A57>Anni,"",B122) | C57: =IF($A57>Anni,"",C122) | D57: =IF($A57>Anni,"",M122) | E57: =IF($A57>Anni,"",R122) | F57: =IF($A57>Anni,"",W122) | G57: =IF($A57>Anni,"",AC122) | H57: =IF($A57>Anni,"",AJ122) | I57: =IF($A57>Anni,"",AO122) | J57: =IF($A57>Anni,"",N122) | K57: =IF($A57>Anni,"",S122) | L57: =IF($A57>Anni,"",X122) | M57: =IF($A57>Anni,"",AD122) | N57: =IF($A57>Anni,"",AK122) | O57: =IF($A57>Anni,"",AP122) | P57: =IF($A57>Anni,"",IF(D122=1,"osservato","ipotesi"))
A58: =A123 -> 53 | B58: =IF($A58>Anni,"",B123) | C58: =IF($A58>Anni,"",C123) | D58: =IF($A58>Anni,"",M123) | E58: =IF($A58>Anni,"",R123) | F58: =IF($A58>Anni,"",W123) | G58: =IF($A58>Anni,"",AC123) | H58: =IF($A58>Anni,"",AJ123) | I58: =IF($A58>Anni,"",AO123) | J58: =IF($A58>Anni,"",N123) | K58: =IF($A58>Anni,"",S123) | L58: =IF($A58>Anni,"",X123) | M58: =IF($A58>Anni,"",AD123) | N58: =IF($A58>Anni,"",AK123) | O58: =IF($A58>Anni,"",AP123) | P58: =IF($A58>Anni,"",IF(D123=1,"osservato","ipotesi"))
A59: =A124 -> 54 | B59: =IF($A59>Anni,"",B124) | C59: =IF($A59>Anni,"",C124) | D59: =IF($A59>Anni,"",M124) | E59: =IF($A59>Anni,"",R124) | F59: =IF($A59>Anni,"",W124) | G59: =IF($A59>Anni,"",AC124) | H59: =IF($A59>Anni,"",AJ124) | I59: =IF($A59>Anni,"",AO124) | J59: =IF($A59>Anni,"",N124) | K59: =IF($A59>Anni,"",S124) | L59: =IF($A59>Anni,"",X124) | M59: =IF($A59>Anni,"",AD124) | N59: =IF($A59>Anni,"",AK124) | O59: =IF($A59>Anni,"",AP124) | P59: =IF($A59>Anni,"",IF(D124=1,"osservato","ipotesi"))
A60: =A125 -> 55 | B60: =IF($A60>Anni,"",B125) | C60: =IF($A60>Anni,"",C125) | D60: =IF($A60>Anni,"",M125) | E60: =IF($A60>Anni,"",R125) | F60: =IF($A60>Anni,"",W125) | G60: =IF($A60>Anni,"",AC125) | H60: =IF($A60>Anni,"",AJ125) | I60: =IF($A60>Anni,"",AO125) | J60: =IF($A60>Anni,"",N125) | K60: =IF($A60>Anni,"",S125) | L60: =IF($A60>Anni,"",X125) | M60: =IF($A60>Anni,"",AD125) | N60: =IF($A60>Anni,"",AK125) | O60: =IF($A60>Anni,"",AP125) | P60: =IF($A60>Anni,"",IF(D125=1,"osservato","ipotesi"))
... A65: =A130 -> 60 | B65: =IF($A65>Anni,"",B130) | C65: =IF($A65>Anni,"",C130) | D65: =IF($A65>Anni,"",M130) | E65: =IF($A65>Anni,"",R130) | F65: =IF($A65>Anni,"",W130) | G65: =IF($A65>Anni,"",AC130) | H65: =IF($A65>Anni,"",AJ130) | I65: =IF($A65>Anni,"",AO130) | J65: =IF($A65>Anni,"",N130) | K65: =IF($A65>Anni,"",S130) | L65: =IF($A65>Anni,"",X130) | M65: =IF($A65>Anni,"",AD130) | N65: =IF($A65>Anni,"",AK130) | O65: =IF($A65>Anni,"",AP130) | P65: =IF($A65>Anni,"",IF(D130=1,"osservato","ipotesi"))
A68: Motore del calcolo, non modificare
A69: Anno e rendimenti | J69: Fisso indicizzato | O69: Percentuale costante | T69: Percentuale con pavimento | Y69: Percentuale variabile | AE69: Guardrail (senza tetto all'inflazione) | AL69: Tetto e pavimento | AQ69: Cambio % annuo della spesa pagata
A70: t | B70: Età | C70: Anno | D70: Dato storico (1/0) | E70: Rendimento nominale 60/40 | F70: Inflazione | G70: Fattore nominale dopo bollo (g) | H70: Base di costo / valore (k) | I70: Quota netta del venduto (q) | J70: Fisso: pianificata | K70: Fisso: venduto | L70: Fisso: esaurimento | M70: Fisso: pagata | N70: Fisso: capitale (W) | O70: Perc. costante: pianificata | P70: Perc. costante: venduto | Q70: Perc. costante: esaurimento | R70: Perc. costante: pagata | S70: Perc. costante: capitale (W) | T70: Perc. con pav.: pianificata | U70: Perc. con pav.: venduto | V70: Perc. con pav.: esaurimento | W70: Perc. con pav.: pagata | X70: Perc. con pav.: capitale (W) | Y70: Perc. variabile: percentuale | Z70: Perc. variabile: pianificata | AA70: Perc. variabile: venduto | AB70: Perc. variabile: esaurimento | AC70: Perc. variabile: pagata | AD70: Perc. variabile: capitale (W) | AE70: Guardrail: prima della regola | AF70: Guardrail: tasso corrente | AG70: Guardrail: pianificata | AH70: Guardrail: venduto | AI70: Guardrail: esaurimento | AJ70: Guardrail: pagata | AK70: Guardrail: capitale (W) | AL70: Tetto e pav.: pianificata | AM70: Tetto e pav.: venduto | AN70: Tetto e pav.: esaurimento | AO70: Tetto e pav.: pagata | AP70: Tetto e pav.: capitale (W) | AQ70: Cambio % fisso | AR70: Cambio % perc. costante | AS70: Cambio % perc. con pav. | AT70: Cambio % perc. variabile | AU70: Cambio % guardrail | AV70: Cambio % tetto e pav.
