Workbook

Sheet 0 - Indice
A1: Marco FIRE — Il tuo tasso vero: SWR, cedole e il ponte (2026)
A2: Strumento informativo / divulgativo. NON è consulenza finanziaria. I valori sono indicativi al 2026 e vanno verificati col tuo consulente.
A4: Indice
A5: 1 - Il tuo tasso vero | B5: I quattro tassi: quello che ti racconti, quello sulla spesa, quello vero, e quello confrontabile col 4% storico
A6: 2 - Quanto costa il canale | B6: Quanto costa ogni canale di incasso, il break-even al 48,08% e il contatore dello zainetto di minusvalenze
A7: 3 - Il ponte | B7: Il motore del ponte anno per anno, i tre scenari a 67 anni e il capitale necessario lordizzato
A8: 4 - Cedole contro total return | B8: L'identita' dei due modi di contare, e quanto costa pagare l'imposta in anticipo a parita' di aliquota
A9: 5 - Sequenza | B9: Lo stesso multiset di rendimenti in due ordini: quanto costa l'ordine
A11: Come usare
A12: 1. Le celle GIALLE sono input — modificale coi tuoi numeri.
A13: 2. Le celle VERDI sono output — si aggiornano automaticamente.
A14: 3. Tutti i numeri di default sono al 2026 da fonti pubbliche.
A15: 4. Niente codice nascosto: l'Excel è solo formule modificabili.
A17: Fonti dati
A18: • MEF - Dipartimento del Tesoro, comunicato del 6 marzo 2026: BTP Valore ISIN IT0005696320, tassi DEFINITIVI 2,60% (anni 1-2), 3,20% (3-4), 3,80% (5-6), cedole trimestrali, premio fedelta' 0,8%, scadenza 10/03/2032. Rendimento vero a scadenza 3,336% lordo e 2,919% netto
A19: • D.L. 66/2014 art. 3 (conv. L. 89/2014): 26% su plusvalenze, dividendi e proventi di fondi; 12,5% su titoli di Stato ed emittenti white list; i redditi diversi da titoli di Stato rilevano nella misura del 48,08%. Da qui il break-even: 0,26 x q = 0,125 da' q = 48,077%
A20: • D.P.R. 600/1973 art. 26-quinquies c. 3: sulle quote di ETF e OICR l'imposta colpisce la sola plusvalenza, col costo medio ponderato
A21: • TUIR art. 67 e art. 68 c. 5, D.Lgs. 461/1997 art. 6 c. 5: le minusvalenze sono redditi diversi, riportabili nell'anno di realizzo e nei quattro successivi, e NON compensano cedole e dividendi, che sono redditi di capitale (art. 44 TUIR)
A22: • Imposta di bollo sui prodotti finanziari: 0,2% annuo, applicata qui al patrimonio di FINE anno (anno 1: 1.862 € su 931.139 €)
A23: • Cooley, Hubbard, Walz, «Retirement Savings: Choosing a Withdrawal Rate That Is Sustainable», AAII Journal, febbraio 1998 (Trinity Study). Testuale nel paper: «The study did not adjust for taxes or transaction costs» — per questo il termine omogeneo col 4% e' il 3,47%, non il 3,67%
... A27: Aggiornamenti: github.com/marcofire-it/marco-fire-simulatori

Sheet 1 - Il tuo tasso vero
A1: Il tuo tasso vero — i quattro numeri, in trenta secondi
A2: Strumento informativo / divulgativo. NON è consulenza finanziaria. I valori sono indicativi al 2026 e vanno verificati col tuo consulente.
A3: Tre numeri in giallo e il foglio ti dice quanto stai prelevando davvero. Il tasso che ti racconti conta solo la parte di spesa che NON e' coperta dalle cedole; il tasso vero conta tutto quello che esce dal portafoglio per farti spendere quella cifra, imposte e bollo compresi. Sono lo stesso portafoglio e la stessa spesa: cambia solo il modo di contarli.
A5: I TUOI NUMERI — cambia solo le celle gialle
A6: Patrimonio totale investito | B6: 920000 | D6: Il caso del video: 450.000 di azionario, 320.000 di BTP Valore, 80.000 di certificati, 70.000 di monetario.
A7: Spesa netta annua che ti serve | B7: 30000 | D7: Quello che ti serve davvero in tasca in un anno, non quello che incassi.
A8: Cedole, dividendi e premi NETTI incassati | B8: 15000 | D8: Il flusso che arriva in conto con la ritenuta gia' pagata.
A9: Plusvalenza latente sulle quote da vendere | B9: 0.2 | D9: Quanta parte del valore delle quote e' guadagno non ancora realizzato. Se hai comprato a 80 e oggi vale 100, e' il 20%.
A10: Aliquota media sulle cedole che incassi | B10: 0.0706522 | D10: Nel caso del video vale 7,07%: le cedole del BTP Valore pagano il 12,5%, ma i premi dei certificati sono azzerati dallo zainetto di minusvalenze finche' dura (1.040 € di imposta su 14.720 € di cedole lorde). Se incassi solo cedole di titoli di Stato scrivi 12,5%; se sono dividendi, 26%.
A11: Aliquota sulle plusvalenze | B11: 0.26 | D11: 26% sulla sola plusvalenza, calcolata col costo medio ponderato (D.P.R. 600/1973 art. 26-quinquies).
A12: Imposta di bollo sui prodotti finanziari | B12: 0.002 | D12: 0,2% annuo del valore. E' un costo, non un prelievo: per questo ha una cella sua e resta fuori dal confronto col 4% storico.
A14: I QUATTRO TASSI
A15: Tasso che ti racconti | B15: =($B$7-$B$8)/$B$6 | D15: (spesa netta meno cedole) diviso patrimonio. E' l'etichetta: conta solo il pezzo di spesa che le cedole non coprono, come se le cedole fossero denaro caduto dal cielo. Nel caso del video: 1,63%.
A16: Tasso sulla spesa | B16: =$B$7/$B$6 | D16: spesa netta diviso patrimonio. E' il conto che torna, ed e' gia' il doppio dell'etichetta. Nel caso del video: 3,26%.
A17: TASSO VERO DI USCITA (imposte e bollo) | B17: =($B$21+$B$24+$B$25)/$B$6 | D17: tutto quello che esce dal portafoglio per farti spendere quella cifra: cedole LORDE, vendita LORDA di quote e imposta di bollo. Nel caso del video: 3,67%. E' il numero-titolo.
A18: Confrontabile con il 4% storico (senza bollo) | B18: =($B$21+$B$24)/$B$6 | D18: Il Trinity Study del 1998 dice testualmente «the study did not adjust for taxes or transaction costs»: il bollo li' non c'e'. Il termine omogeneo col 4% e' questo, 3,47%, non il 3,67%.
A20: DA DOVE VENGONO — la cascata dell'anno 1
A21: Cedole LORDE che il portafoglio stacca | B21: =$B$8/(1-$B$10) | D21: Le cedole nette che incassi, rilordizzate: e' quello che il portafoglio ha davvero pagato, ritenuta compresa.
A22: Fabbisogno da coprire vendendo quote | B22: =$B$7-$B$8
A23: Aliquota effettiva sulla vendita | B23: =$B$11*$B$9 | D23: 26% sulla sola plusvalenza: col 20% latente sono il 5,2% dell'importo venduto. E' il numero che rende la vendita di quote piu' efficiente della cedola sotto il 48,08% di plusvalenza latente (foglio 2).
A24: Vendita LORDA di quote | B24: =$B$22/(1-$B$23)
A25: Imposta di bollo in euro | B25: =$B$12*$B$6
A26: USCITA TOTALE DAL PORTAFOGLIO | B26: =$B$21+$B$24+$B$25 | D26: Il costo pieno di essere investita in Italia.
A27: di cui, senza il bollo | B27: =$B$21+$B$24
A29: Una nota di onesta' sul foglio: qui la cascata usa i 15.000 € netti tondi dichiarati dal caso, mentre il modello del foglio 3 calcola le cedole anno per anno e per l'anno 1 trova 13.680 € netti su 14.720 € lordi. La differenza sull'uscita totale e' di 28 € su 33.800, e non sposta nessuno dei quattro tassi al secondo decimale.
A30: Se il tasso vero e' piu' alto di quello che ti raccontavi, non e' successo niente di grave: e' successo che adesso lo sai, e puoi fare la verifica che con l'etichetta non avresti mai fatto. Il foglio 3 la fa.

Sheet 2 - Quanto costa il canale
A1: Quanto costa il canale — la classifica dei modi di incassare
A2: Strumento informativo / divulgativo. NON è consulenza finanziaria. I valori sono indicativi al 2026 e vanno verificati col tuo consulente.
A3: La domanda di questo foglio e' «quale strumento tengo in portafoglio», non «da dove prelevo». Sono due domande diverse e hanno due risposte diverse: la seconda e' nel riquadro in fondo.
A5: IL TUO CASO
A6: Importo NETTO che ti serve incassare | B6: 15000 | G6: Nel video sono i 15.000 € netti che coprono meta' della spesa di Elena.
A7: Aliquota su dividendi, premi e plusvalenze | B7: 0.26 | G7: D.L. 66/2014 art. 3 c. 1.
A8: Aliquota su titoli di Stato e white list | B8: 0.125 | G8: D.L. 66/2014 art. 3 c. 2: i redditi diversi da titoli di Stato rilevano nella misura del 48,08%, che e' esattamente 12,5 / 26.
A10: LA CLASSIFICA — quanto devi smobilizzare per averne 15.000 netti
A11: Canale di incasso | B11: Plusvalenza latente | C11: Aliquota effettiva | D11: Lordo da smobilizzare | E11: Imposta pagata
A12: Vendita di quote ETF, plusvalenza latente 10% | B12: 0.1 | C12: =$B$7*$B12 | D12: =$B$6/(1-$C12) | E12: =$D12-$B$6
A13: Vendita di quote ETF, plusvalenza latente 20% | B13: 0.2 | C13: =$B$7*$B13 | D13: =$B$6/(1-$C13) | E13: =$D13-$B$6
A14: Vendita di quote ETF, plusvalenza latente 30% | B14: 0.3 | C14: =$B$7*$B14 | D14: =$B$6/(1-$C14) | E14: =$D14-$B$6
A15: CEDOLE BTP e titoli di Stato — il pareggio | B15: =$B$8/$B$7 | C15: =$B$8 | D15: =$B$6/(1-$C15) | E15: =$D15-$B$6
A16: Vendita di quote ETF, plusvalenza latente 80% | B16: 0.8 | C16: =$B$7*$B16 | D16: =$B$6/(1-$C16) | E16: =$D16-$B$6
A17: Dividendi, o premi senza minusvalenze in capienza | B17: — | C17: =$B$7 | D17: =$B$6/(1-$C17) | E17: =$D17-$B$6
A18: La riga gialla e' il pareggio: la cedola di un titolo di Stato costa il 12,5% dell'INTERO flusso, la vendita di quote costa il 26% della sola plusvalenza. Sopra la riga gialla la cedola conviene, sotto conviene vendere quote — e sotto ci stanno quasi tutti.
A20: IL BREAK-EVEN — sopra quanta plusvalenza la cedola conviene
A21: Plusvalenza latente che pareggia la cedola | B21: =$B$8/$B$7 | G21: 0,26 x q = 0,125 da' q = 48,077%. E' la stessa frazione con cui il D.L. 66/2014 abbatte la base imponibile dei titoli di Stato: la stessa divisione, fatta due volte.
A22: Sotto il 48,08% di plusvalenza latente la cedola gia' incassata ti e' costata piu' di quanto ti sarebbe costato vendere quote per lo stesso importo. E' un costo di DETENZIONE: lo paghi ogni anno per il fatto di possedere quello strumento, anche negli anni in cui la cassa non ti serve.
A24: FUORI CLASSIFICA — i premi dei certificati finche' dura la minusvalenza
A25: Questa riga non entra in classifica perche' non e' una proprieta' dello strumento: e' una condizione temporanea, che finisce quando lo zainetto di minusvalenze si esaurisce. Le minusvalenze sono redditi diversi e si riportano nell'anno di realizzo e nei QUATTRO successivi (art. 68 c. 5 TUIR); i premi condizionati dei certificati sono anch'essi redditi diversi, e quindi li assorbono.
A26: Premi dei certificati con minusvalenza in capienza | B26: temporaneo | C26: =0 | D26: =$B$6 | E26: =$D$26-$B$6
A28: Zainetto di minusvalenze da smaltire | B28: 10000 | G28: Dato del caso del video.
A29: Premi lordi dei certificati in un anno | B29: 6400 | G29: 8% su 80.000 €: ipotesi dichiarata, forbice 6-10%.
A30: Risparmio fiscale massimo — IN TUTTO, non all'anno | B30: =$B$7*$B$28 | G30: 26% x 10.000 = 2.600 €, una volta sola: 28 punti base sul patrimonio del caso. Manovra di smaltimento, non pilastro.
A31: Anni per assorbirlo, ai premi dichiarati | B31: =$B$28/$B$29
A32: Se la minusvalenza venisse da titoli di Stato (48,08%) | B32: =$B$7*($B$8/$B$7)*$B$28
A34: Anno | B34: Minusvalenza residua a inizio anno | C34: Premi compensati | D34: Imposta risparmiata | E34: Residua a fine anno
A35: 1 | B35: =$B$28 | C35: =MIN($B35,$B$29) | D35: =$C35*$B$7 | E35: =$B35-$C35
A36: 2 | B36: =$E35 | C36: =MIN($B36,$B$29) | D36: =$C36*$B$7 | E36: =$B36-$C36
A37: 3 | B37: =$E36 | C37: =MIN($B37,$B$29) | D37: =$C37*$B$7 | E37: =$B37-$C37
A38: 4 | B38: =$E37 | C38: =MIN($B38,$B$29) | D38: =$C38*$B$7 | E38: =$B38-$C38
A39: 5 | B39: =$E38 | C39: =MIN($B39,$B$29) | D39: =$C39*$B$7 | E39: =$B39-$C39
A40: Dopo un anno e mezzo il contatore e' a zero e i certificati restano li', con i premi al 26% pieno e il capitale non garantito a scadenza. Il vantaggio fiscale era vero, ed era piccolo e a termine.
A42: DOMANDA B — da dove prelevo, dato il portafoglio che ho
A43: 1. La classifica qui sopra risponde alla domanda «quale strumento tengo». Se la domanda e' invece «da dove prelevo, dato il portafoglio che ho gia'», la risposta si ribalta: la cedola gia' incassata ha costo marginale fiscale ZERO.
A44: 2. La ritenuta e' stata trattenuta comunque e la cedola e' arrivata comunque. Non spenderla e vendere altro al suo posto significa pagare DUE imposte sullo stesso euro di spesa: quella gia' pagata sulla cedola e quella nuova sulla plusvalenza della vendita.
A45: 3. La sintesi che tiene insieme le due domande: il costo fiscale della cedola e' un costo di DETENZIONE, non di prelievo. La domanda giusta non e' «da dove prelevo» — su quella la risposta era gia' corretta — ma «quanto mi costa, ogni anno, avere un portafoglio che mi consegna denaro che non ho chiesto».

Sheet 3 - Il ponte
A1: Il ponte — dieci anni misurati anno per anno
A2: Strumento informativo / divulgativo. NON è consulenza finanziaria. I valori sono indicativi al 2026 e vanno verificati col tuo consulente.
A3: Questo modello tratta il portafoglio come un blocco unico con un unico rendimento. Nella realta' una parte scade e va reinvestita, e strumenti diversi si comportano diversamente nei crolli: il modello serve a misurare i flussi e le imposte, non a premiare un'allocazione. Le uniche eccezioni sono lo schedario cedolare del BTP Valore, il premio fedelta' e il reinvestimento all'anno di rimborso, che sono espliciti.
A5: PARAMETRI DEL MODELLO — cambia solo le celle gialle
A6: Patrimonio iniziale | B6: 920000 | D6: Dato del caso.
A7: Spesa netta dell'anno 1 | B7: 30000 | D7: Indicizzata all'inflazione negli anni successivi.
A8: Inflazione | B8: 0.02 | D8: Ipotesi del modello.
A9: Rendimento reale — scenario centrale | B9: 0.03 | D9: Ipotesi dichiarata, non previsione. Il conto bottom-up sul portafoglio del caso da' 3,02-3,34% reale lordo: il 3% e' il pavimento della forbice.
A10: Rendimento reale — scenario prudente | B10: 0.01 | D10: La banda dichiarata e' 1% / 3%, piu' i due ordinamenti di sequenza del foglio 5. Non esiste uno scenario al 5%.
A11: Durata del ponte (anni) | B11: 10 | D11: Da 57 a 67 anni. Il motore ha dieci righe: per cambiare durata vanno aggiunte o tolte righe.
A12: Plusvalenza latente iniziale | B12: 0.2 | D12: Ipotesi dichiarata.
A13: Aliquota sulle plusvalenze | B13: 0.26 | D13: Sulla sola plusvalenza, a costo medio ponderato.
A14: Aliquota su cedole BTP e premio fedelta' | B14: 0.125
A15: Aliquota sui premi dei certificati | B15: 0.26 | D15: Redditi diversi: compensano le minusvalenze.
A16: Imposta di bollo | B16: 0.002 | D16: 0,2% del patrimonio di FINE anno, applicata a fine anno. Anno 1: 1.862 €.
A17: BTP Valore — capitale nominale | B17: 320000 | D17: ISIN IT0005696320, godimento 10/03/2026, scadenza 10/03/2032.
A18: cedola anni 1-2 | B18: 0.026 | D18: MEF, comunicato del 6 marzo 2026: tassi DEFINITIVI, rivisti al rialzo.
A19: cedola anni 3-4 | B19: 0.032
A20: cedola anni 5-6 | B20: 0.038 | D20: Cedola finale 3,80%, rendimento vero a scadenza 3,336% lordo e 2,919% netto: lo step-up e' marketing di flusso.
A21: premio fedelta' | B21: 0.008 | D21: 0,8% a chi sottoscrive in collocamento e tiene a scadenza. Vale 12 punti base l'anno: sembra grande perche' non e' annualizzato.
A22: anno di rimborso del titolo | B22: 6 | D22: Il rimborso alla pari di 320.000 € dentro l'orizzonte e' 34,8 punti di patrimonio: e' la vera difesa dalla sequenza, e non viene dalle cedole.
A23: tasso di reinvestimento dall'anno successivo | B23: 0.03 | D23: Sensibilita': da 1,5% a 4,0% il capitale finale cambia di 851 € su 817.000, con segno NEGATIVO. Nel modello una cedola piu' alta non aggiunge rendimento: sposta reddito verso un canale piu' tassato.
A24: Certificati — capitale nominale | B24: 80000
A25: premi condizionati | B25: 0.08 | D25: Ipotesi dichiarata, forbice 6-10%. Da questa cella dipende la quota di flusso prodotta dai certificati: fra il 28% e il 49% secondo l'ipotesi e il biennio.
A26: Zainetto di minusvalenze | B26: 10000 | D26: Si consuma sui premi dei certificati, come nel foglio 2.
A28: SCHEDARIO CEDOLARE — i tassi definitivi, anno per anno
A29: Anno | B29: Cedola BTP Valore lorda | C29: Premio fedelta' | D29: Premi dei certificati | E29: CEDOLE LORDE TOTALI
A30: 1 | B30: =IF(1<=2,$B$17*$B$18,IF(1<=4,$B$17*$B$19,IF(1<=$B$22,$B$17*$B$20,$B$17*$B$23))) | C30: =IF(1=$B$22,$B$17*$B$21,0) | D30: =$B$24*$B$25 | E30: =$B30+$C30+$D30
A31: 2 | B31: =IF(2<=2,$B$17*$B$18,IF(2<=4,$B$17*$B$19,IF(2<=$B$22,$B$17*$B$20,$B$17*$B$23))) | C31: =IF(2=$B$22,$B$17*$B$21,0) | D31: =$B$24*$B$25 | E31: =$B31+$C31+$D31
A32: 3 | B32: =IF(3<=2,$B$17*$B$18,IF(3<=4,$B$17*$B$19,IF(3<=$B$22,$B$17*$B$20,$B$17*$B$23))) | C32: =IF(3=$B$22,$B$17*$B$21,0) | D32: =$B$24*$B$25 | E32: =$B32+$C32+$D32
A33: 4 | B33: =IF(4<=2,$B$17*$B$18,IF(4<=4,$B$17*$B$19,IF(4<=$B$22,$B$17*$B$20,$B$17*$B$23))) | C33: =IF(4=$B$22,$B$17*$B$21,0) | D33: =$B$24*$B$25 | E33: =$B33+$C33+$D33
A34: 5 | B34: =IF(5<=2,$B$17*$B$18,IF(5<=4,$B$17*$B$19,IF(5<=$B$22,$B$17*$B$20,$B$17*$B$23))) | C34: =IF(5=$B$22,$B$17*$B$21,0) | D34: =$B$24*$B$25 | E34: =$B34+$C34+$D34
A35: 6 | B35: =IF(6<=2,$B$17*$B$18,IF(6<=4,$B$17*$B$19,IF(6<=$B$22,$B$17*$B$20,$B$17*$B$23))) | C35: =IF(6=$B$22,$B$17*$B$21,0) | D35: =$B$24*$B$25 | E35: =$B35+$C35+$D35
A36: 7 | B36: =IF(7<=2,$B$17*$B$18,IF(7<=4,$B$17*$B$19,IF(7<=$B$22,$B$17*$B$20,$B$17*$B$23))) | C36: =IF(7=$B$22,$B$17*$B$21,0) | D36: =$B$24*$B$25 | E36: =$B36+$C36+$D36
A37: 8 | B37: =IF(8<=2,$B$17*$B$18,IF(8<=4,$B$17*$B$19,IF(8<=$B$22,$B$17*$B$20,$B$17*$B$23))) | C37: =IF(8=$B$22,$B$17*$B$21,0) | D37: =$B$24*$B$25 | E37: =$B37+$C37+$D37
A38: 9 | B38: =IF(9<=2,$B$17*$B$18,IF(9<=4,$B$17*$B$19,IF(9<=$B$22,$B$17*$B$20,$B$17*$B$23))) | C38: =IF(9=$B$22,$B$17*$B$21,0) | D38: =$B$24*$B$25 | E38: =$B38+$C38+$D38
A39: 10 | B39: =IF(10<=2,$B$17*$B$18,IF(10<=4,$B$17*$B$19,IF(10<=$B$22,$B$17*$B$20,$B$17*$B$23))) | C39: =IF(10=$B$22,$B$17*$B$21,0) | D39: =$B$24*$B$25 | E39: =$B39+$C39+$D39
A41: IL PONTE — scenario centrale (rendimento reale della cella B9)
A42: Anno | B42: Spesa netta dell'anno | C42: Cedole lorde | D42: Imposta 12,5% su BTP e premio | E42: Zainetto minus. a inizio anno | F42: Imposta 26% sui premi | G42: Cedole nette | H42: Da coprire vendendo | I42: Plusvalenza latente | J42: Aliquota eff. sulla vendita | K42: Vendita lorda | L42: Uscita lorda (cedole+vendita) | M42: Rendimento reale | N42: Patrimonio prima del bollo | O42: Imposta di bollo | P42: Patrimonio a fine anno | Q42: USCITA TOTALE col bollo | R42: Costo fiscale a fine anno | S42: Patrimonio in euro di oggi
A43: 1 | B43: =$B$7*(1+$B$8)^(1-1) | C43: =$E$30 | D43: =($B$30+$C$30)*$B$14 | E43: =$B$26 | F43: =MAX(0,$D$30-E43)*$B$15 | G43: =C43-D43-F43 | H43: =B43-G43 | I43: =1-($B$6*(1-$B$12))/$B$6 | J43: =$B$13*I43 | K43: =H43/(1-J43) | L43: =C43+K43 | M43: =$B$9 | N43: =($B$6-L43)*(1+M43)*(1+$B$8) | O43: =N43-P43 | P43: =N43/(1+$B$16) | Q43: =L43+O43 | R43: =($B$6*(1-$B$12))-K43*($B$6*(1-$B$12))/$B$6 | S43: =P43/(1+$B$8)^1
...

Sheet 4 - Cedole contro total return
A1: Contabilita' a cedole contro total return
A2: Strumento informativo / divulgativo. NON è consulenza finanziaria. I valori sono indicativi al 2026 e vanno verificati col tuo consulente.
A3: Le prime due colonne sono IDENTICHE, e non e' un risultato: e' un'identita' del modello. A parita' di portafoglio, il modo di contare non cambia un euro dei flussi. Cambia quello che il framing ti induce a fare: quale portafoglio costruisci, quale domanda ti poni, quanto spendi quando il budget si allarga.
A5: GLI STESSI FLUSSI, DUE MODI DI CONTARLI
A6: Voce | B6: Contabilita' a cedole | C6: Total return | D6: Differenza
A7: Come descrive il prelievo | B7: «prelevo 15.000: il mio SWR e' 1,63%» | C7: «il portafoglio mi consegna 30.000: 3,26%»
A8: Tasso che dichiara | B8: ='1 - Il tuo tasso vero'!$B$15 | C8: ='1 - Il tuo tasso vero'!$B$16 | D8: l'unica cosa che cambia
A9: Spesa netta dell'anno 1 | B9: ='3 - Il ponte'!$B$43 | C9: ='3 - Il ponte'!$B$43 | D9: =$C9-$B9
A10: Uscita lorda dal portafoglio | B10: ='3 - Il ponte'!$L$43 | C10: ='3 - Il ponte'!$L$43 | D10: =$C10-$B10
A11: Uscita totale con il bollo | B11: ='3 - Il ponte'!$Q$43 | C11: ='3 - Il ponte'!$Q$43 | D11: =$C11-$B11
A12: Capitale a 67 anni, 3% reale | B12: ='3 - Il ponte'!$B$70 | C12: ='3 - Il ponte'!$B$70 | D12: =$C12-$B12
A13: Capitale a 67 anni, crolli all'inizio | B13: ='3 - Il ponte'!$B$72 | C13: ='3 - Il ponte'!$B$72 | D13: =$C13-$B13
A14: Tasso vero di uscita sul patrimonio | B14: =$B$11/'3 - Il ponte'!$B$6 | C14: =$C$11/'3 - Il ponte'!$B$6 | D14: =$C$14-$B$14
A16: La colonna «Differenza» e' zero riga per riga, e deve esserlo. Il vantaggio che la contabilita' a cedole sembra avere — vendere meno azionario in un anno storto — e' reale ma e' una proprieta' dell'ALLOCAZIONE, non della contabilita': gli stessi 320.000 € di BTP producono la stessa protezione anche se li chiami «parte del 3,26%». E nel caso del video quella protezione viene dal rimborso alla pari del 2032, non dalle cedole.
A18: L'ATTRITO DELL'IMPOSTA ANTICIPATA — a parita' di aliquota
A19: Convenzione dichiarata: versamenti a INIZIO anno, rendimento nominale, STESSA aliquota sui due rami. Cambia solo il momento in cui l'imposta si paga: subito su ogni cedola incassata, oppure alla fine su tutto il montante. Il confronto e' onesto solo cosi': confrontare il 12,5% della cedola col 26% di un ETF azionario misurerebbe due cose insieme.
A20: Flusso annuo | B20: 16000 | F20: Il flusso cedolare che non ti serve subito.
A21: Rendimento nominale | B21: 0.05
A22: Orizzonte (anni) | B22: 10
A23: Aliquota (selettore) | B23: 0.125 | F23: Scegli 12,50% o 26,00% dal menu. Il 12,5% e' il comparatore onesto della cedola di un titolo di Stato.
A24: Montante lordo del flusso (senza imposte) | B24: =$B$20*(1+$B$21)*((1+$B$21)^$B$22-1)/$B$21
A25: Ramo cedola — tassata subito, netto reinvestito | B25: =$B$24*(1-$B$23)-($B$24*(1-$B$23)-$B$20*(1-$B$23)*$B$22)*$B$23
A26: Ramo accumulo — imposta pagata alla fine | B26: =$B$24*(1-$B$23)
A27: VANTAGGIO DELL'ACCUMULO | B27: =$B$26-$B$25
A28: in percentuale | B28: =$B$27/$B$25
A30: LE DUE ALIQUOTE, UNA ACCANTO ALL'ALTRA
A31: Aliquota | B31: Ramo cedola | C31: Ramo accumulo | D31: Vantaggio dell'accumulo
A32: 0.125 | B32: =$B$24*(1-$A32)-($B$24*(1-$A32)-$B$20*(1-$A32)*$B$22)*$A32 | C32: =$B$24*(1-$A32) | D32: =$C32-$B32
A33: 0.26 | B33: =$B$24*(1-$A33)-($B$24*(1-$A33)-$B$20*(1-$A33)*$B$22)*$A33 | C33: =$B$24*(1-$A33) | D33: =$C33-$B33
A35: Al 12,5% l'accumulo vale 5.612 € in piu' su dieci anni, il 3,1%. Al 26% sono 9.872 €, il 6,7%. Il vantaggio e' esattamente l'imposta che il ramo cedola paga in anticipo sulla crescita del reinvestito: e' piccolo, ed e' vero. Lo stesso meccanismo degli ETF ad accumulazione contro quelli a distribuzione, applicato alle cedole.
A36: Controprova in convenzione posticipata (versamenti a fine anno): il vantaggio scende a 4.511 € e 7.936 €. Il segno non cambia.

Sheet 5 - Sequenza
A1: La sequenza — lo stesso rendimento medio, due ordini diversi
A2: Strumento informativo / divulgativo. NON è consulenza finanziaria. I valori sono indicativi al 2026 e vanno verificati col tuo consulente.
A3: Le due colonne contengono ESATTAMENTE gli stessi dieci rendimenti, in ordine invertito: stessa media geometrica, stessa somma, stesso tutto. L'unica differenza e' quando arrivano i crolli. Questo e' il rischio di sequenza, e non ha niente a che vedere con quanto rende il portafoglio.
A5: IL MULTISET — dieci rendimenti reali, due ordini
A6: Anno | B6: Crolli all'inizio | C6: Crolli alla fine
A7: 1 | B7: -0.1412 | C7: =$B$16
A8: 2 | B8: -0.0912 | C8: =$B$15
A9: 3 | B9: -0.1212 | C9: =$B$14
A10: 4 | B10: 0.1788 | C10: =$B$13
A11: 5 | B11: 0.1188 | C11: =$B$12
A12: 6 | B12: 0.0788 | C12: =$B$11
A13: 7 | B13: 0.1388 | C13: =$B$10
A14: 8 | B14: 0.0588 | C14: =$B$9
A15: 9 | B15: 0.0888 | C15: =$B$8
A16: 10 | B16: 0.0488 | C16: =$B$7
A17: Media geometrica | B17: =EXP(SUMPRODUCT(LN(1+$B$7:$B$16))/10)-1 | C17: =EXP(SUMPRODUCT(LN(1+$C$7:$C$16))/10)-1
A18: 2,998%, che si dichiara come «il 3%» e non come «esattamente il 3,0000%». La colonna di destra e' una formula che rovescia quella di sinistra: cambia un rendimento a sinistra e resta lo stesso multiset.
A20: IL PONTE CON I CROLLI ALL'INIZIO
A21: Anno | B21: Spesa netta dell'anno | C21: Cedole lorde | D21: Imposta 12,5% su BTP e premio | E21: Zainetto minus. a inizio anno | F21: Imposta 26% sui premi | G21: Cedole nette | H21: Da coprire vendendo | I21: Plusvalenza latente | J21: Aliquota eff. sulla vendita | K21: Vendita lorda | L21: Uscita lorda (cedole+vendita) | M21: Rendimento reale | N21: Patrimonio prima del bollo | O21: Imposta di bollo | P21: Patrimonio a fine anno | Q21: USCITA TOTALE col bollo | R21: Costo fiscale a fine anno | S21: Patrimonio in euro di oggi
A22: 1 | B22: ='3 - Il ponte'!$B$7*(1+'3 - Il ponte'!$B$8)^(1-1) | C22: ='3 - Il ponte'!$E$30 | D22: =('3 - Il ponte'!$B$30+'3 - Il ponte'!$C$30)*'3 - Il ponte'!$B$14 | E22: ='3 - Il ponte'!$B$26 | F22: =MAX(0,'3 - Il ponte'!$D$30-E22)*'3 - Il ponte'!$B$15 | G22: =C22-D22-F22 | H22: =B22-G22 | I22: =1-('3 - Il ponte'!$B$6*(1-'3 - Il ponte'!$B$12))/'3 - Il ponte'!$B$6 | J22: ='3 - Il ponte'!$B$13*I22 | K22: =H22/(1-J22) | L22: =C22+K22 | M22: =$B$7 | N22: =('3 - Il ponte'!$B$6-L22)*(1+M22)*(1+'3 - Il ponte'!$B$8) | O22: =N22-P22 | P22: =N22/(1+'3 - Il ponte'!$B$16) | Q22: =L22+O22 | R22: =('3 - Il ponte'!$B$6*(1-'3 - Il ponte'!$B$12))-K22*('3 - Il ponte'!$B$6*(1-'3 - Il ponte'!$B$12))/'3 - Il ponte'!$B$6 | S22: =P22/(1+'3 - Il ponte'!$B$8)^1
A23: 2 | B23: ='3 - Il ponte'!$B$7*(1+'3 - Il ponte'!$B$8)^(2-1) | C23: ='3 - Il ponte'!$E$31 | D23: =('3 - Il ponte'!$B$31+'3 - Il ponte'!$C$31)*'3 - Il ponte'!$B$14 | E23: =MAX(0,E22-'3 - Il ponte'!$D$30) | F23: =MAX(0,'3 - Il ponte'!$D$31-E23)*'3 - Il ponte'!$B$15 | G23: =C23-D23-F23 | H23: =B23-G23 | I23: =1-R22/P22 | J23: ='3 - Il ponte'!$B$13*I23 | K23: =H23/(1-J23) | L23: =C23+K23 | M23: =$B$8 | N23: =(P22-L23)*(1+M23)*(1+'3 - Il ponte'!$B$8) | O23: =N23-P23 | P23: =N23/(1+'3 - Il ponte'!$B$16) | Q23: =L23+O23 | R23: =R22-K23*R22/P22 | S23: =P23/(1+'3 - Il ponte'!$B$8)^2
A24: 3 | B24: ='3 - Il ponte'!$B$7*(1+'3 - Il ponte'!$B$8)^(3-1) | C24: ='3 - Il ponte'!$E$32 | D24: =('3 - Il ponte'!$B$32+'3 - Il ponte'!$C$32)*'3 - Il ponte'!$B$14 | E24: =MAX(0,E23-'3 - Il ponte'!$D$31) | F24: =MAX(0,'3 - Il ponte'!$D$32-E24)*'3 - Il ponte'!$B$15 | G24: =C24-D24-F24 | H24: =B24-G24 | I24: =1-R23/P23 | J24: ='3 - Il ponte'!$B$13*I24 | K24: =H24/(1-J24) | L24: =C24+K24 | M24: =$B$9 | N24: =(P23-L24)*(1+M24)*(1+'3 - Il ponte'!$B$8) | O24: =N24-P24 | P24: =N24/(1+'3 - Il ponte'!$B$16) | Q24: =L24+O24 | R24: =R23-K24*R23/P23 | S24: =P24/(1+'3 - Il ponte'!$B$8)^3
A25: 4 | B25: ='3 - Il ponte'!$B$7*(1+'3 - Il ponte'!$B$8)^(4-1) | C25: ='3 - Il ponte'!$E$33 | D25: =('3 - Il ponte'!$B$33+'3 - Il ponte'!$C$33)*'3 - Il ponte'!$B$14 | E25: =MAX(0,E24-'3 - Il ponte'!$D$32) | F25: =MAX(0,'3 - Il ponte'!$D$33-E25)*'3 - Il ponte'!$B$15 | G25: =C25-D25-F25 | H25: =B25-G25 | I25: =1-R24/P24 | J25: ='3 - Il ponte'!$B$13*I25 | K25: =H25/(1-J25) | L25: =C25+K25 | M25: =$B$10 | N25: =(P24-L25)*(1+M25)*(1+'3 - Il ponte'!$B$8) | O25: =N25-P25 | P25: =N25/(1+'3 - Il ponte'!$B$16) | Q25: =L25+O25 | R25: =R24-K25*R24/P24 | S25: =P25/(1+'3 - Il ponte'!$B$8)^4
A26: 5 | B26: ='3 - Il ponte'!$B$7*(1+'3 - Il ponte'!$B$8)^(5-1) | C26: ='3 - Il ponte'!$E$34 | D26: =('3 - Il ponte'!$B$34+'3 - Il ponte'!$C$34)*'3 - Il ponte'!$B$14 | E26: =MAX(0,E25-'3 - Il ponte'!$D$33) | F26: =MAX(0,'3 - Il ponte'!$D$34-E26)*'3 - Il ponte'!$B$15 | G26: =C26-D26-F26 | H26: =B26-G26 | I26: =1-R25/P25 | J26: ='3 - Il ponte'!$B$13*I26 | K26: =H26/(1-J26) | L26: =C26+K26 | M26: =$B$11 | N26: =(P25-L26)*(1+M26)*(1+'3 - Il ponte'!$B$8) | O26: =N26-P26 | P26: =N26/(1+'3 - Il ponte'!$B$16) | Q26: =L26+O26 | R26: =R25-K26*R25/P25 | S26: =P26/(1+'3 - Il ponte'!$B$8)^5
A27: 6 | B27: ='3 - Il ponte'!$B$7*(1+'3 - Il ponte'!$B$8)^(6-1) | C27: ='3 - Il ponte'!$E$35 | D27: =('3 - Il ponte'!$B$35+'3 - Il ponte'!$C$35)*'3 - Il ponte'!$B$14 | E27: =MAX(0,E26-'3 - Il ponte'!$D$34) | F27: =MAX(0,'3 - Il ponte'!$D$35-E27)*'3 - Il ponte'!$B$15 | G27: =C27-D27-F27 | H27: =B27-G27 | I27: =1-R26/P26 | J27: ='3 - Il ponte'!$B$13*I27 | K27: =H27/(1-J27) | L27: =C27+K27 | M27: =$B$12 | N27: =(P26-L27)*(1+M27)*(1+'3 - Il ponte'!$B$8) | O27: =N27-P27 | P27: =N27/(1+'3 - Il ponte'!$B$16) | Q27: =L27+O27 | R27: =R26-K27*R26/P26 | S27: =P27/(1+'3 - Il ponte'!$B$8)^6
A28: 7 | B28: ='3 - Il ponte'!$B$7*(1+'3 - Il ponte'!$B$8)^(7-1) | C28: ='3 - Il ponte'!$E$36 | D28: =('3 - Il ponte'!$B$36+'3 - Il ponte'!$C$36)*'3 - Il ponte'!$B$14 | E28: =MAX(0,E27-'3 - Il ponte'!$D$35) | F28: =MAX(0,'3 - Il ponte'!$D$36-E28)*'3 - Il ponte'!$B$15 | G28: =C28-D28-F28 | H28: =B28-G28 | I28: =1-R27/P27 | J28: ='3 - Il ponte'!$B$13*I28 | K28: =H28/(1-J28) | L28: =C28+K28 | M28: =$B$13 | N28: =(P27-L28)*(1+M28)*(1+'3 - Il ponte'!$B$8) | O28: =N28-P28 | P28: =N28/(1+'3 - Il ponte'!$B$16) | Q28: =L28+O28 | R28: =R27-K28*R27/P27 | S28: =P28/(1+'3 - Il ponte'!$B$8)^7
A29: 8 | B29: ='3 - Il ponte'!$B$7*(1+'3 - Il ponte'!$B$8)^(8-1) | C29: ='3 - Il ponte'!$E$37 | D29: =('3 - Il ponte'!$B$37+'3 - Il ponte'!$C$37)*'3 - Il ponte'!$B$14 | E29: =MAX(0,E28-'3 - Il ponte'!$D$36) | F29: =MAX(0,'3 - Il ponte'!$D$37-E29)*'3 - Il ponte'!$B$15 | G29: =C29-D29-F29 | H29: =B29-G29 | I29: =1-R28/P28 | J29: ='3 - Il ponte'!$B$13*I29 | K29: =H29/(1-J29) | L29: =C29+K29 | M29: =$B$14 | N29: =(P28-L29)*(1+M29)*(1+'3 - Il ponte'!$B$8) | O29: =N29-P29 | P29: =N29/(1+'3 - Il ponte'!$B$16) | Q29: =L29+O29 | R29: =R28-K29*R28/P28 | S29: =P29/(1+'3 - Il ponte'!$B$8)^8
A30: 9 | B30: ='3 - Il ponte'!$B$7*(1+'3 - Il ponte'!$B$8)^(9-1) | C30: ='3 - Il ponte'!$E$38 | D30: =('3 - Il ponte'!$B$38+'3 - Il ponte'!$C$38)*'3 - Il ponte'!$B$14 | E30: =MAX(0,E29-'3 - Il ponte'!$D$37) | F30: =MAX(0,'3 - Il ponte'!$D$38-E30)*'3 - Il ponte'!$B$15 | G30: =C30-D30-F30 | H30: =B30-G30 | I30: =1-R29/P29 | J30: ='3 - Il ponte'!$B$13*I30 | K30: =H30/(1-J30) | L30: =C30+K30 | M30: =$B$15 | N30: =(P29-L30)*(1+M30)*(1+'3 - Il ponte'!$B$8) | O30: =N30-P30 | P30: =N30/(1+'3 - Il ponte'!$B$16) | Q30: =L30+O30 | R30: =R29-K30*R29/P29 | S30: =P30/(1+'3 - Il ponte'!$B$8)^9
A31: 10 | B31: ='3 - Il ponte'!$B$7*(1+'3 - Il ponte'!$B$8)^(10-1) | C31: ='3 - Il ponte'!$E$39 | D31: =('3 - Il ponte'!$B$39+'3 - Il ponte'!$C$39)*'3 - Il ponte'!$B$14 | E31: =MAX(0,E30-'3 - Il ponte'!$D$38) | F31: =MAX(0,'3 - Il ponte'!$D$39-E31)*'3 - Il ponte'!$B$15 | G31: =C31-D31-F31 | H31: =B31-G31 | I31: =1-R30/P30 | J31: ='3 - Il ponte'!$B$13*I31 | K31: =H31/(1-J31) | L31: =C31+K31 | M31: =$B$16 | N31: =(P30-L31)*(1+M31)*(1+'3 - Il ponte'!$B$8) | O31: =N31-P31 | P31: =N31/(1+'3 - Il ponte'!$B$16) | Q31: =L31+O31 | R31: =R30-K31*R30/P30 | S31: =P31/(1+'3 - Il ponte'!$B$8)^10
A34: IL PONTE CON I CROLLI ALLA FINE
A35: Anno | B35: Spesa netta dell'anno | C35: Cedole lorde | D35: Imposta 12,5% su BTP e premio | E35: Zainetto minus. a inizio anno | F35: Imposta 26% sui premi | G35: Cedole nette | H35: Da coprire vendendo | I35: Plusvalenza latente | J35: Aliquota eff. sulla vendita | K35: Vendita lorda | L35: Uscita lorda (cedole+vendita) | M35: Rendimento reale | N35: Patrimonio prima del bollo | O35: Imposta di bollo | P35: Patrimonio a fine anno | Q35: USCITA TOTALE col bollo | R35: Costo fiscale a fine anno | S35: Patrimonio in euro di oggi
A36: 1 | B36: ='3 - Il ponte'!$B$7*(1+'3 - Il ponte'!$B$8)^(1-1) | C36: ='3 - Il ponte'!$E$30 | D36: =('3 - Il ponte'!$B$30+'3 - Il ponte'!$C$30)*'3 - Il ponte'!$B$14 | E36: ='3 - Il ponte'!$B$26 | F36: =MAX(0,'3 - Il ponte'!$D$30-E36)*'3 - Il ponte'!$B$15 | G36: =C36-D36-F36 | H36: =B36-G36 | I36: =1-('3 - Il ponte'!$B$6*(1-'3 - Il ponte'!$B$12))/'3 - Il ponte'!$B$6 | J36: ='3 - Il ponte'!$B$13*I36 | K36: =H36/(1-J36) | L36: =C36+K36 | M36: =$C$7 | N36: =('3 - Il ponte'!$B$6-L36)*(1+M36)*(1+'3 - Il ponte'!$B$8) | O36: =N36-P36 | P36: =N36/(1+'3 - Il ponte'!$B$16) | Q36: =L36+O36 | R36: =('3 - Il ponte'!$B$6*(1-'3 - Il ponte'!$B$12))-K36*('3 - Il ponte'!$B$6*(1-'3 - Il ponte'!$B$12))/'3 - Il ponte'!$B$6 | S36: =P36/(1+'3 - Il ponte'!$B$8)^1
A37: 2 | B37: ='3 - Il ponte'!$B$7*(1+'3 - Il ponte'!$B$8)^(2-1) | C37: ='3 - Il ponte'!$E$31 | D37: =('3 - Il ponte'!$B$31+'3 - Il ponte'!$C$31)*'3 - Il ponte'!$B$14 | E37: =MAX(0,E36-'3 - Il ponte'!$D$30) | F37: =MAX(0,'3 - Il ponte'!$D$31-E37)*'3 - Il ponte'!$B$15 | G37: =C37-D37-F37 | H37: =B37-G37 | I37: =1-R36/P36 | J37: ='3 - Il ponte'!$B$13*I37 | K37: =H37/(1-J37) | L37: =C37+K37 | M37: =$C$8 | N37: =(P36-L37)*(1+M37)*(1+'3 - Il ponte'!$B$8) | O37: =N37-P37 | P37: =N37/(1+'3 - Il ponte'!$B$16) | Q37: =L37+O37 | R37: =R36-K37*R36/P36 | S37: =P37/(1+'3 - Il ponte'!$B$8)^2
A38: 3 | B38: ='3 - Il ponte'!$B$7*(1+'3 - Il ponte'!$B$8)^(3-1) | C38: ='3 - Il ponte'!$E$32 | D38: =('3 - Il ponte'!$B$32+'3 - Il ponte'!$C$32)*'3 - Il ponte'!$B$14 | E38: =MAX(0,E37-'3 - Il ponte'!$D$31) | F38: =MAX(0,'3 - Il ponte'!$D$32-E38)*'3 - Il ponte'!$B$15 | G38: =C38-D38-F38 | H38: =B38-G38 | I38: =1-R37/P37 | J38: ='3 - Il ponte'!$B$13*I38 | K38: =H38/(1-J38) | L38: =C38+K38 | M38: =$C$9 | N38: =(P37-L38)*(1+M38)*(1+'3 - Il ponte'!$B$8) | O38: =N38-P38 | P38: =N38/(1+'3 - Il ponte'!$B$16) | Q38: =L38+O38 | R38: =R37-K38*R37/P37 | S38: =P38/(1+'3 - Il ponte'!$B$8)^3
A39: 4 | B39: ='3 - Il ponte'!$B$7*(1+'3 - Il ponte'!$B$8)^(4-1) | C39: ='3 - Il ponte'!$E$33 | D39: =('3 - Il ponte'!$B$33+'3 - Il ponte'!$C$33)*'3 - Il ponte'!$B$14 | E39: =MAX(0,E38-'3 - Il ponte'!$D$32) | F39: =MAX(0,'3 - Il ponte'!$D$33-E39)*'3 - Il ponte'!$B$15 | G39: =C39-D39-F39 | H39: =B39-G39 | I39: =1-R38/P38 | J39: ='3 - Il ponte'!$B$13*I39 | K39: =H39/(1-J39) | L39: =C39+K39 | M39: =$C$10 | N39: =(P38-L39)*(1+M39)*(1+'3 - Il ponte'!$B$8) | O39: =N39-P39 | P39: =N39/(1+'3 - Il ponte'!$B$16) | Q39: =L39+O39 | R39: =R38-K39*R38/P38 | S39: =P39/(1+'3 - Il ponte'!$B$8)^4
A40: 5 | B40: ='3 - Il ponte'!$B$7*(1+'3 - Il ponte'!$B$8)^(5-1) | C40: ='3 - Il ponte'!$E$34 | D40: =('3 - Il ponte'!$B$34+'3 - Il ponte'!$C$34)*'3 - Il ponte'!$B$14 | E40: =MAX(0,E39-'3 - Il ponte'!$D$33) | F40: =MAX(0,'3 - Il ponte'!$D$34-E40)*'3 - Il ponte'!$B$15 | G40: =C40-D40-F40 | H40: =B40-G40 | I40: =1-R39/P39 | J40: ='3 - Il ponte'!$B$13*I40 | K40: =H40/(1-J40) | L40: =C40+K40 | M40: =$C$11 | N40: =(P39-L40)*(1+M40)*(1+'3 - Il ponte'!$B$8) | O40: =N40-P40 | P40: =N40/(1+'3 - Il ponte'!$B$16) | Q40: =L40+O40 | R40: =R39-K40*R39/P39 | S40: =P40/(1+'3 - Il ponte'!$B$8)^5
A41: 6 | B41: ='3 - Il ponte'!$B$7*(1+'3 - Il ponte'!$B$8)^(6-1) | C41: ='3 - Il ponte'!$E$35 | D41: =('3 - Il ponte'!$B$35+'3 - Il ponte'!$C$35)*'3 - Il ponte'!$B$14 | E41: =MAX(0,E40-'3 - Il ponte'!$D$34) | F41: =MAX(0,'3 - Il ponte'!$D$35-E41)*'3 - Il ponte'!$B$15 | G41: =C41-D41-F41 | H41: =B41-G41 | I41: =1-R40/P40 | J41: ='3 - Il ponte'!$B$13*I41 | K41: =H41/(1-J41) | L41: =C41+K41 | M41: =$C$12 | N41: =(P40-L41)*(1+M41)*(1+'3 - Il ponte'!$B$8) | O41: =N41-P41 | P41: =N41/(1+'3 - Il ponte'!$B$16) | Q41: =L41+O41 | R41: =R40-K41*R40/P40 | S41: =P41/(1+'3 - Il ponte'!$B$8)^6
A42: 7 | B42: ='3 - Il ponte'!$B$7*(1+'3 - Il ponte'!$B$8)^(7-1) | C42: ='3 - Il ponte'!$E$36 | D42: =('3 - Il ponte'!$B$36+'3 - Il ponte'!$C$36)*'3 - Il ponte'!$B$14 | E42: =MAX(0,E41-'3 - Il ponte'!$D$35) | F42: =MAX(0,'3 - Il ponte'!$D$36-E42)*'3 - Il ponte'!$B$15 | G42: =C42-D42-F42 | H42: =B42-G42 | I42: =1-R41/P41 | J42: ='3 - Il ponte'!$B$13*I42 | K42: =H42/(1-J42) | L42: =C42+K42 | M42: =$C$13 | N42: =(P41-L42)*(1+M42)*(1+'3 - Il ponte'!$B$8) | O42: =N42-P42 | P42: =N42/(1+'3 - Il ponte'!$B$16) | Q42: =L42+O42 | R42: =R41-K42*R41/P41 | S42: =P42/(1+'3 - Il ponte'!$B$8)^7
A43: 8 | B43: ='3 - Il ponte'!$B$7*(1+'3 - Il ponte'!$B$8)^(8-1) | C43: ='3 - Il ponte'!$E$37 | D43: =('3 - Il ponte'!$B$37+'3 - Il ponte'!$C$37)*'3 - Il ponte'!$B$14 | E43: =MAX(0,E42-'3 - Il ponte'!$D$36) | F43: =MAX(0,'3 - Il ponte'!$D$37-E43)*'3 - Il ponte'!$B$15 | G43: =C43-D43-F43 | H43: =B43-G43 | I43: =1-R42/P42 | J43: ='3 - Il ponte'!$B$13*I43 | K43: =H43/(1-J43) | L43: =C43+K43 | M43: =$C$14 | N43: =(P42-L43)*(1+M43)*(1+'3 - Il ponte'!$B$8) | O43: =N43-P43 | P43: =N43/(1+'3 - Il ponte'!$B$16) | Q43: =L43+O43 | R43: =R42-K43*R42/P42 | S43: =P43/(1+'3 - Il ponte'!$B$8)^8
A44: 9 | B44: ='3 - Il ponte'!$B$7*(1+'3 - Il ponte'!$B$8)^(9-1) | C44: ='3 - Il ponte'!$E$38 | D44: =('3 - Il ponte'!$B$38+'3 - Il ponte'!$C$38)*'3 - Il ponte'!$B$14 | E44: =MAX(0,E43-'3 - Il ponte'!$D$37) | F44: =MAX(0,'3 - Il ponte'!$D$38-E44)*'3 - Il ponte'!$B$15 | G44: =C44-D44-F44 | H44: =B44-G44 | I44: =1-R43/P43 | J44: ='3 - Il ponte'!$B$13*I44 | K44: =H44/(1-J44) | L44: =C44+K44 | M44: =$C$15 | N44: =(P43-L44)*(1+M44)*(1+'3 - Il ponte'!$B$8) | O44: =N44-P44 | P44: =N44/(1+'3 - Il ponte'!$B$16) | Q44: =L44+O44 | R44: =R43-K44*R43/P43 | S44: =P44/(1+'3 - Il ponte'!$B$8)^9
...
