Workbook

Sheet 0-Indice
A1: Marco FIRE — Il numero vero del ritiro (caso Chiara, 2026)
A2: Strumento informativo / divulgativo. NON è consulenza finanziaria. I valori sono indicativi al 2026 e vanno verificati col tuo consulente.
A4: Indice
A5: 1-Input | B5: I 22 input del caso e i netti di coppia
A6: P-Parametri | B6: Parametri normativi: aliquote, coefficienti, soglie
A7: 2-Composizione | B7: Accumulo 2003-2026, evento 2019, plusvalenza latente
A8: 3-Rendimento | B8: Il 3,25% derivato e la banda 3,00 / 3,25 / 4,15
A9: 4-Montanti | B9: Montanti contributivi al 2026 e al ritiro
A10: 5-Pensioni | B10: Vecchiaia a 68a2m e via contributiva intorno ai 65
A11: 6-TFR | B11: Liquidazione di coppia, tassazione separata, salvaguardia
A12: 7-Fabbisogno | B12: Ponte, coda, waterfall del twist, curva del ×25
A13: 8-Patrimonio | B13: Traiettoria anno per anno e anno dei due milioni
A14: 9-Leve | B14: Le otto leve, ipotesi prudente e scenario centrale
A15: 10-Glide | B15: Glide path, costo atteso, anno peggiore, break-even
A16: 11-Banda | B16: Le quattordici righe della banda del fabbisogno
A17: 12-Verifica | B17: Il controllo annuale: quattro indicatori e semaforo
A19: Come usare
A20: 1. Le celle GIALLE sono input — modificale coi tuoi numeri.
A21: 2. Le celle VERDI sono output — si aggiornano automaticamente.
A22: 3. Tutti i numeri di default sono al 2026 da fonti pubbliche.
A23: 4. Niente codice nascosto: l'Excel è solo formule modificabili.
A25: Fonti dati
A26: • IRPEF 2026 (23% / 33% / 43%) — L. 199/2025; detrazioni art. 13 TUIR c. 3 e c. 3-bis
A27: • Coefficienti di trasformazione — DM 20/11/2024, biennio 2025-2026
A28: • Via contributiva intorno ai 65 anni — art. 24 c. 11 D.L. 201/2011, testo vigente; soglia di 3,2 volte l'assegno sociale in vigore dal 2030
A29: • Requisiti 2027-2028 e proiezione a 68 anni e 2 mesi per il 2039-2040 — L. 199/2025 art. 1 c. 185 e proiezioni RGS per coorte (proiezioni, non norme)
A30: • TFR: quota 1/13,5 e rivalutazione 1,5% + 75% ISTAT — art. 2120 c.c.; tassazione separata art. 19 TUIR
A31: • Clausola di salvaguardia con gli scaglioni 2006 — L. 296/2006, rinumerata nell'art. 21 c. 11 del D.Lgs. 117/2026 (GU n. 152 del 3/7/2026, S.O. 26/L)
... A36: Aggiornamenti: github.com/marcofire-it/marco-fire-simulatori

Sheet 1-Input
A1: I 22 input del caso
A2: Strumento informativo / divulgativo. NON è consulenza finanziaria. I valori sono indicativi al 2026 e vanno verificati col tuo consulente.
A4: INPUT — cambia una cella gialla e tutti i verdi si muovono
A5: (1) Nascita di Chiara — anno / mese | B5: 1972 | C5: 4
A6: (2) Nascita del marito — anno / mese | B6: 1971 | C6: 4
A7: (3) Retribuzione attuale di Chiara (lorda) | B7: 60000
A8: (4) Retribuzione attuale del marito (lorda) | B8: 48000
A9: (5) Media di carriera di Chiara (previdenziale) | B9: 34000
A10: (6) Chiara — anni di carriera al 2026 / densita' contributiva | B10: 30 | C10: 0.85
A11: (7) Media di carriera del marito (previdenziale) | B11: 30000
A12: (8) Marito — anni di carriera al 2026 / densita' contributiva | B12: 30 | C12: 1
A13: (9) Spesa netta di coppia (€/anno) | B13: 52000
A14: (10) Evento del 2019 — netto reinvestito (quota societaria ceduta) | B14: 280000
A15: (11) Anno dell'evento | B15: 2019
A16: (12) Accumulo — primo anno / anno di riferimento (oggi) | B16: 2003 | C16: 2026
A17: (13) Rendimento lordo atteso — menu 3,00% / 3,25% / 4,15% | B17: 0.0325
A18: (14) Bollo titoli | B18: 0.002
A19: (15) Anno di ritiro | B19: 2036
A20: (16) Orizzonte — eta' finale di Chiara: menu 92 / 95 / 97 | B20: 95
A21: (17) Crescita reale del montante — menu 0,0% / 0,6% / 1,2% | B21: 0.006
A22: (18) Requisito anagrafico — anni in piu': 0 / 1 / 2 | B22: 0
A23: (19) Anzianita' TFR al ritiro — Chiara / marito | B23: 18 | C23: 41
A24: (20) TFR lordo maturato al ritiro — Chiara / marito | B24: 80000 | C24: 124000
A25: (21) Retribuzione di riferimento TFR del marito / rivalutazione reale | B25: 34000 | C25: 0.0115
A26: (22) TFR: 1 = in cassa, 0 = conferito al fondo pensione | B26: 1
A27: Le tre grandezze del marito sono DIVERSE e restano distinte: retribuzione attuale 48.000, media di carriera previdenziale 30.000, retribuzione media di riferimento per il TFR 34.000. Sulla terza il foglio 6 mostra la banda del ±15%.
A28: CONVENZIONE 5 — l'input del motore e' il RISPARMIO ARROTONDATO all'euro (riga 40): l'arrotondamento sta all'ingresso del motore, non all'uscita.
A30: I NETTI DI COPPIA — IRPEF 2026, modulo completo
A31: Voce | B31: Chiara | C31: Marito
A32: Retribuzione lorda | B32: =B7 | C32: =B8
A33: Contributi a carico del lavoratore | B33: =B32*'P-Parametri'!$B$17 | C33: =C32*'P-Parametri'!$B$17
A34: Imponibile IRPEF | B34: =B32-B33 | C34: =C32-C33
A35: IRPEF lorda | B35: =IF(B34<='P-Parametri'!$B$6,'P-Parametri'!$C$6*B34,IF(B34<='P-Parametri'!$B$7,'P-Parametri'!$B$9+'P-Parametri'!$C$7*(B34-'P-Parametri'!$B$6),'P-Parametri'!$B$10+'P-Parametri'!$C$8*(B34-'P-Parametri'!$B$7))) | C35: =IF(C34<='P-Parametri'!$B$6,'P-Parametri'!$C$6*C34,IF(C34<='P-Parametri'!$B$7,'P-Parametri'!$B$9+'P-Parametri'!$C$7*(C34-'P-Parametri'!$B$6),'P-Parametri'!$B$10+'P-Parametri'!$C$8*(C34-'P-Parametri'!$B$7)))
A36: Detrazione da lavoro dipendente | B36: =IF(B34<=15000,1955,IF(B34<='P-Parametri'!$B$6,1910+1190*('P-Parametri'!$B$6-B34)/13000,IF(B34<='P-Parametri'!$B$7,'P-Parametri'!$B$16*('P-Parametri'!$B$7-B34)/'P-Parametri'!$C$16,0))) | C36: =IF(C34<=15000,1955,IF(C34<='P-Parametri'!$B$6,1910+1190*('P-Parametri'!$B$6-C34)/13000,IF(C34<='P-Parametri'!$B$7,'P-Parametri'!$B$16*('P-Parametri'!$B$7-C34)/'P-Parametri'!$C$16,0)))
A37: NETTO annuo (imponibile − imposta netta − addizionali) | B37: =B34-MAX(0,B35-B36)-IF(MAX(0,B35-B36)<=0,0,'P-Parametri'!$B$11*B34) | C37: =C34-MAX(0,C35-C36)-IF(MAX(0,C35-C36)<=0,0,'P-Parametri'!$B$11*C34)
A38: NETTO DI COPPIA | B38: =B37+C37
A39: Spesa netta di coppia | B39: =B13
A40: RISPARMIO ANNUO — input del motore, arrotondato (Convenzione 5) | B40: =ROUND(B38-B39,0)
A41: Risparmio in quota del netto | B41: =B40/B38
A42: Spesa contro i consumi ISTAT di coppia | B42: =B13/'P-Parametri'!$B$46
...

Sheet P-Parametri
A1: Parametri normativi e di fonte
A2: Strumento informativo / divulgativo. NON è consulenza finanziaria. I valori sono indicativi al 2026 e vanno verificati col tuo consulente.
A3: Le uniche costanti del modello, oltre agli input, stanno qui: aliquote, coefficienti, soglie, parametri di fonte. Tutti gli altri fogli le referenziano.
A5: IRPEF 2026 (L. 199/2025) e detrazioni
A6: Primo scaglione — limite / aliquota | B6: 28000 | C6: 0.23
A7: Secondo scaglione — limite / aliquota | B7: 50000 | C7: 0.33
A8: Terzo scaglione — aliquota oltre il secondo limite | C8: 0.43
A9: Imposta cumulata fino al primo scaglione | B9: =B6*C6
A10: Imposta cumulata fino al secondo scaglione | B10: =B9+(B7-B6)*C7
A11: Addizionali regionali e comunali | B11: 0.02
A12: Detrazione da pensione — importo massimo / soglia bassa | B12: 1955 | C12: 8500
A13: Detrazione da pensione 8.500-28.000 — base / incremento / ampiezza | B13: 700 | C13: 1255 | D13: 19500
A14: Detrazione da pensione 28.000-50.000 — base / ampiezza | B14: 700 | C14: 22000
A15: Detrazione art. 13 comma 3-bis — importo / da / a | B15: 50 | C15: 25000 | D15: 29000
A16: Detrazione da lavoro dipendente 28.000-50.000 — base / ampiezza | B16: 1910 | C16: 22000
A17: Contributi a carico del lavoratore | B17: 0.0919
A18: Previdenza obbligatoria
A19: Aliquota di computo (dipendenti) | B19: 0.33
A20: Mensilita' della pensione | B20: 13
A21: Coefficiente di trasformazione — 68 anni e 2 mesi | B21: 0.05844
A22: Coefficiente di trasformazione — 65 anni | B22: 0.0525
A23: Coefficiente di trasformazione — 66 anni | B23: 0.05423
A24: Coefficiente di trasformazione — 70 anni e 2 mesi (controprova) | B24: 0.063
A25: Soglia di 3,2 volte l'assegno sociale (€/mese) | B25: 1747.97
A26: Cap di 5 volte il trattamento minimo (€/mese) | B26: 3059.25
A27: Soglia di importo minima (€/mese) | B27: 546.24
A28: Fattore di rivalutazione cumulata del montante al 2026 | B28: 1.020765
A29: Anni minimi di contribuzione | B29: 20
A30: Fiscalita' finanziaria
A31: Capital gain | B31: 0.26
A32: Titoli di Stato ed equiparati | B32: 0.125
A33: TFR
A34: Quota annua accantonata — divisore | B34: 13.5
A35: Ritenuta sul TFR conferito al fondo — iniziale / a regime | B35: 0.15 | C35: 0.09
A36: Clausola di salvaguardia — scaglioni 2006
A37: Primo scaglione — limite / aliquota | B37: 26000 | C37: 0.23
A38: Secondo scaglione — limite / aliquota | B38: 33500 | C38: 0.33
A39: Terzo scaglione — limite / aliquota | B39: 100000 | C39: 0.39
A40: Oltre — aliquota | C40: 0.43
A41: Rendimenti attesi — le due nature restano dichiarate separatamente
...

Sheet 2-Composizione
A1: Composizione del patrimonio e plusvalenza latente
A2: Strumento informativo / divulgativo. NON è consulenza finanziaria. I valori sono indicativi al 2026 e vanno verificati col tuo consulente.
A4: ACCUMULO ANNO PER ANNO — la latente e' DERIVATA, non postulata
A5: Anno | B5: Versamento | C5: Evento | D5: Montante a fine anno | E5: Base di costo cumulata
A6: ='1-Input'!$B$16 | B6: =IF(A6>'1-Input'!$C$16,0,'1-Input'!$B$40) | C6: =IF(A6='1-Input'!$B$15,'1-Input'!$B$14,0) | D6: =(B6)*(1+'1-Input'!$B$46)+C6 | E6: =B6+C6
A7: =A6+1 | B7: =IF(A7>'1-Input'!$C$16,0,'1-Input'!$B$40) | C7: =IF(A7='1-Input'!$B$15,'1-Input'!$B$14,0) | D7: =(D6+B7)*(1+'1-Input'!$B$46)+C7 | E7: =E6+B7+C7
A8: =A7+1 | B8: =IF(A8>'1-Input'!$C$16,0,'1-Input'!$B$40) | C8: =IF(A8='1-Input'!$B$15,'1-Input'!$B$14,0) | D8: =(D7+B8)*(1+'1-Input'!$B$46)+C8 | E8: =E7+B8+C8
A9: =A8+1 | B9: =IF(A9>'1-Input'!$C$16,0,'1-Input'!$B$40) | C9: =IF(A9='1-Input'!$B$15,'1-Input'!$B$14,0) | D9: =(D8+B9)*(1+'1-Input'!$B$46)+C9 | E9: =E8+B9+C9
A10: =A9+1 | B10: =IF(A10>'1-Input'!$C$16,0,'1-Input'!$B$40) | C10: =IF(A10='1-Input'!$B$15,'1-Input'!$B$14,0) | D10: =(D9+B10)*(1+'1-Input'!$B$46)+C10 | E10: =E9+B10+C10
A11: =A10+1 | B11: =IF(A11>'1-Input'!$C$16,0,'1-Input'!$B$40) | C11: =IF(A11='1-Input'!$B$15,'1-Input'!$B$14,0) | D11: =(D10+B11)*(1+'1-Input'!$B$46)+C11 | E11: =E10+B11+C11
A12: =A11+1 | B12: =IF(A12>'1-Input'!$C$16,0,'1-Input'!$B$40) | C12: =IF(A12='1-Input'!$B$15,'1-Input'!$B$14,0) | D12: =(D11+B12)*(1+'1-Input'!$B$46)+C12 | E12: =E11+B12+C12
A13: =A12+1 | B13: =IF(A13>'1-Input'!$C$16,0,'1-Input'!$B$40) | C13: =IF(A13='1-Input'!$B$15,'1-Input'!$B$14,0) | D13: =(D12+B13)*(1+'1-Input'!$B$46)+C13 | E13: =E12+B13+C13
A14: =A13+1 | B14: =IF(A14>'1-Input'!$C$16,0,'1-Input'!$B$40) | C14: =IF(A14='1-Input'!$B$15,'1-Input'!$B$14,0) | D14: =(D13+B14)*(1+'1-Input'!$B$46)+C14 | E14: =E13+B14+C14
A15: =A14+1 | B15: =IF(A15>'1-Input'!$C$16,0,'1-Input'!$B$40) | C15: =IF(A15='1-Input'!$B$15,'1-Input'!$B$14,0) | D15: =(D14+B15)*(1+'1-Input'!$B$46)+C15 | E15: =E14+B15+C15
A16: =A15+1 | B16: =IF(A16>'1-Input'!$C$16,0,'1-Input'!$B$40) | C16: =IF(A16='1-Input'!$B$15,'1-Input'!$B$14,0) | D16: =(D15+B16)*(1+'1-Input'!$B$46)+C16 | E16: =E15+B16+C16
A17: =A16+1 | B17: =IF(A17>'1-Input'!$C$16,0,'1-Input'!$B$40) | C17: =IF(A17='1-Input'!$B$15,'1-Input'!$B$14,0) | D17: =(D16+B17)*(1+'1-Input'!$B$46)+C17 | E17: =E16+B17+C17
A18: =A17+1 | B18: =IF(A18>'1-Input'!$C$16,0,'1-Input'!$B$40) | C18: =IF(A18='1-Input'!$B$15,'1-Input'!$B$14,0) | D18: =(D17+B18)*(1+'1-Input'!$B$46)+C18 | E18: =E17+B18+C18
... A29: =A28+1 | B29: =IF(A29>'1-Input'!$C$16,0,'1-Input'!$B$40) | C29: =IF(A29='1-Input'!$B$15,'1-Input'!$B$14,0) | D29: =(D28+B29)*(1+'1-Input'!$B$46)+C29 | E29: =E28+B29+C29
A31: IL PATRIMONIO DI OGGI
A32: Componente da accumulo (24 versamenti reali costanti) | B32: =D29-B33
A33: Componente dall'evento del 2019, capitalizzata | B33: ='1-Input'!$B$14*(1+'1-Input'!$B$46)^('1-Input'!$C$16-'1-Input'!$B$15)
A34: Base di costo dell'accumulo | B34: ='1-Input'!$B$45*'1-Input'!$B$40
A35: Base di costo dell'evento | B35: ='1-Input'!$B$14
A36: PATRIMONIO FINANZIARIO al 2026 | B36: =D29
A37: Base di costo totale | B37: =E29
A38: PLUSVALENZA LATENTE (con il floor a zero) | B38: =MAX(0,(B36-B37)/B36)
A39: Fattore di lordizzazione G(2026) = 1 / (1 − capital gain × latente) | B39: =1/(1-'P-Parametri'!$B$31*B38)
A41: LA SOGLIA IN CUI IL CAPITALE DIVENTA IL MOTORE
A42: Soglia K* = versamento annuo / rendimento netto | B42: ='1-Input'!$B$40/'1-Input'!$B$46
A43: Multiplo del versamento annuo | B43: =1/'1-Input'!$B$46
A44: Anno in cui la soglia e' stata superata | B44: =INDEX($A$6:$A$29,MATCH(B42,$D$6:$D$29,1)+1)
A45: Capitale a fine dell'anno precedente | B45: =INDEX($D$6:$D$29,MATCH(B42,$D$6:$D$29,1))
A46: Capitale a fine dell'anno di superamento | B46: =INDEX($D$6:$D$29,MATCH(B42,$D$6:$D$29,1)+1)
A47: Crescita attesa del primo anno (patrimonio × rendimento lordo) | B47: =B36*'1-Input'!$B$17
A48: Rapporto fra crescita attesa e versamenti annui | B48: =B47/'1-Input'!$B$40
A50: LA LATENTE E' DERIVATA. Cambiando la spesa cambia il risparmio, quindi l'accumulo, quindi il patrimonio e la base di costo: la plusvalenza latente esce dalla catena e non e' un parametro postulato. Il floor a zero e' dichiarato: una latente negativa non ha significato fiscale qui, e il fattore di lordizzazione non puo' scendere sotto 1.
A51: Convenzione dichiarata: i versamenti entrano a inizio anno e capitalizzano per l'anno intero; l'evento del 2019 entra a fine anno e capitalizza dall'anno successivo. Il rendimento e' quello NETTO BOLLO (rendimento lordo − 0,20%).
A52: Cautela sul caso: 17.457 € reali costanti per ventiquattro anni significa che nei primi anni lo sforzo di risparmio era molto piu' pesante di oggi.

Sheet 3-Rendimento
A1: Il rendimento derivato e la banda
A2: Strumento informativo / divulgativo. NON è consulenza finanziaria. I valori sono indicativi al 2026 e vanno verificati col tuo consulente.
A4: r(w) = rendimento delle azioni × w + rendimento delle obbligazioni × (1 − w)
A5: Quota azionaria del portafoglio | B5: ='P-Parametri'!$B$54
A6: Rendimento atteso delle azioni (forward-looking, Fig. 52) | B6: ='P-Parametri'!$B$42
A7: Rendimento atteso delle obbligazioni (forward-looking, Fig. 52) | B7: ='P-Parametri'!$C$42
A8: RENDIMENTO LORDO DERIVATO sul 70/30 | B8: =B6*B5+B7*(1-B5)
A9: Verifica sul 60/40 del canale (il pavimento della banda) | B9: =B6*0.6+B7*0.4
A10: Bollo titoli | B10: ='1-Input'!$B$18
A11: RENDIMENTO NETTO BOLLO usato dal motore | B11: ='1-Input'!$B$17-'1-Input'!$B$18
A13: LA BANDA — ogni estremo con la sua edizione dichiarata
A14: Estremo | B14: Quota azionaria | C14: Rendimento lordo | D14: Rendimento netto bollo | E14: Edizione dichiarata
A15: Pavimento — 60/40 forward-looking | B15: =0.6 | C15: =B6*0.6+B7*0.4 | D15: =C15-'1-Input'!$B$18 | E15: Yearbook 2023, Fig. 52 — prospettico
A16: Centro — 70/30 forward-looking | B16: =B5 | C16: =B8 | D16: =C16-'1-Input'!$B$18 | E16: Yearbook 2023, Fig. 52 — prospettico
A17: Tetto — 70/30 sul reale storico 1900-2024 | B17: =B5 | C17: ='P-Parametri'!$B$43*B5+'P-Parametri'!$C$43*(1-B5) | D17: =C17-'1-Input'!$B$18 | E17: Yearbook 2025, storico 1900-2024
A19: Centro e pavimento sono FORWARD-LOOKING (Yearbook 2023, cap. 5, Fig. 52 «World in the future»); il tetto e' STORICO (reale 1900-2024, Yearbook 2025). Le due nature sono diverse e metterle nella stessa banda e' una scelta del canale, non della fonte: qui e' dichiarata riga per riga.
A20: Tranello evitato: lo 0,9% del summary 2025 e' la media semplice dei ventuno paesi, non l'indice mondiale, e non entra in questa banda.
A21: Il 3,25% e' una stima prospettica, non una previsione. Il canone del canale resta il 3% reale: questo caso usa il 3,25% derivato dall'allocazione dichiarata, con il 3,00% come pavimento.

Sheet 4-Montanti
A1: Montanti contributivi
A2: Strumento informativo / divulgativo. NON è consulenza finanziaria. I valori sono indicativi al 2026 e vanno verificati col tuo consulente.
A4: IL MONTANTE DI OGGI (2026)
A5: Voce | B5: Chiara | C5: Marito
A6: Anni contributivi al 2026 (anni di carriera × densita') | B6: ='1-Input'!$B$49 | C6: ='1-Input'!$C$49
A7: Contributo annuo medio (aliquota di computo × media di carriera) | B7: ='1-Input'!$B$9*'P-Parametri'!$B$19 | C7: ='1-Input'!$B$11*'P-Parametri'!$B$19
A8: Fattore di rivalutazione cumulata al 2026 | B8: ='P-Parametri'!$B$28 | C8: ='P-Parametri'!$B$28
A9: MONTANTE CONTRIBUTIVO AL 2026 | B9: =B6*B7*B8 | C9: =C6*C7*C8
A10: Banda del montante di Chiara — minimo (buchi all'inizio) / massimo | B10: ='P-Parametri'!$B$45 | C10: ='P-Parametri'!$C$45
A11: Semaforo: almeno 20 anni di contribuzione? | B11: =IF(B6>='P-Parametri'!$B$29,"SI","NO") | C11: =IF(C6>='P-Parametri'!$B$29,"SI","NO")
A13: IL MONTANTE AL RITIRO
A14: Contributo annuo futuro (aliquota × retribuzione attuale) | B14: ='1-Input'!$B$48 | C14: ='1-Input'!$C$48
A15: Anni di contribuzione dopo il 2026 | B15: ='1-Input'!$B$50 | C15: ='1-Input'!$B$50
A16: Fattore di rivalutazione dello stock (1 + g) elevato agli anni | B16: =(1+'1-Input'!$B$21)^B15 | C16: =(1+'1-Input'!$B$21)^C15
A17: Fattore di accumulo dei contributi futuri | B17: =IF('1-Input'!$B$21=0,B15,((1+'1-Input'!$B$21)^B15-1)/'1-Input'!$B$21) | C17: =IF('1-Input'!$B$21=0,C15,((1+'1-Input'!$B$21)^C15-1)/'1-Input'!$B$21)
A18: MONTANTE AL RITIRO (fine dell'anno di ritiro) | B18: =B9*B16+B14*B17 | C18: =C9*C16+C14*C17
A20: CONVENZIONE — ac + ar e' una COSTANTE. La distanza fra oggi e la decorrenza dipende dall'eta', non dalla data in cui si smette di lavorare: lavorare uno o due anni in piu' sposta anni dalla sola rivalutazione alla contribuzione, non li aggiunge. Il motore lo implementa nei fogli 5, 9 e 11.
A21: Il fattore di rivalutazione cumulata al 2026 (1,020765) sintetizza la serie storica del PIL nominale quinquennale. La ricostruzione anno per anno sulla serie INPS 707/2026 e' un refresh dichiarato: la direzione dell'errore e' ignota, l'ampiezza e' misurata (±3% sul montante di Chiara vale circa ±13.000 € sul fabbisogno).
A22: La densita' contributiva di Chiara (85%) e' un'ipotesi centrale con i buchi distribuiti in modo uniforme. La banda della riga 10 mostra gli estremi: buchi all'inizio (montante piu' basso) e buchi alla fine (montante piu' alto).

Sheet 5-Pensioni
A1: Le due pensioni
A2: Strumento informativo / divulgativo. NON è consulenza finanziaria. I valori sono indicativi al 2026 e vanno verificati col tuo consulente.
A4: SCENARIO A — vecchiaia a 68 anni e 2 mesi (proiezione RGS)
A5: Voce | B5: Chiara | C5: Marito
A6: Montante contributivo al 2026 | B6: ='4-Montanti'!$B$9 | C6: ='4-Montanti'!$C$9
A7: Anni di contribuzione dopo il 2026 | B7: ='1-Input'!$B$50 | C7: ='1-Input'!$B$50
A8: Anno di decorrenza (requisito anagrafico incluso) | B8: ='1-Input'!$B$51+'1-Input'!$B$22 | C8: ='1-Input'!$B$52+'1-Input'!$B$22
A9: Mese di decorrenza | B9: ='1-Input'!$C$51 | C9: ='1-Input'!$C$52
A10: Anni di sola rivalutazione fino alla decorrenza (ar) | B10: =B8-('1-Input'!$C$16+1)+(B9-1)/12-B7 | C10: =C8-('1-Input'!$C$16+1)+(C9-1)/12-C7
A11: Montante alla decorrenza | B11: =(B6*(1+'1-Input'!$B$21)^B7+'1-Input'!$B$48*(IF('1-Input'!$B$21=0,B7,((1+'1-Input'!$B$21)^B7-1)/'1-Input'!$B$21)))*(1+'1-Input'!$B$21)^B10 | C11: =(C6*(1+'1-Input'!$B$21)^C7+'1-Input'!$C$48*(IF('1-Input'!$B$21=0,C7,((1+'1-Input'!$B$21)^C7-1)/'1-Input'!$B$21)))*(1+'1-Input'!$B$21)^C10
A12: Coefficiente di trasformazione | B12: ='P-Parametri'!$B$21 | C12: ='P-Parametri'!$B$21
A13: PENSIONE LORDA annua | B13: =B11*B12 | C13: =C11*C12
A14: Pensione lorda mensile | B14: =B13/'P-Parametri'!$B$20 | C14: =C13/'P-Parametri'!$B$20
A15: IRPEF lorda | B15: =IF(B13<='P-Parametri'!$B$6,'P-Parametri'!$C$6*B13,IF(B13<='P-Parametri'!$B$7,'P-Parametri'!$B$9+'P-Parametri'!$C$7*(B13-'P-Parametri'!$B$6),'P-Parametri'!$B$10+'P-Parametri'!$C$8*(B13-'P-Parametri'!$B$7))) | C15: =IF(C13<='P-Parametri'!$B$6,'P-Parametri'!$C$6*C13,IF(C13<='P-Parametri'!$B$7,'P-Parametri'!$B$9+'P-Parametri'!$C$7*(C13-'P-Parametri'!$B$6),'P-Parametri'!$B$10+'P-Parametri'!$C$8*(C13-'P-Parametri'!$B$7)))
A16: Detrazione da pensione (art. 13 c. 3 + comma 3-bis) | B16: =IF(B13<='P-Parametri'!$C$12,'P-Parametri'!$B$12,IF(B13<='P-Parametri'!$B$6,'P-Parametri'!$B$13+'P-Parametri'!$C$13*('P-Parametri'!$B$6-B13)/'P-Parametri'!$D$13,IF(B13<='P-Parametri'!$B$7,'P-Parametri'!$B$14*('P-Parametri'!$B$7-B13)/'P-Parametri'!$C$14,0)))+IF(AND(B13>'P-Parametri'!$C$15,B13<'P-Parametri'!$D$15),'P-Parametri'!$B$15,0) | C16: =IF(C13<='P-Parametri'!$C$12,'P-Parametri'!$B$12,IF(C13<='P-Parametri'!$B$6,'P-Parametri'!$B$13+'P-Parametri'!$C$13*('P-Parametri'!$B$6-C13)/'P-Parametri'!$D$13,IF(C13<='P-Parametri'!$B$7,'P-Parametri'!$B$14*('P-Parametri'!$B$7-C13)/'P-Parametri'!$C$14,0)))+IF(AND(C13>'P-Parametri'!$C$15,C13<'P-Parametri'!$D$15),'P-Parametri'!$B$15,0)
A17: Addizionali (non dovute se l'IRPEF netta e' zero) | B17: =IF(MAX(0,B15-B16)<=0,0,'P-Parametri'!$B$11*B13) | C17: =IF(MAX(0,C15-C16)<=0,0,'P-Parametri'!$B$11*C13)
A18: PENSIONE NETTA annua | B18: =B13-MAX(0,B15-B16)-B17 | C18: =C13-MAX(0,C15-C16)-C17
A19: Frazione della prima annualita' (mezza se la decorrenza non e' di gennaio) | B19: =IF(B9=1,1,'P-Parametri'!$B$59) | C19: =IF(C9=1,1,'P-Parametri'!$B$59)
A20: PENSIONI NETTE DI COPPIA (a regime) | B20: =B18+C18
A21: Copertura della spesa di coppia | B21: =B20/'1-Input'!$B$13
A22: Gap di coda (spesa − pensioni) | B22: ='1-Input'!$B$13-B20
A24: SCENARIO B — la via contributiva intorno ai 65 anni (art. 24 c. 11)
A25: Voce | B25: Chiara | C25: Marito
A26: Anno di decorrenza | B26: ='1-Input'!$B$53 | C26: ='1-Input'!$B$54
A27: Mese di decorrenza | B27: ='1-Input'!$C$53 | C27: ='1-Input'!$C$54
A28: Coefficiente interpolato fra 65 e 66 anni | B28: ='1-Input'!$B$55 | C28: ='1-Input'!$C$55
A29: Anni di sola rivalutazione fino alla decorrenza | B29: =B26-('1-Input'!$C$16+1)+(B27-1)/12-B7 | C29: =C26-('1-Input'!$C$16+1)+(C27-1)/12-C7
A30: Montante alla decorrenza | B30: =(B6*(1+'1-Input'!$B$21)^B7+'1-Input'!$B$48*(IF('1-Input'!$B$21=0,B7,((1+'1-Input'!$B$21)^B7-1)/'1-Input'!$B$21)))*(1+'1-Input'!$B$21)^B29 | C30: =(C6*(1+'1-Input'!$B$21)^C7+'1-Input'!$C$48*(IF('1-Input'!$B$21=0,C7,((1+'1-Input'!$B$21)^C7-1)/'1-Input'!$B$21)))*(1+'1-Input'!$B$21)^C29
A31: PENSIONE LORDA annua | B31: =B30*B28 | C31: =C30*C28
A32: Pensione lorda mensile | B32: =B31/'P-Parametri'!$B$20 | C32: =C31/'P-Parametri'!$B$20
A33: Soglia di 3,2 volte l'assegno sociale (€/mese) | B33: ='P-Parametri'!$B$25 | C33: ='P-Parametri'!$B$25
A34: Verifica di soglia: l'importo e' sopra? | B34: =IF(B32>=B33,"SI","NO") | C34: =IF(C32>=C33,"SI","NO")
A35: Margine sopra la soglia | B35: =B32/B33-1 | C35: =C32/C33-1
A36: Cap di 5 volte il trattamento minimo — l'importo resta sotto? | B36: =IF(B32<='P-Parametri'!$B$26,"SI","NO") | C36: =IF(C32<='P-Parametri'!$B$26,"SI","NO")
A37: IRPEF lorda | B37: =IF(B31<='P-Parametri'!$B$6,'P-Parametri'!$C$6*B31,IF(B31<='P-Parametri'!$B$7,'P-Parametri'!$B$9+'P-Parametri'!$C$7*(B31-'P-Parametri'!$B$6),'P-Parametri'!$B$10+'P-Parametri'!$C$8*(B31-'P-Parametri'!$B$7))) | C37: =IF(C31<='P-Parametri'!$B$6,'P-Parametri'!$C$6*C31,IF(C31<='P-Parametri'!$B$7,'P-Parametri'!$B$9+'P-Parametri'!$C$7*(C31-'P-Parametri'!$B$6),'P-Parametri'!$B$10+'P-Parametri'!$C$8*(C31-'P-Parametri'!$B$7)))
A38: Detrazione da pensione (art. 13 c. 3 + comma 3-bis) | B38: =IF(B31<='P-Parametri'!$C$12,'P-Parametri'!$B$12,IF(B31<='P-Parametri'!$B$6,'P-Parametri'!$B$13+'P-Parametri'!$C$13*('P-Parametri'!$B$6-B31)/'P-Parametri'!$D$13,IF(B31<='P-Parametri'!$B$7,'P-Parametri'!$B$14*('P-Parametri'!$B$7-B31)/'P-Parametri'!$C$14,0)))+IF(AND(B31>'P-Parametri'!$C$15,B31<'P-Parametri'!$D$15),'P-Parametri'!$B$15,0) | C38: =IF(C31<='P-Parametri'!$C$12,'P-Parametri'!$B$12,IF(C31<='P-Parametri'!$B$6,'P-Parametri'!$B$13+'P-Parametri'!$C$13*('P-Parametri'!$B$6-C31)/'P-Parametri'!$D$13,IF(C31<='P-Parametri'!$B$7,'P-Parametri'!$B$14*('P-Parametri'!$B$7-C31)/'P-Parametri'!$C$14,0)))+IF(AND(C31>'P-Parametri'!$C$15,C31<'P-Parametri'!$D$15),'P-Parametri'!$B$15,0)
A39: Addizionali | B39: =IF(MAX(0,B37-B38)<=0,0,'P-Parametri'!$B$11*B31) | C39: =IF(MAX(0,C37-C38)<=0,0,'P-Parametri'!$B$11*C31)
A40: PENSIONE NETTA annua | B40: =B31-MAX(0,B37-B38)-B39 | C40: =C31-MAX(0,C37-C38)-C39
A41: Frazione della prima annualita' | B41: =IF(B27=1,1,'P-Parametri'!$B$59) | C41: =IF(C27=1,1,'P-Parametri'!$B$59)
A42: PENSIONI NETTE DI COPPIA (a regime) | B42: =B40+C40
...

Sheet 6-TFR
A1: Il TFR di coppia
A2: Strumento informativo / divulgativo. NON è consulenza finanziaria. I valori sono indicativi al 2026 e vanno verificati col tuo consulente.
A4: IL TFR AL RITIRO E LA TASSAZIONE SEPARATA
A5: Voce | B5: Chiara | C5: Marito | D5: Coppia
A6: Anzianita' TFR al ritiro (anni) | B6: ='1-Input'!$B$23 | C6: ='1-Input'!$C$23
A7: TFR lordo maturato al ritiro | B7: ='1-Input'!$B$24 | C7: ='1-Input'!$C$24 | D7: =B7+C7
A8: Reddito di riferimento (TFR / anzianita' × 12) | B8: =B7/B6*12 | C8: =C7/C6*12
A9: Aliquota della tassazione separata (aliquota media IRPEF 2026) | B9: =(IF(B8<='P-Parametri'!$B$6,'P-Parametri'!$C$6*B8,IF(B8<='P-Parametri'!$B$7,'P-Parametri'!$B$9+'P-Parametri'!$C$7*(B8-'P-Parametri'!$B$6),'P-Parametri'!$B$10+'P-Parametri'!$C$8*(B8-'P-Parametri'!$B$7))))/B8 | C9: =(IF(C8<='P-Parametri'!$B$6,'P-Parametri'!$C$6*C8,IF(C8<='P-Parametri'!$B$7,'P-Parametri'!$B$9+'P-Parametri'!$C$7*(C8-'P-Parametri'!$B$6),'P-Parametri'!$B$10+'P-Parametri'!$C$8*(C8-'P-Parametri'!$B$7))))/C8
A10: TFR NETTO al ritiro | B10: =B7*(1-B9) | C10: =C7*(1-C9) | D10: =B10+C10
A12: Banda del ±15% sul TFR netto — minimo / centrale / massimo | B12: =D10*0.85 | C12: =D10 | D12: =D10*1.15
A14: IL TFR SE SI LAVORA UNO O DUE ANNI IN PIU'
A15: Voce | B15: Al ritiro | C15: +1 anno | D15: +2 anni
A16: Quota annua di Chiara (reddito di riferimento / 13,5) | B16: =B8/'P-Parametri'!$B$34
A17: Quota annua del marito (retribuzione di riferimento / 13,5) | B17: ='1-Input'!$B$25/'P-Parametri'!$B$34
A18: TFR lordo di Chiara | B18: =B7 | C18: =B18*(1+'1-Input'!$C$25)+$B$16 | D18: =C18*(1+'1-Input'!$C$25)+$B$16
A19: TFR lordo del marito | B19: =C7 | C19: =B19*(1+'1-Input'!$C$25)+$B$17 | D19: =C19*(1+'1-Input'!$C$25)+$B$17
A20: Anzianita' di Chiara | B20: =B6 | C20: =B20+1 | D20: =C20+1
A21: Anzianita' del marito | B21: =C6 | C21: =B21+1 | D21: =C21+1
A22: TFR netto di Chiara | B22: =B18*(1-(IF((B18/B20*12)<='P-Parametri'!$B$6,'P-Parametri'!$C$6*(B18/B20*12),IF((B18/B20*12)<='P-Parametri'!$B$7,'P-Parametri'!$B$9+'P-Parametri'!$C$7*((B18/B20*12)-'P-Parametri'!$B$6),'P-Parametri'!$B$10+'P-Parametri'!$C$8*((B18/B20*12)-'P-Parametri'!$B$7))))/(B18/B20*12)) | C22: =C18*(1-(IF((C18/C20*12)<='P-Parametri'!$B$6,'P-Parametri'!$C$6*(C18/C20*12),IF((C18/C20*12)<='P-Parametri'!$B$7,'P-Parametri'!$B$9+'P-Parametri'!$C$7*((C18/C20*12)-'P-Parametri'!$B$6),'P-Parametri'!$B$10+'P-Parametri'!$C$8*((C18/C20*12)-'P-Parametri'!$B$7))))/(C18/C20*12)) | D22: =D18*(1-(IF((D18/D20*12)<='P-Parametri'!$B$6,'P-Parametri'!$C$6*(D18/D20*12),IF((D18/D20*12)<='P-Parametri'!$B$7,'P-Parametri'!$B$9+'P-Parametri'!$C$7*((D18/D20*12)-'P-Parametri'!$B$6),'P-Parametri'!$B$10+'P-Parametri'!$C$8*((D18/D20*12)-'P-Parametri'!$B$7))))/(D18/D20*12))
A23: TFR netto del marito | B23: =B19*(1-(IF((B19/B21*12)<='P-Parametri'!$B$6,'P-Parametri'!$C$6*(B19/B21*12),IF((B19/B21*12)<='P-Parametri'!$B$7,'P-Parametri'!$B$9+'P-Parametri'!$C$7*((B19/B21*12)-'P-Parametri'!$B$6),'P-Parametri'!$B$10+'P-Parametri'!$C$8*((B19/B21*12)-'P-Parametri'!$B$7))))/(B19/B21*12)) | C23: =C19*(1-(IF((C19/C21*12)<='P-Parametri'!$B$6,'P-Parametri'!$C$6*(C19/C21*12),IF((C19/C21*12)<='P-Parametri'!$B$7,'P-Parametri'!$B$9+'P-Parametri'!$C$7*((C19/C21*12)-'P-Parametri'!$B$6),'P-Parametri'!$B$10+'P-Parametri'!$C$8*((C19/C21*12)-'P-Parametri'!$B$7))))/(C19/C21*12)) | D23: =D19*(1-(IF((D19/D21*12)<='P-Parametri'!$B$6,'P-Parametri'!$C$6*(D19/D21*12),IF((D19/D21*12)<='P-Parametri'!$B$7,'P-Parametri'!$B$9+'P-Parametri'!$C$7*((D19/D21*12)-'P-Parametri'!$B$6),'P-Parametri'!$B$10+'P-Parametri'!$C$8*((D19/D21*12)-'P-Parametri'!$B$7))))/(D19/D21*12))
A24: TFR NETTO DI COPPIA — la risorsa che il motore usa | B24: =IF('1-Input'!$B$26=1,B22+B23,(B18+B19)*(1-'P-Parametri'!$C$35)) | C24: =IF('1-Input'!$B$26=1,C22+C23,(C18+C19)*(1-'P-Parametri'!$C$35)) | D24: =IF('1-Input'!$B$26=1,D22+D23,(D18+D19)*(1-'P-Parametri'!$C$35))
A26: IL TFR CONFERITO AL FONDO PENSIONE — vale PIU' della cassa
A27: TFR lordo di coppia al ritiro | B27: =D7
A28: Netto con la ritenuta iniziale del 15% | B28: =B27*(1-'P-Parametri'!$B$35)
A29: Netto con la ritenuta a regime del 9% | B29: =B27*(1-'P-Parametri'!$C$35)
A30: Differenza contro la cassa (ritenuta a regime) | B30: =B29-D10
A32: CLAUSOLA DI SALVAGUARDIA — scaglioni 2006 (art. 21 c. 11 D.Lgs. 117/2026)
A33: Voce | B33: Chiara | C33: Marito
A34: Reddito di riferimento | B34: =B8 | C34: =C8
A35: Aliquota con gli scaglioni 2006 | B35: =(IF(B34<='P-Parametri'!$B$37,'P-Parametri'!$C$37*B34,IF(B34<='P-Parametri'!$B$38,'P-Parametri'!$C$37*'P-Parametri'!$B$37+'P-Parametri'!$C$38*(B34-'P-Parametri'!$B$37),IF(B34<='P-Parametri'!$B$39,'P-Parametri'!$C$37*'P-Parametri'!$B$37+'P-Parametri'!$C$38*('P-Parametri'!$B$38-'P-Parametri'!$B$37)+'P-Parametri'!$C$39*(B34-'P-Parametri'!$B$38),'P-Parametri'!$C$37*'P-Parametri'!$B$37+'P-Parametri'!$C$38*('P-Parametri'!$B$38-'P-Parametri'!$B$37)+'P-Parametri'!$C$39*('P-Parametri'!$B$39-'P-Parametri'!$B$38)+'P-Parametri'!$C$40*(B34-'P-Parametri'!$B$39)))))/B34 | C35: =(IF(C34<='P-Parametri'!$B$37,'P-Parametri'!$C$37*C34,IF(C34<='P-Parametri'!$B$38,'P-Parametri'!$C$37*'P-Parametri'!$B$37+'P-Parametri'!$C$38*(C34-'P-Parametri'!$B$37),IF(C34<='P-Parametri'!$B$39,'P-Parametri'!$C$37*'P-Parametri'!$B$37+'P-Parametri'!$C$38*('P-Parametri'!$B$38-'P-Parametri'!$B$37)+'P-Parametri'!$C$39*(C34-'P-Parametri'!$B$38),'P-Parametri'!$C$37*'P-Parametri'!$B$37+'P-Parametri'!$C$38*('P-Parametri'!$B$38-'P-Parametri'!$B$37)+'P-Parametri'!$C$39*('P-Parametri'!$B$39-'P-Parametri'!$B$38)+'P-Parametri'!$C$40*(C34-'P-Parametri'!$B$39)))))/C34
A36: Aliquota con l'IRPEF 2026 | B36: =B9 | C36: =C9
A37: Margine (punti percentuali) | B37: =(B35-B36)*100 | C37: =(C35-C36)*100
A38: La clausola morde su questo profilo? | B38: =IF(B35<B36,"SI","NO") | C38: =IF(C35<C36,"SI","NO")
A40: IL TFR E' GIA' NETTO E NON SI LORDIZZA. La tassazione separata e' gia' scontata alla liquidazione: per portare in tasca un euro di TFR non si vende nulla, quindi non c'e' imposta sulla plusvalenza. Un euro di TFR risparmia al portafoglio G euro di capitale, non uno: e' per questo che nel waterfall il gradino della liquidazione si scrive in CAPITALE (netto × G) e non in netto.
A41: Il TFR e' STIMATO, non calcolato sulla serie: anzianita', retribuzioni di riferimento e rivalutazione reale sono ipotesi dichiarate, e l'aliquota separata e' applicata all'intero montante invece che alle sole quote. Ampiezza plausibile ±15% (riga 12), su un numero che vale circa meta' del fabbisogno.
A42: La retribuzione media di riferimento del marito per il TFR (34.000) e' una grandezza DIVERSA dalla sua media di carriera previdenziale (30.000) e dalla sua retribuzione attuale (48.000): la prima e' la media dell'ultimo rapporto di lavoro rivalutata, la seconda e' la media di tutta la carriera.
A43: Il margine della clausola di salvaguardia e' di circa un punto sul profilo del marito: «non morde SU QUESTI DUE PROFILI», non «non morde». Le ipotesi su anzianita' e retribuzione di riferimento (±15%) se lo mangerebbero.
A44: Il conferimento al fondo pensione (ritenuta dal 15% scalata al 9%) vale PIU' della cassa: la riga non entra nella banda del fabbisogno, perche' quella banda misura il rischio e questa voce lo abbassa. Rimando a fondo_pensione_guida.

Sheet 7-Fabbisogno
A1: Ponte, coda e fabbisogno al ritiro
A2: Strumento informativo / divulgativo. NON è consulenza finanziaria. I valori sono indicativi al 2026 e vanno verificati col tuo consulente.
A4: IL FLUSSO ANNO PER ANNO — il ponte e la coda
A5: Anno | B5: Eta' di Chiara | C5: Pensione del marito | D5: Pensione di Chiara | E5: Pensioni totali | F5: Spesa | G5: Fabbisogno netto | H5: Fattore di sconto | I5: Valore attuale | K5: Anno | L5: Pensioni (stop oggi) | M5: Fabbisogno netto | N5: Valore attuale
A6: ='1-Input'!$B$19+1 | B6: =$A6-'1-Input'!$B$5 | C6: =IF($A6>'1-Input'!$B$47,0,IF($A6<'5-Pensioni'!$C$8,0,IF($A6='5-Pensioni'!$C$8,'5-Pensioni'!$C$18*'5-Pensioni'!$C$19,'5-Pensioni'!$C$18))) | D6: =IF($A6>'1-Input'!$B$47,0,IF($A6<'5-Pensioni'!$B$8,0,IF($A6='5-Pensioni'!$B$8,'5-Pensioni'!$B$18*'5-Pensioni'!$B$19,'5-Pensioni'!$B$18))) | E6: =C6+D6 | F6: =IF($A6>'1-Input'!$B$47,0,'1-Input'!$B$13) | G6: =F6-E6 | H6: =IF($A6>'1-Input'!$B$47,0,1/(1+'1-Input'!$B$46)^($A6-'1-Input'!$B$19-1)) | I6: =G6*H6 | K6: ='1-Input'!$C$16+1 | L6: =IF($K6>'1-Input'!$B$47,0,IF($K6<'5-Pensioni'!$C$8,0,IF($K6='5-Pensioni'!$C$8,'5-Pensioni'!$C$54*'5-Pensioni'!$C$19,'5-Pensioni'!$C$54))+IF($K6<'5-Pensioni'!$B$8,0,IF($K6='5-Pensioni'!$B$8,'5-Pensioni'!$B$54*'5-Pensioni'!$B$19,'5-Pensioni'!$B$54))) | M6: =IF($K6>'1-Input'!$B$47,0,'1-Input'!$B$13-L6) | N6: =IF($K6>'1-Input'!$B$47,0,M6/(1+'1-Input'!$B$46)^($K6-'1-Input'!$C$16-1))
A7: =A6+1 | B7: =$A7-'1-Input'!$B$5 | C7: =IF($A7>'1-Input'!$B$47,0,IF($A7<'5-Pensioni'!$C$8,0,IF($A7='5-Pensioni'!$C$8,'5-Pensioni'!$C$18*'5-Pensioni'!$C$19,'5-Pensioni'!$C$18))) | D7: =IF($A7>'1-Input'!$B$47,0,IF($A7<'5-Pensioni'!$B$8,0,IF($A7='5-Pensioni'!$B$8,'5-Pensioni'!$B$18*'5-Pensioni'!$B$19,'5-Pensioni'!$B$18))) | E7: =C7+D7 | F7: =IF($A7>'1-Input'!$B$47,0,'1-Input'!$B$13) | G7: =F7-E7 | H7: =IF($A7>'1-Input'!$B$47,0,1/(1+'1-Input'!$B$46)^($A7-'1-Input'!$B$19-1)) | I7: =G7*H7 | K7: =K6+1 | L7: =IF($K7>'1-Input'!$B$47,0,IF($K7<'5-Pensioni'!$C$8,0,IF($K7='5-Pensioni'!$C$8,'5-Pensioni'!$C$54*'5-Pensioni'!$C$19,'5-Pensioni'!$C$54))+IF($K7<'5-Pensioni'!$B$8,0,IF($K7='5-Pensioni'!$B$8,'5-Pensioni'!$B$54*'5-Pensioni'!$B$19,'5-Pensioni'!$B$54))) | M7: =IF($K7>'1-Input'!$B$47,0,'1-Input'!$B$13-L7) | N7: =IF($K7>'1-Input'!$B$47,0,M7/(1+'1-Input'!$B$46)^($K7-'1-Input'!$C$16-1))
A8: =A7+1 | B8: =$A8-'1-Input'!$B$5 | C8: =IF($A8>'1-Input'!$B$47,0,IF($A8<'5-Pensioni'!$C$8,0,IF($A8='5-Pensioni'!$C$8,'5-Pensioni'!$C$18*'5-Pensioni'!$C$19,'5-Pensioni'!$C$18))) | D8: =IF($A8>'1-Input'!$B$47,0,IF($A8<'5-Pensioni'!$B$8,0,IF($A8='5-Pensioni'!$B$8,'5-Pensioni'!$B$18*'5-Pensioni'!$B$19,'5-Pensioni'!$B$18))) | E8: =C8+D8 | F8: =IF($A8>'1-Input'!$B$47,0,'1-Input'!$B$13) | G8: =F8-E8 | H8: =IF($A8>'1-Input'!$B$47,0,1/(1+'1-Input'!$B$46)^($A8-'1-Input'!$B$19-1)) | I8: =G8*H8 | K8: =K7+1 | L8: =IF($K8>'1-Input'!$B$47,0,IF($K8<'5-Pensioni'!$C$8,0,IF($K8='5-Pensioni'!$C$8,'5-Pensioni'!$C$54*'5-Pensioni'!$C$19,'5-Pensioni'!$C$54))+IF($K8<'5-Pensioni'!$B$8,0,IF($K8='5-Pensioni'!$B$8,'5-Pensioni'!$B$54*'5-Pensioni'!$B$19,'5-Pensioni'!$B$54))) | M8: =IF($K8>'1-Input'!$B$47,0,'1-Input'!$B$13-L8) | N8: =IF($K8>'1-Input'!$B$47,0,M8/(1+'1-Input'!$B$46)^($K8-'1-Input'!$C$16-1))
A9: =A8+1 | B9: =$A9-'1-Input'!$B$5 | C9: =IF($A9>'1-Input'!$B$47,0,IF($A9<'5-Pensioni'!$C$8,0,IF($A9='5-Pensioni'!$C$8,'5-Pensioni'!$C$18*'5-Pensioni'!$C$19,'5-Pensioni'!$C$18))) | D9: =IF($A9>'1-Input'!$B$47,0,IF($A9<'5-Pensioni'!$B$8,0,IF($A9='5-Pensioni'!$B$8,'5-Pensioni'!$B$18*'5-Pensioni'!$B$19,'5-Pensioni'!$B$18))) | E9: =C9+D9 | F9: =IF($A9>'1-Input'!$B$47,0,'1-Input'!$B$13) | G9: =F9-E9 | H9: =IF($A9>'1-Input'!$B$47,0,1/(1+'1-Input'!$B$46)^($A9-'1-Input'!$B$19-1)) | I9: =G9*H9 | K9: =K8+1 | L9: =IF($K9>'1-Input'!$B$47,0,IF($K9<'5-Pensioni'!$C$8,0,IF($K9='5-Pensioni'!$C$8,'5-Pensioni'!$C$54*'5-Pensioni'!$C$19,'5-Pensioni'!$C$54))+IF($K9<'5-Pensioni'!$B$8,0,IF($K9='5-Pensioni'!$B$8,'5-Pensioni'!$B$54*'5-Pensioni'!$B$19,'5-Pensioni'!$B$54))) | M9: =IF($K9>'1-Input'!$B$47,0,'1-Input'!$B$13-L9) | N9: =IF($K9>'1-Input'!$B$47,0,M9/(1+'1-Input'!$B$46)^($K9-'1-Input'!$C$16-1))
A10: =A9+1 | B10: =$A10-'1-Input'!$B$5 | C10: =IF($A10>'1-Input'!$B$47,0,IF($A10<'5-Pensioni'!$C$8,0,IF($A10='5-Pensioni'!$C$8,'5-Pensioni'!$C$18*'5-Pensioni'!$C$19,'5-Pensioni'!$C$18))) | D10: =IF($A10>'1-Input'!$B$47,0,IF($A10<'5-Pensioni'!$B$8,0,IF($A10='5-Pensioni'!$B$8,'5-Pensioni'!$B$18*'5-Pensioni'!$B$19,'5-Pensioni'!$B$18))) | E10: =C10+D10 | F10: =IF($A10>'1-Input'!$B$47,0,'1-Input'!$B$13) | G10: =F10-E10 | H10: =IF($A10>'1-Input'!$B$47,0,1/(1+'1-Input'!$B$46)^($A10-'1-Input'!$B$19-1)) | I10: =G10*H10 | K10: =K9+1 | L10: =IF($K10>'1-Input'!$B$47,0,IF($K10<'5-Pensioni'!$C$8,0,IF($K10='5-Pensioni'!$C$8,'5-Pensioni'!$C$54*'5-Pensioni'!$C$19,'5-Pensioni'!$C$54))+IF($K10<'5-Pensioni'!$B$8,0,IF($K10='5-Pensioni'!$B$8,'5-Pensioni'!$B$54*'5-Pensioni'!$B$19,'5-Pensioni'!$B$54))) | M10: =IF($K10>'1-Input'!$B$47,0,'1-Input'!$B$13-L10) | N10: =IF($K10>'1-Input'!$B$47,0,M10/(1+'1-Input'!$B$46)^($K10-'1-Input'!$C$16-1))
A11: =A10+1 | B11: =$A11-'1-Input'!$B$5 | C11: =IF($A11>'1-Input'!$B$47,0,IF($A11<'5-Pensioni'!$C$8,0,IF($A11='5-Pensioni'!$C$8,'5-Pensioni'!$C$18*'5-Pensioni'!$C$19,'5-Pensioni'!$C$18))) | D11: =IF($A11>'1-Input'!$B$47,0,IF($A11<'5-Pensioni'!$B$8,0,IF($A11='5-Pensioni'!$B$8,'5-Pensioni'!$B$18*'5-Pensioni'!$B$19,'5-Pensioni'!$B$18))) | E11: =C11+D11 | F11: =IF($A11>'1-Input'!$B$47,0,'1-Input'!$B$13) | G11: =F11-E11 | H11: =IF($A11>'1-Input'!$B$47,0,1/(1+'1-Input'!$B$46)^($A11-'1-Input'!$B$19-1)) | I11: =G11*H11 | K11: =K10+1 | L11: =IF($K11>'1-Input'!$B$47,0,IF($K11<'5-Pensioni'!$C$8,0,IF($K11='5-Pensioni'!$C$8,'5-Pensioni'!$C$54*'5-Pensioni'!$C$19,'5-Pensioni'!$C$54))+IF($K11<'5-Pensioni'!$B$8,0,IF($K11='5-Pensioni'!$B$8,'5-Pensioni'!$B$54*'5-Pensioni'!$B$19,'5-Pensioni'!$B$54))) | M11: =IF($K11>'1-Input'!$B$47,0,'1-Input'!$B$13-L11) | N11: =IF($K11>'1-Input'!$B$47,0,M11/(1+'1-Input'!$B$46)^($K11-'1-Input'!$C$16-1))
A12: =A11+1 | B12: =$A12-'1-Input'!$B$5 | C12: =IF($A12>'1-Input'!$B$47,0,IF($A12<'5-Pensioni'!$C$8,0,IF($A12='5-Pensioni'!$C$8,'5-Pensioni'!$C$18*'5-Pensioni'!$C$19,'5-Pensioni'!$C$18))) | D12: =IF($A12>'1-Input'!$B$47,0,IF($A12<'5-Pensioni'!$B$8,0,IF($A12='5-Pensioni'!$B$8,'5-Pensioni'!$B$18*'5-Pensioni'!$B$19,'5-Pensioni'!$B$18))) | E12: =C12+D12 | F12: =IF($A12>'1-Input'!$B$47,0,'1-Input'!$B$13) | G12: =F12-E12 | H12: =IF($A12>'1-Input'!$B$47,0,1/(1+'1-Input'!$B$46)^($A12-'1-Input'!$B$19-1)) | I12: =G12*H12 | K12: =K11+1 | L12: =IF($K12>'1-Input'!$B$47,0,IF($K12<'5-Pensioni'!$C$8,0,IF($K12='5-Pensioni'!$C$8,'5-Pensioni'!$C$54*'5-Pensioni'!$C$19,'5-Pensioni'!$C$54))+IF($K12<'5-Pensioni'!$B$8,0,IF($K12='5-Pensioni'!$B$8,'5-Pensioni'!$B$54*'5-Pensioni'!$B$19,'5-Pensioni'!$B$54))) | M12: =IF($K12>'1-Input'!$B$47,0,'1-Input'!$B$13-L12) | N12: =IF($K12>'1-Input'!$B$47,0,M12/(1+'1-Input'!$B$46)^($K12-'1-Input'!$C$16-1))
A13: =A12+1 | B13: =$A13-'1-Input'!$B$5 | C13: =IF($A13>'1-Input'!$B$47,0,IF($A13<'5-Pensioni'!$C$8,0,IF($A13='5-Pensioni'!$C$8,'5-Pensioni'!$C$18*'5-Pensioni'!$C$19,'5-Pensioni'!$C$18))) | D13: =IF($A13>'1-Input'!$B$47,0,IF($A13<'5-Pensioni'!$B$8,0,IF($A13='5-Pensioni'!$B$8,'5-Pensioni'!$B$18*'5-Pensioni'!$B$19,'5-Pensioni'!$B$18))) | E13: =C13+D13 | F13: =IF($A13>'1-Input'!$B$47,0,'1-Input'!$B$13) | G13: =F13-E13 | H13: =IF($A13>'1-Input'!$B$47,0,1/(1+'1-Input'!$B$46)^($A13-'1-Input'!$B$19-1)) | I13: =G13*H13 | K13: =K12+1 | L13: =IF($K13>'1-Input'!$B$47,0,IF($K13<'5-Pensioni'!$C$8,0,IF($K13='5-Pensioni'!$C$8,'5-Pensioni'!$C$54*'5-Pensioni'!$C$19,'5-Pensioni'!$C$54))+IF($K13<'5-Pensioni'!$B$8,0,IF($K13='5-Pensioni'!$B$8,'5-Pensioni'!$B$54*'5-Pensioni'!$B$19,'5-Pensioni'!$B$54))) | M13: =IF($K13>'1-Input'!$B$47,0,'1-Input'!$B$13-L13) | N13: =IF($K13>'1-Input'!$B$47,0,M13/(1+'1-Input'!$B$46)^($K13-'1-Input'!$C$16-1))
A14: =A13+1 | B14: =$A14-'1-Input'!$B$5 | C14: =IF($A14>'1-Input'!$B$47,0,IF($A14<'5-Pensioni'!$C$8,0,IF($A14='5-Pensioni'!$C$8,'5-Pensioni'!$C$18*'5-Pensioni'!$C$19,'5-Pensioni'!$C$18))) | D14: =IF($A14>'1-Input'!$B$47,0,IF($A14<'5-Pensioni'!$B$8,0,IF($A14='5-Pensioni'!$B$8,'5-Pensioni'!$B$18*'5-Pensioni'!$B$19,'5-Pensioni'!$B$18))) | E14: =C14+D14 | F14: =IF($A14>'1-Input'!$B$47,0,'1-Input'!$B$13) | G14: =F14-E14 | H14: =IF($A14>'1-Input'!$B$47,0,1/(1+'1-Input'!$B$46)^($A14-'1-Input'!$B$19-1)) | I14: =G14*H14 | K14: =K13+1 | L14: =IF($K14>'1-Input'!$B$47,0,IF($K14<'5-Pensioni'!$C$8,0,IF($K14='5-Pensioni'!$C$8,'5-Pensioni'!$C$54*'5-Pensioni'!$C$19,'5-Pensioni'!$C$54))+IF($K14<'5-Pensioni'!$B$8,0,IF($K14='5-Pensioni'!$B$8,'5-Pensioni'!$B$54*'5-Pensioni'!$B$19,'5-Pensioni'!$B$54))) | M14: =IF($K14>'1-Input'!$B$47,0,'1-Input'!$B$13-L14) | N14: =IF($K14>'1-Input'!$B$47,0,M14/(1+'1-Input'!$B$46)^($K14-'1-Input'!$C$16-1))
A15: =A14+1 | B15: =$A15-'1-Input'!$B$5 | C15: =IF($A15>'1-Input'!$B$47,0,IF($A15<'5-Pensioni'!$C$8,0,IF($A15='5-Pensioni'!$C$8,'5-Pensioni'!$C$18*'5-Pensioni'!$C$19,'5-Pensioni'!$C$18))) | D15: =IF($A15>'1-Input'!$B$47,0,IF($A15<'5-Pensioni'!$B$8,0,IF($A15='5-Pensioni'!$B$8,'5-Pensioni'!$B$18*'5-Pensioni'!$B$19,'5-Pensioni'!$B$18))) | E15: =C15+D15 | F15: =IF($A15>'1-Input'!$B$47,0,'1-Input'!$B$13) | G15: =F15-E15 | H15: =IF($A15>'1-Input'!$B$47,0,1/(1+'1-Input'!$B$46)^($A15-'1-Input'!$B$19-1)) | I15: =G15*H15 | K15: =K14+1 | L15: =IF($K15>'1-Input'!$B$47,0,IF($K15<'5-Pensioni'!$C$8,0,IF($K15='5-Pensioni'!$C$8,'5-Pensioni'!$C$54*'5-Pensioni'!$C$19,'5-Pensioni'!$C$54))+IF($K15<'5-Pensioni'!$B$8,0,IF($K15='5-Pensioni'!$B$8,'5-Pensioni'!$B$54*'5-Pensioni'!$B$19,'5-Pensioni'!$B$54))) | M15: =IF($K15>'1-Input'!$B$47,0,'1-Input'!$B$13-L15) | N15: =IF($K15>'1-Input'!$B$47,0,M15/(1+'1-Input'!$B$46)^($K15-'1-Input'!$C$16-1))
A16: =A15+1 | B16: =$A16-'1-Input'!$B$5 | C16: =IF($A16>'1-Input'!$B$47,0,IF($A16<'5-Pensioni'!$C$8,0,IF($A16='5-Pensioni'!$C$8,'5-Pensioni'!$C$18*'5-Pensioni'!$C$19,'5-Pensioni'!$C$18))) | D16: =IF($A16>'1-Input'!$B$47,0,IF($A16<'5-Pensioni'!$B$8,0,IF($A16='5-Pensioni'!$B$8,'5-Pensioni'!$B$18*'5-Pensioni'!$B$19,'5-Pensioni'!$B$18))) | E16: =C16+D16 | F16: =IF($A16>'1-Input'!$B$47,0,'1-Input'!$B$13) | G16: =F16-E16 | H16: =IF($A16>'1-Input'!$B$47,0,1/(1+'1-Input'!$B$46)^($A16-'1-Input'!$B$19-1)) | I16: =G16*H16 | K16: =K15+1 | L16: =IF($K16>'1-Input'!$B$47,0,IF($K16<'5-Pensioni'!$C$8,0,IF($K16='5-Pensioni'!$C$8,'5-Pensioni'!$C$54*'5-Pensioni'!$C$19,'5-Pensioni'!$C$54))+IF($K16<'5-Pensioni'!$B$8,0,IF($K16='5-Pensioni'!$B$8,'5-Pensioni'!$B$54*'5-Pensioni'!$B$19,'5-Pensioni'!$B$54))) | M16: =IF($K16>'1-Input'!$B$47,0,'1-Input'!$B$13-L16) | N16: =IF($K16>'1-Input'!$B$47,0,M16/(1+'1-Input'!$B$46)^($K16-'1-Input'!$C$16-1))
A17: =A16+1 | B17: =$A17-'1-Input'!$B$5 | C17: =IF($A17>'1-Input'!$B$47,0,IF($A17<'5-Pensioni'!$C$8,0,IF($A17='5-Pensioni'!$C$8,'5-Pensioni'!$C$18*'5-Pensioni'!$C$19,'5-Pensioni'!$C$18))) | D17: =IF($A17>'1-Input'!$B$47,0,IF($A17<'5-Pensioni'!$B$8,0,IF($A17='5-Pensioni'!$B$8,'5-Pensioni'!$B$18*'5-Pensioni'!$B$19,'5-Pensioni'!$B$18))) | E17: =C17+D17 | F17: =IF($A17>'1-Input'!$B$47,0,'1-Input'!$B$13) | G17: =F17-E17 | H17: =IF($A17>'1-Input'!$B$47,0,1/(1+'1-Input'!$B$46)^($A17-'1-Input'!$B$19-1)) | I17: =G17*H17 | K17: =K16+1 | L17: =IF($K17>'1-Input'!$B$47,0,IF($K17<'5-Pensioni'!$C$8,0,IF($K17='5-Pensioni'!$C$8,'5-Pensioni'!$C$54*'5-Pensioni'!$C$19,'5-Pensioni'!$C$54))+IF($K17<'5-Pensioni'!$B$8,0,IF($K17='5-Pensioni'!$B$8,'5-Pensioni'!$B$54*'5-Pensioni'!$B$19,'5-Pensioni'!$B$54))) | M17: =IF($K17>'1-Input'!$B$47,0,'1-Input'!$B$13-L17) | N17: =IF($K17>'1-Input'!$B$47,0,M17/(1+'1-Input'!$B$46)^($K17-'1-Input'!$C$16-1))
A18: =A17+1 | B18: =$A18-'1-Input'!$B$5 | C18: =IF($A18>'1-Input'!$B$47,0,IF($A18<'5-Pensioni'!$C$8,0,IF($A18='5-Pensioni'!$C$8,'5-Pensioni'!$C$18*'5-Pensioni'!$C$19,'5-Pensioni'!$C$18))) | D18: =IF($A18>'1-Input'!$B$47,0,IF($A18<'5-Pensioni'!$B$8,0,IF($A18='5-Pensioni'!$B$8,'5-Pensioni'!$B$18*'5-Pensioni'!$B$19,'5-Pensioni'!$B$18))) | E18: =C18+D18 | F18: =IF($A18>'1-Input'!$B$47,0,'1-Input'!$B$13) | G18: =F18-E18 | H18: =IF($A18>'1-Input'!$B$47,0,1/(1+'1-Input'!$B$46)^($A18-'1-Input'!$B$19-1)) | I18: =G18*H18 | K18: =K17+1 | L18: =IF($K18>'1-Input'!$B$47,0,IF($K18<'5-Pensioni'!$C$8,0,IF($K18='5-Pensioni'!$C$8,'5-Pensioni'!$C$54*'5-Pensioni'!$C$19,'5-Pensioni'!$C$54))+IF($K18<'5-Pensioni'!$B$8,0,IF($K18='5-Pensioni'!$B$8,'5-Pensioni'!$B$54*'5-Pensioni'!$B$19,'5-Pensioni'!$B$54))) | M18: =IF($K18>'1-Input'!$B$47,0,'1-Input'!$B$13-L18) | N18: =IF($K18>'1-Input'!$B$47,0,M18/(1+'1-Input'!$B$46)^($K18-'1-Input'!$C$16-1))
... A39: =A38+1 | B39: =$A39-'1-Input'!$B$5 | C39: =IF($A39>'1-Input'!$B$47,0,IF($A39<'5-Pensioni'!$C$8,0,IF($A39='5-Pensioni'!$C$8,'5-Pensioni'!$C$18*'5-Pensioni'!$C$19,'5-Pensioni'!$C$18))) | D39: =IF($A39>'1-Input'!$B$47,0,IF($A39<'5-Pensioni'!$B$8,0,IF($A39='5-Pensioni'!$B$8,'5-Pensioni'!$B$18*'5-Pensioni'!$B$19,'5-Pensioni'!$B$18))) | E39: =C39+D39 | F39: =IF($A39>'1-Input'!$B$47,0,'1-Input'!$B$13) | G39: =F39-E39 | H39: =IF($A39>'1-Input'!$B$47,0,1/(1+'1-Input'!$B$46)^($A39-'1-Input'!$B$19-1)) | I39: =G39*H39 | K39: =K38+1 | L39: =IF($K39>'1-Input'!$B$47,0,IF($K39<'5-Pensioni'!$C$8,0,IF($K39='5-Pensioni'!$C$8,'5-Pensioni'!$C$54*'5-Pensioni'!$C$19,'5-Pensioni'!$C$54))+IF($K39<'5-Pensioni'!$B$8,0,IF($K39='5-Pensioni'!$B$8,'5-Pensioni'!$B$54*'5-Pensioni'!$B$19,'5-Pensioni'!$B$54))) | M39: =IF($K39>'1-Input'!$B$47,0,'1-Input'!$B$13-L39) | N39: =IF($K39>'1-Input'!$B$47,0,M39/(1+'1-Input'!$B$46)^($K39-'1-Input'!$C$16-1))
K40: =K39+1 | L40: =IF($K40>'1-Input'!$B$47,0,IF($K40<'5-Pensioni'!$C$8,0,IF($K40='5-Pensioni'!$C$8,'5-Pensioni'!$C$54*'5-Pensioni'!$C$19,'5-Pensioni'!$C$54))+IF($K40<'5-Pensioni'!$B$8,0,IF($K40='5-Pensioni'!$B$8,'5-Pensioni'!$B$54*'5-Pensioni'!$B$19,'5-Pensioni'!$B$54))) | M40: =IF($K40>'1-Input'!$B$47,0,'1-Input'!$B$13-L40) | N40: =IF($K40>'1-Input'!$B$47,0,M40/(1+'1-Input'!$B$46)^($K40-'1-Input'!$C$16-1))
A41: IL FABBISOGNO AL RITIRO — le due letture chiudono allo stesso numero | K41: =K40+1 | L41: =IF($K41>'1-Input'!$B$47,0,IF($K41<'5-Pensioni'!$C$8,0,IF($K41='5-Pensioni'!$C$8,'5-Pensioni'!$C$54*'5-Pensioni'!$C$19,'5-Pensioni'!$C$54))+IF($K41<'5-Pensioni'!$B$8,0,IF($K41='5-Pensioni'!$B$8,'5-Pensioni'!$B$54*'5-Pensioni'!$B$19,'5-Pensioni'!$B$54))) | M41: =IF($K41>'1-Input'!$B$47,0,'1-Input'!$B$13-L41) | N41: =IF($K41>'1-Input'!$B$47,0,M41/(1+'1-Input'!$B$46)^($K41-'1-Input'!$C$16-1))
A42: Capitale al ritiro | B42: ='2-Composizione'!$B$36*(1+'1-Input'!$B$46)^'1-Input'!$B$50+'1-Input'!$B$40*(1+'1-Input'!$B$46)*(((1+'1-Input'!$B$46)^'1-Input'!$B$50-1)/'1-Input'!$B$46) | K42: =K41+1 | L42: =IF($K42>'1-Input'!$B$47,0,IF($K42<'5-Pensioni'!$C$8,0,IF($K42='5-Pensioni'!$C$8,'5-Pensioni'!$C$54*'5-Pensioni'!$C$19,'5-Pensioni'!$C$54))+IF($K42<'5-Pensioni'!$B$8,0,IF($K42='5-Pensioni'!$B$8,'5-Pensioni'!$B$54*'5-Pensioni'!$B$19,'5-Pensioni'!$B$54))) | M42: =IF($K42>'1-Input'!$B$47,0,'1-Input'!$B$13-L42) | N42: =IF($K42>'1-Input'!$B$47,0,M42/(1+'1-Input'!$B$46)^($K42-'1-Input'!$C$16-1))
A43: Base di costo al ritiro | B43: ='2-Composizione'!$B$37+'1-Input'!$B$50*'1-Input'!$B$40 | K43: =K42+1 | L43: =IF($K43>'1-Input'!$B$47,0,IF($K43<'5-Pensioni'!$C$8,0,IF($K43='5-Pensioni'!$C$8,'5-Pensioni'!$C$54*'5-Pensioni'!$C$19,'5-Pensioni'!$C$54))+IF($K43<'5-Pensioni'!$B$8,0,IF($K43='5-Pensioni'!$B$8,'5-Pensioni'!$B$54*'5-Pensioni'!$B$19,'5-Pensioni'!$B$54))) | M43: =IF($K43>'1-Input'!$B$47,0,'1-Input'!$B$13-L43) | N43: =IF($K43>'1-Input'!$B$47,0,M43/(1+'1-Input'!$B$46)^($K43-'1-Input'!$C$16-1))
A44: Plusvalenza latente al ritiro (floor a zero) | B44: =MAX(0,(B42-B43)/B42) | K44: =K43+1 | L44: =IF($K44>'1-Input'!$B$47,0,IF($K44<'5-Pensioni'!$C$8,0,IF($K44='5-Pensioni'!$C$8,'5-Pensioni'!$C$54*'5-Pensioni'!$C$19,'5-Pensioni'!$C$54))+IF($K44<'5-Pensioni'!$B$8,0,IF($K44='5-Pensioni'!$B$8,'5-Pensioni'!$B$54*'5-Pensioni'!$B$19,'5-Pensioni'!$B$54))) | M44: =IF($K44>'1-Input'!$B$47,0,'1-Input'!$B$13-L44) | N44: =IF($K44>'1-Input'!$B$47,0,M44/(1+'1-Input'!$B$46)^($K44-'1-Input'!$C$16-1))
A45: Fattore di lordizzazione G al ritiro | B45: =1/(1-'P-Parametri'!$B$31*B44) | K45: =K44+1 | L45: =IF($K45>'1-Input'!$B$47,0,IF($K45<'5-Pensioni'!$C$8,0,IF($K45='5-Pensioni'!$C$8,'5-Pensioni'!$C$54*'5-Pensioni'!$C$19,'5-Pensioni'!$C$54))+IF($K45<'5-Pensioni'!$B$8,0,IF($K45='5-Pensioni'!$B$8,'5-Pensioni'!$B$54*'5-Pensioni'!$B$19,'5-Pensioni'!$B$54))) | M45: =IF($K45>'1-Input'!$B$47,0,'1-Input'!$B$13-L45) | N45: =IF($K45>'1-Input'!$B$47,0,M45/(1+'1-Input'!$B$46)^($K45-'1-Input'!$C$16-1))
A46: Valore attuale netto del fabbisogno | B46: =SUM(I6:I39) | K46: =K45+1 | L46: =IF($K46>'1-Input'!$B$47,0,IF($K46<'5-Pensioni'!$C$8,0,IF($K46='5-Pensioni'!$C$8,'5-Pensioni'!$C$54*'5-Pensioni'!$C$19,'5-Pensioni'!$C$54))+IF($K46<'5-Pensioni'!$B$8,0,IF($K46='5-Pensioni'!$B$8,'5-Pensioni'!$B$54*'5-Pensioni'!$B$19,'5-Pensioni'!$B$54))) | M46: =IF($K46>'1-Input'!$B$47,0,'1-Input'!$B$13-L46) | N46: =IF($K46>'1-Input'!$B$47,0,M46/(1+'1-Input'!$B$46)^($K46-'1-Input'!$C$16-1))
A47: TFR netto incassato al ritiro | B47: ='6-TFR'!$B$24 | K47: =K46+1 | L47: =IF($K47>'1-Input'!$B$47,0,IF($K47<'5-Pensioni'!$C$8,0,IF($K47='5-Pensioni'!$C$8,'5-Pensioni'!$C$54*'5-Pensioni'!$C$19,'5-Pensioni'!$C$54))+IF($K47<'5-Pensioni'!$B$8,0,IF($K47='5-Pensioni'!$B$8,'5-Pensioni'!$B$54*'5-Pensioni'!$B$19,'5-Pensioni'!$B$54))) | M47: =IF($K47>'1-Input'!$B$47,0,'1-Input'!$B$13-L47) | N47: =IF($K47>'1-Input'!$B$47,0,M47/(1+'1-Input'!$B$46)^($K47-'1-Input'!$C$16-1))
A48: LETTURA IN NETTO — a carico del portafoglio, in netto | B48: =B46-B47 | K48: =K47+1 | L48: =IF($K48>'1-Input'!$B$47,0,IF($K48<'5-Pensioni'!$C$8,0,IF($K48='5-Pensioni'!$C$8,'5-Pensioni'!$C$54*'5-Pensioni'!$C$19,'5-Pensioni'!$C$54))+IF($K48<'5-Pensioni'!$B$8,0,IF($K48='5-Pensioni'!$B$8,'5-Pensioni'!$B$54*'5-Pensioni'!$B$19,'5-Pensioni'!$B$54))) | M48: =IF($K48>'1-Input'!$B$47,0,'1-Input'!$B$13-L48) | N48: =IF($K48>'1-Input'!$B$47,0,M48/(1+'1-Input'!$B$46)^($K48-'1-Input'!$C$16-1))
A49: …portata in capitale (× G) | B49: =MAX(0,B48*B45) | K49: =K48+1 | L49: =IF($K49>'1-Input'!$B$47,0,IF($K49<'5-Pensioni'!$C$8,0,IF($K49='5-Pensioni'!$C$8,'5-Pensioni'!$C$54*'5-Pensioni'!$C$19,'5-Pensioni'!$C$54))+IF($K49<'5-Pensioni'!$B$8,0,IF($K49='5-Pensioni'!$B$8,'5-Pensioni'!$B$54*'5-Pensioni'!$B$19,'5-Pensioni'!$B$54))) | M49: =IF($K49>'1-Input'!$B$47,0,'1-Input'!$B$13-L49) | N49: =IF($K49>'1-Input'!$B$47,0,M49/(1+'1-Input'!$B$46)^($K49-'1-Input'!$C$16-1))
A50: LETTURA IN CAPITALE — fabbisogno lordo (valore attuale × G) | B50: =B46*B45
A51: …meno il capitale che la liquidazione risparmia al portafoglio | B51: =-B47*B45
A52: FABBISOGNO FINANZIARIO (floor a zero) | B52: =MAX(0,B50+B51)
A53: Quota della liquidazione sul fabbisogno lordo | B53: =-B51/B50
A54: Copertura della spesa data dalle pensioni / gap di coda | B54: ='5-Pensioni'!$B$21 | C54: ='5-Pensioni'!$B$22
A56: IL WATERFALL DEL TWIST — cinque gradini, e uno tira nell'altra direzione
A57: Gradino | B57: Valore | C57: Fattore
A58: 0 — Il target dichiarato | B58: ='P-Parametri'!$B$47
A59: 1 — Al tasso vero del portafoglio, bollo incluso, sempre perpetuo | B59: ='1-Input'!$B$13/'1-Input'!$B$46 | C59: =B58/B59
A60: 2 — Orizzonte finito invece dell'infinito (annualita' anticipata) | B60: ='1-Input'!$B$13*((1-(1+'1-Input'!$B$46)^-('1-Input'!$B$47-'1-Input'!$B$19))/'1-Input'!$B$46)*(1+'1-Input'!$B$46) | C60: =B59/B60
A61: 3 — La fiscalita' del prelievo — QUESTO GRADINO SALE | B61: =B60*B45 | C61: =B60/B61
A62: 4 — Contate le due pensioni | B62: =B50 | C62: =B61/B62
...

Sheet 8-Patrimonio
A1: La traiettoria del patrimonio
A2: Strumento informativo / divulgativo. NON è consulenza finanziaria. I valori sono indicativi al 2026 e vanno verificati col tuo consulente.
A4: ANNO PER ANNO — accumulo, poi decumulo con il TFR consumato per primo
A5: Anno | B5: Eta' | C5: Versamento | D5: Pensioni nette | E5: Fabbisogno netto | F5: TFR usato | G5: TFR residuo | H5: Prelievo lordizzato | I5: Capitale centrale | J5: Capitale al pavimento | K5: Capitale al tetto | L5: Capitale con la sequenza sfavorevole
A6: ='1-Input'!$C$16 | B6: =$A6-'1-Input'!$B$5 | C6: =0 | D6: =0 | E6: =0 | F6: =0 | G6: ='6-TFR'!$B$24 | H6: =0 | I6: ='2-Composizione'!$B$36 | J6: ='2-Composizione'!$B$36 | K6: ='2-Composizione'!$B$36 | L6: ='2-Composizione'!$B$36
A7: =A6+1 | B7: =$A7-'1-Input'!$B$5 | C7: =IF($A7<='1-Input'!$B$19,'1-Input'!$B$40,0) | D7: =IF($A7<='1-Input'!$B$19,0,IF($A7>'1-Input'!$B$47,0,IF($A7<'5-Pensioni'!$C$8,0,IF($A7='5-Pensioni'!$C$8,'5-Pensioni'!$C$18*'5-Pensioni'!$C$19,'5-Pensioni'!$C$18))+IF($A7<'5-Pensioni'!$B$8,0,IF($A7='5-Pensioni'!$B$8,'5-Pensioni'!$B$18*'5-Pensioni'!$B$19,'5-Pensioni'!$B$18)))) | E7: =IF($A7<='1-Input'!$B$19,0,IF($A7>'1-Input'!$B$47,0,MAX(0,'1-Input'!$B$13-D7))) | F7: =MIN(E7,G6) | G7: =G6-F7 | H7: =MAX(0,E7-F7)*$B$51 | I7: =IF($A7<='1-Input'!$B$19,(I6+C7)*(1+'1-Input'!$B$46),(I6-H7)*(1+'1-Input'!$B$46)) | J7: =IF($A7<='1-Input'!$B$19,(J6+C7)*(1+'3-Rendimento'!$D$15),(J6-MAX(0,E7-F7)*$C$51)*(1+'3-Rendimento'!$D$15)) | K7: =IF($A7<='1-Input'!$B$19,(K6+C7)*(1+'3-Rendimento'!$D$17),(K6-MAX(0,E7-F7)*$D$51)*(1+'3-Rendimento'!$D$17)) | L7: =IF($A7>'1-Input'!$B$19,"",(L6+C7)*(1+IF($A7='1-Input'!$B$19-1,'P-Parametri'!$B$54*'P-Parametri'!$B$52+(1-'P-Parametri'!$B$54)*('P-Parametri'!$C$42-'1-Input'!$B$18),IF($A7='1-Input'!$B$19,'P-Parametri'!$B$54*'P-Parametri'!$C$52+(1-'P-Parametri'!$B$54)*('P-Parametri'!$C$42-'1-Input'!$B$18),'1-Input'!$B$46))))
A8: =A7+1 | B8: =$A8-'1-Input'!$B$5 | C8: =IF($A8<='1-Input'!$B$19,'1-Input'!$B$40,0) | D8: =IF($A8<='1-Input'!$B$19,0,IF($A8>'1-Input'!$B$47,0,IF($A8<'5-Pensioni'!$C$8,0,IF($A8='5-Pensioni'!$C$8,'5-Pensioni'!$C$18*'5-Pensioni'!$C$19,'5-Pensioni'!$C$18))+IF($A8<'5-Pensioni'!$B$8,0,IF($A8='5-Pensioni'!$B$8,'5-Pensioni'!$B$18*'5-Pensioni'!$B$19,'5-Pensioni'!$B$18)))) | E8: =IF($A8<='1-Input'!$B$19,0,IF($A8>'1-Input'!$B$47,0,MAX(0,'1-Input'!$B$13-D8))) | F8: =MIN(E8,G7) | G8: =G7-F8 | H8: =MAX(0,E8-F8)*$B$51 | I8: =IF($A8<='1-Input'!$B$19,(I7+C8)*(1+'1-Input'!$B$46),(I7-H8)*(1+'1-Input'!$B$46)) | J8: =IF($A8<='1-Input'!$B$19,(J7+C8)*(1+'3-Rendimento'!$D$15),(J7-MAX(0,E8-F8)*$C$51)*(1+'3-Rendimento'!$D$15)) | K8: =IF($A8<='1-Input'!$B$19,(K7+C8)*(1+'3-Rendimento'!$D$17),(K7-MAX(0,E8-F8)*$D$51)*(1+'3-Rendimento'!$D$17)) | L8: =IF($A8>'1-Input'!$B$19,"",(L7+C8)*(1+IF($A8='1-Input'!$B$19-1,'P-Parametri'!$B$54*'P-Parametri'!$B$52+(1-'P-Parametri'!$B$54)*('P-Parametri'!$C$42-'1-Input'!$B$18),IF($A8='1-Input'!$B$19,'P-Parametri'!$B$54*'P-Parametri'!$C$52+(1-'P-Parametri'!$B$54)*('P-Parametri'!$C$42-'1-Input'!$B$18),'1-Input'!$B$46))))
A9: =A8+1 | B9: =$A9-'1-Input'!$B$5 | C9: =IF($A9<='1-Input'!$B$19,'1-Input'!$B$40,0) | D9: =IF($A9<='1-Input'!$B$19,0,IF($A9>'1-Input'!$B$47,0,IF($A9<'5-Pensioni'!$C$8,0,IF($A9='5-Pensioni'!$C$8,'5-Pensioni'!$C$18*'5-Pensioni'!$C$19,'5-Pensioni'!$C$18))+IF($A9<'5-Pensioni'!$B$8,0,IF($A9='5-Pensioni'!$B$8,'5-Pensioni'!$B$18*'5-Pensioni'!$B$19,'5-Pensioni'!$B$18)))) | E9: =IF($A9<='1-Input'!$B$19,0,IF($A9>'1-Input'!$B$47,0,MAX(0,'1-Input'!$B$13-D9))) | F9: =MIN(E9,G8) | G9: =G8-F9 | H9: =MAX(0,E9-F9)*$B$51 | I9: =IF($A9<='1-Input'!$B$19,(I8+C9)*(1+'1-Input'!$B$46),(I8-H9)*(1+'1-Input'!$B$46)) | J9: =IF($A9<='1-Input'!$B$19,(J8+C9)*(1+'3-Rendimento'!$D$15),(J8-MAX(0,E9-F9)*$C$51)*(1+'3-Rendimento'!$D$15)) | K9: =IF($A9<='1-Input'!$B$19,(K8+C9)*(1+'3-Rendimento'!$D$17),(K8-MAX(0,E9-F9)*$D$51)*(1+'3-Rendimento'!$D$17)) | L9: =IF($A9>'1-Input'!$B$19,"",(L8+C9)*(1+IF($A9='1-Input'!$B$19-1,'P-Parametri'!$B$54*'P-Parametri'!$B$52+(1-'P-Parametri'!$B$54)*('P-Parametri'!$C$42-'1-Input'!$B$18),IF($A9='1-Input'!$B$19,'P-Parametri'!$B$54*'P-Parametri'!$C$52+(1-'P-Parametri'!$B$54)*('P-Parametri'!$C$42-'1-Input'!$B$18),'1-Input'!$B$46))))
A10: =A9+1 | B10: =$A10-'1-Input'!$B$5 | C10: =IF($A10<='1-Input'!$B$19,'1-Input'!$B$40,0) | D10: =IF($A10<='1-Input'!$B$19,0,IF($A10>'1-Input'!$B$47,0,IF($A10<'5-Pensioni'!$C$8,0,IF($A10='5-Pensioni'!$C$8,'5-Pensioni'!$C$18*'5-Pensioni'!$C$19,'5-Pensioni'!$C$18))+IF($A10<'5-Pensioni'!$B$8,0,IF($A10='5-Pensioni'!$B$8,'5-Pensioni'!$B$18*'5-Pensioni'!$B$19,'5-Pensioni'!$B$18)))) | E10: =IF($A10<='1-Input'!$B$19,0,IF($A10>'1-Input'!$B$47,0,MAX(0,'1-Input'!$B$13-D10))) | F10: =MIN(E10,G9) | G10: =G9-F10 | H10: =MAX(0,E10-F10)*$B$51 | I10: =IF($A10<='1-Input'!$B$19,(I9+C10)*(1+'1-Input'!$B$46),(I9-H10)*(1+'1-Input'!$B$46)) | J10: =IF($A10<='1-Input'!$B$19,(J9+C10)*(1+'3-Rendimento'!$D$15),(J9-MAX(0,E10-F10)*$C$51)*(1+'3-Rendimento'!$D$15)) | K10: =IF($A10<='1-Input'!$B$19,(K9+C10)*(1+'3-Rendimento'!$D$17),(K9-MAX(0,E10-F10)*$D$51)*(1+'3-Rendimento'!$D$17)) | L10: =IF($A10>'1-Input'!$B$19,"",(L9+C10)*(1+IF($A10='1-Input'!$B$19-1,'P-Parametri'!$B$54*'P-Parametri'!$B$52+(1-'P-Parametri'!$B$54)*('P-Parametri'!$C$42-'1-Input'!$B$18),IF($A10='1-Input'!$B$19,'P-Parametri'!$B$54*'P-Parametri'!$C$52+(1-'P-Parametri'!$B$54)*('P-Parametri'!$C$42-'1-Input'!$B$18),'1-Input'!$B$46))))
A11: =A10+1 | B11: =$A11-'1-Input'!$B$5 | C11: =IF($A11<='1-Input'!$B$19,'1-Input'!$B$40,0) | D11: =IF($A11<='1-Input'!$B$19,0,IF($A11>'1-Input'!$B$47,0,IF($A11<'5-Pensioni'!$C$8,0,IF($A11='5-Pensioni'!$C$8,'5-Pensioni'!$C$18*'5-Pensioni'!$C$19,'5-Pensioni'!$C$18))+IF($A11<'5-Pensioni'!$B$8,0,IF($A11='5-Pensioni'!$B$8,'5-Pensioni'!$B$18*'5-Pensioni'!$B$19,'5-Pensioni'!$B$18)))) | E11: =IF($A11<='1-Input'!$B$19,0,IF($A11>'1-Input'!$B$47,0,MAX(0,'1-Input'!$B$13-D11))) | F11: =MIN(E11,G10) | G11: =G10-F11 | H11: =MAX(0,E11-F11)*$B$51 | I11: =IF($A11<='1-Input'!$B$19,(I10+C11)*(1+'1-Input'!$B$46),(I10-H11)*(1+'1-Input'!$B$46)) | J11: =IF($A11<='1-Input'!$B$19,(J10+C11)*(1+'3-Rendimento'!$D$15),(J10-MAX(0,E11-F11)*$C$51)*(1+'3-Rendimento'!$D$15)) | K11: =IF($A11<='1-Input'!$B$19,(K10+C11)*(1+'3-Rendimento'!$D$17),(K10-MAX(0,E11-F11)*$D$51)*(1+'3-Rendimento'!$D$17)) | L11: =IF($A11>'1-Input'!$B$19,"",(L10+C11)*(1+IF($A11='1-Input'!$B$19-1,'P-Parametri'!$B$54*'P-Parametri'!$B$52+(1-'P-Parametri'!$B$54)*('P-Parametri'!$C$42-'1-Input'!$B$18),IF($A11='1-Input'!$B$19,'P-Parametri'!$B$54*'P-Parametri'!$C$52+(1-'P-Parametri'!$B$54)*('P-Parametri'!$C$42-'1-Input'!$B$18),'1-Input'!$B$46))))
A12: =A11+1 | B12: =$A12-'1-Input'!$B$5 | C12: =IF($A12<='1-Input'!$B$19,'1-Input'!$B$40,0) | D12: =IF($A12<='1-Input'!$B$19,0,IF($A12>'1-Input'!$B$47,0,IF($A12<'5-Pensioni'!$C$8,0,IF($A12='5-Pensioni'!$C$8,'5-Pensioni'!$C$18*'5-Pensioni'!$C$19,'5-Pensioni'!$C$18))+IF($A12<'5-Pensioni'!$B$8,0,IF($A12='5-Pensioni'!$B$8,'5-Pensioni'!$B$18*'5-Pensioni'!$B$19,'5-Pensioni'!$B$18)))) | E12: =IF($A12<='1-Input'!$B$19,0,IF($A12>'1-Input'!$B$47,0,MAX(0,'1-Input'!$B$13-D12))) | F12: =MIN(E12,G11) | G12: =G11-F12 | H12: =MAX(0,E12-F12)*$B$51 | I12: =IF($A12<='1-Input'!$B$19,(I11+C12)*(1+'1-Input'!$B$46),(I11-H12)*(1+'1-Input'!$B$46)) | J12: =IF($A12<='1-Input'!$B$19,(J11+C12)*(1+'3-Rendimento'!$D$15),(J11-MAX(0,E12-F12)*$C$51)*(1+'3-Rendimento'!$D$15)) | K12: =IF($A12<='1-Input'!$B$19,(K11+C12)*(1+'3-Rendimento'!$D$17),(K11-MAX(0,E12-F12)*$D$51)*(1+'3-Rendimento'!$D$17)) | L12: =IF($A12>'1-Input'!$B$19,"",(L11+C12)*(1+IF($A12='1-Input'!$B$19-1,'P-Parametri'!$B$54*'P-Parametri'!$B$52+(1-'P-Parametri'!$B$54)*('P-Parametri'!$C$42-'1-Input'!$B$18),IF($A12='1-Input'!$B$19,'P-Parametri'!$B$54*'P-Parametri'!$C$52+(1-'P-Parametri'!$B$54)*('P-Parametri'!$C$42-'1-Input'!$B$18),'1-Input'!$B$46))))
A13: =A12+1 | B13: =$A13-'1-Input'!$B$5 | C13: =IF($A13<='1-Input'!$B$19,'1-Input'!$B$40,0) | D13: =IF($A13<='1-Input'!$B$19,0,IF($A13>'1-Input'!$B$47,0,IF($A13<'5-Pensioni'!$C$8,0,IF($A13='5-Pensioni'!$C$8,'5-Pensioni'!$C$18*'5-Pensioni'!$C$19,'5-Pensioni'!$C$18))+IF($A13<'5-Pensioni'!$B$8,0,IF($A13='5-Pensioni'!$B$8,'5-Pensioni'!$B$18*'5-Pensioni'!$B$19,'5-Pensioni'!$B$18)))) | E13: =IF($A13<='1-Input'!$B$19,0,IF($A13>'1-Input'!$B$47,0,MAX(0,'1-Input'!$B$13-D13))) | F13: =MIN(E13,G12) | G13: =G12-F13 | H13: =MAX(0,E13-F13)*$B$51 | I13: =IF($A13<='1-Input'!$B$19,(I12+C13)*(1+'1-Input'!$B$46),(I12-H13)*(1+'1-Input'!$B$46)) | J13: =IF($A13<='1-Input'!$B$19,(J12+C13)*(1+'3-Rendimento'!$D$15),(J12-MAX(0,E13-F13)*$C$51)*(1+'3-Rendimento'!$D$15)) | K13: =IF($A13<='1-Input'!$B$19,(K12+C13)*(1+'3-Rendimento'!$D$17),(K12-MAX(0,E13-F13)*$D$51)*(1+'3-Rendimento'!$D$17)) | L13: =IF($A13>'1-Input'!$B$19,"",(L12+C13)*(1+IF($A13='1-Input'!$B$19-1,'P-Parametri'!$B$54*'P-Parametri'!$B$52+(1-'P-Parametri'!$B$54)*('P-Parametri'!$C$42-'1-Input'!$B$18),IF($A13='1-Input'!$B$19,'P-Parametri'!$B$54*'P-Parametri'!$C$52+(1-'P-Parametri'!$B$54)*('P-Parametri'!$C$42-'1-Input'!$B$18),'1-Input'!$B$46))))
