Workbook

Sheet 0-Indice
A1: Marco FIRE — Quanto vale tornare al lavoro (caso Davide, 2026)
A2: Strumento informativo / divulgativo. NON è consulenza finanziaria. I valori sono indicativi al 2026 e vanno verificati col tuo consulente.
A4: Indice
A5: 1-Input | B5: Il caso di Davide: i diciannove input e i derivati
A6: P-Parametri | B6: Parametri normativi 2026, coefficienti, sequenze
A7: 2-Composizione | B7: Da dove vengono i 760.000 e la plusvalenza latente
A8: 3-Simulazione | B8: Il portafoglio anno per anno, quarantadue righe
A9: 4-Griglia | B9: La griglia 3x4: spesa massima, età di esaurimento, capitale
A10: 5-Leve | B10: LE DUE LEVE IN ORDINE: quanto lavoro, quanto taglio di spesa
A11: 6-Fisco | B11: La finestra fiscale riga per riga, la soglia e lo scalino
A12: 7-Rientro | B12: Tabella madre, anni di margine, momento del rientro
A13: 8-Capitale | B13: Capitale equivalente, effetto sequenza, pendenza
A14: 9-Pensione | B14: Montante, contributi riattivati, valore in capitale
A15: 10-Verifica | B15: Cruscotto, semaforo e le note di scadenza
A16: M1 / M2 / M3 | B16: I motori: secanti a sei valutazioni, una simulazione ciascuna
A18: Come usare
A19: 1. Le celle GIALLE sono input — modificale coi tuoi numeri.
A20: 2. Le celle VERDI sono output — si aggiornano automaticamente.
A21: 3. Tutti i numeri di default sono al 2026 da fonti pubbliche.
A22: 4. Niente codice nascosto: l'Excel è solo formule modificabili.
A24: Fonti dati
A25: • IRPEF 2026 (23% / 33% / 43%) — L. 199/2025; detrazioni art. 13 TUIR c. 1 (lavoro) e c. 3 (pensione), che non si cumulano fra loro
A26: • Trattamento integrativo 1.200 € e somma integrativa sul cuneo (7,1% / 5,3% / 4,8%) — L. 207/2024 art. 1 cc. 4-5; ulteriore detrazione 1.000 € fra 20.000 e 40.000 € — L. 207/2024 art. 1 c. 6
A27: • Contributi a carico del lavoratore dipendente 9,19%; aliquota di computo 33% sulla RETRIBUZIONE IMPONIBILE PREVIDENZIALE (il lordo, non il netto)
A28: • Coefficiente di trasformazione a 68 anni e 8 mesi (5,9520%, interpolato) — DM 20/11/2024, biennio 2025-2026: REFRESH GENNAIO 2027
A29: • Decorrenza a 68 anni e 8 mesi nel 2045 per il nato nel 1976: PROIEZIONE della Ragioneria generale dello Stato, non una norma in vigore
A30: • Capital gain 26% — art. 68 TUIR e D.Lgs. 461/1997; imposta di bollo 0,20% sul patrimonio di FINE anno
... A36: Aggiornamenti: github.com/marcofire-it/marco-fire-simulatori

Sheet 1-Input
A1: Il caso di Davide — gli input
A2: Strumento informativo / divulgativo. NON è consulenza finanziaria. I valori sono indicativi al 2026 e vanno verificati col tuo consulente.
A4: INPUT — cambia una cella gialla e tutti i verdi si muovono
A5: (1) Età oggi / anno di nascita | B5: 50 | C5: 1976
A6: (2) Età di decorrenza della pensione — anni / mesi | B6: 68 | C6: 8
A7: (3) Orizzonte di piano (età finale) | B7: 92
A8: (4) Patrimonio investito | B8: 760000
A9: (5) Base di costo | B9: 586000
A10: (6) Spesa netta annua | B10: 29000
A11: (7) Reddito LORDO annuo del rientro | B11: 12000
A12: (8) Anni di rientro — durata A / durata B | B12: 5 | C12: 10
A13: (9) Anno di avvio del rientro (1 = subito) | B13: 1
A14: (10) Pensione attesa — netta / lorda al mese | B14: 1195 | C14: 1462
A15: (11) Rendimento reale del caso base | B15: 0.03
A16: (12) Ordine dei rendimenti del caso base (1=cost. 2=inizio 3=meta 4=fine) | B16: 2
A17: (13) Retribuzione media di carriera (previdenziale) | B17: 35000
A18: (14) Anni di contributi già maturati | B18: 25
A19: (15) Giorni di lavoro nell'anno (365 = contratto per l'anno intero) | B19: 365
A20: Lo stato abitativo fa parte della scheda-caso: Davide è single, ha la CASA DI PROPRIETÀ e il mutuo estinto. Serve perché il video confronta la sua spesa con aggregati ISTAT che includono l'affitto figurativo — una componente non monetaria.
A21: DERIVATI — non si toccano, si ricalcolano
A22: Anni di piano (orizzonte - età oggi) | B22: =B7-B5 -> 42
A23: Pensione netta annua (x 13 mensilità) | B23: =B14*'P-Parametri'!$B$25 -> 15535
A24: Pensione lorda annua (x 13 mensilità) | B24: =C14*'P-Parametri'!$B$25 -> 19006
A25: Decorrenza, in anni dall'inizio del piano | B25: =(B6+C6/12)-B5 -> 18.666667
A26: Anni pieni senza pensione (ponte) | B26: =IF(B25=INT(B25),B25-1,INT(B25)) -> 18
A27: Frazione di pensione nell'anno successivo | B27: =IF(B25=INT(B25),1,1-(B25-INT(B25))) -> 0.33333333
A28: Quota della base di costo sul patrimonio | B28: =B9/B8 -> 0.77105263
A29: Plusvalenza latente iniziale | B29: =(B8-B9)/B8 -> 0.22894737
A30: Netto in busta del reddito del rientro | B30: =((B11*(1-'P-Parametri'!$B$22))+0)-(MAX(0,(IF(((B11*(1-'P-Parametri'!$B$22))+0)<='P-Parametri'!$B$6,'P-Parametri'!$C$6*((B11*(1-'P-Parametri'!$B$22))+0),IF(((B11*(1-'P-Parametri'!$B$22))+0)<='P-Parametri'!$B$7,'P-Parametri'!$B$9+'P-Parametri'!$C$7*(((B11*(1-'P-Parametri'!$B$22))+0)-'P-Parametri'!$B$6),'P-Parametri'!$B$10+'P-Parametri'!$C$8*(((B11*(1-'P-Parametri'!$B$22))+0)-'P-Parametri'!$B$7))))-(IF(((B11*(1-'P-Parametri'!$B$22))+0)<='P-Parametri'!$C$12,'P-Parametri'!$B$12,IF(((B11*(1-'P-Parametri'!$B$22))+0)<='P-Parametri'!$B$6,'P-Parametri'!$B$13+'P-Parametri'!$C$13*('P-Parametri'!$B$6-((B11*(1-'P-Parametri'!$B$22))+0))/'P-Parametri'!$D$13,IF(((B11*(1-'P-Parametri'!$B$22))+0)<='P-Parametri'!$B$7,'P-Parametri'!$B$14*('P-Parametri'!$B$7-((B11*(1-'P-Parametri'!$B$22))+0))/'P-Parametri'!$C$14,0))))-(IF((B11*(1-'P-Parametri'!$B$22))>0,IF(((B11*(1-'P-Parametri'!$B$22))+0)<='P-Parametri'!$C$21,0,IF(((B11*(1-'P-Parametri'!$B$22))+0)<='P-Parametri'!$D$21,'P-Parametri'!$B$21,IF(((B11*(1-'P-Parametri'!$B$22))+0)<'P-Parametri'!$E$21,'P-Parametri'!$B$21*('P-Parametri'!$E$21-((B11*(1-'P-Parametri'!$B$22))+0))/('P-Parametri'!$E$21-'P-Parametri'!$D$21),0))),0))))-(IF(MAX(0,(IF(((B11*(1-'P-Parametri'!$B$22))+0)<='P-Parametri'!$B$6,'P-Parametri'!$C$6*((B11*(1-'P-Parametri'!$B$22))+0),IF(((B11*(1-'P-Parametri'!$B$22))+0)<='P-Parametri'!$B$7,'P-Parametri'!$B$9+'P-Parametri'!$C$7*(((B11*(1-'P-Parametri'!$B$22))+0)-'P-Parametri'!$B$6),'P-Parametri'!$B$10+'P-Parametri'!$C$8*(((B11*(1-'P-Parametri'!$B$22))+0)-'P-Parametri'!$B$7))))-(IF(((B11*(1-'P-Parametri'!$B$22))+0)<='P-Parametri'!$C$12,'P-Parametri'!$B$12,IF(((B11*(1-'P-Parametri'!$B$22))+0)<='P-Parametri'!$B$6,'P-Parametri'!$B$13+'P-Parametri'!$C$13*('P-Parametri'!$B$6-((B11*(1-'P-Parametri'!$B$22))+0))/'P-Parametri'!$D$13,IF(((B11*(1-'P-Parametri'!$B$22))+0)<='P-Parametri'!$B$7,'P-Parametri'!$B$14*('P-Parametri'!$B$7-((B11*(1-'P-Parametri'!$B$22))+0))/'P-Parametri'!$C$14,0))))-(IF((B11*(1-'P-Parametri'!$B$22))>0,IF(((B11*(1-'P-Parametri'!$B$22))+0)<='P-Parametri'!$C$21,0,IF(((B11*(1-'P-Parametri'!$B$22))+0)<='P-Parametri'!$D$21,'P-Parametri'!$B$21,IF(((B11*(1-'P-Parametri'!$B$22))+0)<'P-Parametri'!$E$21,'P-Parametri'!$B$21*('P-Parametri'!$E$21-((B11*(1-'P-Parametri'!$B$22))+0))/('P-Parametri'!$E$21-'P-Parametri'!$D$21),0))),0)))>0,'P-Parametri'!$B$11*((B11*(1-'P-Parametri'!$B$22))+0),0))+(IF(AND(((B11*(1-'P-Parametri'!$B$22))+0)<='P-Parametri'!$C$18,(IF(((B11*(1-'P-Parametri'!$B$22))+0)<='P-Parametri'!$B$6,'P-Parametri'!$C$6*((B11*(1-'P-Parametri'!$B$22))+0),IF(((B11*(1-'P-Parametri'!$B$22))+0)<='P-Parametri'!$B$7,'P-Parametri'!$B$9+'P-Parametri'!$C$7*(((B11*(1-'P-Parametri'!$B$22))+0)-'P-Parametri'!$B$6),'P-Parametri'!$B$10+'P-Parametri'!$C$8*(((B11*(1-'P-Parametri'!$B$22))+0)-'P-Parametri'!$B$7))))>(IF(((B11*(1-'P-Parametri'!$B$22))+0)<='P-Parametri'!$C$12,'P-Parametri'!$B$12,IF(((B11*(1-'P-Parametri'!$B$22))+0)<='P-Parametri'!$B$6,'P-Parametri'!$B$13+'P-Parametri'!$C$13*('P-Parametri'!$B$6-((B11*(1-'P-Parametri'!$B$22))+0))/'P-Parametri'!$D$13,IF(((B11*(1-'P-Parametri'!$B$22))+0)<='P-Parametri'!$B$7,'P-Parametri'!$B$14*('P-Parametri'!$B$7-((B11*(1-'P-Parametri'!$B$22))+0))/'P-Parametri'!$C$14,0))))-'P-Parametri'!$D$18),'P-Parametri'!$B$18,0))+(IF((B11*(1-'P-Parametri'!$B$22))>0,IF(((B11*(1-'P-Parametri'!$B$22))+0)>'P-Parametri'!$D$20,0,IF(((B11*(1-'P-Parametri'!$B$22))+0)<='P-Parametri'!$B$20,'P-Parametri'!$B$19*(B11*(1-'P-Parametri'!$B$22)),IF(((B11*(1-'P-Parametri'!$B$22))+0)<='P-Parametri'!$C$20,'P-Parametri'!$C$19*(B11*(1-'P-Parametri'!$B$22)),'P-Parametri'!$D$19*(B11*(1-'P-Parametri'!$B$22))))),0)) -> 11905.452
A31: Netto / lordo del reddito del rientro | B31: =B30/B11 -> 0.99212097
A32: Pensione in più (netta) dai contributi riattivati | B32: =(('P-Parametri'!$B$24*B11)*(1+'P-Parametri'!$B$26)^(B25-B13-B12+1)*(IF('P-Parametri'!$B$26=0,B12,((1+'P-Parametri'!$B$26)^B12-1)/'P-Parametri'!$B$26)))*'P-Parametri'!$B$27*(1-'P-Parametri'!$B$28) -> 887.4451
A33: Tasso di prelievo di cassa, anno 1 | B33: =B10/B8 -> 0.038157895
A34: Tasso omogeneo (vendita lorda), anno 1 | B34: =(B10/(1-'P-Parametri'!$B$31*B29))/B8 -> 0.040573059
A35: Tasso col bollo (patrimonio di FINE anno), anno 1 | B35: =(B10/(1-'P-Parametri'!$B$31*B29)+'P-Parametri'!$B$32*((B8-B10/(1-'P-Parametri'!$B$31*B29))*(1+B15)))/B8 -> 0.042549479
A37: Il bollo dello 0,20% grava sul patrimonio di FINE anno: è la convenzione del motore ed è la ragione per cui la terza scala del tasso vale 4,255% e non 4,257%. Il 4,257% è lo stesso bollo calcolato sul patrimonio di INIZIO anno.
A38: I 68 anni e 8 mesi e il 2045 sono una PROIEZIONE della Ragioneria generale dello Stato per la coorte del 1976, non una norma in vigore. Vanno dichiarati tali ogni volta che entrano in un conto.
A39: Il montante contributivo si calcola sul 33% della RETRIBUZIONE LORDA, anno per anno, ciascuna annualità rivalutata fino alla decorrenza: non è il 33% del netto in busta, e non si ottiene scalando linearmente il montante di cinque anni.

Sheet P-Parametri
A1: Parametri normativi e di fonte — fotografia del 2026
A2: Strumento informativo / divulgativo. NON è consulenza finanziaria. I valori sono indicativi al 2026 e vanno verificati col tuo consulente.
A3: Le uniche costanti del modello, oltre agli input del foglio 1, stanno qui. Tutti gli altri fogli le referenziano: cambiare un'aliquota qui muove ogni cella verde della cartella.
A5: IRPEF 2026 (L. 199/2025) e detrazioni dell'art. 13 TUIR
A6: Primo scaglione — limite / aliquota | B6: 28000 | C6: 0.23
A7: Secondo scaglione — limite / aliquota | B7: 50000 | C7: 0.33
A8: Terzo scaglione — aliquota oltre il secondo limite | C8: 0.43
A9: Imposta cumulata fino al primo scaglione | B9: =B6*C6 -> 6440
A10: Imposta cumulata fino al secondo scaglione | B10: =B9+(B7-B6)*C7 -> 13700
A11: Addizionali regionale e comunale | B11: 0.02
A12: Detrazione da LAVORO (c. 1) — importo pieno / soglia bassa | B12: 1955 | C12: 15000
A13: Detrazione da lavoro 15.000-28.000 — base / incremento / ampiezza | B13: 1910 | C13: 1190 | D13: 13000
A14: Detrazione da lavoro 28.000-50.000 — base / ampiezza | B14: 1910 | C14: 22000
A15: Detrazione da PENSIONE (c. 3) — importo pieno / soglia bassa | B15: 1955 | C15: 8500
A16: Detrazione da pensione 8.500-28.000 — base / incremento / ampiezza | B16: 700 | C16: 1255 | D16: 19500
A17: Detrazione da pensione 28.000-50.000 — base / ampiezza | B17: 700 | C17: 22000
A18: Trattamento integrativo — importo / soglia / scarto di capienza | B18: 1200 | C18: 15000 | D18: 75
A19: Somma sul cuneo — aliquote (fino a 8.500 / 15.000 / 20.000) | B19: 0.071 | C19: 0.053 | D19: 0.048
A20: Somma sul cuneo — soglie di reddito complessivo | B20: 8500 | C20: 15000 | D20: 20000
A21: Ulteriore detrazione — importo / da / piena fino a / azzerata a | B21: 1000 | C21: 20000 | D21: 32000 | E21: 40000
A22: Contributi a carico del lavoratore dipendente | B22: 0.0919
A23: Previdenza obbligatoria
A24: Aliquota di computo (dipendenti), sulla retribuzione LORDA | B24: 0.33
A25: Mensilità della pensione | B25: 13
A26: Rivalutazione REALE annua del montante (ipotesi RGS) | B26: 0.006
A27: Coefficiente di trasformazione a 68 anni e 8 mesi (interpolato) | B27: 0.05952
A28: Aliquota marginale effettiva sulla pensione | B28: 0.31436
A29: Anni minimi di contribuzione per la vecchiaia | B29: 20
A30: Fiscalità finanziaria
A31: Imposta sulla plusvalenza realizzata | B31: 0.26
A32: Imposta di bollo, sul patrimonio di FINE anno | B32: 0.002
A33: Sequenze dei rendimenti — illustrative, NON probabilistiche
A34: Crolli: primo / secondo | B34: -0.35 | C34: -0.2
A35: Ordine «crolli INIZIO» — anni | B35: 1 | C35: 2
A36: Ordine «crolli METÀ» — anni | B36: 21 | C36: 22
A37: Ordine «crolli FINE» — anni | B37: 41 | C37: 42
A38: Riferimenti del caso
A39: Spesa media ISTAT 2024, persona sola 35-64 (€/anno) | B39: 25164
A40: NASpI — soglia autonomo / subordinato | B40: 5500 | C40: 8500
A41: Maestas — retribuzione pre-ritiro / post (rev. 2004) / post (rev. 2005), in dollari | B41: 42045 | C41: 9592 | D41: 10192
...

Sheet 2-Composizione
A1: Da dove vengono i 760.000 € — e perché la latente è derivata
A2: Strumento informativo / divulgativo. NON è consulenza finanziaria. I valori sono indicativi al 2026 e vanno verificati col tuo consulente.
A3: La plusvalenza latente non si postula: si deriva dalla storia di accumulo. Le tre righe qui sotto sono input gialli; il valore di oggi, la base di costo e la latente sono formule.
A5: LE TRE COMPONENTI DEL PATRIMONIO
A6: Componente | B6: Versamento / importo | C6: Anni | D6: Rendimento reale | E6: Valore oggi | F6: Latente | G6: Conferito totale (base)
A7: Accumulo finanziario — versamento annuo a inizio anno | B7: 11000 | C7: 25 | D7: ='P-Parametri'!$B$42 -> 0.028 | E7: =B7*(((1+D7)^C7-1)/D7)*(1+D7) -> 401624.48 | F7: =E7-G7 -> 126624.48 | G7: =B7*C7 -> 275000
A8: TFR netto alla cessazione (tassazione separata) | B8: 48000 | C8: 0 | D8: ='P-Parametri'!$B$42 -> 0.028 | E8: =B8 -> 48000 | F8: =E8-G8 -> 0 | G8: =B8 -> 48000
A9: Eredità ricevuta a 44 anni e investita | B9: 263000 | C9: 6 | D9: ='P-Parametri'!$B$42 -> 0.028 | E9: =B9*(1+D9)^C9 -> 310394.8 | F9: =E9-G9 -> 47394.8 | G9: =B9 -> 263000
A10: TOTALE — derivato | E10: =SUM(E7:E9) -> 760019.28 | F10: =SUM(F7:F9) -> 174019.28 | G10: =SUM(G7:G9) -> 586000
A11: Plusvalenza latente derivata (latente / valore) | B11: =F10/E10 -> 0.22896693
A12: Patrimonio e base del foglio 1 (arrotondati) — e i due scarti | B12: ='1-Input'!$B$8 -> 760000 | C12: ='1-Input'!$B$9 -> 586000 | E12: =B12-E10 -> -19.276952 | G12: =C12-G10 -> 0
A13: Latente iniziale adottata dal motore ((W − B) / W) | B13: ='1-Input'!$B$29 -> 0.22894737
A14: Peso dell'eredità sul patrimonio | B14: =E9/E10 -> 0.40840385
A15: L'eredità pesa oltre il quaranta per cento del patrimonio, ed è la componente entrata a base piena solo sei anni fa: è la ragione per cui la latente di Davide è più bassa di quella degli altri casi del catalogo. Va dichiarata a schermo.
A17: IL CASO CHIUDE? — tasso di risparmio implicito
A18: Retribuzione lorda media di carriera | B18: ='1-Input'!$B$17 -> 35000
A19: Netto in busta della carriera (modulo fiscale del foglio 6) | B19: =(('1-Input'!$B$17*(1-'P-Parametri'!$B$22))+0)-(MAX(0,(IF((('1-Input'!$B$17*(1-'P-Parametri'!$B$22))+0)<='P-Parametri'!$B$6,'P-Parametri'!$C$6*(('1-Input'!$B$17*(1-'P-Parametri'!$B$22))+0),IF((('1-Input'!$B$17*(1-'P-Parametri'!$B$22))+0)<='P-Parametri'!$B$7,'P-Parametri'!$B$9+'P-Parametri'!$C$7*((('1-Input'!$B$17*(1-'P-Parametri'!$B$22))+0)-'P-Parametri'!$B$6),'P-Parametri'!$B$10+'P-Parametri'!$C$8*((('1-Input'!$B$17*(1-'P-Parametri'!$B$22))+0)-'P-Parametri'!$B$7))))-(IF((('1-Input'!$B$17*(1-'P-Parametri'!$B$22))+0)<='P-Parametri'!$C$12,'P-Parametri'!$B$12,IF((('1-Input'!$B$17*(1-'P-Parametri'!$B$22))+0)<='P-Parametri'!$B$6,'P-Parametri'!$B$13+'P-Parametri'!$C$13*('P-Parametri'!$B$6-(('1-Input'!$B$17*(1-'P-Parametri'!$B$22))+0))/'P-Parametri'!$D$13,IF((('1-Input'!$B$17*(1-'P-Parametri'!$B$22))+0)<='P-Parametri'!$B$7,'P-Parametri'!$B$14*('P-Parametri'!$B$7-(('1-Input'!$B$17*(1-'P-Parametri'!$B$22))+0))/'P-Parametri'!$C$14,0))))-(IF(('1-Input'!$B$17*(1-'P-Parametri'!$B$22))>0,IF((('1-Input'!$B$17*(1-'P-Parametri'!$B$22))+0)<='P-Parametri'!$C$21,0,IF((('1-Input'!$B$17*(1-'P-Parametri'!$B$22))+0)<='P-Parametri'!$D$21,'P-Parametri'!$B$21,IF((('1-Input'!$B$17*(1-'P-Parametri'!$B$22))+0)<'P-Parametri'!$E$21,'P-Parametri'!$B$21*('P-Parametri'!$E$21-(('1-Input'!$B$17*(1-'P-Parametri'!$B$22))+0))/('P-Parametri'!$E$21-'P-Parametri'!$D$21),0))),0))))-(IF(MAX(0,(IF((('1-Input'!$B$17*(1-'P-Parametri'!$B$22))+0)<='P-Parametri'!$B$6,'P-Parametri'!$C$6*(('1-Input'!$B$17*(1-'P-Parametri'!$B$22))+0),IF((('1-Input'!$B$17*(1-'P-Parametri'!$B$22))+0)<='P-Parametri'!$B$7,'P-Parametri'!$B$9+'P-Parametri'!$C$7*((('1-Input'!$B$17*(1-'P-Parametri'!$B$22))+0)-'P-Parametri'!$B$6),'P-Parametri'!$B$10+'P-Parametri'!$C$8*((('1-Input'!$B$17*(1-'P-Parametri'!$B$22))+0)-'P-Parametri'!$B$7))))-(IF((('1-Input'!$B$17*(1-'P-Parametri'!$B$22))+0)<='P-Parametri'!$C$12,'P-Parametri'!$B$12,IF((('1-Input'!$B$17*(1-'P-Parametri'!$B$22))+0)<='P-Parametri'!$B$6,'P-Parametri'!$B$13+'P-Parametri'!$C$13*('P-Parametri'!$B$6-(('1-Input'!$B$17*(1-'P-Parametri'!$B$22))+0))/'P-Parametri'!$D$13,IF((('1-Input'!$B$17*(1-'P-Parametri'!$B$22))+0)<='P-Parametri'!$B$7,'P-Parametri'!$B$14*('P-Parametri'!$B$7-(('1-Input'!$B$17*(1-'P-Parametri'!$B$22))+0))/'P-Parametri'!$C$14,0))))-(IF(('1-Input'!$B$17*(1-'P-Parametri'!$B$22))>0,IF((('1-Input'!$B$17*(1-'P-Parametri'!$B$22))+0)<='P-Parametri'!$C$21,0,IF((('1-Input'!$B$17*(1-'P-Parametri'!$B$22))+0)<='P-Parametri'!$D$21,'P-Parametri'!$B$21,IF((('1-Input'!$B$17*(1-'P-Parametri'!$B$22))+0)<'P-Parametri'!$E$21,'P-Parametri'!$B$21*('P-Parametri'!$E$21-(('1-Input'!$B$17*(1-'P-Parametri'!$B$22))+0))/('P-Parametri'!$E$21-'P-Parametri'!$D$21),0))),0)))>0,'P-Parametri'!$B$11*(('1-Input'!$B$17*(1-'P-Parametri'!$B$22))+0),0))+(IF(AND((('1-Input'!$B$17*(1-'P-Parametri'!$B$22))+0)<='P-Parametri'!$C$18,(IF((('1-Input'!$B$17*(1-'P-Parametri'!$B$22))+0)<='P-Parametri'!$B$6,'P-Parametri'!$C$6*(('1-Input'!$B$17*(1-'P-Parametri'!$B$22))+0),IF((('1-Input'!$B$17*(1-'P-Parametri'!$B$22))+0)<='P-Parametri'!$B$7,'P-Parametri'!$B$9+'P-Parametri'!$C$7*((('1-Input'!$B$17*(1-'P-Parametri'!$B$22))+0)-'P-Parametri'!$B$6),'P-Parametri'!$B$10+'P-Parametri'!$C$8*((('1-Input'!$B$17*(1-'P-Parametri'!$B$22))+0)-'P-Parametri'!$B$7))))>(IF((('1-Input'!$B$17*(1-'P-Parametri'!$B$22))+0)<='P-Parametri'!$C$12,'P-Parametri'!$B$12,IF((('1-Input'!$B$17*(1-'P-Parametri'!$B$22))+0)<='P-Parametri'!$B$6,'P-Parametri'!$B$13+'P-Parametri'!$C$13*('P-Parametri'!$B$6-(('1-Input'!$B$17*(1-'P-Parametri'!$B$22))+0))/'P-Parametri'!$D$13,IF((('1-Input'!$B$17*(1-'P-Parametri'!$B$22))+0)<='P-Parametri'!$B$7,'P-Parametri'!$B$14*('P-Parametri'!$B$7-(('1-Input'!$B$17*(1-'P-Parametri'!$B$22))+0))/'P-Parametri'!$C$14,0))))-'P-Parametri'!$D$18),'P-Parametri'!$B$18,0))+(IF(('1-Input'!$B$17*(1-'P-Parametri'!$B$22))>0,IF((('1-Input'!$B$17*(1-'P-Parametri'!$B$22))+0)>'P-Parametri'!$D$20,0,IF((('1-Input'!$B$17*(1-'P-Parametri'!$B$22))+0)<='P-Parametri'!$B$20,'P-Parametri'!$B$19*('1-Input'!$B$17*(1-'P-Parametri'!$B$22)),IF((('1-Input'!$B$17*(1-'P-Parametri'!$B$22))+0)<='P-Parametri'!$C$20,'P-Parametri'!$C$19*('1-Input'!$B$17*(1-'P-Parametri'!$B$22)),'P-Parametri'!$D$19*('1-Input'!$B$17*(1-'P-Parametri'!$B$22))))),0)) -> 26040.798
A20: Risparmio annuo reale (dalla riga dell'accumulo) | B20: =B7 -> 11000
A21: TASSO DI RISPARMIO IMPLICITO | B21: =B20/B19 -> 0.42241408
A22: Tenore di vita durante l'accumulo (netto − risparmio) | B22: =B19-B20 -> 15040.798
A23: Il salto: spesa di oggi / tenore dell'accumulo | B23: ='1-Input'!$B$10/B22 -> 1.9280891
A25: IL CONFRONTO ISTAT — nelle DUE direzioni
A26: Spesa media ISTAT 2024, persona sola 35-64 (€/anno) | B26: ='P-Parametri'!$B$39 -> 25164
A27: Spesa di oggi / ISTAT | B27: ='1-Input'!$B$10/B26 -> 1.15244
A28: Tenore dell'accumulo / ISTAT | B28: =B22/B26 -> 0.59771095
A29: CLAUSOLA OBBLIGATORIA. L'aggregato ISTAT «spesa media per consumi» INCLUDE l'affitto figurativo, che non è un esborso di cassa. Davide ha la casa di proprietà e il mutuo estinto: il confronto è semmai generoso verso di lui, e va detto in entrambe le direzioni — non solo in quella che conviene.
A31: LA CONVENZIONE DELLA COMPOSIZIONE COSTANTE
A32: Quota della base di costo sul patrimonio, tenuta fissa | B32: ='1-Input'!$B$28 -> 0.77105263
A33: Nella tabella del capitale necessario la composizione del patrimonio è tenuta costante — stessa proporzione fra base di costo e valore — perché altrimenti si confronterebbero due Davide diversi. La latente si deriva dalla storia di accumulo per il caso; per la tabella che dal caso discende, si tiene ferma.

Sheet 3-Simulazione
A1: Il portafoglio anno per anno — il caso base del foglio 1
A2: Strumento informativo / divulgativo. NON è consulenza finanziaria. I valori sono indicativi al 2026 e vanno verificati col tuo consulente.
A4: LA SEQUENZA SCELTA NEL FOGLIO 1
A5: Rendimento della banda / ordine scelto | B5: ='1-Input'!$B$15 -> 0.03 | C5: =CHOOSE('1-Input'!$B$16,"costante","crolli INIZIO","crolli META'","crolli FINE") -> crolli INIZIO
A6: Anno del primo / secondo crollo | B6: =INDEX('P-Parametri'!$B$47:'P-Parametri'!$E$47,'1-Input'!$B$16) -> 1 | C6: =INDEX('P-Parametri'!$B$48:'P-Parametri'!$E$48,'1-Input'!$B$16) -> 2
A7: Rendimento degli anni non di crollo | B7: =IF(B6=0,'1-Input'!$B$15,((1+'1-Input'!$B$15)^'1-Input'!$B$22/((1+'P-Parametri'!$B$34)*(1+'P-Parametri'!$C$34)))^(1/('1-Input'!$B$22-2))-1) -> 0.048525513
A9: SENZA RIENTRO — il piano come sta
A10: anno | B10: rend. | C10: pensione | D10: lavoro | E10: G lordo | F10: patrimonio | G10: base | H10: copre?
A11: =0 -> 0 | E11: =0 -> 0 | F11: ='1-Input'!$B$8 -> 760000 | G11: ='1-Input'!$B$9 -> 586000 | H11: =1 -> 1
A12: =A11+1 -> 1 | B12: =IF($A12='3-Simulazione'!$B$6,'P-Parametri'!$B$34,IF($A12='3-Simulazione'!$C$6,'P-Parametri'!$C$34,'3-Simulazione'!$B$7)) -> -0.35 | C12: =IF($A12<='1-Input'!$B$26,0,IF($A12='1-Input'!$B$26+1,('1-Input'!$B$23+0)*'1-Input'!$B$27,'1-Input'!$B$23+0)) -> 0 | D12: =IF(AND($A12>=1,$A12<1+0),0,0) -> 0 | E12: =MAX(0,('1-Input'!$B$10-C12-D12))/(1-'P-Parametri'!$B$31*MAX(0,IF(F11<=0,0,(F11-G11)/F11))) -> 30835.525 | F12: =((F11-E12+MAX(0,-('1-Input'!$B$10-C12-D12)))*(1+B12))*(1-'P-Parametri'!$B$32) -> 473008.99 | G12: =IF(F11<=0,G11,G11*(1-E12/F11))+MAX(0,-('1-Input'!$B$10-C12-D12)) -> 562224.19 | H12: =IF(OR(F11<=0,F11<E12),0,1) -> 1
A13: =A12+1 -> 2 | B13: =IF($A13='3-Simulazione'!$B$6,'P-Parametri'!$B$34,IF($A13='3-Simulazione'!$C$6,'P-Parametri'!$C$34,'3-Simulazione'!$B$7)) -> -0.2 | C13: =IF($A13<='1-Input'!$B$26,0,IF($A13='1-Input'!$B$26+1,('1-Input'!$B$23+0)*'1-Input'!$B$27,'1-Input'!$B$23+0)) -> 0 | D13: =IF(AND($A13>=1,$A13<1+0),0,0) -> 0 | E13: =MAX(0,('1-Input'!$B$10-C13-D13))/(1-'P-Parametri'!$B$31*MAX(0,IF(F12<=0,0,(F12-G12)/F12))) -> 29000 | F13: =((F12-E13+MAX(0,-('1-Input'!$B$10-C13-D13)))*(1+B13))*(1-'P-Parametri'!$B$32) -> 354496.78 | G13: =IF(F12<=0,G12,G12*(1-E13/F12))+MAX(0,-('1-Input'!$B$10-C13-D13)) -> 527754.44 | H13: =IF(OR(F12<=0,F12<E13),0,1) -> 1
A14: =A13+1 -> 3 | B14: =IF($A14='3-Simulazione'!$B$6,'P-Parametri'!$B$34,IF($A14='3-Simulazione'!$C$6,'P-Parametri'!$C$34,'3-Simulazione'!$B$7)) -> 0.048525513 | C14: =IF($A14<='1-Input'!$B$26,0,IF($A14='1-Input'!$B$26+1,('1-Input'!$B$23+0)*'1-Input'!$B$27,'1-Input'!$B$23+0)) -> 0 | D14: =IF(AND($A14>=1,$A14<1+0),0,0) -> 0 | E14: =MAX(0,('1-Input'!$B$10-C14-D14))/(1-'P-Parametri'!$B$31*MAX(0,IF(F13<=0,0,(F13-G13)/F13))) -> 29000 | F14: =((F13-E14+MAX(0,-('1-Input'!$B$10-C14-D14)))*(1+B14))*(1-'P-Parametri'!$B$32) -> 340609.1 | G14: =IF(F13<=0,G13,G13*(1-E14/F13))+MAX(0,-('1-Input'!$B$10-C14-D14)) -> 484580.9 | H14: =IF(OR(F13<=0,F13<E14),0,1) -> 1
A15: =A14+1 -> 4 | B15: =IF($A15='3-Simulazione'!$B$6,'P-Parametri'!$B$34,IF($A15='3-Simulazione'!$C$6,'P-Parametri'!$C$34,'3-Simulazione'!$B$7)) -> 0.048525513 | C15: =IF($A15<='1-Input'!$B$26,0,IF($A15='1-Input'!$B$26+1,('1-Input'!$B$23+0)*'1-Input'!$B$27,'1-Input'!$B$23+0)) -> 0 | D15: =IF(AND($A15>=1,$A15<1+0),0,0) -> 0 | E15: =MAX(0,('1-Input'!$B$10-C15-D15))/(1-'P-Parametri'!$B$31*MAX(0,IF(F14<=0,0,(F14-G14)/F14))) -> 29000 | F15: =((F14-E15+MAX(0,-('1-Input'!$B$10-C15-D15)))*(1+B15))*(1-'P-Parametri'!$B$32) -> 326076.63 | G15: =IF(F14<=0,G14,G14*(1-E15/F14))+MAX(0,-('1-Input'!$B$10-C15-D15)) -> 443322.92 | H15: =IF(OR(F14<=0,F14<E15),0,1) -> 1
A16: =A15+1 -> 5 | B16: =IF($A16='3-Simulazione'!$B$6,'P-Parametri'!$B$34,IF($A16='3-Simulazione'!$C$6,'P-Parametri'!$C$34,'3-Simulazione'!$B$7)) -> 0.048525513 | C16: =IF($A16<='1-Input'!$B$26,0,IF($A16='1-Input'!$B$26+1,('1-Input'!$B$23+0)*'1-Input'!$B$27,'1-Input'!$B$23+0)) -> 0 | D16: =IF(AND($A16>=1,$A16<1+0),0,0) -> 0 | E16: =MAX(0,('1-Input'!$B$10-C16-D16))/(1-'P-Parametri'!$B$31*MAX(0,IF(F15<=0,0,(F15-G15)/F15))) -> 29000 | F16: =((F15-E16+MAX(0,-('1-Input'!$B$10-C16-D16)))*(1+B16))*(1-'P-Parametri'!$B$32) -> 310869.44 | G16: =IF(F15<=0,G15,G15*(1-E16/F15))+MAX(0,-('1-Input'!$B$10-C16-D16)) -> 403895.48 | H16: =IF(OR(F15<=0,F15<E16),0,1) -> 1
A17: =A16+1 -> 6 | B17: =IF($A17='3-Simulazione'!$B$6,'P-Parametri'!$B$34,IF($A17='3-Simulazione'!$C$6,'P-Parametri'!$C$34,'3-Simulazione'!$B$7)) -> 0.048525513 | C17: =IF($A17<='1-Input'!$B$26,0,IF($A17='1-Input'!$B$26+1,('1-Input'!$B$23+0)*'1-Input'!$B$27,'1-Input'!$B$23+0)) -> 0 | D17: =IF(AND($A17>=1,$A17<1+0),0,0) -> 0 | E17: =MAX(0,('1-Input'!$B$10-C17-D17))/(1-'P-Parametri'!$B$31*MAX(0,IF(F16<=0,0,(F16-G16)/F16))) -> 29000 | F17: =((F16-E17+MAX(0,-('1-Input'!$B$10-C17-D17)))*(1+B17))*(1-'P-Parametri'!$B$32) -> 294956.2 | G17: =IF(F16<=0,G16,G16*(1-E17/F16))+MAX(0,-('1-Input'!$B$10-C17-D17)) -> 366217.38 | H17: =IF(OR(F16<=0,F16<E17),0,1) -> 1
A18: =A17+1 -> 7 | B18: =IF($A18='3-Simulazione'!$B$6,'P-Parametri'!$B$34,IF($A18='3-Simulazione'!$C$6,'P-Parametri'!$C$34,'3-Simulazione'!$B$7)) -> 0.048525513 | C18: =IF($A18<='1-Input'!$B$26,0,IF($A18='1-Input'!$B$26+1,('1-Input'!$B$23+0)*'1-Input'!$B$27,'1-Input'!$B$23+0)) -> 0 | D18: =IF(AND($A18>=1,$A18<1+0),0,0) -> 0 | E18: =MAX(0,('1-Input'!$B$10-C18-D18))/(1-'P-Parametri'!$B$31*MAX(0,IF(F17<=0,0,(F17-G17)/F17))) -> 29000 | F18: =((F17-E18+MAX(0,-('1-Input'!$B$10-C18-D18)))*(1+B18))*(1-'P-Parametri'!$B$32) -> 278304.14 | G18: =IF(F17<=0,G17,G17*(1-E18/F17))+MAX(0,-('1-Input'!$B$10-C18-D18)) -> 330211.01 | H18: =IF(OR(F17<=0,F17<E18),0,1) -> 1
A19: =A18+1 -> 8 | B19: =IF($A19='3-Simulazione'!$B$6,'P-Parametri'!$B$34,IF($A19='3-Simulazione'!$C$6,'P-Parametri'!$C$34,'3-Simulazione'!$B$7)) -> 0.048525513 | C19: =IF($A19<='1-Input'!$B$26,0,IF($A19='1-Input'!$B$26+1,('1-Input'!$B$23+0)*'1-Input'!$B$27,'1-Input'!$B$23+0)) -> 0 | D19: =IF(AND($A19>=1,$A19<1+0),0,0) -> 0 | E19: =MAX(0,('1-Input'!$B$10-C19-D19))/(1-'P-Parametri'!$B$31*MAX(0,IF(F18<=0,0,(F18-G18)/F18))) -> 29000 | F19: =((F18-E19+MAX(0,-('1-Input'!$B$10-C19-D19)))*(1+B19))*(1-'P-Parametri'!$B$32) -> 260878.95 | G19: =IF(F18<=0,G18,G18*(1-E19/F18))+MAX(0,-('1-Input'!$B$10-C19-D19)) -> 295802.18 | H19: =IF(OR(F18<=0,F18<E19),0,1) -> 1
A20: =A19+1 -> 9 | B20: =IF($A20='3-Simulazione'!$B$6,'P-Parametri'!$B$34,IF($A20='3-Simulazione'!$C$6,'P-Parametri'!$C$34,'3-Simulazione'!$B$7)) -> 0.048525513 | C20: =IF($A20<='1-Input'!$B$26,0,IF($A20='1-Input'!$B$26+1,('1-Input'!$B$23+0)*'1-Input'!$B$27,'1-Input'!$B$23+0)) -> 0 | D20: =IF(AND($A20>=1,$A20<1+0),0,0) -> 0 | E20: =MAX(0,('1-Input'!$B$10-C20-D20))/(1-'P-Parametri'!$B$31*MAX(0,IF(F19<=0,0,(F19-G19)/F19))) -> 29000 | F20: =((F19-E20+MAX(0,-('1-Input'!$B$10-C20-D20)))*(1+B20))*(1-'P-Parametri'!$B$32) -> 242644.73 | G20: =IF(F19<=0,G19,G19*(1-E20/F19))+MAX(0,-('1-Input'!$B$10-C20-D20)) -> 262920.02 | H20: =IF(OR(F19<=0,F19<E20),0,1) -> 1
A21: =A20+1 -> 10 | B21: =IF($A21='3-Simulazione'!$B$6,'P-Parametri'!$B$34,IF($A21='3-Simulazione'!$C$6,'P-Parametri'!$C$34,'3-Simulazione'!$B$7)) -> 0.048525513 | C21: =IF($A21<='1-Input'!$B$26,0,IF($A21='1-Input'!$B$26+1,('1-Input'!$B$23+0)*'1-Input'!$B$27,'1-Input'!$B$23+0)) -> 0 | D21: =IF(AND($A21>=1,$A21<1+0),0,0) -> 0 | E21: =MAX(0,('1-Input'!$B$10-C21-D21))/(1-'P-Parametri'!$B$31*MAX(0,IF(F20<=0,0,(F20-G20)/F20))) -> 29000 | F21: =((F20-E21+MAX(0,-('1-Input'!$B$10-C21-D21)))*(1+B21))*(1-'P-Parametri'!$B$32) -> 223563.93 | G21: =IF(F20<=0,G20,G20*(1-E21/F20))+MAX(0,-('1-Input'!$B$10-C21-D21)) -> 231496.79 | H21: =IF(OR(F20<=0,F20<E21),0,1) -> 1
A22: =A21+1 -> 11 | B22: =IF($A22='3-Simulazione'!$B$6,'P-Parametri'!$B$34,IF($A22='3-Simulazione'!$C$6,'P-Parametri'!$C$34,'3-Simulazione'!$B$7)) -> 0.048525513 | C22: =IF($A22<='1-Input'!$B$26,0,IF($A22='1-Input'!$B$26+1,('1-Input'!$B$23+0)*'1-Input'!$B$27,'1-Input'!$B$23+0)) -> 0 | D22: =IF(AND($A22>=1,$A22<1+0),0,0) -> 0 | E22: =MAX(0,('1-Input'!$B$10-C22-D22))/(1-'P-Parametri'!$B$31*MAX(0,IF(F21<=0,0,(F21-G21)/F21))) -> 29000 | F22: =((F21-E22+MAX(0,-('1-Input'!$B$10-C22-D22)))*(1+B22))*(1-'P-Parametri'!$B$32) -> 203597.23 | G22: =IF(F21<=0,G21,G21*(1-E22/F21))+MAX(0,-('1-Input'!$B$10-C22-D22)) -> 201467.77 | H22: =IF(OR(F21<=0,F21<E22),0,1) -> 1
A23: =A22+1 -> 12 | B23: =IF($A23='3-Simulazione'!$B$6,'P-Parametri'!$B$34,IF($A23='3-Simulazione'!$C$6,'P-Parametri'!$C$34,'3-Simulazione'!$B$7)) -> 0.048525513 | C23: =IF($A23<='1-Input'!$B$26,0,IF($A23='1-Input'!$B$26+1,('1-Input'!$B$23+0)*'1-Input'!$B$27,'1-Input'!$B$23+0)) -> 0 | D23: =IF(AND($A23>=1,$A23<1+0),0,0) -> 0 | E23: =MAX(0,('1-Input'!$B$10-C23-D23))/(1-'P-Parametri'!$B$31*MAX(0,IF(F22<=0,0,(F22-G22)/F22))) -> 29079.077 | F23: =((F22-E23+MAX(0,-('1-Input'!$B$10-C23-D23)))*(1+B23))*(1-'P-Parametri'!$B$32) -> 182620.76 | G23: =IF(F22<=0,G22,G22*(1-E23/F22))+MAX(0,-('1-Input'!$B$10-C23-D23)) -> 172692.83 | H23: =IF(OR(F22<=0,F22<E23),0,1) -> 1
... A53: =A52+1 -> 42 | B53: =IF($A53='3-Simulazione'!$B$6,'P-Parametri'!$B$34,IF($A53='3-Simulazione'!$C$6,'P-Parametri'!$C$34,'3-Simulazione'!$B$7)) -> 0.048525513 | C53: =IF($A53<='1-Input'!$B$26,0,IF($A53='1-Input'!$B$26+1,('1-Input'!$B$23+0)*'1-Input'!$B$27,'1-Input'!$B$23+0)) -> 15535 | D53: =IF(AND($A53>=1,$A53<1+0),0,0) -> 0 | E53: =MAX(0,('1-Input'!$B$10-C53-D53))/(1-'P-Parametri'!$B$31*MAX(0,IF(F52<=0,0,(F52-G52)/F52))) -> 13465 | F53: =((F52-E53+MAX(0,-('1-Input'!$B$10-C53-D53)))*(1+B53))*(1-'P-Parametri'!$B$32) -> -558049.32 | G53: =IF(F52<=0,G52,G52*(1-E53/F52))+MAX(0,-('1-Input'!$B$10-C53-D53)) -> -9180.7268 | H53: =IF(OR(F52<=0,F52<E53),0,1) -> 0
A54: ETÀ DI ESAURIMENTO | B54: =IFERROR('1-Input'!$B$5-1+MATCH(0,H11:H53,0)-1,"non si esaurisce") -> 69 | D54: patrimonio finale | E54: =F53 -> -558049.32
A57: CON IL RIENTRO DEL FOGLIO 1 — reddito, durata e avvio degli input
A58: anno | B58: rend. | C58: pensione | D58: lavoro | E58: G lordo | F58: patrimonio | G58: base | H58: copre?
A59: =0 -> 0 | E59: =0 -> 0 | F59: ='1-Input'!$B$8 -> 760000 | G59: ='1-Input'!$B$9 -> 586000 | H59: =1 -> 1
A60: =A59+1 -> 1 | B60: =IF($A60='3-Simulazione'!$B$6,'P-Parametri'!$B$34,IF($A60='3-Simulazione'!$C$6,'P-Parametri'!$C$34,'3-Simulazione'!$B$7)) -> -0.35 | C60: =IF($A60<='1-Input'!$B$26,0,IF($A60='1-Input'!$B$26+1,('1-Input'!$B$23+'1-Input'!$B$32)*'1-Input'!$B$27,'1-Input'!$B$23+'1-Input'!$B$32)) -> 0 | D60: =IF(AND($A60>='1-Input'!$B$13,$A60<'1-Input'!$B$13+'1-Input'!$B$12),'1-Input'!$B$30,0) -> 11905.452 | E60: =MAX(0,('1-Input'!$B$10-C60-D60))/(1-'P-Parametri'!$B$31*MAX(0,IF(F59<=0,0,(F59-G59)/F59))) -> 18176.53 | F60: =((F59-E60+MAX(0,-('1-Input'!$B$10-C60-D60)))*(1+B60))*(1-'P-Parametri'!$B$32) -> 481220.88 | G60: =IF(F59<=0,G59,G59*(1-E60/F59))+MAX(0,-('1-Input'!$B$10-C60-D60)) -> 571984.94 | H60: =IF(OR(F59<=0,F59<E60),0,1) -> 1
A61: =A60+1 -> 2 | B61: =IF($A61='3-Simulazione'!$B$6,'P-Parametri'!$B$34,IF($A61='3-Simulazione'!$C$6,'P-Parametri'!$C$34,'3-Simulazione'!$B$7)) -> -0.2 | C61: =IF($A61<='1-Input'!$B$26,0,IF($A61='1-Input'!$B$26+1,('1-Input'!$B$23+'1-Input'!$B$32)*'1-Input'!$B$27,'1-Input'!$B$23+'1-Input'!$B$32)) -> 0 | D61: =IF(AND($A61>='1-Input'!$B$13,$A61<'1-Input'!$B$13+'1-Input'!$B$12),'1-Input'!$B$30,0) -> 11905.452 | E61: =MAX(0,('1-Input'!$B$10-C61-D61))/(1-'P-Parametri'!$B$31*MAX(0,IF(F60<=0,0,(F60-G60)/F60))) -> 17094.548 | F61: =((F60-E61+MAX(0,-('1-Input'!$B$10-C61-D61)))*(1+B61))*(1-'P-Parametri'!$B$32) -> 370558.47 | G61: =IF(F60<=0,G60,G60*(1-E61/F60))+MAX(0,-('1-Input'!$B$10-C61-D61)) -> 551666.15 | H61: =IF(OR(F60<=0,F60<E61),0,1) -> 1
A62: =A61+1 -> 3 | B62: =IF($A62='3-Simulazione'!$B$6,'P-Parametri'!$B$34,IF($A62='3-Simulazione'!$C$6,'P-Parametri'!$C$34,'3-Simulazione'!$B$7)) -> 0.048525513 | C62: =IF($A62<='1-Input'!$B$26,0,IF($A62='1-Input'!$B$26+1,('1-Input'!$B$23+'1-Input'!$B$32)*'1-Input'!$B$27,'1-Input'!$B$23+'1-Input'!$B$32)) -> 0 | D62: =IF(AND($A62>='1-Input'!$B$13,$A62<'1-Input'!$B$13+'1-Input'!$B$12),'1-Input'!$B$30,0) -> 11905.452 | E62: =MAX(0,('1-Input'!$B$10-C62-D62))/(1-'P-Parametri'!$B$31*MAX(0,IF(F61<=0,0,(F61-G61)/F61))) -> 17094.548 | F62: =((F61-E62+MAX(0,-('1-Input'!$B$10-C62-D62)))*(1+B62))*(1-'P-Parametri'!$B$32) -> 369874.7 | G62: =IF(F61<=0,G61,G61*(1-E62/F61))+MAX(0,-('1-Input'!$B$10-C62-D62)) -> 526216.77 | H62: =IF(OR(F61<=0,F61<E62),0,1) -> 1
A63: =A62+1 -> 4 | B63: =IF($A63='3-Simulazione'!$B$6,'P-Parametri'!$B$34,IF($A63='3-Simulazione'!$C$6,'P-Parametri'!$C$34,'3-Simulazione'!$B$7)) -> 0.048525513 | C63: =IF($A63<='1-Input'!$B$26,0,IF($A63='1-Input'!$B$26+1,('1-Input'!$B$23+'1-Input'!$B$32)*'1-Input'!$B$27,'1-Input'!$B$23+'1-Input'!$B$32)) -> 0 | D63: =IF(AND($A63>='1-Input'!$B$13,$A63<'1-Input'!$B$13+'1-Input'!$B$12),'1-Input'!$B$30,0) -> 11905.452 | E63: =MAX(0,('1-Input'!$B$10-C63-D63))/(1-'P-Parametri'!$B$31*MAX(0,IF(F62<=0,0,(F62-G62)/F62))) -> 17094.548 | F63: =((F62-E63+MAX(0,-('1-Input'!$B$10-C63-D63)))*(1+B63))*(1-'P-Parametri'!$B$32) -> 369159.2 | G63: =IF(F62<=0,G62,G62*(1-E63/F62))+MAX(0,-('1-Input'!$B$10-C63-D63)) -> 501896.54 | H63: =IF(OR(F62<=0,F62<E63),0,1) -> 1
A64: =A63+1 -> 5 | B64: =IF($A64='3-Simulazione'!$B$6,'P-Parametri'!$B$34,IF($A64='3-Simulazione'!$C$6,'P-Parametri'!$C$34,'3-Simulazione'!$B$7)) -> 0.048525513 | C64: =IF($A64<='1-Input'!$B$26,0,IF($A64='1-Input'!$B$26+1,('1-Input'!$B$23+'1-Input'!$B$32)*'1-Input'!$B$27,'1-Input'!$B$23+'1-Input'!$B$32)) -> 0 | D64: =IF(AND($A64>='1-Input'!$B$13,$A64<'1-Input'!$B$13+'1-Input'!$B$12),'1-Input'!$B$30,0) -> 11905.452 | E64: =MAX(0,('1-Input'!$B$10-C64-D64))/(1-'P-Parametri'!$B$31*MAX(0,IF(F63<=0,0,(F63-G63)/F63))) -> 17094.548 | F64: =((F63-E64+MAX(0,-('1-Input'!$B$10-C64-D64)))*(1+B64))*(1-'P-Parametri'!$B$32) -> 368410.47 | G64: =IF(F63<=0,G63,G63*(1-E64/F63))+MAX(0,-('1-Input'!$B$10-C64-D64)) -> 478655.36 | H64: =IF(OR(F63<=0,F63<E64),0,1) -> 1
A65: =A64+1 -> 6 | B65: =IF($A65='3-Simulazione'!$B$6,'P-Parametri'!$B$34,IF($A65='3-Simulazione'!$C$6,'P-Parametri'!$C$34,'3-Simulazione'!$B$7)) -> 0.048525513 | C65: =IF($A65<='1-Input'!$B$26,0,IF($A65='1-Input'!$B$26+1,('1-Input'!$B$23+'1-Input'!$B$32)*'1-Input'!$B$27,'1-Input'!$B$23+'1-Input'!$B$32)) -> 0 | D65: =IF(AND($A65>='1-Input'!$B$13,$A65<'1-Input'!$B$13+'1-Input'!$B$12),'1-Input'!$B$30,0) -> 0 | E65: =MAX(0,('1-Input'!$B$10-C65-D65))/(1-'P-Parametri'!$B$31*MAX(0,IF(F64<=0,0,(F64-G64)/F64))) -> 29000 | F65: =((F64-E65+MAX(0,-('1-Input'!$B$10-C65-D65)))*(1+B65))*(1-'P-Parametri'!$B$32) -> 355168.77 | G65: =IF(F64<=0,G64,G64*(1-E65/F64))+MAX(0,-('1-Input'!$B$10-C65-D65)) -> 440977.26 | H65: =IF(OR(F64<=0,F64<E65),0,1) -> 1
A66: =A65+1 -> 7 | B66: =IF($A66='3-Simulazione'!$B$6,'P-Parametri'!$B$34,IF($A66='3-Simulazione'!$C$6,'P-Parametri'!$C$34,'3-Simulazione'!$B$7)) -> 0.048525513 | C66: =IF($A66<='1-Input'!$B$26,0,IF($A66='1-Input'!$B$26+1,('1-Input'!$B$23+'1-Input'!$B$32)*'1-Input'!$B$27,'1-Input'!$B$23+'1-Input'!$B$32)) -> 0 | D66: =IF(AND($A66>='1-Input'!$B$13,$A66<'1-Input'!$B$13+'1-Input'!$B$12),'1-Input'!$B$30,0) -> 0 | E66: =MAX(0,('1-Input'!$B$10-C66-D66))/(1-'P-Parametri'!$B$31*MAX(0,IF(F65<=0,0,(F65-G65)/F65))) -> 29000 | F66: =((F65-E66+MAX(0,-('1-Input'!$B$10-C66-D66)))*(1+B66))*(1-'P-Parametri'!$B$32) -> 341312.29 | G66: =IF(F65<=0,G65,G65*(1-E66/F65))+MAX(0,-('1-Input'!$B$10-C66-D66)) -> 404970.89 | H66: =IF(OR(F65<=0,F65<E66),0,1) -> 1
A67: =A66+1 -> 8 | B67: =IF($A67='3-Simulazione'!$B$6,'P-Parametri'!$B$34,IF($A67='3-Simulazione'!$C$6,'P-Parametri'!$C$34,'3-Simulazione'!$B$7)) -> 0.048525513 | C67: =IF($A67<='1-Input'!$B$26,0,IF($A67='1-Input'!$B$26+1,('1-Input'!$B$23+'1-Input'!$B$32)*'1-Input'!$B$27,'1-Input'!$B$23+'1-Input'!$B$32)) -> 0 | D67: =IF(AND($A67>='1-Input'!$B$13,$A67<'1-Input'!$B$13+'1-Input'!$B$12),'1-Input'!$B$30,0) -> 0 | E67: =MAX(0,('1-Input'!$B$10-C67-D67))/(1-'P-Parametri'!$B$31*MAX(0,IF(F66<=0,0,(F66-G66)/F66))) -> 29000 | F67: =((F66-E67+MAX(0,-('1-Input'!$B$10-C67-D67)))*(1+B67))*(1-'P-Parametri'!$B$32) -> 326812.47 | G67: =IF(F66<=0,G66,G66*(1-E67/F66))+MAX(0,-('1-Input'!$B$10-C67-D67)) -> 370562.06 | H67: =IF(OR(F66<=0,F66<E67),0,1) -> 1
A68: =A67+1 -> 9 | B68: =IF($A68='3-Simulazione'!$B$6,'P-Parametri'!$B$34,IF($A68='3-Simulazione'!$C$6,'P-Parametri'!$C$34,'3-Simulazione'!$B$7)) -> 0.048525513 | C68: =IF($A68<='1-Input'!$B$26,0,IF($A68='1-Input'!$B$26+1,('1-Input'!$B$23+'1-Input'!$B$32)*'1-Input'!$B$27,'1-Input'!$B$23+'1-Input'!$B$32)) -> 0 | D68: =IF(AND($A68>='1-Input'!$B$13,$A68<'1-Input'!$B$13+'1-Input'!$B$12),'1-Input'!$B$30,0) -> 0 | E68: =MAX(0,('1-Input'!$B$10-C68-D68))/(1-'P-Parametri'!$B$31*MAX(0,IF(F67<=0,0,(F67-G67)/F67))) -> 29000 | F68: =((F67-E68+MAX(0,-('1-Input'!$B$10-C68-D68)))*(1+B68))*(1-'P-Parametri'!$B$32) -> 311639.44 | G68: =IF(F67<=0,G67,G67*(1-E68/F67))+MAX(0,-('1-Input'!$B$10-C68-D68)) -> 337679.9 | H68: =IF(OR(F67<=0,F67<E68),0,1) -> 1
A69: =A68+1 -> 10 | B69: =IF($A69='3-Simulazione'!$B$6,'P-Parametri'!$B$34,IF($A69='3-Simulazione'!$C$6,'P-Parametri'!$C$34,'3-Simulazione'!$B$7)) -> 0.048525513 | C69: =IF($A69<='1-Input'!$B$26,0,IF($A69='1-Input'!$B$26+1,('1-Input'!$B$23+'1-Input'!$B$32)*'1-Input'!$B$27,'1-Input'!$B$23+'1-Input'!$B$32)) -> 0 | D69: =IF(AND($A69>='1-Input'!$B$13,$A69<'1-Input'!$B$13+'1-Input'!$B$12),'1-Input'!$B$30,0) -> 0 | E69: =MAX(0,('1-Input'!$B$10-C69-D69))/(1-'P-Parametri'!$B$31*MAX(0,IF(F68<=0,0,(F68-G68)/F68))) -> 29000 | F69: =((F68-E69+MAX(0,-('1-Input'!$B$10-C69-D69)))*(1+B69))*(1-'P-Parametri'!$B$32) -> 295761.96 | G69: =IF(F68<=0,G68,G68*(1-E69/F68))+MAX(0,-('1-Input'!$B$10-C69-D69)) -> 306256.67 | H69: =IF(OR(F68<=0,F68<E69),0,1) -> 1
A70: =A69+1 -> 11 | B70: =IF($A70='3-Simulazione'!$B$6,'P-Parametri'!$B$34,IF($A70='3-Simulazione'!$C$6,'P-Parametri'!$C$34,'3-Simulazione'!$B$7)) -> 0.048525513 | C70: =IF($A70<='1-Input'!$B$26,0,IF($A70='1-Input'!$B$26+1,('1-Input'!$B$23+'1-Input'!$B$32)*'1-Input'!$B$27,'1-Input'!$B$23+'1-Input'!$B$32)) -> 0 | D70: =IF(AND($A70>='1-Input'!$B$13,$A70<'1-Input'!$B$13+'1-Input'!$B$12),'1-Input'!$B$30,0) -> 0 | E70: =MAX(0,('1-Input'!$B$10-C70-D70))/(1-'P-Parametri'!$B$31*MAX(0,IF(F69<=0,0,(F69-G69)/F69))) -> 29000 | F70: =((F69-E70+MAX(0,-('1-Input'!$B$10-C70-D70)))*(1+B70))*(1-'P-Parametri'!$B$32) -> 279147.31 | G70: =IF(F69<=0,G69,G69*(1-E70/F69))+MAX(0,-('1-Input'!$B$10-C70-D70)) -> 276227.65 | H70: =IF(OR(F69<=0,F69<E70),0,1) -> 1
A71: =A70+1 -> 12 | B71: =IF($A71='3-Simulazione'!$B$6,'P-Parametri'!$B$34,IF($A71='3-Simulazione'!$C$6,'P-Parametri'!$C$34,'3-Simulazione'!$B$7)) -> 0.048525513 | C71: =IF($A71<='1-Input'!$B$26,0,IF($A71='1-Input'!$B$26+1,('1-Input'!$B$23+'1-Input'!$B$32)*'1-Input'!$B$27,'1-Input'!$B$23+'1-Input'!$B$32)) -> 0 | D71: =IF(AND($A71>='1-Input'!$B$13,$A71<'1-Input'!$B$13+'1-Input'!$B$12),'1-Input'!$B$30,0) -> 0 | E71: =MAX(0,('1-Input'!$B$10-C71-D71))/(1-'P-Parametri'!$B$31*MAX(0,IF(F70<=0,0,(F70-G70)/F70))) -> 29079.077 | F71: =((F70-E71+MAX(0,-('1-Input'!$B$10-C71-D71)))*(1+B71))*(1-'P-Parametri'!$B$32) -> 261678.51 | G71: =IF(F70<=0,G70,G70*(1-E71/F70))+MAX(0,-('1-Input'!$B$10-C71-D71)) -> 247452.71 | H71: =IF(OR(F70<=0,F70<E71),0,1) -> 1
... A101: =A100+1 -> 42 | B101: =IF($A101='3-Simulazione'!$B$6,'P-Parametri'!$B$34,IF($A101='3-Simulazione'!$C$6,'P-Parametri'!$C$34,'3-Simulazione'!$B$7)) -> 0.048525513 | C101: =IF($A101<='1-Input'!$B$26,0,IF($A101='1-Input'!$B$26+1,('1-Input'!$B$23+'1-Input'!$B$32)*'1-Input'!$B$27,'1-Input'!$B$23+'1-Input'!$B$32)) -> 16422.445 | D101: =IF(AND($A101>='1-Input'!$B$13,$A101<'1-Input'!$B$13+'1-Input'!$B$12),'1-Input'!$B$30,0) -> 0 | E101: =MAX(0,('1-Input'!$B$10-C101-D101))/(1-'P-Parametri'!$B$31*MAX(0,IF(F100<=0,0,(F100-G100)/F100))) -> 12577.555 | F101: =((F100-E101+MAX(0,-('1-Input'!$B$10-C101-D101)))*(1+B101))*(1-'P-Parametri'!$B$32) -> -245034.25 | G101: =IF(F100<=0,G100,G100*(1-E101/F100))+MAX(0,-('1-Input'!$B$10-C101-D101)) -> -4151.7713 | H101: =IF(OR(F100<=0,F100<E101),0,1) -> 0
A102: ETÀ DI ESAURIMENTO | B102: =IFERROR('1-Input'!$B$5-1+MATCH(0,H59:H101,0)-1,"non si esaurisce") -> 78 | D102: patrimonio finale | E102: =F101 -> -245034.25
...

Sheet 4-Griglia
A1: La griglia 3 × 4 — dodici combinazioni costruite, non estratte
A2: Strumento informativo / divulgativo. NON è consulenza finanziaria. I valori sono indicativi al 2026 e vanno verificati col tuo consulente.
A4: SPESA MASSIMA SOSTENIBILE PER QUARANTADUE ANNI
B5: costante | C5: crolli INIZIO | D5: crolli METÀ | E5: crolli FINE
A6: r = 1% | B6: ='M1-Motore-Griglia'!$B$51 -> 27451.637 | C6: ='M1-Motore-Griglia'!$B$101 -> 21221.533 | D6: ='M1-Motore-Griglia'!$B$151 -> 28180.139 | E6: ='M1-Motore-Griglia'!$B$201 -> 31993.758
A7: r = 2% | B7: ='M1-Motore-Griglia'!$B$251 -> 30039.815 | C7: ='M1-Motore-Griglia'!$B$301 -> 22621.704 | D7: ='M1-Motore-Griglia'!$B$351 -> 30932.171 | E7: ='M1-Motore-Griglia'!$B$401 -> 35415.973
A8: r = 3% | B8: ='M1-Motore-Griglia'!$B$451 -> 32989.828 | C8: ='M1-Motore-Griglia'!$B$501 -> 24119.551 | D8: ='M1-Motore-Griglia'!$B$551 -> 34109.015 | E8: ='M1-Motore-Griglia'!$B$601 -> 39202.863
A10: SCARTO SULLA SPESA DEL CASO
B11: costante | C11: crolli INIZIO | D11: crolli METÀ | E11: crolli FINE
A12: r = 1% | B12: ='M1-Motore-Griglia'!$B$51/'1-Input'!$B$10-1 -> -0.053391811 | C12: ='M1-Motore-Griglia'!$B$101/'1-Input'!$B$10-1 -> -0.26822301 | D12: ='M1-Motore-Griglia'!$B$151/'1-Input'!$B$10-1 -> -0.028271081 | E12: ='M1-Motore-Griglia'!$B$201/'1-Input'!$B$10-1 -> 0.10323304
A13: r = 2% | B13: ='M1-Motore-Griglia'!$B$251/'1-Input'!$B$10-1 -> 0.035855697 | C13: ='M1-Motore-Griglia'!$B$301/'1-Input'!$B$10-1 -> -0.21994123 | D13: ='M1-Motore-Griglia'!$B$351/'1-Input'!$B$10-1 -> 0.066626573 | E13: ='M1-Motore-Griglia'!$B$401/'1-Input'!$B$10-1 -> 0.22124044
A14: r = 3% | B14: ='M1-Motore-Griglia'!$B$451/'1-Input'!$B$10-1 -> 0.13758029 | C14: ='M1-Motore-Griglia'!$B$501/'1-Input'!$B$10-1 -> -0.16829135 | D14: ='M1-Motore-Griglia'!$B$551/'1-Input'!$B$10-1 -> 0.17617293 | E14: ='M1-Motore-Griglia'!$B$601/'1-Input'!$B$10-1 -> 0.35182286
A16: ETÀ A CUI IL CAPITALE NON COPRE PIÙ IL PRELIEVO
B17: costante | C17: crolli INIZIO | D17: crolli METÀ | E17: crolli FINE
A18: r = 1% | B18: ='M1-Motore-Griglia'!$B$1299 -> 86 | C18: ='M1-Motore-Griglia'!$B$1347 -> 66 | D18: ='M1-Motore-Griglia'!$B$1395 -> 89 | E18: ='M1-Motore-Griglia'!$B$1443 -> non si esaurisce
A19: r = 2% | B19: ='M1-Motore-Griglia'!$B$1491 -> non si esaurisce | C19: ='M1-Motore-Griglia'!$B$1539 -> 67 | D19: ='M1-Motore-Griglia'!$B$1587 -> non si esaurisce | E19: ='M1-Motore-Griglia'!$B$1635 -> non si esaurisce
A20: r = 3% | B20: ='M1-Motore-Griglia'!$B$1683 -> non si esaurisce | C20: ='M1-Motore-Griglia'!$B$1731 -> 69 | D20: ='M1-Motore-Griglia'!$B$1779 -> non si esaurisce | E20: ='M1-Motore-Griglia'!$B$1827 -> non si esaurisce
A22: CAPITALE NECESSARIO PER SOSTENERE LA SPESA DEL CASO
B23: costante | C23: crolli INIZIO | D23: crolli METÀ | E23: crolli FINE
A24: r = 1% | B24: ='M1-Motore-Griglia'!$B$651 -> 820838.9 | C24: ='M1-Motore-Griglia'!$B$701 -> 1177197.5 | D24: ='M1-Motore-Griglia'!$B$751 -> 792436.33 | E24: ='M1-Motore-Griglia'!$B$801 -> 669001.43
A25: r = 2% | B25: ='M1-Motore-Griglia'!$B$851 -> 725053.81 | C25: ='M1-Motore-Griglia'!$B$901 -> 1059405.2 | D25: ='M1-Motore-Griglia'!$B$951 -> 695002.54 | E25: ='M1-Motore-Griglia'!$B$1001 -> 592846.01
A26: r = 3% | B26: ='M1-Motore-Griglia'!$B$1051 -> 644533.22 | C26: ='M1-Motore-Griglia'!$B$1101 -> 962349.45 | D26: ='M1-Motore-Griglia'!$B$1151 -> 613108.89 | E26: ='M1-Motore-Griglia'!$B$1201 -> 529788.44
A28: LETTURE DELLA GRIGLIA
A29: Celle in cui il piano regge (su dodici costruite) | B29: =COUNTIF(B6:E8,">="&'1-Input'!$B$10) -> 7
A30: Celle rosse | B30: =12-B29 -> 5
A31: Cella peggiore — spesa massima / età | B31: =MIN(B6:E8) -> 21221.533 | C31: =MIN(B18:E20) -> 66
A32: Capitale necessario nella cella peggiore, e quanto ne manca | B32: =MAX(B24:E26) -> 1177197.5 | C32: =B32-'1-Input'!$B$8 -> 417197.47
A33: Capitale necessario senza alcuna pensione (r = 3%, costante) | B33: ='M1-Motore-Griglia'!$B$1251 -> 839268.36
A34: VALORE IN CAPITALE DELLA PENSIONE PUBBLICA | B34: =B33-'M1-Motore-Griglia'!$B$1051 -> 194735.14
A35: «Sette delle dodici combinazioni che ho costruito» — non «sette su dodici» detto come una frequenza. Le posizioni dei crolli (anni 1-2, 21-22, 41-42) sono SCELTE, non stimate: la griglia è illustrativa, non probabilistica. E una griglia in cui aggiungere reddito non può peggiorare le cose non dimostra che rientrare convenga: dimostra soltanto di quanto.
A36: Il numero grande dell'atto è un'ETA', non un conteggio: sessantasei è una grandezza misurata, «sette su dodici» è un conteggio di scenari scelti a mano e non sopravvive alla perdita della cornice verbale.
A38: LE TRE SCALE DEL TASSO DI PRELIEVO
B39: Cassa | C39: Omogeneo (vendita lorda) | D39: Col bollo
A40: Senza lavoro | B40: ='1-Input'!$B$10/'1-Input'!$B$8 -> 0.038157895 | C40: =('1-Input'!$B$10/(1-'P-Parametri'!$B$31*'1-Input'!$B$29))/'1-Input'!$B$8 -> 0.040573059 | D40: =(('1-Input'!$B$10/(1-'P-Parametri'!$B$31*'1-Input'!$B$29))+'P-Parametri'!$B$32*(('1-Input'!$B$8-'1-Input'!$B$10/(1-'P-Parametri'!$B$31*'1-Input'!$B$29))*(1+'1-Input'!$B$15)))/'1-Input'!$B$8 -> 0.042549479
A41: Col reddito del rientro del foglio 1 | B41: =('1-Input'!$B$10-'1-Input'!$B$30)/'1-Input'!$B$8 -> 0.022492827 | C41: =(('1-Input'!$B$10-'1-Input'!$B$30)/(1-'P-Parametri'!$B$31*'1-Input'!$B$29))/'1-Input'!$B$8 -> 0.023916487 | D41: =((('1-Input'!$B$10-'1-Input'!$B$30)/(1-'P-Parametri'!$B$31*'1-Input'!$B$29))+'P-Parametri'!$B$32*(('1-Input'!$B$8-('1-Input'!$B$10-'1-Input'!$B$30)/(1-'P-Parametri'!$B$31*'1-Input'!$B$29))*(1+'1-Input'!$B$15)))/'1-Input'!$B$8 -> 0.025927219
A42: Il bollo grava sul patrimonio di FINE anno: è la convenzione del motore, ed è la ragione per cui la terza scala vale 4,255% e non 4,257%. Il 4,257% è lo stesso bollo calcolato sul patrimonio di INIZIO anno.
A43: Copertura della spesa dalla pensione pubblica | B43: ='1-Input'!$B$23/'1-Input'!$B$10 -> 0.53568966

Sheet 5-Leve
A1: LE DUE LEVE, IN ORDINE — prima la spesa, poi il lavoro
A2: Strumento informativo / divulgativo. NON è consulenza finanziaria. I valori sono indicativi al 2026 e vanno verificati col tuo consulente.
A3: Questo foglio risponde a una sola domanda: che cosa chiude una cella rossa. La risposta ha due forme — tagliare la spesa, una volta sola e per sempre, oppure lavorare, per un numero di anni dichiarato. Non sono due strade equivalenti: sono una strada e una scorciatoia, e la scorciatoia è la spesa.
A5: CHE COSA CHIUDE OGNI CELLA ROSSA
A6: Cella | B6: Spesa massima | C6: Età | D6: Taglio di spesa | E6: Taglio % | F6: Lavoro — durata A | G6: × carriera | H6: netto in busta | I6: pensione in più | J6: residuo finale | K6: esito | L6: Lavoro — durata B | M6: × carriera | N6: netto in busta | O6: pensione in più | P6: residuo finale | Q6: esito
A7: r = 1% · crolli INIZIO | B7: ='M1-Motore-Griglia'!$B$101 -> 21221.533 | C7: ='M1-Motore-Griglia'!$B$1347 -> 66 | D7: ='1-Input'!$B$10-B7 -> 7778.4674 | E7: =D7/'1-Input'!$B$10 -> 0.26822301 | F7: ='M2-Motore-Chiusura'!$B$53 -> 59803.65 | G7: =F7/'1-Input'!$B$17 -> 1.7086757 | H7: =(($F$7*(1-'P-Parametri'!$B$22))+0)-(MAX(0,(IF((($F$7*(1-'P-Parametri'!$B$22))+0)<='P-Parametri'!$B$6,'P-Parametri'!$C$6*(($F$7*(1-'P-Parametri'!$B$22))+0),IF((($F$7*(1-'P-Parametri'!$B$22))+0)<='P-Parametri'!$B$7,'P-Parametri'!$B$9+'P-Parametri'!$C$7*((($F$7*(1-'P-Parametri'!$B$22))+0)-'P-Parametri'!$B$6),'P-Parametri'!$B$10+'P-Parametri'!$C$8*((($F$7*(1-'P-Parametri'!$B$22))+0)-'P-Parametri'!$B$7))))-(IF((($F$7*(1-'P-Parametri'!$B$22))+0)<='P-Parametri'!$C$12,'P-Parametri'!$B$12,IF((($F$7*(1-'P-Parametri'!$B$22))+0)<='P-Parametri'!$B$6,'P-Parametri'!$B$13+'P-Parametri'!$C$13*('P-Parametri'!$B$6-(($F$7*(1-'P-Parametri'!$B$22))+0))/'P-Parametri'!$D$13,IF((($F$7*(1-'P-Parametri'!$B$22))+0)<='P-Parametri'!$B$7,'P-Parametri'!$B$14*('P-Parametri'!$B$7-(($F$7*(1-'P-Parametri'!$B$22))+0))/'P-Parametri'!$C$14,0))))-(IF(($F$7*(1-'P-Parametri'!$B$22))>0,IF((($F$7*(1-'P-Parametri'!$B$22))+0)<='P-Parametri'!$C$21,0,IF((($F$7*(1-'P-Parametri'!$B$22))+0)<='P-Parametri'!$D$21,'P-Parametri'!$B$21,IF((($F$7*(1-'P-Parametri'!$B$22))+0)<'P-Parametri'!$E$21,'P-Parametri'!$B$21*('P-Parametri'!$E$21-(($F$7*(1-'P-Parametri'!$B$22))+0))/('P-Parametri'!$E$21-'P-Parametri'!$D$21),0))),0))))-(IF(MAX(0,(IF((($F$7*(1-'P-Parametri'!$B$22))+0)<='P-Parametri'!$B$6,'P-Parametri'!$C$6*(($F$7*(1-'P-Parametri'!$B$22))+0),IF((($F$7*(1-'P-Parametri'!$B$22))+0)<='P-Parametri'!$B$7,'P-Parametri'!$B$9+'P-Parametri'!$C$7*((($F$7*(1-'P-Parametri'!$B$22))+0)-'P-Parametri'!$B$6),'P-Parametri'!$B$10+'P-Parametri'!$C$8*((($F$7*(1-'P-Parametri'!$B$22))+0)-'P-Parametri'!$B$7))))-(IF((($F$7*(1-'P-Parametri'!$B$22))+0)<='P-Parametri'!$C$12,'P-Parametri'!$B$12,IF((($F$7*(1-'P-Parametri'!$B$22))+0)<='P-Parametri'!$B$6,'P-Parametri'!$B$13+'P-Parametri'!$C$13*('P-Parametri'!$B$6-(($F$7*(1-'P-Parametri'!$B$22))+0))/'P-Parametri'!$D$13,IF((($F$7*(1-'P-Parametri'!$B$22))+0)<='P-Parametri'!$B$7,'P-Parametri'!$B$14*('P-Parametri'!$B$7-(($F$7*(1-'P-Parametri'!$B$22))+0))/'P-Parametri'!$C$14,0))))-(IF(($F$7*(1-'P-Parametri'!$B$22))>0,IF((($F$7*(1-'P-Parametri'!$B$22))+0)<='P-Parametri'!$C$21,0,IF((($F$7*(1-'P-Parametri'!$B$22))+0)<='P-Parametri'!$D$21,'P-Parametri'!$B$21,IF((($F$7*(1-'P-Parametri'!$B$22))+0)<'P-Parametri'!$E$21,'P-Parametri'!$B$21*('P-Parametri'!$E$21-(($F$7*(1-'P-Parametri'!$B$22))+0))/('P-Parametri'!$E$21-'P-Parametri'!$D$21),0))),0)))>0,'P-Parametri'!$B$11*(($F$7*(1-'P-Parametri'!$B$22))+0),0))+(IF(AND((($F$7*(1-'P-Parametri'!$B$22))+0)<='P-Parametri'!$C$18,(IF((($F$7*(1-'P-Parametri'!$B$22))+0)<='P-Parametri'!$B$6,'P-Parametri'!$C$6*(($F$7*(1-'P-Parametri'!$B$22))+0),IF((($F$7*(1-'P-Parametri'!$B$22))+0)<='P-Parametri'!$B$7,'P-Parametri'!$B$9+'P-Parametri'!$C$7*((($F$7*(1-'P-Parametri'!$B$22))+0)-'P-Parametri'!$B$6),'P-Parametri'!$B$10+'P-Parametri'!$C$8*((($F$7*(1-'P-Parametri'!$B$22))+0)-'P-Parametri'!$B$7))))>(IF((($F$7*(1-'P-Parametri'!$B$22))+0)<='P-Parametri'!$C$12,'P-Parametri'!$B$12,IF((($F$7*(1-'P-Parametri'!$B$22))+0)<='P-Parametri'!$B$6,'P-Parametri'!$B$13+'P-Parametri'!$C$13*('P-Parametri'!$B$6-(($F$7*(1-'P-Parametri'!$B$22))+0))/'P-Parametri'!$D$13,IF((($F$7*(1-'P-Parametri'!$B$22))+0)<='P-Parametri'!$B$7,'P-Parametri'!$B$14*('P-Parametri'!$B$7-(($F$7*(1-'P-Parametri'!$B$22))+0))/'P-Parametri'!$C$14,0))))-'P-Parametri'!$D$18),'P-Parametri'!$B$18,0))+(IF(($F$7*(1-'P-Parametri'!$B$22))>0,IF((($F$7*(1-'P-Parametri'!$B$22))+0)>'P-Parametri'!$D$20,0,IF((($F$7*(1-'P-Parametri'!$B$22))+0)<='P-Parametri'!$B$20,'P-Parametri'!$B$19*($F$7*(1-'P-Parametri'!$B$22)),IF((($F$7*(1-'P-Parametri'!$B$22))+0)<='P-Parametri'!$C$20,'P-Parametri'!$C$19*($F$7*(1-'P-Parametri'!$B$22)),'P-Parametri'!$D$19*($F$7*(1-'P-Parametri'!$B$22))))),0)) -> 37669.232 | I7: =(('P-Parametri'!$B$24*$F$7)*(1+'P-Parametri'!$B$26)^('1-Input'!$B$25-1-'1-Input'!$B$12+1)*(IF('P-Parametri'!$B$26=0,'1-Input'!$B$12,((1+'P-Parametri'!$B$26)^'1-Input'!$B$12-1)/'P-Parametri'!$B$26)))*'P-Parametri'!$B$27*(1-'P-Parametri'!$B$28) -> 4422.7047 | J7: ='M2-Motore-Chiusura'!$E$569 -> 1.9970436e-09 | K7: =IF(ABS(J7)<=1,"radice","GRADINO — la cella si chiude su uno scalino fiscale, non su una radice") -> radice | L7: ='M2-Motore-Chiusura'!$B$105 -> 23941.317 | M7: =L7/'1-Input'!$B$17 -> 0.68403763 | N7: =(($L$7*(1-'P-Parametri'!$B$22))+0)-(MAX(0,(IF((($L$7*(1-'P-Parametri'!$B$22))+0)<='P-Parametri'!$B$6,'P-Parametri'!$C$6*(($L$7*(1-'P-Parametri'!$B$22))+0),IF((($L$7*(1-'P-Parametri'!$B$22))+0)<='P-Parametri'!$B$7,'P-Parametri'!$B$9+'P-Parametri'!$C$7*((($L$7*(1-'P-Parametri'!$B$22))+0)-'P-Parametri'!$B$6),'P-Parametri'!$B$10+'P-Parametri'!$C$8*((($L$7*(1-'P-Parametri'!$B$22))+0)-'P-Parametri'!$B$7))))-(IF((($L$7*(1-'P-Parametri'!$B$22))+0)<='P-Parametri'!$C$12,'P-Parametri'!$B$12,IF((($L$7*(1-'P-Parametri'!$B$22))+0)<='P-Parametri'!$B$6,'P-Parametri'!$B$13+'P-Parametri'!$C$13*('P-Parametri'!$B$6-(($L$7*(1-'P-Parametri'!$B$22))+0))/'P-Parametri'!$D$13,IF((($L$7*(1-'P-Parametri'!$B$22))+0)<='P-Parametri'!$B$7,'P-Parametri'!$B$14*('P-Parametri'!$B$7-(($L$7*(1-'P-Parametri'!$B$22))+0))/'P-Parametri'!$C$14,0))))-(IF(($L$7*(1-'P-Parametri'!$B$22))>0,IF((($L$7*(1-'P-Parametri'!$B$22))+0)<='P-Parametri'!$C$21,0,IF((($L$7*(1-'P-Parametri'!$B$22))+0)<='P-Parametri'!$D$21,'P-Parametri'!$B$21,IF((($L$7*(1-'P-Parametri'!$B$22))+0)<'P-Parametri'!$E$21,'P-Parametri'!$B$21*('P-Parametri'!$E$21-(($L$7*(1-'P-Parametri'!$B$22))+0))/('P-Parametri'!$E$21-'P-Parametri'!$D$21),0))),0))))-(IF(MAX(0,(IF((($L$7*(1-'P-Parametri'!$B$22))+0)<='P-Parametri'!$B$6,'P-Parametri'!$C$6*(($L$7*(1-'P-Parametri'!$B$22))+0),IF((($L$7*(1-'P-Parametri'!$B$22))+0)<='P-Parametri'!$B$7,'P-Parametri'!$B$9+'P-Parametri'!$C$7*((($L$7*(1-'P-Parametri'!$B$22))+0)-'P-Parametri'!$B$6),'P-Parametri'!$B$10+'P-Parametri'!$C$8*((($L$7*(1-'P-Parametri'!$B$22))+0)-'P-Parametri'!$B$7))))-(IF((($L$7*(1-'P-Parametri'!$B$22))+0)<='P-Parametri'!$C$12,'P-Parametri'!$B$12,IF((($L$7*(1-'P-Parametri'!$B$22))+0)<='P-Parametri'!$B$6,'P-Parametri'!$B$13+'P-Parametri'!$C$13*('P-Parametri'!$B$6-(($L$7*(1-'P-Parametri'!$B$22))+0))/'P-Parametri'!$D$13,IF((($L$7*(1-'P-Parametri'!$B$22))+0)<='P-Parametri'!$B$7,'P-Parametri'!$B$14*('P-Parametri'!$B$7-(($L$7*(1-'P-Parametri'!$B$22))+0))/'P-Parametri'!$C$14,0))))-(IF(($L$7*(1-'P-Parametri'!$B$22))>0,IF((($L$7*(1-'P-Parametri'!$B$22))+0)<='P-Parametri'!$C$21,0,IF((($L$7*(1-'P-Parametri'!$B$22))+0)<='P-Parametri'!$D$21,'P-Parametri'!$B$21,IF((($L$7*(1-'P-Parametri'!$B$22))+0)<'P-Parametri'!$E$21,'P-Parametri'!$B$21*('P-Parametri'!$E$21-(($L$7*(1-'P-Parametri'!$B$22))+0))/('P-Parametri'!$E$21-'P-Parametri'!$D$21),0))),0)))>0,'P-Parametri'!$B$11*(($L$7*(1-'P-Parametri'!$B$22))+0),0))+(IF(AND((($L$7*(1-'P-Parametri'!$B$22))+0)<='P-Parametri'!$C$18,(IF((($L$7*(1-'P-Parametri'!$B$22))+0)<='P-Parametri'!$B$6,'P-Parametri'!$C$6*(($L$7*(1-'P-Parametri'!$B$22))+0),IF((($L$7*(1-'P-Parametri'!$B$22))+0)<='P-Parametri'!$B$7,'P-Parametri'!$B$9+'P-Parametri'!$C$7*((($L$7*(1-'P-Parametri'!$B$22))+0)-'P-Parametri'!$B$6),'P-Parametri'!$B$10+'P-Parametri'!$C$8*((($L$7*(1-'P-Parametri'!$B$22))+0)-'P-Parametri'!$B$7))))>(IF((($L$7*(1-'P-Parametri'!$B$22))+0)<='P-Parametri'!$C$12,'P-Parametri'!$B$12,IF((($L$7*(1-'P-Parametri'!$B$22))+0)<='P-Parametri'!$B$6,'P-Parametri'!$B$13+'P-Parametri'!$C$13*('P-Parametri'!$B$6-(($L$7*(1-'P-Parametri'!$B$22))+0))/'P-Parametri'!$D$13,IF((($L$7*(1-'P-Parametri'!$B$22))+0)<='P-Parametri'!$B$7,'P-Parametri'!$B$14*('P-Parametri'!$B$7-(($L$7*(1-'P-Parametri'!$B$22))+0))/'P-Parametri'!$C$14,0))))-'P-Parametri'!$D$18),'P-Parametri'!$B$18,0))+(IF(($L$7*(1-'P-Parametri'!$B$22))>0,IF((($L$7*(1-'P-Parametri'!$B$22))+0)>'P-Parametri'!$D$20,0,IF((($L$7*(1-'P-Parametri'!$B$22))+0)<='P-Parametri'!$B$20,'P-Parametri'!$B$19*($L$7*(1-'P-Parametri'!$B$22)),IF((($L$7*(1-'P-Parametri'!$B$22))+0)<='P-Parametri'!$C$20,'P-Parametri'!$C$19*($L$7*(1-'P-Parametri'!$B$22)),'P-Parametri'!$D$19*($L$7*(1-'P-Parametri'!$B$22))))),0)) -> 19788.762 | O7: =(('P-Parametri'!$B$24*$L$7)*(1+'P-Parametri'!$B$26)^('1-Input'!$B$25-1-'1-Input'!$C$12+1)*(IF('P-Parametri'!$B$26=0,'1-Input'!$C$12,((1+'P-Parametri'!$B$26)^'1-Input'!$C$12-1)/'P-Parametri'!$B$26)))*'P-Parametri'!$B$27*(1-'P-Parametri'!$B$28) -> 3488.9271 | P7: ='M2-Motore-Chiusura'!$E$617 -> -1.564444e-09 | Q7: =IF(ABS(P7)<=1,"radice","GRADINO — la cella si chiude su uno scalino fiscale, non su una radice") -> radice
